[2021-08-24 08:34:45,876][Thread-3:17996][task_id:django.request][log.py:230][ERROR][Internal Server Error: /logistic/LogisticWorkStation]
Traceback (most recent call last):
  File "D:\zhouzhi\gitlit_code\logistic_tracking_system\logistic_tracking_system\lts\views.py", line 2448, in get
    drs = db.execute_sql(conn, sql_main)
  File "D:\zhouzhi\gitlit_code\logistic_tracking_system\logistic_tracking_system\common\db.py", line 45, in execute_sql
    cursor.execute(sql)
  File "C:\Users\zhi.zhou\Anaconda3\envs\lts\lib\site-packages\pymysql\cursors.py", line 148, in execute
    result = self._query(query)
  File "C:\Users\zhi.zhou\Anaconda3\envs\lts\lib\site-packages\pymysql\cursors.py", line 310, in _query
    conn.query(q)
  File "C:\Users\zhi.zhou\Anaconda3\envs\lts\lib\site-packages\pymysql\connections.py", line 548, in query
    self._affected_rows = self._read_query_result(unbuffered=unbuffered)
  File "C:\Users\zhi.zhou\Anaconda3\envs\lts\lib\site-packages\pymysql\connections.py", line 775, in _read_query_result
    result.read()
  File "C:\Users\zhi.zhou\Anaconda3\envs\lts\lib\site-packages\pymysql\connections.py", line 1156, in read
    first_packet = self.connection._read_packet()
  File "C:\Users\zhi.zhou\Anaconda3\envs\lts\lib\site-packages\pymysql\connections.py", line 725, in _read_packet
    packet.raise_for_error()
  File "C:\Users\zhi.zhou\Anaconda3\envs\lts\lib\site-packages\pymysql\protocol.py", line 221, in raise_for_error
    err.raise_mysql_exception(self._data)
  File "C:\Users\zhi.zhou\Anaconda3\envs\lts\lib\site-packages\pymysql\err.py", line 143, in raise_mysql_exception
    raise errorclass(errno, errval)
pymysql.err.OperationalError: (1046, 'No database selected')

During handling of the above exception, another exception occurred:

Traceback (most recent call last):
  File "C:\Users\zhi.zhou\Anaconda3\envs\lts\lib\site-packages\django\core\handlers\exception.py", line 47, in inner
    response = get_response(request)
  File "C:\Users\zhi.zhou\Anaconda3\envs\lts\lib\site-packages\django\core\handlers\base.py", line 181, in _get_response
    response = wrapped_callback(request, *callback_args, **callback_kwargs)
  File "C:\Users\zhi.zhou\Anaconda3\envs\lts\lib\site-packages\django\views\generic\base.py", line 70, in view
    return self.dispatch(request, *args, **kwargs)
  File "C:\Users\zhi.zhou\Anaconda3\envs\lts\lib\site-packages\django\views\generic\base.py", line 98, in dispatch
    return handler(request, *args, **kwargs)
  File "D:\zhouzhi\gitlit_code\logistic_tracking_system\logistic_tracking_system\lts\views.py", line 2483, in get
    result = json.dumps(result)
  File "C:\Users\zhi.zhou\Anaconda3\envs\lts\lib\json\__init__.py", line 231, in dumps
    return _default_encoder.encode(obj)
  File "C:\Users\zhi.zhou\Anaconda3\envs\lts\lib\json\encoder.py", line 199, in encode
    chunks = self.iterencode(o, _one_shot=True)
  File "C:\Users\zhi.zhou\Anaconda3\envs\lts\lib\json\encoder.py", line 257, in iterencode
    return _iterencode(o, 0)
  File "C:\Users\zhi.zhou\Anaconda3\envs\lts\lib\json\encoder.py", line 180, in default
    o.__class__.__name__)
TypeError: Object of type 'OperationalError' is not JSON serializable
[2021-08-24 08:59:19,057][Thread-5:18128][task_id:django.request][log.py:230][ERROR][Internal Server Error: /logistic/LogisticFinishedProductStorage]
Traceback (most recent call last):
  File "D:\zhouzhi\gitlit_code\logistic_tracking_system\logistic_tracking_system\lts\views.py", line 5769, in get
    if product_plan_code:
NameError: name 'product_plan_code' is not defined

During handling of the above exception, another exception occurred:

Traceback (most recent call last):
  File "C:\Users\zhi.zhou\Anaconda3\envs\lts\lib\site-packages\django\core\handlers\exception.py", line 47, in inner
    response = get_response(request)
  File "C:\Users\zhi.zhou\Anaconda3\envs\lts\lib\site-packages\django\core\handlers\base.py", line 181, in _get_response
    response = wrapped_callback(request, *callback_args, **callback_kwargs)
  File "C:\Users\zhi.zhou\Anaconda3\envs\lts\lib\site-packages\django\views\generic\base.py", line 70, in view
    return self.dispatch(request, *args, **kwargs)
  File "C:\Users\zhi.zhou\Anaconda3\envs\lts\lib\site-packages\django\views\generic\base.py", line 98, in dispatch
    return handler(request, *args, **kwargs)
  File "D:\zhouzhi\gitlit_code\logistic_tracking_system\logistic_tracking_system\lts\views.py", line 5836, in get
    result = json.dumps(result)
  File "C:\Users\zhi.zhou\Anaconda3\envs\lts\lib\json\__init__.py", line 231, in dumps
    return _default_encoder.encode(obj)
  File "C:\Users\zhi.zhou\Anaconda3\envs\lts\lib\json\encoder.py", line 199, in encode
    chunks = self.iterencode(o, _one_shot=True)
  File "C:\Users\zhi.zhou\Anaconda3\envs\lts\lib\json\encoder.py", line 257, in iterencode
    return _iterencode(o, 0)
  File "C:\Users\zhi.zhou\Anaconda3\envs\lts\lib\json\encoder.py", line 180, in default
    o.__class__.__name__)
TypeError: Object of type 'NameError' is not JSON serializable
[2021-08-24 08:59:46,504][Thread-7:18052][task_id:django.request][log.py:230][ERROR][Internal Server Error: /logistic/LogisticFinishedProductStorage]
Traceback (most recent call last):
  File "D:\zhouzhi\gitlit_code\logistic_tracking_system\logistic_tracking_system\lts\views.py", line 5769, in get
    if product_plan_code:
NameError: name 'product_plan_code' is not defined

During handling of the above exception, another exception occurred:

Traceback (most recent call last):
  File "C:\Users\zhi.zhou\Anaconda3\envs\lts\lib\site-packages\django\core\handlers\exception.py", line 47, in inner
    response = get_response(request)
  File "C:\Users\zhi.zhou\Anaconda3\envs\lts\lib\site-packages\django\core\handlers\base.py", line 181, in _get_response
    response = wrapped_callback(request, *callback_args, **callback_kwargs)
  File "C:\Users\zhi.zhou\Anaconda3\envs\lts\lib\site-packages\django\views\generic\base.py", line 70, in view
    return self.dispatch(request, *args, **kwargs)
  File "C:\Users\zhi.zhou\Anaconda3\envs\lts\lib\site-packages\django\views\generic\base.py", line 98, in dispatch
    return handler(request, *args, **kwargs)
  File "D:\zhouzhi\gitlit_code\logistic_tracking_system\logistic_tracking_system\lts\views.py", line 5836, in get
    result = json.dumps(result)
  File "C:\Users\zhi.zhou\Anaconda3\envs\lts\lib\json\__init__.py", line 231, in dumps
    return _default_encoder.encode(obj)
  File "C:\Users\zhi.zhou\Anaconda3\envs\lts\lib\json\encoder.py", line 199, in encode
    chunks = self.iterencode(o, _one_shot=True)
  File "C:\Users\zhi.zhou\Anaconda3\envs\lts\lib\json\encoder.py", line 257, in iterencode
    return _iterencode(o, 0)
  File "C:\Users\zhi.zhou\Anaconda3\envs\lts\lib\json\encoder.py", line 180, in default
    o.__class__.__name__)
TypeError: Object of type 'NameError' is not JSON serializable
[2021-08-24 09:05:27,943][Thread-3:15032][task_id:django.request][log.py:230][ERROR][Internal Server Error: /logistic/LogisticFinishedProductStorage]
Traceback (most recent call last):
  File "D:\zhouzhi\gitlit_code\logistic_tracking_system\logistic_tracking_system\lts\views.py", line 5823, in get
    drs = db.execute_sql(conn, sql)
  File "D:\zhouzhi\gitlit_code\logistic_tracking_system\logistic_tracking_system\common\db.py", line 45, in execute_sql
    cursor.execute(sql)
  File "C:\Users\zhi.zhou\Anaconda3\envs\lts\lib\site-packages\pymysql\cursors.py", line 148, in execute
    result = self._query(query)
  File "C:\Users\zhi.zhou\Anaconda3\envs\lts\lib\site-packages\pymysql\cursors.py", line 310, in _query
    conn.query(q)
  File "C:\Users\zhi.zhou\Anaconda3\envs\lts\lib\site-packages\pymysql\connections.py", line 548, in query
    self._affected_rows = self._read_query_result(unbuffered=unbuffered)
  File "C:\Users\zhi.zhou\Anaconda3\envs\lts\lib\site-packages\pymysql\connections.py", line 775, in _read_query_result
    result.read()
  File "C:\Users\zhi.zhou\Anaconda3\envs\lts\lib\site-packages\pymysql\connections.py", line 1156, in read
    first_packet = self.connection._read_packet()
  File "C:\Users\zhi.zhou\Anaconda3\envs\lts\lib\site-packages\pymysql\connections.py", line 725, in _read_packet
    packet.raise_for_error()
  File "C:\Users\zhi.zhou\Anaconda3\envs\lts\lib\site-packages\pymysql\protocol.py", line 221, in raise_for_error
    err.raise_mysql_exception(self._data)
  File "C:\Users\zhi.zhou\Anaconda3\envs\lts\lib\site-packages\pymysql\err.py", line 143, in raise_mysql_exception
    raise errorclass(errno, errval)
pymysql.err.ProgrammingError: (1064, "You have an error in your SQL syntax; check the manual that corresponds to your MySQL server version for the right syntax to use near ''Im_ProductPlan_1'' at line 1")

During handling of the above exception, another exception occurred:

Traceback (most recent call last):
  File "C:\Users\zhi.zhou\Anaconda3\envs\lts\lib\site-packages\django\core\handlers\exception.py", line 47, in inner
    response = get_response(request)
  File "C:\Users\zhi.zhou\Anaconda3\envs\lts\lib\site-packages\django\core\handlers\base.py", line 181, in _get_response
    response = wrapped_callback(request, *callback_args, **callback_kwargs)
  File "C:\Users\zhi.zhou\Anaconda3\envs\lts\lib\site-packages\django\views\generic\base.py", line 70, in view
    return self.dispatch(request, *args, **kwargs)
  File "C:\Users\zhi.zhou\Anaconda3\envs\lts\lib\site-packages\django\views\generic\base.py", line 98, in dispatch
    return handler(request, *args, **kwargs)
  File "D:\zhouzhi\gitlit_code\logistic_tracking_system\logistic_tracking_system\lts\views.py", line 5881, in get
    result = json.dumps(result)
  File "C:\Users\zhi.zhou\Anaconda3\envs\lts\lib\json\__init__.py", line 231, in dumps
    return _default_encoder.encode(obj)
  File "C:\Users\zhi.zhou\Anaconda3\envs\lts\lib\json\encoder.py", line 199, in encode
    chunks = self.iterencode(o, _one_shot=True)
  File "C:\Users\zhi.zhou\Anaconda3\envs\lts\lib\json\encoder.py", line 257, in iterencode
    return _iterencode(o, 0)
  File "C:\Users\zhi.zhou\Anaconda3\envs\lts\lib\json\encoder.py", line 180, in default
    o.__class__.__name__)
TypeError: Object of type 'ProgrammingError' is not JSON serializable
[2021-08-24 09:05:28,865][Thread-3:15032][task_id:django.request][log.py:230][ERROR][Internal Server Error: /logistic/LogisticFinishedProductStorage]
Traceback (most recent call last):
  File "D:\zhouzhi\gitlit_code\logistic_tracking_system\logistic_tracking_system\lts\views.py", line 5823, in get
    drs = db.execute_sql(conn, sql)
  File "D:\zhouzhi\gitlit_code\logistic_tracking_system\logistic_tracking_system\common\db.py", line 45, in execute_sql
    cursor.execute(sql)
  File "C:\Users\zhi.zhou\Anaconda3\envs\lts\lib\site-packages\pymysql\cursors.py", line 148, in execute
    result = self._query(query)
  File "C:\Users\zhi.zhou\Anaconda3\envs\lts\lib\site-packages\pymysql\cursors.py", line 310, in _query
    conn.query(q)
  File "C:\Users\zhi.zhou\Anaconda3\envs\lts\lib\site-packages\pymysql\connections.py", line 548, in query
    self._affected_rows = self._read_query_result(unbuffered=unbuffered)
  File "C:\Users\zhi.zhou\Anaconda3\envs\lts\lib\site-packages\pymysql\connections.py", line 775, in _read_query_result
    result.read()
  File "C:\Users\zhi.zhou\Anaconda3\envs\lts\lib\site-packages\pymysql\connections.py", line 1156, in read
    first_packet = self.connection._read_packet()
  File "C:\Users\zhi.zhou\Anaconda3\envs\lts\lib\site-packages\pymysql\connections.py", line 725, in _read_packet
    packet.raise_for_error()
  File "C:\Users\zhi.zhou\Anaconda3\envs\lts\lib\site-packages\pymysql\protocol.py", line 221, in raise_for_error
    err.raise_mysql_exception(self._data)
  File "C:\Users\zhi.zhou\Anaconda3\envs\lts\lib\site-packages\pymysql\err.py", line 143, in raise_mysql_exception
    raise errorclass(errno, errval)
pymysql.err.ProgrammingError: (1064, "You have an error in your SQL syntax; check the manual that corresponds to your MySQL server version for the right syntax to use near ''Im_ProductPlan_1'' at line 1")

During handling of the above exception, another exception occurred:

Traceback (most recent call last):
  File "C:\Users\zhi.zhou\Anaconda3\envs\lts\lib\site-packages\django\core\handlers\exception.py", line 47, in inner
    response = get_response(request)
  File "C:\Users\zhi.zhou\Anaconda3\envs\lts\lib\site-packages\django\core\handlers\base.py", line 181, in _get_response
    response = wrapped_callback(request, *callback_args, **callback_kwargs)
  File "C:\Users\zhi.zhou\Anaconda3\envs\lts\lib\site-packages\django\views\generic\base.py", line 70, in view
    return self.dispatch(request, *args, **kwargs)
  File "C:\Users\zhi.zhou\Anaconda3\envs\lts\lib\site-packages\django\views\generic\base.py", line 98, in dispatch
    return handler(request, *args, **kwargs)
  File "D:\zhouzhi\gitlit_code\logistic_tracking_system\logistic_tracking_system\lts\views.py", line 5881, in get
    result = json.dumps(result)
  File "C:\Users\zhi.zhou\Anaconda3\envs\lts\lib\json\__init__.py", line 231, in dumps
    return _default_encoder.encode(obj)
  File "C:\Users\zhi.zhou\Anaconda3\envs\lts\lib\json\encoder.py", line 199, in encode
    chunks = self.iterencode(o, _one_shot=True)
  File "C:\Users\zhi.zhou\Anaconda3\envs\lts\lib\json\encoder.py", line 257, in iterencode
    return _iterencode(o, 0)
  File "C:\Users\zhi.zhou\Anaconda3\envs\lts\lib\json\encoder.py", line 180, in default
    o.__class__.__name__)
TypeError: Object of type 'ProgrammingError' is not JSON serializable
[2021-08-24 09:06:57,641][Thread-5:13076][task_id:django.request][log.py:230][ERROR][Internal Server Error: /logistic/LogisticFinishedProductStorage]
Traceback (most recent call last):
  File "D:\zhouzhi\gitlit_code\logistic_tracking_system\logistic_tracking_system\lts\views.py", line 5823, in get
    drs = db.execute_sql(conn, sql)
  File "D:\zhouzhi\gitlit_code\logistic_tracking_system\logistic_tracking_system\common\db.py", line 45, in execute_sql
    cursor.execute(sql)
  File "C:\Users\zhi.zhou\Anaconda3\envs\lts\lib\site-packages\pymysql\cursors.py", line 148, in execute
    result = self._query(query)
  File "C:\Users\zhi.zhou\Anaconda3\envs\lts\lib\site-packages\pymysql\cursors.py", line 310, in _query
    conn.query(q)
  File "C:\Users\zhi.zhou\Anaconda3\envs\lts\lib\site-packages\pymysql\connections.py", line 548, in query
    self._affected_rows = self._read_query_result(unbuffered=unbuffered)
  File "C:\Users\zhi.zhou\Anaconda3\envs\lts\lib\site-packages\pymysql\connections.py", line 775, in _read_query_result
    result.read()
  File "C:\Users\zhi.zhou\Anaconda3\envs\lts\lib\site-packages\pymysql\connections.py", line 1156, in read
    first_packet = self.connection._read_packet()
  File "C:\Users\zhi.zhou\Anaconda3\envs\lts\lib\site-packages\pymysql\connections.py", line 725, in _read_packet
    packet.raise_for_error()
  File "C:\Users\zhi.zhou\Anaconda3\envs\lts\lib\site-packages\pymysql\protocol.py", line 221, in raise_for_error
    err.raise_mysql_exception(self._data)
  File "C:\Users\zhi.zhou\Anaconda3\envs\lts\lib\site-packages\pymysql\err.py", line 143, in raise_mysql_exception
    raise errorclass(errno, errval)
pymysql.err.ProgrammingError: (1064, "You have an error in your SQL syntax; check the manual that corresponds to your MySQL server version for the right syntax to use near ''Im_ProductPlan_1'' at line 1")

During handling of the above exception, another exception occurred:

Traceback (most recent call last):
  File "C:\Users\zhi.zhou\Anaconda3\envs\lts\lib\site-packages\django\core\handlers\exception.py", line 47, in inner
    response = get_response(request)
  File "C:\Users\zhi.zhou\Anaconda3\envs\lts\lib\site-packages\django\core\handlers\base.py", line 181, in _get_response
    response = wrapped_callback(request, *callback_args, **callback_kwargs)
  File "C:\Users\zhi.zhou\Anaconda3\envs\lts\lib\site-packages\django\views\generic\base.py", line 70, in view
    return self.dispatch(request, *args, **kwargs)
  File "C:\Users\zhi.zhou\Anaconda3\envs\lts\lib\site-packages\django\views\generic\base.py", line 98, in dispatch
    return handler(request, *args, **kwargs)
  File "D:\zhouzhi\gitlit_code\logistic_tracking_system\logistic_tracking_system\lts\views.py", line 5881, in get
    result = json.dumps(result)
  File "C:\Users\zhi.zhou\Anaconda3\envs\lts\lib\json\__init__.py", line 231, in dumps
    return _default_encoder.encode(obj)
  File "C:\Users\zhi.zhou\Anaconda3\envs\lts\lib\json\encoder.py", line 199, in encode
    chunks = self.iterencode(o, _one_shot=True)
  File "C:\Users\zhi.zhou\Anaconda3\envs\lts\lib\json\encoder.py", line 257, in iterencode
    return _iterencode(o, 0)
  File "C:\Users\zhi.zhou\Anaconda3\envs\lts\lib\json\encoder.py", line 180, in default
    o.__class__.__name__)
TypeError: Object of type 'ProgrammingError' is not JSON serializable
[2021-08-24 09:07:30,680][Thread-7:17948][task_id:django.request][log.py:230][ERROR][Internal Server Error: /logistic/LogisticFinishedProductStorage]
Traceback (most recent call last):
  File "D:\zhouzhi\gitlit_code\logistic_tracking_system\logistic_tracking_system\lts\views.py", line 5823, in get
    drs = db.execute_sql(conn, sql)
  File "D:\zhouzhi\gitlit_code\logistic_tracking_system\logistic_tracking_system\common\db.py", line 45, in execute_sql
    cursor.execute(sql)
  File "C:\Users\zhi.zhou\Anaconda3\envs\lts\lib\site-packages\pymysql\cursors.py", line 148, in execute
    result = self._query(query)
  File "C:\Users\zhi.zhou\Anaconda3\envs\lts\lib\site-packages\pymysql\cursors.py", line 310, in _query
    conn.query(q)
  File "C:\Users\zhi.zhou\Anaconda3\envs\lts\lib\site-packages\pymysql\connections.py", line 548, in query
    self._affected_rows = self._read_query_result(unbuffered=unbuffered)
  File "C:\Users\zhi.zhou\Anaconda3\envs\lts\lib\site-packages\pymysql\connections.py", line 775, in _read_query_result
    result.read()
  File "C:\Users\zhi.zhou\Anaconda3\envs\lts\lib\site-packages\pymysql\connections.py", line 1156, in read
    first_packet = self.connection._read_packet()
  File "C:\Users\zhi.zhou\Anaconda3\envs\lts\lib\site-packages\pymysql\connections.py", line 725, in _read_packet
    packet.raise_for_error()
  File "C:\Users\zhi.zhou\Anaconda3\envs\lts\lib\site-packages\pymysql\protocol.py", line 221, in raise_for_error
    err.raise_mysql_exception(self._data)
  File "C:\Users\zhi.zhou\Anaconda3\envs\lts\lib\site-packages\pymysql\err.py", line 143, in raise_mysql_exception
    raise errorclass(errno, errval)
pymysql.err.ProgrammingError: (1064, "You have an error in your SQL syntax; check the manual that corresponds to your MySQL server version for the right syntax to use near ''Im_ProductPlan_1'' at line 1")

During handling of the above exception, another exception occurred:

Traceback (most recent call last):
  File "C:\Users\zhi.zhou\Anaconda3\envs\lts\lib\site-packages\django\core\handlers\exception.py", line 47, in inner
    response = get_response(request)
  File "C:\Users\zhi.zhou\Anaconda3\envs\lts\lib\site-packages\django\core\handlers\base.py", line 181, in _get_response
    response = wrapped_callback(request, *callback_args, **callback_kwargs)
  File "C:\Users\zhi.zhou\Anaconda3\envs\lts\lib\site-packages\django\views\generic\base.py", line 70, in view
    return self.dispatch(request, *args, **kwargs)
  File "C:\Users\zhi.zhou\Anaconda3\envs\lts\lib\site-packages\django\views\generic\base.py", line 98, in dispatch
    return handler(request, *args, **kwargs)
  File "D:\zhouzhi\gitlit_code\logistic_tracking_system\logistic_tracking_system\lts\views.py", line 5881, in get
    result = json.dumps(result)
  File "C:\Users\zhi.zhou\Anaconda3\envs\lts\lib\json\__init__.py", line 231, in dumps
    return _default_encoder.encode(obj)
  File "C:\Users\zhi.zhou\Anaconda3\envs\lts\lib\json\encoder.py", line 199, in encode
    chunks = self.iterencode(o, _one_shot=True)
  File "C:\Users\zhi.zhou\Anaconda3\envs\lts\lib\json\encoder.py", line 257, in iterencode
    return _iterencode(o, 0)
  File "C:\Users\zhi.zhou\Anaconda3\envs\lts\lib\json\encoder.py", line 180, in default
    o.__class__.__name__)
TypeError: Object of type 'ProgrammingError' is not JSON serializable
[2021-08-24 09:07:38,350][Thread-7:17948][task_id:django.request][log.py:230][ERROR][Internal Server Error: /logistic/LogisticFinishedProductStorage]
Traceback (most recent call last):
  File "D:\zhouzhi\gitlit_code\logistic_tracking_system\logistic_tracking_system\lts\views.py", line 5823, in get
    drs = db.execute_sql(conn, sql)
  File "D:\zhouzhi\gitlit_code\logistic_tracking_system\logistic_tracking_system\common\db.py", line 45, in execute_sql
    cursor.execute(sql)
  File "C:\Users\zhi.zhou\Anaconda3\envs\lts\lib\site-packages\pymysql\cursors.py", line 148, in execute
    result = self._query(query)
  File "C:\Users\zhi.zhou\Anaconda3\envs\lts\lib\site-packages\pymysql\cursors.py", line 310, in _query
    conn.query(q)
  File "C:\Users\zhi.zhou\Anaconda3\envs\lts\lib\site-packages\pymysql\connections.py", line 548, in query
    self._affected_rows = self._read_query_result(unbuffered=unbuffered)
  File "C:\Users\zhi.zhou\Anaconda3\envs\lts\lib\site-packages\pymysql\connections.py", line 775, in _read_query_result
    result.read()
  File "C:\Users\zhi.zhou\Anaconda3\envs\lts\lib\site-packages\pymysql\connections.py", line 1156, in read
    first_packet = self.connection._read_packet()
  File "C:\Users\zhi.zhou\Anaconda3\envs\lts\lib\site-packages\pymysql\connections.py", line 725, in _read_packet
    packet.raise_for_error()
  File "C:\Users\zhi.zhou\Anaconda3\envs\lts\lib\site-packages\pymysql\protocol.py", line 221, in raise_for_error
    err.raise_mysql_exception(self._data)
  File "C:\Users\zhi.zhou\Anaconda3\envs\lts\lib\site-packages\pymysql\err.py", line 143, in raise_mysql_exception
    raise errorclass(errno, errval)
pymysql.err.ProgrammingError: (1064, "You have an error in your SQL syntax; check the manual that corresponds to your MySQL server version for the right syntax to use near ''Im_ProductPlan_2'' at line 1")

During handling of the above exception, another exception occurred:

Traceback (most recent call last):
  File "C:\Users\zhi.zhou\Anaconda3\envs\lts\lib\site-packages\django\core\handlers\exception.py", line 47, in inner
    response = get_response(request)
  File "C:\Users\zhi.zhou\Anaconda3\envs\lts\lib\site-packages\django\core\handlers\base.py", line 181, in _get_response
    response = wrapped_callback(request, *callback_args, **callback_kwargs)
  File "C:\Users\zhi.zhou\Anaconda3\envs\lts\lib\site-packages\django\views\generic\base.py", line 70, in view
    return self.dispatch(request, *args, **kwargs)
  File "C:\Users\zhi.zhou\Anaconda3\envs\lts\lib\site-packages\django\views\generic\base.py", line 98, in dispatch
    return handler(request, *args, **kwargs)
  File "D:\zhouzhi\gitlit_code\logistic_tracking_system\logistic_tracking_system\lts\views.py", line 5881, in get
    result = json.dumps(result)
  File "C:\Users\zhi.zhou\Anaconda3\envs\lts\lib\json\__init__.py", line 231, in dumps
    return _default_encoder.encode(obj)
  File "C:\Users\zhi.zhou\Anaconda3\envs\lts\lib\json\encoder.py", line 199, in encode
    chunks = self.iterencode(o, _one_shot=True)
  File "C:\Users\zhi.zhou\Anaconda3\envs\lts\lib\json\encoder.py", line 257, in iterencode
    return _iterencode(o, 0)
  File "C:\Users\zhi.zhou\Anaconda3\envs\lts\lib\json\encoder.py", line 180, in default
    o.__class__.__name__)
TypeError: Object of type 'ProgrammingError' is not JSON serializable
[2021-08-24 09:14:59,560][Thread-20:2932][task_id:django.request][log.py:230][ERROR][Internal Server Error: /logistic/LogisticFinishedProductStorage]
Traceback (most recent call last):
  File "D:\zhouzhi\gitlit_code\logistic_tracking_system\logistic_tracking_system\lts\views.py", line 5823, in get
    drs = db.execute_sql(conn, sql)
  File "D:\zhouzhi\gitlit_code\logistic_tracking_system\logistic_tracking_system\common\db.py", line 45, in execute_sql
    cursor.execute(sql)
  File "C:\Users\zhi.zhou\Anaconda3\envs\lts\lib\site-packages\pymysql\cursors.py", line 148, in execute
    result = self._query(query)
  File "C:\Users\zhi.zhou\Anaconda3\envs\lts\lib\site-packages\pymysql\cursors.py", line 310, in _query
    conn.query(q)
  File "C:\Users\zhi.zhou\Anaconda3\envs\lts\lib\site-packages\pymysql\connections.py", line 548, in query
    self._affected_rows = self._read_query_result(unbuffered=unbuffered)
  File "C:\Users\zhi.zhou\Anaconda3\envs\lts\lib\site-packages\pymysql\connections.py", line 775, in _read_query_result
    result.read()
  File "C:\Users\zhi.zhou\Anaconda3\envs\lts\lib\site-packages\pymysql\connections.py", line 1156, in read
    first_packet = self.connection._read_packet()
  File "C:\Users\zhi.zhou\Anaconda3\envs\lts\lib\site-packages\pymysql\connections.py", line 725, in _read_packet
    packet.raise_for_error()
  File "C:\Users\zhi.zhou\Anaconda3\envs\lts\lib\site-packages\pymysql\protocol.py", line 221, in raise_for_error
    err.raise_mysql_exception(self._data)
  File "C:\Users\zhi.zhou\Anaconda3\envs\lts\lib\site-packages\pymysql\err.py", line 143, in raise_mysql_exception
    raise errorclass(errno, errval)
pymysql.err.ProgrammingError: (1064, "You have an error in your SQL syntax; check the manual that corresponds to your MySQL server version for the right syntax to use near ''Im_ProductPlan_2'' at line 1")

During handling of the above exception, another exception occurred:

Traceback (most recent call last):
  File "C:\Users\zhi.zhou\Anaconda3\envs\lts\lib\site-packages\django\core\handlers\exception.py", line 47, in inner
    response = get_response(request)
  File "C:\Users\zhi.zhou\Anaconda3\envs\lts\lib\site-packages\django\core\handlers\base.py", line 181, in _get_response
    response = wrapped_callback(request, *callback_args, **callback_kwargs)
  File "C:\Users\zhi.zhou\Anaconda3\envs\lts\lib\site-packages\django\views\generic\base.py", line 70, in view
    return self.dispatch(request, *args, **kwargs)
  File "C:\Users\zhi.zhou\Anaconda3\envs\lts\lib\site-packages\django\views\generic\base.py", line 98, in dispatch
    return handler(request, *args, **kwargs)
  File "D:\zhouzhi\gitlit_code\logistic_tracking_system\logistic_tracking_system\lts\views.py", line 5881, in get
    result = json.dumps(result)
  File "C:\Users\zhi.zhou\Anaconda3\envs\lts\lib\json\__init__.py", line 231, in dumps
    return _default_encoder.encode(obj)
  File "C:\Users\zhi.zhou\Anaconda3\envs\lts\lib\json\encoder.py", line 199, in encode
    chunks = self.iterencode(o, _one_shot=True)
  File "C:\Users\zhi.zhou\Anaconda3\envs\lts\lib\json\encoder.py", line 257, in iterencode
    return _iterencode(o, 0)
  File "C:\Users\zhi.zhou\Anaconda3\envs\lts\lib\json\encoder.py", line 180, in default
    o.__class__.__name__)
TypeError: Object of type 'ProgrammingError' is not JSON serializable
[2021-08-24 09:15:03,184][Thread-17:15152][task_id:django.request][log.py:230][ERROR][Internal Server Error: /logistic/LogisticFinishedProductStorage]
Traceback (most recent call last):
  File "D:\zhouzhi\gitlit_code\logistic_tracking_system\logistic_tracking_system\lts\views.py", line 5823, in get
    drs = db.execute_sql(conn, sql)
  File "D:\zhouzhi\gitlit_code\logistic_tracking_system\logistic_tracking_system\common\db.py", line 45, in execute_sql
    cursor.execute(sql)
  File "C:\Users\zhi.zhou\Anaconda3\envs\lts\lib\site-packages\pymysql\cursors.py", line 148, in execute
    result = self._query(query)
  File "C:\Users\zhi.zhou\Anaconda3\envs\lts\lib\site-packages\pymysql\cursors.py", line 310, in _query
    conn.query(q)
  File "C:\Users\zhi.zhou\Anaconda3\envs\lts\lib\site-packages\pymysql\connections.py", line 548, in query
    self._affected_rows = self._read_query_result(unbuffered=unbuffered)
  File "C:\Users\zhi.zhou\Anaconda3\envs\lts\lib\site-packages\pymysql\connections.py", line 775, in _read_query_result
    result.read()
  File "C:\Users\zhi.zhou\Anaconda3\envs\lts\lib\site-packages\pymysql\connections.py", line 1156, in read
    first_packet = self.connection._read_packet()
  File "C:\Users\zhi.zhou\Anaconda3\envs\lts\lib\site-packages\pymysql\connections.py", line 725, in _read_packet
    packet.raise_for_error()
  File "C:\Users\zhi.zhou\Anaconda3\envs\lts\lib\site-packages\pymysql\protocol.py", line 221, in raise_for_error
    err.raise_mysql_exception(self._data)
  File "C:\Users\zhi.zhou\Anaconda3\envs\lts\lib\site-packages\pymysql\err.py", line 143, in raise_mysql_exception
    raise errorclass(errno, errval)
pymysql.err.ProgrammingError: (1064, "You have an error in your SQL syntax; check the manual that corresponds to your MySQL server version for the right syntax to use near ''Im_ProductPlan_2'' at line 1")

During handling of the above exception, another exception occurred:

Traceback (most recent call last):
  File "C:\Users\zhi.zhou\Anaconda3\envs\lts\lib\site-packages\django\core\handlers\exception.py", line 47, in inner
    response = get_response(request)
  File "C:\Users\zhi.zhou\Anaconda3\envs\lts\lib\site-packages\django\core\handlers\base.py", line 181, in _get_response
    response = wrapped_callback(request, *callback_args, **callback_kwargs)
  File "C:\Users\zhi.zhou\Anaconda3\envs\lts\lib\site-packages\django\views\generic\base.py", line 70, in view
    return self.dispatch(request, *args, **kwargs)
  File "C:\Users\zhi.zhou\Anaconda3\envs\lts\lib\site-packages\django\views\generic\base.py", line 98, in dispatch
    return handler(request, *args, **kwargs)
  File "D:\zhouzhi\gitlit_code\logistic_tracking_system\logistic_tracking_system\lts\views.py", line 5881, in get
    result = json.dumps(result)
  File "C:\Users\zhi.zhou\Anaconda3\envs\lts\lib\json\__init__.py", line 231, in dumps
    return _default_encoder.encode(obj)
  File "C:\Users\zhi.zhou\Anaconda3\envs\lts\lib\json\encoder.py", line 199, in encode
    chunks = self.iterencode(o, _one_shot=True)
  File "C:\Users\zhi.zhou\Anaconda3\envs\lts\lib\json\encoder.py", line 257, in iterencode
    return _iterencode(o, 0)
  File "C:\Users\zhi.zhou\Anaconda3\envs\lts\lib\json\encoder.py", line 180, in default
    o.__class__.__name__)
TypeError: Object of type 'ProgrammingError' is not JSON serializable
[2021-08-24 09:15:19,868][Thread-20:2932][task_id:django.request][log.py:230][ERROR][Internal Server Error: /logistic/LogisticFinishedProductStorage]
Traceback (most recent call last):
  File "D:\zhouzhi\gitlit_code\logistic_tracking_system\logistic_tracking_system\lts\views.py", line 5823, in get
    drs = db.execute_sql(conn, sql)
  File "D:\zhouzhi\gitlit_code\logistic_tracking_system\logistic_tracking_system\common\db.py", line 45, in execute_sql
    cursor.execute(sql)
  File "C:\Users\zhi.zhou\Anaconda3\envs\lts\lib\site-packages\pymysql\cursors.py", line 148, in execute
    result = self._query(query)
  File "C:\Users\zhi.zhou\Anaconda3\envs\lts\lib\site-packages\pymysql\cursors.py", line 310, in _query
    conn.query(q)
  File "C:\Users\zhi.zhou\Anaconda3\envs\lts\lib\site-packages\pymysql\connections.py", line 548, in query
    self._affected_rows = self._read_query_result(unbuffered=unbuffered)
  File "C:\Users\zhi.zhou\Anaconda3\envs\lts\lib\site-packages\pymysql\connections.py", line 775, in _read_query_result
    result.read()
  File "C:\Users\zhi.zhou\Anaconda3\envs\lts\lib\site-packages\pymysql\connections.py", line 1156, in read
    first_packet = self.connection._read_packet()
  File "C:\Users\zhi.zhou\Anaconda3\envs\lts\lib\site-packages\pymysql\connections.py", line 725, in _read_packet
    packet.raise_for_error()
  File "C:\Users\zhi.zhou\Anaconda3\envs\lts\lib\site-packages\pymysql\protocol.py", line 221, in raise_for_error
    err.raise_mysql_exception(self._data)
  File "C:\Users\zhi.zhou\Anaconda3\envs\lts\lib\site-packages\pymysql\err.py", line 143, in raise_mysql_exception
    raise errorclass(errno, errval)
pymysql.err.ProgrammingError: (1064, "You have an error in your SQL syntax; check the manual that corresponds to your MySQL server version for the right syntax to use near ''Im_ProductPlan_2'' at line 1")

During handling of the above exception, another exception occurred:

Traceback (most recent call last):
  File "C:\Users\zhi.zhou\Anaconda3\envs\lts\lib\site-packages\django\core\handlers\exception.py", line 47, in inner
    response = get_response(request)
  File "C:\Users\zhi.zhou\Anaconda3\envs\lts\lib\site-packages\django\core\handlers\base.py", line 181, in _get_response
    response = wrapped_callback(request, *callback_args, **callback_kwargs)
  File "C:\Users\zhi.zhou\Anaconda3\envs\lts\lib\site-packages\django\views\generic\base.py", line 70, in view
    return self.dispatch(request, *args, **kwargs)
  File "C:\Users\zhi.zhou\Anaconda3\envs\lts\lib\site-packages\django\views\generic\base.py", line 98, in dispatch
    return handler(request, *args, **kwargs)
  File "D:\zhouzhi\gitlit_code\logistic_tracking_system\logistic_tracking_system\lts\views.py", line 5881, in get
    result = json.dumps(result)
  File "C:\Users\zhi.zhou\Anaconda3\envs\lts\lib\json\__init__.py", line 231, in dumps
    return _default_encoder.encode(obj)
  File "C:\Users\zhi.zhou\Anaconda3\envs\lts\lib\json\encoder.py", line 199, in encode
    chunks = self.iterencode(o, _one_shot=True)
  File "C:\Users\zhi.zhou\Anaconda3\envs\lts\lib\json\encoder.py", line 257, in iterencode
    return _iterencode(o, 0)
  File "C:\Users\zhi.zhou\Anaconda3\envs\lts\lib\json\encoder.py", line 180, in default
    o.__class__.__name__)
TypeError: Object of type 'ProgrammingError' is not JSON serializable
[2021-08-24 09:15:28,897][Thread-18:17020][task_id:django.request][log.py:230][ERROR][Internal Server Error: /logistic/LogisticFinishedProductStorage]
Traceback (most recent call last):
  File "D:\zhouzhi\gitlit_code\logistic_tracking_system\logistic_tracking_system\lts\views.py", line 5823, in get
    drs = db.execute_sql(conn, sql)
  File "D:\zhouzhi\gitlit_code\logistic_tracking_system\logistic_tracking_system\common\db.py", line 45, in execute_sql
    cursor.execute(sql)
  File "C:\Users\zhi.zhou\Anaconda3\envs\lts\lib\site-packages\pymysql\cursors.py", line 148, in execute
    result = self._query(query)
  File "C:\Users\zhi.zhou\Anaconda3\envs\lts\lib\site-packages\pymysql\cursors.py", line 310, in _query
    conn.query(q)
  File "C:\Users\zhi.zhou\Anaconda3\envs\lts\lib\site-packages\pymysql\connections.py", line 548, in query
    self._affected_rows = self._read_query_result(unbuffered=unbuffered)
  File "C:\Users\zhi.zhou\Anaconda3\envs\lts\lib\site-packages\pymysql\connections.py", line 775, in _read_query_result
    result.read()
  File "C:\Users\zhi.zhou\Anaconda3\envs\lts\lib\site-packages\pymysql\connections.py", line 1156, in read
    first_packet = self.connection._read_packet()
  File "C:\Users\zhi.zhou\Anaconda3\envs\lts\lib\site-packages\pymysql\connections.py", line 725, in _read_packet
    packet.raise_for_error()
  File "C:\Users\zhi.zhou\Anaconda3\envs\lts\lib\site-packages\pymysql\protocol.py", line 221, in raise_for_error
    err.raise_mysql_exception(self._data)
  File "C:\Users\zhi.zhou\Anaconda3\envs\lts\lib\site-packages\pymysql\err.py", line 143, in raise_mysql_exception
    raise errorclass(errno, errval)
pymysql.err.ProgrammingError: (1064, "You have an error in your SQL syntax; check the manual that corresponds to your MySQL server version for the right syntax to use near ''Im_ProductPlan_2'' at line 1")

During handling of the above exception, another exception occurred:

Traceback (most recent call last):
  File "C:\Users\zhi.zhou\Anaconda3\envs\lts\lib\site-packages\django\core\handlers\exception.py", line 47, in inner
    response = get_response(request)
  File "C:\Users\zhi.zhou\Anaconda3\envs\lts\lib\site-packages\django\core\handlers\base.py", line 181, in _get_response
    response = wrapped_callback(request, *callback_args, **callback_kwargs)
  File "C:\Users\zhi.zhou\Anaconda3\envs\lts\lib\site-packages\django\views\generic\base.py", line 70, in view
    return self.dispatch(request, *args, **kwargs)
  File "C:\Users\zhi.zhou\Anaconda3\envs\lts\lib\site-packages\django\views\generic\base.py", line 98, in dispatch
    return handler(request, *args, **kwargs)
  File "D:\zhouzhi\gitlit_code\logistic_tracking_system\logistic_tracking_system\lts\views.py", line 5881, in get
    result = json.dumps(result)
  File "C:\Users\zhi.zhou\Anaconda3\envs\lts\lib\json\__init__.py", line 231, in dumps
    return _default_encoder.encode(obj)
  File "C:\Users\zhi.zhou\Anaconda3\envs\lts\lib\json\encoder.py", line 199, in encode
    chunks = self.iterencode(o, _one_shot=True)
  File "C:\Users\zhi.zhou\Anaconda3\envs\lts\lib\json\encoder.py", line 257, in iterencode
    return _iterencode(o, 0)
  File "C:\Users\zhi.zhou\Anaconda3\envs\lts\lib\json\encoder.py", line 180, in default
    o.__class__.__name__)
TypeError: Object of type 'ProgrammingError' is not JSON serializable
[2021-08-24 09:15:53,610][Thread-20:2932][task_id:django.request][log.py:230][ERROR][Internal Server Error: /logistic/LogisticFinishedProductStorage]
Traceback (most recent call last):
  File "D:\zhouzhi\gitlit_code\logistic_tracking_system\logistic_tracking_system\lts\views.py", line 5823, in get
    drs = db.execute_sql(conn, sql)
  File "D:\zhouzhi\gitlit_code\logistic_tracking_system\logistic_tracking_system\common\db.py", line 45, in execute_sql
    cursor.execute(sql)
  File "C:\Users\zhi.zhou\Anaconda3\envs\lts\lib\site-packages\pymysql\cursors.py", line 148, in execute
    result = self._query(query)
  File "C:\Users\zhi.zhou\Anaconda3\envs\lts\lib\site-packages\pymysql\cursors.py", line 310, in _query
    conn.query(q)
  File "C:\Users\zhi.zhou\Anaconda3\envs\lts\lib\site-packages\pymysql\connections.py", line 548, in query
    self._affected_rows = self._read_query_result(unbuffered=unbuffered)
  File "C:\Users\zhi.zhou\Anaconda3\envs\lts\lib\site-packages\pymysql\connections.py", line 775, in _read_query_result
    result.read()
  File "C:\Users\zhi.zhou\Anaconda3\envs\lts\lib\site-packages\pymysql\connections.py", line 1156, in read
    first_packet = self.connection._read_packet()
  File "C:\Users\zhi.zhou\Anaconda3\envs\lts\lib\site-packages\pymysql\connections.py", line 725, in _read_packet
    packet.raise_for_error()
  File "C:\Users\zhi.zhou\Anaconda3\envs\lts\lib\site-packages\pymysql\protocol.py", line 221, in raise_for_error
    err.raise_mysql_exception(self._data)
  File "C:\Users\zhi.zhou\Anaconda3\envs\lts\lib\site-packages\pymysql\err.py", line 143, in raise_mysql_exception
    raise errorclass(errno, errval)
pymysql.err.ProgrammingError: (1064, "You have an error in your SQL syntax; check the manual that corresponds to your MySQL server version for the right syntax to use near ''Im_ProductPlan_2'' at line 1")

During handling of the above exception, another exception occurred:

Traceback (most recent call last):
  File "C:\Users\zhi.zhou\Anaconda3\envs\lts\lib\site-packages\django\core\handlers\exception.py", line 47, in inner
    response = get_response(request)
  File "C:\Users\zhi.zhou\Anaconda3\envs\lts\lib\site-packages\django\core\handlers\base.py", line 181, in _get_response
    response = wrapped_callback(request, *callback_args, **callback_kwargs)
  File "C:\Users\zhi.zhou\Anaconda3\envs\lts\lib\site-packages\django\views\generic\base.py", line 70, in view
    return self.dispatch(request, *args, **kwargs)
  File "C:\Users\zhi.zhou\Anaconda3\envs\lts\lib\site-packages\django\views\generic\base.py", line 98, in dispatch
    return handler(request, *args, **kwargs)
  File "D:\zhouzhi\gitlit_code\logistic_tracking_system\logistic_tracking_system\lts\views.py", line 5881, in get
    result = json.dumps(result)
  File "C:\Users\zhi.zhou\Anaconda3\envs\lts\lib\json\__init__.py", line 231, in dumps
    return _default_encoder.encode(obj)
  File "C:\Users\zhi.zhou\Anaconda3\envs\lts\lib\json\encoder.py", line 199, in encode
    chunks = self.iterencode(o, _one_shot=True)
  File "C:\Users\zhi.zhou\Anaconda3\envs\lts\lib\json\encoder.py", line 257, in iterencode
    return _iterencode(o, 0)
  File "C:\Users\zhi.zhou\Anaconda3\envs\lts\lib\json\encoder.py", line 180, in default
    o.__class__.__name__)
TypeError: Object of type 'ProgrammingError' is not JSON serializable
[2021-08-24 09:16:02,546][Thread-18:17020][task_id:django.request][log.py:230][ERROR][Internal Server Error: /logistic/LogisticFinishedProductStorage]
Traceback (most recent call last):
  File "D:\zhouzhi\gitlit_code\logistic_tracking_system\logistic_tracking_system\lts\views.py", line 5823, in get
    drs = db.execute_sql(conn, sql)
  File "D:\zhouzhi\gitlit_code\logistic_tracking_system\logistic_tracking_system\common\db.py", line 45, in execute_sql
    cursor.execute(sql)
  File "C:\Users\zhi.zhou\Anaconda3\envs\lts\lib\site-packages\pymysql\cursors.py", line 148, in execute
    result = self._query(query)
  File "C:\Users\zhi.zhou\Anaconda3\envs\lts\lib\site-packages\pymysql\cursors.py", line 310, in _query
    conn.query(q)
  File "C:\Users\zhi.zhou\Anaconda3\envs\lts\lib\site-packages\pymysql\connections.py", line 548, in query
    self._affected_rows = self._read_query_result(unbuffered=unbuffered)
  File "C:\Users\zhi.zhou\Anaconda3\envs\lts\lib\site-packages\pymysql\connections.py", line 775, in _read_query_result
    result.read()
  File "C:\Users\zhi.zhou\Anaconda3\envs\lts\lib\site-packages\pymysql\connections.py", line 1156, in read
    first_packet = self.connection._read_packet()
  File "C:\Users\zhi.zhou\Anaconda3\envs\lts\lib\site-packages\pymysql\connections.py", line 725, in _read_packet
    packet.raise_for_error()
  File "C:\Users\zhi.zhou\Anaconda3\envs\lts\lib\site-packages\pymysql\protocol.py", line 221, in raise_for_error
    err.raise_mysql_exception(self._data)
  File "C:\Users\zhi.zhou\Anaconda3\envs\lts\lib\site-packages\pymysql\err.py", line 143, in raise_mysql_exception
    raise errorclass(errno, errval)
pymysql.err.ProgrammingError: (1064, "You have an error in your SQL syntax; check the manual that corresponds to your MySQL server version for the right syntax to use near ''Im_ProductPlan_2'' at line 1")

During handling of the above exception, another exception occurred:

Traceback (most recent call last):
  File "C:\Users\zhi.zhou\Anaconda3\envs\lts\lib\site-packages\django\core\handlers\exception.py", line 47, in inner
    response = get_response(request)
  File "C:\Users\zhi.zhou\Anaconda3\envs\lts\lib\site-packages\django\core\handlers\base.py", line 181, in _get_response
    response = wrapped_callback(request, *callback_args, **callback_kwargs)
  File "C:\Users\zhi.zhou\Anaconda3\envs\lts\lib\site-packages\django\views\generic\base.py", line 70, in view
    return self.dispatch(request, *args, **kwargs)
  File "C:\Users\zhi.zhou\Anaconda3\envs\lts\lib\site-packages\django\views\generic\base.py", line 98, in dispatch
    return handler(request, *args, **kwargs)
  File "D:\zhouzhi\gitlit_code\logistic_tracking_system\logistic_tracking_system\lts\views.py", line 5881, in get
    result = json.dumps(result)
  File "C:\Users\zhi.zhou\Anaconda3\envs\lts\lib\json\__init__.py", line 231, in dumps
    return _default_encoder.encode(obj)
  File "C:\Users\zhi.zhou\Anaconda3\envs\lts\lib\json\encoder.py", line 199, in encode
    chunks = self.iterencode(o, _one_shot=True)
  File "C:\Users\zhi.zhou\Anaconda3\envs\lts\lib\json\encoder.py", line 257, in iterencode
    return _iterencode(o, 0)
  File "C:\Users\zhi.zhou\Anaconda3\envs\lts\lib\json\encoder.py", line 180, in default
    o.__class__.__name__)
TypeError: Object of type 'ProgrammingError' is not JSON serializable
[2021-08-24 09:16:32,887][Thread-20:2932][task_id:django.request][log.py:230][ERROR][Internal Server Error: /logistic/LogisticFinishedProductStorage]
Traceback (most recent call last):
  File "D:\zhouzhi\gitlit_code\logistic_tracking_system\logistic_tracking_system\lts\views.py", line 5823, in get
    drs = db.execute_sql(conn, sql)
  File "D:\zhouzhi\gitlit_code\logistic_tracking_system\logistic_tracking_system\common\db.py", line 45, in execute_sql
    cursor.execute(sql)
  File "C:\Users\zhi.zhou\Anaconda3\envs\lts\lib\site-packages\pymysql\cursors.py", line 148, in execute
    result = self._query(query)
  File "C:\Users\zhi.zhou\Anaconda3\envs\lts\lib\site-packages\pymysql\cursors.py", line 310, in _query
    conn.query(q)
  File "C:\Users\zhi.zhou\Anaconda3\envs\lts\lib\site-packages\pymysql\connections.py", line 548, in query
    self._affected_rows = self._read_query_result(unbuffered=unbuffered)
  File "C:\Users\zhi.zhou\Anaconda3\envs\lts\lib\site-packages\pymysql\connections.py", line 775, in _read_query_result
    result.read()
  File "C:\Users\zhi.zhou\Anaconda3\envs\lts\lib\site-packages\pymysql\connections.py", line 1156, in read
    first_packet = self.connection._read_packet()
  File "C:\Users\zhi.zhou\Anaconda3\envs\lts\lib\site-packages\pymysql\connections.py", line 725, in _read_packet
    packet.raise_for_error()
  File "C:\Users\zhi.zhou\Anaconda3\envs\lts\lib\site-packages\pymysql\protocol.py", line 221, in raise_for_error
    err.raise_mysql_exception(self._data)
  File "C:\Users\zhi.zhou\Anaconda3\envs\lts\lib\site-packages\pymysql\err.py", line 143, in raise_mysql_exception
    raise errorclass(errno, errval)
pymysql.err.ProgrammingError: (1064, "You have an error in your SQL syntax; check the manual that corresponds to your MySQL server version for the right syntax to use near ''Im_ProductPlan_2'' at line 1")

During handling of the above exception, another exception occurred:

Traceback (most recent call last):
  File "C:\Users\zhi.zhou\Anaconda3\envs\lts\lib\site-packages\django\core\handlers\exception.py", line 47, in inner
    response = get_response(request)
  File "C:\Users\zhi.zhou\Anaconda3\envs\lts\lib\site-packages\django\core\handlers\base.py", line 181, in _get_response
    response = wrapped_callback(request, *callback_args, **callback_kwargs)
  File "C:\Users\zhi.zhou\Anaconda3\envs\lts\lib\site-packages\django\views\generic\base.py", line 70, in view
    return self.dispatch(request, *args, **kwargs)
  File "C:\Users\zhi.zhou\Anaconda3\envs\lts\lib\site-packages\django\views\generic\base.py", line 98, in dispatch
    return handler(request, *args, **kwargs)
  File "D:\zhouzhi\gitlit_code\logistic_tracking_system\logistic_tracking_system\lts\views.py", line 5881, in get
    result = json.dumps(result)
  File "C:\Users\zhi.zhou\Anaconda3\envs\lts\lib\json\__init__.py", line 231, in dumps
    return _default_encoder.encode(obj)
  File "C:\Users\zhi.zhou\Anaconda3\envs\lts\lib\json\encoder.py", line 199, in encode
    chunks = self.iterencode(o, _one_shot=True)
  File "C:\Users\zhi.zhou\Anaconda3\envs\lts\lib\json\encoder.py", line 257, in iterencode
    return _iterencode(o, 0)
  File "C:\Users\zhi.zhou\Anaconda3\envs\lts\lib\json\encoder.py", line 180, in default
    o.__class__.__name__)
TypeError: Object of type 'ProgrammingError' is not JSON serializable
[2021-08-24 09:19:37,307][Thread-24:15276][task_id:django.request][log.py:230][ERROR][Internal Server Error: /logistic/LogisticFinishedProductStorage]
Traceback (most recent call last):
  File "D:\zhouzhi\gitlit_code\logistic_tracking_system\logistic_tracking_system\lts\views.py", line 5823, in get
    drs = db.execute_sql(conn, sql)
  File "D:\zhouzhi\gitlit_code\logistic_tracking_system\logistic_tracking_system\common\db.py", line 45, in execute_sql
    cursor.execute(sql)
  File "C:\Users\zhi.zhou\Anaconda3\envs\lts\lib\site-packages\pymysql\cursors.py", line 148, in execute
    result = self._query(query)
  File "C:\Users\zhi.zhou\Anaconda3\envs\lts\lib\site-packages\pymysql\cursors.py", line 310, in _query
    conn.query(q)
  File "C:\Users\zhi.zhou\Anaconda3\envs\lts\lib\site-packages\pymysql\connections.py", line 548, in query
    self._affected_rows = self._read_query_result(unbuffered=unbuffered)
  File "C:\Users\zhi.zhou\Anaconda3\envs\lts\lib\site-packages\pymysql\connections.py", line 775, in _read_query_result
    result.read()
  File "C:\Users\zhi.zhou\Anaconda3\envs\lts\lib\site-packages\pymysql\connections.py", line 1156, in read
    first_packet = self.connection._read_packet()
  File "C:\Users\zhi.zhou\Anaconda3\envs\lts\lib\site-packages\pymysql\connections.py", line 725, in _read_packet
    packet.raise_for_error()
  File "C:\Users\zhi.zhou\Anaconda3\envs\lts\lib\site-packages\pymysql\protocol.py", line 221, in raise_for_error
    err.raise_mysql_exception(self._data)
  File "C:\Users\zhi.zhou\Anaconda3\envs\lts\lib\site-packages\pymysql\err.py", line 143, in raise_mysql_exception
    raise errorclass(errno, errval)
pymysql.err.ProgrammingError: (1064, "You have an error in your SQL syntax; check the manual that corresponds to your MySQL server version for the right syntax to use near ''Im_ProductPlan_2'' at line 1")

During handling of the above exception, another exception occurred:

Traceback (most recent call last):
  File "C:\Users\zhi.zhou\Anaconda3\envs\lts\lib\site-packages\django\core\handlers\exception.py", line 47, in inner
    response = get_response(request)
  File "C:\Users\zhi.zhou\Anaconda3\envs\lts\lib\site-packages\django\core\handlers\base.py", line 181, in _get_response
    response = wrapped_callback(request, *callback_args, **callback_kwargs)
  File "C:\Users\zhi.zhou\Anaconda3\envs\lts\lib\site-packages\django\views\generic\base.py", line 70, in view
    return self.dispatch(request, *args, **kwargs)
  File "C:\Users\zhi.zhou\Anaconda3\envs\lts\lib\site-packages\django\views\generic\base.py", line 98, in dispatch
    return handler(request, *args, **kwargs)
  File "D:\zhouzhi\gitlit_code\logistic_tracking_system\logistic_tracking_system\lts\views.py", line 5881, in get
    result = json.dumps(result)
  File "C:\Users\zhi.zhou\Anaconda3\envs\lts\lib\json\__init__.py", line 231, in dumps
    return _default_encoder.encode(obj)
  File "C:\Users\zhi.zhou\Anaconda3\envs\lts\lib\json\encoder.py", line 199, in encode
    chunks = self.iterencode(o, _one_shot=True)
  File "C:\Users\zhi.zhou\Anaconda3\envs\lts\lib\json\encoder.py", line 257, in iterencode
    return _iterencode(o, 0)
  File "C:\Users\zhi.zhou\Anaconda3\envs\lts\lib\json\encoder.py", line 180, in default
    o.__class__.__name__)
TypeError: Object of type 'ProgrammingError' is not JSON serializable
[2021-08-24 09:20:16,938][Thread-21:5208][task_id:django.request][log.py:230][ERROR][Internal Server Error: /logistic/LogisticFinishedProductStorage]
Traceback (most recent call last):
  File "D:\zhouzhi\gitlit_code\logistic_tracking_system\logistic_tracking_system\lts\views.py", line 5823, in get
    drs = db.execute_sql(conn, sql)
  File "D:\zhouzhi\gitlit_code\logistic_tracking_system\logistic_tracking_system\common\db.py", line 45, in execute_sql
    cursor.execute(sql)
  File "C:\Users\zhi.zhou\Anaconda3\envs\lts\lib\site-packages\pymysql\cursors.py", line 148, in execute
    result = self._query(query)
  File "C:\Users\zhi.zhou\Anaconda3\envs\lts\lib\site-packages\pymysql\cursors.py", line 310, in _query
    conn.query(q)
  File "C:\Users\zhi.zhou\Anaconda3\envs\lts\lib\site-packages\pymysql\connections.py", line 548, in query
    self._affected_rows = self._read_query_result(unbuffered=unbuffered)
  File "C:\Users\zhi.zhou\Anaconda3\envs\lts\lib\site-packages\pymysql\connections.py", line 775, in _read_query_result
    result.read()
  File "C:\Users\zhi.zhou\Anaconda3\envs\lts\lib\site-packages\pymysql\connections.py", line 1156, in read
    first_packet = self.connection._read_packet()
  File "C:\Users\zhi.zhou\Anaconda3\envs\lts\lib\site-packages\pymysql\connections.py", line 725, in _read_packet
    packet.raise_for_error()
  File "C:\Users\zhi.zhou\Anaconda3\envs\lts\lib\site-packages\pymysql\protocol.py", line 221, in raise_for_error
    err.raise_mysql_exception(self._data)
  File "C:\Users\zhi.zhou\Anaconda3\envs\lts\lib\site-packages\pymysql\err.py", line 143, in raise_mysql_exception
    raise errorclass(errno, errval)
pymysql.err.ProgrammingError: (1064, "You have an error in your SQL syntax; check the manual that corresponds to your MySQL server version for the right syntax to use near ''Im_ProductPlan_2'' at line 1")

During handling of the above exception, another exception occurred:

Traceback (most recent call last):
  File "C:\Users\zhi.zhou\Anaconda3\envs\lts\lib\site-packages\django\core\handlers\exception.py", line 47, in inner
    response = get_response(request)
  File "C:\Users\zhi.zhou\Anaconda3\envs\lts\lib\site-packages\django\core\handlers\base.py", line 181, in _get_response
    response = wrapped_callback(request, *callback_args, **callback_kwargs)
  File "C:\Users\zhi.zhou\Anaconda3\envs\lts\lib\site-packages\django\views\generic\base.py", line 70, in view
    return self.dispatch(request, *args, **kwargs)
  File "C:\Users\zhi.zhou\Anaconda3\envs\lts\lib\site-packages\django\views\generic\base.py", line 98, in dispatch
    return handler(request, *args, **kwargs)
  File "D:\zhouzhi\gitlit_code\logistic_tracking_system\logistic_tracking_system\lts\views.py", line 5881, in get
    result = json.dumps(result)
  File "C:\Users\zhi.zhou\Anaconda3\envs\lts\lib\json\__init__.py", line 231, in dumps
    return _default_encoder.encode(obj)
  File "C:\Users\zhi.zhou\Anaconda3\envs\lts\lib\json\encoder.py", line 199, in encode
    chunks = self.iterencode(o, _one_shot=True)
  File "C:\Users\zhi.zhou\Anaconda3\envs\lts\lib\json\encoder.py", line 257, in iterencode
    return _iterencode(o, 0)
  File "C:\Users\zhi.zhou\Anaconda3\envs\lts\lib\json\encoder.py", line 180, in default
    o.__class__.__name__)
TypeError: Object of type 'ProgrammingError' is not JSON serializable
[2021-08-24 09:20:33,640][Thread-22:2372][task_id:django.request][log.py:230][ERROR][Internal Server Error: /logistic/LogisticFinishedProductStorage]
Traceback (most recent call last):
  File "D:\zhouzhi\gitlit_code\logistic_tracking_system\logistic_tracking_system\lts\views.py", line 5823, in get
    drs = db.execute_sql(conn, sql)
  File "D:\zhouzhi\gitlit_code\logistic_tracking_system\logistic_tracking_system\common\db.py", line 45, in execute_sql
    cursor.execute(sql)
  File "C:\Users\zhi.zhou\Anaconda3\envs\lts\lib\site-packages\pymysql\cursors.py", line 148, in execute
    result = self._query(query)
  File "C:\Users\zhi.zhou\Anaconda3\envs\lts\lib\site-packages\pymysql\cursors.py", line 310, in _query
    conn.query(q)
  File "C:\Users\zhi.zhou\Anaconda3\envs\lts\lib\site-packages\pymysql\connections.py", line 548, in query
    self._affected_rows = self._read_query_result(unbuffered=unbuffered)
  File "C:\Users\zhi.zhou\Anaconda3\envs\lts\lib\site-packages\pymysql\connections.py", line 775, in _read_query_result
    result.read()
  File "C:\Users\zhi.zhou\Anaconda3\envs\lts\lib\site-packages\pymysql\connections.py", line 1156, in read
    first_packet = self.connection._read_packet()
  File "C:\Users\zhi.zhou\Anaconda3\envs\lts\lib\site-packages\pymysql\connections.py", line 725, in _read_packet
    packet.raise_for_error()
  File "C:\Users\zhi.zhou\Anaconda3\envs\lts\lib\site-packages\pymysql\protocol.py", line 221, in raise_for_error
    err.raise_mysql_exception(self._data)
  File "C:\Users\zhi.zhou\Anaconda3\envs\lts\lib\site-packages\pymysql\err.py", line 143, in raise_mysql_exception
    raise errorclass(errno, errval)
pymysql.err.ProgrammingError: (1064, "You have an error in your SQL syntax; check the manual that corresponds to your MySQL server version for the right syntax to use near ''Im_ProductPlan_2'' at line 1")

During handling of the above exception, another exception occurred:

Traceback (most recent call last):
  File "C:\Users\zhi.zhou\Anaconda3\envs\lts\lib\site-packages\django\core\handlers\exception.py", line 47, in inner
    response = get_response(request)
  File "C:\Users\zhi.zhou\Anaconda3\envs\lts\lib\site-packages\django\core\handlers\base.py", line 181, in _get_response
    response = wrapped_callback(request, *callback_args, **callback_kwargs)
  File "C:\Users\zhi.zhou\Anaconda3\envs\lts\lib\site-packages\django\views\generic\base.py", line 70, in view
    return self.dispatch(request, *args, **kwargs)
  File "C:\Users\zhi.zhou\Anaconda3\envs\lts\lib\site-packages\django\views\generic\base.py", line 98, in dispatch
    return handler(request, *args, **kwargs)
  File "D:\zhouzhi\gitlit_code\logistic_tracking_system\logistic_tracking_system\lts\views.py", line 5881, in get
    result = json.dumps(result)
  File "C:\Users\zhi.zhou\Anaconda3\envs\lts\lib\json\__init__.py", line 231, in dumps
    return _default_encoder.encode(obj)
  File "C:\Users\zhi.zhou\Anaconda3\envs\lts\lib\json\encoder.py", line 199, in encode
    chunks = self.iterencode(o, _one_shot=True)
  File "C:\Users\zhi.zhou\Anaconda3\envs\lts\lib\json\encoder.py", line 257, in iterencode
    return _iterencode(o, 0)
  File "C:\Users\zhi.zhou\Anaconda3\envs\lts\lib\json\encoder.py", line 180, in default
    o.__class__.__name__)
TypeError: Object of type 'ProgrammingError' is not JSON serializable
[2021-08-24 09:21:53,271][Thread-32:11220][task_id:django.request][log.py:230][ERROR][Internal Server Error: /logistic/LogisticFinishedProductStorage]
Traceback (most recent call last):
  File "D:\zhouzhi\gitlit_code\logistic_tracking_system\logistic_tracking_system\lts\views.py", line 5823, in get
    drs = db.execute_sql(conn, sql)
  File "D:\zhouzhi\gitlit_code\logistic_tracking_system\logistic_tracking_system\common\db.py", line 45, in execute_sql
    cursor.execute(sql)
  File "C:\Users\zhi.zhou\Anaconda3\envs\lts\lib\site-packages\pymysql\cursors.py", line 148, in execute
    result = self._query(query)
  File "C:\Users\zhi.zhou\Anaconda3\envs\lts\lib\site-packages\pymysql\cursors.py", line 310, in _query
    conn.query(q)
  File "C:\Users\zhi.zhou\Anaconda3\envs\lts\lib\site-packages\pymysql\connections.py", line 548, in query
    self._affected_rows = self._read_query_result(unbuffered=unbuffered)
  File "C:\Users\zhi.zhou\Anaconda3\envs\lts\lib\site-packages\pymysql\connections.py", line 775, in _read_query_result
    result.read()
  File "C:\Users\zhi.zhou\Anaconda3\envs\lts\lib\site-packages\pymysql\connections.py", line 1156, in read
    first_packet = self.connection._read_packet()
  File "C:\Users\zhi.zhou\Anaconda3\envs\lts\lib\site-packages\pymysql\connections.py", line 725, in _read_packet
    packet.raise_for_error()
  File "C:\Users\zhi.zhou\Anaconda3\envs\lts\lib\site-packages\pymysql\protocol.py", line 221, in raise_for_error
    err.raise_mysql_exception(self._data)
  File "C:\Users\zhi.zhou\Anaconda3\envs\lts\lib\site-packages\pymysql\err.py", line 143, in raise_mysql_exception
    raise errorclass(errno, errval)
pymysql.err.ProgrammingError: (1064, "You have an error in your SQL syntax; check the manual that corresponds to your MySQL server version for the right syntax to use near ''Im_ProductPlan_2'' at line 1")

During handling of the above exception, another exception occurred:

Traceback (most recent call last):
  File "C:\Users\zhi.zhou\Anaconda3\envs\lts\lib\site-packages\django\core\handlers\exception.py", line 47, in inner
    response = get_response(request)
  File "C:\Users\zhi.zhou\Anaconda3\envs\lts\lib\site-packages\django\core\handlers\base.py", line 181, in _get_response
    response = wrapped_callback(request, *callback_args, **callback_kwargs)
  File "C:\Users\zhi.zhou\Anaconda3\envs\lts\lib\site-packages\django\views\generic\base.py", line 70, in view
    return self.dispatch(request, *args, **kwargs)
  File "C:\Users\zhi.zhou\Anaconda3\envs\lts\lib\site-packages\django\views\generic\base.py", line 98, in dispatch
    return handler(request, *args, **kwargs)
  File "D:\zhouzhi\gitlit_code\logistic_tracking_system\logistic_tracking_system\lts\views.py", line 5881, in get
    result = json.dumps(result)
  File "C:\Users\zhi.zhou\Anaconda3\envs\lts\lib\json\__init__.py", line 231, in dumps
    return _default_encoder.encode(obj)
  File "C:\Users\zhi.zhou\Anaconda3\envs\lts\lib\json\encoder.py", line 199, in encode
    chunks = self.iterencode(o, _one_shot=True)
  File "C:\Users\zhi.zhou\Anaconda3\envs\lts\lib\json\encoder.py", line 257, in iterencode
    return _iterencode(o, 0)
  File "C:\Users\zhi.zhou\Anaconda3\envs\lts\lib\json\encoder.py", line 180, in default
    o.__class__.__name__)
TypeError: Object of type 'ProgrammingError' is not JSON serializable
[2021-08-24 09:23:04,281][Thread-4:2996][task_id:django.request][log.py:230][ERROR][Internal Server Error: /logistic/LogisticFinishedProductStorage]
Traceback (most recent call last):
  File "D:\zhouzhi\gitlit_code\logistic_tracking_system\logistic_tracking_system\lts\views.py", line 5825, in get
    drs = db.execute_sql(conn, sql)
  File "D:\zhouzhi\gitlit_code\logistic_tracking_system\logistic_tracking_system\common\db.py", line 45, in execute_sql
    cursor.execute(sql)
  File "C:\Users\zhi.zhou\Anaconda3\envs\lts\lib\site-packages\pymysql\cursors.py", line 148, in execute
    result = self._query(query)
  File "C:\Users\zhi.zhou\Anaconda3\envs\lts\lib\site-packages\pymysql\cursors.py", line 310, in _query
    conn.query(q)
  File "C:\Users\zhi.zhou\Anaconda3\envs\lts\lib\site-packages\pymysql\connections.py", line 548, in query
    self._affected_rows = self._read_query_result(unbuffered=unbuffered)
  File "C:\Users\zhi.zhou\Anaconda3\envs\lts\lib\site-packages\pymysql\connections.py", line 775, in _read_query_result
    result.read()
  File "C:\Users\zhi.zhou\Anaconda3\envs\lts\lib\site-packages\pymysql\connections.py", line 1156, in read
    first_packet = self.connection._read_packet()
  File "C:\Users\zhi.zhou\Anaconda3\envs\lts\lib\site-packages\pymysql\connections.py", line 725, in _read_packet
    packet.raise_for_error()
  File "C:\Users\zhi.zhou\Anaconda3\envs\lts\lib\site-packages\pymysql\protocol.py", line 221, in raise_for_error
    err.raise_mysql_exception(self._data)
  File "C:\Users\zhi.zhou\Anaconda3\envs\lts\lib\site-packages\pymysql\err.py", line 143, in raise_mysql_exception
    raise errorclass(errno, errval)
pymysql.err.ProgrammingError: (1064, "You have an error in your SQL syntax; check the manual that corresponds to your MySQL server version for the right syntax to use near ''Im_ProductPlan_2'' at line 1")

During handling of the above exception, another exception occurred:

Traceback (most recent call last):
  File "C:\Users\zhi.zhou\Anaconda3\envs\lts\lib\site-packages\django\core\handlers\exception.py", line 47, in inner
    response = get_response(request)
  File "C:\Users\zhi.zhou\Anaconda3\envs\lts\lib\site-packages\django\core\handlers\base.py", line 181, in _get_response
    response = wrapped_callback(request, *callback_args, **callback_kwargs)
  File "C:\Users\zhi.zhou\Anaconda3\envs\lts\lib\site-packages\django\views\generic\base.py", line 70, in view
    return self.dispatch(request, *args, **kwargs)
  File "C:\Users\zhi.zhou\Anaconda3\envs\lts\lib\site-packages\django\views\generic\base.py", line 98, in dispatch
    return handler(request, *args, **kwargs)
  File "D:\zhouzhi\gitlit_code\logistic_tracking_system\logistic_tracking_system\lts\views.py", line 5883, in get
    result = json.dumps(result)
  File "C:\Users\zhi.zhou\Anaconda3\envs\lts\lib\json\__init__.py", line 231, in dumps
    return _default_encoder.encode(obj)
  File "C:\Users\zhi.zhou\Anaconda3\envs\lts\lib\json\encoder.py", line 199, in encode
    chunks = self.iterencode(o, _one_shot=True)
  File "C:\Users\zhi.zhou\Anaconda3\envs\lts\lib\json\encoder.py", line 257, in iterencode
    return _iterencode(o, 0)
  File "C:\Users\zhi.zhou\Anaconda3\envs\lts\lib\json\encoder.py", line 180, in default
    o.__class__.__name__)
TypeError: Object of type 'ProgrammingError' is not JSON serializable
[2021-08-24 09:32:11,239][Thread-1:1688][task_id:django.request][log.py:230][ERROR][Internal Server Error: /logistic/LogisticBOMProductList]
Traceback (most recent call last):
  File "C:\Users\zhi.zhou\Anaconda3\envs\lts\lib\site-packages\django\core\handlers\exception.py", line 47, in inner
    response = get_response(request)
  File "C:\Users\zhi.zhou\Anaconda3\envs\lts\lib\site-packages\django\core\handlers\base.py", line 188, in _get_response
    self.check_response(response, callback)
  File "C:\Users\zhi.zhou\Anaconda3\envs\lts\lib\site-packages\django\core\handlers\base.py", line 311, in check_response
    "instead." % name
ValueError: The view lts.views.BOMProductList didn't return an HttpResponse object. It returned None instead.
[2021-08-24 09:32:27,359][Thread-1:1688][task_id:django.request][log.py:230][ERROR][Internal Server Error: /logistic/LogisticBOMProductList]
Traceback (most recent call last):
  File "C:\Users\zhi.zhou\Anaconda3\envs\lts\lib\site-packages\django\core\handlers\exception.py", line 47, in inner
    response = get_response(request)
  File "C:\Users\zhi.zhou\Anaconda3\envs\lts\lib\site-packages\django\core\handlers\base.py", line 188, in _get_response
    self.check_response(response, callback)
  File "C:\Users\zhi.zhou\Anaconda3\envs\lts\lib\site-packages\django\core\handlers\base.py", line 311, in check_response
    "instead." % name
ValueError: The view lts.views.BOMProductList didn't return an HttpResponse object. It returned None instead.
[2021-08-24 09:55:35,424][Thread-4:4748][task_id:django.request][log.py:230][ERROR][Internal Server Error: /logistic/LogisticProductTransitInfo]
Traceback (most recent call last):
  File "D:\zhouzhi\gitlit_code\logistic_tracking_system\logistic_tracking_system\lts\views.py", line 4617, in get
    drs = db.execute_sql(conn, sql_main)
  File "D:\zhouzhi\gitlit_code\logistic_tracking_system\logistic_tracking_system\common\db.py", line 45, in execute_sql
    cursor.execute(sql)
  File "C:\Users\zhi.zhou\Anaconda3\envs\lts\lib\site-packages\pymysql\cursors.py", line 148, in execute
    result = self._query(query)
  File "C:\Users\zhi.zhou\Anaconda3\envs\lts\lib\site-packages\pymysql\cursors.py", line 310, in _query
    conn.query(q)
  File "C:\Users\zhi.zhou\Anaconda3\envs\lts\lib\site-packages\pymysql\connections.py", line 548, in query
    self._affected_rows = self._read_query_result(unbuffered=unbuffered)
  File "C:\Users\zhi.zhou\Anaconda3\envs\lts\lib\site-packages\pymysql\connections.py", line 775, in _read_query_result
    result.read()
  File "C:\Users\zhi.zhou\Anaconda3\envs\lts\lib\site-packages\pymysql\connections.py", line 1156, in read
    first_packet = self.connection._read_packet()
  File "C:\Users\zhi.zhou\Anaconda3\envs\lts\lib\site-packages\pymysql\connections.py", line 725, in _read_packet
    packet.raise_for_error()
  File "C:\Users\zhi.zhou\Anaconda3\envs\lts\lib\site-packages\pymysql\protocol.py", line 221, in raise_for_error
    err.raise_mysql_exception(self._data)
  File "C:\Users\zhi.zhou\Anaconda3\envs\lts\lib\site-packages\pymysql\err.py", line 143, in raise_mysql_exception
    raise errorclass(errno, errval)
pymysql.err.ProgrammingError: (1064, "You have an error in your SQL syntax; check the manual that corresponds to your MySQL server version for the right syntax to use near '-05 where 2 > 1     and work_code = 'Im_WorkStation_6'' at line 1")

During handling of the above exception, another exception occurred:

Traceback (most recent call last):
  File "C:\Users\zhi.zhou\Anaconda3\envs\lts\lib\site-packages\django\core\handlers\exception.py", line 47, in inner
    response = get_response(request)
  File "C:\Users\zhi.zhou\Anaconda3\envs\lts\lib\site-packages\django\core\handlers\base.py", line 181, in _get_response
    response = wrapped_callback(request, *callback_args, **callback_kwargs)
  File "C:\Users\zhi.zhou\Anaconda3\envs\lts\lib\site-packages\django\views\generic\base.py", line 70, in view
    return self.dispatch(request, *args, **kwargs)
  File "C:\Users\zhi.zhou\Anaconda3\envs\lts\lib\site-packages\django\views\generic\base.py", line 98, in dispatch
    return handler(request, *args, **kwargs)
  File "D:\zhouzhi\gitlit_code\logistic_tracking_system\logistic_tracking_system\lts\views.py", line 4672, in get
    data = json.dumps(data)
  File "C:\Users\zhi.zhou\Anaconda3\envs\lts\lib\json\__init__.py", line 231, in dumps
    return _default_encoder.encode(obj)
  File "C:\Users\zhi.zhou\Anaconda3\envs\lts\lib\json\encoder.py", line 199, in encode
    chunks = self.iterencode(o, _one_shot=True)
  File "C:\Users\zhi.zhou\Anaconda3\envs\lts\lib\json\encoder.py", line 257, in iterencode
    return _iterencode(o, 0)
  File "C:\Users\zhi.zhou\Anaconda3\envs\lts\lib\json\encoder.py", line 180, in default
    o.__class__.__name__)
TypeError: Object of type 'ProgrammingError' is not JSON serializable
[2021-08-24 10:13:29,522][Thread-1:11568][task_id:lts.views][views.py:207][ERROR][用户名或者密码不正确或者没有管理员的权限]
[2021-08-24 10:13:33,586][Thread-1:11568][task_id:lts.views][views.py:207][ERROR][用户名或者密码不正确或者没有管理员的权限]
[2021-08-24 10:14:37,192][Thread-1:11568][task_id:lts.views][views.py:6818][ERROR][查询物产品信息失败,tuple index out of range]
[2021-08-24 10:14:37,233][Thread-4:3704][task_id:lts.views][views.py:6419][ERROR][查询物料信息失败,(1054, "Unknown column 'a.matter_id' in 'field list'")]
[2021-08-24 10:14:39,032][Thread-1:11568][task_id:lts.views][views.py:6534][ERROR][查询物产品信息失败,tuple index out of range]
[2021-08-24 10:14:39,047][Thread-5:6284][task_id:lts.views][views.py:6615][ERROR][查询物料信息失败,(1054, "Unknown column 'a.matter_id' in 'field list'")]
[2021-08-24 10:14:40,637][Thread-4:3704][task_id:lts.views][views.py:6818][ERROR][查询物产品信息失败,tuple index out of range]
[2021-08-24 10:14:40,719][Thread-1:11568][task_id:lts.views][views.py:6419][ERROR][查询物料信息失败,(1054, "Unknown column 'a.matter_id' in 'field list'")]
[2021-08-24 10:14:46,589][Thread-4:3704][task_id:lts.views][views.py:6818][ERROR][查询物产品信息失败,tuple index out of range]
[2021-08-24 10:14:46,635][Thread-5:6284][task_id:lts.views][views.py:6419][ERROR][查询物料信息失败,(1054, "Unknown column 'a.matter_id' in 'field list'")]
[2021-08-24 10:22:12,423][Thread-22:14704][task_id:django.request][log.py:230][ERROR][Internal Server Error: /logistic/LogisticQualifiedMatterCode]
Traceback (most recent call last):
  File "D:\zhouzhi\gitlit_code\logistic_tracking_system\logistic_tracking_system\lts\views.py", line 5029, in get
    dfs = db.execute_sql(conn, sql_table)
  File "D:\zhouzhi\gitlit_code\logistic_tracking_system\logistic_tracking_system\common\db.py", line 45, in execute_sql
    cursor.execute(sql)
  File "C:\Users\zhi.zhou\Anaconda3\envs\lts\lib\site-packages\pymysql\cursors.py", line 148, in execute
    result = self._query(query)
  File "C:\Users\zhi.zhou\Anaconda3\envs\lts\lib\site-packages\pymysql\cursors.py", line 310, in _query
    conn.query(q)
  File "C:\Users\zhi.zhou\Anaconda3\envs\lts\lib\site-packages\pymysql\connections.py", line 548, in query
    self._affected_rows = self._read_query_result(unbuffered=unbuffered)
  File "C:\Users\zhi.zhou\Anaconda3\envs\lts\lib\site-packages\pymysql\connections.py", line 775, in _read_query_result
    result.read()
  File "C:\Users\zhi.zhou\Anaconda3\envs\lts\lib\site-packages\pymysql\connections.py", line 1156, in read
    first_packet = self.connection._read_packet()
  File "C:\Users\zhi.zhou\Anaconda3\envs\lts\lib\site-packages\pymysql\connections.py", line 725, in _read_packet
    packet.raise_for_error()
  File "C:\Users\zhi.zhou\Anaconda3\envs\lts\lib\site-packages\pymysql\protocol.py", line 221, in raise_for_error
    err.raise_mysql_exception(self._data)
  File "C:\Users\zhi.zhou\Anaconda3\envs\lts\lib\site-packages\pymysql\err.py", line 143, in raise_mysql_exception
    raise errorclass(errno, errval)
pymysql.err.ProgrammingError: (1064, "You have an error in your SQL syntax; check the manual that corresponds to your MySQL server version for the right syntax to use near '-08 where finished_product_code = '123' \n                             group by f' at line 1")

During handling of the above exception, another exception occurred:

Traceback (most recent call last):
  File "C:\Users\zhi.zhou\Anaconda3\envs\lts\lib\site-packages\django\core\handlers\exception.py", line 47, in inner
    response = get_response(request)
  File "C:\Users\zhi.zhou\Anaconda3\envs\lts\lib\site-packages\django\core\handlers\base.py", line 181, in _get_response
    response = wrapped_callback(request, *callback_args, **callback_kwargs)
  File "C:\Users\zhi.zhou\Anaconda3\envs\lts\lib\site-packages\django\views\generic\base.py", line 70, in view
    return self.dispatch(request, *args, **kwargs)
  File "C:\Users\zhi.zhou\Anaconda3\envs\lts\lib\site-packages\django\views\generic\base.py", line 98, in dispatch
    return handler(request, *args, **kwargs)
  File "D:\zhouzhi\gitlit_code\logistic_tracking_system\logistic_tracking_system\lts\views.py", line 5055, in get
    data = json.dumps(data)
  File "C:\Users\zhi.zhou\Anaconda3\envs\lts\lib\json\__init__.py", line 231, in dumps
    return _default_encoder.encode(obj)
  File "C:\Users\zhi.zhou\Anaconda3\envs\lts\lib\json\encoder.py", line 199, in encode
    chunks = self.iterencode(o, _one_shot=True)
  File "C:\Users\zhi.zhou\Anaconda3\envs\lts\lib\json\encoder.py", line 257, in iterencode
    return _iterencode(o, 0)
  File "C:\Users\zhi.zhou\Anaconda3\envs\lts\lib\json\encoder.py", line 180, in default
    o.__class__.__name__)
TypeError: Object of type 'ProgrammingError' is not JSON serializable
[2021-08-24 10:22:17,206][Thread-22:14704][task_id:django.request][log.py:230][ERROR][Internal Server Error: /logistic/LogisticQualifiedMatterCode]
Traceback (most recent call last):
  File "D:\zhouzhi\gitlit_code\logistic_tracking_system\logistic_tracking_system\lts\views.py", line 5029, in get
    dfs = db.execute_sql(conn, sql_table)
  File "D:\zhouzhi\gitlit_code\logistic_tracking_system\logistic_tracking_system\common\db.py", line 45, in execute_sql
    cursor.execute(sql)
  File "C:\Users\zhi.zhou\Anaconda3\envs\lts\lib\site-packages\pymysql\cursors.py", line 148, in execute
    result = self._query(query)
  File "C:\Users\zhi.zhou\Anaconda3\envs\lts\lib\site-packages\pymysql\cursors.py", line 310, in _query
    conn.query(q)
  File "C:\Users\zhi.zhou\Anaconda3\envs\lts\lib\site-packages\pymysql\connections.py", line 548, in query
    self._affected_rows = self._read_query_result(unbuffered=unbuffered)
  File "C:\Users\zhi.zhou\Anaconda3\envs\lts\lib\site-packages\pymysql\connections.py", line 775, in _read_query_result
    result.read()
  File "C:\Users\zhi.zhou\Anaconda3\envs\lts\lib\site-packages\pymysql\connections.py", line 1156, in read
    first_packet = self.connection._read_packet()
  File "C:\Users\zhi.zhou\Anaconda3\envs\lts\lib\site-packages\pymysql\connections.py", line 725, in _read_packet
    packet.raise_for_error()
  File "C:\Users\zhi.zhou\Anaconda3\envs\lts\lib\site-packages\pymysql\protocol.py", line 221, in raise_for_error
    err.raise_mysql_exception(self._data)
  File "C:\Users\zhi.zhou\Anaconda3\envs\lts\lib\site-packages\pymysql\err.py", line 143, in raise_mysql_exception
    raise errorclass(errno, errval)
pymysql.err.ProgrammingError: (1064, "You have an error in your SQL syntax; check the manual that corresponds to your MySQL server version for the right syntax to use near '-08 where finished_product_code = '123123' \n                             group b' at line 1")

During handling of the above exception, another exception occurred:

Traceback (most recent call last):
  File "C:\Users\zhi.zhou\Anaconda3\envs\lts\lib\site-packages\django\core\handlers\exception.py", line 47, in inner
    response = get_response(request)
  File "C:\Users\zhi.zhou\Anaconda3\envs\lts\lib\site-packages\django\core\handlers\base.py", line 181, in _get_response
    response = wrapped_callback(request, *callback_args, **callback_kwargs)
  File "C:\Users\zhi.zhou\Anaconda3\envs\lts\lib\site-packages\django\views\generic\base.py", line 70, in view
    return self.dispatch(request, *args, **kwargs)
  File "C:\Users\zhi.zhou\Anaconda3\envs\lts\lib\site-packages\django\views\generic\base.py", line 98, in dispatch
    return handler(request, *args, **kwargs)
  File "D:\zhouzhi\gitlit_code\logistic_tracking_system\logistic_tracking_system\lts\views.py", line 5055, in get
    data = json.dumps(data)
  File "C:\Users\zhi.zhou\Anaconda3\envs\lts\lib\json\__init__.py", line 231, in dumps
    return _default_encoder.encode(obj)
  File "C:\Users\zhi.zhou\Anaconda3\envs\lts\lib\json\encoder.py", line 199, in encode
    chunks = self.iterencode(o, _one_shot=True)
  File "C:\Users\zhi.zhou\Anaconda3\envs\lts\lib\json\encoder.py", line 257, in iterencode
    return _iterencode(o, 0)
  File "C:\Users\zhi.zhou\Anaconda3\envs\lts\lib\json\encoder.py", line 180, in default
    o.__class__.__name__)
TypeError: Object of type 'ProgrammingError' is not JSON serializable
[2021-08-24 10:37:11,580][Thread-36:9916][task_id:django.request][log.py:230][ERROR][Internal Server Error: /logistic/LogisticProductTransitInfo]
Traceback (most recent call last):
  File "D:\zhouzhi\gitlit_code\logistic_tracking_system\logistic_tracking_system\lts\views.py", line 4337, in get
    drs = db.execute_sql(conn, sql_main)
  File "D:\zhouzhi\gitlit_code\logistic_tracking_system\logistic_tracking_system\common\db.py", line 45, in execute_sql
    cursor.execute(sql)
  File "C:\Users\zhi.zhou\Anaconda3\envs\lts\lib\site-packages\pymysql\cursors.py", line 148, in execute
    result = self._query(query)
  File "C:\Users\zhi.zhou\Anaconda3\envs\lts\lib\site-packages\pymysql\cursors.py", line 310, in _query
    conn.query(q)
  File "C:\Users\zhi.zhou\Anaconda3\envs\lts\lib\site-packages\pymysql\connections.py", line 548, in query
    self._affected_rows = self._read_query_result(unbuffered=unbuffered)
  File "C:\Users\zhi.zhou\Anaconda3\envs\lts\lib\site-packages\pymysql\connections.py", line 775, in _read_query_result
    result.read()
  File "C:\Users\zhi.zhou\Anaconda3\envs\lts\lib\site-packages\pymysql\connections.py", line 1156, in read
    first_packet = self.connection._read_packet()
  File "C:\Users\zhi.zhou\Anaconda3\envs\lts\lib\site-packages\pymysql\connections.py", line 725, in _read_packet
    packet.raise_for_error()
  File "C:\Users\zhi.zhou\Anaconda3\envs\lts\lib\site-packages\pymysql\protocol.py", line 221, in raise_for_error
    err.raise_mysql_exception(self._data)
  File "C:\Users\zhi.zhou\Anaconda3\envs\lts\lib\site-packages\pymysql\err.py", line 143, in raise_mysql_exception
    raise errorclass(errno, errval)
pymysql.err.ProgrammingError: (1064, "You have an error in your SQL syntax; check the manual that corresponds to your MySQL server version for the right syntax to use near '-05 where 2 > 1     and work_code = 'Im_WorkStation_6'' at line 1")

During handling of the above exception, another exception occurred:

Traceback (most recent call last):
  File "C:\Users\zhi.zhou\Anaconda3\envs\lts\lib\site-packages\django\core\handlers\exception.py", line 47, in inner
    response = get_response(request)
  File "C:\Users\zhi.zhou\Anaconda3\envs\lts\lib\site-packages\django\core\handlers\base.py", line 181, in _get_response
    response = wrapped_callback(request, *callback_args, **callback_kwargs)
  File "C:\Users\zhi.zhou\Anaconda3\envs\lts\lib\site-packages\django\views\generic\base.py", line 70, in view
    return self.dispatch(request, *args, **kwargs)
  File "C:\Users\zhi.zhou\Anaconda3\envs\lts\lib\site-packages\django\views\generic\base.py", line 98, in dispatch
    return handler(request, *args, **kwargs)
  File "D:\zhouzhi\gitlit_code\logistic_tracking_system\logistic_tracking_system\lts\views.py", line 4392, in get
    data = json.dumps(data)
  File "C:\Users\zhi.zhou\Anaconda3\envs\lts\lib\json\__init__.py", line 231, in dumps
    return _default_encoder.encode(obj)
  File "C:\Users\zhi.zhou\Anaconda3\envs\lts\lib\json\encoder.py", line 199, in encode
    chunks = self.iterencode(o, _one_shot=True)
  File "C:\Users\zhi.zhou\Anaconda3\envs\lts\lib\json\encoder.py", line 257, in iterencode
    return _iterencode(o, 0)
  File "C:\Users\zhi.zhou\Anaconda3\envs\lts\lib\json\encoder.py", line 180, in default
    o.__class__.__name__)
TypeError: Object of type 'ProgrammingError' is not JSON serializable
[2021-08-24 10:37:15,238][Thread-36:9916][task_id:django.request][log.py:230][ERROR][Internal Server Error: /logistic/LogisticUnqualifiedProduct]
Traceback (most recent call last):
  File "D:\zhouzhi\gitlit_code\logistic_tracking_system\logistic_tracking_system\lts\views.py", line 4821, in get
    drs = db.execute_sql(conn, sql_main)
  File "D:\zhouzhi\gitlit_code\logistic_tracking_system\logistic_tracking_system\common\db.py", line 45, in execute_sql
    cursor.execute(sql)
  File "C:\Users\zhi.zhou\Anaconda3\envs\lts\lib\site-packages\pymysql\cursors.py", line 148, in execute
    result = self._query(query)
  File "C:\Users\zhi.zhou\Anaconda3\envs\lts\lib\site-packages\pymysql\cursors.py", line 310, in _query
    conn.query(q)
  File "C:\Users\zhi.zhou\Anaconda3\envs\lts\lib\site-packages\pymysql\connections.py", line 548, in query
    self._affected_rows = self._read_query_result(unbuffered=unbuffered)
  File "C:\Users\zhi.zhou\Anaconda3\envs\lts\lib\site-packages\pymysql\connections.py", line 775, in _read_query_result
    result.read()
  File "C:\Users\zhi.zhou\Anaconda3\envs\lts\lib\site-packages\pymysql\connections.py", line 1156, in read
    first_packet = self.connection._read_packet()
  File "C:\Users\zhi.zhou\Anaconda3\envs\lts\lib\site-packages\pymysql\connections.py", line 725, in _read_packet
    packet.raise_for_error()
  File "C:\Users\zhi.zhou\Anaconda3\envs\lts\lib\site-packages\pymysql\protocol.py", line 221, in raise_for_error
    err.raise_mysql_exception(self._data)
  File "C:\Users\zhi.zhou\Anaconda3\envs\lts\lib\site-packages\pymysql\err.py", line 143, in raise_mysql_exception
    raise errorclass(errno, errval)
pymysql.err.ProgrammingError: (1064, "You have an error in your SQL syntax; check the manual that corresponds to your MySQL server version for the right syntax to use near '-05 where 2 > 1     group by finished_product_code' at line 1")

During handling of the above exception, another exception occurred:

Traceback (most recent call last):
  File "C:\Users\zhi.zhou\Anaconda3\envs\lts\lib\site-packages\django\core\handlers\exception.py", line 47, in inner
    response = get_response(request)
  File "C:\Users\zhi.zhou\Anaconda3\envs\lts\lib\site-packages\django\core\handlers\base.py", line 181, in _get_response
    response = wrapped_callback(request, *callback_args, **callback_kwargs)
  File "C:\Users\zhi.zhou\Anaconda3\envs\lts\lib\site-packages\django\views\generic\base.py", line 70, in view
    return self.dispatch(request, *args, **kwargs)
  File "C:\Users\zhi.zhou\Anaconda3\envs\lts\lib\site-packages\django\views\generic\base.py", line 98, in dispatch
    return handler(request, *args, **kwargs)
  File "D:\zhouzhi\gitlit_code\logistic_tracking_system\logistic_tracking_system\lts\views.py", line 4865, in get
    data = json.dumps(data)
  File "C:\Users\zhi.zhou\Anaconda3\envs\lts\lib\json\__init__.py", line 231, in dumps
    return _default_encoder.encode(obj)
  File "C:\Users\zhi.zhou\Anaconda3\envs\lts\lib\json\encoder.py", line 199, in encode
    chunks = self.iterencode(o, _one_shot=True)
  File "C:\Users\zhi.zhou\Anaconda3\envs\lts\lib\json\encoder.py", line 257, in iterencode
    return _iterencode(o, 0)
  File "C:\Users\zhi.zhou\Anaconda3\envs\lts\lib\json\encoder.py", line 180, in default
    o.__class__.__name__)
TypeError: Object of type 'ProgrammingError' is not JSON serializable
[2021-08-24 10:37:59,918][Thread-36:9916][task_id:django.request][log.py:230][ERROR][Internal Server Error: /logistic/LogisticProductTransitInfo]
Traceback (most recent call last):
  File "D:\zhouzhi\gitlit_code\logistic_tracking_system\logistic_tracking_system\lts\views.py", line 4499, in post
    producttransit = db.execute_sql(conn, sql_producttransit_main)
  File "D:\zhouzhi\gitlit_code\logistic_tracking_system\logistic_tracking_system\common\db.py", line 45, in execute_sql
    cursor.execute(sql)
  File "C:\Users\zhi.zhou\Anaconda3\envs\lts\lib\site-packages\pymysql\cursors.py", line 148, in execute
    result = self._query(query)
  File "C:\Users\zhi.zhou\Anaconda3\envs\lts\lib\site-packages\pymysql\cursors.py", line 310, in _query
    conn.query(q)
  File "C:\Users\zhi.zhou\Anaconda3\envs\lts\lib\site-packages\pymysql\connections.py", line 548, in query
    self._affected_rows = self._read_query_result(unbuffered=unbuffered)
  File "C:\Users\zhi.zhou\Anaconda3\envs\lts\lib\site-packages\pymysql\connections.py", line 775, in _read_query_result
    result.read()
  File "C:\Users\zhi.zhou\Anaconda3\envs\lts\lib\site-packages\pymysql\connections.py", line 1156, in read
    first_packet = self.connection._read_packet()
  File "C:\Users\zhi.zhou\Anaconda3\envs\lts\lib\site-packages\pymysql\connections.py", line 725, in _read_packet
    packet.raise_for_error()
  File "C:\Users\zhi.zhou\Anaconda3\envs\lts\lib\site-packages\pymysql\protocol.py", line 221, in raise_for_error
    err.raise_mysql_exception(self._data)
  File "C:\Users\zhi.zhou\Anaconda3\envs\lts\lib\site-packages\pymysql\err.py", line 143, in raise_mysql_exception
    raise errorclass(errno, errval)
pymysql.err.ProgrammingError: (1064, "You have an error in your SQL syntax; check the manual that corresponds to your MySQL server version for the right syntax to use near '-05' at line 1")

During handling of the above exception, another exception occurred:

Traceback (most recent call last):
  File "C:\Users\zhi.zhou\Anaconda3\envs\lts\lib\site-packages\django\core\handlers\exception.py", line 47, in inner
    response = get_response(request)
  File "C:\Users\zhi.zhou\Anaconda3\envs\lts\lib\site-packages\django\core\handlers\base.py", line 181, in _get_response
    response = wrapped_callback(request, *callback_args, **callback_kwargs)
  File "C:\Users\zhi.zhou\Anaconda3\envs\lts\lib\site-packages\django\views\generic\base.py", line 70, in view
    return self.dispatch(request, *args, **kwargs)
  File "C:\Users\zhi.zhou\Anaconda3\envs\lts\lib\site-packages\django\views\generic\base.py", line 98, in dispatch
    return handler(request, *args, **kwargs)
  File "D:\zhouzhi\gitlit_code\logistic_tracking_system\logistic_tracking_system\lts\views.py", line 4534, in post
    data = json.dumps(data)
  File "C:\Users\zhi.zhou\Anaconda3\envs\lts\lib\json\__init__.py", line 231, in dumps
    return _default_encoder.encode(obj)
  File "C:\Users\zhi.zhou\Anaconda3\envs\lts\lib\json\encoder.py", line 199, in encode
    chunks = self.iterencode(o, _one_shot=True)
  File "C:\Users\zhi.zhou\Anaconda3\envs\lts\lib\json\encoder.py", line 257, in iterencode
    return _iterencode(o, 0)
  File "C:\Users\zhi.zhou\Anaconda3\envs\lts\lib\json\encoder.py", line 180, in default
    o.__class__.__name__)
TypeError: Object of type 'ProgrammingError' is not JSON serializable
[2021-08-24 10:38:13,765][Thread-36:9916][task_id:django.request][log.py:230][ERROR][Internal Server Error: /logistic/LogisticProductTransitInfo]
Traceback (most recent call last):
  File "D:\zhouzhi\gitlit_code\logistic_tracking_system\logistic_tracking_system\lts\views.py", line 4499, in post
    producttransit = db.execute_sql(conn, sql_producttransit_main)
  File "D:\zhouzhi\gitlit_code\logistic_tracking_system\logistic_tracking_system\common\db.py", line 45, in execute_sql
    cursor.execute(sql)
  File "C:\Users\zhi.zhou\Anaconda3\envs\lts\lib\site-packages\pymysql\cursors.py", line 148, in execute
    result = self._query(query)
  File "C:\Users\zhi.zhou\Anaconda3\envs\lts\lib\site-packages\pymysql\cursors.py", line 310, in _query
    conn.query(q)
  File "C:\Users\zhi.zhou\Anaconda3\envs\lts\lib\site-packages\pymysql\connections.py", line 548, in query
    self._affected_rows = self._read_query_result(unbuffered=unbuffered)
  File "C:\Users\zhi.zhou\Anaconda3\envs\lts\lib\site-packages\pymysql\connections.py", line 775, in _read_query_result
    result.read()
  File "C:\Users\zhi.zhou\Anaconda3\envs\lts\lib\site-packages\pymysql\connections.py", line 1156, in read
    first_packet = self.connection._read_packet()
  File "C:\Users\zhi.zhou\Anaconda3\envs\lts\lib\site-packages\pymysql\connections.py", line 725, in _read_packet
    packet.raise_for_error()
  File "C:\Users\zhi.zhou\Anaconda3\envs\lts\lib\site-packages\pymysql\protocol.py", line 221, in raise_for_error
    err.raise_mysql_exception(self._data)
  File "C:\Users\zhi.zhou\Anaconda3\envs\lts\lib\site-packages\pymysql\err.py", line 143, in raise_mysql_exception
    raise errorclass(errno, errval)
pymysql.err.ProgrammingError: (1064, "You have an error in your SQL syntax; check the manual that corresponds to your MySQL server version for the right syntax to use near '-05' at line 1")

During handling of the above exception, another exception occurred:

Traceback (most recent call last):
  File "C:\Users\zhi.zhou\Anaconda3\envs\lts\lib\site-packages\django\core\handlers\exception.py", line 47, in inner
    response = get_response(request)
  File "C:\Users\zhi.zhou\Anaconda3\envs\lts\lib\site-packages\django\core\handlers\base.py", line 181, in _get_response
    response = wrapped_callback(request, *callback_args, **callback_kwargs)
  File "C:\Users\zhi.zhou\Anaconda3\envs\lts\lib\site-packages\django\views\generic\base.py", line 70, in view
    return self.dispatch(request, *args, **kwargs)
  File "C:\Users\zhi.zhou\Anaconda3\envs\lts\lib\site-packages\django\views\generic\base.py", line 98, in dispatch
    return handler(request, *args, **kwargs)
  File "D:\zhouzhi\gitlit_code\logistic_tracking_system\logistic_tracking_system\lts\views.py", line 4534, in post
    data = json.dumps(data)
  File "C:\Users\zhi.zhou\Anaconda3\envs\lts\lib\json\__init__.py", line 231, in dumps
    return _default_encoder.encode(obj)
  File "C:\Users\zhi.zhou\Anaconda3\envs\lts\lib\json\encoder.py", line 199, in encode
    chunks = self.iterencode(o, _one_shot=True)
  File "C:\Users\zhi.zhou\Anaconda3\envs\lts\lib\json\encoder.py", line 257, in iterencode
    return _iterencode(o, 0)
  File "C:\Users\zhi.zhou\Anaconda3\envs\lts\lib\json\encoder.py", line 180, in default
    o.__class__.__name__)
TypeError: Object of type 'ProgrammingError' is not JSON serializable
[2021-08-24 10:43:05,180][Thread-1:14644][task_id:django.request][log.py:230][ERROR][Internal Server Error: /logistic/LogisticProductTransitInfo]
Traceback (most recent call last):
  File "D:\zhouzhi\gitlit_code\logistic_tracking_system\logistic_tracking_system\lts\views.py", line 4143, in post
    producttransit = db.execute_sql(conn, sql_producttransit_main)
  File "D:\zhouzhi\gitlit_code\logistic_tracking_system\logistic_tracking_system\common\db.py", line 45, in execute_sql
    cursor.execute(sql)
  File "C:\Users\zhi.zhou\Anaconda3\envs\lts\lib\site-packages\pymysql\cursors.py", line 148, in execute
    result = self._query(query)
  File "C:\Users\zhi.zhou\Anaconda3\envs\lts\lib\site-packages\pymysql\cursors.py", line 310, in _query
    conn.query(q)
  File "C:\Users\zhi.zhou\Anaconda3\envs\lts\lib\site-packages\pymysql\connections.py", line 548, in query
    self._affected_rows = self._read_query_result(unbuffered=unbuffered)
  File "C:\Users\zhi.zhou\Anaconda3\envs\lts\lib\site-packages\pymysql\connections.py", line 775, in _read_query_result
    result.read()
  File "C:\Users\zhi.zhou\Anaconda3\envs\lts\lib\site-packages\pymysql\connections.py", line 1156, in read
    first_packet = self.connection._read_packet()
  File "C:\Users\zhi.zhou\Anaconda3\envs\lts\lib\site-packages\pymysql\connections.py", line 725, in _read_packet
    packet.raise_for_error()
  File "C:\Users\zhi.zhou\Anaconda3\envs\lts\lib\site-packages\pymysql\protocol.py", line 221, in raise_for_error
    err.raise_mysql_exception(self._data)
  File "C:\Users\zhi.zhou\Anaconda3\envs\lts\lib\site-packages\pymysql\err.py", line 143, in raise_mysql_exception
    raise errorclass(errno, errval)
pymysql.err.ProgrammingError: (1064, "You have an error in your SQL syntax; check the manual that corresponds to your MySQL server version for the right syntax to use near '-05' at line 1")

During handling of the above exception, another exception occurred:

Traceback (most recent call last):
  File "C:\Users\zhi.zhou\Anaconda3\envs\lts\lib\site-packages\django\core\handlers\exception.py", line 47, in inner
    response = get_response(request)
  File "C:\Users\zhi.zhou\Anaconda3\envs\lts\lib\site-packages\django\core\handlers\base.py", line 181, in _get_response
    response = wrapped_callback(request, *callback_args, **callback_kwargs)
  File "C:\Users\zhi.zhou\Anaconda3\envs\lts\lib\site-packages\django\views\generic\base.py", line 70, in view
    return self.dispatch(request, *args, **kwargs)
  File "C:\Users\zhi.zhou\Anaconda3\envs\lts\lib\site-packages\django\views\generic\base.py", line 98, in dispatch
    return handler(request, *args, **kwargs)
  File "D:\zhouzhi\gitlit_code\logistic_tracking_system\logistic_tracking_system\lts\views.py", line 4178, in post
    data = json.dumps(data)
  File "C:\Users\zhi.zhou\Anaconda3\envs\lts\lib\json\__init__.py", line 231, in dumps
    return _default_encoder.encode(obj)
  File "C:\Users\zhi.zhou\Anaconda3\envs\lts\lib\json\encoder.py", line 199, in encode
    chunks = self.iterencode(o, _one_shot=True)
  File "C:\Users\zhi.zhou\Anaconda3\envs\lts\lib\json\encoder.py", line 257, in iterencode
    return _iterencode(o, 0)
  File "C:\Users\zhi.zhou\Anaconda3\envs\lts\lib\json\encoder.py", line 180, in default
    o.__class__.__name__)
TypeError: Object of type 'ProgrammingError' is not JSON serializable
[2021-08-24 10:57:14,421][Thread-31:4384][task_id:lts.views][views.py:5946][ERROR][修改成品状态失败,(1064, "You have an error in your SQL syntax; check the manual that corresponds to your MySQL server version for the right syntax to use near '-08' at line 1")]
[2021-08-24 10:59:49,035][Thread-33:5008][task_id:django.request][log.py:230][ERROR][Internal Server Error: /logistic/LogisticProductTransitInfo]
Traceback (most recent call last):
  File "D:\zhouzhi\gitlit_code\logistic_tracking_system\logistic_tracking_system\lts\views.py", line 4143, in post
    producttransit = db.execute_sql(conn, sql_producttransit_main)
  File "D:\zhouzhi\gitlit_code\logistic_tracking_system\logistic_tracking_system\common\db.py", line 45, in execute_sql
    cursor.execute(sql)
  File "C:\Users\zhi.zhou\Anaconda3\envs\lts\lib\site-packages\pymysql\cursors.py", line 148, in execute
    result = self._query(query)
  File "C:\Users\zhi.zhou\Anaconda3\envs\lts\lib\site-packages\pymysql\cursors.py", line 310, in _query
    conn.query(q)
  File "C:\Users\zhi.zhou\Anaconda3\envs\lts\lib\site-packages\pymysql\connections.py", line 548, in query
    self._affected_rows = self._read_query_result(unbuffered=unbuffered)
  File "C:\Users\zhi.zhou\Anaconda3\envs\lts\lib\site-packages\pymysql\connections.py", line 775, in _read_query_result
    result.read()
  File "C:\Users\zhi.zhou\Anaconda3\envs\lts\lib\site-packages\pymysql\connections.py", line 1156, in read
    first_packet = self.connection._read_packet()
  File "C:\Users\zhi.zhou\Anaconda3\envs\lts\lib\site-packages\pymysql\connections.py", line 725, in _read_packet
    packet.raise_for_error()
  File "C:\Users\zhi.zhou\Anaconda3\envs\lts\lib\site-packages\pymysql\protocol.py", line 221, in raise_for_error
    err.raise_mysql_exception(self._data)
  File "C:\Users\zhi.zhou\Anaconda3\envs\lts\lib\site-packages\pymysql\err.py", line 143, in raise_mysql_exception
    raise errorclass(errno, errval)
pymysql.err.ProgrammingError: (1064, "You have an error in your SQL syntax; check the manual that corresponds to your MySQL server version for the right syntax to use near '-05' at line 1")

During handling of the above exception, another exception occurred:

Traceback (most recent call last):
  File "C:\Users\zhi.zhou\Anaconda3\envs\lts\lib\site-packages\django\core\handlers\exception.py", line 47, in inner
    response = get_response(request)
  File "C:\Users\zhi.zhou\Anaconda3\envs\lts\lib\site-packages\django\core\handlers\base.py", line 181, in _get_response
    response = wrapped_callback(request, *callback_args, **callback_kwargs)
  File "C:\Users\zhi.zhou\Anaconda3\envs\lts\lib\site-packages\django\views\generic\base.py", line 70, in view
    return self.dispatch(request, *args, **kwargs)
  File "C:\Users\zhi.zhou\Anaconda3\envs\lts\lib\site-packages\django\views\generic\base.py", line 98, in dispatch
    return handler(request, *args, **kwargs)
  File "D:\zhouzhi\gitlit_code\logistic_tracking_system\logistic_tracking_system\lts\views.py", line 4178, in post
    data = json.dumps(data)
  File "C:\Users\zhi.zhou\Anaconda3\envs\lts\lib\json\__init__.py", line 231, in dumps
    return _default_encoder.encode(obj)
  File "C:\Users\zhi.zhou\Anaconda3\envs\lts\lib\json\encoder.py", line 199, in encode
    chunks = self.iterencode(o, _one_shot=True)
  File "C:\Users\zhi.zhou\Anaconda3\envs\lts\lib\json\encoder.py", line 257, in iterencode
    return _iterencode(o, 0)
  File "C:\Users\zhi.zhou\Anaconda3\envs\lts\lib\json\encoder.py", line 180, in default
    o.__class__.__name__)
TypeError: Object of type 'ProgrammingError' is not JSON serializable
[2021-08-24 11:09:05,451][Thread-1:18668][task_id:lts.views][views.py:7637][ERROR][删除失败,(1146, "Table 'co2.package' doesn't exist")]
[2021-08-24 11:13:28,155][Thread-3:18600][task_id:lts.views][views.py:7088][ERROR][项目下的数据库已经存在此表格]
[2021-08-24 11:14:02,779][Thread-4:19448][task_id:django.request][log.py:230][ERROR][Internal Server Error: /logistic/LogisticProductTransitInfo]
Traceback (most recent call last):
  File "D:\zhouzhi\gitlit_code\logistic_tracking_system\logistic_tracking_system\lts\views.py", line 4143, in post
    producttransit = db.execute_sql(conn, sql_producttransit_main)
  File "D:\zhouzhi\gitlit_code\logistic_tracking_system\logistic_tracking_system\common\db.py", line 45, in execute_sql
    cursor.execute(sql)
  File "C:\Users\zhi.zhou\Anaconda3\envs\lts\lib\site-packages\pymysql\cursors.py", line 148, in execute
    result = self._query(query)
  File "C:\Users\zhi.zhou\Anaconda3\envs\lts\lib\site-packages\pymysql\cursors.py", line 310, in _query
    conn.query(q)
  File "C:\Users\zhi.zhou\Anaconda3\envs\lts\lib\site-packages\pymysql\connections.py", line 548, in query
    self._affected_rows = self._read_query_result(unbuffered=unbuffered)
  File "C:\Users\zhi.zhou\Anaconda3\envs\lts\lib\site-packages\pymysql\connections.py", line 775, in _read_query_result
    result.read()
  File "C:\Users\zhi.zhou\Anaconda3\envs\lts\lib\site-packages\pymysql\connections.py", line 1156, in read
    first_packet = self.connection._read_packet()
  File "C:\Users\zhi.zhou\Anaconda3\envs\lts\lib\site-packages\pymysql\connections.py", line 725, in _read_packet
    packet.raise_for_error()
  File "C:\Users\zhi.zhou\Anaconda3\envs\lts\lib\site-packages\pymysql\protocol.py", line 221, in raise_for_error
    err.raise_mysql_exception(self._data)
  File "C:\Users\zhi.zhou\Anaconda3\envs\lts\lib\site-packages\pymysql\err.py", line 143, in raise_mysql_exception
    raise errorclass(errno, errval)
pymysql.err.ProgrammingError: (1064, "You have an error in your SQL syntax; check the manual that corresponds to your MySQL server version for the right syntax to use near '-05' at line 1")

During handling of the above exception, another exception occurred:

Traceback (most recent call last):
  File "C:\Users\zhi.zhou\Anaconda3\envs\lts\lib\site-packages\django\core\handlers\exception.py", line 47, in inner
    response = get_response(request)
  File "C:\Users\zhi.zhou\Anaconda3\envs\lts\lib\site-packages\django\core\handlers\base.py", line 181, in _get_response
    response = wrapped_callback(request, *callback_args, **callback_kwargs)
  File "C:\Users\zhi.zhou\Anaconda3\envs\lts\lib\site-packages\django\views\generic\base.py", line 70, in view
    return self.dispatch(request, *args, **kwargs)
  File "C:\Users\zhi.zhou\Anaconda3\envs\lts\lib\site-packages\django\views\generic\base.py", line 98, in dispatch
    return handler(request, *args, **kwargs)
  File "D:\zhouzhi\gitlit_code\logistic_tracking_system\logistic_tracking_system\lts\views.py", line 4178, in post
    data = json.dumps(data)
  File "C:\Users\zhi.zhou\Anaconda3\envs\lts\lib\json\__init__.py", line 231, in dumps
    return _default_encoder.encode(obj)
  File "C:\Users\zhi.zhou\Anaconda3\envs\lts\lib\json\encoder.py", line 199, in encode
    chunks = self.iterencode(o, _one_shot=True)
  File "C:\Users\zhi.zhou\Anaconda3\envs\lts\lib\json\encoder.py", line 257, in iterencode
    return _iterencode(o, 0)
  File "C:\Users\zhi.zhou\Anaconda3\envs\lts\lib\json\encoder.py", line 180, in default
    o.__class__.__name__)
TypeError: Object of type 'ProgrammingError' is not JSON serializable
[2021-08-24 11:22:13,662][Thread-11:4776][task_id:django.request][log.py:230][ERROR][Internal Server Error: /logistic/LogisticWorkStation]
Traceback (most recent call last):
  File "D:\zhouzhi\gitlit_code\logistic_tracking_system\logistic_tracking_system\lts\views.py", line 1827, in get
    drs = db.execute_sql(conn, sql_main)
  File "D:\zhouzhi\gitlit_code\logistic_tracking_system\logistic_tracking_system\common\db.py", line 45, in execute_sql
    cursor.execute(sql)
  File "C:\Users\zhi.zhou\Anaconda3\envs\lts\lib\site-packages\pymysql\cursors.py", line 148, in execute
    result = self._query(query)
  File "C:\Users\zhi.zhou\Anaconda3\envs\lts\lib\site-packages\pymysql\cursors.py", line 310, in _query
    conn.query(q)
  File "C:\Users\zhi.zhou\Anaconda3\envs\lts\lib\site-packages\pymysql\connections.py", line 548, in query
    self._affected_rows = self._read_query_result(unbuffered=unbuffered)
  File "C:\Users\zhi.zhou\Anaconda3\envs\lts\lib\site-packages\pymysql\connections.py", line 775, in _read_query_result
    result.read()
  File "C:\Users\zhi.zhou\Anaconda3\envs\lts\lib\site-packages\pymysql\connections.py", line 1156, in read
    first_packet = self.connection._read_packet()
  File "C:\Users\zhi.zhou\Anaconda3\envs\lts\lib\site-packages\pymysql\connections.py", line 725, in _read_packet
    packet.raise_for_error()
  File "C:\Users\zhi.zhou\Anaconda3\envs\lts\lib\site-packages\pymysql\protocol.py", line 221, in raise_for_error
    err.raise_mysql_exception(self._data)
  File "C:\Users\zhi.zhou\Anaconda3\envs\lts\lib\site-packages\pymysql\err.py", line 143, in raise_mysql_exception
    raise errorclass(errno, errval)
pymysql.err.OperationalError: (1046, 'No database selected')

During handling of the above exception, another exception occurred:

Traceback (most recent call last):
  File "C:\Users\zhi.zhou\Anaconda3\envs\lts\lib\site-packages\django\core\handlers\exception.py", line 47, in inner
    response = get_response(request)
  File "C:\Users\zhi.zhou\Anaconda3\envs\lts\lib\site-packages\django\core\handlers\base.py", line 181, in _get_response
    response = wrapped_callback(request, *callback_args, **callback_kwargs)
  File "C:\Users\zhi.zhou\Anaconda3\envs\lts\lib\site-packages\django\views\generic\base.py", line 70, in view
    return self.dispatch(request, *args, **kwargs)
  File "C:\Users\zhi.zhou\Anaconda3\envs\lts\lib\site-packages\django\views\generic\base.py", line 98, in dispatch
    return handler(request, *args, **kwargs)
  File "D:\zhouzhi\gitlit_code\logistic_tracking_system\logistic_tracking_system\lts\views.py", line 1862, in get
    result = json.dumps(result)
  File "C:\Users\zhi.zhou\Anaconda3\envs\lts\lib\json\__init__.py", line 231, in dumps
    return _default_encoder.encode(obj)
  File "C:\Users\zhi.zhou\Anaconda3\envs\lts\lib\json\encoder.py", line 199, in encode
    chunks = self.iterencode(o, _one_shot=True)
  File "C:\Users\zhi.zhou\Anaconda3\envs\lts\lib\json\encoder.py", line 257, in iterencode
    return _iterencode(o, 0)
  File "C:\Users\zhi.zhou\Anaconda3\envs\lts\lib\json\encoder.py", line 180, in default
    o.__class__.__name__)
TypeError: Object of type 'OperationalError' is not JSON serializable
[2021-08-24 11:22:32,860][Thread-13:19304][task_id:lts.views][views.py:6462][ERROR][查询物产品信息失败,tuple index out of range]
[2021-08-24 11:22:32,905][Thread-11:4776][task_id:django.request][log.py:230][ERROR][Internal Server Error: /logistic/LogisticWorkCodeName]
Traceback (most recent call last):
  File "D:\zhouzhi\gitlit_code\logistic_tracking_system\logistic_tracking_system\lts\views.py", line 3461, in get
    drs = db.execute_sql(conn, sql)
  File "D:\zhouzhi\gitlit_code\logistic_tracking_system\logistic_tracking_system\common\db.py", line 45, in execute_sql
    cursor.execute(sql)
  File "C:\Users\zhi.zhou\Anaconda3\envs\lts\lib\site-packages\pymysql\cursors.py", line 148, in execute
    result = self._query(query)
  File "C:\Users\zhi.zhou\Anaconda3\envs\lts\lib\site-packages\pymysql\cursors.py", line 310, in _query
    conn.query(q)
  File "C:\Users\zhi.zhou\Anaconda3\envs\lts\lib\site-packages\pymysql\connections.py", line 548, in query
    self._affected_rows = self._read_query_result(unbuffered=unbuffered)
  File "C:\Users\zhi.zhou\Anaconda3\envs\lts\lib\site-packages\pymysql\connections.py", line 775, in _read_query_result
    result.read()
  File "C:\Users\zhi.zhou\Anaconda3\envs\lts\lib\site-packages\pymysql\connections.py", line 1156, in read
    first_packet = self.connection._read_packet()
  File "C:\Users\zhi.zhou\Anaconda3\envs\lts\lib\site-packages\pymysql\connections.py", line 725, in _read_packet
    packet.raise_for_error()
  File "C:\Users\zhi.zhou\Anaconda3\envs\lts\lib\site-packages\pymysql\protocol.py", line 221, in raise_for_error
    err.raise_mysql_exception(self._data)
  File "C:\Users\zhi.zhou\Anaconda3\envs\lts\lib\site-packages\pymysql\err.py", line 143, in raise_mysql_exception
    raise errorclass(errno, errval)
pymysql.err.OperationalError: (1046, 'No database selected')

During handling of the above exception, another exception occurred:

Traceback (most recent call last):
  File "C:\Users\zhi.zhou\Anaconda3\envs\lts\lib\site-packages\django\core\handlers\exception.py", line 47, in inner
    response = get_response(request)
  File "C:\Users\zhi.zhou\Anaconda3\envs\lts\lib\site-packages\django\core\handlers\base.py", line 181, in _get_response
    response = wrapped_callback(request, *callback_args, **callback_kwargs)
  File "C:\Users\zhi.zhou\Anaconda3\envs\lts\lib\site-packages\django\views\generic\base.py", line 70, in view
    return self.dispatch(request, *args, **kwargs)
  File "C:\Users\zhi.zhou\Anaconda3\envs\lts\lib\site-packages\django\views\generic\base.py", line 98, in dispatch
    return handler(request, *args, **kwargs)
  File "D:\zhouzhi\gitlit_code\logistic_tracking_system\logistic_tracking_system\lts\views.py", line 3478, in get
    data = json.dumps(data)
  File "C:\Users\zhi.zhou\Anaconda3\envs\lts\lib\json\__init__.py", line 231, in dumps
    return _default_encoder.encode(obj)
  File "C:\Users\zhi.zhou\Anaconda3\envs\lts\lib\json\encoder.py", line 199, in encode
    chunks = self.iterencode(o, _one_shot=True)
  File "C:\Users\zhi.zhou\Anaconda3\envs\lts\lib\json\encoder.py", line 257, in iterencode
    return _iterencode(o, 0)
  File "C:\Users\zhi.zhou\Anaconda3\envs\lts\lib\json\encoder.py", line 180, in default
    o.__class__.__name__)
TypeError: Object of type 'OperationalError' is not JSON serializable
[2021-08-24 11:22:32,928][Thread-12:18568][task_id:django.request][log.py:230][ERROR][Internal Server Error: /logistic/LogisticPersonCodeName]
Traceback (most recent call last):
  File "D:\zhouzhi\gitlit_code\logistic_tracking_system\logistic_tracking_system\lts\views.py", line 3430, in get
    drs = db.execute_sql(conn, sql)
  File "D:\zhouzhi\gitlit_code\logistic_tracking_system\logistic_tracking_system\common\db.py", line 45, in execute_sql
    cursor.execute(sql)
  File "C:\Users\zhi.zhou\Anaconda3\envs\lts\lib\site-packages\pymysql\cursors.py", line 148, in execute
    result = self._query(query)
  File "C:\Users\zhi.zhou\Anaconda3\envs\lts\lib\site-packages\pymysql\cursors.py", line 310, in _query
    conn.query(q)
  File "C:\Users\zhi.zhou\Anaconda3\envs\lts\lib\site-packages\pymysql\connections.py", line 548, in query
    self._affected_rows = self._read_query_result(unbuffered=unbuffered)
  File "C:\Users\zhi.zhou\Anaconda3\envs\lts\lib\site-packages\pymysql\connections.py", line 775, in _read_query_result
    result.read()
  File "C:\Users\zhi.zhou\Anaconda3\envs\lts\lib\site-packages\pymysql\connections.py", line 1156, in read
    first_packet = self.connection._read_packet()
  File "C:\Users\zhi.zhou\Anaconda3\envs\lts\lib\site-packages\pymysql\connections.py", line 725, in _read_packet
    packet.raise_for_error()
  File "C:\Users\zhi.zhou\Anaconda3\envs\lts\lib\site-packages\pymysql\protocol.py", line 221, in raise_for_error
    err.raise_mysql_exception(self._data)
  File "C:\Users\zhi.zhou\Anaconda3\envs\lts\lib\site-packages\pymysql\err.py", line 143, in raise_mysql_exception
    raise errorclass(errno, errval)
pymysql.err.OperationalError: (1046, 'No database selected')

During handling of the above exception, another exception occurred:

Traceback (most recent call last):
  File "C:\Users\zhi.zhou\Anaconda3\envs\lts\lib\site-packages\django\core\handlers\exception.py", line 47, in inner
    response = get_response(request)
  File "C:\Users\zhi.zhou\Anaconda3\envs\lts\lib\site-packages\django\core\handlers\base.py", line 181, in _get_response
    response = wrapped_callback(request, *callback_args, **callback_kwargs)
  File "C:\Users\zhi.zhou\Anaconda3\envs\lts\lib\site-packages\django\views\generic\base.py", line 70, in view
    return self.dispatch(request, *args, **kwargs)
  File "C:\Users\zhi.zhou\Anaconda3\envs\lts\lib\site-packages\django\views\generic\base.py", line 98, in dispatch
    return handler(request, *args, **kwargs)
  File "D:\zhouzhi\gitlit_code\logistic_tracking_system\logistic_tracking_system\lts\views.py", line 3444, in get
    data = json.dumps(data)
  File "C:\Users\zhi.zhou\Anaconda3\envs\lts\lib\json\__init__.py", line 231, in dumps
    return _default_encoder.encode(obj)
  File "C:\Users\zhi.zhou\Anaconda3\envs\lts\lib\json\encoder.py", line 199, in encode
    chunks = self.iterencode(o, _one_shot=True)
  File "C:\Users\zhi.zhou\Anaconda3\envs\lts\lib\json\encoder.py", line 257, in iterencode
    return _iterencode(o, 0)
  File "C:\Users\zhi.zhou\Anaconda3\envs\lts\lib\json\encoder.py", line 180, in default
    o.__class__.__name__)
TypeError: Object of type 'OperationalError' is not JSON serializable
[2021-08-24 11:24:38,590][Thread-3:12508][task_id:lts.views][views.py:6462][ERROR][查询物产品信息失败,tuple index out of range]
[2021-08-24 11:24:38,830][Thread-2:11540][task_id:django.request][log.py:230][ERROR][Internal Server Error: /logistic/LogisticPersonCodeName]
Traceback (most recent call last):
  File "D:\zhouzhi\gitlit_code\logistic_tracking_system\logistic_tracking_system\lts\views.py", line 3430, in get
    drs = db.execute_sql(conn, sql)
  File "D:\zhouzhi\gitlit_code\logistic_tracking_system\logistic_tracking_system\common\db.py", line 45, in execute_sql
    cursor.execute(sql)
  File "C:\Users\zhi.zhou\Anaconda3\envs\lts\lib\site-packages\pymysql\cursors.py", line 148, in execute
    result = self._query(query)
  File "C:\Users\zhi.zhou\Anaconda3\envs\lts\lib\site-packages\pymysql\cursors.py", line 310, in _query
    conn.query(q)
  File "C:\Users\zhi.zhou\Anaconda3\envs\lts\lib\site-packages\pymysql\connections.py", line 548, in query
    self._affected_rows = self._read_query_result(unbuffered=unbuffered)
  File "C:\Users\zhi.zhou\Anaconda3\envs\lts\lib\site-packages\pymysql\connections.py", line 775, in _read_query_result
    result.read()
  File "C:\Users\zhi.zhou\Anaconda3\envs\lts\lib\site-packages\pymysql\connections.py", line 1156, in read
    first_packet = self.connection._read_packet()
  File "C:\Users\zhi.zhou\Anaconda3\envs\lts\lib\site-packages\pymysql\connections.py", line 725, in _read_packet
    packet.raise_for_error()
  File "C:\Users\zhi.zhou\Anaconda3\envs\lts\lib\site-packages\pymysql\protocol.py", line 221, in raise_for_error
    err.raise_mysql_exception(self._data)
  File "C:\Users\zhi.zhou\Anaconda3\envs\lts\lib\site-packages\pymysql\err.py", line 143, in raise_mysql_exception
    raise errorclass(errno, errval)
pymysql.err.OperationalError: (1046, 'No database selected')

During handling of the above exception, another exception occurred:

Traceback (most recent call last):
  File "C:\Users\zhi.zhou\Anaconda3\envs\lts\lib\site-packages\django\core\handlers\exception.py", line 47, in inner
    response = get_response(request)
  File "C:\Users\zhi.zhou\Anaconda3\envs\lts\lib\site-packages\django\core\handlers\base.py", line 181, in _get_response
    response = wrapped_callback(request, *callback_args, **callback_kwargs)
  File "C:\Users\zhi.zhou\Anaconda3\envs\lts\lib\site-packages\django\views\generic\base.py", line 70, in view
    return self.dispatch(request, *args, **kwargs)
  File "C:\Users\zhi.zhou\Anaconda3\envs\lts\lib\site-packages\django\views\generic\base.py", line 98, in dispatch
    return handler(request, *args, **kwargs)
  File "D:\zhouzhi\gitlit_code\logistic_tracking_system\logistic_tracking_system\lts\views.py", line 3444, in get
    data = json.dumps(data)
  File "C:\Users\zhi.zhou\Anaconda3\envs\lts\lib\json\__init__.py", line 231, in dumps
    return _default_encoder.encode(obj)
  File "C:\Users\zhi.zhou\Anaconda3\envs\lts\lib\json\encoder.py", line 199, in encode
    chunks = self.iterencode(o, _one_shot=True)
  File "C:\Users\zhi.zhou\Anaconda3\envs\lts\lib\json\encoder.py", line 257, in iterencode
    return _iterencode(o, 0)
  File "C:\Users\zhi.zhou\Anaconda3\envs\lts\lib\json\encoder.py", line 180, in default
    o.__class__.__name__)
TypeError: Object of type 'OperationalError' is not JSON serializable
[2021-08-24 11:24:38,854][Thread-1:18860][task_id:django.request][log.py:230][ERROR][Internal Server Error: /logistic/LogisticWorkCodeName]
Traceback (most recent call last):
  File "D:\zhouzhi\gitlit_code\logistic_tracking_system\logistic_tracking_system\lts\views.py", line 3461, in get
    drs = db.execute_sql(conn, sql)
  File "D:\zhouzhi\gitlit_code\logistic_tracking_system\logistic_tracking_system\common\db.py", line 45, in execute_sql
    cursor.execute(sql)
  File "C:\Users\zhi.zhou\Anaconda3\envs\lts\lib\site-packages\pymysql\cursors.py", line 148, in execute
    result = self._query(query)
  File "C:\Users\zhi.zhou\Anaconda3\envs\lts\lib\site-packages\pymysql\cursors.py", line 310, in _query
    conn.query(q)
  File "C:\Users\zhi.zhou\Anaconda3\envs\lts\lib\site-packages\pymysql\connections.py", line 548, in query
    self._affected_rows = self._read_query_result(unbuffered=unbuffered)
  File "C:\Users\zhi.zhou\Anaconda3\envs\lts\lib\site-packages\pymysql\connections.py", line 775, in _read_query_result
    result.read()
  File "C:\Users\zhi.zhou\Anaconda3\envs\lts\lib\site-packages\pymysql\connections.py", line 1156, in read
    first_packet = self.connection._read_packet()
  File "C:\Users\zhi.zhou\Anaconda3\envs\lts\lib\site-packages\pymysql\connections.py", line 725, in _read_packet
    packet.raise_for_error()
  File "C:\Users\zhi.zhou\Anaconda3\envs\lts\lib\site-packages\pymysql\protocol.py", line 221, in raise_for_error
    err.raise_mysql_exception(self._data)
  File "C:\Users\zhi.zhou\Anaconda3\envs\lts\lib\site-packages\pymysql\err.py", line 143, in raise_mysql_exception
    raise errorclass(errno, errval)
pymysql.err.OperationalError: (1046, 'No database selected')

During handling of the above exception, another exception occurred:

Traceback (most recent call last):
  File "C:\Users\zhi.zhou\Anaconda3\envs\lts\lib\site-packages\django\core\handlers\exception.py", line 47, in inner
    response = get_response(request)
  File "C:\Users\zhi.zhou\Anaconda3\envs\lts\lib\site-packages\django\core\handlers\base.py", line 181, in _get_response
    response = wrapped_callback(request, *callback_args, **callback_kwargs)
  File "C:\Users\zhi.zhou\Anaconda3\envs\lts\lib\site-packages\django\views\generic\base.py", line 70, in view
    return self.dispatch(request, *args, **kwargs)
  File "C:\Users\zhi.zhou\Anaconda3\envs\lts\lib\site-packages\django\views\generic\base.py", line 98, in dispatch
    return handler(request, *args, **kwargs)
  File "D:\zhouzhi\gitlit_code\logistic_tracking_system\logistic_tracking_system\lts\views.py", line 3478, in get
    data = json.dumps(data)
  File "C:\Users\zhi.zhou\Anaconda3\envs\lts\lib\json\__init__.py", line 231, in dumps
    return _default_encoder.encode(obj)
  File "C:\Users\zhi.zhou\Anaconda3\envs\lts\lib\json\encoder.py", line 199, in encode
    chunks = self.iterencode(o, _one_shot=True)
  File "C:\Users\zhi.zhou\Anaconda3\envs\lts\lib\json\encoder.py", line 257, in iterencode
    return _iterencode(o, 0)
  File "C:\Users\zhi.zhou\Anaconda3\envs\lts\lib\json\encoder.py", line 180, in default
    o.__class__.__name__)
TypeError: Object of type 'OperationalError' is not JSON serializable
[2021-08-24 11:25:07,783][Thread-4:7284][task_id:django.request][log.py:230][ERROR][Internal Server Error: /logistic/LogisticWorkStation]
Traceback (most recent call last):
  File "D:\zhouzhi\gitlit_code\logistic_tracking_system\logistic_tracking_system\lts\views.py", line 1827, in get
    drs = db.execute_sql(conn, sql_main)
  File "D:\zhouzhi\gitlit_code\logistic_tracking_system\logistic_tracking_system\common\db.py", line 45, in execute_sql
    cursor.execute(sql)
  File "C:\Users\zhi.zhou\Anaconda3\envs\lts\lib\site-packages\pymysql\cursors.py", line 148, in execute
    result = self._query(query)
  File "C:\Users\zhi.zhou\Anaconda3\envs\lts\lib\site-packages\pymysql\cursors.py", line 310, in _query
    conn.query(q)
  File "C:\Users\zhi.zhou\Anaconda3\envs\lts\lib\site-packages\pymysql\connections.py", line 548, in query
    self._affected_rows = self._read_query_result(unbuffered=unbuffered)
  File "C:\Users\zhi.zhou\Anaconda3\envs\lts\lib\site-packages\pymysql\connections.py", line 775, in _read_query_result
    result.read()
  File "C:\Users\zhi.zhou\Anaconda3\envs\lts\lib\site-packages\pymysql\connections.py", line 1156, in read
    first_packet = self.connection._read_packet()
  File "C:\Users\zhi.zhou\Anaconda3\envs\lts\lib\site-packages\pymysql\connections.py", line 725, in _read_packet
    packet.raise_for_error()
  File "C:\Users\zhi.zhou\Anaconda3\envs\lts\lib\site-packages\pymysql\protocol.py", line 221, in raise_for_error
    err.raise_mysql_exception(self._data)
  File "C:\Users\zhi.zhou\Anaconda3\envs\lts\lib\site-packages\pymysql\err.py", line 143, in raise_mysql_exception
    raise errorclass(errno, errval)
pymysql.err.OperationalError: (1046, 'No database selected')

During handling of the above exception, another exception occurred:

Traceback (most recent call last):
  File "C:\Users\zhi.zhou\Anaconda3\envs\lts\lib\site-packages\django\core\handlers\exception.py", line 47, in inner
    response = get_response(request)
  File "C:\Users\zhi.zhou\Anaconda3\envs\lts\lib\site-packages\django\core\handlers\base.py", line 181, in _get_response
    response = wrapped_callback(request, *callback_args, **callback_kwargs)
  File "C:\Users\zhi.zhou\Anaconda3\envs\lts\lib\site-packages\django\views\generic\base.py", line 70, in view
    return self.dispatch(request, *args, **kwargs)
  File "C:\Users\zhi.zhou\Anaconda3\envs\lts\lib\site-packages\django\views\generic\base.py", line 98, in dispatch
    return handler(request, *args, **kwargs)
  File "D:\zhouzhi\gitlit_code\logistic_tracking_system\logistic_tracking_system\lts\views.py", line 1862, in get
    result = json.dumps(result)
  File "C:\Users\zhi.zhou\Anaconda3\envs\lts\lib\json\__init__.py", line 231, in dumps
    return _default_encoder.encode(obj)
  File "C:\Users\zhi.zhou\Anaconda3\envs\lts\lib\json\encoder.py", line 199, in encode
    chunks = self.iterencode(o, _one_shot=True)
  File "C:\Users\zhi.zhou\Anaconda3\envs\lts\lib\json\encoder.py", line 257, in iterencode
    return _iterencode(o, 0)
  File "C:\Users\zhi.zhou\Anaconda3\envs\lts\lib\json\encoder.py", line 180, in default
    o.__class__.__name__)
TypeError: Object of type 'OperationalError' is not JSON serializable
[2021-08-24 11:25:32,615][Thread-4:7284][task_id:django.request][log.py:230][ERROR][Internal Server Error: /logistic/LogisticWorkCodeName]
Traceback (most recent call last):
  File "D:\zhouzhi\gitlit_code\logistic_tracking_system\logistic_tracking_system\lts\views.py", line 3461, in get
    drs = db.execute_sql(conn, sql)
  File "D:\zhouzhi\gitlit_code\logistic_tracking_system\logistic_tracking_system\common\db.py", line 45, in execute_sql
    cursor.execute(sql)
  File "C:\Users\zhi.zhou\Anaconda3\envs\lts\lib\site-packages\pymysql\cursors.py", line 148, in execute
    result = self._query(query)
  File "C:\Users\zhi.zhou\Anaconda3\envs\lts\lib\site-packages\pymysql\cursors.py", line 310, in _query
    conn.query(q)
  File "C:\Users\zhi.zhou\Anaconda3\envs\lts\lib\site-packages\pymysql\connections.py", line 548, in query
    self._affected_rows = self._read_query_result(unbuffered=unbuffered)
  File "C:\Users\zhi.zhou\Anaconda3\envs\lts\lib\site-packages\pymysql\connections.py", line 775, in _read_query_result
    result.read()
  File "C:\Users\zhi.zhou\Anaconda3\envs\lts\lib\site-packages\pymysql\connections.py", line 1156, in read
    first_packet = self.connection._read_packet()
  File "C:\Users\zhi.zhou\Anaconda3\envs\lts\lib\site-packages\pymysql\connections.py", line 725, in _read_packet
    packet.raise_for_error()
  File "C:\Users\zhi.zhou\Anaconda3\envs\lts\lib\site-packages\pymysql\protocol.py", line 221, in raise_for_error
    err.raise_mysql_exception(self._data)
  File "C:\Users\zhi.zhou\Anaconda3\envs\lts\lib\site-packages\pymysql\err.py", line 143, in raise_mysql_exception
    raise errorclass(errno, errval)
pymysql.err.OperationalError: (1046, 'No database selected')

During handling of the above exception, another exception occurred:

Traceback (most recent call last):
  File "C:\Users\zhi.zhou\Anaconda3\envs\lts\lib\site-packages\django\core\handlers\exception.py", line 47, in inner
    response = get_response(request)
  File "C:\Users\zhi.zhou\Anaconda3\envs\lts\lib\site-packages\django\core\handlers\base.py", line 181, in _get_response
    response = wrapped_callback(request, *callback_args, **callback_kwargs)
  File "C:\Users\zhi.zhou\Anaconda3\envs\lts\lib\site-packages\django\views\generic\base.py", line 70, in view
    return self.dispatch(request, *args, **kwargs)
  File "C:\Users\zhi.zhou\Anaconda3\envs\lts\lib\site-packages\django\views\generic\base.py", line 98, in dispatch
    return handler(request, *args, **kwargs)
  File "D:\zhouzhi\gitlit_code\logistic_tracking_system\logistic_tracking_system\lts\views.py", line 3478, in get
    data = json.dumps(data)
  File "C:\Users\zhi.zhou\Anaconda3\envs\lts\lib\json\__init__.py", line 231, in dumps
    return _default_encoder.encode(obj)
  File "C:\Users\zhi.zhou\Anaconda3\envs\lts\lib\json\encoder.py", line 199, in encode
    chunks = self.iterencode(o, _one_shot=True)
  File "C:\Users\zhi.zhou\Anaconda3\envs\lts\lib\json\encoder.py", line 257, in iterencode
    return _iterencode(o, 0)
  File "C:\Users\zhi.zhou\Anaconda3\envs\lts\lib\json\encoder.py", line 180, in default
    o.__class__.__name__)
TypeError: Object of type 'OperationalError' is not JSON serializable
[2021-08-24 11:25:32,620][Thread-6:14424][task_id:lts.views][views.py:6462][ERROR][查询物产品信息失败,tuple index out of range]
[2021-08-24 11:25:32,656][Thread-5:18512][task_id:django.request][log.py:230][ERROR][Internal Server Error: /logistic/LogisticPersonCodeName]
Traceback (most recent call last):
  File "D:\zhouzhi\gitlit_code\logistic_tracking_system\logistic_tracking_system\lts\views.py", line 3430, in get
    drs = db.execute_sql(conn, sql)
  File "D:\zhouzhi\gitlit_code\logistic_tracking_system\logistic_tracking_system\common\db.py", line 45, in execute_sql
    cursor.execute(sql)
  File "C:\Users\zhi.zhou\Anaconda3\envs\lts\lib\site-packages\pymysql\cursors.py", line 148, in execute
    result = self._query(query)
  File "C:\Users\zhi.zhou\Anaconda3\envs\lts\lib\site-packages\pymysql\cursors.py", line 310, in _query
    conn.query(q)
  File "C:\Users\zhi.zhou\Anaconda3\envs\lts\lib\site-packages\pymysql\connections.py", line 548, in query
    self._affected_rows = self._read_query_result(unbuffered=unbuffered)
  File "C:\Users\zhi.zhou\Anaconda3\envs\lts\lib\site-packages\pymysql\connections.py", line 775, in _read_query_result
    result.read()
  File "C:\Users\zhi.zhou\Anaconda3\envs\lts\lib\site-packages\pymysql\connections.py", line 1156, in read
    first_packet = self.connection._read_packet()
  File "C:\Users\zhi.zhou\Anaconda3\envs\lts\lib\site-packages\pymysql\connections.py", line 725, in _read_packet
    packet.raise_for_error()
  File "C:\Users\zhi.zhou\Anaconda3\envs\lts\lib\site-packages\pymysql\protocol.py", line 221, in raise_for_error
    err.raise_mysql_exception(self._data)
  File "C:\Users\zhi.zhou\Anaconda3\envs\lts\lib\site-packages\pymysql\err.py", line 143, in raise_mysql_exception
    raise errorclass(errno, errval)
pymysql.err.OperationalError: (1046, 'No database selected')

During handling of the above exception, another exception occurred:

Traceback (most recent call last):
  File "C:\Users\zhi.zhou\Anaconda3\envs\lts\lib\site-packages\django\core\handlers\exception.py", line 47, in inner
    response = get_response(request)
  File "C:\Users\zhi.zhou\Anaconda3\envs\lts\lib\site-packages\django\core\handlers\base.py", line 181, in _get_response
    response = wrapped_callback(request, *callback_args, **callback_kwargs)
  File "C:\Users\zhi.zhou\Anaconda3\envs\lts\lib\site-packages\django\views\generic\base.py", line 70, in view
    return self.dispatch(request, *args, **kwargs)
  File "C:\Users\zhi.zhou\Anaconda3\envs\lts\lib\site-packages\django\views\generic\base.py", line 98, in dispatch
    return handler(request, *args, **kwargs)
  File "D:\zhouzhi\gitlit_code\logistic_tracking_system\logistic_tracking_system\lts\views.py", line 3444, in get
    data = json.dumps(data)
  File "C:\Users\zhi.zhou\Anaconda3\envs\lts\lib\json\__init__.py", line 231, in dumps
    return _default_encoder.encode(obj)
  File "C:\Users\zhi.zhou\Anaconda3\envs\lts\lib\json\encoder.py", line 199, in encode
    chunks = self.iterencode(o, _one_shot=True)
  File "C:\Users\zhi.zhou\Anaconda3\envs\lts\lib\json\encoder.py", line 257, in iterencode
    return _iterencode(o, 0)
  File "C:\Users\zhi.zhou\Anaconda3\envs\lts\lib\json\encoder.py", line 180, in default
    o.__class__.__name__)
TypeError: Object of type 'OperationalError' is not JSON serializable
[2021-08-24 13:28:41,680][Thread-2:18908][task_id:root][views.py:129][ERROR][用户没有进入此工站的权限]
[2021-08-24 13:38:58,447][Thread-10:18664][task_id:django.request][log.py:230][ERROR][Internal Server Error: /logistic/LogisticProductTransitInfo]
Traceback (most recent call last):
  File "D:\zhouzhi\gitlit_code\logistic_tracking_system\logistic_tracking_system\lts\views.py", line 4086, in post
    db.execute_sql(conn, sql_create_unqualified)
  File "D:\zhouzhi\gitlit_code\logistic_tracking_system\logistic_tracking_system\common\db.py", line 45, in execute_sql
    cursor.execute(sql)
  File "C:\Users\zhi.zhou\Anaconda3\envs\lts\lib\site-packages\pymysql\cursors.py", line 148, in execute
    result = self._query(query)
  File "C:\Users\zhi.zhou\Anaconda3\envs\lts\lib\site-packages\pymysql\cursors.py", line 310, in _query
    conn.query(q)
  File "C:\Users\zhi.zhou\Anaconda3\envs\lts\lib\site-packages\pymysql\connections.py", line 548, in query
    self._affected_rows = self._read_query_result(unbuffered=unbuffered)
  File "C:\Users\zhi.zhou\Anaconda3\envs\lts\lib\site-packages\pymysql\connections.py", line 775, in _read_query_result
    result.read()
  File "C:\Users\zhi.zhou\Anaconda3\envs\lts\lib\site-packages\pymysql\connections.py", line 1156, in read
    first_packet = self.connection._read_packet()
  File "C:\Users\zhi.zhou\Anaconda3\envs\lts\lib\site-packages\pymysql\connections.py", line 725, in _read_packet
    packet.raise_for_error()
  File "C:\Users\zhi.zhou\Anaconda3\envs\lts\lib\site-packages\pymysql\protocol.py", line 221, in raise_for_error
    err.raise_mysql_exception(self._data)
  File "C:\Users\zhi.zhou\Anaconda3\envs\lts\lib\site-packages\pymysql\err.py", line 143, in raise_mysql_exception
    raise errorclass(errno, errval)
pymysql.err.OperationalError: (1050, "Table 'unqualified_product_station_05' already exists")

During handling of the above exception, another exception occurred:

Traceback (most recent call last):
  File "C:\Users\zhi.zhou\Anaconda3\envs\lts\lib\site-packages\django\core\handlers\exception.py", line 47, in inner
    response = get_response(request)
  File "C:\Users\zhi.zhou\Anaconda3\envs\lts\lib\site-packages\django\core\handlers\base.py", line 181, in _get_response
    response = wrapped_callback(request, *callback_args, **callback_kwargs)
  File "C:\Users\zhi.zhou\Anaconda3\envs\lts\lib\site-packages\django\views\generic\base.py", line 70, in view
    return self.dispatch(request, *args, **kwargs)
  File "C:\Users\zhi.zhou\Anaconda3\envs\lts\lib\site-packages\django\views\generic\base.py", line 98, in dispatch
    return handler(request, *args, **kwargs)
  File "D:\zhouzhi\gitlit_code\logistic_tracking_system\logistic_tracking_system\lts\views.py", line 4165, in post
    data = json.dumps(data)
  File "C:\Users\zhi.zhou\Anaconda3\envs\lts\lib\json\__init__.py", line 231, in dumps
    return _default_encoder.encode(obj)
  File "C:\Users\zhi.zhou\Anaconda3\envs\lts\lib\json\encoder.py", line 199, in encode
    chunks = self.iterencode(o, _one_shot=True)
  File "C:\Users\zhi.zhou\Anaconda3\envs\lts\lib\json\encoder.py", line 257, in iterencode
    return _iterencode(o, 0)
  File "C:\Users\zhi.zhou\Anaconda3\envs\lts\lib\json\encoder.py", line 180, in default
    o.__class__.__name__)
TypeError: Object of type 'OperationalError' is not JSON serializable
[2021-08-24 13:38:59,698][Thread-10:18664][task_id:django.request][log.py:230][ERROR][Internal Server Error: /logistic/LogisticProductTransitInfo]
Traceback (most recent call last):
  File "D:\zhouzhi\gitlit_code\logistic_tracking_system\logistic_tracking_system\lts\views.py", line 4086, in post
    db.execute_sql(conn, sql_create_unqualified)
  File "D:\zhouzhi\gitlit_code\logistic_tracking_system\logistic_tracking_system\common\db.py", line 45, in execute_sql
    cursor.execute(sql)
  File "C:\Users\zhi.zhou\Anaconda3\envs\lts\lib\site-packages\pymysql\cursors.py", line 148, in execute
    result = self._query(query)
  File "C:\Users\zhi.zhou\Anaconda3\envs\lts\lib\site-packages\pymysql\cursors.py", line 310, in _query
    conn.query(q)
  File "C:\Users\zhi.zhou\Anaconda3\envs\lts\lib\site-packages\pymysql\connections.py", line 548, in query
    self._affected_rows = self._read_query_result(unbuffered=unbuffered)
  File "C:\Users\zhi.zhou\Anaconda3\envs\lts\lib\site-packages\pymysql\connections.py", line 775, in _read_query_result
    result.read()
  File "C:\Users\zhi.zhou\Anaconda3\envs\lts\lib\site-packages\pymysql\connections.py", line 1156, in read
    first_packet = self.connection._read_packet()
  File "C:\Users\zhi.zhou\Anaconda3\envs\lts\lib\site-packages\pymysql\connections.py", line 725, in _read_packet
    packet.raise_for_error()
  File "C:\Users\zhi.zhou\Anaconda3\envs\lts\lib\site-packages\pymysql\protocol.py", line 221, in raise_for_error
    err.raise_mysql_exception(self._data)
  File "C:\Users\zhi.zhou\Anaconda3\envs\lts\lib\site-packages\pymysql\err.py", line 143, in raise_mysql_exception
    raise errorclass(errno, errval)
pymysql.err.OperationalError: (1050, "Table 'unqualified_product_station_05' already exists")

During handling of the above exception, another exception occurred:

Traceback (most recent call last):
  File "C:\Users\zhi.zhou\Anaconda3\envs\lts\lib\site-packages\django\core\handlers\exception.py", line 47, in inner
    response = get_response(request)
  File "C:\Users\zhi.zhou\Anaconda3\envs\lts\lib\site-packages\django\core\handlers\base.py", line 181, in _get_response
    response = wrapped_callback(request, *callback_args, **callback_kwargs)
  File "C:\Users\zhi.zhou\Anaconda3\envs\lts\lib\site-packages\django\views\generic\base.py", line 70, in view
    return self.dispatch(request, *args, **kwargs)
  File "C:\Users\zhi.zhou\Anaconda3\envs\lts\lib\site-packages\django\views\generic\base.py", line 98, in dispatch
    return handler(request, *args, **kwargs)
  File "D:\zhouzhi\gitlit_code\logistic_tracking_system\logistic_tracking_system\lts\views.py", line 4165, in post
    data = json.dumps(data)
  File "C:\Users\zhi.zhou\Anaconda3\envs\lts\lib\json\__init__.py", line 231, in dumps
    return _default_encoder.encode(obj)
  File "C:\Users\zhi.zhou\Anaconda3\envs\lts\lib\json\encoder.py", line 199, in encode
    chunks = self.iterencode(o, _one_shot=True)
  File "C:\Users\zhi.zhou\Anaconda3\envs\lts\lib\json\encoder.py", line 257, in iterencode
    return _iterencode(o, 0)
  File "C:\Users\zhi.zhou\Anaconda3\envs\lts\lib\json\encoder.py", line 180, in default
    o.__class__.__name__)
TypeError: Object of type 'OperationalError' is not JSON serializable
[2021-08-24 13:39:58,735][Thread-1:4104][task_id:django.request][log.py:230][ERROR][Internal Server Error: /logistic/LogisticProductTransitInfo]
Traceback (most recent call last):
  File "D:\zhouzhi\gitlit_code\logistic_tracking_system\logistic_tracking_system\lts\views.py", line 4102, in post
    matter_num = matter_num + 1
TypeError: unsupported operand type(s) for +: 'NoneType' and 'int'

During handling of the above exception, another exception occurred:

Traceback (most recent call last):
  File "C:\Users\zhi.zhou\Anaconda3\envs\lts\lib\site-packages\django\core\handlers\exception.py", line 47, in inner
    response = get_response(request)
  File "C:\Users\zhi.zhou\Anaconda3\envs\lts\lib\site-packages\django\core\handlers\base.py", line 181, in _get_response
    response = wrapped_callback(request, *callback_args, **callback_kwargs)
  File "C:\Users\zhi.zhou\Anaconda3\envs\lts\lib\site-packages\django\views\generic\base.py", line 70, in view
    return self.dispatch(request, *args, **kwargs)
  File "C:\Users\zhi.zhou\Anaconda3\envs\lts\lib\site-packages\django\views\generic\base.py", line 98, in dispatch
    return handler(request, *args, **kwargs)
  File "D:\zhouzhi\gitlit_code\logistic_tracking_system\logistic_tracking_system\lts\views.py", line 4165, in post
    data = json.dumps(data)
  File "C:\Users\zhi.zhou\Anaconda3\envs\lts\lib\json\__init__.py", line 231, in dumps
    return _default_encoder.encode(obj)
  File "C:\Users\zhi.zhou\Anaconda3\envs\lts\lib\json\encoder.py", line 199, in encode
    chunks = self.iterencode(o, _one_shot=True)
  File "C:\Users\zhi.zhou\Anaconda3\envs\lts\lib\json\encoder.py", line 257, in iterencode
    return _iterencode(o, 0)
  File "C:\Users\zhi.zhou\Anaconda3\envs\lts\lib\json\encoder.py", line 180, in default
    o.__class__.__name__)
TypeError: Object of type 'TypeError' is not JSON serializable
[2021-08-24 13:40:48,467][Thread-1:7284][task_id:django.request][log.py:230][ERROR][Internal Server Error: /logistic/LogisticProductTransitInfo]
Traceback (most recent call last):
  File "D:\zhouzhi\gitlit_code\logistic_tracking_system\logistic_tracking_system\lts\views.py", line 4104, in post
    matter_num = matter_num + 1
TypeError: unsupported operand type(s) for +: 'NoneType' and 'int'

During handling of the above exception, another exception occurred:

Traceback (most recent call last):
  File "C:\Users\zhi.zhou\Anaconda3\envs\lts\lib\site-packages\django\core\handlers\exception.py", line 47, in inner
    response = get_response(request)
  File "C:\Users\zhi.zhou\Anaconda3\envs\lts\lib\site-packages\django\core\handlers\base.py", line 181, in _get_response
    response = wrapped_callback(request, *callback_args, **callback_kwargs)
  File "C:\Users\zhi.zhou\Anaconda3\envs\lts\lib\site-packages\django\views\generic\base.py", line 70, in view
    return self.dispatch(request, *args, **kwargs)
  File "C:\Users\zhi.zhou\Anaconda3\envs\lts\lib\site-packages\django\views\generic\base.py", line 98, in dispatch
    return handler(request, *args, **kwargs)
  File "D:\zhouzhi\gitlit_code\logistic_tracking_system\logistic_tracking_system\lts\views.py", line 4167, in post
    data = json.dumps(data)
  File "C:\Users\zhi.zhou\Anaconda3\envs\lts\lib\json\__init__.py", line 231, in dumps
    return _default_encoder.encode(obj)
  File "C:\Users\zhi.zhou\Anaconda3\envs\lts\lib\json\encoder.py", line 199, in encode
    chunks = self.iterencode(o, _one_shot=True)
  File "C:\Users\zhi.zhou\Anaconda3\envs\lts\lib\json\encoder.py", line 257, in iterencode
    return _iterencode(o, 0)
  File "C:\Users\zhi.zhou\Anaconda3\envs\lts\lib\json\encoder.py", line 180, in default
    o.__class__.__name__)
TypeError: Object of type 'TypeError' is not JSON serializable
[2021-08-24 13:42:19,082][Thread-11:5052][task_id:django.request][log.py:230][ERROR][Internal Server Error: /logistic/LogisticPutProductPlanDeal]
Traceback (most recent call last):
  File "D:\zhouzhi\gitlit_code\logistic_tracking_system\logistic_tracking_system\lts\views.py", line 2262, in get
    drs = db.execute_sql(conn, sql_main)
  File "D:\zhouzhi\gitlit_code\logistic_tracking_system\logistic_tracking_system\common\db.py", line 45, in execute_sql
    cursor.execute(sql)
  File "C:\Users\zhi.zhou\Anaconda3\envs\lts\lib\site-packages\pymysql\cursors.py", line 148, in execute
    result = self._query(query)
  File "C:\Users\zhi.zhou\Anaconda3\envs\lts\lib\site-packages\pymysql\cursors.py", line 310, in _query
    conn.query(q)
  File "C:\Users\zhi.zhou\Anaconda3\envs\lts\lib\site-packages\pymysql\connections.py", line 548, in query
    self._affected_rows = self._read_query_result(unbuffered=unbuffered)
  File "C:\Users\zhi.zhou\Anaconda3\envs\lts\lib\site-packages\pymysql\connections.py", line 775, in _read_query_result
    result.read()
  File "C:\Users\zhi.zhou\Anaconda3\envs\lts\lib\site-packages\pymysql\connections.py", line 1156, in read
    first_packet = self.connection._read_packet()
  File "C:\Users\zhi.zhou\Anaconda3\envs\lts\lib\site-packages\pymysql\connections.py", line 725, in _read_packet
    packet.raise_for_error()
  File "C:\Users\zhi.zhou\Anaconda3\envs\lts\lib\site-packages\pymysql\protocol.py", line 221, in raise_for_error
    err.raise_mysql_exception(self._data)
  File "C:\Users\zhi.zhou\Anaconda3\envs\lts\lib\site-packages\pymysql\err.py", line 143, in raise_mysql_exception
    raise errorclass(errno, errval)
pymysql.err.DataError: (1366, "Incorrect integer value: '第一生产计划' for column 'plan_count' at row 1")

During handling of the above exception, another exception occurred:

Traceback (most recent call last):
  File "C:\Users\zhi.zhou\Anaconda3\envs\lts\lib\site-packages\django\core\handlers\exception.py", line 47, in inner
    response = get_response(request)
  File "C:\Users\zhi.zhou\Anaconda3\envs\lts\lib\site-packages\django\core\handlers\base.py", line 181, in _get_response
    response = wrapped_callback(request, *callback_args, **callback_kwargs)
  File "C:\Users\zhi.zhou\Anaconda3\envs\lts\lib\site-packages\django\views\generic\base.py", line 70, in view
    return self.dispatch(request, *args, **kwargs)
  File "C:\Users\zhi.zhou\Anaconda3\envs\lts\lib\site-packages\django\views\generic\base.py", line 98, in dispatch
    return handler(request, *args, **kwargs)
  File "D:\zhouzhi\gitlit_code\logistic_tracking_system\logistic_tracking_system\lts\views.py", line 2287, in get
    data = json.dumps(data)
  File "C:\Users\zhi.zhou\Anaconda3\envs\lts\lib\json\__init__.py", line 231, in dumps
    return _default_encoder.encode(obj)
  File "C:\Users\zhi.zhou\Anaconda3\envs\lts\lib\json\encoder.py", line 199, in encode
    chunks = self.iterencode(o, _one_shot=True)
  File "C:\Users\zhi.zhou\Anaconda3\envs\lts\lib\json\encoder.py", line 257, in iterencode
    return _iterencode(o, 0)
  File "C:\Users\zhi.zhou\Anaconda3\envs\lts\lib\json\encoder.py", line 180, in default
    o.__class__.__name__)
TypeError: Object of type 'DataError' is not JSON serializable
[2021-08-24 13:43:11,192][Thread-11:5052][task_id:django.request][log.py:230][ERROR][Internal Server Error: /logistic/LogisticPutProductPlanDeal]
Traceback (most recent call last):
  File "D:\zhouzhi\gitlit_code\logistic_tracking_system\logistic_tracking_system\lts\views.py", line 2262, in get
    drs = db.execute_sql(conn, sql_main)
  File "D:\zhouzhi\gitlit_code\logistic_tracking_system\logistic_tracking_system\common\db.py", line 45, in execute_sql
    cursor.execute(sql)
  File "C:\Users\zhi.zhou\Anaconda3\envs\lts\lib\site-packages\pymysql\cursors.py", line 148, in execute
    result = self._query(query)
  File "C:\Users\zhi.zhou\Anaconda3\envs\lts\lib\site-packages\pymysql\cursors.py", line 310, in _query
    conn.query(q)
  File "C:\Users\zhi.zhou\Anaconda3\envs\lts\lib\site-packages\pymysql\connections.py", line 548, in query
    self._affected_rows = self._read_query_result(unbuffered=unbuffered)
  File "C:\Users\zhi.zhou\Anaconda3\envs\lts\lib\site-packages\pymysql\connections.py", line 775, in _read_query_result
    result.read()
  File "C:\Users\zhi.zhou\Anaconda3\envs\lts\lib\site-packages\pymysql\connections.py", line 1156, in read
    first_packet = self.connection._read_packet()
  File "C:\Users\zhi.zhou\Anaconda3\envs\lts\lib\site-packages\pymysql\connections.py", line 725, in _read_packet
    packet.raise_for_error()
  File "C:\Users\zhi.zhou\Anaconda3\envs\lts\lib\site-packages\pymysql\protocol.py", line 221, in raise_for_error
    err.raise_mysql_exception(self._data)
  File "C:\Users\zhi.zhou\Anaconda3\envs\lts\lib\site-packages\pymysql\err.py", line 143, in raise_mysql_exception
    raise errorclass(errno, errval)
pymysql.err.OperationalError: (1205, 'Lock wait timeout exceeded; try restarting transaction')

During handling of the above exception, another exception occurred:

Traceback (most recent call last):
  File "C:\Users\zhi.zhou\Anaconda3\envs\lts\lib\site-packages\django\core\handlers\exception.py", line 47, in inner
    response = get_response(request)
  File "C:\Users\zhi.zhou\Anaconda3\envs\lts\lib\site-packages\django\core\handlers\base.py", line 181, in _get_response
    response = wrapped_callback(request, *callback_args, **callback_kwargs)
  File "C:\Users\zhi.zhou\Anaconda3\envs\lts\lib\site-packages\django\views\generic\base.py", line 70, in view
    return self.dispatch(request, *args, **kwargs)
  File "C:\Users\zhi.zhou\Anaconda3\envs\lts\lib\site-packages\django\views\generic\base.py", line 98, in dispatch
    return handler(request, *args, **kwargs)
  File "D:\zhouzhi\gitlit_code\logistic_tracking_system\logistic_tracking_system\lts\views.py", line 2287, in get
    data = json.dumps(data)
  File "C:\Users\zhi.zhou\Anaconda3\envs\lts\lib\json\__init__.py", line 231, in dumps
    return _default_encoder.encode(obj)
  File "C:\Users\zhi.zhou\Anaconda3\envs\lts\lib\json\encoder.py", line 199, in encode
    chunks = self.iterencode(o, _one_shot=True)
  File "C:\Users\zhi.zhou\Anaconda3\envs\lts\lib\json\encoder.py", line 257, in iterencode
    return _iterencode(o, 0)
  File "C:\Users\zhi.zhou\Anaconda3\envs\lts\lib\json\encoder.py", line 180, in default
    o.__class__.__name__)
TypeError: Object of type 'OperationalError' is not JSON serializable
[2021-08-24 13:43:19,250][Thread-12:17476][task_id:django.request][log.py:230][ERROR][Internal Server Error: /logistic/LogisticPutProductPlanDeal]
Traceback (most recent call last):
  File "D:\zhouzhi\gitlit_code\logistic_tracking_system\logistic_tracking_system\lts\views.py", line 2262, in get
    drs = db.execute_sql(conn, sql_main)
  File "D:\zhouzhi\gitlit_code\logistic_tracking_system\logistic_tracking_system\common\db.py", line 45, in execute_sql
    cursor.execute(sql)
  File "C:\Users\zhi.zhou\Anaconda3\envs\lts\lib\site-packages\pymysql\cursors.py", line 148, in execute
    result = self._query(query)
  File "C:\Users\zhi.zhou\Anaconda3\envs\lts\lib\site-packages\pymysql\cursors.py", line 310, in _query
    conn.query(q)
  File "C:\Users\zhi.zhou\Anaconda3\envs\lts\lib\site-packages\pymysql\connections.py", line 548, in query
    self._affected_rows = self._read_query_result(unbuffered=unbuffered)
  File "C:\Users\zhi.zhou\Anaconda3\envs\lts\lib\site-packages\pymysql\connections.py", line 775, in _read_query_result
    result.read()
  File "C:\Users\zhi.zhou\Anaconda3\envs\lts\lib\site-packages\pymysql\connections.py", line 1156, in read
    first_packet = self.connection._read_packet()
  File "C:\Users\zhi.zhou\Anaconda3\envs\lts\lib\site-packages\pymysql\connections.py", line 725, in _read_packet
    packet.raise_for_error()
  File "C:\Users\zhi.zhou\Anaconda3\envs\lts\lib\site-packages\pymysql\protocol.py", line 221, in raise_for_error
    err.raise_mysql_exception(self._data)
  File "C:\Users\zhi.zhou\Anaconda3\envs\lts\lib\site-packages\pymysql\err.py", line 143, in raise_mysql_exception
    raise errorclass(errno, errval)
pymysql.err.OperationalError: (1205, 'Lock wait timeout exceeded; try restarting transaction')

During handling of the above exception, another exception occurred:

Traceback (most recent call last):
  File "C:\Users\zhi.zhou\Anaconda3\envs\lts\lib\site-packages\django\core\handlers\exception.py", line 47, in inner
    response = get_response(request)
  File "C:\Users\zhi.zhou\Anaconda3\envs\lts\lib\site-packages\django\core\handlers\base.py", line 181, in _get_response
    response = wrapped_callback(request, *callback_args, **callback_kwargs)
  File "C:\Users\zhi.zhou\Anaconda3\envs\lts\lib\site-packages\django\views\generic\base.py", line 70, in view
    return self.dispatch(request, *args, **kwargs)
  File "C:\Users\zhi.zhou\Anaconda3\envs\lts\lib\site-packages\django\views\generic\base.py", line 98, in dispatch
    return handler(request, *args, **kwargs)
  File "D:\zhouzhi\gitlit_code\logistic_tracking_system\logistic_tracking_system\lts\views.py", line 2287, in get
    data = json.dumps(data)
  File "C:\Users\zhi.zhou\Anaconda3\envs\lts\lib\json\__init__.py", line 231, in dumps
    return _default_encoder.encode(obj)
  File "C:\Users\zhi.zhou\Anaconda3\envs\lts\lib\json\encoder.py", line 199, in encode
    chunks = self.iterencode(o, _one_shot=True)
  File "C:\Users\zhi.zhou\Anaconda3\envs\lts\lib\json\encoder.py", line 257, in iterencode
    return _iterencode(o, 0)
  File "C:\Users\zhi.zhou\Anaconda3\envs\lts\lib\json\encoder.py", line 180, in default
    o.__class__.__name__)
TypeError: Object of type 'OperationalError' is not JSON serializable
[2021-08-24 13:43:58,100][Thread-13:15116][task_id:django.request][log.py:230][ERROR][Internal Server Error: /logistic/LogisticPutProductPlanDeal]
Traceback (most recent call last):
  File "D:\zhouzhi\gitlit_code\logistic_tracking_system\logistic_tracking_system\lts\views.py", line 2262, in get
    drs = db.execute_sql(conn, sql_main)
  File "D:\zhouzhi\gitlit_code\logistic_tracking_system\logistic_tracking_system\common\db.py", line 45, in execute_sql
    cursor.execute(sql)
  File "C:\Users\zhi.zhou\Anaconda3\envs\lts\lib\site-packages\pymysql\cursors.py", line 148, in execute
    result = self._query(query)
  File "C:\Users\zhi.zhou\Anaconda3\envs\lts\lib\site-packages\pymysql\cursors.py", line 310, in _query
    conn.query(q)
  File "C:\Users\zhi.zhou\Anaconda3\envs\lts\lib\site-packages\pymysql\connections.py", line 548, in query
    self._affected_rows = self._read_query_result(unbuffered=unbuffered)
  File "C:\Users\zhi.zhou\Anaconda3\envs\lts\lib\site-packages\pymysql\connections.py", line 775, in _read_query_result
    result.read()
  File "C:\Users\zhi.zhou\Anaconda3\envs\lts\lib\site-packages\pymysql\connections.py", line 1156, in read
    first_packet = self.connection._read_packet()
  File "C:\Users\zhi.zhou\Anaconda3\envs\lts\lib\site-packages\pymysql\connections.py", line 725, in _read_packet
    packet.raise_for_error()
  File "C:\Users\zhi.zhou\Anaconda3\envs\lts\lib\site-packages\pymysql\protocol.py", line 221, in raise_for_error
    err.raise_mysql_exception(self._data)
  File "C:\Users\zhi.zhou\Anaconda3\envs\lts\lib\site-packages\pymysql\err.py", line 143, in raise_mysql_exception
    raise errorclass(errno, errval)
pymysql.err.OperationalError: (1205, 'Lock wait timeout exceeded; try restarting transaction')

During handling of the above exception, another exception occurred:

Traceback (most recent call last):
  File "C:\Users\zhi.zhou\Anaconda3\envs\lts\lib\site-packages\django\core\handlers\exception.py", line 47, in inner
    response = get_response(request)
  File "C:\Users\zhi.zhou\Anaconda3\envs\lts\lib\site-packages\django\core\handlers\base.py", line 181, in _get_response
    response = wrapped_callback(request, *callback_args, **callback_kwargs)
  File "C:\Users\zhi.zhou\Anaconda3\envs\lts\lib\site-packages\django\views\generic\base.py", line 70, in view
    return self.dispatch(request, *args, **kwargs)
  File "C:\Users\zhi.zhou\Anaconda3\envs\lts\lib\site-packages\django\views\generic\base.py", line 98, in dispatch
    return handler(request, *args, **kwargs)
  File "D:\zhouzhi\gitlit_code\logistic_tracking_system\logistic_tracking_system\lts\views.py", line 2287, in get
    data = json.dumps(data)
  File "C:\Users\zhi.zhou\Anaconda3\envs\lts\lib\json\__init__.py", line 231, in dumps
    return _default_encoder.encode(obj)
  File "C:\Users\zhi.zhou\Anaconda3\envs\lts\lib\json\encoder.py", line 199, in encode
    chunks = self.iterencode(o, _one_shot=True)
  File "C:\Users\zhi.zhou\Anaconda3\envs\lts\lib\json\encoder.py", line 257, in iterencode
    return _iterencode(o, 0)
  File "C:\Users\zhi.zhou\Anaconda3\envs\lts\lib\json\encoder.py", line 180, in default
    o.__class__.__name__)
TypeError: Object of type 'OperationalError' is not JSON serializable
[2021-08-24 13:44:31,322][Thread-15:7700][task_id:django.request][log.py:230][ERROR][Internal Server Error: /logistic/LogisticPutProductPlanDeal]
Traceback (most recent call last):
  File "D:\zhouzhi\gitlit_code\logistic_tracking_system\logistic_tracking_system\lts\views.py", line 2262, in get
    drs = db.execute_sql(conn, sql_main)
  File "D:\zhouzhi\gitlit_code\logistic_tracking_system\logistic_tracking_system\common\db.py", line 45, in execute_sql
    cursor.execute(sql)
  File "C:\Users\zhi.zhou\Anaconda3\envs\lts\lib\site-packages\pymysql\cursors.py", line 148, in execute
    result = self._query(query)
  File "C:\Users\zhi.zhou\Anaconda3\envs\lts\lib\site-packages\pymysql\cursors.py", line 310, in _query
    conn.query(q)
  File "C:\Users\zhi.zhou\Anaconda3\envs\lts\lib\site-packages\pymysql\connections.py", line 548, in query
    self._affected_rows = self._read_query_result(unbuffered=unbuffered)
  File "C:\Users\zhi.zhou\Anaconda3\envs\lts\lib\site-packages\pymysql\connections.py", line 775, in _read_query_result
    result.read()
  File "C:\Users\zhi.zhou\Anaconda3\envs\lts\lib\site-packages\pymysql\connections.py", line 1156, in read
    first_packet = self.connection._read_packet()
  File "C:\Users\zhi.zhou\Anaconda3\envs\lts\lib\site-packages\pymysql\connections.py", line 725, in _read_packet
    packet.raise_for_error()
  File "C:\Users\zhi.zhou\Anaconda3\envs\lts\lib\site-packages\pymysql\protocol.py", line 221, in raise_for_error
    err.raise_mysql_exception(self._data)
  File "C:\Users\zhi.zhou\Anaconda3\envs\lts\lib\site-packages\pymysql\err.py", line 143, in raise_mysql_exception
    raise errorclass(errno, errval)
pymysql.err.OperationalError: (1205, 'Lock wait timeout exceeded; try restarting transaction')

During handling of the above exception, another exception occurred:

Traceback (most recent call last):
  File "C:\Users\zhi.zhou\Anaconda3\envs\lts\lib\site-packages\django\core\handlers\exception.py", line 47, in inner
    response = get_response(request)
  File "C:\Users\zhi.zhou\Anaconda3\envs\lts\lib\site-packages\django\core\handlers\base.py", line 181, in _get_response
    response = wrapped_callback(request, *callback_args, **callback_kwargs)
  File "C:\Users\zhi.zhou\Anaconda3\envs\lts\lib\site-packages\django\views\generic\base.py", line 70, in view
    return self.dispatch(request, *args, **kwargs)
  File "C:\Users\zhi.zhou\Anaconda3\envs\lts\lib\site-packages\django\views\generic\base.py", line 98, in dispatch
    return handler(request, *args, **kwargs)
  File "D:\zhouzhi\gitlit_code\logistic_tracking_system\logistic_tracking_system\lts\views.py", line 2287, in get
    data = json.dumps(data)
  File "C:\Users\zhi.zhou\Anaconda3\envs\lts\lib\json\__init__.py", line 231, in dumps
    return _default_encoder.encode(obj)
  File "C:\Users\zhi.zhou\Anaconda3\envs\lts\lib\json\encoder.py", line 199, in encode
    chunks = self.iterencode(o, _one_shot=True)
  File "C:\Users\zhi.zhou\Anaconda3\envs\lts\lib\json\encoder.py", line 257, in iterencode
    return _iterencode(o, 0)
  File "C:\Users\zhi.zhou\Anaconda3\envs\lts\lib\json\encoder.py", line 180, in default
    o.__class__.__name__)
TypeError: Object of type 'OperationalError' is not JSON serializable
[2021-08-24 14:48:32,143][Thread-17:11576][task_id:root][views.py:129][ERROR][用户没有进入此工站的权限]
[2021-08-24 16:51:54,579][Thread-153:18664][task_id:lts.views][views.py:256][ERROR][输入的旧密码有误]
[2021-08-24 17:02:49,692][Thread-169:20108][task_id:lts.views][views.py:184][ERROR][用户名或者密码不正确或者没有管理员的权限]
[2021-08-24 19:30:47,064][Thread-14:1232][task_id:lts.views][views.py:7801][ERROR][包装前检验成品操作失败->,(1146, "Table 'co2.product_transit_station_11' doesn't exist")]
[2021-08-24 19:30:53,306][Thread-13:18500][task_id:lts.views][views.py:7801][ERROR][包装前检验成品操作失败->,(1146, "Table 'co2.product_transit_station_11' doesn't exist")]
[2021-08-24 19:34:13,865][Thread-19:20544][task_id:lts.views][views.py:7801][ERROR][包装前检验成品操作失败->,(1146, "Table 'co2.product_transit_station_11' doesn't exist")]
[2021-08-24 19:34:22,236][Thread-18:12328][task_id:lts.views][views.py:7801][ERROR][包装前检验成品操作失败->,(1146, "Table 'co2.product_transit_station_11' doesn't exist")]
