[2021-07-27 09:23:14,205][Thread-4:17376][task_id:django.request][log.py:230][ERROR][Internal Server Error: /logistic/LogisticProcessDeal]
Traceback (most recent call last):
  File "D:\zhouzhi\gitlit_code\logistic_tracking_system\logistic_tracking_system\lts\views.py", line 3773, in get
    if len(production_name) == 0 and len(prodect_code) == 0 and len(work_id) == 0:
TypeError: object of type 'NoneType' has no len()

During handling of the above exception, another exception occurred:

Traceback (most recent call last):
  File "C:\Users\zhi.zhou\Anaconda3\envs\lts\lib\site-packages\django\core\handlers\exception.py", line 47, in inner
    response = get_response(request)
  File "C:\Users\zhi.zhou\Anaconda3\envs\lts\lib\site-packages\django\core\handlers\base.py", line 181, in _get_response
    response = wrapped_callback(request, *callback_args, **callback_kwargs)
  File "C:\Users\zhi.zhou\Anaconda3\envs\lts\lib\site-packages\django\views\generic\base.py", line 70, in view
    return self.dispatch(request, *args, **kwargs)
  File "C:\Users\zhi.zhou\Anaconda3\envs\lts\lib\site-packages\django\views\generic\base.py", line 98, in dispatch
    return handler(request, *args, **kwargs)
  File "D:\zhouzhi\gitlit_code\logistic_tracking_system\logistic_tracking_system\lts\views.py", line 4033, in get
    data = json.dumps(data)
  File "C:\Users\zhi.zhou\Anaconda3\envs\lts\lib\json\__init__.py", line 231, in dumps
    return _default_encoder.encode(obj)
  File "C:\Users\zhi.zhou\Anaconda3\envs\lts\lib\json\encoder.py", line 199, in encode
    chunks = self.iterencode(o, _one_shot=True)
  File "C:\Users\zhi.zhou\Anaconda3\envs\lts\lib\json\encoder.py", line 257, in iterencode
    return _iterencode(o, 0)
  File "C:\Users\zhi.zhou\Anaconda3\envs\lts\lib\json\encoder.py", line 180, in default
    o.__class__.__name__)
TypeError: Object of type 'TypeError' is not JSON serializable
[2021-07-27 09:28:15,291][Thread-6:10400][task_id:django.request][log.py:230][ERROR][Internal Server Error: /logistic/LogisticWorkStation]
Traceback (most recent call last):
  File "D:\zhouzhi\gitlit_code\logistic_tracking_system\logistic_tracking_system\lts\views.py", line 2451, in get
    drs = db.execute_sql(conn, sql_main)
  File "D:\zhouzhi\gitlit_code\logistic_tracking_system\logistic_tracking_system\common\db.py", line 45, in execute_sql
    cursor.execute(sql)
  File "C:\Users\zhi.zhou\Anaconda3\envs\lts\lib\site-packages\pymysql\cursors.py", line 148, in execute
    result = self._query(query)
  File "C:\Users\zhi.zhou\Anaconda3\envs\lts\lib\site-packages\pymysql\cursors.py", line 310, in _query
    conn.query(q)
  File "C:\Users\zhi.zhou\Anaconda3\envs\lts\lib\site-packages\pymysql\connections.py", line 548, in query
    self._affected_rows = self._read_query_result(unbuffered=unbuffered)
  File "C:\Users\zhi.zhou\Anaconda3\envs\lts\lib\site-packages\pymysql\connections.py", line 775, in _read_query_result
    result.read()
  File "C:\Users\zhi.zhou\Anaconda3\envs\lts\lib\site-packages\pymysql\connections.py", line 1156, in read
    first_packet = self.connection._read_packet()
  File "C:\Users\zhi.zhou\Anaconda3\envs\lts\lib\site-packages\pymysql\connections.py", line 725, in _read_packet
    packet.raise_for_error()
  File "C:\Users\zhi.zhou\Anaconda3\envs\lts\lib\site-packages\pymysql\protocol.py", line 221, in raise_for_error
    err.raise_mysql_exception(self._data)
  File "C:\Users\zhi.zhou\Anaconda3\envs\lts\lib\site-packages\pymysql\err.py", line 143, in raise_mysql_exception
    raise errorclass(errno, errval)
pymysql.err.OperationalError: (1046, 'No database selected')

During handling of the above exception, another exception occurred:

Traceback (most recent call last):
  File "C:\Users\zhi.zhou\Anaconda3\envs\lts\lib\site-packages\django\core\handlers\exception.py", line 47, in inner
    response = get_response(request)
  File "C:\Users\zhi.zhou\Anaconda3\envs\lts\lib\site-packages\django\core\handlers\base.py", line 181, in _get_response
    response = wrapped_callback(request, *callback_args, **callback_kwargs)
  File "C:\Users\zhi.zhou\Anaconda3\envs\lts\lib\site-packages\django\views\generic\base.py", line 70, in view
    return self.dispatch(request, *args, **kwargs)
  File "C:\Users\zhi.zhou\Anaconda3\envs\lts\lib\site-packages\django\views\generic\base.py", line 98, in dispatch
    return handler(request, *args, **kwargs)
  File "D:\zhouzhi\gitlit_code\logistic_tracking_system\logistic_tracking_system\lts\views.py", line 2587, in get
    result = json.dumps(result)
  File "C:\Users\zhi.zhou\Anaconda3\envs\lts\lib\json\__init__.py", line 231, in dumps
    return _default_encoder.encode(obj)
  File "C:\Users\zhi.zhou\Anaconda3\envs\lts\lib\json\encoder.py", line 199, in encode
    chunks = self.iterencode(o, _one_shot=True)
  File "C:\Users\zhi.zhou\Anaconda3\envs\lts\lib\json\encoder.py", line 257, in iterencode
    return _iterencode(o, 0)
  File "C:\Users\zhi.zhou\Anaconda3\envs\lts\lib\json\encoder.py", line 180, in default
    o.__class__.__name__)
TypeError: Object of type 'OperationalError' is not JSON serializable
[2021-07-27 09:28:41,425][Thread-6:10400][task_id:django.request][log.py:230][ERROR][Internal Server Error: /logistic/LogisticProcessDeal]
Traceback (most recent call last):
  File "D:\zhouzhi\gitlit_code\logistic_tracking_system\logistic_tracking_system\lts\views.py", line 3773, in get
    if len(production_name) == 0 and len(prodect_code) == 0 and len(work_id) == 0:
TypeError: object of type 'NoneType' has no len()

During handling of the above exception, another exception occurred:

Traceback (most recent call last):
  File "C:\Users\zhi.zhou\Anaconda3\envs\lts\lib\site-packages\django\core\handlers\exception.py", line 47, in inner
    response = get_response(request)
  File "C:\Users\zhi.zhou\Anaconda3\envs\lts\lib\site-packages\django\core\handlers\base.py", line 181, in _get_response
    response = wrapped_callback(request, *callback_args, **callback_kwargs)
  File "C:\Users\zhi.zhou\Anaconda3\envs\lts\lib\site-packages\django\views\generic\base.py", line 70, in view
    return self.dispatch(request, *args, **kwargs)
  File "C:\Users\zhi.zhou\Anaconda3\envs\lts\lib\site-packages\django\views\generic\base.py", line 98, in dispatch
    return handler(request, *args, **kwargs)
  File "D:\zhouzhi\gitlit_code\logistic_tracking_system\logistic_tracking_system\lts\views.py", line 4033, in get
    data = json.dumps(data)
  File "C:\Users\zhi.zhou\Anaconda3\envs\lts\lib\json\__init__.py", line 231, in dumps
    return _default_encoder.encode(obj)
  File "C:\Users\zhi.zhou\Anaconda3\envs\lts\lib\json\encoder.py", line 199, in encode
    chunks = self.iterencode(o, _one_shot=True)
  File "C:\Users\zhi.zhou\Anaconda3\envs\lts\lib\json\encoder.py", line 257, in iterencode
    return _iterencode(o, 0)
  File "C:\Users\zhi.zhou\Anaconda3\envs\lts\lib\json\encoder.py", line 180, in default
    o.__class__.__name__)
TypeError: Object of type 'TypeError' is not JSON serializable
[2021-07-27 09:29:53,552][Thread-9:3132][task_id:django.request][log.py:230][ERROR][Internal Server Error: /logistic/LogisticProcessDeal]
Traceback (most recent call last):
  File "D:\zhouzhi\gitlit_code\logistic_tracking_system\logistic_tracking_system\lts\views.py", line 3773, in get
    if len(production_name) == 0 and len(prodect_code) == 0 and len(work_id) == 0:
TypeError: object of type 'NoneType' has no len()

During handling of the above exception, another exception occurred:

Traceback (most recent call last):
  File "C:\Users\zhi.zhou\Anaconda3\envs\lts\lib\site-packages\django\core\handlers\exception.py", line 47, in inner
    response = get_response(request)
  File "C:\Users\zhi.zhou\Anaconda3\envs\lts\lib\site-packages\django\core\handlers\base.py", line 181, in _get_response
    response = wrapped_callback(request, *callback_args, **callback_kwargs)
  File "C:\Users\zhi.zhou\Anaconda3\envs\lts\lib\site-packages\django\views\generic\base.py", line 70, in view
    return self.dispatch(request, *args, **kwargs)
  File "C:\Users\zhi.zhou\Anaconda3\envs\lts\lib\site-packages\django\views\generic\base.py", line 98, in dispatch
    return handler(request, *args, **kwargs)
  File "D:\zhouzhi\gitlit_code\logistic_tracking_system\logistic_tracking_system\lts\views.py", line 4033, in get
    data = json.dumps(data)
  File "C:\Users\zhi.zhou\Anaconda3\envs\lts\lib\json\__init__.py", line 231, in dumps
    return _default_encoder.encode(obj)
  File "C:\Users\zhi.zhou\Anaconda3\envs\lts\lib\json\encoder.py", line 199, in encode
    chunks = self.iterencode(o, _one_shot=True)
  File "C:\Users\zhi.zhou\Anaconda3\envs\lts\lib\json\encoder.py", line 257, in iterencode
    return _iterencode(o, 0)
  File "C:\Users\zhi.zhou\Anaconda3\envs\lts\lib\json\encoder.py", line 180, in default
    o.__class__.__name__)
TypeError: Object of type 'TypeError' is not JSON serializable
[2021-07-27 09:29:53,722][Thread-10:4316][task_id:django.request][log.py:230][ERROR][Internal Server Error: /logistic/LogisticProcessDeal]
Traceback (most recent call last):
  File "D:\zhouzhi\gitlit_code\logistic_tracking_system\logistic_tracking_system\lts\views.py", line 3773, in get
    if len(production_name) == 0 and len(prodect_code) == 0 and len(work_id) == 0:
TypeError: object of type 'NoneType' has no len()

During handling of the above exception, another exception occurred:

Traceback (most recent call last):
  File "C:\Users\zhi.zhou\Anaconda3\envs\lts\lib\site-packages\django\core\handlers\exception.py", line 47, in inner
    response = get_response(request)
  File "C:\Users\zhi.zhou\Anaconda3\envs\lts\lib\site-packages\django\core\handlers\base.py", line 181, in _get_response
    response = wrapped_callback(request, *callback_args, **callback_kwargs)
  File "C:\Users\zhi.zhou\Anaconda3\envs\lts\lib\site-packages\django\views\generic\base.py", line 70, in view
    return self.dispatch(request, *args, **kwargs)
  File "C:\Users\zhi.zhou\Anaconda3\envs\lts\lib\site-packages\django\views\generic\base.py", line 98, in dispatch
    return handler(request, *args, **kwargs)
  File "D:\zhouzhi\gitlit_code\logistic_tracking_system\logistic_tracking_system\lts\views.py", line 4033, in get
    data = json.dumps(data)
  File "C:\Users\zhi.zhou\Anaconda3\envs\lts\lib\json\__init__.py", line 231, in dumps
    return _default_encoder.encode(obj)
  File "C:\Users\zhi.zhou\Anaconda3\envs\lts\lib\json\encoder.py", line 199, in encode
    chunks = self.iterencode(o, _one_shot=True)
  File "C:\Users\zhi.zhou\Anaconda3\envs\lts\lib\json\encoder.py", line 257, in iterencode
    return _iterencode(o, 0)
  File "C:\Users\zhi.zhou\Anaconda3\envs\lts\lib\json\encoder.py", line 180, in default
    o.__class__.__name__)
TypeError: Object of type 'TypeError' is not JSON serializable
[2021-07-27 09:48:12,701][Thread-8:9800][task_id:django.request][log.py:230][ERROR][Internal Server Error: /logistic/LogisticProcessDeal]
Traceback (most recent call last):
  File "D:\zhouzhi\gitlit_code\logistic_tracking_system\logistic_tracking_system\lts\views.py", line 3774, in get
    if len(production_name) == 0 and len(prodect_code) == 0 and len(work_id) == 0:
TypeError: object of type 'NoneType' has no len()

During handling of the above exception, another exception occurred:

Traceback (most recent call last):
  File "C:\Users\zhi.zhou\Anaconda3\envs\lts\lib\site-packages\django\core\handlers\exception.py", line 47, in inner
    response = get_response(request)
  File "C:\Users\zhi.zhou\Anaconda3\envs\lts\lib\site-packages\django\core\handlers\base.py", line 181, in _get_response
    response = wrapped_callback(request, *callback_args, **callback_kwargs)
  File "C:\Users\zhi.zhou\Anaconda3\envs\lts\lib\site-packages\django\views\generic\base.py", line 70, in view
    return self.dispatch(request, *args, **kwargs)
  File "C:\Users\zhi.zhou\Anaconda3\envs\lts\lib\site-packages\django\views\generic\base.py", line 98, in dispatch
    return handler(request, *args, **kwargs)
  File "D:\zhouzhi\gitlit_code\logistic_tracking_system\logistic_tracking_system\lts\views.py", line 4042, in get
    data = json.dumps(data)
  File "C:\Users\zhi.zhou\Anaconda3\envs\lts\lib\json\__init__.py", line 231, in dumps
    return _default_encoder.encode(obj)
  File "C:\Users\zhi.zhou\Anaconda3\envs\lts\lib\json\encoder.py", line 199, in encode
    chunks = self.iterencode(o, _one_shot=True)
  File "C:\Users\zhi.zhou\Anaconda3\envs\lts\lib\json\encoder.py", line 257, in iterencode
    return _iterencode(o, 0)
  File "C:\Users\zhi.zhou\Anaconda3\envs\lts\lib\json\encoder.py", line 180, in default
    o.__class__.__name__)
TypeError: Object of type 'TypeError' is not JSON serializable
[2021-07-27 09:53:15,864][Thread-10:17092][task_id:django.request][log.py:230][ERROR][Internal Server Error: /logistic/LogisticWorkStation]
Traceback (most recent call last):
  File "D:\zhouzhi\gitlit_code\logistic_tracking_system\logistic_tracking_system\lts\views.py", line 2452, in get
    drs = db.execute_sql(conn, sql_main)
  File "D:\zhouzhi\gitlit_code\logistic_tracking_system\logistic_tracking_system\common\db.py", line 45, in execute_sql
    cursor.execute(sql)
  File "C:\Users\zhi.zhou\Anaconda3\envs\lts\lib\site-packages\pymysql\cursors.py", line 148, in execute
    result = self._query(query)
  File "C:\Users\zhi.zhou\Anaconda3\envs\lts\lib\site-packages\pymysql\cursors.py", line 310, in _query
    conn.query(q)
  File "C:\Users\zhi.zhou\Anaconda3\envs\lts\lib\site-packages\pymysql\connections.py", line 548, in query
    self._affected_rows = self._read_query_result(unbuffered=unbuffered)
  File "C:\Users\zhi.zhou\Anaconda3\envs\lts\lib\site-packages\pymysql\connections.py", line 775, in _read_query_result
    result.read()
  File "C:\Users\zhi.zhou\Anaconda3\envs\lts\lib\site-packages\pymysql\connections.py", line 1156, in read
    first_packet = self.connection._read_packet()
  File "C:\Users\zhi.zhou\Anaconda3\envs\lts\lib\site-packages\pymysql\connections.py", line 725, in _read_packet
    packet.raise_for_error()
  File "C:\Users\zhi.zhou\Anaconda3\envs\lts\lib\site-packages\pymysql\protocol.py", line 221, in raise_for_error
    err.raise_mysql_exception(self._data)
  File "C:\Users\zhi.zhou\Anaconda3\envs\lts\lib\site-packages\pymysql\err.py", line 143, in raise_mysql_exception
    raise errorclass(errno, errval)
pymysql.err.OperationalError: (1046, 'No database selected')

During handling of the above exception, another exception occurred:

Traceback (most recent call last):
  File "C:\Users\zhi.zhou\Anaconda3\envs\lts\lib\site-packages\django\core\handlers\exception.py", line 47, in inner
    response = get_response(request)
  File "C:\Users\zhi.zhou\Anaconda3\envs\lts\lib\site-packages\django\core\handlers\base.py", line 181, in _get_response
    response = wrapped_callback(request, *callback_args, **callback_kwargs)
  File "C:\Users\zhi.zhou\Anaconda3\envs\lts\lib\site-packages\django\views\generic\base.py", line 70, in view
    return self.dispatch(request, *args, **kwargs)
  File "C:\Users\zhi.zhou\Anaconda3\envs\lts\lib\site-packages\django\views\generic\base.py", line 98, in dispatch
    return handler(request, *args, **kwargs)
  File "D:\zhouzhi\gitlit_code\logistic_tracking_system\logistic_tracking_system\lts\views.py", line 2588, in get
    result = json.dumps(result)
  File "C:\Users\zhi.zhou\Anaconda3\envs\lts\lib\json\__init__.py", line 231, in dumps
    return _default_encoder.encode(obj)
  File "C:\Users\zhi.zhou\Anaconda3\envs\lts\lib\json\encoder.py", line 199, in encode
    chunks = self.iterencode(o, _one_shot=True)
  File "C:\Users\zhi.zhou\Anaconda3\envs\lts\lib\json\encoder.py", line 257, in iterencode
    return _iterencode(o, 0)
  File "C:\Users\zhi.zhou\Anaconda3\envs\lts\lib\json\encoder.py", line 180, in default
    o.__class__.__name__)
TypeError: Object of type 'OperationalError' is not JSON serializable
[2021-07-27 09:54:15,434][Thread-10:17092][task_id:django.request][log.py:230][ERROR][Internal Server Error: /logistic/LogisticWorkCodeName]
Traceback (most recent call last):
  File "D:\zhouzhi\gitlit_code\logistic_tracking_system\logistic_tracking_system\lts\views.py", line 4245, in get
    drs = db.execute_sql(conn, sql)
  File "D:\zhouzhi\gitlit_code\logistic_tracking_system\logistic_tracking_system\common\db.py", line 45, in execute_sql
    cursor.execute(sql)
  File "C:\Users\zhi.zhou\Anaconda3\envs\lts\lib\site-packages\pymysql\cursors.py", line 148, in execute
    result = self._query(query)
  File "C:\Users\zhi.zhou\Anaconda3\envs\lts\lib\site-packages\pymysql\cursors.py", line 310, in _query
    conn.query(q)
  File "C:\Users\zhi.zhou\Anaconda3\envs\lts\lib\site-packages\pymysql\connections.py", line 548, in query
    self._affected_rows = self._read_query_result(unbuffered=unbuffered)
  File "C:\Users\zhi.zhou\Anaconda3\envs\lts\lib\site-packages\pymysql\connections.py", line 775, in _read_query_result
    result.read()
  File "C:\Users\zhi.zhou\Anaconda3\envs\lts\lib\site-packages\pymysql\connections.py", line 1156, in read
    first_packet = self.connection._read_packet()
  File "C:\Users\zhi.zhou\Anaconda3\envs\lts\lib\site-packages\pymysql\connections.py", line 725, in _read_packet
    packet.raise_for_error()
  File "C:\Users\zhi.zhou\Anaconda3\envs\lts\lib\site-packages\pymysql\protocol.py", line 221, in raise_for_error
    err.raise_mysql_exception(self._data)
  File "C:\Users\zhi.zhou\Anaconda3\envs\lts\lib\site-packages\pymysql\err.py", line 143, in raise_mysql_exception
    raise errorclass(errno, errval)
pymysql.err.OperationalError: (1046, 'No database selected')

During handling of the above exception, another exception occurred:

Traceback (most recent call last):
  File "C:\Users\zhi.zhou\Anaconda3\envs\lts\lib\site-packages\django\core\handlers\exception.py", line 47, in inner
    response = get_response(request)
  File "C:\Users\zhi.zhou\Anaconda3\envs\lts\lib\site-packages\django\core\handlers\base.py", line 181, in _get_response
    response = wrapped_callback(request, *callback_args, **callback_kwargs)
  File "C:\Users\zhi.zhou\Anaconda3\envs\lts\lib\site-packages\django\views\generic\base.py", line 70, in view
    return self.dispatch(request, *args, **kwargs)
  File "C:\Users\zhi.zhou\Anaconda3\envs\lts\lib\site-packages\django\views\generic\base.py", line 98, in dispatch
    return handler(request, *args, **kwargs)
  File "D:\zhouzhi\gitlit_code\logistic_tracking_system\logistic_tracking_system\lts\views.py", line 4259, in get
    data = json.dumps(data)
  File "C:\Users\zhi.zhou\Anaconda3\envs\lts\lib\json\__init__.py", line 231, in dumps
    return _default_encoder.encode(obj)
  File "C:\Users\zhi.zhou\Anaconda3\envs\lts\lib\json\encoder.py", line 199, in encode
    chunks = self.iterencode(o, _one_shot=True)
  File "C:\Users\zhi.zhou\Anaconda3\envs\lts\lib\json\encoder.py", line 257, in iterencode
    return _iterencode(o, 0)
  File "C:\Users\zhi.zhou\Anaconda3\envs\lts\lib\json\encoder.py", line 180, in default
    o.__class__.__name__)
TypeError: Object of type 'OperationalError' is not JSON serializable
[2021-07-27 09:54:26,795][Thread-10:17092][task_id:django.request][log.py:230][ERROR][Internal Server Error: /logistic/LogisticWorkStation]
Traceback (most recent call last):
  File "D:\zhouzhi\gitlit_code\logistic_tracking_system\logistic_tracking_system\lts\views.py", line 2452, in get
    drs = db.execute_sql(conn, sql_main)
  File "D:\zhouzhi\gitlit_code\logistic_tracking_system\logistic_tracking_system\common\db.py", line 45, in execute_sql
    cursor.execute(sql)
  File "C:\Users\zhi.zhou\Anaconda3\envs\lts\lib\site-packages\pymysql\cursors.py", line 148, in execute
    result = self._query(query)
  File "C:\Users\zhi.zhou\Anaconda3\envs\lts\lib\site-packages\pymysql\cursors.py", line 310, in _query
    conn.query(q)
  File "C:\Users\zhi.zhou\Anaconda3\envs\lts\lib\site-packages\pymysql\connections.py", line 548, in query
    self._affected_rows = self._read_query_result(unbuffered=unbuffered)
  File "C:\Users\zhi.zhou\Anaconda3\envs\lts\lib\site-packages\pymysql\connections.py", line 775, in _read_query_result
    result.read()
  File "C:\Users\zhi.zhou\Anaconda3\envs\lts\lib\site-packages\pymysql\connections.py", line 1156, in read
    first_packet = self.connection._read_packet()
  File "C:\Users\zhi.zhou\Anaconda3\envs\lts\lib\site-packages\pymysql\connections.py", line 725, in _read_packet
    packet.raise_for_error()
  File "C:\Users\zhi.zhou\Anaconda3\envs\lts\lib\site-packages\pymysql\protocol.py", line 221, in raise_for_error
    err.raise_mysql_exception(self._data)
  File "C:\Users\zhi.zhou\Anaconda3\envs\lts\lib\site-packages\pymysql\err.py", line 143, in raise_mysql_exception
    raise errorclass(errno, errval)
pymysql.err.OperationalError: (1046, 'No database selected')

During handling of the above exception, another exception occurred:

Traceback (most recent call last):
  File "C:\Users\zhi.zhou\Anaconda3\envs\lts\lib\site-packages\django\core\handlers\exception.py", line 47, in inner
    response = get_response(request)
  File "C:\Users\zhi.zhou\Anaconda3\envs\lts\lib\site-packages\django\core\handlers\base.py", line 181, in _get_response
    response = wrapped_callback(request, *callback_args, **callback_kwargs)
  File "C:\Users\zhi.zhou\Anaconda3\envs\lts\lib\site-packages\django\views\generic\base.py", line 70, in view
    return self.dispatch(request, *args, **kwargs)
  File "C:\Users\zhi.zhou\Anaconda3\envs\lts\lib\site-packages\django\views\generic\base.py", line 98, in dispatch
    return handler(request, *args, **kwargs)
  File "D:\zhouzhi\gitlit_code\logistic_tracking_system\logistic_tracking_system\lts\views.py", line 2588, in get
    result = json.dumps(result)
  File "C:\Users\zhi.zhou\Anaconda3\envs\lts\lib\json\__init__.py", line 231, in dumps
    return _default_encoder.encode(obj)
  File "C:\Users\zhi.zhou\Anaconda3\envs\lts\lib\json\encoder.py", line 199, in encode
    chunks = self.iterencode(o, _one_shot=True)
  File "C:\Users\zhi.zhou\Anaconda3\envs\lts\lib\json\encoder.py", line 257, in iterencode
    return _iterencode(o, 0)
  File "C:\Users\zhi.zhou\Anaconda3\envs\lts\lib\json\encoder.py", line 180, in default
    o.__class__.__name__)
TypeError: Object of type 'OperationalError' is not JSON serializable
[2021-07-27 09:54:28,608][Thread-10:17092][task_id:django.request][log.py:230][ERROR][Internal Server Error: /logistic/LogisticWorkCodeName]
Traceback (most recent call last):
  File "D:\zhouzhi\gitlit_code\logistic_tracking_system\logistic_tracking_system\lts\views.py", line 4245, in get
    drs = db.execute_sql(conn, sql)
  File "D:\zhouzhi\gitlit_code\logistic_tracking_system\logistic_tracking_system\common\db.py", line 45, in execute_sql
    cursor.execute(sql)
  File "C:\Users\zhi.zhou\Anaconda3\envs\lts\lib\site-packages\pymysql\cursors.py", line 148, in execute
    result = self._query(query)
  File "C:\Users\zhi.zhou\Anaconda3\envs\lts\lib\site-packages\pymysql\cursors.py", line 310, in _query
    conn.query(q)
  File "C:\Users\zhi.zhou\Anaconda3\envs\lts\lib\site-packages\pymysql\connections.py", line 548, in query
    self._affected_rows = self._read_query_result(unbuffered=unbuffered)
  File "C:\Users\zhi.zhou\Anaconda3\envs\lts\lib\site-packages\pymysql\connections.py", line 775, in _read_query_result
    result.read()
  File "C:\Users\zhi.zhou\Anaconda3\envs\lts\lib\site-packages\pymysql\connections.py", line 1156, in read
    first_packet = self.connection._read_packet()
  File "C:\Users\zhi.zhou\Anaconda3\envs\lts\lib\site-packages\pymysql\connections.py", line 725, in _read_packet
    packet.raise_for_error()
  File "C:\Users\zhi.zhou\Anaconda3\envs\lts\lib\site-packages\pymysql\protocol.py", line 221, in raise_for_error
    err.raise_mysql_exception(self._data)
  File "C:\Users\zhi.zhou\Anaconda3\envs\lts\lib\site-packages\pymysql\err.py", line 143, in raise_mysql_exception
    raise errorclass(errno, errval)
pymysql.err.OperationalError: (1046, 'No database selected')

During handling of the above exception, another exception occurred:

Traceback (most recent call last):
  File "C:\Users\zhi.zhou\Anaconda3\envs\lts\lib\site-packages\django\core\handlers\exception.py", line 47, in inner
    response = get_response(request)
  File "C:\Users\zhi.zhou\Anaconda3\envs\lts\lib\site-packages\django\core\handlers\base.py", line 181, in _get_response
    response = wrapped_callback(request, *callback_args, **callback_kwargs)
  File "C:\Users\zhi.zhou\Anaconda3\envs\lts\lib\site-packages\django\views\generic\base.py", line 70, in view
    return self.dispatch(request, *args, **kwargs)
  File "C:\Users\zhi.zhou\Anaconda3\envs\lts\lib\site-packages\django\views\generic\base.py", line 98, in dispatch
    return handler(request, *args, **kwargs)
  File "D:\zhouzhi\gitlit_code\logistic_tracking_system\logistic_tracking_system\lts\views.py", line 4259, in get
    data = json.dumps(data)
  File "C:\Users\zhi.zhou\Anaconda3\envs\lts\lib\json\__init__.py", line 231, in dumps
    return _default_encoder.encode(obj)
  File "C:\Users\zhi.zhou\Anaconda3\envs\lts\lib\json\encoder.py", line 199, in encode
    chunks = self.iterencode(o, _one_shot=True)
  File "C:\Users\zhi.zhou\Anaconda3\envs\lts\lib\json\encoder.py", line 257, in iterencode
    return _iterencode(o, 0)
  File "C:\Users\zhi.zhou\Anaconda3\envs\lts\lib\json\encoder.py", line 180, in default
    o.__class__.__name__)
TypeError: Object of type 'OperationalError' is not JSON serializable
[2021-07-27 09:56:29,992][Thread-13:9804][task_id:django.request][log.py:230][ERROR][Internal Server Error: /logistic/LogisticWorkCodeName]
Traceback (most recent call last):
  File "D:\zhouzhi\gitlit_code\logistic_tracking_system\logistic_tracking_system\lts\views.py", line 4245, in get
    drs = db.execute_sql(conn, sql)
  File "D:\zhouzhi\gitlit_code\logistic_tracking_system\logistic_tracking_system\common\db.py", line 45, in execute_sql
    cursor.execute(sql)
  File "C:\Users\zhi.zhou\Anaconda3\envs\lts\lib\site-packages\pymysql\cursors.py", line 148, in execute
    result = self._query(query)
  File "C:\Users\zhi.zhou\Anaconda3\envs\lts\lib\site-packages\pymysql\cursors.py", line 310, in _query
    conn.query(q)
  File "C:\Users\zhi.zhou\Anaconda3\envs\lts\lib\site-packages\pymysql\connections.py", line 548, in query
    self._affected_rows = self._read_query_result(unbuffered=unbuffered)
  File "C:\Users\zhi.zhou\Anaconda3\envs\lts\lib\site-packages\pymysql\connections.py", line 775, in _read_query_result
    result.read()
  File "C:\Users\zhi.zhou\Anaconda3\envs\lts\lib\site-packages\pymysql\connections.py", line 1156, in read
    first_packet = self.connection._read_packet()
  File "C:\Users\zhi.zhou\Anaconda3\envs\lts\lib\site-packages\pymysql\connections.py", line 725, in _read_packet
    packet.raise_for_error()
  File "C:\Users\zhi.zhou\Anaconda3\envs\lts\lib\site-packages\pymysql\protocol.py", line 221, in raise_for_error
    err.raise_mysql_exception(self._data)
  File "C:\Users\zhi.zhou\Anaconda3\envs\lts\lib\site-packages\pymysql\err.py", line 143, in raise_mysql_exception
    raise errorclass(errno, errval)
pymysql.err.OperationalError: (1046, 'No database selected')

During handling of the above exception, another exception occurred:

Traceback (most recent call last):
  File "C:\Users\zhi.zhou\Anaconda3\envs\lts\lib\site-packages\django\core\handlers\exception.py", line 47, in inner
    response = get_response(request)
  File "C:\Users\zhi.zhou\Anaconda3\envs\lts\lib\site-packages\django\core\handlers\base.py", line 181, in _get_response
    response = wrapped_callback(request, *callback_args, **callback_kwargs)
  File "C:\Users\zhi.zhou\Anaconda3\envs\lts\lib\site-packages\django\views\generic\base.py", line 70, in view
    return self.dispatch(request, *args, **kwargs)
  File "C:\Users\zhi.zhou\Anaconda3\envs\lts\lib\site-packages\django\views\generic\base.py", line 98, in dispatch
    return handler(request, *args, **kwargs)
  File "D:\zhouzhi\gitlit_code\logistic_tracking_system\logistic_tracking_system\lts\views.py", line 4259, in get
    data = json.dumps(data)
  File "C:\Users\zhi.zhou\Anaconda3\envs\lts\lib\json\__init__.py", line 231, in dumps
    return _default_encoder.encode(obj)
  File "C:\Users\zhi.zhou\Anaconda3\envs\lts\lib\json\encoder.py", line 199, in encode
    chunks = self.iterencode(o, _one_shot=True)
  File "C:\Users\zhi.zhou\Anaconda3\envs\lts\lib\json\encoder.py", line 257, in iterencode
    return _iterencode(o, 0)
  File "C:\Users\zhi.zhou\Anaconda3\envs\lts\lib\json\encoder.py", line 180, in default
    o.__class__.__name__)
TypeError: Object of type 'OperationalError' is not JSON serializable
[2021-07-27 09:56:45,240][Thread-13:9804][task_id:django.request][log.py:230][ERROR][Internal Server Error: /logistic/LogisticWorkCodeName]
Traceback (most recent call last):
  File "D:\zhouzhi\gitlit_code\logistic_tracking_system\logistic_tracking_system\lts\views.py", line 4245, in get
    drs = db.execute_sql(conn, sql)
  File "D:\zhouzhi\gitlit_code\logistic_tracking_system\logistic_tracking_system\common\db.py", line 45, in execute_sql
    cursor.execute(sql)
  File "C:\Users\zhi.zhou\Anaconda3\envs\lts\lib\site-packages\pymysql\cursors.py", line 148, in execute
    result = self._query(query)
  File "C:\Users\zhi.zhou\Anaconda3\envs\lts\lib\site-packages\pymysql\cursors.py", line 310, in _query
    conn.query(q)
  File "C:\Users\zhi.zhou\Anaconda3\envs\lts\lib\site-packages\pymysql\connections.py", line 548, in query
    self._affected_rows = self._read_query_result(unbuffered=unbuffered)
  File "C:\Users\zhi.zhou\Anaconda3\envs\lts\lib\site-packages\pymysql\connections.py", line 775, in _read_query_result
    result.read()
  File "C:\Users\zhi.zhou\Anaconda3\envs\lts\lib\site-packages\pymysql\connections.py", line 1156, in read
    first_packet = self.connection._read_packet()
  File "C:\Users\zhi.zhou\Anaconda3\envs\lts\lib\site-packages\pymysql\connections.py", line 725, in _read_packet
    packet.raise_for_error()
  File "C:\Users\zhi.zhou\Anaconda3\envs\lts\lib\site-packages\pymysql\protocol.py", line 221, in raise_for_error
    err.raise_mysql_exception(self._data)
  File "C:\Users\zhi.zhou\Anaconda3\envs\lts\lib\site-packages\pymysql\err.py", line 143, in raise_mysql_exception
    raise errorclass(errno, errval)
pymysql.err.OperationalError: (1046, 'No database selected')

During handling of the above exception, another exception occurred:

Traceback (most recent call last):
  File "C:\Users\zhi.zhou\Anaconda3\envs\lts\lib\site-packages\django\core\handlers\exception.py", line 47, in inner
    response = get_response(request)
  File "C:\Users\zhi.zhou\Anaconda3\envs\lts\lib\site-packages\django\core\handlers\base.py", line 181, in _get_response
    response = wrapped_callback(request, *callback_args, **callback_kwargs)
  File "C:\Users\zhi.zhou\Anaconda3\envs\lts\lib\site-packages\django\views\generic\base.py", line 70, in view
    return self.dispatch(request, *args, **kwargs)
  File "C:\Users\zhi.zhou\Anaconda3\envs\lts\lib\site-packages\django\views\generic\base.py", line 98, in dispatch
    return handler(request, *args, **kwargs)
  File "D:\zhouzhi\gitlit_code\logistic_tracking_system\logistic_tracking_system\lts\views.py", line 4259, in get
    data = json.dumps(data)
  File "C:\Users\zhi.zhou\Anaconda3\envs\lts\lib\json\__init__.py", line 231, in dumps
    return _default_encoder.encode(obj)
  File "C:\Users\zhi.zhou\Anaconda3\envs\lts\lib\json\encoder.py", line 199, in encode
    chunks = self.iterencode(o, _one_shot=True)
  File "C:\Users\zhi.zhou\Anaconda3\envs\lts\lib\json\encoder.py", line 257, in iterencode
    return _iterencode(o, 0)
  File "C:\Users\zhi.zhou\Anaconda3\envs\lts\lib\json\encoder.py", line 180, in default
    o.__class__.__name__)
TypeError: Object of type 'OperationalError' is not JSON serializable
[2021-07-27 09:56:50,376][Thread-13:9804][task_id:django.request][log.py:230][ERROR][Internal Server Error: /logistic/LogisticWorkStation]
Traceback (most recent call last):
  File "D:\zhouzhi\gitlit_code\logistic_tracking_system\logistic_tracking_system\lts\views.py", line 2452, in get
    drs = db.execute_sql(conn, sql_main)
  File "D:\zhouzhi\gitlit_code\logistic_tracking_system\logistic_tracking_system\common\db.py", line 45, in execute_sql
    cursor.execute(sql)
  File "C:\Users\zhi.zhou\Anaconda3\envs\lts\lib\site-packages\pymysql\cursors.py", line 148, in execute
    result = self._query(query)
  File "C:\Users\zhi.zhou\Anaconda3\envs\lts\lib\site-packages\pymysql\cursors.py", line 310, in _query
    conn.query(q)
  File "C:\Users\zhi.zhou\Anaconda3\envs\lts\lib\site-packages\pymysql\connections.py", line 548, in query
    self._affected_rows = self._read_query_result(unbuffered=unbuffered)
  File "C:\Users\zhi.zhou\Anaconda3\envs\lts\lib\site-packages\pymysql\connections.py", line 775, in _read_query_result
    result.read()
  File "C:\Users\zhi.zhou\Anaconda3\envs\lts\lib\site-packages\pymysql\connections.py", line 1156, in read
    first_packet = self.connection._read_packet()
  File "C:\Users\zhi.zhou\Anaconda3\envs\lts\lib\site-packages\pymysql\connections.py", line 725, in _read_packet
    packet.raise_for_error()
  File "C:\Users\zhi.zhou\Anaconda3\envs\lts\lib\site-packages\pymysql\protocol.py", line 221, in raise_for_error
    err.raise_mysql_exception(self._data)
  File "C:\Users\zhi.zhou\Anaconda3\envs\lts\lib\site-packages\pymysql\err.py", line 143, in raise_mysql_exception
    raise errorclass(errno, errval)
pymysql.err.OperationalError: (1046, 'No database selected')

During handling of the above exception, another exception occurred:

Traceback (most recent call last):
  File "C:\Users\zhi.zhou\Anaconda3\envs\lts\lib\site-packages\django\core\handlers\exception.py", line 47, in inner
    response = get_response(request)
  File "C:\Users\zhi.zhou\Anaconda3\envs\lts\lib\site-packages\django\core\handlers\base.py", line 181, in _get_response
    response = wrapped_callback(request, *callback_args, **callback_kwargs)
  File "C:\Users\zhi.zhou\Anaconda3\envs\lts\lib\site-packages\django\views\generic\base.py", line 70, in view
    return self.dispatch(request, *args, **kwargs)
  File "C:\Users\zhi.zhou\Anaconda3\envs\lts\lib\site-packages\django\views\generic\base.py", line 98, in dispatch
    return handler(request, *args, **kwargs)
  File "D:\zhouzhi\gitlit_code\logistic_tracking_system\logistic_tracking_system\lts\views.py", line 2588, in get
    result = json.dumps(result)
  File "C:\Users\zhi.zhou\Anaconda3\envs\lts\lib\json\__init__.py", line 231, in dumps
    return _default_encoder.encode(obj)
  File "C:\Users\zhi.zhou\Anaconda3\envs\lts\lib\json\encoder.py", line 199, in encode
    chunks = self.iterencode(o, _one_shot=True)
  File "C:\Users\zhi.zhou\Anaconda3\envs\lts\lib\json\encoder.py", line 257, in iterencode
    return _iterencode(o, 0)
  File "C:\Users\zhi.zhou\Anaconda3\envs\lts\lib\json\encoder.py", line 180, in default
    o.__class__.__name__)
TypeError: Object of type 'OperationalError' is not JSON serializable
[2021-07-27 09:56:51,300][Thread-13:9804][task_id:django.request][log.py:230][ERROR][Internal Server Error: /logistic/LogisticWorkCodeName]
Traceback (most recent call last):
  File "D:\zhouzhi\gitlit_code\logistic_tracking_system\logistic_tracking_system\lts\views.py", line 4245, in get
    drs = db.execute_sql(conn, sql)
  File "D:\zhouzhi\gitlit_code\logistic_tracking_system\logistic_tracking_system\common\db.py", line 45, in execute_sql
    cursor.execute(sql)
  File "C:\Users\zhi.zhou\Anaconda3\envs\lts\lib\site-packages\pymysql\cursors.py", line 148, in execute
    result = self._query(query)
  File "C:\Users\zhi.zhou\Anaconda3\envs\lts\lib\site-packages\pymysql\cursors.py", line 310, in _query
    conn.query(q)
  File "C:\Users\zhi.zhou\Anaconda3\envs\lts\lib\site-packages\pymysql\connections.py", line 548, in query
    self._affected_rows = self._read_query_result(unbuffered=unbuffered)
  File "C:\Users\zhi.zhou\Anaconda3\envs\lts\lib\site-packages\pymysql\connections.py", line 775, in _read_query_result
    result.read()
  File "C:\Users\zhi.zhou\Anaconda3\envs\lts\lib\site-packages\pymysql\connections.py", line 1156, in read
    first_packet = self.connection._read_packet()
  File "C:\Users\zhi.zhou\Anaconda3\envs\lts\lib\site-packages\pymysql\connections.py", line 725, in _read_packet
    packet.raise_for_error()
  File "C:\Users\zhi.zhou\Anaconda3\envs\lts\lib\site-packages\pymysql\protocol.py", line 221, in raise_for_error
    err.raise_mysql_exception(self._data)
  File "C:\Users\zhi.zhou\Anaconda3\envs\lts\lib\site-packages\pymysql\err.py", line 143, in raise_mysql_exception
    raise errorclass(errno, errval)
pymysql.err.OperationalError: (1046, 'No database selected')

During handling of the above exception, another exception occurred:

Traceback (most recent call last):
  File "C:\Users\zhi.zhou\Anaconda3\envs\lts\lib\site-packages\django\core\handlers\exception.py", line 47, in inner
    response = get_response(request)
  File "C:\Users\zhi.zhou\Anaconda3\envs\lts\lib\site-packages\django\core\handlers\base.py", line 181, in _get_response
    response = wrapped_callback(request, *callback_args, **callback_kwargs)
  File "C:\Users\zhi.zhou\Anaconda3\envs\lts\lib\site-packages\django\views\generic\base.py", line 70, in view
    return self.dispatch(request, *args, **kwargs)
  File "C:\Users\zhi.zhou\Anaconda3\envs\lts\lib\site-packages\django\views\generic\base.py", line 98, in dispatch
    return handler(request, *args, **kwargs)
  File "D:\zhouzhi\gitlit_code\logistic_tracking_system\logistic_tracking_system\lts\views.py", line 4259, in get
    data = json.dumps(data)
  File "C:\Users\zhi.zhou\Anaconda3\envs\lts\lib\json\__init__.py", line 231, in dumps
    return _default_encoder.encode(obj)
  File "C:\Users\zhi.zhou\Anaconda3\envs\lts\lib\json\encoder.py", line 199, in encode
    chunks = self.iterencode(o, _one_shot=True)
  File "C:\Users\zhi.zhou\Anaconda3\envs\lts\lib\json\encoder.py", line 257, in iterencode
    return _iterencode(o, 0)
  File "C:\Users\zhi.zhou\Anaconda3\envs\lts\lib\json\encoder.py", line 180, in default
    o.__class__.__name__)
TypeError: Object of type 'OperationalError' is not JSON serializable
[2021-07-27 09:56:53,827][Thread-13:9804][task_id:django.request][log.py:230][ERROR][Internal Server Error: /logistic/LogisticWorkCodeName]
Traceback (most recent call last):
  File "D:\zhouzhi\gitlit_code\logistic_tracking_system\logistic_tracking_system\lts\views.py", line 4245, in get
    drs = db.execute_sql(conn, sql)
  File "D:\zhouzhi\gitlit_code\logistic_tracking_system\logistic_tracking_system\common\db.py", line 45, in execute_sql
    cursor.execute(sql)
  File "C:\Users\zhi.zhou\Anaconda3\envs\lts\lib\site-packages\pymysql\cursors.py", line 148, in execute
    result = self._query(query)
  File "C:\Users\zhi.zhou\Anaconda3\envs\lts\lib\site-packages\pymysql\cursors.py", line 310, in _query
    conn.query(q)
  File "C:\Users\zhi.zhou\Anaconda3\envs\lts\lib\site-packages\pymysql\connections.py", line 548, in query
    self._affected_rows = self._read_query_result(unbuffered=unbuffered)
  File "C:\Users\zhi.zhou\Anaconda3\envs\lts\lib\site-packages\pymysql\connections.py", line 775, in _read_query_result
    result.read()
  File "C:\Users\zhi.zhou\Anaconda3\envs\lts\lib\site-packages\pymysql\connections.py", line 1156, in read
    first_packet = self.connection._read_packet()
  File "C:\Users\zhi.zhou\Anaconda3\envs\lts\lib\site-packages\pymysql\connections.py", line 725, in _read_packet
    packet.raise_for_error()
  File "C:\Users\zhi.zhou\Anaconda3\envs\lts\lib\site-packages\pymysql\protocol.py", line 221, in raise_for_error
    err.raise_mysql_exception(self._data)
  File "C:\Users\zhi.zhou\Anaconda3\envs\lts\lib\site-packages\pymysql\err.py", line 143, in raise_mysql_exception
    raise errorclass(errno, errval)
pymysql.err.OperationalError: (1046, 'No database selected')

During handling of the above exception, another exception occurred:

Traceback (most recent call last):
  File "C:\Users\zhi.zhou\Anaconda3\envs\lts\lib\site-packages\django\core\handlers\exception.py", line 47, in inner
    response = get_response(request)
  File "C:\Users\zhi.zhou\Anaconda3\envs\lts\lib\site-packages\django\core\handlers\base.py", line 181, in _get_response
    response = wrapped_callback(request, *callback_args, **callback_kwargs)
  File "C:\Users\zhi.zhou\Anaconda3\envs\lts\lib\site-packages\django\views\generic\base.py", line 70, in view
    return self.dispatch(request, *args, **kwargs)
  File "C:\Users\zhi.zhou\Anaconda3\envs\lts\lib\site-packages\django\views\generic\base.py", line 98, in dispatch
    return handler(request, *args, **kwargs)
  File "D:\zhouzhi\gitlit_code\logistic_tracking_system\logistic_tracking_system\lts\views.py", line 4259, in get
    data = json.dumps(data)
  File "C:\Users\zhi.zhou\Anaconda3\envs\lts\lib\json\__init__.py", line 231, in dumps
    return _default_encoder.encode(obj)
  File "C:\Users\zhi.zhou\Anaconda3\envs\lts\lib\json\encoder.py", line 199, in encode
    chunks = self.iterencode(o, _one_shot=True)
  File "C:\Users\zhi.zhou\Anaconda3\envs\lts\lib\json\encoder.py", line 257, in iterencode
    return _iterencode(o, 0)
  File "C:\Users\zhi.zhou\Anaconda3\envs\lts\lib\json\encoder.py", line 180, in default
    o.__class__.__name__)
TypeError: Object of type 'OperationalError' is not JSON serializable
[2021-07-27 10:00:44,527][Thread-14:18160][task_id:django.request][log.py:230][ERROR][Internal Server Error: /logistic/LogisticWorkCodeName]
Traceback (most recent call last):
  File "D:\zhouzhi\gitlit_code\logistic_tracking_system\logistic_tracking_system\lts\views.py", line 4245, in get
    drs = db.execute_sql(conn, sql)
  File "D:\zhouzhi\gitlit_code\logistic_tracking_system\logistic_tracking_system\common\db.py", line 45, in execute_sql
    cursor.execute(sql)
  File "C:\Users\zhi.zhou\Anaconda3\envs\lts\lib\site-packages\pymysql\cursors.py", line 148, in execute
    result = self._query(query)
  File "C:\Users\zhi.zhou\Anaconda3\envs\lts\lib\site-packages\pymysql\cursors.py", line 310, in _query
    conn.query(q)
  File "C:\Users\zhi.zhou\Anaconda3\envs\lts\lib\site-packages\pymysql\connections.py", line 548, in query
    self._affected_rows = self._read_query_result(unbuffered=unbuffered)
  File "C:\Users\zhi.zhou\Anaconda3\envs\lts\lib\site-packages\pymysql\connections.py", line 775, in _read_query_result
    result.read()
  File "C:\Users\zhi.zhou\Anaconda3\envs\lts\lib\site-packages\pymysql\connections.py", line 1156, in read
    first_packet = self.connection._read_packet()
  File "C:\Users\zhi.zhou\Anaconda3\envs\lts\lib\site-packages\pymysql\connections.py", line 725, in _read_packet
    packet.raise_for_error()
  File "C:\Users\zhi.zhou\Anaconda3\envs\lts\lib\site-packages\pymysql\protocol.py", line 221, in raise_for_error
    err.raise_mysql_exception(self._data)
  File "C:\Users\zhi.zhou\Anaconda3\envs\lts\lib\site-packages\pymysql\err.py", line 143, in raise_mysql_exception
    raise errorclass(errno, errval)
pymysql.err.OperationalError: (1046, 'No database selected')

During handling of the above exception, another exception occurred:

Traceback (most recent call last):
  File "C:\Users\zhi.zhou\Anaconda3\envs\lts\lib\site-packages\django\core\handlers\exception.py", line 47, in inner
    response = get_response(request)
  File "C:\Users\zhi.zhou\Anaconda3\envs\lts\lib\site-packages\django\core\handlers\base.py", line 181, in _get_response
    response = wrapped_callback(request, *callback_args, **callback_kwargs)
  File "C:\Users\zhi.zhou\Anaconda3\envs\lts\lib\site-packages\django\views\generic\base.py", line 70, in view
    return self.dispatch(request, *args, **kwargs)
  File "C:\Users\zhi.zhou\Anaconda3\envs\lts\lib\site-packages\django\views\generic\base.py", line 98, in dispatch
    return handler(request, *args, **kwargs)
  File "D:\zhouzhi\gitlit_code\logistic_tracking_system\logistic_tracking_system\lts\views.py", line 4259, in get
    data = json.dumps(data)
  File "C:\Users\zhi.zhou\Anaconda3\envs\lts\lib\json\__init__.py", line 231, in dumps
    return _default_encoder.encode(obj)
  File "C:\Users\zhi.zhou\Anaconda3\envs\lts\lib\json\encoder.py", line 199, in encode
    chunks = self.iterencode(o, _one_shot=True)
  File "C:\Users\zhi.zhou\Anaconda3\envs\lts\lib\json\encoder.py", line 257, in iterencode
    return _iterencode(o, 0)
  File "C:\Users\zhi.zhou\Anaconda3\envs\lts\lib\json\encoder.py", line 180, in default
    o.__class__.__name__)
TypeError: Object of type 'OperationalError' is not JSON serializable
[2021-07-27 10:16:09,200][Thread-15:19468][task_id:django.request][log.py:230][ERROR][Internal Server Error: /logistic/LogisticProcessDeal]
Traceback (most recent call last):
  File "D:\zhouzhi\gitlit_code\logistic_tracking_system\logistic_tracking_system\lts\views.py", line 3774, in get
    if len(production_name) == 0 and len(prodect_code) == 0 and len(work_id) == 0:
TypeError: object of type 'NoneType' has no len()

During handling of the above exception, another exception occurred:

Traceback (most recent call last):
  File "C:\Users\zhi.zhou\Anaconda3\envs\lts\lib\site-packages\django\core\handlers\exception.py", line 47, in inner
    response = get_response(request)
  File "C:\Users\zhi.zhou\Anaconda3\envs\lts\lib\site-packages\django\core\handlers\base.py", line 181, in _get_response
    response = wrapped_callback(request, *callback_args, **callback_kwargs)
  File "C:\Users\zhi.zhou\Anaconda3\envs\lts\lib\site-packages\django\views\generic\base.py", line 70, in view
    return self.dispatch(request, *args, **kwargs)
  File "C:\Users\zhi.zhou\Anaconda3\envs\lts\lib\site-packages\django\views\generic\base.py", line 98, in dispatch
    return handler(request, *args, **kwargs)
  File "D:\zhouzhi\gitlit_code\logistic_tracking_system\logistic_tracking_system\lts\views.py", line 4042, in get
    data = json.dumps(data)
  File "C:\Users\zhi.zhou\Anaconda3\envs\lts\lib\json\__init__.py", line 231, in dumps
    return _default_encoder.encode(obj)
  File "C:\Users\zhi.zhou\Anaconda3\envs\lts\lib\json\encoder.py", line 199, in encode
    chunks = self.iterencode(o, _one_shot=True)
  File "C:\Users\zhi.zhou\Anaconda3\envs\lts\lib\json\encoder.py", line 257, in iterencode
    return _iterencode(o, 0)
  File "C:\Users\zhi.zhou\Anaconda3\envs\lts\lib\json\encoder.py", line 180, in default
    o.__class__.__name__)
TypeError: Object of type 'TypeError' is not JSON serializable
[2021-07-27 10:16:15,935][Thread-15:19468][task_id:django.request][log.py:230][ERROR][Internal Server Error: /logistic/LogisticProcessDeal]
Traceback (most recent call last):
  File "D:\zhouzhi\gitlit_code\logistic_tracking_system\logistic_tracking_system\lts\views.py", line 3774, in get
    if len(production_name) == 0 and len(prodect_code) == 0 and len(work_id) == 0:
TypeError: object of type 'NoneType' has no len()

During handling of the above exception, another exception occurred:

Traceback (most recent call last):
  File "C:\Users\zhi.zhou\Anaconda3\envs\lts\lib\site-packages\django\core\handlers\exception.py", line 47, in inner
    response = get_response(request)
  File "C:\Users\zhi.zhou\Anaconda3\envs\lts\lib\site-packages\django\core\handlers\base.py", line 181, in _get_response
    response = wrapped_callback(request, *callback_args, **callback_kwargs)
  File "C:\Users\zhi.zhou\Anaconda3\envs\lts\lib\site-packages\django\views\generic\base.py", line 70, in view
    return self.dispatch(request, *args, **kwargs)
  File "C:\Users\zhi.zhou\Anaconda3\envs\lts\lib\site-packages\django\views\generic\base.py", line 98, in dispatch
    return handler(request, *args, **kwargs)
  File "D:\zhouzhi\gitlit_code\logistic_tracking_system\logistic_tracking_system\lts\views.py", line 4042, in get
    data = json.dumps(data)
  File "C:\Users\zhi.zhou\Anaconda3\envs\lts\lib\json\__init__.py", line 231, in dumps
    return _default_encoder.encode(obj)
  File "C:\Users\zhi.zhou\Anaconda3\envs\lts\lib\json\encoder.py", line 199, in encode
    chunks = self.iterencode(o, _one_shot=True)
  File "C:\Users\zhi.zhou\Anaconda3\envs\lts\lib\json\encoder.py", line 257, in iterencode
    return _iterencode(o, 0)
  File "C:\Users\zhi.zhou\Anaconda3\envs\lts\lib\json\encoder.py", line 180, in default
    o.__class__.__name__)
TypeError: Object of type 'TypeError' is not JSON serializable
[2021-07-27 10:17:02,544][Thread-15:19468][task_id:django.request][log.py:230][ERROR][Internal Server Error: /logistic/LogisticProcessDeal]
Traceback (most recent call last):
  File "D:\zhouzhi\gitlit_code\logistic_tracking_system\logistic_tracking_system\lts\views.py", line 3774, in get
    if len(production_name) == 0 and len(prodect_code) == 0 and len(work_id) == 0:
TypeError: object of type 'NoneType' has no len()

During handling of the above exception, another exception occurred:

Traceback (most recent call last):
  File "C:\Users\zhi.zhou\Anaconda3\envs\lts\lib\site-packages\django\core\handlers\exception.py", line 47, in inner
    response = get_response(request)
  File "C:\Users\zhi.zhou\Anaconda3\envs\lts\lib\site-packages\django\core\handlers\base.py", line 181, in _get_response
    response = wrapped_callback(request, *callback_args, **callback_kwargs)
  File "C:\Users\zhi.zhou\Anaconda3\envs\lts\lib\site-packages\django\views\generic\base.py", line 70, in view
    return self.dispatch(request, *args, **kwargs)
  File "C:\Users\zhi.zhou\Anaconda3\envs\lts\lib\site-packages\django\views\generic\base.py", line 98, in dispatch
    return handler(request, *args, **kwargs)
  File "D:\zhouzhi\gitlit_code\logistic_tracking_system\logistic_tracking_system\lts\views.py", line 4042, in get
    data = json.dumps(data)
  File "C:\Users\zhi.zhou\Anaconda3\envs\lts\lib\json\__init__.py", line 231, in dumps
    return _default_encoder.encode(obj)
  File "C:\Users\zhi.zhou\Anaconda3\envs\lts\lib\json\encoder.py", line 199, in encode
    chunks = self.iterencode(o, _one_shot=True)
  File "C:\Users\zhi.zhou\Anaconda3\envs\lts\lib\json\encoder.py", line 257, in iterencode
    return _iterencode(o, 0)
  File "C:\Users\zhi.zhou\Anaconda3\envs\lts\lib\json\encoder.py", line 180, in default
    o.__class__.__name__)
TypeError: Object of type 'TypeError' is not JSON serializable
[2021-07-27 10:17:11,612][Thread-16:18520][task_id:django.request][log.py:230][ERROR][Internal Server Error: /logistic/LogisticWorkCodeName]
Traceback (most recent call last):
  File "D:\zhouzhi\gitlit_code\logistic_tracking_system\logistic_tracking_system\lts\views.py", line 4245, in get
    drs = db.execute_sql(conn, sql)
  File "D:\zhouzhi\gitlit_code\logistic_tracking_system\logistic_tracking_system\common\db.py", line 45, in execute_sql
    cursor.execute(sql)
  File "C:\Users\zhi.zhou\Anaconda3\envs\lts\lib\site-packages\pymysql\cursors.py", line 148, in execute
    result = self._query(query)
  File "C:\Users\zhi.zhou\Anaconda3\envs\lts\lib\site-packages\pymysql\cursors.py", line 310, in _query
    conn.query(q)
  File "C:\Users\zhi.zhou\Anaconda3\envs\lts\lib\site-packages\pymysql\connections.py", line 548, in query
    self._affected_rows = self._read_query_result(unbuffered=unbuffered)
  File "C:\Users\zhi.zhou\Anaconda3\envs\lts\lib\site-packages\pymysql\connections.py", line 775, in _read_query_result
    result.read()
  File "C:\Users\zhi.zhou\Anaconda3\envs\lts\lib\site-packages\pymysql\connections.py", line 1156, in read
    first_packet = self.connection._read_packet()
  File "C:\Users\zhi.zhou\Anaconda3\envs\lts\lib\site-packages\pymysql\connections.py", line 725, in _read_packet
    packet.raise_for_error()
  File "C:\Users\zhi.zhou\Anaconda3\envs\lts\lib\site-packages\pymysql\protocol.py", line 221, in raise_for_error
    err.raise_mysql_exception(self._data)
  File "C:\Users\zhi.zhou\Anaconda3\envs\lts\lib\site-packages\pymysql\err.py", line 143, in raise_mysql_exception
    raise errorclass(errno, errval)
pymysql.err.OperationalError: (1046, 'No database selected')

During handling of the above exception, another exception occurred:

Traceback (most recent call last):
  File "C:\Users\zhi.zhou\Anaconda3\envs\lts\lib\site-packages\django\core\handlers\exception.py", line 47, in inner
    response = get_response(request)
  File "C:\Users\zhi.zhou\Anaconda3\envs\lts\lib\site-packages\django\core\handlers\base.py", line 181, in _get_response
    response = wrapped_callback(request, *callback_args, **callback_kwargs)
  File "C:\Users\zhi.zhou\Anaconda3\envs\lts\lib\site-packages\django\views\generic\base.py", line 70, in view
    return self.dispatch(request, *args, **kwargs)
  File "C:\Users\zhi.zhou\Anaconda3\envs\lts\lib\site-packages\django\views\generic\base.py", line 98, in dispatch
    return handler(request, *args, **kwargs)
  File "D:\zhouzhi\gitlit_code\logistic_tracking_system\logistic_tracking_system\lts\views.py", line 4259, in get
    data = json.dumps(data)
  File "C:\Users\zhi.zhou\Anaconda3\envs\lts\lib\json\__init__.py", line 231, in dumps
    return _default_encoder.encode(obj)
  File "C:\Users\zhi.zhou\Anaconda3\envs\lts\lib\json\encoder.py", line 199, in encode
    chunks = self.iterencode(o, _one_shot=True)
  File "C:\Users\zhi.zhou\Anaconda3\envs\lts\lib\json\encoder.py", line 257, in iterencode
    return _iterencode(o, 0)
  File "C:\Users\zhi.zhou\Anaconda3\envs\lts\lib\json\encoder.py", line 180, in default
    o.__class__.__name__)
TypeError: Object of type 'OperationalError' is not JSON serializable
[2021-07-27 10:17:19,127][Thread-15:19468][task_id:django.request][log.py:230][ERROR][Internal Server Error: /logistic/LogisticProcessDeal]
Traceback (most recent call last):
  File "D:\zhouzhi\gitlit_code\logistic_tracking_system\logistic_tracking_system\lts\views.py", line 3774, in get
    if len(production_name) == 0 and len(prodect_code) == 0 and len(work_id) == 0:
TypeError: object of type 'NoneType' has no len()

During handling of the above exception, another exception occurred:

Traceback (most recent call last):
  File "C:\Users\zhi.zhou\Anaconda3\envs\lts\lib\site-packages\django\core\handlers\exception.py", line 47, in inner
    response = get_response(request)
  File "C:\Users\zhi.zhou\Anaconda3\envs\lts\lib\site-packages\django\core\handlers\base.py", line 181, in _get_response
    response = wrapped_callback(request, *callback_args, **callback_kwargs)
  File "C:\Users\zhi.zhou\Anaconda3\envs\lts\lib\site-packages\django\views\generic\base.py", line 70, in view
    return self.dispatch(request, *args, **kwargs)
  File "C:\Users\zhi.zhou\Anaconda3\envs\lts\lib\site-packages\django\views\generic\base.py", line 98, in dispatch
    return handler(request, *args, **kwargs)
  File "D:\zhouzhi\gitlit_code\logistic_tracking_system\logistic_tracking_system\lts\views.py", line 4042, in get
    data = json.dumps(data)
  File "C:\Users\zhi.zhou\Anaconda3\envs\lts\lib\json\__init__.py", line 231, in dumps
    return _default_encoder.encode(obj)
  File "C:\Users\zhi.zhou\Anaconda3\envs\lts\lib\json\encoder.py", line 199, in encode
    chunks = self.iterencode(o, _one_shot=True)
  File "C:\Users\zhi.zhou\Anaconda3\envs\lts\lib\json\encoder.py", line 257, in iterencode
    return _iterencode(o, 0)
  File "C:\Users\zhi.zhou\Anaconda3\envs\lts\lib\json\encoder.py", line 180, in default
    o.__class__.__name__)
TypeError: Object of type 'TypeError' is not JSON serializable
[2021-07-27 10:17:46,627][Thread-16:18520][task_id:django.request][log.py:230][ERROR][Internal Server Error: /logistic/LogisticProcessDeal]
Traceback (most recent call last):
  File "D:\zhouzhi\gitlit_code\logistic_tracking_system\logistic_tracking_system\lts\views.py", line 3774, in get
    if len(production_name) == 0 and len(prodect_code) == 0 and len(work_id) == 0:
TypeError: object of type 'NoneType' has no len()

During handling of the above exception, another exception occurred:

Traceback (most recent call last):
  File "C:\Users\zhi.zhou\Anaconda3\envs\lts\lib\site-packages\django\core\handlers\exception.py", line 47, in inner
    response = get_response(request)
  File "C:\Users\zhi.zhou\Anaconda3\envs\lts\lib\site-packages\django\core\handlers\base.py", line 181, in _get_response
    response = wrapped_callback(request, *callback_args, **callback_kwargs)
  File "C:\Users\zhi.zhou\Anaconda3\envs\lts\lib\site-packages\django\views\generic\base.py", line 70, in view
    return self.dispatch(request, *args, **kwargs)
  File "C:\Users\zhi.zhou\Anaconda3\envs\lts\lib\site-packages\django\views\generic\base.py", line 98, in dispatch
    return handler(request, *args, **kwargs)
  File "D:\zhouzhi\gitlit_code\logistic_tracking_system\logistic_tracking_system\lts\views.py", line 4042, in get
    data = json.dumps(data)
  File "C:\Users\zhi.zhou\Anaconda3\envs\lts\lib\json\__init__.py", line 231, in dumps
    return _default_encoder.encode(obj)
  File "C:\Users\zhi.zhou\Anaconda3\envs\lts\lib\json\encoder.py", line 199, in encode
    chunks = self.iterencode(o, _one_shot=True)
  File "C:\Users\zhi.zhou\Anaconda3\envs\lts\lib\json\encoder.py", line 257, in iterencode
    return _iterencode(o, 0)
  File "C:\Users\zhi.zhou\Anaconda3\envs\lts\lib\json\encoder.py", line 180, in default
    o.__class__.__name__)
TypeError: Object of type 'TypeError' is not JSON serializable
[2021-07-27 10:20:34,545][Thread-1:9956][task_id:django.request][log.py:230][ERROR][Internal Server Error: /logistic/LogisticProcessDeal]
Traceback (most recent call last):
  File "D:\zhouzhi\gitlit_code\logistic_tracking_system\logistic_tracking_system\lts\views.py", line 3774, in get
    if len(production_name) == 0 and len(prodect_code) == 0 and len(work_id) == 0:
TypeError: object of type 'NoneType' has no len()

During handling of the above exception, another exception occurred:

Traceback (most recent call last):
  File "C:\Users\zhi.zhou\Anaconda3\envs\lts\lib\site-packages\django\core\handlers\exception.py", line 47, in inner
    response = get_response(request)
  File "C:\Users\zhi.zhou\Anaconda3\envs\lts\lib\site-packages\django\core\handlers\base.py", line 181, in _get_response
    response = wrapped_callback(request, *callback_args, **callback_kwargs)
  File "C:\Users\zhi.zhou\Anaconda3\envs\lts\lib\site-packages\django\views\generic\base.py", line 70, in view
    return self.dispatch(request, *args, **kwargs)
  File "C:\Users\zhi.zhou\Anaconda3\envs\lts\lib\site-packages\django\views\generic\base.py", line 98, in dispatch
    return handler(request, *args, **kwargs)
  File "D:\zhouzhi\gitlit_code\logistic_tracking_system\logistic_tracking_system\lts\views.py", line 4042, in get
    data = json.dumps(data)
  File "C:\Users\zhi.zhou\Anaconda3\envs\lts\lib\json\__init__.py", line 231, in dumps
    return _default_encoder.encode(obj)
  File "C:\Users\zhi.zhou\Anaconda3\envs\lts\lib\json\encoder.py", line 199, in encode
    chunks = self.iterencode(o, _one_shot=True)
  File "C:\Users\zhi.zhou\Anaconda3\envs\lts\lib\json\encoder.py", line 257, in iterencode
    return _iterencode(o, 0)
  File "C:\Users\zhi.zhou\Anaconda3\envs\lts\lib\json\encoder.py", line 180, in default
    o.__class__.__name__)
TypeError: Object of type 'TypeError' is not JSON serializable
[2021-07-27 10:20:49,480][Thread-1:12752][task_id:django.request][log.py:230][ERROR][Internal Server Error: /logistic/LogisticProcessDeal]
Traceback (most recent call last):
  File "D:\zhouzhi\gitlit_code\logistic_tracking_system\logistic_tracking_system\lts\views.py", line 3774, in get
    if len(production_name) == 0 and len(prodect_code) == 0 and len(work_id) == 0:
TypeError: object of type 'NoneType' has no len()

During handling of the above exception, another exception occurred:

Traceback (most recent call last):
  File "C:\Users\zhi.zhou\Anaconda3\envs\lts\lib\site-packages\django\core\handlers\exception.py", line 47, in inner
    response = get_response(request)
  File "C:\Users\zhi.zhou\Anaconda3\envs\lts\lib\site-packages\django\core\handlers\base.py", line 181, in _get_response
    response = wrapped_callback(request, *callback_args, **callback_kwargs)
  File "C:\Users\zhi.zhou\Anaconda3\envs\lts\lib\site-packages\django\views\generic\base.py", line 70, in view
    return self.dispatch(request, *args, **kwargs)
  File "C:\Users\zhi.zhou\Anaconda3\envs\lts\lib\site-packages\django\views\generic\base.py", line 98, in dispatch
    return handler(request, *args, **kwargs)
  File "D:\zhouzhi\gitlit_code\logistic_tracking_system\logistic_tracking_system\lts\views.py", line 4042, in get
    data = json.dumps(data)
  File "C:\Users\zhi.zhou\Anaconda3\envs\lts\lib\json\__init__.py", line 231, in dumps
    return _default_encoder.encode(obj)
  File "C:\Users\zhi.zhou\Anaconda3\envs\lts\lib\json\encoder.py", line 199, in encode
    chunks = self.iterencode(o, _one_shot=True)
  File "C:\Users\zhi.zhou\Anaconda3\envs\lts\lib\json\encoder.py", line 257, in iterencode
    return _iterencode(o, 0)
  File "C:\Users\zhi.zhou\Anaconda3\envs\lts\lib\json\encoder.py", line 180, in default
    o.__class__.__name__)
TypeError: Object of type 'TypeError' is not JSON serializable
[2021-07-27 10:20:49,499][Thread-2:11388][task_id:django.request][log.py:230][ERROR][Internal Server Error: /logistic/LogisticProcessDeal]
Traceback (most recent call last):
  File "D:\zhouzhi\gitlit_code\logistic_tracking_system\logistic_tracking_system\lts\views.py", line 3774, in get
    if len(production_name) == 0 and len(prodect_code) == 0 and len(work_id) == 0:
TypeError: object of type 'NoneType' has no len()

During handling of the above exception, another exception occurred:

Traceback (most recent call last):
  File "C:\Users\zhi.zhou\Anaconda3\envs\lts\lib\site-packages\django\core\handlers\exception.py", line 47, in inner
    response = get_response(request)
  File "C:\Users\zhi.zhou\Anaconda3\envs\lts\lib\site-packages\django\core\handlers\base.py", line 181, in _get_response
    response = wrapped_callback(request, *callback_args, **callback_kwargs)
  File "C:\Users\zhi.zhou\Anaconda3\envs\lts\lib\site-packages\django\views\generic\base.py", line 70, in view
    return self.dispatch(request, *args, **kwargs)
  File "C:\Users\zhi.zhou\Anaconda3\envs\lts\lib\site-packages\django\views\generic\base.py", line 98, in dispatch
    return handler(request, *args, **kwargs)
  File "D:\zhouzhi\gitlit_code\logistic_tracking_system\logistic_tracking_system\lts\views.py", line 4042, in get
    data = json.dumps(data)
  File "C:\Users\zhi.zhou\Anaconda3\envs\lts\lib\json\__init__.py", line 231, in dumps
    return _default_encoder.encode(obj)
  File "C:\Users\zhi.zhou\Anaconda3\envs\lts\lib\json\encoder.py", line 199, in encode
    chunks = self.iterencode(o, _one_shot=True)
  File "C:\Users\zhi.zhou\Anaconda3\envs\lts\lib\json\encoder.py", line 257, in iterencode
    return _iterencode(o, 0)
  File "C:\Users\zhi.zhou\Anaconda3\envs\lts\lib\json\encoder.py", line 180, in default
    o.__class__.__name__)
TypeError: Object of type 'TypeError' is not JSON serializable
[2021-07-27 10:48:47,226][Thread-2:13216][task_id:django.request][log.py:230][ERROR][Internal Server Error: /logistic/LogisticProcessDeal]
Traceback (most recent call last):
  File "D:\zhouzhi\gitlit_code\logistic_tracking_system\logistic_tracking_system\lts\views.py", line 3757, in get
    work_id = request.session['session_workId']
  File "C:\Users\zhi.zhou\Anaconda3\envs\lts\lib\site-packages\django\contrib\sessions\backends\base.py", line 65, in __getitem__
    return self._session[key]
KeyError: 'session_workId'

During handling of the above exception, another exception occurred:

Traceback (most recent call last):
  File "C:\Users\zhi.zhou\Anaconda3\envs\lts\lib\site-packages\django\core\handlers\exception.py", line 47, in inner
    response = get_response(request)
  File "C:\Users\zhi.zhou\Anaconda3\envs\lts\lib\site-packages\django\core\handlers\base.py", line 181, in _get_response
    response = wrapped_callback(request, *callback_args, **callback_kwargs)
  File "C:\Users\zhi.zhou\Anaconda3\envs\lts\lib\site-packages\django\views\generic\base.py", line 70, in view
    return self.dispatch(request, *args, **kwargs)
  File "C:\Users\zhi.zhou\Anaconda3\envs\lts\lib\site-packages\django\views\generic\base.py", line 98, in dispatch
    return handler(request, *args, **kwargs)
  File "D:\zhouzhi\gitlit_code\logistic_tracking_system\logistic_tracking_system\lts\views.py", line 4093, in get
    data = json.dumps(data)
  File "C:\Users\zhi.zhou\Anaconda3\envs\lts\lib\json\__init__.py", line 231, in dumps
    return _default_encoder.encode(obj)
  File "C:\Users\zhi.zhou\Anaconda3\envs\lts\lib\json\encoder.py", line 199, in encode
    chunks = self.iterencode(o, _one_shot=True)
  File "C:\Users\zhi.zhou\Anaconda3\envs\lts\lib\json\encoder.py", line 257, in iterencode
    return _iterencode(o, 0)
  File "C:\Users\zhi.zhou\Anaconda3\envs\lts\lib\json\encoder.py", line 180, in default
    o.__class__.__name__)
TypeError: Object of type 'KeyError' is not JSON serializable
[2021-07-27 10:48:51,240][Thread-2:13216][task_id:django.request][log.py:230][ERROR][Internal Server Error: /logistic/LogisticProcessDeal]
Traceback (most recent call last):
  File "D:\zhouzhi\gitlit_code\logistic_tracking_system\logistic_tracking_system\lts\views.py", line 3757, in get
    work_id = request.session['session_workId']
  File "C:\Users\zhi.zhou\Anaconda3\envs\lts\lib\site-packages\django\contrib\sessions\backends\base.py", line 65, in __getitem__
    return self._session[key]
KeyError: 'session_workId'

During handling of the above exception, another exception occurred:

Traceback (most recent call last):
  File "C:\Users\zhi.zhou\Anaconda3\envs\lts\lib\site-packages\django\core\handlers\exception.py", line 47, in inner
    response = get_response(request)
  File "C:\Users\zhi.zhou\Anaconda3\envs\lts\lib\site-packages\django\core\handlers\base.py", line 181, in _get_response
    response = wrapped_callback(request, *callback_args, **callback_kwargs)
  File "C:\Users\zhi.zhou\Anaconda3\envs\lts\lib\site-packages\django\views\generic\base.py", line 70, in view
    return self.dispatch(request, *args, **kwargs)
  File "C:\Users\zhi.zhou\Anaconda3\envs\lts\lib\site-packages\django\views\generic\base.py", line 98, in dispatch
    return handler(request, *args, **kwargs)
  File "D:\zhouzhi\gitlit_code\logistic_tracking_system\logistic_tracking_system\lts\views.py", line 4093, in get
    data = json.dumps(data)
  File "C:\Users\zhi.zhou\Anaconda3\envs\lts\lib\json\__init__.py", line 231, in dumps
    return _default_encoder.encode(obj)
  File "C:\Users\zhi.zhou\Anaconda3\envs\lts\lib\json\encoder.py", line 199, in encode
    chunks = self.iterencode(o, _one_shot=True)
  File "C:\Users\zhi.zhou\Anaconda3\envs\lts\lib\json\encoder.py", line 257, in iterencode
    return _iterencode(o, 0)
  File "C:\Users\zhi.zhou\Anaconda3\envs\lts\lib\json\encoder.py", line 180, in default
    o.__class__.__name__)
TypeError: Object of type 'KeyError' is not JSON serializable
[2021-07-27 11:07:26,636][Thread-4:20392][task_id:django.request][log.py:230][ERROR][Internal Server Error: /logistic/LogisticProductTransitInfo]
Traceback (most recent call last):
  File "D:\zhouzhi\gitlit_code\logistic_tracking_system\logistic_tracking_system\lts\views.py", line 4752, in get
    work_code = drss[0][0]
IndexError: tuple index out of range

During handling of the above exception, another exception occurred:

Traceback (most recent call last):
  File "C:\Users\zhi.zhou\Anaconda3\envs\lts\lib\site-packages\django\core\handlers\exception.py", line 47, in inner
    response = get_response(request)
  File "C:\Users\zhi.zhou\Anaconda3\envs\lts\lib\site-packages\django\core\handlers\base.py", line 181, in _get_response
    response = wrapped_callback(request, *callback_args, **callback_kwargs)
  File "C:\Users\zhi.zhou\Anaconda3\envs\lts\lib\site-packages\django\views\generic\base.py", line 70, in view
    return self.dispatch(request, *args, **kwargs)
  File "C:\Users\zhi.zhou\Anaconda3\envs\lts\lib\site-packages\django\views\generic\base.py", line 98, in dispatch
    return handler(request, *args, **kwargs)
  File "D:\zhouzhi\gitlit_code\logistic_tracking_system\logistic_tracking_system\lts\views.py", line 4886, in get
    data = json.dumps(data)
  File "C:\Users\zhi.zhou\Anaconda3\envs\lts\lib\json\__init__.py", line 231, in dumps
    return _default_encoder.encode(obj)
  File "C:\Users\zhi.zhou\Anaconda3\envs\lts\lib\json\encoder.py", line 199, in encode
    chunks = self.iterencode(o, _one_shot=True)
  File "C:\Users\zhi.zhou\Anaconda3\envs\lts\lib\json\encoder.py", line 257, in iterencode
    return _iterencode(o, 0)
  File "C:\Users\zhi.zhou\Anaconda3\envs\lts\lib\json\encoder.py", line 180, in default
    o.__class__.__name__)
TypeError: Object of type 'IndexError' is not JSON serializable
[2021-07-27 12:38:43,520][Thread-21:19772][task_id:django.request][log.py:230][ERROR][Internal Server Error: /logistic/LogisticProductPlanCodeName]
Traceback (most recent call last):
  File "D:\zhouzhi\gitlit_code\logistic_tracking_system\logistic_tracking_system\lts\views.py", line 4250, in get
    drs = db.execute_sql(conn, sql)
  File "D:\zhouzhi\gitlit_code\logistic_tracking_system\logistic_tracking_system\common\db.py", line 45, in execute_sql
    cursor.execute(sql)
  File "C:\Users\zhi.zhou\Anaconda3\envs\lts\lib\site-packages\pymysql\cursors.py", line 148, in execute
    result = self._query(query)
  File "C:\Users\zhi.zhou\Anaconda3\envs\lts\lib\site-packages\pymysql\cursors.py", line 310, in _query
    conn.query(q)
  File "C:\Users\zhi.zhou\Anaconda3\envs\lts\lib\site-packages\pymysql\connections.py", line 548, in query
    self._affected_rows = self._read_query_result(unbuffered=unbuffered)
  File "C:\Users\zhi.zhou\Anaconda3\envs\lts\lib\site-packages\pymysql\connections.py", line 775, in _read_query_result
    result.read()
  File "C:\Users\zhi.zhou\Anaconda3\envs\lts\lib\site-packages\pymysql\connections.py", line 1156, in read
    first_packet = self.connection._read_packet()
  File "C:\Users\zhi.zhou\Anaconda3\envs\lts\lib\site-packages\pymysql\connections.py", line 725, in _read_packet
    packet.raise_for_error()
  File "C:\Users\zhi.zhou\Anaconda3\envs\lts\lib\site-packages\pymysql\protocol.py", line 221, in raise_for_error
    err.raise_mysql_exception(self._data)
  File "C:\Users\zhi.zhou\Anaconda3\envs\lts\lib\site-packages\pymysql\err.py", line 143, in raise_mysql_exception
    raise errorclass(errno, errval)
pymysql.err.OperationalError: (1046, 'No database selected')

During handling of the above exception, another exception occurred:

Traceback (most recent call last):
  File "C:\Users\zhi.zhou\Anaconda3\envs\lts\lib\site-packages\django\core\handlers\exception.py", line 47, in inner
    response = get_response(request)
  File "C:\Users\zhi.zhou\Anaconda3\envs\lts\lib\site-packages\django\core\handlers\base.py", line 181, in _get_response
    response = wrapped_callback(request, *callback_args, **callback_kwargs)
  File "C:\Users\zhi.zhou\Anaconda3\envs\lts\lib\site-packages\django\views\generic\base.py", line 70, in view
    return self.dispatch(request, *args, **kwargs)
  File "C:\Users\zhi.zhou\Anaconda3\envs\lts\lib\site-packages\django\views\generic\base.py", line 98, in dispatch
    return handler(request, *args, **kwargs)
  File "D:\zhouzhi\gitlit_code\logistic_tracking_system\logistic_tracking_system\lts\views.py", line 4263, in get
    data = json.dumps(data)
  File "C:\Users\zhi.zhou\Anaconda3\envs\lts\lib\json\__init__.py", line 231, in dumps
    return _default_encoder.encode(obj)
  File "C:\Users\zhi.zhou\Anaconda3\envs\lts\lib\json\encoder.py", line 199, in encode
    chunks = self.iterencode(o, _one_shot=True)
  File "C:\Users\zhi.zhou\Anaconda3\envs\lts\lib\json\encoder.py", line 257, in iterencode
    return _iterencode(o, 0)
  File "C:\Users\zhi.zhou\Anaconda3\envs\lts\lib\json\encoder.py", line 180, in default
    o.__class__.__name__)
TypeError: Object of type 'OperationalError' is not JSON serializable
[2021-07-27 12:53:15,346][Thread-25:18584][task_id:django.request][log.py:230][ERROR][Internal Server Error: /logistic/LogisticProductPlanCodeName]
Traceback (most recent call last):
  File "D:\zhouzhi\gitlit_code\logistic_tracking_system\logistic_tracking_system\lts\views.py", line 4250, in get
    drs = db.execute_sql(conn, sql)
  File "D:\zhouzhi\gitlit_code\logistic_tracking_system\logistic_tracking_system\common\db.py", line 45, in execute_sql
    cursor.execute(sql)
  File "C:\Users\zhi.zhou\Anaconda3\envs\lts\lib\site-packages\pymysql\cursors.py", line 148, in execute
    result = self._query(query)
  File "C:\Users\zhi.zhou\Anaconda3\envs\lts\lib\site-packages\pymysql\cursors.py", line 310, in _query
    conn.query(q)
  File "C:\Users\zhi.zhou\Anaconda3\envs\lts\lib\site-packages\pymysql\connections.py", line 548, in query
    self._affected_rows = self._read_query_result(unbuffered=unbuffered)
  File "C:\Users\zhi.zhou\Anaconda3\envs\lts\lib\site-packages\pymysql\connections.py", line 775, in _read_query_result
    result.read()
  File "C:\Users\zhi.zhou\Anaconda3\envs\lts\lib\site-packages\pymysql\connections.py", line 1156, in read
    first_packet = self.connection._read_packet()
  File "C:\Users\zhi.zhou\Anaconda3\envs\lts\lib\site-packages\pymysql\connections.py", line 725, in _read_packet
    packet.raise_for_error()
  File "C:\Users\zhi.zhou\Anaconda3\envs\lts\lib\site-packages\pymysql\protocol.py", line 221, in raise_for_error
    err.raise_mysql_exception(self._data)
  File "C:\Users\zhi.zhou\Anaconda3\envs\lts\lib\site-packages\pymysql\err.py", line 143, in raise_mysql_exception
    raise errorclass(errno, errval)
pymysql.err.OperationalError: (1046, 'No database selected')

During handling of the above exception, another exception occurred:

Traceback (most recent call last):
  File "C:\Users\zhi.zhou\Anaconda3\envs\lts\lib\site-packages\django\core\handlers\exception.py", line 47, in inner
    response = get_response(request)
  File "C:\Users\zhi.zhou\Anaconda3\envs\lts\lib\site-packages\django\core\handlers\base.py", line 181, in _get_response
    response = wrapped_callback(request, *callback_args, **callback_kwargs)
  File "C:\Users\zhi.zhou\Anaconda3\envs\lts\lib\site-packages\django\views\generic\base.py", line 70, in view
    return self.dispatch(request, *args, **kwargs)
  File "C:\Users\zhi.zhou\Anaconda3\envs\lts\lib\site-packages\django\views\generic\base.py", line 98, in dispatch
    return handler(request, *args, **kwargs)
  File "D:\zhouzhi\gitlit_code\logistic_tracking_system\logistic_tracking_system\lts\views.py", line 4263, in get
    data = json.dumps(data)
  File "C:\Users\zhi.zhou\Anaconda3\envs\lts\lib\json\__init__.py", line 231, in dumps
    return _default_encoder.encode(obj)
  File "C:\Users\zhi.zhou\Anaconda3\envs\lts\lib\json\encoder.py", line 199, in encode
    chunks = self.iterencode(o, _one_shot=True)
  File "C:\Users\zhi.zhou\Anaconda3\envs\lts\lib\json\encoder.py", line 257, in iterencode
    return _iterencode(o, 0)
  File "C:\Users\zhi.zhou\Anaconda3\envs\lts\lib\json\encoder.py", line 180, in default
    o.__class__.__name__)
TypeError: Object of type 'OperationalError' is not JSON serializable
[2021-07-27 13:17:18,329][Thread-32:3296][task_id:django.request][log.py:230][ERROR][Internal Server Error: /logistic/LogisticProductPlanCodeName]
Traceback (most recent call last):
  File "D:\zhouzhi\gitlit_code\logistic_tracking_system\logistic_tracking_system\lts\views.py", line 4250, in get
    drs = db.execute_sql(conn, sql)
  File "D:\zhouzhi\gitlit_code\logistic_tracking_system\logistic_tracking_system\common\db.py", line 45, in execute_sql
    cursor.execute(sql)
  File "C:\Users\zhi.zhou\Anaconda3\envs\lts\lib\site-packages\pymysql\cursors.py", line 148, in execute
    result = self._query(query)
  File "C:\Users\zhi.zhou\Anaconda3\envs\lts\lib\site-packages\pymysql\cursors.py", line 310, in _query
    conn.query(q)
  File "C:\Users\zhi.zhou\Anaconda3\envs\lts\lib\site-packages\pymysql\connections.py", line 548, in query
    self._affected_rows = self._read_query_result(unbuffered=unbuffered)
  File "C:\Users\zhi.zhou\Anaconda3\envs\lts\lib\site-packages\pymysql\connections.py", line 775, in _read_query_result
    result.read()
  File "C:\Users\zhi.zhou\Anaconda3\envs\lts\lib\site-packages\pymysql\connections.py", line 1156, in read
    first_packet = self.connection._read_packet()
  File "C:\Users\zhi.zhou\Anaconda3\envs\lts\lib\site-packages\pymysql\connections.py", line 725, in _read_packet
    packet.raise_for_error()
  File "C:\Users\zhi.zhou\Anaconda3\envs\lts\lib\site-packages\pymysql\protocol.py", line 221, in raise_for_error
    err.raise_mysql_exception(self._data)
  File "C:\Users\zhi.zhou\Anaconda3\envs\lts\lib\site-packages\pymysql\err.py", line 143, in raise_mysql_exception
    raise errorclass(errno, errval)
pymysql.err.OperationalError: (1046, 'No database selected')

During handling of the above exception, another exception occurred:

Traceback (most recent call last):
  File "C:\Users\zhi.zhou\Anaconda3\envs\lts\lib\site-packages\django\core\handlers\exception.py", line 47, in inner
    response = get_response(request)
  File "C:\Users\zhi.zhou\Anaconda3\envs\lts\lib\site-packages\django\core\handlers\base.py", line 181, in _get_response
    response = wrapped_callback(request, *callback_args, **callback_kwargs)
  File "C:\Users\zhi.zhou\Anaconda3\envs\lts\lib\site-packages\django\views\generic\base.py", line 70, in view
    return self.dispatch(request, *args, **kwargs)
  File "C:\Users\zhi.zhou\Anaconda3\envs\lts\lib\site-packages\django\views\generic\base.py", line 98, in dispatch
    return handler(request, *args, **kwargs)
  File "D:\zhouzhi\gitlit_code\logistic_tracking_system\logistic_tracking_system\lts\views.py", line 4263, in get
    data = json.dumps(data)
  File "C:\Users\zhi.zhou\Anaconda3\envs\lts\lib\json\__init__.py", line 231, in dumps
    return _default_encoder.encode(obj)
  File "C:\Users\zhi.zhou\Anaconda3\envs\lts\lib\json\encoder.py", line 199, in encode
    chunks = self.iterencode(o, _one_shot=True)
  File "C:\Users\zhi.zhou\Anaconda3\envs\lts\lib\json\encoder.py", line 257, in iterencode
    return _iterencode(o, 0)
  File "C:\Users\zhi.zhou\Anaconda3\envs\lts\lib\json\encoder.py", line 180, in default
    o.__class__.__name__)
TypeError: Object of type 'OperationalError' is not JSON serializable
[2021-07-27 13:17:18,990][Thread-32:3296][task_id:django.request][log.py:230][ERROR][Internal Server Error: /logistic/LogisticProductPlanCodeName]
Traceback (most recent call last):
  File "D:\zhouzhi\gitlit_code\logistic_tracking_system\logistic_tracking_system\lts\views.py", line 4250, in get
    drs = db.execute_sql(conn, sql)
  File "D:\zhouzhi\gitlit_code\logistic_tracking_system\logistic_tracking_system\common\db.py", line 45, in execute_sql
    cursor.execute(sql)
  File "C:\Users\zhi.zhou\Anaconda3\envs\lts\lib\site-packages\pymysql\cursors.py", line 148, in execute
    result = self._query(query)
  File "C:\Users\zhi.zhou\Anaconda3\envs\lts\lib\site-packages\pymysql\cursors.py", line 310, in _query
    conn.query(q)
  File "C:\Users\zhi.zhou\Anaconda3\envs\lts\lib\site-packages\pymysql\connections.py", line 548, in query
    self._affected_rows = self._read_query_result(unbuffered=unbuffered)
  File "C:\Users\zhi.zhou\Anaconda3\envs\lts\lib\site-packages\pymysql\connections.py", line 775, in _read_query_result
    result.read()
  File "C:\Users\zhi.zhou\Anaconda3\envs\lts\lib\site-packages\pymysql\connections.py", line 1156, in read
    first_packet = self.connection._read_packet()
  File "C:\Users\zhi.zhou\Anaconda3\envs\lts\lib\site-packages\pymysql\connections.py", line 725, in _read_packet
    packet.raise_for_error()
  File "C:\Users\zhi.zhou\Anaconda3\envs\lts\lib\site-packages\pymysql\protocol.py", line 221, in raise_for_error
    err.raise_mysql_exception(self._data)
  File "C:\Users\zhi.zhou\Anaconda3\envs\lts\lib\site-packages\pymysql\err.py", line 143, in raise_mysql_exception
    raise errorclass(errno, errval)
pymysql.err.OperationalError: (1046, 'No database selected')

During handling of the above exception, another exception occurred:

Traceback (most recent call last):
  File "C:\Users\zhi.zhou\Anaconda3\envs\lts\lib\site-packages\django\core\handlers\exception.py", line 47, in inner
    response = get_response(request)
  File "C:\Users\zhi.zhou\Anaconda3\envs\lts\lib\site-packages\django\core\handlers\base.py", line 181, in _get_response
    response = wrapped_callback(request, *callback_args, **callback_kwargs)
  File "C:\Users\zhi.zhou\Anaconda3\envs\lts\lib\site-packages\django\views\generic\base.py", line 70, in view
    return self.dispatch(request, *args, **kwargs)
  File "C:\Users\zhi.zhou\Anaconda3\envs\lts\lib\site-packages\django\views\generic\base.py", line 98, in dispatch
    return handler(request, *args, **kwargs)
  File "D:\zhouzhi\gitlit_code\logistic_tracking_system\logistic_tracking_system\lts\views.py", line 4263, in get
    data = json.dumps(data)
  File "C:\Users\zhi.zhou\Anaconda3\envs\lts\lib\json\__init__.py", line 231, in dumps
    return _default_encoder.encode(obj)
  File "C:\Users\zhi.zhou\Anaconda3\envs\lts\lib\json\encoder.py", line 199, in encode
    chunks = self.iterencode(o, _one_shot=True)
  File "C:\Users\zhi.zhou\Anaconda3\envs\lts\lib\json\encoder.py", line 257, in iterencode
    return _iterencode(o, 0)
  File "C:\Users\zhi.zhou\Anaconda3\envs\lts\lib\json\encoder.py", line 180, in default
    o.__class__.__name__)
TypeError: Object of type 'OperationalError' is not JSON serializable
[2021-07-27 13:21:39,828][Thread-38:7356][task_id:lts.views][views.py:1856][ERROR][查询产品列表失败]
[2021-07-27 14:03:32,815][Thread-2:19224][task_id:django.request][log.py:230][ERROR][Internal Server Error: /logistic/LogisticQualifiedMatterCode]
Traceback (most recent call last):
  File "D:\zhouzhi\gitlit_code\logistic_tracking_system\logistic_tracking_system\lts\views.py", line 5407, in get
    drs = db.execute_sql(conn, sql_work_id)
  File "D:\zhouzhi\gitlit_code\logistic_tracking_system\logistic_tracking_system\common\db.py", line 45, in execute_sql
    cursor.execute(sql)
  File "C:\Users\zhi.zhou\Anaconda3\envs\lts\lib\site-packages\pymysql\cursors.py", line 148, in execute
    result = self._query(query)
  File "C:\Users\zhi.zhou\Anaconda3\envs\lts\lib\site-packages\pymysql\cursors.py", line 310, in _query
    conn.query(q)
  File "C:\Users\zhi.zhou\Anaconda3\envs\lts\lib\site-packages\pymysql\connections.py", line 548, in query
    self._affected_rows = self._read_query_result(unbuffered=unbuffered)
  File "C:\Users\zhi.zhou\Anaconda3\envs\lts\lib\site-packages\pymysql\connections.py", line 775, in _read_query_result
    result.read()
  File "C:\Users\zhi.zhou\Anaconda3\envs\lts\lib\site-packages\pymysql\connections.py", line 1156, in read
    first_packet = self.connection._read_packet()
  File "C:\Users\zhi.zhou\Anaconda3\envs\lts\lib\site-packages\pymysql\connections.py", line 725, in _read_packet
    packet.raise_for_error()
  File "C:\Users\zhi.zhou\Anaconda3\envs\lts\lib\site-packages\pymysql\protocol.py", line 221, in raise_for_error
    err.raise_mysql_exception(self._data)
  File "C:\Users\zhi.zhou\Anaconda3\envs\lts\lib\site-packages\pymysql\err.py", line 143, in raise_mysql_exception
    raise errorclass(errno, errval)
pymysql.err.OperationalError: (1046, 'No database selected')

During handling of the above exception, another exception occurred:

Traceback (most recent call last):
  File "C:\Users\zhi.zhou\Anaconda3\envs\lts\lib\site-packages\django\core\handlers\exception.py", line 47, in inner
    response = get_response(request)
  File "C:\Users\zhi.zhou\Anaconda3\envs\lts\lib\site-packages\django\core\handlers\base.py", line 181, in _get_response
    response = wrapped_callback(request, *callback_args, **callback_kwargs)
  File "C:\Users\zhi.zhou\Anaconda3\envs\lts\lib\site-packages\django\views\generic\base.py", line 70, in view
    return self.dispatch(request, *args, **kwargs)
  File "C:\Users\zhi.zhou\Anaconda3\envs\lts\lib\site-packages\django\views\generic\base.py", line 98, in dispatch
    return handler(request, *args, **kwargs)
  File "D:\zhouzhi\gitlit_code\logistic_tracking_system\logistic_tracking_system\lts\views.py", line 5437, in get
    data = json.dumps(data)
  File "C:\Users\zhi.zhou\Anaconda3\envs\lts\lib\json\__init__.py", line 231, in dumps
    return _default_encoder.encode(obj)
  File "C:\Users\zhi.zhou\Anaconda3\envs\lts\lib\json\encoder.py", line 199, in encode
    chunks = self.iterencode(o, _one_shot=True)
  File "C:\Users\zhi.zhou\Anaconda3\envs\lts\lib\json\encoder.py", line 257, in iterencode
    return _iterencode(o, 0)
  File "C:\Users\zhi.zhou\Anaconda3\envs\lts\lib\json\encoder.py", line 180, in default
    o.__class__.__name__)
TypeError: Object of type 'OperationalError' is not JSON serializable
[2021-07-27 14:03:32,833][Thread-1:19020][task_id:django.request][log.py:230][ERROR][Internal Server Error: /logistic/LogisticUnqualifiedProduct]
Traceback (most recent call last):
  File "D:\zhouzhi\gitlit_code\logistic_tracking_system\logistic_tracking_system\lts\views.py", line 5236, in get
    page = int(request.GET.get("page"))
TypeError: int() argument must be a string, a bytes-like object or a number, not 'NoneType'

During handling of the above exception, another exception occurred:

Traceback (most recent call last):
  File "C:\Users\zhi.zhou\Anaconda3\envs\lts\lib\site-packages\django\core\handlers\exception.py", line 47, in inner
    response = get_response(request)
  File "C:\Users\zhi.zhou\Anaconda3\envs\lts\lib\site-packages\django\core\handlers\base.py", line 181, in _get_response
    response = wrapped_callback(request, *callback_args, **callback_kwargs)
  File "C:\Users\zhi.zhou\Anaconda3\envs\lts\lib\site-packages\django\views\generic\base.py", line 70, in view
    return self.dispatch(request, *args, **kwargs)
  File "C:\Users\zhi.zhou\Anaconda3\envs\lts\lib\site-packages\django\views\generic\base.py", line 98, in dispatch
    return handler(request, *args, **kwargs)
  File "D:\zhouzhi\gitlit_code\logistic_tracking_system\logistic_tracking_system\lts\views.py", line 5315, in get
    data = json.dumps(data)
  File "C:\Users\zhi.zhou\Anaconda3\envs\lts\lib\json\__init__.py", line 231, in dumps
    return _default_encoder.encode(obj)
  File "C:\Users\zhi.zhou\Anaconda3\envs\lts\lib\json\encoder.py", line 199, in encode
    chunks = self.iterencode(o, _one_shot=True)
  File "C:\Users\zhi.zhou\Anaconda3\envs\lts\lib\json\encoder.py", line 257, in iterencode
    return _iterencode(o, 0)
  File "C:\Users\zhi.zhou\Anaconda3\envs\lts\lib\json\encoder.py", line 180, in default
    o.__class__.__name__)
TypeError: Object of type 'TypeError' is not JSON serializable
[2021-07-27 14:03:32,892][Thread-2:19224][task_id:django.request][log.py:230][ERROR][Internal Server Error: /logistic/LogisticProductTransitInfo]
Traceback (most recent call last):
  File "D:\zhouzhi\gitlit_code\logistic_tracking_system\logistic_tracking_system\lts\views.py", line 4755, in get
    drss = db.execute_sql(conn, sql_work_code_main)
  File "D:\zhouzhi\gitlit_code\logistic_tracking_system\logistic_tracking_system\common\db.py", line 45, in execute_sql
    cursor.execute(sql)
  File "C:\Users\zhi.zhou\Anaconda3\envs\lts\lib\site-packages\pymysql\cursors.py", line 148, in execute
    result = self._query(query)
  File "C:\Users\zhi.zhou\Anaconda3\envs\lts\lib\site-packages\pymysql\cursors.py", line 310, in _query
    conn.query(q)
  File "C:\Users\zhi.zhou\Anaconda3\envs\lts\lib\site-packages\pymysql\connections.py", line 548, in query
    self._affected_rows = self._read_query_result(unbuffered=unbuffered)
  File "C:\Users\zhi.zhou\Anaconda3\envs\lts\lib\site-packages\pymysql\connections.py", line 775, in _read_query_result
    result.read()
  File "C:\Users\zhi.zhou\Anaconda3\envs\lts\lib\site-packages\pymysql\connections.py", line 1156, in read
    first_packet = self.connection._read_packet()
  File "C:\Users\zhi.zhou\Anaconda3\envs\lts\lib\site-packages\pymysql\connections.py", line 725, in _read_packet
    packet.raise_for_error()
  File "C:\Users\zhi.zhou\Anaconda3\envs\lts\lib\site-packages\pymysql\protocol.py", line 221, in raise_for_error
    err.raise_mysql_exception(self._data)
  File "C:\Users\zhi.zhou\Anaconda3\envs\lts\lib\site-packages\pymysql\err.py", line 143, in raise_mysql_exception
    raise errorclass(errno, errval)
pymysql.err.OperationalError: (1046, 'No database selected')

During handling of the above exception, another exception occurred:

Traceback (most recent call last):
  File "C:\Users\zhi.zhou\Anaconda3\envs\lts\lib\site-packages\django\core\handlers\exception.py", line 47, in inner
    response = get_response(request)
  File "C:\Users\zhi.zhou\Anaconda3\envs\lts\lib\site-packages\django\core\handlers\base.py", line 181, in _get_response
    response = wrapped_callback(request, *callback_args, **callback_kwargs)
  File "C:\Users\zhi.zhou\Anaconda3\envs\lts\lib\site-packages\django\views\generic\base.py", line 70, in view
    return self.dispatch(request, *args, **kwargs)
  File "C:\Users\zhi.zhou\Anaconda3\envs\lts\lib\site-packages\django\views\generic\base.py", line 98, in dispatch
    return handler(request, *args, **kwargs)
  File "D:\zhouzhi\gitlit_code\logistic_tracking_system\logistic_tracking_system\lts\views.py", line 4890, in get
    data = json.dumps(data)
  File "C:\Users\zhi.zhou\Anaconda3\envs\lts\lib\json\__init__.py", line 231, in dumps
    return _default_encoder.encode(obj)
  File "C:\Users\zhi.zhou\Anaconda3\envs\lts\lib\json\encoder.py", line 199, in encode
    chunks = self.iterencode(o, _one_shot=True)
  File "C:\Users\zhi.zhou\Anaconda3\envs\lts\lib\json\encoder.py", line 257, in iterencode
    return _iterencode(o, 0)
  File "C:\Users\zhi.zhou\Anaconda3\envs\lts\lib\json\encoder.py", line 180, in default
    o.__class__.__name__)
TypeError: Object of type 'OperationalError' is not JSON serializable
[2021-07-27 14:06:32,592][Thread-2:10968][task_id:lts.views][views.py:1852][ERROR][查询产品列表失败]
[2021-07-27 14:33:44,807][Thread-1:9884][task_id:django.request][log.py:230][ERROR][Internal Server Error: /logistic/LogisticProductPlanCodeName]
Traceback (most recent call last):
  File "D:\zhouzhi\gitlit_code\logistic_tracking_system\logistic_tracking_system\lts\views.py", line 4245, in get
    drs = db.execute_sql(conn, sql)
  File "D:\zhouzhi\gitlit_code\logistic_tracking_system\logistic_tracking_system\common\db.py", line 45, in execute_sql
    cursor.execute(sql)
  File "C:\Users\zhi.zhou\Anaconda3\envs\lts\lib\site-packages\pymysql\cursors.py", line 148, in execute
    result = self._query(query)
  File "C:\Users\zhi.zhou\Anaconda3\envs\lts\lib\site-packages\pymysql\cursors.py", line 310, in _query
    conn.query(q)
  File "C:\Users\zhi.zhou\Anaconda3\envs\lts\lib\site-packages\pymysql\connections.py", line 548, in query
    self._affected_rows = self._read_query_result(unbuffered=unbuffered)
  File "C:\Users\zhi.zhou\Anaconda3\envs\lts\lib\site-packages\pymysql\connections.py", line 775, in _read_query_result
    result.read()
  File "C:\Users\zhi.zhou\Anaconda3\envs\lts\lib\site-packages\pymysql\connections.py", line 1156, in read
    first_packet = self.connection._read_packet()
  File "C:\Users\zhi.zhou\Anaconda3\envs\lts\lib\site-packages\pymysql\connections.py", line 725, in _read_packet
    packet.raise_for_error()
  File "C:\Users\zhi.zhou\Anaconda3\envs\lts\lib\site-packages\pymysql\protocol.py", line 221, in raise_for_error
    err.raise_mysql_exception(self._data)
  File "C:\Users\zhi.zhou\Anaconda3\envs\lts\lib\site-packages\pymysql\err.py", line 143, in raise_mysql_exception
    raise errorclass(errno, errval)
pymysql.err.OperationalError: (1046, 'No database selected')

During handling of the above exception, another exception occurred:

Traceback (most recent call last):
  File "C:\Users\zhi.zhou\Anaconda3\envs\lts\lib\site-packages\django\core\handlers\exception.py", line 47, in inner
    response = get_response(request)
  File "C:\Users\zhi.zhou\Anaconda3\envs\lts\lib\site-packages\django\core\handlers\base.py", line 181, in _get_response
    response = wrapped_callback(request, *callback_args, **callback_kwargs)
  File "C:\Users\zhi.zhou\Anaconda3\envs\lts\lib\site-packages\django\views\generic\base.py", line 70, in view
    return self.dispatch(request, *args, **kwargs)
  File "C:\Users\zhi.zhou\Anaconda3\envs\lts\lib\site-packages\django\views\generic\base.py", line 98, in dispatch
    return handler(request, *args, **kwargs)
  File "D:\zhouzhi\gitlit_code\logistic_tracking_system\logistic_tracking_system\lts\views.py", line 4258, in get
    data = json.dumps(data)
  File "C:\Users\zhi.zhou\Anaconda3\envs\lts\lib\json\__init__.py", line 231, in dumps
    return _default_encoder.encode(obj)
  File "C:\Users\zhi.zhou\Anaconda3\envs\lts\lib\json\encoder.py", line 199, in encode
    chunks = self.iterencode(o, _one_shot=True)
  File "C:\Users\zhi.zhou\Anaconda3\envs\lts\lib\json\encoder.py", line 257, in iterencode
    return _iterencode(o, 0)
  File "C:\Users\zhi.zhou\Anaconda3\envs\lts\lib\json\encoder.py", line 180, in default
    o.__class__.__name__)
TypeError: Object of type 'OperationalError' is not JSON serializable
[2021-07-27 14:34:15,914][Thread-3:14304][task_id:django.request][log.py:230][ERROR][Internal Server Error: /logistic/LogisticWorkCodeName]
Traceback (most recent call last):
  File "D:\zhouzhi\gitlit_code\logistic_tracking_system\logistic_tracking_system\lts\views.py", line 4304, in get
    drs = db.execute_sql(conn, sql)
  File "D:\zhouzhi\gitlit_code\logistic_tracking_system\logistic_tracking_system\common\db.py", line 45, in execute_sql
    cursor.execute(sql)
  File "C:\Users\zhi.zhou\Anaconda3\envs\lts\lib\site-packages\pymysql\cursors.py", line 148, in execute
    result = self._query(query)
  File "C:\Users\zhi.zhou\Anaconda3\envs\lts\lib\site-packages\pymysql\cursors.py", line 310, in _query
    conn.query(q)
  File "C:\Users\zhi.zhou\Anaconda3\envs\lts\lib\site-packages\pymysql\connections.py", line 548, in query
    self._affected_rows = self._read_query_result(unbuffered=unbuffered)
  File "C:\Users\zhi.zhou\Anaconda3\envs\lts\lib\site-packages\pymysql\connections.py", line 775, in _read_query_result
    result.read()
  File "C:\Users\zhi.zhou\Anaconda3\envs\lts\lib\site-packages\pymysql\connections.py", line 1156, in read
    first_packet = self.connection._read_packet()
  File "C:\Users\zhi.zhou\Anaconda3\envs\lts\lib\site-packages\pymysql\connections.py", line 725, in _read_packet
    packet.raise_for_error()
  File "C:\Users\zhi.zhou\Anaconda3\envs\lts\lib\site-packages\pymysql\protocol.py", line 221, in raise_for_error
    err.raise_mysql_exception(self._data)
  File "C:\Users\zhi.zhou\Anaconda3\envs\lts\lib\site-packages\pymysql\err.py", line 143, in raise_mysql_exception
    raise errorclass(errno, errval)
pymysql.err.OperationalError: (1046, 'No database selected')

During handling of the above exception, another exception occurred:

Traceback (most recent call last):
  File "C:\Users\zhi.zhou\Anaconda3\envs\lts\lib\site-packages\django\core\handlers\exception.py", line 47, in inner
    response = get_response(request)
  File "C:\Users\zhi.zhou\Anaconda3\envs\lts\lib\site-packages\django\core\handlers\base.py", line 181, in _get_response
    response = wrapped_callback(request, *callback_args, **callback_kwargs)
  File "C:\Users\zhi.zhou\Anaconda3\envs\lts\lib\site-packages\django\views\generic\base.py", line 70, in view
    return self.dispatch(request, *args, **kwargs)
  File "C:\Users\zhi.zhou\Anaconda3\envs\lts\lib\site-packages\django\views\generic\base.py", line 98, in dispatch
    return handler(request, *args, **kwargs)
  File "D:\zhouzhi\gitlit_code\logistic_tracking_system\logistic_tracking_system\lts\views.py", line 4319, in get
    data = json.dumps(data)
  File "C:\Users\zhi.zhou\Anaconda3\envs\lts\lib\json\__init__.py", line 231, in dumps
    return _default_encoder.encode(obj)
  File "C:\Users\zhi.zhou\Anaconda3\envs\lts\lib\json\encoder.py", line 199, in encode
    chunks = self.iterencode(o, _one_shot=True)
  File "C:\Users\zhi.zhou\Anaconda3\envs\lts\lib\json\encoder.py", line 257, in iterencode
    return _iterencode(o, 0)
  File "C:\Users\zhi.zhou\Anaconda3\envs\lts\lib\json\encoder.py", line 180, in default
    o.__class__.__name__)
TypeError: Object of type 'OperationalError' is not JSON serializable
[2021-07-27 14:36:08,713][Thread-4:12188][task_id:lts.views][views.py:1853][ERROR][查询产品列表失败]
[2021-07-27 15:09:56,043][Thread-2:8376][task_id:lts.views][views.py:1606][ERROR][修改失败---->(1064, "You have an error in your SQL syntax; check the manual that corresponds to your MySQL server version for the right syntax to use near 'where matter_code = 'Im_BOM_Matter_1'' at line 3")]
[2021-07-27 15:10:06,690][Thread-2:8376][task_id:lts.views][views.py:1606][ERROR][修改失败---->(1064, "You have an error in your SQL syntax; check the manual that corresponds to your MySQL server version for the right syntax to use near 'where matter_code = 'Im_BOM_Matter_1'' at line 3")]
[2021-07-27 15:11:41,266][Thread-1:17504][task_id:lts.views][views.py:1608][ERROR][修改失败---->(1064, "You have an error in your SQL syntax; check the manual that corresponds to your MySQL server version for the right syntax to use near 'where matter_code = 'Im_BOM_Matter_1'' at line 3")]
[2021-07-27 15:27:06,808][Thread-13:1608][task_id:lts.views][views.py:3528][ERROR][创建产品详情表失败]
[2021-07-27 16:11:43,272][Thread-2:7096][task_id:lts.views][views.py:1864][ERROR][查询产品列表失败]
[2021-07-27 16:28:02,851][Thread-1:3468][task_id:django.request][log.py:230][ERROR][Internal Server Error: /logistic/LogisticNoPagePersonMatter]
Traceback (most recent call last):
  File "D:\zhouzhi\gitlit_code\logistic_tracking_system\logistic_tracking_system\lts\views.py", line 3702, in get
    dict_data["rule"] = dr[4]
IndexError: tuple index out of range

During handling of the above exception, another exception occurred:

Traceback (most recent call last):
  File "C:\Users\zhi.zhou\Anaconda3\envs\lts\lib\site-packages\django\core\handlers\exception.py", line 47, in inner
    response = get_response(request)
  File "C:\Users\zhi.zhou\Anaconda3\envs\lts\lib\site-packages\django\core\handlers\base.py", line 181, in _get_response
    response = wrapped_callback(request, *callback_args, **callback_kwargs)
  File "C:\Users\zhi.zhou\Anaconda3\envs\lts\lib\site-packages\django\views\generic\base.py", line 70, in view
    return self.dispatch(request, *args, **kwargs)
  File "C:\Users\zhi.zhou\Anaconda3\envs\lts\lib\site-packages\django\views\generic\base.py", line 98, in dispatch
    return handler(request, *args, **kwargs)
  File "D:\zhouzhi\gitlit_code\logistic_tracking_system\logistic_tracking_system\lts\views.py", line 3726, in get
    result = json.dumps(result)
  File "C:\Users\zhi.zhou\Anaconda3\envs\lts\lib\json\__init__.py", line 231, in dumps
    return _default_encoder.encode(obj)
  File "C:\Users\zhi.zhou\Anaconda3\envs\lts\lib\json\encoder.py", line 199, in encode
    chunks = self.iterencode(o, _one_shot=True)
  File "C:\Users\zhi.zhou\Anaconda3\envs\lts\lib\json\encoder.py", line 257, in iterencode
    return _iterencode(o, 0)
  File "C:\Users\zhi.zhou\Anaconda3\envs\lts\lib\json\encoder.py", line 180, in default
    o.__class__.__name__)
TypeError: Object of type 'IndexError' is not JSON serializable
[2021-07-27 16:28:16,270][Thread-1:3468][task_id:django.request][log.py:230][ERROR][Internal Server Error: /logistic/LogisticNoPagePersonMatter]
Traceback (most recent call last):
  File "D:\zhouzhi\gitlit_code\logistic_tracking_system\logistic_tracking_system\lts\views.py", line 3702, in get
    dict_data["rule"] = dr[4]
IndexError: tuple index out of range

During handling of the above exception, another exception occurred:

Traceback (most recent call last):
  File "C:\Users\zhi.zhou\Anaconda3\envs\lts\lib\site-packages\django\core\handlers\exception.py", line 47, in inner
    response = get_response(request)
  File "C:\Users\zhi.zhou\Anaconda3\envs\lts\lib\site-packages\django\core\handlers\base.py", line 181, in _get_response
    response = wrapped_callback(request, *callback_args, **callback_kwargs)
  File "C:\Users\zhi.zhou\Anaconda3\envs\lts\lib\site-packages\django\views\generic\base.py", line 70, in view
    return self.dispatch(request, *args, **kwargs)
  File "C:\Users\zhi.zhou\Anaconda3\envs\lts\lib\site-packages\django\views\generic\base.py", line 98, in dispatch
    return handler(request, *args, **kwargs)
  File "D:\zhouzhi\gitlit_code\logistic_tracking_system\logistic_tracking_system\lts\views.py", line 3726, in get
    result = json.dumps(result)
  File "C:\Users\zhi.zhou\Anaconda3\envs\lts\lib\json\__init__.py", line 231, in dumps
    return _default_encoder.encode(obj)
  File "C:\Users\zhi.zhou\Anaconda3\envs\lts\lib\json\encoder.py", line 199, in encode
    chunks = self.iterencode(o, _one_shot=True)
  File "C:\Users\zhi.zhou\Anaconda3\envs\lts\lib\json\encoder.py", line 257, in iterencode
    return _iterencode(o, 0)
  File "C:\Users\zhi.zhou\Anaconda3\envs\lts\lib\json\encoder.py", line 180, in default
    o.__class__.__name__)
TypeError: Object of type 'IndexError' is not JSON serializable
[2021-07-27 16:33:23,583][Thread-3:16984][task_id:django.request][log.py:230][ERROR][Internal Server Error: /logistic/LogisticNoPagePersonMatter]
Traceback (most recent call last):
  File "D:\zhouzhi\gitlit_code\logistic_tracking_system\logistic_tracking_system\lts\views.py", line 3702, in get
    dict_data["rule"] = dr[4]
IndexError: tuple index out of range

During handling of the above exception, another exception occurred:

Traceback (most recent call last):
  File "C:\Users\zhi.zhou\Anaconda3\envs\lts\lib\site-packages\django\core\handlers\exception.py", line 47, in inner
    response = get_response(request)
  File "C:\Users\zhi.zhou\Anaconda3\envs\lts\lib\site-packages\django\core\handlers\base.py", line 181, in _get_response
    response = wrapped_callback(request, *callback_args, **callback_kwargs)
  File "C:\Users\zhi.zhou\Anaconda3\envs\lts\lib\site-packages\django\views\generic\base.py", line 70, in view
    return self.dispatch(request, *args, **kwargs)
  File "C:\Users\zhi.zhou\Anaconda3\envs\lts\lib\site-packages\django\views\generic\base.py", line 98, in dispatch
    return handler(request, *args, **kwargs)
  File "D:\zhouzhi\gitlit_code\logistic_tracking_system\logistic_tracking_system\lts\views.py", line 3726, in get
    result = json.dumps(result)
  File "C:\Users\zhi.zhou\Anaconda3\envs\lts\lib\json\__init__.py", line 231, in dumps
    return _default_encoder.encode(obj)
  File "C:\Users\zhi.zhou\Anaconda3\envs\lts\lib\json\encoder.py", line 199, in encode
    chunks = self.iterencode(o, _one_shot=True)
  File "C:\Users\zhi.zhou\Anaconda3\envs\lts\lib\json\encoder.py", line 257, in iterencode
    return _iterencode(o, 0)
  File "C:\Users\zhi.zhou\Anaconda3\envs\lts\lib\json\encoder.py", line 180, in default
    o.__class__.__name__)
TypeError: Object of type 'IndexError' is not JSON serializable
[2021-07-27 16:33:28,164][Thread-6:6724][task_id:django.request][log.py:230][ERROR][Internal Server Error: /logistic/LogisticNoPagePersonMatter]
Traceback (most recent call last):
  File "D:\zhouzhi\gitlit_code\logistic_tracking_system\logistic_tracking_system\lts\views.py", line 3702, in get
    dict_data["rule"] = dr[4]
IndexError: tuple index out of range

During handling of the above exception, another exception occurred:

Traceback (most recent call last):
  File "C:\Users\zhi.zhou\Anaconda3\envs\lts\lib\site-packages\django\core\handlers\exception.py", line 47, in inner
    response = get_response(request)
  File "C:\Users\zhi.zhou\Anaconda3\envs\lts\lib\site-packages\django\core\handlers\base.py", line 181, in _get_response
    response = wrapped_callback(request, *callback_args, **callback_kwargs)
  File "C:\Users\zhi.zhou\Anaconda3\envs\lts\lib\site-packages\django\views\generic\base.py", line 70, in view
    return self.dispatch(request, *args, **kwargs)
  File "C:\Users\zhi.zhou\Anaconda3\envs\lts\lib\site-packages\django\views\generic\base.py", line 98, in dispatch
    return handler(request, *args, **kwargs)
  File "D:\zhouzhi\gitlit_code\logistic_tracking_system\logistic_tracking_system\lts\views.py", line 3726, in get
    result = json.dumps(result)
  File "C:\Users\zhi.zhou\Anaconda3\envs\lts\lib\json\__init__.py", line 231, in dumps
    return _default_encoder.encode(obj)
  File "C:\Users\zhi.zhou\Anaconda3\envs\lts\lib\json\encoder.py", line 199, in encode
    chunks = self.iterencode(o, _one_shot=True)
  File "C:\Users\zhi.zhou\Anaconda3\envs\lts\lib\json\encoder.py", line 257, in iterencode
    return _iterencode(o, 0)
  File "C:\Users\zhi.zhou\Anaconda3\envs\lts\lib\json\encoder.py", line 180, in default
    o.__class__.__name__)
TypeError: Object of type 'IndexError' is not JSON serializable
[2021-07-27 16:35:16,862][Thread-7:12936][task_id:django.request][log.py:230][ERROR][Internal Server Error: /logistic/LogisticNoPagePersonMatter]
Traceback (most recent call last):
  File "D:\zhouzhi\gitlit_code\logistic_tracking_system\logistic_tracking_system\lts\views.py", line 3702, in get
    dict_data["rule"] = dr[4]
IndexError: tuple index out of range

During handling of the above exception, another exception occurred:

Traceback (most recent call last):
  File "C:\Users\zhi.zhou\Anaconda3\envs\lts\lib\site-packages\django\core\handlers\exception.py", line 47, in inner
    response = get_response(request)
  File "C:\Users\zhi.zhou\Anaconda3\envs\lts\lib\site-packages\django\core\handlers\base.py", line 181, in _get_response
    response = wrapped_callback(request, *callback_args, **callback_kwargs)
  File "C:\Users\zhi.zhou\Anaconda3\envs\lts\lib\site-packages\django\views\generic\base.py", line 70, in view
    return self.dispatch(request, *args, **kwargs)
  File "C:\Users\zhi.zhou\Anaconda3\envs\lts\lib\site-packages\django\views\generic\base.py", line 98, in dispatch
    return handler(request, *args, **kwargs)
  File "D:\zhouzhi\gitlit_code\logistic_tracking_system\logistic_tracking_system\lts\views.py", line 3726, in get
    result = json.dumps(result)
  File "C:\Users\zhi.zhou\Anaconda3\envs\lts\lib\json\__init__.py", line 231, in dumps
    return _default_encoder.encode(obj)
  File "C:\Users\zhi.zhou\Anaconda3\envs\lts\lib\json\encoder.py", line 199, in encode
    chunks = self.iterencode(o, _one_shot=True)
  File "C:\Users\zhi.zhou\Anaconda3\envs\lts\lib\json\encoder.py", line 257, in iterencode
    return _iterencode(o, 0)
  File "C:\Users\zhi.zhou\Anaconda3\envs\lts\lib\json\encoder.py", line 180, in default
    o.__class__.__name__)
TypeError: Object of type 'IndexError' is not JSON serializable
[2021-07-27 17:02:30,078][Thread-16:15672][task_id:lts.views][views.py:3620][ERROR][修改失败---->(1054, "Unknown column 'status' in 'field list'")]
[2021-07-27 17:03:28,805][Thread-20:2944][task_id:lts.views][views.py:3620][ERROR][修改失败---->(1054, "Unknown column 'status' in 'field list'")]
[2021-07-27 17:04:40,024][Thread-16:15672][task_id:lts.views][views.py:3620][ERROR][修改失败---->(1054, "Unknown column 'status' in 'field list'")]
[2021-07-27 17:05:16,548][Thread-16:15672][task_id:lts.views][views.py:3620][ERROR][修改失败---->(1054, "Unknown column 'status' in 'field list'")]
[2021-07-27 17:06:49,195][Thread-23:13368][task_id:django.request][log.py:230][ERROR][Internal Server Error: /logistic/LogisticMatterNameCode]
Traceback (most recent call last):
  File "D:\zhouzhi\gitlit_code\logistic_tracking_system\logistic_tracking_system\lts\views.py", line 5096, in get
    drs = db.execute_sql(conn, sql)
  File "D:\zhouzhi\gitlit_code\logistic_tracking_system\logistic_tracking_system\common\db.py", line 45, in execute_sql
    cursor.execute(sql)
  File "C:\Users\zhi.zhou\Anaconda3\envs\lts\lib\site-packages\pymysql\cursors.py", line 148, in execute
    result = self._query(query)
  File "C:\Users\zhi.zhou\Anaconda3\envs\lts\lib\site-packages\pymysql\cursors.py", line 310, in _query
    conn.query(q)
  File "C:\Users\zhi.zhou\Anaconda3\envs\lts\lib\site-packages\pymysql\connections.py", line 548, in query
    self._affected_rows = self._read_query_result(unbuffered=unbuffered)
  File "C:\Users\zhi.zhou\Anaconda3\envs\lts\lib\site-packages\pymysql\connections.py", line 775, in _read_query_result
    result.read()
  File "C:\Users\zhi.zhou\Anaconda3\envs\lts\lib\site-packages\pymysql\connections.py", line 1156, in read
    first_packet = self.connection._read_packet()
  File "C:\Users\zhi.zhou\Anaconda3\envs\lts\lib\site-packages\pymysql\connections.py", line 725, in _read_packet
    packet.raise_for_error()
  File "C:\Users\zhi.zhou\Anaconda3\envs\lts\lib\site-packages\pymysql\protocol.py", line 221, in raise_for_error
    err.raise_mysql_exception(self._data)
  File "C:\Users\zhi.zhou\Anaconda3\envs\lts\lib\site-packages\pymysql\err.py", line 143, in raise_mysql_exception
    raise errorclass(errno, errval)
pymysql.err.OperationalError: (1054, "Unknown column 'matter_name' in 'field list'")

During handling of the above exception, another exception occurred:

Traceback (most recent call last):
  File "C:\Users\zhi.zhou\Anaconda3\envs\lts\lib\site-packages\django\core\handlers\exception.py", line 47, in inner
    response = get_response(request)
  File "C:\Users\zhi.zhou\Anaconda3\envs\lts\lib\site-packages\django\core\handlers\base.py", line 181, in _get_response
    response = wrapped_callback(request, *callback_args, **callback_kwargs)
  File "C:\Users\zhi.zhou\Anaconda3\envs\lts\lib\site-packages\django\views\generic\base.py", line 70, in view
    return self.dispatch(request, *args, **kwargs)
  File "C:\Users\zhi.zhou\Anaconda3\envs\lts\lib\site-packages\django\views\generic\base.py", line 98, in dispatch
    return handler(request, *args, **kwargs)
  File "D:\zhouzhi\gitlit_code\logistic_tracking_system\logistic_tracking_system\lts\views.py", line 5110, in get
    data = json.dumps(data)
  File "C:\Users\zhi.zhou\Anaconda3\envs\lts\lib\json\__init__.py", line 231, in dumps
    return _default_encoder.encode(obj)
  File "C:\Users\zhi.zhou\Anaconda3\envs\lts\lib\json\encoder.py", line 199, in encode
    chunks = self.iterencode(o, _one_shot=True)
  File "C:\Users\zhi.zhou\Anaconda3\envs\lts\lib\json\encoder.py", line 257, in iterencode
    return _iterencode(o, 0)
  File "C:\Users\zhi.zhou\Anaconda3\envs\lts\lib\json\encoder.py", line 180, in default
    o.__class__.__name__)
TypeError: Object of type 'OperationalError' is not JSON serializable
[2021-07-27 17:06:50,060][Thread-23:13368][task_id:django.request][log.py:230][ERROR][Internal Server Error: /logistic/LogisticMatterNameCode]
Traceback (most recent call last):
  File "D:\zhouzhi\gitlit_code\logistic_tracking_system\logistic_tracking_system\lts\views.py", line 5096, in get
    drs = db.execute_sql(conn, sql)
  File "D:\zhouzhi\gitlit_code\logistic_tracking_system\logistic_tracking_system\common\db.py", line 45, in execute_sql
    cursor.execute(sql)
  File "C:\Users\zhi.zhou\Anaconda3\envs\lts\lib\site-packages\pymysql\cursors.py", line 148, in execute
    result = self._query(query)
  File "C:\Users\zhi.zhou\Anaconda3\envs\lts\lib\site-packages\pymysql\cursors.py", line 310, in _query
    conn.query(q)
  File "C:\Users\zhi.zhou\Anaconda3\envs\lts\lib\site-packages\pymysql\connections.py", line 548, in query
    self._affected_rows = self._read_query_result(unbuffered=unbuffered)
  File "C:\Users\zhi.zhou\Anaconda3\envs\lts\lib\site-packages\pymysql\connections.py", line 775, in _read_query_result
    result.read()
  File "C:\Users\zhi.zhou\Anaconda3\envs\lts\lib\site-packages\pymysql\connections.py", line 1156, in read
    first_packet = self.connection._read_packet()
  File "C:\Users\zhi.zhou\Anaconda3\envs\lts\lib\site-packages\pymysql\connections.py", line 725, in _read_packet
    packet.raise_for_error()
  File "C:\Users\zhi.zhou\Anaconda3\envs\lts\lib\site-packages\pymysql\protocol.py", line 221, in raise_for_error
    err.raise_mysql_exception(self._data)
  File "C:\Users\zhi.zhou\Anaconda3\envs\lts\lib\site-packages\pymysql\err.py", line 143, in raise_mysql_exception
    raise errorclass(errno, errval)
pymysql.err.OperationalError: (1054, "Unknown column 'matter_name' in 'field list'")

During handling of the above exception, another exception occurred:

Traceback (most recent call last):
  File "C:\Users\zhi.zhou\Anaconda3\envs\lts\lib\site-packages\django\core\handlers\exception.py", line 47, in inner
    response = get_response(request)
  File "C:\Users\zhi.zhou\Anaconda3\envs\lts\lib\site-packages\django\core\handlers\base.py", line 181, in _get_response
    response = wrapped_callback(request, *callback_args, **callback_kwargs)
  File "C:\Users\zhi.zhou\Anaconda3\envs\lts\lib\site-packages\django\views\generic\base.py", line 70, in view
    return self.dispatch(request, *args, **kwargs)
  File "C:\Users\zhi.zhou\Anaconda3\envs\lts\lib\site-packages\django\views\generic\base.py", line 98, in dispatch
    return handler(request, *args, **kwargs)
  File "D:\zhouzhi\gitlit_code\logistic_tracking_system\logistic_tracking_system\lts\views.py", line 5110, in get
    data = json.dumps(data)
  File "C:\Users\zhi.zhou\Anaconda3\envs\lts\lib\json\__init__.py", line 231, in dumps
    return _default_encoder.encode(obj)
  File "C:\Users\zhi.zhou\Anaconda3\envs\lts\lib\json\encoder.py", line 199, in encode
    chunks = self.iterencode(o, _one_shot=True)
  File "C:\Users\zhi.zhou\Anaconda3\envs\lts\lib\json\encoder.py", line 257, in iterencode
    return _iterencode(o, 0)
  File "C:\Users\zhi.zhou\Anaconda3\envs\lts\lib\json\encoder.py", line 180, in default
    o.__class__.__name__)
TypeError: Object of type 'OperationalError' is not JSON serializable
[2021-07-27 17:08:31,648][Thread-27:22360][task_id:lts.views][views.py:3620][ERROR][修改失败---->(1054, "Unknown column 'status' in 'field list'")]
[2021-07-27 17:09:17,910][Thread-28:21696][task_id:lts.views][views.py:3620][ERROR][修改失败---->(1054, "Unknown column 'status' in 'field list'")]
