[2021-09-07 10:26:48,794][Thread-1:15944][task_id:lts.views][views.py:7976][ERROR][生命周期失败'<' not supported between instances of 'NoneType' and 'str']
[2021-09-07 10:28:50,607][Thread-1:19524][task_id:lts.views][views.py:7976][ERROR][生命周期失败'<' not supported between instances of 'NoneType' and 'str']
[2021-09-07 10:29:41,118][Thread-1:13696][task_id:lts.views][views.py:7976][ERROR][生命周期失败'<' not supported between instances of 'NoneType' and 'str']
[2021-09-07 10:33:44,550][Thread-1:16692][task_id:lts.views][views.py:7976][ERROR][生命周期失败'<' not supported between instances of 'NoneType' and 'str']
[2021-09-07 10:41:10,849][Thread-1:20264][task_id:lts.views][views.py:7976][ERROR][生命周期失败'<' not supported between instances of 'NoneType' and 'str']
[2021-09-07 10:42:59,751][Thread-1:20156][task_id:lts.views][views.py:7976][ERROR][生命周期失败'<' not supported between instances of 'NoneType' and 'str']
[2021-09-07 10:45:07,780][Thread-1:11956][task_id:lts.views][views.py:7976][ERROR][生命周期失败'<' not supported between instances of 'NoneType' and 'str']
[2021-09-07 13:33:44,623][Thread-1:19576][task_id:lts.views][views.py:9378][ERROR][查询产品出库失败]
[2021-09-07 13:34:49,170][Thread-1:20292][task_id:lts.views][views.py:9378][ERROR][查询产品出库失败]
[2021-09-07 13:36:49,295][Thread-1:21216][task_id:lts.views][views.py:9381][ERROR][查询产品出库失败]
[2021-09-07 13:38:21,205][Thread-1:18532][task_id:lts.views][views.py:9381][ERROR][查询产品出库失败]
[2021-09-07 13:41:10,374][Thread-1:20788][task_id:lts.views][views.py:9382][ERROR][查询产品出库失败]
[2021-09-07 13:42:01,895][Thread-1:16932][task_id:lts.views][views.py:9383][ERROR][查询产品出库失败]
[2021-09-07 13:42:17,765][Thread-1:12440][task_id:lts.views][views.py:9383][ERROR][查询产品出库失败]
[2021-09-07 13:42:45,464][Thread-1:20488][task_id:lts.views][views.py:9383][ERROR][查询产品出库失败]
[2021-09-07 13:44:14,973][Thread-1:9720][task_id:lts.views][views.py:9383][ERROR][查询产品出库失败]
[2021-09-07 13:44:49,858][Thread-1:20416][task_id:lts.views][views.py:9384][ERROR][查询产品出库失败]
[2021-09-07 13:45:26,109][Thread-1:20952][task_id:lts.views][views.py:9386][ERROR][查询产品出库失败]
[2021-09-07 13:45:58,800][Thread-1:19696][task_id:lts.views][views.py:9386][ERROR][查询产品出库失败]
[2021-09-07 13:48:17,275][Thread-1:21192][task_id:lts.views][views.py:9387][ERROR][查询产品出库失败]
[2021-09-07 13:49:26,007][Thread-1:2588][task_id:lts.views][views.py:9387][ERROR][查询产品出库失败]
[2021-09-07 14:18:19,243][Thread-1:8604][task_id:lts.views][views.py:2214][ERROR][查询生产计划表信息失败(1046, 'No database selected')]
[2021-09-07 14:18:19,252][Thread-4:16688][task_id:lts.views][views.py:2214][ERROR][查询生产计划表信息失败(1046, 'No database selected')]
[2021-09-07 14:18:19,590][Thread-5:20824][task_id:django.request][log.py:230][ERROR][Internal Server Error: /logistic/LogisticPersonCodeName]
Traceback (most recent call last):
  File "D:\zhouzhi\gitlit_code\logistic_tracking_system\logistic_tracking_system\lts\views.py", line 3233, in get
    drs = db.execute_sql(conn, sql)
  File "D:\zhouzhi\gitlit_code\logistic_tracking_system\logistic_tracking_system\common\db.py", line 50, in execute_sql
    cursor.execute(sql)
  File "C:\Users\zhi.zhou\Anaconda3\envs\lts\lib\site-packages\pymysql\cursors.py", line 148, in execute
    result = self._query(query)
  File "C:\Users\zhi.zhou\Anaconda3\envs\lts\lib\site-packages\pymysql\cursors.py", line 310, in _query
    conn.query(q)
  File "C:\Users\zhi.zhou\Anaconda3\envs\lts\lib\site-packages\pymysql\connections.py", line 548, in query
    self._affected_rows = self._read_query_result(unbuffered=unbuffered)
  File "C:\Users\zhi.zhou\Anaconda3\envs\lts\lib\site-packages\pymysql\connections.py", line 775, in _read_query_result
    result.read()
  File "C:\Users\zhi.zhou\Anaconda3\envs\lts\lib\site-packages\pymysql\connections.py", line 1156, in read
    first_packet = self.connection._read_packet()
  File "C:\Users\zhi.zhou\Anaconda3\envs\lts\lib\site-packages\pymysql\connections.py", line 725, in _read_packet
    packet.raise_for_error()
  File "C:\Users\zhi.zhou\Anaconda3\envs\lts\lib\site-packages\pymysql\protocol.py", line 221, in raise_for_error
    err.raise_mysql_exception(self._data)
  File "C:\Users\zhi.zhou\Anaconda3\envs\lts\lib\site-packages\pymysql\err.py", line 143, in raise_mysql_exception
    raise errorclass(errno, errval)
pymysql.err.OperationalError: (1046, 'No database selected')

During handling of the above exception, another exception occurred:

Traceback (most recent call last):
  File "C:\Users\zhi.zhou\Anaconda3\envs\lts\lib\site-packages\django\core\handlers\exception.py", line 47, in inner
    response = get_response(request)
  File "C:\Users\zhi.zhou\Anaconda3\envs\lts\lib\site-packages\django\core\handlers\base.py", line 181, in _get_response
    response = wrapped_callback(request, *callback_args, **callback_kwargs)
  File "C:\Users\zhi.zhou\Anaconda3\envs\lts\lib\site-packages\django\views\generic\base.py", line 70, in view
    return self.dispatch(request, *args, **kwargs)
  File "C:\Users\zhi.zhou\Anaconda3\envs\lts\lib\site-packages\django\views\generic\base.py", line 98, in dispatch
    return handler(request, *args, **kwargs)
  File "D:\zhouzhi\gitlit_code\logistic_tracking_system\logistic_tracking_system\lts\views.py", line 3249, in get
    data = json.dumps(data)
  File "C:\Users\zhi.zhou\Anaconda3\envs\lts\lib\json\__init__.py", line 231, in dumps
    return _default_encoder.encode(obj)
  File "C:\Users\zhi.zhou\Anaconda3\envs\lts\lib\json\encoder.py", line 199, in encode
    chunks = self.iterencode(o, _one_shot=True)
  File "C:\Users\zhi.zhou\Anaconda3\envs\lts\lib\json\encoder.py", line 257, in iterencode
    return _iterencode(o, 0)
  File "C:\Users\zhi.zhou\Anaconda3\envs\lts\lib\json\encoder.py", line 180, in default
    o.__class__.__name__)
TypeError: Object of type 'OperationalError' is not JSON serializable
[2021-09-07 14:18:19,613][Thread-2:20176][task_id:django.request][log.py:230][ERROR][Internal Server Error: /logistic/LogisticWorkCodeName]
Traceback (most recent call last):
  File "D:\zhouzhi\gitlit_code\logistic_tracking_system\logistic_tracking_system\lts\views.py", line 3270, in get
    drs = db.execute_sql(conn, sql)
  File "D:\zhouzhi\gitlit_code\logistic_tracking_system\logistic_tracking_system\common\db.py", line 50, in execute_sql
    cursor.execute(sql)
  File "C:\Users\zhi.zhou\Anaconda3\envs\lts\lib\site-packages\pymysql\cursors.py", line 148, in execute
    result = self._query(query)
  File "C:\Users\zhi.zhou\Anaconda3\envs\lts\lib\site-packages\pymysql\cursors.py", line 310, in _query
    conn.query(q)
  File "C:\Users\zhi.zhou\Anaconda3\envs\lts\lib\site-packages\pymysql\connections.py", line 548, in query
    self._affected_rows = self._read_query_result(unbuffered=unbuffered)
  File "C:\Users\zhi.zhou\Anaconda3\envs\lts\lib\site-packages\pymysql\connections.py", line 775, in _read_query_result
    result.read()
  File "C:\Users\zhi.zhou\Anaconda3\envs\lts\lib\site-packages\pymysql\connections.py", line 1156, in read
    first_packet = self.connection._read_packet()
  File "C:\Users\zhi.zhou\Anaconda3\envs\lts\lib\site-packages\pymysql\connections.py", line 725, in _read_packet
    packet.raise_for_error()
  File "C:\Users\zhi.zhou\Anaconda3\envs\lts\lib\site-packages\pymysql\protocol.py", line 221, in raise_for_error
    err.raise_mysql_exception(self._data)
  File "C:\Users\zhi.zhou\Anaconda3\envs\lts\lib\site-packages\pymysql\err.py", line 143, in raise_mysql_exception
    raise errorclass(errno, errval)
pymysql.err.OperationalError: (1046, 'No database selected')

During handling of the above exception, another exception occurred:

Traceback (most recent call last):
  File "C:\Users\zhi.zhou\Anaconda3\envs\lts\lib\site-packages\django\core\handlers\exception.py", line 47, in inner
    response = get_response(request)
  File "C:\Users\zhi.zhou\Anaconda3\envs\lts\lib\site-packages\django\core\handlers\base.py", line 181, in _get_response
    response = wrapped_callback(request, *callback_args, **callback_kwargs)
  File "C:\Users\zhi.zhou\Anaconda3\envs\lts\lib\site-packages\django\views\generic\base.py", line 70, in view
    return self.dispatch(request, *args, **kwargs)
  File "C:\Users\zhi.zhou\Anaconda3\envs\lts\lib\site-packages\django\views\generic\base.py", line 98, in dispatch
    return handler(request, *args, **kwargs)
  File "D:\zhouzhi\gitlit_code\logistic_tracking_system\logistic_tracking_system\lts\views.py", line 3289, in get
    data = json.dumps(data)
  File "C:\Users\zhi.zhou\Anaconda3\envs\lts\lib\json\__init__.py", line 231, in dumps
    return _default_encoder.encode(obj)
  File "C:\Users\zhi.zhou\Anaconda3\envs\lts\lib\json\encoder.py", line 199, in encode
    chunks = self.iterencode(o, _one_shot=True)
  File "C:\Users\zhi.zhou\Anaconda3\envs\lts\lib\json\encoder.py", line 257, in iterencode
    return _iterencode(o, 0)
  File "C:\Users\zhi.zhou\Anaconda3\envs\lts\lib\json\encoder.py", line 180, in default
    o.__class__.__name__)
TypeError: Object of type 'OperationalError' is not JSON serializable
[2021-09-07 14:18:19,637][Thread-3:15916][task_id:django.request][log.py:230][ERROR][Internal Server Error: /logistic/LogisticOperationSystem]
Traceback (most recent call last):
  File "D:\zhouzhi\gitlit_code\logistic_tracking_system\logistic_tracking_system\lts\views.py", line 6495, in get
    drs = db.execute_sql(conn, sql)
  File "D:\zhouzhi\gitlit_code\logistic_tracking_system\logistic_tracking_system\common\db.py", line 50, in execute_sql
    cursor.execute(sql)
  File "C:\Users\zhi.zhou\Anaconda3\envs\lts\lib\site-packages\pymysql\cursors.py", line 148, in execute
    result = self._query(query)
  File "C:\Users\zhi.zhou\Anaconda3\envs\lts\lib\site-packages\pymysql\cursors.py", line 310, in _query
    conn.query(q)
  File "C:\Users\zhi.zhou\Anaconda3\envs\lts\lib\site-packages\pymysql\connections.py", line 548, in query
    self._affected_rows = self._read_query_result(unbuffered=unbuffered)
  File "C:\Users\zhi.zhou\Anaconda3\envs\lts\lib\site-packages\pymysql\connections.py", line 775, in _read_query_result
    result.read()
  File "C:\Users\zhi.zhou\Anaconda3\envs\lts\lib\site-packages\pymysql\connections.py", line 1156, in read
    first_packet = self.connection._read_packet()
  File "C:\Users\zhi.zhou\Anaconda3\envs\lts\lib\site-packages\pymysql\connections.py", line 725, in _read_packet
    packet.raise_for_error()
  File "C:\Users\zhi.zhou\Anaconda3\envs\lts\lib\site-packages\pymysql\protocol.py", line 221, in raise_for_error
    err.raise_mysql_exception(self._data)
  File "C:\Users\zhi.zhou\Anaconda3\envs\lts\lib\site-packages\pymysql\err.py", line 143, in raise_mysql_exception
    raise errorclass(errno, errval)
pymysql.err.OperationalError: (1046, 'No database selected')

During handling of the above exception, another exception occurred:

Traceback (most recent call last):
  File "C:\Users\zhi.zhou\Anaconda3\envs\lts\lib\site-packages\django\core\handlers\exception.py", line 47, in inner
    response = get_response(request)
  File "C:\Users\zhi.zhou\Anaconda3\envs\lts\lib\site-packages\django\core\handlers\base.py", line 181, in _get_response
    response = wrapped_callback(request, *callback_args, **callback_kwargs)
  File "C:\Users\zhi.zhou\Anaconda3\envs\lts\lib\site-packages\django\views\generic\base.py", line 70, in view
    return self.dispatch(request, *args, **kwargs)
  File "C:\Users\zhi.zhou\Anaconda3\envs\lts\lib\site-packages\django\views\generic\base.py", line 98, in dispatch
    return handler(request, *args, **kwargs)
  File "D:\zhouzhi\gitlit_code\logistic_tracking_system\logistic_tracking_system\lts\views.py", line 6537, in get
    result = json.dumps(result)
  File "C:\Users\zhi.zhou\Anaconda3\envs\lts\lib\json\__init__.py", line 231, in dumps
    return _default_encoder.encode(obj)
  File "C:\Users\zhi.zhou\Anaconda3\envs\lts\lib\json\encoder.py", line 199, in encode
    chunks = self.iterencode(o, _one_shot=True)
  File "C:\Users\zhi.zhou\Anaconda3\envs\lts\lib\json\encoder.py", line 257, in iterencode
    return _iterencode(o, 0)
  File "C:\Users\zhi.zhou\Anaconda3\envs\lts\lib\json\encoder.py", line 180, in default
    o.__class__.__name__)
TypeError: Object of type 'OperationalError' is not JSON serializable
[2021-09-07 14:18:19,662][Thread-6:20520][task_id:django.request][log.py:230][ERROR][Internal Server Error: /logistic/LogisticFinishedProductStorage]
Traceback (most recent call last):
  File "D:\zhouzhi\gitlit_code\logistic_tracking_system\logistic_tracking_system\lts\views.py", line 5214, in get
    drs = db.execute_sql(conn, sql)
  File "D:\zhouzhi\gitlit_code\logistic_tracking_system\logistic_tracking_system\common\db.py", line 50, in execute_sql
    cursor.execute(sql)
  File "C:\Users\zhi.zhou\Anaconda3\envs\lts\lib\site-packages\pymysql\cursors.py", line 148, in execute
    result = self._query(query)
  File "C:\Users\zhi.zhou\Anaconda3\envs\lts\lib\site-packages\pymysql\cursors.py", line 310, in _query
    conn.query(q)
  File "C:\Users\zhi.zhou\Anaconda3\envs\lts\lib\site-packages\pymysql\connections.py", line 548, in query
    self._affected_rows = self._read_query_result(unbuffered=unbuffered)
  File "C:\Users\zhi.zhou\Anaconda3\envs\lts\lib\site-packages\pymysql\connections.py", line 775, in _read_query_result
    result.read()
  File "C:\Users\zhi.zhou\Anaconda3\envs\lts\lib\site-packages\pymysql\connections.py", line 1156, in read
    first_packet = self.connection._read_packet()
  File "C:\Users\zhi.zhou\Anaconda3\envs\lts\lib\site-packages\pymysql\connections.py", line 725, in _read_packet
    packet.raise_for_error()
  File "C:\Users\zhi.zhou\Anaconda3\envs\lts\lib\site-packages\pymysql\protocol.py", line 221, in raise_for_error
    err.raise_mysql_exception(self._data)
  File "C:\Users\zhi.zhou\Anaconda3\envs\lts\lib\site-packages\pymysql\err.py", line 143, in raise_mysql_exception
    raise errorclass(errno, errval)
pymysql.err.OperationalError: (1046, 'No database selected')

During handling of the above exception, another exception occurred:

Traceback (most recent call last):
  File "C:\Users\zhi.zhou\Anaconda3\envs\lts\lib\site-packages\django\core\handlers\exception.py", line 47, in inner
    response = get_response(request)
  File "C:\Users\zhi.zhou\Anaconda3\envs\lts\lib\site-packages\django\core\handlers\base.py", line 181, in _get_response
    response = wrapped_callback(request, *callback_args, **callback_kwargs)
  File "C:\Users\zhi.zhou\Anaconda3\envs\lts\lib\site-packages\django\views\generic\base.py", line 70, in view
    return self.dispatch(request, *args, **kwargs)
  File "C:\Users\zhi.zhou\Anaconda3\envs\lts\lib\site-packages\django\views\generic\base.py", line 98, in dispatch
    return handler(request, *args, **kwargs)
  File "D:\zhouzhi\gitlit_code\logistic_tracking_system\logistic_tracking_system\lts\views.py", line 5292, in get
    result = json.dumps(result)
  File "C:\Users\zhi.zhou\Anaconda3\envs\lts\lib\json\__init__.py", line 231, in dumps
    return _default_encoder.encode(obj)
  File "C:\Users\zhi.zhou\Anaconda3\envs\lts\lib\json\encoder.py", line 199, in encode
    chunks = self.iterencode(o, _one_shot=True)
  File "C:\Users\zhi.zhou\Anaconda3\envs\lts\lib\json\encoder.py", line 257, in iterencode
    return _iterencode(o, 0)
  File "C:\Users\zhi.zhou\Anaconda3\envs\lts\lib\json\encoder.py", line 180, in default
    o.__class__.__name__)
TypeError: Object of type 'OperationalError' is not JSON serializable
[2021-09-07 14:18:22,552][Thread-8:6764][task_id:lts.views][views.py:2214][ERROR][查询生产计划表信息失败(1046, 'No database selected')]
[2021-09-07 14:18:22,575][Thread-8:6764][task_id:lts.views][views.py:6360][ERROR][不分页的查询物料信息失败,(1046, 'No database selected')]
[2021-09-07 14:18:22,625][Thread-9:16992][task_id:django.request][log.py:230][ERROR][Internal Server Error: /logistic/LogisticProductPlanCodeName]
Traceback (most recent call last):
  File "D:\zhouzhi\gitlit_code\logistic_tracking_system\logistic_tracking_system\lts\views.py", line 3201, in get
    drs = db.execute_sql(conn, sql)
  File "D:\zhouzhi\gitlit_code\logistic_tracking_system\logistic_tracking_system\common\db.py", line 50, in execute_sql
    cursor.execute(sql)
  File "C:\Users\zhi.zhou\Anaconda3\envs\lts\lib\site-packages\pymysql\cursors.py", line 148, in execute
    result = self._query(query)
  File "C:\Users\zhi.zhou\Anaconda3\envs\lts\lib\site-packages\pymysql\cursors.py", line 310, in _query
    conn.query(q)
  File "C:\Users\zhi.zhou\Anaconda3\envs\lts\lib\site-packages\pymysql\connections.py", line 548, in query
    self._affected_rows = self._read_query_result(unbuffered=unbuffered)
  File "C:\Users\zhi.zhou\Anaconda3\envs\lts\lib\site-packages\pymysql\connections.py", line 775, in _read_query_result
    result.read()
  File "C:\Users\zhi.zhou\Anaconda3\envs\lts\lib\site-packages\pymysql\connections.py", line 1156, in read
    first_packet = self.connection._read_packet()
  File "C:\Users\zhi.zhou\Anaconda3\envs\lts\lib\site-packages\pymysql\connections.py", line 725, in _read_packet
    packet.raise_for_error()
  File "C:\Users\zhi.zhou\Anaconda3\envs\lts\lib\site-packages\pymysql\protocol.py", line 221, in raise_for_error
    err.raise_mysql_exception(self._data)
  File "C:\Users\zhi.zhou\Anaconda3\envs\lts\lib\site-packages\pymysql\err.py", line 143, in raise_mysql_exception
    raise errorclass(errno, errval)
pymysql.err.OperationalError: (1046, 'No database selected')

During handling of the above exception, another exception occurred:

Traceback (most recent call last):
  File "C:\Users\zhi.zhou\Anaconda3\envs\lts\lib\site-packages\django\core\handlers\exception.py", line 47, in inner
    response = get_response(request)
  File "C:\Users\zhi.zhou\Anaconda3\envs\lts\lib\site-packages\django\core\handlers\base.py", line 181, in _get_response
    response = wrapped_callback(request, *callback_args, **callback_kwargs)
  File "C:\Users\zhi.zhou\Anaconda3\envs\lts\lib\site-packages\django\views\generic\base.py", line 70, in view
    return self.dispatch(request, *args, **kwargs)
  File "C:\Users\zhi.zhou\Anaconda3\envs\lts\lib\site-packages\django\views\generic\base.py", line 98, in dispatch
    return handler(request, *args, **kwargs)
  File "D:\zhouzhi\gitlit_code\logistic_tracking_system\logistic_tracking_system\lts\views.py", line 3215, in get
    data = json.dumps(data)
  File "C:\Users\zhi.zhou\Anaconda3\envs\lts\lib\json\__init__.py", line 231, in dumps
    return _default_encoder.encode(obj)
  File "C:\Users\zhi.zhou\Anaconda3\envs\lts\lib\json\encoder.py", line 199, in encode
    chunks = self.iterencode(o, _one_shot=True)
  File "C:\Users\zhi.zhou\Anaconda3\envs\lts\lib\json\encoder.py", line 257, in iterencode
    return _iterencode(o, 0)
  File "C:\Users\zhi.zhou\Anaconda3\envs\lts\lib\json\encoder.py", line 180, in default
    o.__class__.__name__)
TypeError: Object of type 'OperationalError' is not JSON serializable
[2021-09-07 14:18:22,649][Thread-11:1448][task_id:django.request][log.py:230][ERROR][Internal Server Error: /logistic/LogisticMatterNameCode]
Traceback (most recent call last):
  File "D:\zhouzhi\gitlit_code\logistic_tracking_system\logistic_tracking_system\lts\views.py", line 3986, in get
    drs = db.execute_sql(conn, sql)
  File "D:\zhouzhi\gitlit_code\logistic_tracking_system\logistic_tracking_system\common\db.py", line 50, in execute_sql
    cursor.execute(sql)
  File "C:\Users\zhi.zhou\Anaconda3\envs\lts\lib\site-packages\pymysql\cursors.py", line 148, in execute
    result = self._query(query)
  File "C:\Users\zhi.zhou\Anaconda3\envs\lts\lib\site-packages\pymysql\cursors.py", line 310, in _query
    conn.query(q)
  File "C:\Users\zhi.zhou\Anaconda3\envs\lts\lib\site-packages\pymysql\connections.py", line 548, in query
    self._affected_rows = self._read_query_result(unbuffered=unbuffered)
  File "C:\Users\zhi.zhou\Anaconda3\envs\lts\lib\site-packages\pymysql\connections.py", line 775, in _read_query_result
    result.read()
  File "C:\Users\zhi.zhou\Anaconda3\envs\lts\lib\site-packages\pymysql\connections.py", line 1156, in read
    first_packet = self.connection._read_packet()
  File "C:\Users\zhi.zhou\Anaconda3\envs\lts\lib\site-packages\pymysql\connections.py", line 725, in _read_packet
    packet.raise_for_error()
  File "C:\Users\zhi.zhou\Anaconda3\envs\lts\lib\site-packages\pymysql\protocol.py", line 221, in raise_for_error
    err.raise_mysql_exception(self._data)
  File "C:\Users\zhi.zhou\Anaconda3\envs\lts\lib\site-packages\pymysql\err.py", line 143, in raise_mysql_exception
    raise errorclass(errno, errval)
pymysql.err.OperationalError: (1046, 'No database selected')

During handling of the above exception, another exception occurred:

Traceback (most recent call last):
  File "C:\Users\zhi.zhou\Anaconda3\envs\lts\lib\site-packages\django\core\handlers\exception.py", line 47, in inner
    response = get_response(request)
  File "C:\Users\zhi.zhou\Anaconda3\envs\lts\lib\site-packages\django\core\handlers\base.py", line 181, in _get_response
    response = wrapped_callback(request, *callback_args, **callback_kwargs)
  File "C:\Users\zhi.zhou\Anaconda3\envs\lts\lib\site-packages\django\views\generic\base.py", line 70, in view
    return self.dispatch(request, *args, **kwargs)
  File "C:\Users\zhi.zhou\Anaconda3\envs\lts\lib\site-packages\django\views\generic\base.py", line 98, in dispatch
    return handler(request, *args, **kwargs)
  File "D:\zhouzhi\gitlit_code\logistic_tracking_system\logistic_tracking_system\lts\views.py", line 4001, in get
    data = json.dumps(data)
  File "C:\Users\zhi.zhou\Anaconda3\envs\lts\lib\json\__init__.py", line 231, in dumps
    return _default_encoder.encode(obj)
  File "C:\Users\zhi.zhou\Anaconda3\envs\lts\lib\json\encoder.py", line 199, in encode
    chunks = self.iterencode(o, _one_shot=True)
  File "C:\Users\zhi.zhou\Anaconda3\envs\lts\lib\json\encoder.py", line 257, in iterencode
    return _iterencode(o, 0)
  File "C:\Users\zhi.zhou\Anaconda3\envs\lts\lib\json\encoder.py", line 180, in default
    o.__class__.__name__)
TypeError: Object of type 'OperationalError' is not JSON serializable
[2021-09-07 14:18:22,674][Thread-7:20664][task_id:django.request][log.py:230][ERROR][Internal Server Error: /logistic/LogisticPersonCodeName]
Traceback (most recent call last):
  File "D:\zhouzhi\gitlit_code\logistic_tracking_system\logistic_tracking_system\lts\views.py", line 3233, in get
    drs = db.execute_sql(conn, sql)
  File "D:\zhouzhi\gitlit_code\logistic_tracking_system\logistic_tracking_system\common\db.py", line 50, in execute_sql
    cursor.execute(sql)
  File "C:\Users\zhi.zhou\Anaconda3\envs\lts\lib\site-packages\pymysql\cursors.py", line 148, in execute
    result = self._query(query)
  File "C:\Users\zhi.zhou\Anaconda3\envs\lts\lib\site-packages\pymysql\cursors.py", line 310, in _query
    conn.query(q)
  File "C:\Users\zhi.zhou\Anaconda3\envs\lts\lib\site-packages\pymysql\connections.py", line 548, in query
    self._affected_rows = self._read_query_result(unbuffered=unbuffered)
  File "C:\Users\zhi.zhou\Anaconda3\envs\lts\lib\site-packages\pymysql\connections.py", line 775, in _read_query_result
    result.read()
  File "C:\Users\zhi.zhou\Anaconda3\envs\lts\lib\site-packages\pymysql\connections.py", line 1156, in read
    first_packet = self.connection._read_packet()
  File "C:\Users\zhi.zhou\Anaconda3\envs\lts\lib\site-packages\pymysql\connections.py", line 725, in _read_packet
    packet.raise_for_error()
  File "C:\Users\zhi.zhou\Anaconda3\envs\lts\lib\site-packages\pymysql\protocol.py", line 221, in raise_for_error
    err.raise_mysql_exception(self._data)
  File "C:\Users\zhi.zhou\Anaconda3\envs\lts\lib\site-packages\pymysql\err.py", line 143, in raise_mysql_exception
    raise errorclass(errno, errval)
pymysql.err.OperationalError: (1046, 'No database selected')

During handling of the above exception, another exception occurred:

Traceback (most recent call last):
  File "C:\Users\zhi.zhou\Anaconda3\envs\lts\lib\site-packages\django\core\handlers\exception.py", line 47, in inner
    response = get_response(request)
  File "C:\Users\zhi.zhou\Anaconda3\envs\lts\lib\site-packages\django\core\handlers\base.py", line 181, in _get_response
    response = wrapped_callback(request, *callback_args, **callback_kwargs)
  File "C:\Users\zhi.zhou\Anaconda3\envs\lts\lib\site-packages\django\views\generic\base.py", line 70, in view
    return self.dispatch(request, *args, **kwargs)
  File "C:\Users\zhi.zhou\Anaconda3\envs\lts\lib\site-packages\django\views\generic\base.py", line 98, in dispatch
    return handler(request, *args, **kwargs)
  File "D:\zhouzhi\gitlit_code\logistic_tracking_system\logistic_tracking_system\lts\views.py", line 3249, in get
    data = json.dumps(data)
  File "C:\Users\zhi.zhou\Anaconda3\envs\lts\lib\json\__init__.py", line 231, in dumps
    return _default_encoder.encode(obj)
  File "C:\Users\zhi.zhou\Anaconda3\envs\lts\lib\json\encoder.py", line 199, in encode
    chunks = self.iterencode(o, _one_shot=True)
  File "C:\Users\zhi.zhou\Anaconda3\envs\lts\lib\json\encoder.py", line 257, in iterencode
    return _iterencode(o, 0)
  File "C:\Users\zhi.zhou\Anaconda3\envs\lts\lib\json\encoder.py", line 180, in default
    o.__class__.__name__)
TypeError: Object of type 'OperationalError' is not JSON serializable
[2021-09-07 14:18:22,715][Thread-10:9032][task_id:django.request][log.py:230][ERROR][Internal Server Error: /logistic/LogisticPersonCodeName]
Traceback (most recent call last):
  File "D:\zhouzhi\gitlit_code\logistic_tracking_system\logistic_tracking_system\lts\views.py", line 3233, in get
    drs = db.execute_sql(conn, sql)
  File "D:\zhouzhi\gitlit_code\logistic_tracking_system\logistic_tracking_system\common\db.py", line 50, in execute_sql
    cursor.execute(sql)
  File "C:\Users\zhi.zhou\Anaconda3\envs\lts\lib\site-packages\pymysql\cursors.py", line 148, in execute
    result = self._query(query)
  File "C:\Users\zhi.zhou\Anaconda3\envs\lts\lib\site-packages\pymysql\cursors.py", line 310, in _query
    conn.query(q)
  File "C:\Users\zhi.zhou\Anaconda3\envs\lts\lib\site-packages\pymysql\connections.py", line 548, in query
    self._affected_rows = self._read_query_result(unbuffered=unbuffered)
  File "C:\Users\zhi.zhou\Anaconda3\envs\lts\lib\site-packages\pymysql\connections.py", line 775, in _read_query_result
    result.read()
  File "C:\Users\zhi.zhou\Anaconda3\envs\lts\lib\site-packages\pymysql\connections.py", line 1156, in read
    first_packet = self.connection._read_packet()
  File "C:\Users\zhi.zhou\Anaconda3\envs\lts\lib\site-packages\pymysql\connections.py", line 725, in _read_packet
    packet.raise_for_error()
  File "C:\Users\zhi.zhou\Anaconda3\envs\lts\lib\site-packages\pymysql\protocol.py", line 221, in raise_for_error
    err.raise_mysql_exception(self._data)
  File "C:\Users\zhi.zhou\Anaconda3\envs\lts\lib\site-packages\pymysql\err.py", line 143, in raise_mysql_exception
    raise errorclass(errno, errval)
pymysql.err.OperationalError: (1046, 'No database selected')

During handling of the above exception, another exception occurred:

Traceback (most recent call last):
  File "C:\Users\zhi.zhou\Anaconda3\envs\lts\lib\site-packages\django\core\handlers\exception.py", line 47, in inner
    response = get_response(request)
  File "C:\Users\zhi.zhou\Anaconda3\envs\lts\lib\site-packages\django\core\handlers\base.py", line 181, in _get_response
    response = wrapped_callback(request, *callback_args, **callback_kwargs)
  File "C:\Users\zhi.zhou\Anaconda3\envs\lts\lib\site-packages\django\views\generic\base.py", line 70, in view
    return self.dispatch(request, *args, **kwargs)
  File "C:\Users\zhi.zhou\Anaconda3\envs\lts\lib\site-packages\django\views\generic\base.py", line 98, in dispatch
    return handler(request, *args, **kwargs)
  File "D:\zhouzhi\gitlit_code\logistic_tracking_system\logistic_tracking_system\lts\views.py", line 3249, in get
    data = json.dumps(data)
  File "C:\Users\zhi.zhou\Anaconda3\envs\lts\lib\json\__init__.py", line 231, in dumps
    return _default_encoder.encode(obj)
  File "C:\Users\zhi.zhou\Anaconda3\envs\lts\lib\json\encoder.py", line 199, in encode
    chunks = self.iterencode(o, _one_shot=True)
  File "C:\Users\zhi.zhou\Anaconda3\envs\lts\lib\json\encoder.py", line 257, in iterencode
    return _iterencode(o, 0)
  File "C:\Users\zhi.zhou\Anaconda3\envs\lts\lib\json\encoder.py", line 180, in default
    o.__class__.__name__)
TypeError: Object of type 'OperationalError' is not JSON serializable
[2021-09-07 14:18:22,723][Thread-12:900][task_id:django.request][log.py:230][ERROR][Internal Server Error: /logistic/LogisticWorkCodeName]
Traceback (most recent call last):
  File "D:\zhouzhi\gitlit_code\logistic_tracking_system\logistic_tracking_system\lts\views.py", line 3270, in get
    drs = db.execute_sql(conn, sql)
  File "D:\zhouzhi\gitlit_code\logistic_tracking_system\logistic_tracking_system\common\db.py", line 50, in execute_sql
    cursor.execute(sql)
  File "C:\Users\zhi.zhou\Anaconda3\envs\lts\lib\site-packages\pymysql\cursors.py", line 148, in execute
    result = self._query(query)
  File "C:\Users\zhi.zhou\Anaconda3\envs\lts\lib\site-packages\pymysql\cursors.py", line 310, in _query
    conn.query(q)
  File "C:\Users\zhi.zhou\Anaconda3\envs\lts\lib\site-packages\pymysql\connections.py", line 548, in query
    self._affected_rows = self._read_query_result(unbuffered=unbuffered)
  File "C:\Users\zhi.zhou\Anaconda3\envs\lts\lib\site-packages\pymysql\connections.py", line 775, in _read_query_result
    result.read()
  File "C:\Users\zhi.zhou\Anaconda3\envs\lts\lib\site-packages\pymysql\connections.py", line 1156, in read
    first_packet = self.connection._read_packet()
  File "C:\Users\zhi.zhou\Anaconda3\envs\lts\lib\site-packages\pymysql\connections.py", line 725, in _read_packet
    packet.raise_for_error()
  File "C:\Users\zhi.zhou\Anaconda3\envs\lts\lib\site-packages\pymysql\protocol.py", line 221, in raise_for_error
    err.raise_mysql_exception(self._data)
  File "C:\Users\zhi.zhou\Anaconda3\envs\lts\lib\site-packages\pymysql\err.py", line 143, in raise_mysql_exception
    raise errorclass(errno, errval)
pymysql.err.OperationalError: (1046, 'No database selected')

During handling of the above exception, another exception occurred:

Traceback (most recent call last):
  File "C:\Users\zhi.zhou\Anaconda3\envs\lts\lib\site-packages\django\core\handlers\exception.py", line 47, in inner
    response = get_response(request)
  File "C:\Users\zhi.zhou\Anaconda3\envs\lts\lib\site-packages\django\core\handlers\base.py", line 181, in _get_response
    response = wrapped_callback(request, *callback_args, **callback_kwargs)
  File "C:\Users\zhi.zhou\Anaconda3\envs\lts\lib\site-packages\django\views\generic\base.py", line 70, in view
    return self.dispatch(request, *args, **kwargs)
  File "C:\Users\zhi.zhou\Anaconda3\envs\lts\lib\site-packages\django\views\generic\base.py", line 98, in dispatch
    return handler(request, *args, **kwargs)
  File "D:\zhouzhi\gitlit_code\logistic_tracking_system\logistic_tracking_system\lts\views.py", line 3289, in get
    data = json.dumps(data)
  File "C:\Users\zhi.zhou\Anaconda3\envs\lts\lib\json\__init__.py", line 231, in dumps
    return _default_encoder.encode(obj)
  File "C:\Users\zhi.zhou\Anaconda3\envs\lts\lib\json\encoder.py", line 199, in encode
    chunks = self.iterencode(o, _one_shot=True)
  File "C:\Users\zhi.zhou\Anaconda3\envs\lts\lib\json\encoder.py", line 257, in iterencode
    return _iterencode(o, 0)
  File "C:\Users\zhi.zhou\Anaconda3\envs\lts\lib\json\encoder.py", line 180, in default
    o.__class__.__name__)
TypeError: Object of type 'OperationalError' is not JSON serializable
[2021-09-07 14:18:51,038][Thread-14:19564][task_id:lts.views][views.py:2214][ERROR][查询生产计划表信息失败(1046, 'No database selected')]
[2021-09-07 14:18:51,064][Thread-14:19564][task_id:lts.views][views.py:6360][ERROR][不分页的查询物料信息失败,(1046, 'No database selected')]
[2021-09-07 14:18:51,123][Thread-16:18716][task_id:django.request][log.py:230][ERROR][Internal Server Error: /logistic/LogisticPersonCodeName]
Traceback (most recent call last):
  File "D:\zhouzhi\gitlit_code\logistic_tracking_system\logistic_tracking_system\lts\views.py", line 3233, in get
    drs = db.execute_sql(conn, sql)
  File "D:\zhouzhi\gitlit_code\logistic_tracking_system\logistic_tracking_system\common\db.py", line 50, in execute_sql
    cursor.execute(sql)
  File "C:\Users\zhi.zhou\Anaconda3\envs\lts\lib\site-packages\pymysql\cursors.py", line 148, in execute
    result = self._query(query)
  File "C:\Users\zhi.zhou\Anaconda3\envs\lts\lib\site-packages\pymysql\cursors.py", line 310, in _query
    conn.query(q)
  File "C:\Users\zhi.zhou\Anaconda3\envs\lts\lib\site-packages\pymysql\connections.py", line 548, in query
    self._affected_rows = self._read_query_result(unbuffered=unbuffered)
  File "C:\Users\zhi.zhou\Anaconda3\envs\lts\lib\site-packages\pymysql\connections.py", line 775, in _read_query_result
    result.read()
  File "C:\Users\zhi.zhou\Anaconda3\envs\lts\lib\site-packages\pymysql\connections.py", line 1156, in read
    first_packet = self.connection._read_packet()
  File "C:\Users\zhi.zhou\Anaconda3\envs\lts\lib\site-packages\pymysql\connections.py", line 725, in _read_packet
    packet.raise_for_error()
  File "C:\Users\zhi.zhou\Anaconda3\envs\lts\lib\site-packages\pymysql\protocol.py", line 221, in raise_for_error
    err.raise_mysql_exception(self._data)
  File "C:\Users\zhi.zhou\Anaconda3\envs\lts\lib\site-packages\pymysql\err.py", line 143, in raise_mysql_exception
    raise errorclass(errno, errval)
pymysql.err.OperationalError: (1046, 'No database selected')

During handling of the above exception, another exception occurred:

Traceback (most recent call last):
  File "C:\Users\zhi.zhou\Anaconda3\envs\lts\lib\site-packages\django\core\handlers\exception.py", line 47, in inner
    response = get_response(request)
  File "C:\Users\zhi.zhou\Anaconda3\envs\lts\lib\site-packages\django\core\handlers\base.py", line 181, in _get_response
    response = wrapped_callback(request, *callback_args, **callback_kwargs)
  File "C:\Users\zhi.zhou\Anaconda3\envs\lts\lib\site-packages\django\views\generic\base.py", line 70, in view
    return self.dispatch(request, *args, **kwargs)
  File "C:\Users\zhi.zhou\Anaconda3\envs\lts\lib\site-packages\django\views\generic\base.py", line 98, in dispatch
    return handler(request, *args, **kwargs)
  File "D:\zhouzhi\gitlit_code\logistic_tracking_system\logistic_tracking_system\lts\views.py", line 3249, in get
    data = json.dumps(data)
  File "C:\Users\zhi.zhou\Anaconda3\envs\lts\lib\json\__init__.py", line 231, in dumps
    return _default_encoder.encode(obj)
  File "C:\Users\zhi.zhou\Anaconda3\envs\lts\lib\json\encoder.py", line 199, in encode
    chunks = self.iterencode(o, _one_shot=True)
  File "C:\Users\zhi.zhou\Anaconda3\envs\lts\lib\json\encoder.py", line 257, in iterencode
    return _iterencode(o, 0)
  File "C:\Users\zhi.zhou\Anaconda3\envs\lts\lib\json\encoder.py", line 180, in default
    o.__class__.__name__)
TypeError: Object of type 'OperationalError' is not JSON serializable
[2021-09-07 14:18:51,147][Thread-15:21172][task_id:django.request][log.py:230][ERROR][Internal Server Error: /logistic/LogisticProductPlanCodeName]
Traceback (most recent call last):
  File "D:\zhouzhi\gitlit_code\logistic_tracking_system\logistic_tracking_system\lts\views.py", line 3201, in get
    drs = db.execute_sql(conn, sql)
  File "D:\zhouzhi\gitlit_code\logistic_tracking_system\logistic_tracking_system\common\db.py", line 50, in execute_sql
    cursor.execute(sql)
  File "C:\Users\zhi.zhou\Anaconda3\envs\lts\lib\site-packages\pymysql\cursors.py", line 148, in execute
    result = self._query(query)
  File "C:\Users\zhi.zhou\Anaconda3\envs\lts\lib\site-packages\pymysql\cursors.py", line 310, in _query
    conn.query(q)
  File "C:\Users\zhi.zhou\Anaconda3\envs\lts\lib\site-packages\pymysql\connections.py", line 548, in query
    self._affected_rows = self._read_query_result(unbuffered=unbuffered)
  File "C:\Users\zhi.zhou\Anaconda3\envs\lts\lib\site-packages\pymysql\connections.py", line 775, in _read_query_result
    result.read()
  File "C:\Users\zhi.zhou\Anaconda3\envs\lts\lib\site-packages\pymysql\connections.py", line 1156, in read
    first_packet = self.connection._read_packet()
  File "C:\Users\zhi.zhou\Anaconda3\envs\lts\lib\site-packages\pymysql\connections.py", line 725, in _read_packet
    packet.raise_for_error()
  File "C:\Users\zhi.zhou\Anaconda3\envs\lts\lib\site-packages\pymysql\protocol.py", line 221, in raise_for_error
    err.raise_mysql_exception(self._data)
  File "C:\Users\zhi.zhou\Anaconda3\envs\lts\lib\site-packages\pymysql\err.py", line 143, in raise_mysql_exception
    raise errorclass(errno, errval)
pymysql.err.OperationalError: (1046, 'No database selected')

During handling of the above exception, another exception occurred:

Traceback (most recent call last):
  File "C:\Users\zhi.zhou\Anaconda3\envs\lts\lib\site-packages\django\core\handlers\exception.py", line 47, in inner
    response = get_response(request)
  File "C:\Users\zhi.zhou\Anaconda3\envs\lts\lib\site-packages\django\core\handlers\base.py", line 181, in _get_response
    response = wrapped_callback(request, *callback_args, **callback_kwargs)
  File "C:\Users\zhi.zhou\Anaconda3\envs\lts\lib\site-packages\django\views\generic\base.py", line 70, in view
    return self.dispatch(request, *args, **kwargs)
  File "C:\Users\zhi.zhou\Anaconda3\envs\lts\lib\site-packages\django\views\generic\base.py", line 98, in dispatch
    return handler(request, *args, **kwargs)
  File "D:\zhouzhi\gitlit_code\logistic_tracking_system\logistic_tracking_system\lts\views.py", line 3215, in get
    data = json.dumps(data)
  File "C:\Users\zhi.zhou\Anaconda3\envs\lts\lib\json\__init__.py", line 231, in dumps
    return _default_encoder.encode(obj)
  File "C:\Users\zhi.zhou\Anaconda3\envs\lts\lib\json\encoder.py", line 199, in encode
    chunks = self.iterencode(o, _one_shot=True)
  File "C:\Users\zhi.zhou\Anaconda3\envs\lts\lib\json\encoder.py", line 257, in iterencode
    return _iterencode(o, 0)
  File "C:\Users\zhi.zhou\Anaconda3\envs\lts\lib\json\encoder.py", line 180, in default
    o.__class__.__name__)
TypeError: Object of type 'OperationalError' is not JSON serializable
[2021-09-07 14:18:51,171][Thread-18:3996][task_id:django.request][log.py:230][ERROR][Internal Server Error: /logistic/LogisticWorkCodeName]
Traceback (most recent call last):
  File "D:\zhouzhi\gitlit_code\logistic_tracking_system\logistic_tracking_system\lts\views.py", line 3270, in get
    drs = db.execute_sql(conn, sql)
  File "D:\zhouzhi\gitlit_code\logistic_tracking_system\logistic_tracking_system\common\db.py", line 50, in execute_sql
    cursor.execute(sql)
  File "C:\Users\zhi.zhou\Anaconda3\envs\lts\lib\site-packages\pymysql\cursors.py", line 148, in execute
    result = self._query(query)
  File "C:\Users\zhi.zhou\Anaconda3\envs\lts\lib\site-packages\pymysql\cursors.py", line 310, in _query
    conn.query(q)
  File "C:\Users\zhi.zhou\Anaconda3\envs\lts\lib\site-packages\pymysql\connections.py", line 548, in query
    self._affected_rows = self._read_query_result(unbuffered=unbuffered)
  File "C:\Users\zhi.zhou\Anaconda3\envs\lts\lib\site-packages\pymysql\connections.py", line 775, in _read_query_result
    result.read()
  File "C:\Users\zhi.zhou\Anaconda3\envs\lts\lib\site-packages\pymysql\connections.py", line 1156, in read
    first_packet = self.connection._read_packet()
  File "C:\Users\zhi.zhou\Anaconda3\envs\lts\lib\site-packages\pymysql\connections.py", line 725, in _read_packet
    packet.raise_for_error()
  File "C:\Users\zhi.zhou\Anaconda3\envs\lts\lib\site-packages\pymysql\protocol.py", line 221, in raise_for_error
    err.raise_mysql_exception(self._data)
  File "C:\Users\zhi.zhou\Anaconda3\envs\lts\lib\site-packages\pymysql\err.py", line 143, in raise_mysql_exception
    raise errorclass(errno, errval)
pymysql.err.OperationalError: (1046, 'No database selected')

During handling of the above exception, another exception occurred:

Traceback (most recent call last):
  File "C:\Users\zhi.zhou\Anaconda3\envs\lts\lib\site-packages\django\core\handlers\exception.py", line 47, in inner
    response = get_response(request)
  File "C:\Users\zhi.zhou\Anaconda3\envs\lts\lib\site-packages\django\core\handlers\base.py", line 181, in _get_response
    response = wrapped_callback(request, *callback_args, **callback_kwargs)
  File "C:\Users\zhi.zhou\Anaconda3\envs\lts\lib\site-packages\django\views\generic\base.py", line 70, in view
    return self.dispatch(request, *args, **kwargs)
  File "C:\Users\zhi.zhou\Anaconda3\envs\lts\lib\site-packages\django\views\generic\base.py", line 98, in dispatch
    return handler(request, *args, **kwargs)
  File "D:\zhouzhi\gitlit_code\logistic_tracking_system\logistic_tracking_system\lts\views.py", line 3289, in get
    data = json.dumps(data)
  File "C:\Users\zhi.zhou\Anaconda3\envs\lts\lib\json\__init__.py", line 231, in dumps
    return _default_encoder.encode(obj)
  File "C:\Users\zhi.zhou\Anaconda3\envs\lts\lib\json\encoder.py", line 199, in encode
    chunks = self.iterencode(o, _one_shot=True)
  File "C:\Users\zhi.zhou\Anaconda3\envs\lts\lib\json\encoder.py", line 257, in iterencode
    return _iterencode(o, 0)
  File "C:\Users\zhi.zhou\Anaconda3\envs\lts\lib\json\encoder.py", line 180, in default
    o.__class__.__name__)
TypeError: Object of type 'OperationalError' is not JSON serializable
[2021-09-07 14:18:51,209][Thread-17:6528][task_id:django.request][log.py:230][ERROR][Internal Server Error: /logistic/LogisticMatterNameCode]
Traceback (most recent call last):
  File "D:\zhouzhi\gitlit_code\logistic_tracking_system\logistic_tracking_system\lts\views.py", line 3986, in get
    drs = db.execute_sql(conn, sql)
  File "D:\zhouzhi\gitlit_code\logistic_tracking_system\logistic_tracking_system\common\db.py", line 50, in execute_sql
    cursor.execute(sql)
  File "C:\Users\zhi.zhou\Anaconda3\envs\lts\lib\site-packages\pymysql\cursors.py", line 148, in execute
    result = self._query(query)
  File "C:\Users\zhi.zhou\Anaconda3\envs\lts\lib\site-packages\pymysql\cursors.py", line 310, in _query
    conn.query(q)
  File "C:\Users\zhi.zhou\Anaconda3\envs\lts\lib\site-packages\pymysql\connections.py", line 548, in query
    self._affected_rows = self._read_query_result(unbuffered=unbuffered)
  File "C:\Users\zhi.zhou\Anaconda3\envs\lts\lib\site-packages\pymysql\connections.py", line 775, in _read_query_result
    result.read()
  File "C:\Users\zhi.zhou\Anaconda3\envs\lts\lib\site-packages\pymysql\connections.py", line 1156, in read
    first_packet = self.connection._read_packet()
  File "C:\Users\zhi.zhou\Anaconda3\envs\lts\lib\site-packages\pymysql\connections.py", line 725, in _read_packet
    packet.raise_for_error()
  File "C:\Users\zhi.zhou\Anaconda3\envs\lts\lib\site-packages\pymysql\protocol.py", line 221, in raise_for_error
    err.raise_mysql_exception(self._data)
  File "C:\Users\zhi.zhou\Anaconda3\envs\lts\lib\site-packages\pymysql\err.py", line 143, in raise_mysql_exception
    raise errorclass(errno, errval)
pymysql.err.OperationalError: (1046, 'No database selected')

During handling of the above exception, another exception occurred:

Traceback (most recent call last):
  File "C:\Users\zhi.zhou\Anaconda3\envs\lts\lib\site-packages\django\core\handlers\exception.py", line 47, in inner
    response = get_response(request)
  File "C:\Users\zhi.zhou\Anaconda3\envs\lts\lib\site-packages\django\core\handlers\base.py", line 181, in _get_response
    response = wrapped_callback(request, *callback_args, **callback_kwargs)
  File "C:\Users\zhi.zhou\Anaconda3\envs\lts\lib\site-packages\django\views\generic\base.py", line 70, in view
    return self.dispatch(request, *args, **kwargs)
  File "C:\Users\zhi.zhou\Anaconda3\envs\lts\lib\site-packages\django\views\generic\base.py", line 98, in dispatch
    return handler(request, *args, **kwargs)
  File "D:\zhouzhi\gitlit_code\logistic_tracking_system\logistic_tracking_system\lts\views.py", line 4001, in get
    data = json.dumps(data)
  File "C:\Users\zhi.zhou\Anaconda3\envs\lts\lib\json\__init__.py", line 231, in dumps
    return _default_encoder.encode(obj)
  File "C:\Users\zhi.zhou\Anaconda3\envs\lts\lib\json\encoder.py", line 199, in encode
    chunks = self.iterencode(o, _one_shot=True)
  File "C:\Users\zhi.zhou\Anaconda3\envs\lts\lib\json\encoder.py", line 257, in iterencode
    return _iterencode(o, 0)
  File "C:\Users\zhi.zhou\Anaconda3\envs\lts\lib\json\encoder.py", line 180, in default
    o.__class__.__name__)
TypeError: Object of type 'OperationalError' is not JSON serializable
[2021-09-07 14:18:51,218][Thread-13:20008][task_id:django.request][log.py:230][ERROR][Internal Server Error: /logistic/LogisticPersonCodeName]
Traceback (most recent call last):
  File "D:\zhouzhi\gitlit_code\logistic_tracking_system\logistic_tracking_system\lts\views.py", line 3233, in get
    drs = db.execute_sql(conn, sql)
  File "D:\zhouzhi\gitlit_code\logistic_tracking_system\logistic_tracking_system\common\db.py", line 50, in execute_sql
    cursor.execute(sql)
  File "C:\Users\zhi.zhou\Anaconda3\envs\lts\lib\site-packages\pymysql\cursors.py", line 148, in execute
    result = self._query(query)
  File "C:\Users\zhi.zhou\Anaconda3\envs\lts\lib\site-packages\pymysql\cursors.py", line 310, in _query
    conn.query(q)
  File "C:\Users\zhi.zhou\Anaconda3\envs\lts\lib\site-packages\pymysql\connections.py", line 548, in query
    self._affected_rows = self._read_query_result(unbuffered=unbuffered)
  File "C:\Users\zhi.zhou\Anaconda3\envs\lts\lib\site-packages\pymysql\connections.py", line 775, in _read_query_result
    result.read()
  File "C:\Users\zhi.zhou\Anaconda3\envs\lts\lib\site-packages\pymysql\connections.py", line 1156, in read
    first_packet = self.connection._read_packet()
  File "C:\Users\zhi.zhou\Anaconda3\envs\lts\lib\site-packages\pymysql\connections.py", line 725, in _read_packet
    packet.raise_for_error()
  File "C:\Users\zhi.zhou\Anaconda3\envs\lts\lib\site-packages\pymysql\protocol.py", line 221, in raise_for_error
    err.raise_mysql_exception(self._data)
  File "C:\Users\zhi.zhou\Anaconda3\envs\lts\lib\site-packages\pymysql\err.py", line 143, in raise_mysql_exception
    raise errorclass(errno, errval)
pymysql.err.OperationalError: (1046, 'No database selected')

During handling of the above exception, another exception occurred:

Traceback (most recent call last):
  File "C:\Users\zhi.zhou\Anaconda3\envs\lts\lib\site-packages\django\core\handlers\exception.py", line 47, in inner
    response = get_response(request)
  File "C:\Users\zhi.zhou\Anaconda3\envs\lts\lib\site-packages\django\core\handlers\base.py", line 181, in _get_response
    response = wrapped_callback(request, *callback_args, **callback_kwargs)
  File "C:\Users\zhi.zhou\Anaconda3\envs\lts\lib\site-packages\django\views\generic\base.py", line 70, in view
    return self.dispatch(request, *args, **kwargs)
  File "C:\Users\zhi.zhou\Anaconda3\envs\lts\lib\site-packages\django\views\generic\base.py", line 98, in dispatch
    return handler(request, *args, **kwargs)
  File "D:\zhouzhi\gitlit_code\logistic_tracking_system\logistic_tracking_system\lts\views.py", line 3249, in get
    data = json.dumps(data)
  File "C:\Users\zhi.zhou\Anaconda3\envs\lts\lib\json\__init__.py", line 231, in dumps
    return _default_encoder.encode(obj)
  File "C:\Users\zhi.zhou\Anaconda3\envs\lts\lib\json\encoder.py", line 199, in encode
    chunks = self.iterencode(o, _one_shot=True)
  File "C:\Users\zhi.zhou\Anaconda3\envs\lts\lib\json\encoder.py", line 257, in iterencode
    return _iterencode(o, 0)
  File "C:\Users\zhi.zhou\Anaconda3\envs\lts\lib\json\encoder.py", line 180, in default
    o.__class__.__name__)
TypeError: Object of type 'OperationalError' is not JSON serializable
[2021-09-07 14:19:21,249][Thread-17:6528][task_id:lts.views][views.py:2214][ERROR][查询生产计划表信息失败(1046, 'No database selected')]
[2021-09-07 14:19:21,274][Thread-17:6528][task_id:lts.views][views.py:6360][ERROR][不分页的查询物料信息失败,(1046, 'No database selected')]
[2021-09-07 14:19:21,323][Thread-18:3996][task_id:django.request][log.py:230][ERROR][Internal Server Error: /logistic/LogisticProductPlanCodeName]
Traceback (most recent call last):
  File "D:\zhouzhi\gitlit_code\logistic_tracking_system\logistic_tracking_system\lts\views.py", line 3201, in get
    drs = db.execute_sql(conn, sql)
  File "D:\zhouzhi\gitlit_code\logistic_tracking_system\logistic_tracking_system\common\db.py", line 50, in execute_sql
    cursor.execute(sql)
  File "C:\Users\zhi.zhou\Anaconda3\envs\lts\lib\site-packages\pymysql\cursors.py", line 148, in execute
    result = self._query(query)
  File "C:\Users\zhi.zhou\Anaconda3\envs\lts\lib\site-packages\pymysql\cursors.py", line 310, in _query
    conn.query(q)
  File "C:\Users\zhi.zhou\Anaconda3\envs\lts\lib\site-packages\pymysql\connections.py", line 548, in query
    self._affected_rows = self._read_query_result(unbuffered=unbuffered)
  File "C:\Users\zhi.zhou\Anaconda3\envs\lts\lib\site-packages\pymysql\connections.py", line 775, in _read_query_result
    result.read()
  File "C:\Users\zhi.zhou\Anaconda3\envs\lts\lib\site-packages\pymysql\connections.py", line 1156, in read
    first_packet = self.connection._read_packet()
  File "C:\Users\zhi.zhou\Anaconda3\envs\lts\lib\site-packages\pymysql\connections.py", line 725, in _read_packet
    packet.raise_for_error()
  File "C:\Users\zhi.zhou\Anaconda3\envs\lts\lib\site-packages\pymysql\protocol.py", line 221, in raise_for_error
    err.raise_mysql_exception(self._data)
  File "C:\Users\zhi.zhou\Anaconda3\envs\lts\lib\site-packages\pymysql\err.py", line 143, in raise_mysql_exception
    raise errorclass(errno, errval)
pymysql.err.OperationalError: (1046, 'No database selected')

During handling of the above exception, another exception occurred:

Traceback (most recent call last):
  File "C:\Users\zhi.zhou\Anaconda3\envs\lts\lib\site-packages\django\core\handlers\exception.py", line 47, in inner
    response = get_response(request)
  File "C:\Users\zhi.zhou\Anaconda3\envs\lts\lib\site-packages\django\core\handlers\base.py", line 181, in _get_response
    response = wrapped_callback(request, *callback_args, **callback_kwargs)
  File "C:\Users\zhi.zhou\Anaconda3\envs\lts\lib\site-packages\django\views\generic\base.py", line 70, in view
    return self.dispatch(request, *args, **kwargs)
  File "C:\Users\zhi.zhou\Anaconda3\envs\lts\lib\site-packages\django\views\generic\base.py", line 98, in dispatch
    return handler(request, *args, **kwargs)
  File "D:\zhouzhi\gitlit_code\logistic_tracking_system\logistic_tracking_system\lts\views.py", line 3215, in get
    data = json.dumps(data)
  File "C:\Users\zhi.zhou\Anaconda3\envs\lts\lib\json\__init__.py", line 231, in dumps
    return _default_encoder.encode(obj)
  File "C:\Users\zhi.zhou\Anaconda3\envs\lts\lib\json\encoder.py", line 199, in encode
    chunks = self.iterencode(o, _one_shot=True)
  File "C:\Users\zhi.zhou\Anaconda3\envs\lts\lib\json\encoder.py", line 257, in iterencode
    return _iterencode(o, 0)
  File "C:\Users\zhi.zhou\Anaconda3\envs\lts\lib\json\encoder.py", line 180, in default
    o.__class__.__name__)
TypeError: Object of type 'OperationalError' is not JSON serializable
[2021-09-07 14:19:21,354][Thread-15:21172][task_id:django.request][log.py:230][ERROR][Internal Server Error: /logistic/LogisticPersonCodeName]
Traceback (most recent call last):
  File "D:\zhouzhi\gitlit_code\logistic_tracking_system\logistic_tracking_system\lts\views.py", line 3233, in get
    drs = db.execute_sql(conn, sql)
  File "D:\zhouzhi\gitlit_code\logistic_tracking_system\logistic_tracking_system\common\db.py", line 50, in execute_sql
    cursor.execute(sql)
  File "C:\Users\zhi.zhou\Anaconda3\envs\lts\lib\site-packages\pymysql\cursors.py", line 148, in execute
    result = self._query(query)
  File "C:\Users\zhi.zhou\Anaconda3\envs\lts\lib\site-packages\pymysql\cursors.py", line 310, in _query
    conn.query(q)
  File "C:\Users\zhi.zhou\Anaconda3\envs\lts\lib\site-packages\pymysql\connections.py", line 548, in query
    self._affected_rows = self._read_query_result(unbuffered=unbuffered)
  File "C:\Users\zhi.zhou\Anaconda3\envs\lts\lib\site-packages\pymysql\connections.py", line 775, in _read_query_result
    result.read()
  File "C:\Users\zhi.zhou\Anaconda3\envs\lts\lib\site-packages\pymysql\connections.py", line 1156, in read
    first_packet = self.connection._read_packet()
  File "C:\Users\zhi.zhou\Anaconda3\envs\lts\lib\site-packages\pymysql\connections.py", line 725, in _read_packet
    packet.raise_for_error()
  File "C:\Users\zhi.zhou\Anaconda3\envs\lts\lib\site-packages\pymysql\protocol.py", line 221, in raise_for_error
    err.raise_mysql_exception(self._data)
  File "C:\Users\zhi.zhou\Anaconda3\envs\lts\lib\site-packages\pymysql\err.py", line 143, in raise_mysql_exception
    raise errorclass(errno, errval)
pymysql.err.OperationalError: (1046, 'No database selected')

During handling of the above exception, another exception occurred:

Traceback (most recent call last):
  File "C:\Users\zhi.zhou\Anaconda3\envs\lts\lib\site-packages\django\core\handlers\exception.py", line 47, in inner
    response = get_response(request)
  File "C:\Users\zhi.zhou\Anaconda3\envs\lts\lib\site-packages\django\core\handlers\base.py", line 181, in _get_response
    response = wrapped_callback(request, *callback_args, **callback_kwargs)
  File "C:\Users\zhi.zhou\Anaconda3\envs\lts\lib\site-packages\django\views\generic\base.py", line 70, in view
    return self.dispatch(request, *args, **kwargs)
  File "C:\Users\zhi.zhou\Anaconda3\envs\lts\lib\site-packages\django\views\generic\base.py", line 98, in dispatch
    return handler(request, *args, **kwargs)
  File "D:\zhouzhi\gitlit_code\logistic_tracking_system\logistic_tracking_system\lts\views.py", line 3249, in get
    data = json.dumps(data)
  File "C:\Users\zhi.zhou\Anaconda3\envs\lts\lib\json\__init__.py", line 231, in dumps
    return _default_encoder.encode(obj)
  File "C:\Users\zhi.zhou\Anaconda3\envs\lts\lib\json\encoder.py", line 199, in encode
    chunks = self.iterencode(o, _one_shot=True)
  File "C:\Users\zhi.zhou\Anaconda3\envs\lts\lib\json\encoder.py", line 257, in iterencode
    return _iterencode(o, 0)
  File "C:\Users\zhi.zhou\Anaconda3\envs\lts\lib\json\encoder.py", line 180, in default
    o.__class__.__name__)
TypeError: Object of type 'OperationalError' is not JSON serializable
[2021-09-07 14:19:21,383][Thread-16:18716][task_id:django.request][log.py:230][ERROR][Internal Server Error: /logistic/LogisticMatterNameCode]
Traceback (most recent call last):
  File "D:\zhouzhi\gitlit_code\logistic_tracking_system\logistic_tracking_system\lts\views.py", line 3986, in get
    drs = db.execute_sql(conn, sql)
  File "D:\zhouzhi\gitlit_code\logistic_tracking_system\logistic_tracking_system\common\db.py", line 50, in execute_sql
    cursor.execute(sql)
  File "C:\Users\zhi.zhou\Anaconda3\envs\lts\lib\site-packages\pymysql\cursors.py", line 148, in execute
    result = self._query(query)
  File "C:\Users\zhi.zhou\Anaconda3\envs\lts\lib\site-packages\pymysql\cursors.py", line 310, in _query
    conn.query(q)
  File "C:\Users\zhi.zhou\Anaconda3\envs\lts\lib\site-packages\pymysql\connections.py", line 548, in query
    self._affected_rows = self._read_query_result(unbuffered=unbuffered)
  File "C:\Users\zhi.zhou\Anaconda3\envs\lts\lib\site-packages\pymysql\connections.py", line 775, in _read_query_result
    result.read()
  File "C:\Users\zhi.zhou\Anaconda3\envs\lts\lib\site-packages\pymysql\connections.py", line 1156, in read
    first_packet = self.connection._read_packet()
  File "C:\Users\zhi.zhou\Anaconda3\envs\lts\lib\site-packages\pymysql\connections.py", line 725, in _read_packet
    packet.raise_for_error()
  File "C:\Users\zhi.zhou\Anaconda3\envs\lts\lib\site-packages\pymysql\protocol.py", line 221, in raise_for_error
    err.raise_mysql_exception(self._data)
  File "C:\Users\zhi.zhou\Anaconda3\envs\lts\lib\site-packages\pymysql\err.py", line 143, in raise_mysql_exception
    raise errorclass(errno, errval)
pymysql.err.OperationalError: (1046, 'No database selected')

During handling of the above exception, another exception occurred:

Traceback (most recent call last):
  File "C:\Users\zhi.zhou\Anaconda3\envs\lts\lib\site-packages\django\core\handlers\exception.py", line 47, in inner
    response = get_response(request)
  File "C:\Users\zhi.zhou\Anaconda3\envs\lts\lib\site-packages\django\core\handlers\base.py", line 181, in _get_response
    response = wrapped_callback(request, *callback_args, **callback_kwargs)
  File "C:\Users\zhi.zhou\Anaconda3\envs\lts\lib\site-packages\django\views\generic\base.py", line 70, in view
    return self.dispatch(request, *args, **kwargs)
  File "C:\Users\zhi.zhou\Anaconda3\envs\lts\lib\site-packages\django\views\generic\base.py", line 98, in dispatch
    return handler(request, *args, **kwargs)
  File "D:\zhouzhi\gitlit_code\logistic_tracking_system\logistic_tracking_system\lts\views.py", line 4001, in get
    data = json.dumps(data)
  File "C:\Users\zhi.zhou\Anaconda3\envs\lts\lib\json\__init__.py", line 231, in dumps
    return _default_encoder.encode(obj)
  File "C:\Users\zhi.zhou\Anaconda3\envs\lts\lib\json\encoder.py", line 199, in encode
    chunks = self.iterencode(o, _one_shot=True)
  File "C:\Users\zhi.zhou\Anaconda3\envs\lts\lib\json\encoder.py", line 257, in iterencode
    return _iterencode(o, 0)
  File "C:\Users\zhi.zhou\Anaconda3\envs\lts\lib\json\encoder.py", line 180, in default
    o.__class__.__name__)
TypeError: Object of type 'OperationalError' is not JSON serializable
[2021-09-07 14:19:21,432][Thread-13:20008][task_id:django.request][log.py:230][ERROR][Internal Server Error: /logistic/LogisticPersonCodeName]
Traceback (most recent call last):
  File "D:\zhouzhi\gitlit_code\logistic_tracking_system\logistic_tracking_system\lts\views.py", line 3233, in get
    drs = db.execute_sql(conn, sql)
  File "D:\zhouzhi\gitlit_code\logistic_tracking_system\logistic_tracking_system\common\db.py", line 50, in execute_sql
    cursor.execute(sql)
  File "C:\Users\zhi.zhou\Anaconda3\envs\lts\lib\site-packages\pymysql\cursors.py", line 148, in execute
    result = self._query(query)
  File "C:\Users\zhi.zhou\Anaconda3\envs\lts\lib\site-packages\pymysql\cursors.py", line 310, in _query
    conn.query(q)
  File "C:\Users\zhi.zhou\Anaconda3\envs\lts\lib\site-packages\pymysql\connections.py", line 548, in query
    self._affected_rows = self._read_query_result(unbuffered=unbuffered)
  File "C:\Users\zhi.zhou\Anaconda3\envs\lts\lib\site-packages\pymysql\connections.py", line 775, in _read_query_result
    result.read()
  File "C:\Users\zhi.zhou\Anaconda3\envs\lts\lib\site-packages\pymysql\connections.py", line 1156, in read
    first_packet = self.connection._read_packet()
  File "C:\Users\zhi.zhou\Anaconda3\envs\lts\lib\site-packages\pymysql\connections.py", line 725, in _read_packet
    packet.raise_for_error()
  File "C:\Users\zhi.zhou\Anaconda3\envs\lts\lib\site-packages\pymysql\protocol.py", line 221, in raise_for_error
    err.raise_mysql_exception(self._data)
  File "C:\Users\zhi.zhou\Anaconda3\envs\lts\lib\site-packages\pymysql\err.py", line 143, in raise_mysql_exception
    raise errorclass(errno, errval)
pymysql.err.OperationalError: (1046, 'No database selected')

During handling of the above exception, another exception occurred:

Traceback (most recent call last):
  File "C:\Users\zhi.zhou\Anaconda3\envs\lts\lib\site-packages\django\core\handlers\exception.py", line 47, in inner
    response = get_response(request)
  File "C:\Users\zhi.zhou\Anaconda3\envs\lts\lib\site-packages\django\core\handlers\base.py", line 181, in _get_response
    response = wrapped_callback(request, *callback_args, **callback_kwargs)
  File "C:\Users\zhi.zhou\Anaconda3\envs\lts\lib\site-packages\django\views\generic\base.py", line 70, in view
    return self.dispatch(request, *args, **kwargs)
  File "C:\Users\zhi.zhou\Anaconda3\envs\lts\lib\site-packages\django\views\generic\base.py", line 98, in dispatch
    return handler(request, *args, **kwargs)
  File "D:\zhouzhi\gitlit_code\logistic_tracking_system\logistic_tracking_system\lts\views.py", line 3249, in get
    data = json.dumps(data)
  File "C:\Users\zhi.zhou\Anaconda3\envs\lts\lib\json\__init__.py", line 231, in dumps
    return _default_encoder.encode(obj)
  File "C:\Users\zhi.zhou\Anaconda3\envs\lts\lib\json\encoder.py", line 199, in encode
    chunks = self.iterencode(o, _one_shot=True)
  File "C:\Users\zhi.zhou\Anaconda3\envs\lts\lib\json\encoder.py", line 257, in iterencode
    return _iterencode(o, 0)
  File "C:\Users\zhi.zhou\Anaconda3\envs\lts\lib\json\encoder.py", line 180, in default
    o.__class__.__name__)
TypeError: Object of type 'OperationalError' is not JSON serializable
[2021-09-07 14:19:21,434][Thread-14:19564][task_id:django.request][log.py:230][ERROR][Internal Server Error: /logistic/LogisticWorkCodeName]
Traceback (most recent call last):
  File "D:\zhouzhi\gitlit_code\logistic_tracking_system\logistic_tracking_system\lts\views.py", line 3270, in get
    drs = db.execute_sql(conn, sql)
  File "D:\zhouzhi\gitlit_code\logistic_tracking_system\logistic_tracking_system\common\db.py", line 50, in execute_sql
    cursor.execute(sql)
  File "C:\Users\zhi.zhou\Anaconda3\envs\lts\lib\site-packages\pymysql\cursors.py", line 148, in execute
    result = self._query(query)
  File "C:\Users\zhi.zhou\Anaconda3\envs\lts\lib\site-packages\pymysql\cursors.py", line 310, in _query
    conn.query(q)
  File "C:\Users\zhi.zhou\Anaconda3\envs\lts\lib\site-packages\pymysql\connections.py", line 548, in query
    self._affected_rows = self._read_query_result(unbuffered=unbuffered)
  File "C:\Users\zhi.zhou\Anaconda3\envs\lts\lib\site-packages\pymysql\connections.py", line 775, in _read_query_result
    result.read()
  File "C:\Users\zhi.zhou\Anaconda3\envs\lts\lib\site-packages\pymysql\connections.py", line 1156, in read
    first_packet = self.connection._read_packet()
  File "C:\Users\zhi.zhou\Anaconda3\envs\lts\lib\site-packages\pymysql\connections.py", line 725, in _read_packet
    packet.raise_for_error()
  File "C:\Users\zhi.zhou\Anaconda3\envs\lts\lib\site-packages\pymysql\protocol.py", line 221, in raise_for_error
    err.raise_mysql_exception(self._data)
  File "C:\Users\zhi.zhou\Anaconda3\envs\lts\lib\site-packages\pymysql\err.py", line 143, in raise_mysql_exception
    raise errorclass(errno, errval)
pymysql.err.OperationalError: (1046, 'No database selected')

During handling of the above exception, another exception occurred:

Traceback (most recent call last):
  File "C:\Users\zhi.zhou\Anaconda3\envs\lts\lib\site-packages\django\core\handlers\exception.py", line 47, in inner
    response = get_response(request)
  File "C:\Users\zhi.zhou\Anaconda3\envs\lts\lib\site-packages\django\core\handlers\base.py", line 181, in _get_response
    response = wrapped_callback(request, *callback_args, **callback_kwargs)
  File "C:\Users\zhi.zhou\Anaconda3\envs\lts\lib\site-packages\django\views\generic\base.py", line 70, in view
    return self.dispatch(request, *args, **kwargs)
  File "C:\Users\zhi.zhou\Anaconda3\envs\lts\lib\site-packages\django\views\generic\base.py", line 98, in dispatch
    return handler(request, *args, **kwargs)
  File "D:\zhouzhi\gitlit_code\logistic_tracking_system\logistic_tracking_system\lts\views.py", line 3289, in get
    data = json.dumps(data)
  File "C:\Users\zhi.zhou\Anaconda3\envs\lts\lib\json\__init__.py", line 231, in dumps
    return _default_encoder.encode(obj)
  File "C:\Users\zhi.zhou\Anaconda3\envs\lts\lib\json\encoder.py", line 199, in encode
    chunks = self.iterencode(o, _one_shot=True)
  File "C:\Users\zhi.zhou\Anaconda3\envs\lts\lib\json\encoder.py", line 257, in iterencode
    return _iterencode(o, 0)
  File "C:\Users\zhi.zhou\Anaconda3\envs\lts\lib\json\encoder.py", line 180, in default
    o.__class__.__name__)
TypeError: Object of type 'OperationalError' is not JSON serializable
[2021-09-07 15:24:14,562][Thread-1:1556][task_id:django.request][log.py:230][ERROR][Internal Server Error: /logistic/LogisticOperationSystem]
Traceback (most recent call last):
  File "D:\zhouzhi\gitlit_code\logistic_tracking_system\logistic_tracking_system\lts\views.py", line 6493, in get
    drs = db.execute_sql(conn, sql)
  File "D:\zhouzhi\gitlit_code\logistic_tracking_system\logistic_tracking_system\common\db.py", line 50, in execute_sql
    cursor.execute(sql)
  File "C:\Users\zhi.zhou\Anaconda3\envs\lts\lib\site-packages\pymysql\cursors.py", line 148, in execute
    result = self._query(query)
  File "C:\Users\zhi.zhou\Anaconda3\envs\lts\lib\site-packages\pymysql\cursors.py", line 310, in _query
    conn.query(q)
  File "C:\Users\zhi.zhou\Anaconda3\envs\lts\lib\site-packages\pymysql\connections.py", line 548, in query
    self._affected_rows = self._read_query_result(unbuffered=unbuffered)
  File "C:\Users\zhi.zhou\Anaconda3\envs\lts\lib\site-packages\pymysql\connections.py", line 775, in _read_query_result
    result.read()
  File "C:\Users\zhi.zhou\Anaconda3\envs\lts\lib\site-packages\pymysql\connections.py", line 1156, in read
    first_packet = self.connection._read_packet()
  File "C:\Users\zhi.zhou\Anaconda3\envs\lts\lib\site-packages\pymysql\connections.py", line 725, in _read_packet
    packet.raise_for_error()
  File "C:\Users\zhi.zhou\Anaconda3\envs\lts\lib\site-packages\pymysql\protocol.py", line 221, in raise_for_error
    err.raise_mysql_exception(self._data)
  File "C:\Users\zhi.zhou\Anaconda3\envs\lts\lib\site-packages\pymysql\err.py", line 143, in raise_mysql_exception
    raise errorclass(errno, errval)
pymysql.err.OperationalError: (1046, 'No database selected')

During handling of the above exception, another exception occurred:

Traceback (most recent call last):
  File "C:\Users\zhi.zhou\Anaconda3\envs\lts\lib\site-packages\django\core\handlers\exception.py", line 47, in inner
    response = get_response(request)
  File "C:\Users\zhi.zhou\Anaconda3\envs\lts\lib\site-packages\django\core\handlers\base.py", line 181, in _get_response
    response = wrapped_callback(request, *callback_args, **callback_kwargs)
  File "C:\Users\zhi.zhou\Anaconda3\envs\lts\lib\site-packages\django\views\generic\base.py", line 70, in view
    return self.dispatch(request, *args, **kwargs)
  File "C:\Users\zhi.zhou\Anaconda3\envs\lts\lib\site-packages\django\views\generic\base.py", line 98, in dispatch
    return handler(request, *args, **kwargs)
  File "D:\zhouzhi\gitlit_code\logistic_tracking_system\logistic_tracking_system\lts\views.py", line 6535, in get
    result = json.dumps(result)
  File "C:\Users\zhi.zhou\Anaconda3\envs\lts\lib\json\__init__.py", line 231, in dumps
    return _default_encoder.encode(obj)
  File "C:\Users\zhi.zhou\Anaconda3\envs\lts\lib\json\encoder.py", line 199, in encode
    chunks = self.iterencode(o, _one_shot=True)
  File "C:\Users\zhi.zhou\Anaconda3\envs\lts\lib\json\encoder.py", line 257, in iterencode
    return _iterencode(o, 0)
  File "C:\Users\zhi.zhou\Anaconda3\envs\lts\lib\json\encoder.py", line 180, in default
    o.__class__.__name__)
TypeError: Object of type 'OperationalError' is not JSON serializable
