[2021-08-17 09:36:32,105][Thread-2:15380][task_id:lts.views][views.py:1352][ERROR][查询产品列表失败]
[2021-08-17 09:50:13,646][Thread-1:15904][task_id:lts.views][views.py:1352][ERROR][查询产品列表失败]
[2021-08-17 10:44:04,974][Thread-2:17048][task_id:django.request][log.py:230][ERROR][Internal Server Error: /logistic/LogisticWorkCodeName]
Traceback (most recent call last):
  File "D:\zhouzhi\gitlit_code\logistic_tracking_system\logistic_tracking_system\lts\views.py", line 3579, in get
    drs = db.execute_sql(conn, sql)
  File "D:\zhouzhi\gitlit_code\logistic_tracking_system\logistic_tracking_system\common\db.py", line 45, in execute_sql
    cursor.execute(sql)
  File "C:\Users\zhi.zhou\Anaconda3\envs\lts\lib\site-packages\pymysql\cursors.py", line 148, in execute
    result = self._query(query)
  File "C:\Users\zhi.zhou\Anaconda3\envs\lts\lib\site-packages\pymysql\cursors.py", line 310, in _query
    conn.query(q)
  File "C:\Users\zhi.zhou\Anaconda3\envs\lts\lib\site-packages\pymysql\connections.py", line 548, in query
    self._affected_rows = self._read_query_result(unbuffered=unbuffered)
  File "C:\Users\zhi.zhou\Anaconda3\envs\lts\lib\site-packages\pymysql\connections.py", line 775, in _read_query_result
    result.read()
  File "C:\Users\zhi.zhou\Anaconda3\envs\lts\lib\site-packages\pymysql\connections.py", line 1156, in read
    first_packet = self.connection._read_packet()
  File "C:\Users\zhi.zhou\Anaconda3\envs\lts\lib\site-packages\pymysql\connections.py", line 725, in _read_packet
    packet.raise_for_error()
  File "C:\Users\zhi.zhou\Anaconda3\envs\lts\lib\site-packages\pymysql\protocol.py", line 221, in raise_for_error
    err.raise_mysql_exception(self._data)
  File "C:\Users\zhi.zhou\Anaconda3\envs\lts\lib\site-packages\pymysql\err.py", line 143, in raise_mysql_exception
    raise errorclass(errno, errval)
pymysql.err.OperationalError: (1046, 'No database selected')

During handling of the above exception, another exception occurred:

Traceback (most recent call last):
  File "C:\Users\zhi.zhou\Anaconda3\envs\lts\lib\site-packages\django\core\handlers\exception.py", line 47, in inner
    response = get_response(request)
  File "C:\Users\zhi.zhou\Anaconda3\envs\lts\lib\site-packages\django\core\handlers\base.py", line 181, in _get_response
    response = wrapped_callback(request, *callback_args, **callback_kwargs)
  File "C:\Users\zhi.zhou\Anaconda3\envs\lts\lib\site-packages\django\views\generic\base.py", line 70, in view
    return self.dispatch(request, *args, **kwargs)
  File "C:\Users\zhi.zhou\Anaconda3\envs\lts\lib\site-packages\django\views\generic\base.py", line 98, in dispatch
    return handler(request, *args, **kwargs)
  File "D:\zhouzhi\gitlit_code\logistic_tracking_system\logistic_tracking_system\lts\views.py", line 3594, in get
    data = json.dumps(data)
  File "C:\Users\zhi.zhou\Anaconda3\envs\lts\lib\json\__init__.py", line 231, in dumps
    return _default_encoder.encode(obj)
  File "C:\Users\zhi.zhou\Anaconda3\envs\lts\lib\json\encoder.py", line 199, in encode
    chunks = self.iterencode(o, _one_shot=True)
  File "C:\Users\zhi.zhou\Anaconda3\envs\lts\lib\json\encoder.py", line 257, in iterencode
    return _iterencode(o, 0)
  File "C:\Users\zhi.zhou\Anaconda3\envs\lts\lib\json\encoder.py", line 180, in default
    o.__class__.__name__)
TypeError: Object of type 'OperationalError' is not JSON serializable
[2021-08-17 11:29:35,240][Thread-13:21084][task_id:django.request][log.py:230][ERROR][Internal Server Error: /logistic/LogisticWorkCodeName]
Traceback (most recent call last):
  File "D:\zhouzhi\gitlit_code\logistic_tracking_system\logistic_tracking_system\lts\views.py", line 3583, in get
    drs = db.execute_sql(conn, sql)
  File "D:\zhouzhi\gitlit_code\logistic_tracking_system\logistic_tracking_system\common\db.py", line 45, in execute_sql
    cursor.execute(sql)
  File "C:\Users\zhi.zhou\Anaconda3\envs\lts\lib\site-packages\pymysql\cursors.py", line 148, in execute
    result = self._query(query)
  File "C:\Users\zhi.zhou\Anaconda3\envs\lts\lib\site-packages\pymysql\cursors.py", line 310, in _query
    conn.query(q)
  File "C:\Users\zhi.zhou\Anaconda3\envs\lts\lib\site-packages\pymysql\connections.py", line 548, in query
    self._affected_rows = self._read_query_result(unbuffered=unbuffered)
  File "C:\Users\zhi.zhou\Anaconda3\envs\lts\lib\site-packages\pymysql\connections.py", line 775, in _read_query_result
    result.read()
  File "C:\Users\zhi.zhou\Anaconda3\envs\lts\lib\site-packages\pymysql\connections.py", line 1156, in read
    first_packet = self.connection._read_packet()
  File "C:\Users\zhi.zhou\Anaconda3\envs\lts\lib\site-packages\pymysql\connections.py", line 725, in _read_packet
    packet.raise_for_error()
  File "C:\Users\zhi.zhou\Anaconda3\envs\lts\lib\site-packages\pymysql\protocol.py", line 221, in raise_for_error
    err.raise_mysql_exception(self._data)
  File "C:\Users\zhi.zhou\Anaconda3\envs\lts\lib\site-packages\pymysql\err.py", line 143, in raise_mysql_exception
    raise errorclass(errno, errval)
pymysql.err.OperationalError: (1046, 'No database selected')

During handling of the above exception, another exception occurred:

Traceback (most recent call last):
  File "C:\Users\zhi.zhou\Anaconda3\envs\lts\lib\site-packages\django\core\handlers\exception.py", line 47, in inner
    response = get_response(request)
  File "C:\Users\zhi.zhou\Anaconda3\envs\lts\lib\site-packages\django\core\handlers\base.py", line 181, in _get_response
    response = wrapped_callback(request, *callback_args, **callback_kwargs)
  File "C:\Users\zhi.zhou\Anaconda3\envs\lts\lib\site-packages\django\views\generic\base.py", line 70, in view
    return self.dispatch(request, *args, **kwargs)
  File "C:\Users\zhi.zhou\Anaconda3\envs\lts\lib\site-packages\django\views\generic\base.py", line 98, in dispatch
    return handler(request, *args, **kwargs)
  File "D:\zhouzhi\gitlit_code\logistic_tracking_system\logistic_tracking_system\lts\views.py", line 3598, in get
    data = json.dumps(data)
  File "C:\Users\zhi.zhou\Anaconda3\envs\lts\lib\json\__init__.py", line 231, in dumps
    return _default_encoder.encode(obj)
  File "C:\Users\zhi.zhou\Anaconda3\envs\lts\lib\json\encoder.py", line 199, in encode
    chunks = self.iterencode(o, _one_shot=True)
  File "C:\Users\zhi.zhou\Anaconda3\envs\lts\lib\json\encoder.py", line 257, in iterencode
    return _iterencode(o, 0)
  File "C:\Users\zhi.zhou\Anaconda3\envs\lts\lib\json\encoder.py", line 180, in default
    o.__class__.__name__)
TypeError: Object of type 'OperationalError' is not JSON serializable
[2021-08-17 11:29:51,184][Thread-13:21084][task_id:django.request][log.py:230][ERROR][Internal Server Error: /logistic/LogisticCurrentUserInfo]
Traceback (most recent call last):
  File "D:\zhouzhi\gitlit_code\logistic_tracking_system\logistic_tracking_system\lts\views.py", line 4380, in get
    drs = db.execute_sql(conn_num, sql_num)
  File "D:\zhouzhi\gitlit_code\logistic_tracking_system\logistic_tracking_system\common\db.py", line 45, in execute_sql
    cursor.execute(sql)
  File "C:\Users\zhi.zhou\Anaconda3\envs\lts\lib\site-packages\pymysql\cursors.py", line 148, in execute
    result = self._query(query)
  File "C:\Users\zhi.zhou\Anaconda3\envs\lts\lib\site-packages\pymysql\cursors.py", line 310, in _query
    conn.query(q)
  File "C:\Users\zhi.zhou\Anaconda3\envs\lts\lib\site-packages\pymysql\connections.py", line 548, in query
    self._affected_rows = self._read_query_result(unbuffered=unbuffered)
  File "C:\Users\zhi.zhou\Anaconda3\envs\lts\lib\site-packages\pymysql\connections.py", line 775, in _read_query_result
    result.read()
  File "C:\Users\zhi.zhou\Anaconda3\envs\lts\lib\site-packages\pymysql\connections.py", line 1156, in read
    first_packet = self.connection._read_packet()
  File "C:\Users\zhi.zhou\Anaconda3\envs\lts\lib\site-packages\pymysql\connections.py", line 725, in _read_packet
    packet.raise_for_error()
  File "C:\Users\zhi.zhou\Anaconda3\envs\lts\lib\site-packages\pymysql\protocol.py", line 221, in raise_for_error
    err.raise_mysql_exception(self._data)
  File "C:\Users\zhi.zhou\Anaconda3\envs\lts\lib\site-packages\pymysql\err.py", line 143, in raise_mysql_exception
    raise errorclass(errno, errval)
pymysql.err.OperationalError: (1046, 'No database selected')

During handling of the above exception, another exception occurred:

Traceback (most recent call last):
  File "C:\Users\zhi.zhou\Anaconda3\envs\lts\lib\site-packages\django\core\handlers\exception.py", line 47, in inner
    response = get_response(request)
  File "C:\Users\zhi.zhou\Anaconda3\envs\lts\lib\site-packages\django\core\handlers\base.py", line 181, in _get_response
    response = wrapped_callback(request, *callback_args, **callback_kwargs)
  File "C:\Users\zhi.zhou\Anaconda3\envs\lts\lib\site-packages\django\views\generic\base.py", line 70, in view
    return self.dispatch(request, *args, **kwargs)
  File "C:\Users\zhi.zhou\Anaconda3\envs\lts\lib\site-packages\django\views\generic\base.py", line 98, in dispatch
    return handler(request, *args, **kwargs)
  File "D:\zhouzhi\gitlit_code\logistic_tracking_system\logistic_tracking_system\lts\views.py", line 4419, in get
    data = json.dumps(data)
  File "C:\Users\zhi.zhou\Anaconda3\envs\lts\lib\json\__init__.py", line 231, in dumps
    return _default_encoder.encode(obj)
  File "C:\Users\zhi.zhou\Anaconda3\envs\lts\lib\json\encoder.py", line 199, in encode
    chunks = self.iterencode(o, _one_shot=True)
  File "C:\Users\zhi.zhou\Anaconda3\envs\lts\lib\json\encoder.py", line 257, in iterencode
    return _iterencode(o, 0)
  File "C:\Users\zhi.zhou\Anaconda3\envs\lts\lib\json\encoder.py", line 180, in default
    o.__class__.__name__)
TypeError: Object of type 'OperationalError' is not JSON serializable
[2021-08-17 11:29:51,260][Thread-13:21084][task_id:django.request][log.py:230][ERROR][Internal Server Error: /logistic/LogisticCurrentUserInfo]
Traceback (most recent call last):
  File "D:\zhouzhi\gitlit_code\logistic_tracking_system\logistic_tracking_system\lts\views.py", line 4380, in get
    drs = db.execute_sql(conn_num, sql_num)
  File "D:\zhouzhi\gitlit_code\logistic_tracking_system\logistic_tracking_system\common\db.py", line 45, in execute_sql
    cursor.execute(sql)
  File "C:\Users\zhi.zhou\Anaconda3\envs\lts\lib\site-packages\pymysql\cursors.py", line 148, in execute
    result = self._query(query)
  File "C:\Users\zhi.zhou\Anaconda3\envs\lts\lib\site-packages\pymysql\cursors.py", line 310, in _query
    conn.query(q)
  File "C:\Users\zhi.zhou\Anaconda3\envs\lts\lib\site-packages\pymysql\connections.py", line 548, in query
    self._affected_rows = self._read_query_result(unbuffered=unbuffered)
  File "C:\Users\zhi.zhou\Anaconda3\envs\lts\lib\site-packages\pymysql\connections.py", line 775, in _read_query_result
    result.read()
  File "C:\Users\zhi.zhou\Anaconda3\envs\lts\lib\site-packages\pymysql\connections.py", line 1156, in read
    first_packet = self.connection._read_packet()
  File "C:\Users\zhi.zhou\Anaconda3\envs\lts\lib\site-packages\pymysql\connections.py", line 725, in _read_packet
    packet.raise_for_error()
  File "C:\Users\zhi.zhou\Anaconda3\envs\lts\lib\site-packages\pymysql\protocol.py", line 221, in raise_for_error
    err.raise_mysql_exception(self._data)
  File "C:\Users\zhi.zhou\Anaconda3\envs\lts\lib\site-packages\pymysql\err.py", line 143, in raise_mysql_exception
    raise errorclass(errno, errval)
pymysql.err.OperationalError: (1046, 'No database selected')

During handling of the above exception, another exception occurred:

Traceback (most recent call last):
  File "C:\Users\zhi.zhou\Anaconda3\envs\lts\lib\site-packages\django\core\handlers\exception.py", line 47, in inner
    response = get_response(request)
  File "C:\Users\zhi.zhou\Anaconda3\envs\lts\lib\site-packages\django\core\handlers\base.py", line 181, in _get_response
    response = wrapped_callback(request, *callback_args, **callback_kwargs)
  File "C:\Users\zhi.zhou\Anaconda3\envs\lts\lib\site-packages\django\views\generic\base.py", line 70, in view
    return self.dispatch(request, *args, **kwargs)
  File "C:\Users\zhi.zhou\Anaconda3\envs\lts\lib\site-packages\django\views\generic\base.py", line 98, in dispatch
    return handler(request, *args, **kwargs)
  File "D:\zhouzhi\gitlit_code\logistic_tracking_system\logistic_tracking_system\lts\views.py", line 4419, in get
    data = json.dumps(data)
  File "C:\Users\zhi.zhou\Anaconda3\envs\lts\lib\json\__init__.py", line 231, in dumps
    return _default_encoder.encode(obj)
  File "C:\Users\zhi.zhou\Anaconda3\envs\lts\lib\json\encoder.py", line 199, in encode
    chunks = self.iterencode(o, _one_shot=True)
  File "C:\Users\zhi.zhou\Anaconda3\envs\lts\lib\json\encoder.py", line 257, in iterencode
    return _iterencode(o, 0)
  File "C:\Users\zhi.zhou\Anaconda3\envs\lts\lib\json\encoder.py", line 180, in default
    o.__class__.__name__)
TypeError: Object of type 'OperationalError' is not JSON serializable
[2021-08-17 11:29:52,594][Thread-13:21084][task_id:django.request][log.py:230][ERROR][Internal Server Error: /logistic/LogisticCurrentUserInfo]
Traceback (most recent call last):
  File "D:\zhouzhi\gitlit_code\logistic_tracking_system\logistic_tracking_system\lts\views.py", line 4380, in get
    drs = db.execute_sql(conn_num, sql_num)
  File "D:\zhouzhi\gitlit_code\logistic_tracking_system\logistic_tracking_system\common\db.py", line 45, in execute_sql
    cursor.execute(sql)
  File "C:\Users\zhi.zhou\Anaconda3\envs\lts\lib\site-packages\pymysql\cursors.py", line 148, in execute
    result = self._query(query)
  File "C:\Users\zhi.zhou\Anaconda3\envs\lts\lib\site-packages\pymysql\cursors.py", line 310, in _query
    conn.query(q)
  File "C:\Users\zhi.zhou\Anaconda3\envs\lts\lib\site-packages\pymysql\connections.py", line 548, in query
    self._affected_rows = self._read_query_result(unbuffered=unbuffered)
  File "C:\Users\zhi.zhou\Anaconda3\envs\lts\lib\site-packages\pymysql\connections.py", line 775, in _read_query_result
    result.read()
  File "C:\Users\zhi.zhou\Anaconda3\envs\lts\lib\site-packages\pymysql\connections.py", line 1156, in read
    first_packet = self.connection._read_packet()
  File "C:\Users\zhi.zhou\Anaconda3\envs\lts\lib\site-packages\pymysql\connections.py", line 725, in _read_packet
    packet.raise_for_error()
  File "C:\Users\zhi.zhou\Anaconda3\envs\lts\lib\site-packages\pymysql\protocol.py", line 221, in raise_for_error
    err.raise_mysql_exception(self._data)
  File "C:\Users\zhi.zhou\Anaconda3\envs\lts\lib\site-packages\pymysql\err.py", line 143, in raise_mysql_exception
    raise errorclass(errno, errval)
pymysql.err.OperationalError: (1046, 'No database selected')

During handling of the above exception, another exception occurred:

Traceback (most recent call last):
  File "C:\Users\zhi.zhou\Anaconda3\envs\lts\lib\site-packages\django\core\handlers\exception.py", line 47, in inner
    response = get_response(request)
  File "C:\Users\zhi.zhou\Anaconda3\envs\lts\lib\site-packages\django\core\handlers\base.py", line 181, in _get_response
    response = wrapped_callback(request, *callback_args, **callback_kwargs)
  File "C:\Users\zhi.zhou\Anaconda3\envs\lts\lib\site-packages\django\views\generic\base.py", line 70, in view
    return self.dispatch(request, *args, **kwargs)
  File "C:\Users\zhi.zhou\Anaconda3\envs\lts\lib\site-packages\django\views\generic\base.py", line 98, in dispatch
    return handler(request, *args, **kwargs)
  File "D:\zhouzhi\gitlit_code\logistic_tracking_system\logistic_tracking_system\lts\views.py", line 4419, in get
    data = json.dumps(data)
  File "C:\Users\zhi.zhou\Anaconda3\envs\lts\lib\json\__init__.py", line 231, in dumps
    return _default_encoder.encode(obj)
  File "C:\Users\zhi.zhou\Anaconda3\envs\lts\lib\json\encoder.py", line 199, in encode
    chunks = self.iterencode(o, _one_shot=True)
  File "C:\Users\zhi.zhou\Anaconda3\envs\lts\lib\json\encoder.py", line 257, in iterencode
    return _iterencode(o, 0)
  File "C:\Users\zhi.zhou\Anaconda3\envs\lts\lib\json\encoder.py", line 180, in default
    o.__class__.__name__)
TypeError: Object of type 'OperationalError' is not JSON serializable
[2021-08-17 11:29:52,673][Thread-15:21280][task_id:django.request][log.py:230][ERROR][Internal Server Error: /logistic/LogisticCurrentUserInfo]
Traceback (most recent call last):
  File "D:\zhouzhi\gitlit_code\logistic_tracking_system\logistic_tracking_system\lts\views.py", line 4380, in get
    drs = db.execute_sql(conn_num, sql_num)
  File "D:\zhouzhi\gitlit_code\logistic_tracking_system\logistic_tracking_system\common\db.py", line 45, in execute_sql
    cursor.execute(sql)
  File "C:\Users\zhi.zhou\Anaconda3\envs\lts\lib\site-packages\pymysql\cursors.py", line 148, in execute
    result = self._query(query)
  File "C:\Users\zhi.zhou\Anaconda3\envs\lts\lib\site-packages\pymysql\cursors.py", line 310, in _query
    conn.query(q)
  File "C:\Users\zhi.zhou\Anaconda3\envs\lts\lib\site-packages\pymysql\connections.py", line 548, in query
    self._affected_rows = self._read_query_result(unbuffered=unbuffered)
  File "C:\Users\zhi.zhou\Anaconda3\envs\lts\lib\site-packages\pymysql\connections.py", line 775, in _read_query_result
    result.read()
  File "C:\Users\zhi.zhou\Anaconda3\envs\lts\lib\site-packages\pymysql\connections.py", line 1156, in read
    first_packet = self.connection._read_packet()
  File "C:\Users\zhi.zhou\Anaconda3\envs\lts\lib\site-packages\pymysql\connections.py", line 725, in _read_packet
    packet.raise_for_error()
  File "C:\Users\zhi.zhou\Anaconda3\envs\lts\lib\site-packages\pymysql\protocol.py", line 221, in raise_for_error
    err.raise_mysql_exception(self._data)
  File "C:\Users\zhi.zhou\Anaconda3\envs\lts\lib\site-packages\pymysql\err.py", line 143, in raise_mysql_exception
    raise errorclass(errno, errval)
pymysql.err.OperationalError: (1046, 'No database selected')

During handling of the above exception, another exception occurred:

Traceback (most recent call last):
  File "C:\Users\zhi.zhou\Anaconda3\envs\lts\lib\site-packages\django\core\handlers\exception.py", line 47, in inner
    response = get_response(request)
  File "C:\Users\zhi.zhou\Anaconda3\envs\lts\lib\site-packages\django\core\handlers\base.py", line 181, in _get_response
    response = wrapped_callback(request, *callback_args, **callback_kwargs)
  File "C:\Users\zhi.zhou\Anaconda3\envs\lts\lib\site-packages\django\views\generic\base.py", line 70, in view
    return self.dispatch(request, *args, **kwargs)
  File "C:\Users\zhi.zhou\Anaconda3\envs\lts\lib\site-packages\django\views\generic\base.py", line 98, in dispatch
    return handler(request, *args, **kwargs)
  File "D:\zhouzhi\gitlit_code\logistic_tracking_system\logistic_tracking_system\lts\views.py", line 4419, in get
    data = json.dumps(data)
  File "C:\Users\zhi.zhou\Anaconda3\envs\lts\lib\json\__init__.py", line 231, in dumps
    return _default_encoder.encode(obj)
  File "C:\Users\zhi.zhou\Anaconda3\envs\lts\lib\json\encoder.py", line 199, in encode
    chunks = self.iterencode(o, _one_shot=True)
  File "C:\Users\zhi.zhou\Anaconda3\envs\lts\lib\json\encoder.py", line 257, in iterencode
    return _iterencode(o, 0)
  File "C:\Users\zhi.zhou\Anaconda3\envs\lts\lib\json\encoder.py", line 180, in default
    o.__class__.__name__)
TypeError: Object of type 'OperationalError' is not JSON serializable
[2021-08-17 11:29:53,225][Thread-15:21280][task_id:django.request][log.py:230][ERROR][Internal Server Error: /logistic/LogisticCurrentUserInfo]
Traceback (most recent call last):
  File "D:\zhouzhi\gitlit_code\logistic_tracking_system\logistic_tracking_system\lts\views.py", line 4380, in get
    drs = db.execute_sql(conn_num, sql_num)
  File "D:\zhouzhi\gitlit_code\logistic_tracking_system\logistic_tracking_system\common\db.py", line 45, in execute_sql
    cursor.execute(sql)
  File "C:\Users\zhi.zhou\Anaconda3\envs\lts\lib\site-packages\pymysql\cursors.py", line 148, in execute
    result = self._query(query)
  File "C:\Users\zhi.zhou\Anaconda3\envs\lts\lib\site-packages\pymysql\cursors.py", line 310, in _query
    conn.query(q)
  File "C:\Users\zhi.zhou\Anaconda3\envs\lts\lib\site-packages\pymysql\connections.py", line 548, in query
    self._affected_rows = self._read_query_result(unbuffered=unbuffered)
  File "C:\Users\zhi.zhou\Anaconda3\envs\lts\lib\site-packages\pymysql\connections.py", line 775, in _read_query_result
    result.read()
  File "C:\Users\zhi.zhou\Anaconda3\envs\lts\lib\site-packages\pymysql\connections.py", line 1156, in read
    first_packet = self.connection._read_packet()
  File "C:\Users\zhi.zhou\Anaconda3\envs\lts\lib\site-packages\pymysql\connections.py", line 725, in _read_packet
    packet.raise_for_error()
  File "C:\Users\zhi.zhou\Anaconda3\envs\lts\lib\site-packages\pymysql\protocol.py", line 221, in raise_for_error
    err.raise_mysql_exception(self._data)
  File "C:\Users\zhi.zhou\Anaconda3\envs\lts\lib\site-packages\pymysql\err.py", line 143, in raise_mysql_exception
    raise errorclass(errno, errval)
pymysql.err.OperationalError: (1046, 'No database selected')

During handling of the above exception, another exception occurred:

Traceback (most recent call last):
  File "C:\Users\zhi.zhou\Anaconda3\envs\lts\lib\site-packages\django\core\handlers\exception.py", line 47, in inner
    response = get_response(request)
  File "C:\Users\zhi.zhou\Anaconda3\envs\lts\lib\site-packages\django\core\handlers\base.py", line 181, in _get_response
    response = wrapped_callback(request, *callback_args, **callback_kwargs)
  File "C:\Users\zhi.zhou\Anaconda3\envs\lts\lib\site-packages\django\views\generic\base.py", line 70, in view
    return self.dispatch(request, *args, **kwargs)
  File "C:\Users\zhi.zhou\Anaconda3\envs\lts\lib\site-packages\django\views\generic\base.py", line 98, in dispatch
    return handler(request, *args, **kwargs)
  File "D:\zhouzhi\gitlit_code\logistic_tracking_system\logistic_tracking_system\lts\views.py", line 4419, in get
    data = json.dumps(data)
  File "C:\Users\zhi.zhou\Anaconda3\envs\lts\lib\json\__init__.py", line 231, in dumps
    return _default_encoder.encode(obj)
  File "C:\Users\zhi.zhou\Anaconda3\envs\lts\lib\json\encoder.py", line 199, in encode
    chunks = self.iterencode(o, _one_shot=True)
  File "C:\Users\zhi.zhou\Anaconda3\envs\lts\lib\json\encoder.py", line 257, in iterencode
    return _iterencode(o, 0)
  File "C:\Users\zhi.zhou\Anaconda3\envs\lts\lib\json\encoder.py", line 180, in default
    o.__class__.__name__)
TypeError: Object of type 'OperationalError' is not JSON serializable
[2021-08-17 11:29:53,300][Thread-13:21084][task_id:django.request][log.py:230][ERROR][Internal Server Error: /logistic/LogisticCurrentUserInfo]
Traceback (most recent call last):
  File "D:\zhouzhi\gitlit_code\logistic_tracking_system\logistic_tracking_system\lts\views.py", line 4380, in get
    drs = db.execute_sql(conn_num, sql_num)
  File "D:\zhouzhi\gitlit_code\logistic_tracking_system\logistic_tracking_system\common\db.py", line 45, in execute_sql
    cursor.execute(sql)
  File "C:\Users\zhi.zhou\Anaconda3\envs\lts\lib\site-packages\pymysql\cursors.py", line 148, in execute
    result = self._query(query)
  File "C:\Users\zhi.zhou\Anaconda3\envs\lts\lib\site-packages\pymysql\cursors.py", line 310, in _query
    conn.query(q)
  File "C:\Users\zhi.zhou\Anaconda3\envs\lts\lib\site-packages\pymysql\connections.py", line 548, in query
    self._affected_rows = self._read_query_result(unbuffered=unbuffered)
  File "C:\Users\zhi.zhou\Anaconda3\envs\lts\lib\site-packages\pymysql\connections.py", line 775, in _read_query_result
    result.read()
  File "C:\Users\zhi.zhou\Anaconda3\envs\lts\lib\site-packages\pymysql\connections.py", line 1156, in read
    first_packet = self.connection._read_packet()
  File "C:\Users\zhi.zhou\Anaconda3\envs\lts\lib\site-packages\pymysql\connections.py", line 725, in _read_packet
    packet.raise_for_error()
  File "C:\Users\zhi.zhou\Anaconda3\envs\lts\lib\site-packages\pymysql\protocol.py", line 221, in raise_for_error
    err.raise_mysql_exception(self._data)
  File "C:\Users\zhi.zhou\Anaconda3\envs\lts\lib\site-packages\pymysql\err.py", line 143, in raise_mysql_exception
    raise errorclass(errno, errval)
pymysql.err.OperationalError: (1046, 'No database selected')

During handling of the above exception, another exception occurred:

Traceback (most recent call last):
  File "C:\Users\zhi.zhou\Anaconda3\envs\lts\lib\site-packages\django\core\handlers\exception.py", line 47, in inner
    response = get_response(request)
  File "C:\Users\zhi.zhou\Anaconda3\envs\lts\lib\site-packages\django\core\handlers\base.py", line 181, in _get_response
    response = wrapped_callback(request, *callback_args, **callback_kwargs)
  File "C:\Users\zhi.zhou\Anaconda3\envs\lts\lib\site-packages\django\views\generic\base.py", line 70, in view
    return self.dispatch(request, *args, **kwargs)
  File "C:\Users\zhi.zhou\Anaconda3\envs\lts\lib\site-packages\django\views\generic\base.py", line 98, in dispatch
    return handler(request, *args, **kwargs)
  File "D:\zhouzhi\gitlit_code\logistic_tracking_system\logistic_tracking_system\lts\views.py", line 4419, in get
    data = json.dumps(data)
  File "C:\Users\zhi.zhou\Anaconda3\envs\lts\lib\json\__init__.py", line 231, in dumps
    return _default_encoder.encode(obj)
  File "C:\Users\zhi.zhou\Anaconda3\envs\lts\lib\json\encoder.py", line 199, in encode
    chunks = self.iterencode(o, _one_shot=True)
  File "C:\Users\zhi.zhou\Anaconda3\envs\lts\lib\json\encoder.py", line 257, in iterencode
    return _iterencode(o, 0)
  File "C:\Users\zhi.zhou\Anaconda3\envs\lts\lib\json\encoder.py", line 180, in default
    o.__class__.__name__)
TypeError: Object of type 'OperationalError' is not JSON serializable
[2021-08-17 11:29:53,827][Thread-13:21084][task_id:django.request][log.py:230][ERROR][Internal Server Error: /logistic/LogisticCurrentUserInfo]
Traceback (most recent call last):
  File "D:\zhouzhi\gitlit_code\logistic_tracking_system\logistic_tracking_system\lts\views.py", line 4380, in get
    drs = db.execute_sql(conn_num, sql_num)
  File "D:\zhouzhi\gitlit_code\logistic_tracking_system\logistic_tracking_system\common\db.py", line 45, in execute_sql
    cursor.execute(sql)
  File "C:\Users\zhi.zhou\Anaconda3\envs\lts\lib\site-packages\pymysql\cursors.py", line 148, in execute
    result = self._query(query)
  File "C:\Users\zhi.zhou\Anaconda3\envs\lts\lib\site-packages\pymysql\cursors.py", line 310, in _query
    conn.query(q)
  File "C:\Users\zhi.zhou\Anaconda3\envs\lts\lib\site-packages\pymysql\connections.py", line 548, in query
    self._affected_rows = self._read_query_result(unbuffered=unbuffered)
  File "C:\Users\zhi.zhou\Anaconda3\envs\lts\lib\site-packages\pymysql\connections.py", line 775, in _read_query_result
    result.read()
  File "C:\Users\zhi.zhou\Anaconda3\envs\lts\lib\site-packages\pymysql\connections.py", line 1156, in read
    first_packet = self.connection._read_packet()
  File "C:\Users\zhi.zhou\Anaconda3\envs\lts\lib\site-packages\pymysql\connections.py", line 725, in _read_packet
    packet.raise_for_error()
  File "C:\Users\zhi.zhou\Anaconda3\envs\lts\lib\site-packages\pymysql\protocol.py", line 221, in raise_for_error
    err.raise_mysql_exception(self._data)
  File "C:\Users\zhi.zhou\Anaconda3\envs\lts\lib\site-packages\pymysql\err.py", line 143, in raise_mysql_exception
    raise errorclass(errno, errval)
pymysql.err.OperationalError: (1046, 'No database selected')

During handling of the above exception, another exception occurred:

Traceback (most recent call last):
  File "C:\Users\zhi.zhou\Anaconda3\envs\lts\lib\site-packages\django\core\handlers\exception.py", line 47, in inner
    response = get_response(request)
  File "C:\Users\zhi.zhou\Anaconda3\envs\lts\lib\site-packages\django\core\handlers\base.py", line 181, in _get_response
    response = wrapped_callback(request, *callback_args, **callback_kwargs)
  File "C:\Users\zhi.zhou\Anaconda3\envs\lts\lib\site-packages\django\views\generic\base.py", line 70, in view
    return self.dispatch(request, *args, **kwargs)
  File "C:\Users\zhi.zhou\Anaconda3\envs\lts\lib\site-packages\django\views\generic\base.py", line 98, in dispatch
    return handler(request, *args, **kwargs)
  File "D:\zhouzhi\gitlit_code\logistic_tracking_system\logistic_tracking_system\lts\views.py", line 4419, in get
    data = json.dumps(data)
  File "C:\Users\zhi.zhou\Anaconda3\envs\lts\lib\json\__init__.py", line 231, in dumps
    return _default_encoder.encode(obj)
  File "C:\Users\zhi.zhou\Anaconda3\envs\lts\lib\json\encoder.py", line 199, in encode
    chunks = self.iterencode(o, _one_shot=True)
  File "C:\Users\zhi.zhou\Anaconda3\envs\lts\lib\json\encoder.py", line 257, in iterencode
    return _iterencode(o, 0)
  File "C:\Users\zhi.zhou\Anaconda3\envs\lts\lib\json\encoder.py", line 180, in default
    o.__class__.__name__)
TypeError: Object of type 'OperationalError' is not JSON serializable
[2021-08-17 11:29:53,900][Thread-15:21280][task_id:django.request][log.py:230][ERROR][Internal Server Error: /logistic/LogisticCurrentUserInfo]
Traceback (most recent call last):
  File "D:\zhouzhi\gitlit_code\logistic_tracking_system\logistic_tracking_system\lts\views.py", line 4380, in get
    drs = db.execute_sql(conn_num, sql_num)
  File "D:\zhouzhi\gitlit_code\logistic_tracking_system\logistic_tracking_system\common\db.py", line 45, in execute_sql
    cursor.execute(sql)
  File "C:\Users\zhi.zhou\Anaconda3\envs\lts\lib\site-packages\pymysql\cursors.py", line 148, in execute
    result = self._query(query)
  File "C:\Users\zhi.zhou\Anaconda3\envs\lts\lib\site-packages\pymysql\cursors.py", line 310, in _query
    conn.query(q)
  File "C:\Users\zhi.zhou\Anaconda3\envs\lts\lib\site-packages\pymysql\connections.py", line 548, in query
    self._affected_rows = self._read_query_result(unbuffered=unbuffered)
  File "C:\Users\zhi.zhou\Anaconda3\envs\lts\lib\site-packages\pymysql\connections.py", line 775, in _read_query_result
    result.read()
  File "C:\Users\zhi.zhou\Anaconda3\envs\lts\lib\site-packages\pymysql\connections.py", line 1156, in read
    first_packet = self.connection._read_packet()
  File "C:\Users\zhi.zhou\Anaconda3\envs\lts\lib\site-packages\pymysql\connections.py", line 725, in _read_packet
    packet.raise_for_error()
  File "C:\Users\zhi.zhou\Anaconda3\envs\lts\lib\site-packages\pymysql\protocol.py", line 221, in raise_for_error
    err.raise_mysql_exception(self._data)
  File "C:\Users\zhi.zhou\Anaconda3\envs\lts\lib\site-packages\pymysql\err.py", line 143, in raise_mysql_exception
    raise errorclass(errno, errval)
pymysql.err.OperationalError: (1046, 'No database selected')

During handling of the above exception, another exception occurred:

Traceback (most recent call last):
  File "C:\Users\zhi.zhou\Anaconda3\envs\lts\lib\site-packages\django\core\handlers\exception.py", line 47, in inner
    response = get_response(request)
  File "C:\Users\zhi.zhou\Anaconda3\envs\lts\lib\site-packages\django\core\handlers\base.py", line 181, in _get_response
    response = wrapped_callback(request, *callback_args, **callback_kwargs)
  File "C:\Users\zhi.zhou\Anaconda3\envs\lts\lib\site-packages\django\views\generic\base.py", line 70, in view
    return self.dispatch(request, *args, **kwargs)
  File "C:\Users\zhi.zhou\Anaconda3\envs\lts\lib\site-packages\django\views\generic\base.py", line 98, in dispatch
    return handler(request, *args, **kwargs)
  File "D:\zhouzhi\gitlit_code\logistic_tracking_system\logistic_tracking_system\lts\views.py", line 4419, in get
    data = json.dumps(data)
  File "C:\Users\zhi.zhou\Anaconda3\envs\lts\lib\json\__init__.py", line 231, in dumps
    return _default_encoder.encode(obj)
  File "C:\Users\zhi.zhou\Anaconda3\envs\lts\lib\json\encoder.py", line 199, in encode
    chunks = self.iterencode(o, _one_shot=True)
  File "C:\Users\zhi.zhou\Anaconda3\envs\lts\lib\json\encoder.py", line 257, in iterencode
    return _iterencode(o, 0)
  File "C:\Users\zhi.zhou\Anaconda3\envs\lts\lib\json\encoder.py", line 180, in default
    o.__class__.__name__)
TypeError: Object of type 'OperationalError' is not JSON serializable
[2021-08-17 14:07:54,426][Thread-1:15200][task_id:django.request][log.py:230][ERROR][Internal Server Error: /logistic/LogisticCurrentUserInfo]
Traceback (most recent call last):
  File "D:\zhouzhi\gitlit_code\logistic_tracking_system\logistic_tracking_system\lts\views.py", line 4380, in get
    drs = db.execute_sql(conn_num, sql_num)
  File "D:\zhouzhi\gitlit_code\logistic_tracking_system\logistic_tracking_system\common\db.py", line 45, in execute_sql
    cursor.execute(sql)
  File "C:\Users\zhi.zhou\Anaconda3\envs\lts\lib\site-packages\pymysql\cursors.py", line 148, in execute
    result = self._query(query)
  File "C:\Users\zhi.zhou\Anaconda3\envs\lts\lib\site-packages\pymysql\cursors.py", line 310, in _query
    conn.query(q)
  File "C:\Users\zhi.zhou\Anaconda3\envs\lts\lib\site-packages\pymysql\connections.py", line 548, in query
    self._affected_rows = self._read_query_result(unbuffered=unbuffered)
  File "C:\Users\zhi.zhou\Anaconda3\envs\lts\lib\site-packages\pymysql\connections.py", line 775, in _read_query_result
    result.read()
  File "C:\Users\zhi.zhou\Anaconda3\envs\lts\lib\site-packages\pymysql\connections.py", line 1156, in read
    first_packet = self.connection._read_packet()
  File "C:\Users\zhi.zhou\Anaconda3\envs\lts\lib\site-packages\pymysql\connections.py", line 725, in _read_packet
    packet.raise_for_error()
  File "C:\Users\zhi.zhou\Anaconda3\envs\lts\lib\site-packages\pymysql\protocol.py", line 221, in raise_for_error
    err.raise_mysql_exception(self._data)
  File "C:\Users\zhi.zhou\Anaconda3\envs\lts\lib\site-packages\pymysql\err.py", line 143, in raise_mysql_exception
    raise errorclass(errno, errval)
pymysql.err.ProgrammingError: (1146, "Table 'db_common.pick_box' doesn't exist")

During handling of the above exception, another exception occurred:

Traceback (most recent call last):
  File "C:\Users\zhi.zhou\Anaconda3\envs\lts\lib\site-packages\django\core\handlers\exception.py", line 47, in inner
    response = get_response(request)
  File "C:\Users\zhi.zhou\Anaconda3\envs\lts\lib\site-packages\django\core\handlers\base.py", line 181, in _get_response
    response = wrapped_callback(request, *callback_args, **callback_kwargs)
  File "C:\Users\zhi.zhou\Anaconda3\envs\lts\lib\site-packages\django\views\generic\base.py", line 70, in view
    return self.dispatch(request, *args, **kwargs)
  File "C:\Users\zhi.zhou\Anaconda3\envs\lts\lib\site-packages\django\views\generic\base.py", line 98, in dispatch
    return handler(request, *args, **kwargs)
  File "D:\zhouzhi\gitlit_code\logistic_tracking_system\logistic_tracking_system\lts\views.py", line 4419, in get
    data = json.dumps(data)
  File "C:\Users\zhi.zhou\Anaconda3\envs\lts\lib\json\__init__.py", line 231, in dumps
    return _default_encoder.encode(obj)
  File "C:\Users\zhi.zhou\Anaconda3\envs\lts\lib\json\encoder.py", line 199, in encode
    chunks = self.iterencode(o, _one_shot=True)
  File "C:\Users\zhi.zhou\Anaconda3\envs\lts\lib\json\encoder.py", line 257, in iterencode
    return _iterencode(o, 0)
  File "C:\Users\zhi.zhou\Anaconda3\envs\lts\lib\json\encoder.py", line 180, in default
    o.__class__.__name__)
TypeError: Object of type 'ProgrammingError' is not JSON serializable
[2021-08-17 16:43:55,853][Thread-5:10988][task_id:lts.views][views.py:363][ERROR][该用户不是超级管理员]
[2021-08-17 16:43:57,641][Thread-5:10988][task_id:lts.views][views.py:363][ERROR][该用户不是超级管理员]
[2021-08-17 16:43:59,955][Thread-2:13636][task_id:lts.views][views.py:363][ERROR][该用户不是超级管理员]
[2021-08-17 16:44:08,114][Thread-5:10988][task_id:lts.views][views.py:363][ERROR][该用户不是超级管理员]
[2021-08-17 16:47:20,128][Thread-6:7124][task_id:lts.views][views.py:363][ERROR][该用户不是超级管理员]
[2021-08-17 16:48:34,051][Thread-1:12564][task_id:lts.views][views.py:365][ERROR][该用户不是超级管理员]
[2021-08-17 16:49:49,966][Thread-1:21232][task_id:lts.views][views.py:366][ERROR][该用户不是超级管理员]
[2021-08-17 16:50:49,105][Thread-1:17416][task_id:lts.views][views.py:366][ERROR][该用户不是超级管理员]
[2021-08-17 16:52:20,378][Thread-1:16472][task_id:lts.views][views.py:367][ERROR][该用户不是超级管理员]
[2021-08-17 16:53:14,592][Thread-1:21080][task_id:lts.views][views.py:368][ERROR][该用户不是超级管理员]
[2021-08-17 16:56:06,447][Thread-1:20656][task_id:lts.views][views.py:375][ERROR][该用户不是超级管理员]
[2021-08-17 16:57:27,530][Thread-1:13748][task_id:lts.views][views.py:375][ERROR][该用户不是超级管理员]
[2021-08-17 16:59:47,920][Thread-1:23456][task_id:lts.views][views.py:372][ERROR][该用户不是超级管理员]
[2021-08-17 17:00:16,729][Thread-1:22388][task_id:lts.views][views.py:372][ERROR][该用户不是超级管理员]
[2021-08-17 17:00:52,704][Thread-1:20600][task_id:lts.views][views.py:373][ERROR][该用户不是超级管理员]
[2021-08-17 17:01:24,818][Thread-1:14740][task_id:lts.views][views.py:373][ERROR][该用户不是超级管理员]
[2021-08-17 17:07:06,245][Thread-3:15684][task_id:django.request][log.py:230][ERROR][Internal Server Error: /logistic/LogisticCurrentUserInfo]
Traceback (most recent call last):
  File "D:\zhouzhi\gitlit_code\logistic_tracking_system\logistic_tracking_system\lts\views.py", line 4551, in get
    dict_data["user_role"] = dr[7]
IndexError: tuple index out of range

During handling of the above exception, another exception occurred:

Traceback (most recent call last):
  File "C:\Users\zhi.zhou\Anaconda3\envs\lts\lib\site-packages\django\core\handlers\exception.py", line 47, in inner
    response = get_response(request)
  File "C:\Users\zhi.zhou\Anaconda3\envs\lts\lib\site-packages\django\core\handlers\base.py", line 181, in _get_response
    response = wrapped_callback(request, *callback_args, **callback_kwargs)
  File "C:\Users\zhi.zhou\Anaconda3\envs\lts\lib\site-packages\django\views\generic\base.py", line 70, in view
    return self.dispatch(request, *args, **kwargs)
  File "C:\Users\zhi.zhou\Anaconda3\envs\lts\lib\site-packages\django\views\generic\base.py", line 98, in dispatch
    return handler(request, *args, **kwargs)
  File "D:\zhouzhi\gitlit_code\logistic_tracking_system\logistic_tracking_system\lts\views.py", line 4601, in get
    data = json.dumps(data)
  File "C:\Users\zhi.zhou\Anaconda3\envs\lts\lib\json\__init__.py", line 231, in dumps
    return _default_encoder.encode(obj)
  File "C:\Users\zhi.zhou\Anaconda3\envs\lts\lib\json\encoder.py", line 199, in encode
    chunks = self.iterencode(o, _one_shot=True)
  File "C:\Users\zhi.zhou\Anaconda3\envs\lts\lib\json\encoder.py", line 257, in iterencode
    return _iterencode(o, 0)
  File "C:\Users\zhi.zhou\Anaconda3\envs\lts\lib\json\encoder.py", line 180, in default
    o.__class__.__name__)
TypeError: Object of type 'IndexError' is not JSON serializable
[2021-08-17 17:07:06,264][Thread-4:15772][task_id:django.request][log.py:230][ERROR][Internal Server Error: /logistic/LogisticCurrentUserInfo]
Traceback (most recent call last):
  File "D:\zhouzhi\gitlit_code\logistic_tracking_system\logistic_tracking_system\lts\views.py", line 4551, in get
    dict_data["user_role"] = dr[7]
IndexError: tuple index out of range

During handling of the above exception, another exception occurred:

Traceback (most recent call last):
  File "C:\Users\zhi.zhou\Anaconda3\envs\lts\lib\site-packages\django\core\handlers\exception.py", line 47, in inner
    response = get_response(request)
  File "C:\Users\zhi.zhou\Anaconda3\envs\lts\lib\site-packages\django\core\handlers\base.py", line 181, in _get_response
    response = wrapped_callback(request, *callback_args, **callback_kwargs)
  File "C:\Users\zhi.zhou\Anaconda3\envs\lts\lib\site-packages\django\views\generic\base.py", line 70, in view
    return self.dispatch(request, *args, **kwargs)
  File "C:\Users\zhi.zhou\Anaconda3\envs\lts\lib\site-packages\django\views\generic\base.py", line 98, in dispatch
    return handler(request, *args, **kwargs)
  File "D:\zhouzhi\gitlit_code\logistic_tracking_system\logistic_tracking_system\lts\views.py", line 4601, in get
    data = json.dumps(data)
  File "C:\Users\zhi.zhou\Anaconda3\envs\lts\lib\json\__init__.py", line 231, in dumps
    return _default_encoder.encode(obj)
  File "C:\Users\zhi.zhou\Anaconda3\envs\lts\lib\json\encoder.py", line 199, in encode
    chunks = self.iterencode(o, _one_shot=True)
  File "C:\Users\zhi.zhou\Anaconda3\envs\lts\lib\json\encoder.py", line 257, in iterencode
    return _iterencode(o, 0)
  File "C:\Users\zhi.zhou\Anaconda3\envs\lts\lib\json\encoder.py", line 180, in default
    o.__class__.__name__)
TypeError: Object of type 'IndexError' is not JSON serializable
[2021-08-17 17:12:19,909][Thread-1:24448][task_id:lts.views][views.py:373][ERROR][该用户不是超级管理员]
[2021-08-17 17:15:18,849][Thread-1:6072][task_id:lts.views][views.py:372][ERROR][该用户不是超级管理员]
[2021-08-17 17:19:24,475][Thread-1:1788][task_id:django.request][log.py:230][ERROR][Internal Server Error: /logistic/LogisticManageLogisticLogin]
Traceback (most recent call last):
  File "C:\Users\zhi.zhou\Anaconda3\envs\lts\lib\site-packages\django\core\handlers\exception.py", line 47, in inner
    response = get_response(request)
  File "C:\Users\zhi.zhou\Anaconda3\envs\lts\lib\site-packages\django\core\handlers\base.py", line 188, in _get_response
    self.check_response(response, callback)
  File "C:\Users\zhi.zhou\Anaconda3\envs\lts\lib\site-packages\django\core\handlers\base.py", line 311, in check_response
    "instead." % name
ValueError: The view lts.views.ManageLogisticLogin didn't return an HttpResponse object. It returned None instead.
[2021-08-17 17:19:31,209][Thread-1:1788][task_id:django.request][log.py:230][ERROR][Internal Server Error: /logistic/LogisticManageLogisticLogin]
Traceback (most recent call last):
  File "C:\Users\zhi.zhou\Anaconda3\envs\lts\lib\site-packages\django\core\handlers\exception.py", line 47, in inner
    response = get_response(request)
  File "C:\Users\zhi.zhou\Anaconda3\envs\lts\lib\site-packages\django\core\handlers\base.py", line 188, in _get_response
    self.check_response(response, callback)
  File "C:\Users\zhi.zhou\Anaconda3\envs\lts\lib\site-packages\django\core\handlers\base.py", line 311, in check_response
    "instead." % name
ValueError: The view lts.views.ManageLogisticLogin didn't return an HttpResponse object. It returned None instead.
[2021-08-17 17:19:32,543][Thread-1:1788][task_id:django.request][log.py:230][ERROR][Internal Server Error: /logistic/LogisticManageLogisticLogin]
Traceback (most recent call last):
  File "C:\Users\zhi.zhou\Anaconda3\envs\lts\lib\site-packages\django\core\handlers\exception.py", line 47, in inner
    response = get_response(request)
  File "C:\Users\zhi.zhou\Anaconda3\envs\lts\lib\site-packages\django\core\handlers\base.py", line 188, in _get_response
    self.check_response(response, callback)
  File "C:\Users\zhi.zhou\Anaconda3\envs\lts\lib\site-packages\django\core\handlers\base.py", line 311, in check_response
    "instead." % name
ValueError: The view lts.views.ManageLogisticLogin didn't return an HttpResponse object. It returned None instead.
[2021-08-17 17:22:31,377][Thread-2:3228][task_id:lts.views][views.py:1543][ERROR][查询产品列表失败]
[2021-08-17 17:22:31,659][Thread-1:15964][task_id:django.request][log.py:230][ERROR][Internal Server Error: /logistic/LogisticCurrentUserInfo]
Traceback (most recent call last):
  File "D:\zhouzhi\gitlit_code\logistic_tracking_system\logistic_tracking_system\lts\views.py", line 4552, in get
    dict_data["user_role"] = dr[7]
IndexError: tuple index out of range

During handling of the above exception, another exception occurred:

Traceback (most recent call last):
  File "C:\Users\zhi.zhou\Anaconda3\envs\lts\lib\site-packages\django\core\handlers\exception.py", line 47, in inner
    response = get_response(request)
  File "C:\Users\zhi.zhou\Anaconda3\envs\lts\lib\site-packages\django\core\handlers\base.py", line 181, in _get_response
    response = wrapped_callback(request, *callback_args, **callback_kwargs)
  File "C:\Users\zhi.zhou\Anaconda3\envs\lts\lib\site-packages\django\views\generic\base.py", line 70, in view
    return self.dispatch(request, *args, **kwargs)
  File "C:\Users\zhi.zhou\Anaconda3\envs\lts\lib\site-packages\django\views\generic\base.py", line 98, in dispatch
    return handler(request, *args, **kwargs)
  File "D:\zhouzhi\gitlit_code\logistic_tracking_system\logistic_tracking_system\lts\views.py", line 4602, in get
    data = json.dumps(data)
  File "C:\Users\zhi.zhou\Anaconda3\envs\lts\lib\json\__init__.py", line 231, in dumps
    return _default_encoder.encode(obj)
  File "C:\Users\zhi.zhou\Anaconda3\envs\lts\lib\json\encoder.py", line 199, in encode
    chunks = self.iterencode(o, _one_shot=True)
  File "C:\Users\zhi.zhou\Anaconda3\envs\lts\lib\json\encoder.py", line 257, in iterencode
    return _iterencode(o, 0)
  File "C:\Users\zhi.zhou\Anaconda3\envs\lts\lib\json\encoder.py", line 180, in default
    o.__class__.__name__)
TypeError: Object of type 'IndexError' is not JSON serializable
[2021-08-17 17:25:32,155][Thread-4:11084][task_id:django.request][log.py:230][ERROR][Internal Server Error: /logistic/LogisticCurrentUserInfo]
Traceback (most recent call last):
  File "D:\zhouzhi\gitlit_code\logistic_tracking_system\logistic_tracking_system\lts\views.py", line 4552, in get
    dict_data["user_role"] = dr[7]
IndexError: tuple index out of range

During handling of the above exception, another exception occurred:

Traceback (most recent call last):
  File "C:\Users\zhi.zhou\Anaconda3\envs\lts\lib\site-packages\django\core\handlers\exception.py", line 47, in inner
    response = get_response(request)
  File "C:\Users\zhi.zhou\Anaconda3\envs\lts\lib\site-packages\django\core\handlers\base.py", line 181, in _get_response
    response = wrapped_callback(request, *callback_args, **callback_kwargs)
  File "C:\Users\zhi.zhou\Anaconda3\envs\lts\lib\site-packages\django\views\generic\base.py", line 70, in view
    return self.dispatch(request, *args, **kwargs)
  File "C:\Users\zhi.zhou\Anaconda3\envs\lts\lib\site-packages\django\views\generic\base.py", line 98, in dispatch
    return handler(request, *args, **kwargs)
  File "D:\zhouzhi\gitlit_code\logistic_tracking_system\logistic_tracking_system\lts\views.py", line 4602, in get
    data = json.dumps(data)
  File "C:\Users\zhi.zhou\Anaconda3\envs\lts\lib\json\__init__.py", line 231, in dumps
    return _default_encoder.encode(obj)
  File "C:\Users\zhi.zhou\Anaconda3\envs\lts\lib\json\encoder.py", line 199, in encode
    chunks = self.iterencode(o, _one_shot=True)
  File "C:\Users\zhi.zhou\Anaconda3\envs\lts\lib\json\encoder.py", line 257, in iterencode
    return _iterencode(o, 0)
  File "C:\Users\zhi.zhou\Anaconda3\envs\lts\lib\json\encoder.py", line 180, in default
    o.__class__.__name__)
TypeError: Object of type 'IndexError' is not JSON serializable
[2021-08-17 17:25:32,183][Thread-5:3892][task_id:lts.views][views.py:1543][ERROR][查询产品列表失败]
[2021-08-17 17:27:01,811][Thread-6:11824][task_id:django.request][log.py:230][ERROR][Internal Server Error: /logistic/LogisticCurrentUserInfo]
Traceback (most recent call last):
  File "D:\zhouzhi\gitlit_code\logistic_tracking_system\logistic_tracking_system\lts\views.py", line 4532, in get
    drs = db.execute_sql(conn_num, sql_num)
  File "D:\zhouzhi\gitlit_code\logistic_tracking_system\logistic_tracking_system\common\db.py", line 45, in execute_sql
    cursor.execute(sql)
  File "C:\Users\zhi.zhou\Anaconda3\envs\lts\lib\site-packages\pymysql\cursors.py", line 148, in execute
    result = self._query(query)
  File "C:\Users\zhi.zhou\Anaconda3\envs\lts\lib\site-packages\pymysql\cursors.py", line 310, in _query
    conn.query(q)
  File "C:\Users\zhi.zhou\Anaconda3\envs\lts\lib\site-packages\pymysql\connections.py", line 548, in query
    self._affected_rows = self._read_query_result(unbuffered=unbuffered)
  File "C:\Users\zhi.zhou\Anaconda3\envs\lts\lib\site-packages\pymysql\connections.py", line 775, in _read_query_result
    result.read()
  File "C:\Users\zhi.zhou\Anaconda3\envs\lts\lib\site-packages\pymysql\connections.py", line 1156, in read
    first_packet = self.connection._read_packet()
  File "C:\Users\zhi.zhou\Anaconda3\envs\lts\lib\site-packages\pymysql\connections.py", line 725, in _read_packet
    packet.raise_for_error()
  File "C:\Users\zhi.zhou\Anaconda3\envs\lts\lib\site-packages\pymysql\protocol.py", line 221, in raise_for_error
    err.raise_mysql_exception(self._data)
  File "C:\Users\zhi.zhou\Anaconda3\envs\lts\lib\site-packages\pymysql\err.py", line 143, in raise_mysql_exception
    raise errorclass(errno, errval)
pymysql.err.ProgrammingError: (1146, "Table 'db_common.pick_box' doesn't exist")

During handling of the above exception, another exception occurred:

Traceback (most recent call last):
  File "C:\Users\zhi.zhou\Anaconda3\envs\lts\lib\site-packages\django\core\handlers\exception.py", line 47, in inner
    response = get_response(request)
  File "C:\Users\zhi.zhou\Anaconda3\envs\lts\lib\site-packages\django\core\handlers\base.py", line 181, in _get_response
    response = wrapped_callback(request, *callback_args, **callback_kwargs)
  File "C:\Users\zhi.zhou\Anaconda3\envs\lts\lib\site-packages\django\views\generic\base.py", line 70, in view
    return self.dispatch(request, *args, **kwargs)
  File "C:\Users\zhi.zhou\Anaconda3\envs\lts\lib\site-packages\django\views\generic\base.py", line 98, in dispatch
    return handler(request, *args, **kwargs)
  File "D:\zhouzhi\gitlit_code\logistic_tracking_system\logistic_tracking_system\lts\views.py", line 4602, in get
    data = json.dumps(data)
  File "C:\Users\zhi.zhou\Anaconda3\envs\lts\lib\json\__init__.py", line 231, in dumps
    return _default_encoder.encode(obj)
  File "C:\Users\zhi.zhou\Anaconda3\envs\lts\lib\json\encoder.py", line 199, in encode
    chunks = self.iterencode(o, _one_shot=True)
  File "C:\Users\zhi.zhou\Anaconda3\envs\lts\lib\json\encoder.py", line 257, in iterencode
    return _iterencode(o, 0)
  File "C:\Users\zhi.zhou\Anaconda3\envs\lts\lib\json\encoder.py", line 180, in default
    o.__class__.__name__)
TypeError: Object of type 'ProgrammingError' is not JSON serializable
[2021-08-17 17:27:01,854][Thread-7:15924][task_id:lts.views][views.py:1543][ERROR][查询产品列表失败]
[2021-08-17 17:27:06,228][Thread-7:15924][task_id:lts.views][views.py:1543][ERROR][查询产品列表失败]
[2021-08-17 17:28:27,902][Thread-9:1992][task_id:lts.views][views.py:1543][ERROR][查询产品列表失败]
[2021-08-17 17:28:27,943][Thread-8:14564][task_id:django.request][log.py:230][ERROR][Internal Server Error: /logistic/LogisticCurrentUserInfo]
Traceback (most recent call last):
  File "D:\zhouzhi\gitlit_code\logistic_tracking_system\logistic_tracking_system\lts\views.py", line 4552, in get
    dict_data["user_role"] = dr[7]
IndexError: tuple index out of range

During handling of the above exception, another exception occurred:

Traceback (most recent call last):
  File "C:\Users\zhi.zhou\Anaconda3\envs\lts\lib\site-packages\django\core\handlers\exception.py", line 47, in inner
    response = get_response(request)
  File "C:\Users\zhi.zhou\Anaconda3\envs\lts\lib\site-packages\django\core\handlers\base.py", line 181, in _get_response
    response = wrapped_callback(request, *callback_args, **callback_kwargs)
  File "C:\Users\zhi.zhou\Anaconda3\envs\lts\lib\site-packages\django\views\generic\base.py", line 70, in view
    return self.dispatch(request, *args, **kwargs)
  File "C:\Users\zhi.zhou\Anaconda3\envs\lts\lib\site-packages\django\views\generic\base.py", line 98, in dispatch
    return handler(request, *args, **kwargs)
  File "D:\zhouzhi\gitlit_code\logistic_tracking_system\logistic_tracking_system\lts\views.py", line 4602, in get
    data = json.dumps(data)
  File "C:\Users\zhi.zhou\Anaconda3\envs\lts\lib\json\__init__.py", line 231, in dumps
    return _default_encoder.encode(obj)
  File "C:\Users\zhi.zhou\Anaconda3\envs\lts\lib\json\encoder.py", line 199, in encode
    chunks = self.iterencode(o, _one_shot=True)
  File "C:\Users\zhi.zhou\Anaconda3\envs\lts\lib\json\encoder.py", line 257, in iterencode
    return _iterencode(o, 0)
  File "C:\Users\zhi.zhou\Anaconda3\envs\lts\lib\json\encoder.py", line 180, in default
    o.__class__.__name__)
TypeError: Object of type 'IndexError' is not JSON serializable
[2021-08-17 17:29:08,267][Thread-10:23648][task_id:django.request][log.py:230][ERROR][Internal Server Error: /logistic/LogisticCurrentUserInfo]
Traceback (most recent call last):
  File "D:\zhouzhi\gitlit_code\logistic_tracking_system\logistic_tracking_system\lts\views.py", line 4552, in get
    dict_data["user_role"] = dr[7]
IndexError: tuple index out of range

During handling of the above exception, another exception occurred:

Traceback (most recent call last):
  File "C:\Users\zhi.zhou\Anaconda3\envs\lts\lib\site-packages\django\core\handlers\exception.py", line 47, in inner
    response = get_response(request)
  File "C:\Users\zhi.zhou\Anaconda3\envs\lts\lib\site-packages\django\core\handlers\base.py", line 181, in _get_response
    response = wrapped_callback(request, *callback_args, **callback_kwargs)
  File "C:\Users\zhi.zhou\Anaconda3\envs\lts\lib\site-packages\django\views\generic\base.py", line 70, in view
    return self.dispatch(request, *args, **kwargs)
  File "C:\Users\zhi.zhou\Anaconda3\envs\lts\lib\site-packages\django\views\generic\base.py", line 98, in dispatch
    return handler(request, *args, **kwargs)
  File "D:\zhouzhi\gitlit_code\logistic_tracking_system\logistic_tracking_system\lts\views.py", line 4602, in get
    data = json.dumps(data)
  File "C:\Users\zhi.zhou\Anaconda3\envs\lts\lib\json\__init__.py", line 231, in dumps
    return _default_encoder.encode(obj)
  File "C:\Users\zhi.zhou\Anaconda3\envs\lts\lib\json\encoder.py", line 199, in encode
    chunks = self.iterencode(o, _one_shot=True)
  File "C:\Users\zhi.zhou\Anaconda3\envs\lts\lib\json\encoder.py", line 257, in iterencode
    return _iterencode(o, 0)
  File "C:\Users\zhi.zhou\Anaconda3\envs\lts\lib\json\encoder.py", line 180, in default
    o.__class__.__name__)
TypeError: Object of type 'IndexError' is not JSON serializable
[2021-08-17 17:29:08,297][Thread-11:11108][task_id:lts.views][views.py:1543][ERROR][查询产品列表失败]
[2021-08-17 17:29:49,542][Thread-13:15080][task_id:lts.views][views.py:1543][ERROR][查询产品列表失败]
[2021-08-17 17:29:49,598][Thread-12:13792][task_id:django.request][log.py:230][ERROR][Internal Server Error: /logistic/LogisticCurrentUserInfo]
Traceback (most recent call last):
  File "D:\zhouzhi\gitlit_code\logistic_tracking_system\logistic_tracking_system\lts\views.py", line 4532, in get
    drs = db.execute_sql(conn_num, sql_num)
  File "D:\zhouzhi\gitlit_code\logistic_tracking_system\logistic_tracking_system\common\db.py", line 45, in execute_sql
    cursor.execute(sql)
  File "C:\Users\zhi.zhou\Anaconda3\envs\lts\lib\site-packages\pymysql\cursors.py", line 148, in execute
    result = self._query(query)
  File "C:\Users\zhi.zhou\Anaconda3\envs\lts\lib\site-packages\pymysql\cursors.py", line 310, in _query
    conn.query(q)
  File "C:\Users\zhi.zhou\Anaconda3\envs\lts\lib\site-packages\pymysql\connections.py", line 548, in query
    self._affected_rows = self._read_query_result(unbuffered=unbuffered)
  File "C:\Users\zhi.zhou\Anaconda3\envs\lts\lib\site-packages\pymysql\connections.py", line 775, in _read_query_result
    result.read()
  File "C:\Users\zhi.zhou\Anaconda3\envs\lts\lib\site-packages\pymysql\connections.py", line 1156, in read
    first_packet = self.connection._read_packet()
  File "C:\Users\zhi.zhou\Anaconda3\envs\lts\lib\site-packages\pymysql\connections.py", line 725, in _read_packet
    packet.raise_for_error()
  File "C:\Users\zhi.zhou\Anaconda3\envs\lts\lib\site-packages\pymysql\protocol.py", line 221, in raise_for_error
    err.raise_mysql_exception(self._data)
  File "C:\Users\zhi.zhou\Anaconda3\envs\lts\lib\site-packages\pymysql\err.py", line 143, in raise_mysql_exception
    raise errorclass(errno, errval)
pymysql.err.ProgrammingError: (1146, "Table 'db_common.pick_box' doesn't exist")

During handling of the above exception, another exception occurred:

Traceback (most recent call last):
  File "C:\Users\zhi.zhou\Anaconda3\envs\lts\lib\site-packages\django\core\handlers\exception.py", line 47, in inner
    response = get_response(request)
  File "C:\Users\zhi.zhou\Anaconda3\envs\lts\lib\site-packages\django\core\handlers\base.py", line 181, in _get_response
    response = wrapped_callback(request, *callback_args, **callback_kwargs)
  File "C:\Users\zhi.zhou\Anaconda3\envs\lts\lib\site-packages\django\views\generic\base.py", line 70, in view
    return self.dispatch(request, *args, **kwargs)
  File "C:\Users\zhi.zhou\Anaconda3\envs\lts\lib\site-packages\django\views\generic\base.py", line 98, in dispatch
    return handler(request, *args, **kwargs)
  File "D:\zhouzhi\gitlit_code\logistic_tracking_system\logistic_tracking_system\lts\views.py", line 4602, in get
    data = json.dumps(data)
  File "C:\Users\zhi.zhou\Anaconda3\envs\lts\lib\json\__init__.py", line 231, in dumps
    return _default_encoder.encode(obj)
  File "C:\Users\zhi.zhou\Anaconda3\envs\lts\lib\json\encoder.py", line 199, in encode
    chunks = self.iterencode(o, _one_shot=True)
  File "C:\Users\zhi.zhou\Anaconda3\envs\lts\lib\json\encoder.py", line 257, in iterencode
    return _iterencode(o, 0)
  File "C:\Users\zhi.zhou\Anaconda3\envs\lts\lib\json\encoder.py", line 180, in default
    o.__class__.__name__)
TypeError: Object of type 'ProgrammingError' is not JSON serializable
[2021-08-17 17:39:37,378][Thread-15:11712][task_id:lts.views][views.py:1543][ERROR][查询产品列表失败]
[2021-08-17 17:48:12,944][Thread-1:1332][task_id:django.request][log.py:230][ERROR][Internal Server Error: /logistic/LogisticWorkStation]
Traceback (most recent call last):
  File "D:\zhouzhi\gitlit_code\logistic_tracking_system\logistic_tracking_system\lts\views.py", line 2171, in get
    drs = db.execute_sql(conn, sql_main)
  File "D:\zhouzhi\gitlit_code\logistic_tracking_system\logistic_tracking_system\common\db.py", line 45, in execute_sql
    cursor.execute(sql)
  File "C:\Users\zhi.zhou\Anaconda3\envs\lts\lib\site-packages\pymysql\cursors.py", line 148, in execute
    result = self._query(query)
  File "C:\Users\zhi.zhou\Anaconda3\envs\lts\lib\site-packages\pymysql\cursors.py", line 310, in _query
    conn.query(q)
  File "C:\Users\zhi.zhou\Anaconda3\envs\lts\lib\site-packages\pymysql\connections.py", line 548, in query
    self._affected_rows = self._read_query_result(unbuffered=unbuffered)
  File "C:\Users\zhi.zhou\Anaconda3\envs\lts\lib\site-packages\pymysql\connections.py", line 775, in _read_query_result
    result.read()
  File "C:\Users\zhi.zhou\Anaconda3\envs\lts\lib\site-packages\pymysql\connections.py", line 1156, in read
    first_packet = self.connection._read_packet()
  File "C:\Users\zhi.zhou\Anaconda3\envs\lts\lib\site-packages\pymysql\connections.py", line 725, in _read_packet
    packet.raise_for_error()
  File "C:\Users\zhi.zhou\Anaconda3\envs\lts\lib\site-packages\pymysql\protocol.py", line 221, in raise_for_error
    err.raise_mysql_exception(self._data)
  File "C:\Users\zhi.zhou\Anaconda3\envs\lts\lib\site-packages\pymysql\err.py", line 143, in raise_mysql_exception
    raise errorclass(errno, errval)
pymysql.err.OperationalError: (1046, 'No database selected')

During handling of the above exception, another exception occurred:

Traceback (most recent call last):
  File "C:\Users\zhi.zhou\Anaconda3\envs\lts\lib\site-packages\django\core\handlers\exception.py", line 47, in inner
    response = get_response(request)
  File "C:\Users\zhi.zhou\Anaconda3\envs\lts\lib\site-packages\django\core\handlers\base.py", line 181, in _get_response
    response = wrapped_callback(request, *callback_args, **callback_kwargs)
  File "C:\Users\zhi.zhou\Anaconda3\envs\lts\lib\site-packages\django\views\generic\base.py", line 70, in view
    return self.dispatch(request, *args, **kwargs)
  File "C:\Users\zhi.zhou\Anaconda3\envs\lts\lib\site-packages\django\views\generic\base.py", line 98, in dispatch
    return handler(request, *args, **kwargs)
  File "D:\zhouzhi\gitlit_code\logistic_tracking_system\logistic_tracking_system\lts\views.py", line 2202, in get
    result = json.dumps(result)
  File "C:\Users\zhi.zhou\Anaconda3\envs\lts\lib\json\__init__.py", line 231, in dumps
    return _default_encoder.encode(obj)
  File "C:\Users\zhi.zhou\Anaconda3\envs\lts\lib\json\encoder.py", line 199, in encode
    chunks = self.iterencode(o, _one_shot=True)
  File "C:\Users\zhi.zhou\Anaconda3\envs\lts\lib\json\encoder.py", line 257, in iterencode
    return _iterencode(o, 0)
  File "C:\Users\zhi.zhou\Anaconda3\envs\lts\lib\json\encoder.py", line 180, in default
    o.__class__.__name__)
TypeError: Object of type 'OperationalError' is not JSON serializable
[2021-08-17 17:48:32,265][Thread-2:2652][task_id:lts.views][views.py:1543][ERROR][查询产品列表失败]
[2021-08-17 17:50:29,347][Thread-4:11728][task_id:lts.views][views.py:1543][ERROR][查询产品列表失败]
[2021-08-17 17:50:44,234][Thread-3:9700][task_id:django.request][log.py:230][ERROR][Internal Server Error: /logistic/LogisticWorkCodeName]
Traceback (most recent call last):
  File "D:\zhouzhi\gitlit_code\logistic_tracking_system\logistic_tracking_system\lts\views.py", line 3738, in get
    drs = db.execute_sql(conn, sql)
  File "D:\zhouzhi\gitlit_code\logistic_tracking_system\logistic_tracking_system\common\db.py", line 45, in execute_sql
    cursor.execute(sql)
  File "C:\Users\zhi.zhou\Anaconda3\envs\lts\lib\site-packages\pymysql\cursors.py", line 148, in execute
    result = self._query(query)
  File "C:\Users\zhi.zhou\Anaconda3\envs\lts\lib\site-packages\pymysql\cursors.py", line 310, in _query
    conn.query(q)
  File "C:\Users\zhi.zhou\Anaconda3\envs\lts\lib\site-packages\pymysql\connections.py", line 548, in query
    self._affected_rows = self._read_query_result(unbuffered=unbuffered)
  File "C:\Users\zhi.zhou\Anaconda3\envs\lts\lib\site-packages\pymysql\connections.py", line 775, in _read_query_result
    result.read()
  File "C:\Users\zhi.zhou\Anaconda3\envs\lts\lib\site-packages\pymysql\connections.py", line 1156, in read
    first_packet = self.connection._read_packet()
  File "C:\Users\zhi.zhou\Anaconda3\envs\lts\lib\site-packages\pymysql\connections.py", line 725, in _read_packet
    packet.raise_for_error()
  File "C:\Users\zhi.zhou\Anaconda3\envs\lts\lib\site-packages\pymysql\protocol.py", line 221, in raise_for_error
    err.raise_mysql_exception(self._data)
  File "C:\Users\zhi.zhou\Anaconda3\envs\lts\lib\site-packages\pymysql\err.py", line 143, in raise_mysql_exception
    raise errorclass(errno, errval)
pymysql.err.OperationalError: (1046, 'No database selected')

During handling of the above exception, another exception occurred:

Traceback (most recent call last):
  File "C:\Users\zhi.zhou\Anaconda3\envs\lts\lib\site-packages\django\core\handlers\exception.py", line 47, in inner
    response = get_response(request)
  File "C:\Users\zhi.zhou\Anaconda3\envs\lts\lib\site-packages\django\core\handlers\base.py", line 181, in _get_response
    response = wrapped_callback(request, *callback_args, **callback_kwargs)
  File "C:\Users\zhi.zhou\Anaconda3\envs\lts\lib\site-packages\django\views\generic\base.py", line 70, in view
    return self.dispatch(request, *args, **kwargs)
  File "C:\Users\zhi.zhou\Anaconda3\envs\lts\lib\site-packages\django\views\generic\base.py", line 98, in dispatch
    return handler(request, *args, **kwargs)
  File "D:\zhouzhi\gitlit_code\logistic_tracking_system\logistic_tracking_system\lts\views.py", line 3753, in get
    data = json.dumps(data)
  File "C:\Users\zhi.zhou\Anaconda3\envs\lts\lib\json\__init__.py", line 231, in dumps
    return _default_encoder.encode(obj)
  File "C:\Users\zhi.zhou\Anaconda3\envs\lts\lib\json\encoder.py", line 199, in encode
    chunks = self.iterencode(o, _one_shot=True)
  File "C:\Users\zhi.zhou\Anaconda3\envs\lts\lib\json\encoder.py", line 257, in iterencode
    return _iterencode(o, 0)
  File "C:\Users\zhi.zhou\Anaconda3\envs\lts\lib\json\encoder.py", line 180, in default
    o.__class__.__name__)
TypeError: Object of type 'OperationalError' is not JSON serializable
[2021-08-17 17:51:54,941][Thread-2:10720][task_id:lts.views][views.py:1543][ERROR][查询产品列表失败]
[2021-08-17 17:52:05,814][Thread-1:12744][task_id:django.request][log.py:230][ERROR][Internal Server Error: /logistic/LogisticWorkCodeName]
Traceback (most recent call last):
  File "D:\zhouzhi\gitlit_code\logistic_tracking_system\logistic_tracking_system\lts\views.py", line 3738, in get
    drs = db.execute_sql(conn, sql)
  File "D:\zhouzhi\gitlit_code\logistic_tracking_system\logistic_tracking_system\common\db.py", line 45, in execute_sql
    cursor.execute(sql)
  File "C:\Users\zhi.zhou\Anaconda3\envs\lts\lib\site-packages\pymysql\cursors.py", line 148, in execute
    result = self._query(query)
  File "C:\Users\zhi.zhou\Anaconda3\envs\lts\lib\site-packages\pymysql\cursors.py", line 310, in _query
    conn.query(q)
  File "C:\Users\zhi.zhou\Anaconda3\envs\lts\lib\site-packages\pymysql\connections.py", line 548, in query
    self._affected_rows = self._read_query_result(unbuffered=unbuffered)
  File "C:\Users\zhi.zhou\Anaconda3\envs\lts\lib\site-packages\pymysql\connections.py", line 775, in _read_query_result
    result.read()
  File "C:\Users\zhi.zhou\Anaconda3\envs\lts\lib\site-packages\pymysql\connections.py", line 1156, in read
    first_packet = self.connection._read_packet()
  File "C:\Users\zhi.zhou\Anaconda3\envs\lts\lib\site-packages\pymysql\connections.py", line 725, in _read_packet
    packet.raise_for_error()
  File "C:\Users\zhi.zhou\Anaconda3\envs\lts\lib\site-packages\pymysql\protocol.py", line 221, in raise_for_error
    err.raise_mysql_exception(self._data)
  File "C:\Users\zhi.zhou\Anaconda3\envs\lts\lib\site-packages\pymysql\err.py", line 143, in raise_mysql_exception
    raise errorclass(errno, errval)
pymysql.err.OperationalError: (1046, 'No database selected')

During handling of the above exception, another exception occurred:

Traceback (most recent call last):
  File "C:\Users\zhi.zhou\Anaconda3\envs\lts\lib\site-packages\django\core\handlers\exception.py", line 47, in inner
    response = get_response(request)
  File "C:\Users\zhi.zhou\Anaconda3\envs\lts\lib\site-packages\django\core\handlers\base.py", line 181, in _get_response
    response = wrapped_callback(request, *callback_args, **callback_kwargs)
  File "C:\Users\zhi.zhou\Anaconda3\envs\lts\lib\site-packages\django\views\generic\base.py", line 70, in view
    return self.dispatch(request, *args, **kwargs)
  File "C:\Users\zhi.zhou\Anaconda3\envs\lts\lib\site-packages\django\views\generic\base.py", line 98, in dispatch
    return handler(request, *args, **kwargs)
  File "D:\zhouzhi\gitlit_code\logistic_tracking_system\logistic_tracking_system\lts\views.py", line 3753, in get
    data = json.dumps(data)
  File "C:\Users\zhi.zhou\Anaconda3\envs\lts\lib\json\__init__.py", line 231, in dumps
    return _default_encoder.encode(obj)
  File "C:\Users\zhi.zhou\Anaconda3\envs\lts\lib\json\encoder.py", line 199, in encode
    chunks = self.iterencode(o, _one_shot=True)
  File "C:\Users\zhi.zhou\Anaconda3\envs\lts\lib\json\encoder.py", line 257, in iterencode
    return _iterencode(o, 0)
  File "C:\Users\zhi.zhou\Anaconda3\envs\lts\lib\json\encoder.py", line 180, in default
    o.__class__.__name__)
TypeError: Object of type 'OperationalError' is not JSON serializable
[2021-08-17 17:53:42,772][Thread-2:11740][task_id:lts.views][views.py:1543][ERROR][查询产品列表失败]
[2021-08-17 17:54:44,961][Thread-5:13664][task_id:lts.views][views.py:1543][ERROR][查询产品列表失败]
[2021-08-17 17:56:23,810][Thread-2:17092][task_id:lts.views][views.py:1545][ERROR][查询产品列表失败]
[2021-08-17 17:56:43,093][Thread-2:17092][task_id:lts.views][views.py:1545][ERROR][查询产品列表失败]
[2021-08-17 17:56:52,894][Thread-1:3588][task_id:lts.views][views.py:1545][ERROR][查询产品列表失败]
[2021-08-17 17:57:34,282][Thread-1:3588][task_id:lts.views][views.py:1545][ERROR][查询产品列表失败]
[2021-08-17 17:57:50,774][Thread-2:17092][task_id:django.request][log.py:230][ERROR][Internal Server Error: /logistic/LogisticProductTransitInfo]
Traceback (most recent call last):
  File "D:\zhouzhi\gitlit_code\logistic_tracking_system\logistic_tracking_system\lts\views.py", line 4182, in get
    work_code = drss[0][0]
IndexError: tuple index out of range

During handling of the above exception, another exception occurred:

Traceback (most recent call last):
  File "C:\Users\zhi.zhou\Anaconda3\envs\lts\lib\site-packages\django\core\handlers\exception.py", line 47, in inner
    response = get_response(request)
  File "C:\Users\zhi.zhou\Anaconda3\envs\lts\lib\site-packages\django\core\handlers\base.py", line 181, in _get_response
    response = wrapped_callback(request, *callback_args, **callback_kwargs)
  File "C:\Users\zhi.zhou\Anaconda3\envs\lts\lib\site-packages\django\views\generic\base.py", line 70, in view
    return self.dispatch(request, *args, **kwargs)
  File "C:\Users\zhi.zhou\Anaconda3\envs\lts\lib\site-packages\django\views\generic\base.py", line 98, in dispatch
    return handler(request, *args, **kwargs)
  File "D:\zhouzhi\gitlit_code\logistic_tracking_system\logistic_tracking_system\lts\views.py", line 4313, in get
    data = json.dumps(data)
  File "C:\Users\zhi.zhou\Anaconda3\envs\lts\lib\json\__init__.py", line 231, in dumps
    return _default_encoder.encode(obj)
  File "C:\Users\zhi.zhou\Anaconda3\envs\lts\lib\json\encoder.py", line 199, in encode
    chunks = self.iterencode(o, _one_shot=True)
  File "C:\Users\zhi.zhou\Anaconda3\envs\lts\lib\json\encoder.py", line 257, in iterencode
    return _iterencode(o, 0)
  File "C:\Users\zhi.zhou\Anaconda3\envs\lts\lib\json\encoder.py", line 180, in default
    o.__class__.__name__)
TypeError: Object of type 'IndexError' is not JSON serializable
[2021-08-17 17:59:28,040][Thread-4:7644][task_id:lts.views][views.py:1545][ERROR][查询产品列表失败]
