[2021-08-11 08:42:54,085][MainThread:16900][task_id:django.utils.autoreload][autoreload.py:637][INFO][Watching for file changes with StatReloader]
[2021-08-11 08:43:45,172][Thread-1:5060][task_id:lts.views][views.py:201][INFO][登录成功]
[2021-08-11 09:04:06,266][MainThread:14604][task_id:django.utils.autoreload][autoreload.py:637][INFO][Watching for file changes with StatReloader]
[2021-08-11 11:27:44,866][MainThread:14604][task_id:django.utils.autoreload][autoreload.py:251][INFO][D:\zhouzhi\gitlit_code\logistic_tracking_system\logistic_tracking_system\lts\urls.py changed, reloading.]
[2021-08-11 11:27:45,967][MainThread:17592][task_id:django.utils.autoreload][autoreload.py:637][INFO][Watching for file changes with StatReloader]
[2021-08-11 11:32:39,373][MainThread:17592][task_id:django.utils.autoreload][autoreload.py:251][INFO][D:\zhouzhi\gitlit_code\logistic_tracking_system\logistic_tracking_system\lts\views.py changed, reloading.]
[2021-08-11 11:32:40,411][MainThread:8404][task_id:django.utils.autoreload][autoreload.py:637][INFO][Watching for file changes with StatReloader]
[2021-08-11 11:37:36,775][MainThread:8404][task_id:django.utils.autoreload][autoreload.py:251][INFO][D:\zhouzhi\gitlit_code\logistic_tracking_system\logistic_tracking_system\lts\views.py changed, reloading.]
[2021-08-11 11:37:37,807][MainThread:14332][task_id:django.utils.autoreload][autoreload.py:637][INFO][Watching for file changes with StatReloader]
[2021-08-11 11:41:41,003][MainThread:14332][task_id:django.utils.autoreload][autoreload.py:251][INFO][D:\zhouzhi\gitlit_code\logistic_tracking_system\logistic_tracking_system\lts\views.py changed, reloading.]
[2021-08-11 11:41:42,041][MainThread:13392][task_id:django.utils.autoreload][autoreload.py:637][INFO][Watching for file changes with StatReloader]
[2021-08-11 11:43:54,886][MainThread:13392][task_id:django.utils.autoreload][autoreload.py:251][INFO][D:\zhouzhi\gitlit_code\logistic_tracking_system\logistic_tracking_system\lts\views.py changed, reloading.]
[2021-08-11 11:43:55,901][MainThread:3844][task_id:django.utils.autoreload][autoreload.py:637][INFO][Watching for file changes with StatReloader]
[2021-08-11 11:44:24,520][Thread-1:5036][task_id:lts.views][views.py:6131][ERROR][查询物产品信息失败,int() argument must be a string, a bytes-like object or a number, not 'NoneType']
[2021-08-11 11:46:01,627][MainThread:3844][task_id:django.utils.autoreload][autoreload.py:251][INFO][D:\zhouzhi\gitlit_code\logistic_tracking_system\logistic_tracking_system\lts\views.py changed, reloading.]
[2021-08-11 11:46:02,793][MainThread:1356][task_id:django.utils.autoreload][autoreload.py:637][INFO][Watching for file changes with StatReloader]
[2021-08-11 11:46:23,929][MainThread:1356][task_id:django.utils.autoreload][autoreload.py:251][INFO][D:\zhouzhi\gitlit_code\logistic_tracking_system\logistic_tracking_system\lts\views.py changed, reloading.]
[2021-08-11 11:46:24,952][MainThread:12900][task_id:django.utils.autoreload][autoreload.py:637][INFO][Watching for file changes with StatReloader]
[2021-08-11 11:48:44,745][MainThread:12900][task_id:django.utils.autoreload][autoreload.py:251][INFO][D:\zhouzhi\gitlit_code\logistic_tracking_system\logistic_tracking_system\lts\views.py changed, reloading.]
[2021-08-11 11:48:45,789][MainThread:1960][task_id:django.utils.autoreload][autoreload.py:637][INFO][Watching for file changes with StatReloader]
[2021-08-11 11:50:38,441][MainThread:1960][task_id:django.utils.autoreload][autoreload.py:251][INFO][D:\zhouzhi\gitlit_code\logistic_tracking_system\logistic_tracking_system\lts\views.py changed, reloading.]
[2021-08-11 11:50:39,478][MainThread:17564][task_id:django.utils.autoreload][autoreload.py:637][INFO][Watching for file changes with StatReloader]
[2021-08-11 11:51:49,952][MainThread:17564][task_id:django.utils.autoreload][autoreload.py:251][INFO][D:\zhouzhi\gitlit_code\logistic_tracking_system\logistic_tracking_system\lts\views.py changed, reloading.]
[2021-08-11 11:51:51,178][MainThread:5460][task_id:django.utils.autoreload][autoreload.py:637][INFO][Watching for file changes with StatReloader]
[2021-08-11 12:01:33,346][MainThread:5460][task_id:django.utils.autoreload][autoreload.py:251][INFO][D:\zhouzhi\gitlit_code\logistic_tracking_system\logistic_tracking_system\lts\views.py changed, reloading.]
[2021-08-11 12:01:34,669][MainThread:13032][task_id:django.utils.autoreload][autoreload.py:637][INFO][Watching for file changes with StatReloader]
[2021-08-11 13:36:32,216][MainThread:13032][task_id:django.utils.autoreload][autoreload.py:251][INFO][D:\zhouzhi\gitlit_code\logistic_tracking_system\logistic_tracking_system\lts\views.py changed, reloading.]
[2021-08-11 13:36:33,428][MainThread:19516][task_id:django.utils.autoreload][autoreload.py:637][INFO][Watching for file changes with StatReloader]
[2021-08-11 13:39:11,996][MainThread:19516][task_id:django.utils.autoreload][autoreload.py:251][INFO][D:\zhouzhi\gitlit_code\logistic_tracking_system\logistic_tracking_system\lts\views.py changed, reloading.]
[2021-08-11 13:39:13,018][MainThread:13832][task_id:django.utils.autoreload][autoreload.py:637][INFO][Watching for file changes with StatReloader]
[2021-08-11 14:17:28,179][MainThread:13832][task_id:django.utils.autoreload][autoreload.py:251][INFO][D:\zhouzhi\gitlit_code\logistic_tracking_system\logistic_tracking_system\logistic_tracking_system\urls.py changed, reloading.]
[2021-08-11 14:17:29,191][MainThread:15380][task_id:django.utils.autoreload][autoreload.py:637][INFO][Watching for file changes with StatReloader]
[2021-08-11 14:17:36,060][MainThread:15380][task_id:django.utils.autoreload][autoreload.py:251][INFO][D:\zhouzhi\gitlit_code\logistic_tracking_system\logistic_tracking_system\logistic_tracking_system\urls.py changed, reloading.]
[2021-08-11 14:17:37,066][MainThread:17420][task_id:django.utils.autoreload][autoreload.py:637][INFO][Watching for file changes with StatReloader]
[2021-08-11 14:17:54,653][MainThread:17420][task_id:django.utils.autoreload][autoreload.py:251][INFO][D:\zhouzhi\gitlit_code\logistic_tracking_system\logistic_tracking_system\logistic_tracking_system\urls.py changed, reloading.]
[2021-08-11 14:17:55,649][MainThread:8496][task_id:django.utils.autoreload][autoreload.py:637][INFO][Watching for file changes with StatReloader]
[2021-08-11 14:18:31,182][MainThread:8496][task_id:django.utils.autoreload][autoreload.py:251][INFO][D:\zhouzhi\gitlit_code\logistic_tracking_system\logistic_tracking_system\logistic_tracking_system\urls.py changed, reloading.]
[2021-08-11 14:18:32,185][MainThread:20160][task_id:django.utils.autoreload][autoreload.py:637][INFO][Watching for file changes with StatReloader]
[2021-08-11 14:21:00,755][MainThread:20160][task_id:django.utils.autoreload][autoreload.py:251][INFO][D:\zhouzhi\gitlit_code\logistic_tracking_system\logistic_tracking_system\lts\views.py changed, reloading.]
[2021-08-11 14:21:02,436][MainThread:3352][task_id:django.utils.autoreload][autoreload.py:637][INFO][Watching for file changes with StatReloader]
[2021-08-11 14:26:09,683][MainThread:3352][task_id:django.utils.autoreload][autoreload.py:251][INFO][D:\zhouzhi\gitlit_code\logistic_tracking_system\logistic_tracking_system\lts\views.py changed, reloading.]
[2021-08-11 14:26:10,679][MainThread:15564][task_id:django.utils.autoreload][autoreload.py:637][INFO][Watching for file changes with StatReloader]
[2021-08-11 14:27:02,260][MainThread:15564][task_id:django.utils.autoreload][autoreload.py:251][INFO][D:\zhouzhi\gitlit_code\logistic_tracking_system\logistic_tracking_system\lts\views.py changed, reloading.]
[2021-08-11 14:27:03,409][MainThread:11932][task_id:django.utils.autoreload][autoreload.py:637][INFO][Watching for file changes with StatReloader]
[2021-08-11 14:29:01,993][MainThread:11932][task_id:django.utils.autoreload][autoreload.py:251][INFO][D:\zhouzhi\gitlit_code\logistic_tracking_system\logistic_tracking_system\lts\views.py changed, reloading.]
[2021-08-11 14:29:03,009][MainThread:18664][task_id:django.utils.autoreload][autoreload.py:637][INFO][Watching for file changes with StatReloader]
[2021-08-11 14:29:05,656][MainThread:18664][task_id:django.utils.autoreload][autoreload.py:251][INFO][D:\zhouzhi\gitlit_code\logistic_tracking_system\logistic_tracking_system\lts\views.py changed, reloading.]
[2021-08-11 14:29:06,670][MainThread:4352][task_id:django.utils.autoreload][autoreload.py:637][INFO][Watching for file changes with StatReloader]
[2021-08-11 14:30:21,403][MainThread:4352][task_id:django.utils.autoreload][autoreload.py:251][INFO][D:\zhouzhi\gitlit_code\logistic_tracking_system\logistic_tracking_system\lts\views.py changed, reloading.]
[2021-08-11 14:30:22,484][MainThread:4116][task_id:django.utils.autoreload][autoreload.py:637][INFO][Watching for file changes with StatReloader]
[2021-08-11 14:31:09,377][MainThread:4116][task_id:django.utils.autoreload][autoreload.py:251][INFO][D:\zhouzhi\gitlit_code\logistic_tracking_system\logistic_tracking_system\lts\views.py changed, reloading.]
[2021-08-11 14:31:10,385][MainThread:13148][task_id:django.utils.autoreload][autoreload.py:637][INFO][Watching for file changes with StatReloader]
[2021-08-11 14:31:17,279][MainThread:13148][task_id:django.utils.autoreload][autoreload.py:251][INFO][D:\zhouzhi\gitlit_code\logistic_tracking_system\logistic_tracking_system\lts\views.py changed, reloading.]
[2021-08-11 14:31:18,295][MainThread:3400][task_id:django.utils.autoreload][autoreload.py:637][INFO][Watching for file changes with StatReloader]
[2021-08-11 14:32:01,172][MainThread:3400][task_id:django.utils.autoreload][autoreload.py:251][INFO][D:\zhouzhi\gitlit_code\logistic_tracking_system\logistic_tracking_system\lts\views.py changed, reloading.]
[2021-08-11 14:32:02,201][MainThread:19364][task_id:django.utils.autoreload][autoreload.py:637][INFO][Watching for file changes with StatReloader]
[2021-08-11 14:47:33,744][MainThread:19364][task_id:django.utils.autoreload][autoreload.py:251][INFO][D:\zhouzhi\gitlit_code\logistic_tracking_system\logistic_tracking_system\lts\views.py changed, reloading.]
[2021-08-11 14:47:34,781][MainThread:19144][task_id:django.utils.autoreload][autoreload.py:637][INFO][Watching for file changes with StatReloader]
[2021-08-11 14:48:14,085][MainThread:19144][task_id:django.utils.autoreload][autoreload.py:251][INFO][D:\zhouzhi\gitlit_code\logistic_tracking_system\logistic_tracking_system\lts\views.py changed, reloading.]
[2021-08-11 14:48:15,107][MainThread:11324][task_id:django.utils.autoreload][autoreload.py:637][INFO][Watching for file changes with StatReloader]
[2021-08-11 14:48:41,346][MainThread:11324][task_id:django.utils.autoreload][autoreload.py:251][INFO][D:\zhouzhi\gitlit_code\logistic_tracking_system\logistic_tracking_system\lts\views.py changed, reloading.]
[2021-08-11 14:48:42,404][MainThread:2840][task_id:django.utils.autoreload][autoreload.py:637][INFO][Watching for file changes with StatReloader]
[2021-08-11 14:50:00,432][MainThread:2840][task_id:django.utils.autoreload][autoreload.py:251][INFO][D:\zhouzhi\gitlit_code\logistic_tracking_system\logistic_tracking_system\lts\views.py changed, reloading.]
[2021-08-11 14:50:01,443][MainThread:4756][task_id:django.utils.autoreload][autoreload.py:637][INFO][Watching for file changes with StatReloader]
[2021-08-11 14:50:27,803][MainThread:4756][task_id:django.utils.autoreload][autoreload.py:251][INFO][D:\zhouzhi\gitlit_code\logistic_tracking_system\logistic_tracking_system\lts\views.py changed, reloading.]
[2021-08-11 14:50:28,835][MainThread:15872][task_id:django.utils.autoreload][autoreload.py:637][INFO][Watching for file changes with StatReloader]
[2021-08-11 14:55:19,412][MainThread:15872][task_id:django.utils.autoreload][autoreload.py:251][INFO][D:\zhouzhi\gitlit_code\logistic_tracking_system\logistic_tracking_system\lts\views.py changed, reloading.]
[2021-08-11 14:55:20,427][MainThread:2840][task_id:django.utils.autoreload][autoreload.py:637][INFO][Watching for file changes with StatReloader]
[2021-08-11 14:56:02,781][MainThread:2840][task_id:django.utils.autoreload][autoreload.py:251][INFO][D:\zhouzhi\gitlit_code\logistic_tracking_system\logistic_tracking_system\lts\views.py changed, reloading.]
[2021-08-11 14:56:03,989][MainThread:19132][task_id:django.utils.autoreload][autoreload.py:637][INFO][Watching for file changes with StatReloader]
[2021-08-11 14:56:46,729][Thread-1:15608][task_id:django.request][log.py:230][ERROR][Internal Server Error: /logistic/LogisticWorkCodeName]
Traceback (most recent call last):
  File "D:\zhouzhi\gitlit_code\logistic_tracking_system\logistic_tracking_system\lts\views.py", line 3510, in get
    drs = db.execute_sql(conn, sql)
  File "D:\zhouzhi\gitlit_code\logistic_tracking_system\logistic_tracking_system\common\db.py", line 45, in execute_sql
    cursor.execute(sql)
  File "C:\Users\zhi.zhou\Anaconda3\envs\lts\lib\site-packages\pymysql\cursors.py", line 148, in execute
    result = self._query(query)
  File "C:\Users\zhi.zhou\Anaconda3\envs\lts\lib\site-packages\pymysql\cursors.py", line 310, in _query
    conn.query(q)
  File "C:\Users\zhi.zhou\Anaconda3\envs\lts\lib\site-packages\pymysql\connections.py", line 548, in query
    self._affected_rows = self._read_query_result(unbuffered=unbuffered)
  File "C:\Users\zhi.zhou\Anaconda3\envs\lts\lib\site-packages\pymysql\connections.py", line 775, in _read_query_result
    result.read()
  File "C:\Users\zhi.zhou\Anaconda3\envs\lts\lib\site-packages\pymysql\connections.py", line 1156, in read
    first_packet = self.connection._read_packet()
  File "C:\Users\zhi.zhou\Anaconda3\envs\lts\lib\site-packages\pymysql\connections.py", line 725, in _read_packet
    packet.raise_for_error()
  File "C:\Users\zhi.zhou\Anaconda3\envs\lts\lib\site-packages\pymysql\protocol.py", line 221, in raise_for_error
    err.raise_mysql_exception(self._data)
  File "C:\Users\zhi.zhou\Anaconda3\envs\lts\lib\site-packages\pymysql\err.py", line 143, in raise_mysql_exception
    raise errorclass(errno, errval)
pymysql.err.OperationalError: (1046, 'No database selected')

During handling of the above exception, another exception occurred:

Traceback (most recent call last):
  File "C:\Users\zhi.zhou\Anaconda3\envs\lts\lib\site-packages\django\core\handlers\exception.py", line 47, in inner
    response = get_response(request)
  File "C:\Users\zhi.zhou\Anaconda3\envs\lts\lib\site-packages\django\core\handlers\base.py", line 181, in _get_response
    response = wrapped_callback(request, *callback_args, **callback_kwargs)
  File "C:\Users\zhi.zhou\Anaconda3\envs\lts\lib\site-packages\django\views\generic\base.py", line 70, in view
    return self.dispatch(request, *args, **kwargs)
  File "C:\Users\zhi.zhou\Anaconda3\envs\lts\lib\site-packages\django\views\generic\base.py", line 98, in dispatch
    return handler(request, *args, **kwargs)
  File "D:\zhouzhi\gitlit_code\logistic_tracking_system\logistic_tracking_system\lts\views.py", line 3525, in get
    data = json.dumps(data)
  File "C:\Users\zhi.zhou\Anaconda3\envs\lts\lib\json\__init__.py", line 231, in dumps
    return _default_encoder.encode(obj)
  File "C:\Users\zhi.zhou\Anaconda3\envs\lts\lib\json\encoder.py", line 199, in encode
    chunks = self.iterencode(o, _one_shot=True)
  File "C:\Users\zhi.zhou\Anaconda3\envs\lts\lib\json\encoder.py", line 257, in iterencode
    return _iterencode(o, 0)
  File "C:\Users\zhi.zhou\Anaconda3\envs\lts\lib\json\encoder.py", line 180, in default
    o.__class__.__name__)
TypeError: Object of type 'OperationalError' is not JSON serializable
[2021-08-11 14:57:01,379][Thread-1:15608][task_id:lts.views][views.py:201][INFO][登录成功]
[2021-08-11 14:59:08,632][MainThread:19132][task_id:django.utils.autoreload][autoreload.py:251][INFO][D:\zhouzhi\gitlit_code\logistic_tracking_system\logistic_tracking_system\lts\views.py changed, reloading.]
[2021-08-11 14:59:09,650][MainThread:19792][task_id:django.utils.autoreload][autoreload.py:637][INFO][Watching for file changes with StatReloader]
[2021-08-11 15:06:11,887][Thread-1:18576][task_id:django.request][log.py:230][ERROR][Internal Server Error: /logistic/LogisticAddModel]
Traceback (most recent call last):
  File "D:\zhouzhi\gitlit_code\logistic_tracking_system\logistic_tracking_system\lts\views.py", line 6500, in post
    excit_psth = os.path.join(path_workstation, product_id)
  File "C:\Users\zhi.zhou\Anaconda3\envs\lts\lib\ntpath.py", line 115, in join
    genericpath._check_arg_types('join', path, *paths)
  File "C:\Users\zhi.zhou\Anaconda3\envs\lts\lib\genericpath.py", line 149, in _check_arg_types
    (funcname, s.__class__.__name__)) from None
TypeError: join() argument must be str or bytes, not 'NoneType'

During handling of the above exception, another exception occurred:

Traceback (most recent call last):
  File "C:\Users\zhi.zhou\Anaconda3\envs\lts\lib\site-packages\django\core\handlers\exception.py", line 47, in inner
    response = get_response(request)
  File "C:\Users\zhi.zhou\Anaconda3\envs\lts\lib\site-packages\django\core\handlers\base.py", line 181, in _get_response
    response = wrapped_callback(request, *callback_args, **callback_kwargs)
  File "C:\Users\zhi.zhou\Anaconda3\envs\lts\lib\site-packages\django\views\generic\base.py", line 70, in view
    return self.dispatch(request, *args, **kwargs)
  File "C:\Users\zhi.zhou\Anaconda3\envs\lts\lib\site-packages\django\views\generic\base.py", line 98, in dispatch
    return handler(request, *args, **kwargs)
  File "D:\zhouzhi\gitlit_code\logistic_tracking_system\logistic_tracking_system\lts\views.py", line 6523, in post
    result = json.dumps(result)
  File "C:\Users\zhi.zhou\Anaconda3\envs\lts\lib\json\__init__.py", line 231, in dumps
    return _default_encoder.encode(obj)
  File "C:\Users\zhi.zhou\Anaconda3\envs\lts\lib\json\encoder.py", line 199, in encode
    chunks = self.iterencode(o, _one_shot=True)
  File "C:\Users\zhi.zhou\Anaconda3\envs\lts\lib\json\encoder.py", line 257, in iterencode
    return _iterencode(o, 0)
  File "C:\Users\zhi.zhou\Anaconda3\envs\lts\lib\json\encoder.py", line 180, in default
    o.__class__.__name__)
TypeError: Object of type 'TypeError' is not JSON serializable
[2021-08-11 15:08:02,699][MainThread:19792][task_id:django.utils.autoreload][autoreload.py:251][INFO][D:\zhouzhi\gitlit_code\logistic_tracking_system\logistic_tracking_system\lts\views.py changed, reloading.]
[2021-08-11 15:08:03,810][MainThread:8432][task_id:django.utils.autoreload][autoreload.py:637][INFO][Watching for file changes with StatReloader]
[2021-08-11 15:08:05,582][Thread-1:19692][task_id:django.request][log.py:230][ERROR][Internal Server Error: /logistic/LogisticAddModel]
Traceback (most recent call last):
  File "D:\zhouzhi\gitlit_code\logistic_tracking_system\logistic_tracking_system\lts\views.py", line 6503, in post
    excit_psth = os.path.join(path_workstation, product_id)
  File "C:\Users\zhi.zhou\Anaconda3\envs\lts\lib\ntpath.py", line 115, in join
    genericpath._check_arg_types('join', path, *paths)
  File "C:\Users\zhi.zhou\Anaconda3\envs\lts\lib\genericpath.py", line 149, in _check_arg_types
    (funcname, s.__class__.__name__)) from None
TypeError: join() argument must be str or bytes, not 'NoneType'

During handling of the above exception, another exception occurred:

Traceback (most recent call last):
  File "C:\Users\zhi.zhou\Anaconda3\envs\lts\lib\site-packages\django\core\handlers\exception.py", line 47, in inner
    response = get_response(request)
  File "C:\Users\zhi.zhou\Anaconda3\envs\lts\lib\site-packages\django\core\handlers\base.py", line 181, in _get_response
    response = wrapped_callback(request, *callback_args, **callback_kwargs)
  File "C:\Users\zhi.zhou\Anaconda3\envs\lts\lib\site-packages\django\views\generic\base.py", line 70, in view
    return self.dispatch(request, *args, **kwargs)
  File "C:\Users\zhi.zhou\Anaconda3\envs\lts\lib\site-packages\django\views\generic\base.py", line 98, in dispatch
    return handler(request, *args, **kwargs)
  File "D:\zhouzhi\gitlit_code\logistic_tracking_system\logistic_tracking_system\lts\views.py", line 6525, in post
    result = json.dumps(result)
  File "C:\Users\zhi.zhou\Anaconda3\envs\lts\lib\json\__init__.py", line 231, in dumps
    return _default_encoder.encode(obj)
  File "C:\Users\zhi.zhou\Anaconda3\envs\lts\lib\json\encoder.py", line 199, in encode
    chunks = self.iterencode(o, _one_shot=True)
  File "C:\Users\zhi.zhou\Anaconda3\envs\lts\lib\json\encoder.py", line 257, in iterencode
    return _iterencode(o, 0)
  File "C:\Users\zhi.zhou\Anaconda3\envs\lts\lib\json\encoder.py", line 180, in default
    o.__class__.__name__)
TypeError: Object of type 'TypeError' is not JSON serializable
[2021-08-11 15:09:03,733][Thread-1:19692][task_id:django.request][log.py:230][ERROR][Internal Server Error: /logistic/LogisticAddModel]
Traceback (most recent call last):
  File "D:\zhouzhi\gitlit_code\logistic_tracking_system\logistic_tracking_system\lts\views.py", line 6503, in post
    excit_psth = os.path.join(path_workstation, product_id)
  File "C:\Users\zhi.zhou\Anaconda3\envs\lts\lib\ntpath.py", line 115, in join
    genericpath._check_arg_types('join', path, *paths)
  File "C:\Users\zhi.zhou\Anaconda3\envs\lts\lib\genericpath.py", line 149, in _check_arg_types
    (funcname, s.__class__.__name__)) from None
TypeError: join() argument must be str or bytes, not 'NoneType'

During handling of the above exception, another exception occurred:

Traceback (most recent call last):
  File "C:\Users\zhi.zhou\Anaconda3\envs\lts\lib\site-packages\django\core\handlers\exception.py", line 47, in inner
    response = get_response(request)
  File "C:\Users\zhi.zhou\Anaconda3\envs\lts\lib\site-packages\django\core\handlers\base.py", line 181, in _get_response
    response = wrapped_callback(request, *callback_args, **callback_kwargs)
  File "C:\Users\zhi.zhou\Anaconda3\envs\lts\lib\site-packages\django\views\generic\base.py", line 70, in view
    return self.dispatch(request, *args, **kwargs)
  File "C:\Users\zhi.zhou\Anaconda3\envs\lts\lib\site-packages\django\views\generic\base.py", line 98, in dispatch
    return handler(request, *args, **kwargs)
  File "D:\zhouzhi\gitlit_code\logistic_tracking_system\logistic_tracking_system\lts\views.py", line 6525, in post
    result = json.dumps(result)
  File "C:\Users\zhi.zhou\Anaconda3\envs\lts\lib\json\__init__.py", line 231, in dumps
    return _default_encoder.encode(obj)
  File "C:\Users\zhi.zhou\Anaconda3\envs\lts\lib\json\encoder.py", line 199, in encode
    chunks = self.iterencode(o, _one_shot=True)
  File "C:\Users\zhi.zhou\Anaconda3\envs\lts\lib\json\encoder.py", line 257, in iterencode
    return _iterencode(o, 0)
  File "C:\Users\zhi.zhou\Anaconda3\envs\lts\lib\json\encoder.py", line 180, in default
    o.__class__.__name__)
TypeError: Object of type 'TypeError' is not JSON serializable
[2021-08-11 15:09:15,725][MainThread:8432][task_id:django.utils.autoreload][autoreload.py:251][INFO][D:\zhouzhi\gitlit_code\logistic_tracking_system\logistic_tracking_system\lts\views.py changed, reloading.]
[2021-08-11 15:09:16,734][MainThread:20164][task_id:django.utils.autoreload][autoreload.py:637][INFO][Watching for file changes with StatReloader]
[2021-08-11 15:10:19,523][MainThread:20164][task_id:django.utils.autoreload][autoreload.py:251][INFO][D:\zhouzhi\gitlit_code\logistic_tracking_system\logistic_tracking_system\lts\views.py changed, reloading.]
[2021-08-11 15:10:20,554][MainThread:17712][task_id:django.utils.autoreload][autoreload.py:637][INFO][Watching for file changes with StatReloader]
[2021-08-11 15:15:32,283][Thread-1:20560][task_id:django.request][log.py:230][ERROR][Internal Server Error: /logistic/LogisticAddModel]
Traceback (most recent call last):
  File "D:\zhouzhi\gitlit_code\logistic_tracking_system\logistic_tracking_system\lts\views.py", line 6508, in post
    f = request.files['file']
AttributeError: 'WSGIRequest' object has no attribute 'files'

During handling of the above exception, another exception occurred:

Traceback (most recent call last):
  File "C:\Users\zhi.zhou\Anaconda3\envs\lts\lib\site-packages\django\core\handlers\exception.py", line 47, in inner
    response = get_response(request)
  File "C:\Users\zhi.zhou\Anaconda3\envs\lts\lib\site-packages\django\core\handlers\base.py", line 181, in _get_response
    response = wrapped_callback(request, *callback_args, **callback_kwargs)
  File "C:\Users\zhi.zhou\Anaconda3\envs\lts\lib\site-packages\django\views\generic\base.py", line 70, in view
    return self.dispatch(request, *args, **kwargs)
  File "C:\Users\zhi.zhou\Anaconda3\envs\lts\lib\site-packages\django\views\generic\base.py", line 98, in dispatch
    return handler(request, *args, **kwargs)
  File "D:\zhouzhi\gitlit_code\logistic_tracking_system\logistic_tracking_system\lts\views.py", line 6528, in post
    result = json.dumps(result)
  File "C:\Users\zhi.zhou\Anaconda3\envs\lts\lib\json\__init__.py", line 231, in dumps
    return _default_encoder.encode(obj)
  File "C:\Users\zhi.zhou\Anaconda3\envs\lts\lib\json\encoder.py", line 199, in encode
    chunks = self.iterencode(o, _one_shot=True)
  File "C:\Users\zhi.zhou\Anaconda3\envs\lts\lib\json\encoder.py", line 257, in iterencode
    return _iterencode(o, 0)
  File "C:\Users\zhi.zhou\Anaconda3\envs\lts\lib\json\encoder.py", line 180, in default
    o.__class__.__name__)
TypeError: Object of type 'AttributeError' is not JSON serializable
[2021-08-11 15:15:56,446][Thread-1:20560][task_id:django.request][log.py:230][ERROR][Internal Server Error: /logistic/LogisticAddModel]
Traceback (most recent call last):
  File "D:\zhouzhi\gitlit_code\logistic_tracking_system\logistic_tracking_system\lts\views.py", line 6508, in post
    f = request.files['file']
AttributeError: 'WSGIRequest' object has no attribute 'files'

During handling of the above exception, another exception occurred:

Traceback (most recent call last):
  File "C:\Users\zhi.zhou\Anaconda3\envs\lts\lib\site-packages\django\core\handlers\exception.py", line 47, in inner
    response = get_response(request)
  File "C:\Users\zhi.zhou\Anaconda3\envs\lts\lib\site-packages\django\core\handlers\base.py", line 181, in _get_response
    response = wrapped_callback(request, *callback_args, **callback_kwargs)
  File "C:\Users\zhi.zhou\Anaconda3\envs\lts\lib\site-packages\django\views\generic\base.py", line 70, in view
    return self.dispatch(request, *args, **kwargs)
  File "C:\Users\zhi.zhou\Anaconda3\envs\lts\lib\site-packages\django\views\generic\base.py", line 98, in dispatch
    return handler(request, *args, **kwargs)
  File "D:\zhouzhi\gitlit_code\logistic_tracking_system\logistic_tracking_system\lts\views.py", line 6528, in post
    result = json.dumps(result)
  File "C:\Users\zhi.zhou\Anaconda3\envs\lts\lib\json\__init__.py", line 231, in dumps
    return _default_encoder.encode(obj)
  File "C:\Users\zhi.zhou\Anaconda3\envs\lts\lib\json\encoder.py", line 199, in encode
    chunks = self.iterencode(o, _one_shot=True)
  File "C:\Users\zhi.zhou\Anaconda3\envs\lts\lib\json\encoder.py", line 257, in iterencode
    return _iterencode(o, 0)
  File "C:\Users\zhi.zhou\Anaconda3\envs\lts\lib\json\encoder.py", line 180, in default
    o.__class__.__name__)
TypeError: Object of type 'AttributeError' is not JSON serializable
[2021-08-11 15:16:38,128][MainThread:17712][task_id:django.utils.autoreload][autoreload.py:251][INFO][D:\zhouzhi\gitlit_code\logistic_tracking_system\logistic_tracking_system\lts\views.py changed, reloading.]
[2021-08-11 15:16:39,264][MainThread:6416][task_id:django.utils.autoreload][autoreload.py:637][INFO][Watching for file changes with StatReloader]
[2021-08-11 15:16:49,049][Thread-1:21484][task_id:django.request][log.py:230][ERROR][Internal Server Error: /logistic/LogisticAddModel]
Traceback (most recent call last):
  File "D:\zhouzhi\gitlit_code\logistic_tracking_system\logistic_tracking_system\lts\views.py", line 6510, in post
    f = request.files['file']
AttributeError: 'WSGIRequest' object has no attribute 'files'

During handling of the above exception, another exception occurred:

Traceback (most recent call last):
  File "C:\Users\zhi.zhou\Anaconda3\envs\lts\lib\site-packages\django\core\handlers\exception.py", line 47, in inner
    response = get_response(request)
  File "C:\Users\zhi.zhou\Anaconda3\envs\lts\lib\site-packages\django\core\handlers\base.py", line 181, in _get_response
    response = wrapped_callback(request, *callback_args, **callback_kwargs)
  File "C:\Users\zhi.zhou\Anaconda3\envs\lts\lib\site-packages\django\views\generic\base.py", line 70, in view
    return self.dispatch(request, *args, **kwargs)
  File "C:\Users\zhi.zhou\Anaconda3\envs\lts\lib\site-packages\django\views\generic\base.py", line 98, in dispatch
    return handler(request, *args, **kwargs)
  File "D:\zhouzhi\gitlit_code\logistic_tracking_system\logistic_tracking_system\lts\views.py", line 6530, in post
    result = json.dumps(result)
  File "C:\Users\zhi.zhou\Anaconda3\envs\lts\lib\json\__init__.py", line 231, in dumps
    return _default_encoder.encode(obj)
  File "C:\Users\zhi.zhou\Anaconda3\envs\lts\lib\json\encoder.py", line 199, in encode
    chunks = self.iterencode(o, _one_shot=True)
  File "C:\Users\zhi.zhou\Anaconda3\envs\lts\lib\json\encoder.py", line 257, in iterencode
    return _iterencode(o, 0)
  File "C:\Users\zhi.zhou\Anaconda3\envs\lts\lib\json\encoder.py", line 180, in default
    o.__class__.__name__)
TypeError: Object of type 'AttributeError' is not JSON serializable
[2021-08-11 15:17:53,815][Thread-2:7144][task_id:django.request][log.py:230][ERROR][Internal Server Error: /logistic/LogisticAddModel]
Traceback (most recent call last):
  File "D:\zhouzhi\gitlit_code\logistic_tracking_system\logistic_tracking_system\lts\views.py", line 6510, in post
    f = request.files['file']
AttributeError: 'WSGIRequest' object has no attribute 'files'

During handling of the above exception, another exception occurred:

Traceback (most recent call last):
  File "C:\Users\zhi.zhou\Anaconda3\envs\lts\lib\site-packages\django\core\handlers\exception.py", line 47, in inner
    response = get_response(request)
  File "C:\Users\zhi.zhou\Anaconda3\envs\lts\lib\site-packages\django\core\handlers\base.py", line 181, in _get_response
    response = wrapped_callback(request, *callback_args, **callback_kwargs)
  File "C:\Users\zhi.zhou\Anaconda3\envs\lts\lib\site-packages\django\views\generic\base.py", line 70, in view
    return self.dispatch(request, *args, **kwargs)
  File "C:\Users\zhi.zhou\Anaconda3\envs\lts\lib\site-packages\django\views\generic\base.py", line 98, in dispatch
    return handler(request, *args, **kwargs)
  File "D:\zhouzhi\gitlit_code\logistic_tracking_system\logistic_tracking_system\lts\views.py", line 6530, in post
    result = json.dumps(result)
  File "C:\Users\zhi.zhou\Anaconda3\envs\lts\lib\json\__init__.py", line 231, in dumps
    return _default_encoder.encode(obj)
  File "C:\Users\zhi.zhou\Anaconda3\envs\lts\lib\json\encoder.py", line 199, in encode
    chunks = self.iterencode(o, _one_shot=True)
  File "C:\Users\zhi.zhou\Anaconda3\envs\lts\lib\json\encoder.py", line 257, in iterencode
    return _iterencode(o, 0)
  File "C:\Users\zhi.zhou\Anaconda3\envs\lts\lib\json\encoder.py", line 180, in default
    o.__class__.__name__)
TypeError: Object of type 'AttributeError' is not JSON serializable
[2021-08-11 15:19:25,185][Thread-3:11532][task_id:django.request][log.py:230][ERROR][Internal Server Error: /logistic/LogisticAddModel]
Traceback (most recent call last):
  File "D:\zhouzhi\gitlit_code\logistic_tracking_system\logistic_tracking_system\lts\views.py", line 6510, in post
    f = request.files['file']
AttributeError: 'WSGIRequest' object has no attribute 'files'

During handling of the above exception, another exception occurred:

Traceback (most recent call last):
  File "C:\Users\zhi.zhou\Anaconda3\envs\lts\lib\site-packages\django\core\handlers\exception.py", line 47, in inner
    response = get_response(request)
  File "C:\Users\zhi.zhou\Anaconda3\envs\lts\lib\site-packages\django\core\handlers\base.py", line 181, in _get_response
    response = wrapped_callback(request, *callback_args, **callback_kwargs)
  File "C:\Users\zhi.zhou\Anaconda3\envs\lts\lib\site-packages\django\views\generic\base.py", line 70, in view
    return self.dispatch(request, *args, **kwargs)
  File "C:\Users\zhi.zhou\Anaconda3\envs\lts\lib\site-packages\django\views\generic\base.py", line 98, in dispatch
    return handler(request, *args, **kwargs)
  File "D:\zhouzhi\gitlit_code\logistic_tracking_system\logistic_tracking_system\lts\views.py", line 6530, in post
    result = json.dumps(result)
  File "C:\Users\zhi.zhou\Anaconda3\envs\lts\lib\json\__init__.py", line 231, in dumps
    return _default_encoder.encode(obj)
  File "C:\Users\zhi.zhou\Anaconda3\envs\lts\lib\json\encoder.py", line 199, in encode
    chunks = self.iterencode(o, _one_shot=True)
  File "C:\Users\zhi.zhou\Anaconda3\envs\lts\lib\json\encoder.py", line 257, in iterencode
    return _iterencode(o, 0)
  File "C:\Users\zhi.zhou\Anaconda3\envs\lts\lib\json\encoder.py", line 180, in default
    o.__class__.__name__)
TypeError: Object of type 'AttributeError' is not JSON serializable
[2021-08-11 15:31:44,910][MainThread:6416][task_id:django.utils.autoreload][autoreload.py:251][INFO][D:\zhouzhi\gitlit_code\logistic_tracking_system\logistic_tracking_system\lts\views.py changed, reloading.]
[2021-08-11 15:31:45,914][MainThread:20732][task_id:django.utils.autoreload][autoreload.py:637][INFO][Watching for file changes with StatReloader]
[2021-08-11 15:31:48,710][MainThread:20732][task_id:django.utils.autoreload][autoreload.py:251][INFO][D:\zhouzhi\gitlit_code\logistic_tracking_system\logistic_tracking_system\utils\print_co2.py changed, reloading.]
[2021-08-11 15:31:49,712][MainThread:21468][task_id:django.utils.autoreload][autoreload.py:637][INFO][Watching for file changes with StatReloader]
[2021-08-11 15:32:46,983][MainThread:21468][task_id:django.utils.autoreload][autoreload.py:251][INFO][D:\zhouzhi\gitlit_code\logistic_tracking_system\logistic_tracking_system\utils\print_co2.py changed, reloading.]
[2021-08-11 15:32:47,979][MainThread:10760][task_id:django.utils.autoreload][autoreload.py:637][INFO][Watching for file changes with StatReloader]
[2021-08-11 15:32:49,535][MainThread:10760][task_id:django.utils.autoreload][autoreload.py:251][INFO][D:\zhouzhi\gitlit_code\logistic_tracking_system\logistic_tracking_system\utils\print_co2.py changed, reloading.]
[2021-08-11 15:32:50,542][MainThread:15448][task_id:django.utils.autoreload][autoreload.py:637][INFO][Watching for file changes with StatReloader]
[2021-08-11 15:38:10,598][Thread-1:21352][task_id:django.request][log.py:230][ERROR][Internal Server Error: /logistic/LogisticAddModel]
Traceback (most recent call last):
  File "D:\zhouzhi\gitlit_code\logistic_tracking_system\logistic_tracking_system\lts\views.py", line 6508, in post
    excit_psth = os.path.join(path_workstation, product_id)
  File "C:\Users\zhi.zhou\Anaconda3\envs\lts\lib\ntpath.py", line 115, in join
    genericpath._check_arg_types('join', path, *paths)
  File "C:\Users\zhi.zhou\Anaconda3\envs\lts\lib\genericpath.py", line 149, in _check_arg_types
    (funcname, s.__class__.__name__)) from None
TypeError: join() argument must be str or bytes, not 'NoneType'

During handling of the above exception, another exception occurred:

Traceback (most recent call last):
  File "C:\Users\zhi.zhou\Anaconda3\envs\lts\lib\site-packages\django\core\handlers\exception.py", line 47, in inner
    response = get_response(request)
  File "C:\Users\zhi.zhou\Anaconda3\envs\lts\lib\site-packages\django\core\handlers\base.py", line 181, in _get_response
    response = wrapped_callback(request, *callback_args, **callback_kwargs)
  File "C:\Users\zhi.zhou\Anaconda3\envs\lts\lib\site-packages\django\views\generic\base.py", line 70, in view
    return self.dispatch(request, *args, **kwargs)
  File "C:\Users\zhi.zhou\Anaconda3\envs\lts\lib\site-packages\django\views\generic\base.py", line 98, in dispatch
    return handler(request, *args, **kwargs)
  File "D:\zhouzhi\gitlit_code\logistic_tracking_system\logistic_tracking_system\lts\views.py", line 6531, in post
    result = json.dumps(result)
  File "C:\Users\zhi.zhou\Anaconda3\envs\lts\lib\json\__init__.py", line 231, in dumps
    return _default_encoder.encode(obj)
  File "C:\Users\zhi.zhou\Anaconda3\envs\lts\lib\json\encoder.py", line 199, in encode
    chunks = self.iterencode(o, _one_shot=True)
  File "C:\Users\zhi.zhou\Anaconda3\envs\lts\lib\json\encoder.py", line 257, in iterencode
    return _iterencode(o, 0)
  File "C:\Users\zhi.zhou\Anaconda3\envs\lts\lib\json\encoder.py", line 180, in default
    o.__class__.__name__)
TypeError: Object of type 'TypeError' is not JSON serializable
[2021-08-11 15:43:44,677][MainThread:15448][task_id:django.utils.autoreload][autoreload.py:251][INFO][D:\zhouzhi\gitlit_code\logistic_tracking_system\logistic_tracking_system\lts\views.py changed, reloading.]
[2021-08-11 15:43:46,256][MainThread:21620][task_id:django.utils.autoreload][autoreload.py:637][INFO][Watching for file changes with StatReloader]
[2021-08-11 15:45:02,861][MainThread:21620][task_id:django.utils.autoreload][autoreload.py:251][INFO][D:\zhouzhi\gitlit_code\logistic_tracking_system\logistic_tracking_system\lts\views.py changed, reloading.]
[2021-08-11 15:45:03,869][MainThread:12752][task_id:django.utils.autoreload][autoreload.py:637][INFO][Watching for file changes with StatReloader]
[2021-08-11 15:46:27,558][MainThread:12752][task_id:django.utils.autoreload][autoreload.py:251][INFO][D:\zhouzhi\gitlit_code\logistic_tracking_system\logistic_tracking_system\lts\views.py changed, reloading.]
[2021-08-11 15:46:28,566][MainThread:15616][task_id:django.utils.autoreload][autoreload.py:637][INFO][Watching for file changes with StatReloader]
[2021-08-11 15:47:03,383][MainThread:15616][task_id:django.utils.autoreload][autoreload.py:251][INFO][D:\zhouzhi\gitlit_code\logistic_tracking_system\logistic_tracking_system\lts\urls.py changed, reloading.]
[2021-08-11 15:47:04,391][MainThread:21416][task_id:django.utils.autoreload][autoreload.py:637][INFO][Watching for file changes with StatReloader]
[2021-08-11 15:47:16,379][MainThread:21416][task_id:django.utils.autoreload][autoreload.py:251][INFO][D:\zhouzhi\gitlit_code\logistic_tracking_system\logistic_tracking_system\lts\urls.py changed, reloading.]
[2021-08-11 15:47:17,393][MainThread:5528][task_id:django.utils.autoreload][autoreload.py:637][INFO][Watching for file changes with StatReloader]
[2021-08-11 15:47:21,508][Thread-1:21024][task_id:django.request][log.py:230][ERROR][Internal Server Error: /logistic/Logistictest2]
Traceback (most recent call last):
  File "C:\Users\zhi.zhou\Anaconda3\envs\lts\lib\site-packages\django\core\handlers\exception.py", line 47, in inner
    response = get_response(request)
  File "C:\Users\zhi.zhou\Anaconda3\envs\lts\lib\site-packages\django\core\handlers\base.py", line 181, in _get_response
    response = wrapped_callback(request, *callback_args, **callback_kwargs)
  File "C:\Users\zhi.zhou\Anaconda3\envs\lts\lib\site-packages\django\views\generic\base.py", line 70, in view
    return self.dispatch(request, *args, **kwargs)
  File "C:\Users\zhi.zhou\Anaconda3\envs\lts\lib\site-packages\django\views\generic\base.py", line 98, in dispatch
    return handler(request, *args, **kwargs)
  File "D:\zhouzhi\gitlit_code\logistic_tracking_system\logistic_tracking_system\lts\views.py", line 6623, in get
    t = test()
TypeError: 'module' object is not callable
[2021-08-11 15:48:53,092][MainThread:5528][task_id:django.utils.autoreload][autoreload.py:251][INFO][D:\zhouzhi\gitlit_code\logistic_tracking_system\logistic_tracking_system\lts\views.py changed, reloading.]
[2021-08-11 15:48:54,234][MainThread:21784][task_id:django.utils.autoreload][autoreload.py:637][INFO][Watching for file changes with StatReloader]
[2021-08-11 15:52:27,585][Thread-2:16276][task_id:django.request][log.py:230][WARNING][Not Found: /favicon.ico]
[2021-08-11 15:52:28,184][Thread-2:16276][task_id:django.request][log.py:230][WARNING][Not Found: /favicon.ico]
[2021-08-11 15:52:28,801][Thread-2:16276][task_id:django.request][log.py:230][WARNING][Not Found: /favicon.ico]
[2021-08-11 15:55:50,852][MainThread:21784][task_id:django.utils.autoreload][autoreload.py:251][INFO][D:\zhouzhi\gitlit_code\logistic_tracking_system\logistic_tracking_system\lts\views.py changed, reloading.]
[2021-08-11 15:55:51,870][MainThread:14920][task_id:django.utils.autoreload][autoreload.py:637][INFO][Watching for file changes with StatReloader]
[2021-08-11 15:55:58,166][Thread-1:4148][task_id:django.request][log.py:230][ERROR][Internal Server Error: /logistic/Logistictest2]
Traceback (most recent call last):
  File "C:\Users\zhi.zhou\Anaconda3\envs\lts\lib\site-packages\django\core\handlers\exception.py", line 47, in inner
    response = get_response(request)
  File "C:\Users\zhi.zhou\Anaconda3\envs\lts\lib\site-packages\django\core\handlers\base.py", line 181, in _get_response
    response = wrapped_callback(request, *callback_args, **callback_kwargs)
  File "C:\Users\zhi.zhou\Anaconda3\envs\lts\lib\site-packages\django\views\generic\base.py", line 70, in view
    return self.dispatch(request, *args, **kwargs)
  File "C:\Users\zhi.zhou\Anaconda3\envs\lts\lib\site-packages\django\views\generic\base.py", line 98, in dispatch
    return handler(request, *args, **kwargs)
  File "D:\zhouzhi\gitlit_code\logistic_tracking_system\logistic_tracking_system\lts\views.py", line 6623, in get
    t = test.test()
NameError: name 'test' is not defined
[2021-08-11 16:01:42,463][MainThread:14920][task_id:django.utils.autoreload][autoreload.py:251][INFO][D:\zhouzhi\gitlit_code\logistic_tracking_system\logistic_tracking_system\lts\views.py changed, reloading.]
[2021-08-11 16:01:43,493][MainThread:20116][task_id:django.utils.autoreload][autoreload.py:637][INFO][Watching for file changes with StatReloader]
[2021-08-11 16:02:35,152][MainThread:20116][task_id:django.utils.autoreload][autoreload.py:251][INFO][D:\zhouzhi\gitlit_code\logistic_tracking_system\logistic_tracking_system\lts\views.py changed, reloading.]
[2021-08-11 16:02:36,171][MainThread:8740][task_id:django.utils.autoreload][autoreload.py:637][INFO][Watching for file changes with StatReloader]
[2021-08-11 16:16:39,922][MainThread:8740][task_id:django.utils.autoreload][autoreload.py:251][INFO][D:\zhouzhi\gitlit_code\logistic_tracking_system\logistic_tracking_system\lts\urls.py changed, reloading.]
[2021-08-11 16:16:41,608][MainThread:23076][task_id:django.utils.autoreload][autoreload.py:637][INFO][Watching for file changes with StatReloader]
[2021-08-11 16:17:02,716][MainThread:23076][task_id:django.utils.autoreload][autoreload.py:251][INFO][D:\zhouzhi\gitlit_code\logistic_tracking_system\logistic_tracking_system\utils\print_co2.py changed, reloading.]
[2021-08-11 16:17:03,739][MainThread:21148][task_id:django.utils.autoreload][autoreload.py:637][INFO][Watching for file changes with StatReloader]
[2021-08-11 16:17:11,913][MainThread:21148][task_id:django.utils.autoreload][autoreload.py:251][INFO][D:\zhouzhi\gitlit_code\logistic_tracking_system\logistic_tracking_system\utils\print_co2.py changed, reloading.]
[2021-08-11 16:17:12,919][MainThread:22172][task_id:django.utils.autoreload][autoreload.py:637][INFO][Watching for file changes with StatReloader]
[2021-08-11 16:19:31,081][MainThread:22172][task_id:django.utils.autoreload][autoreload.py:251][INFO][D:\zhouzhi\gitlit_code\logistic_tracking_system\logistic_tracking_system\lts\views.py changed, reloading.]
[2021-08-11 16:19:32,254][MainThread:19056][task_id:django.utils.autoreload][autoreload.py:637][INFO][Watching for file changes with StatReloader]
[2021-08-11 16:20:01,952][MainThread:19056][task_id:django.utils.autoreload][autoreload.py:251][INFO][D:\zhouzhi\gitlit_code\logistic_tracking_system\logistic_tracking_system\utils\print_co2.py changed, reloading.]
[2021-08-11 16:20:02,962][MainThread:17100][task_id:django.utils.autoreload][autoreload.py:637][INFO][Watching for file changes with StatReloader]
[2021-08-11 16:21:21,292][MainThread:17100][task_id:django.utils.autoreload][autoreload.py:251][INFO][D:\zhouzhi\gitlit_code\logistic_tracking_system\logistic_tracking_system\utils\print_co2.py changed, reloading.]
[2021-08-11 16:21:22,306][MainThread:3628][task_id:django.utils.autoreload][autoreload.py:637][INFO][Watching for file changes with StatReloader]
[2021-08-11 16:21:27,305][MainThread:3628][task_id:django.utils.autoreload][autoreload.py:251][INFO][D:\zhouzhi\gitlit_code\logistic_tracking_system\logistic_tracking_system\utils\print_co2.py changed, reloading.]
[2021-08-11 16:21:28,314][MainThread:20816][task_id:django.utils.autoreload][autoreload.py:637][INFO][Watching for file changes with StatReloader]
[2021-08-11 16:21:46,273][MainThread:20816][task_id:django.utils.autoreload][autoreload.py:251][INFO][D:\zhouzhi\gitlit_code\logistic_tracking_system\logistic_tracking_system\utils\print_co2.py changed, reloading.]
[2021-08-11 16:21:47,285][MainThread:11692][task_id:django.utils.autoreload][autoreload.py:637][INFO][Watching for file changes with StatReloader]
[2021-08-11 16:22:37,176][MainThread:11692][task_id:django.utils.autoreload][autoreload.py:251][INFO][D:\zhouzhi\gitlit_code\logistic_tracking_system\logistic_tracking_system\utils\print_co2.py changed, reloading.]
[2021-08-11 16:22:38,208][MainThread:2576][task_id:django.utils.autoreload][autoreload.py:637][INFO][Watching for file changes with StatReloader]
[2021-08-11 16:22:56,148][Thread-1:23284][task_id:django.request][base.py:103][WARNING][Method Not Allowed (GET): /logistic/LogisticAddModel]
[2021-08-11 16:22:56,149][Thread-1:23284][task_id:django.request][log.py:230][WARNING][Method Not Allowed: /logistic/LogisticAddModel]
[2021-08-11 16:23:10,697][Thread-1:23284][task_id:lts.views][views.py:6019][ERROR][查询物料信息失败,(1046, 'No database selected')]
[2021-08-11 16:23:23,949][MainThread:2576][task_id:django.utils.autoreload][autoreload.py:251][INFO][D:\zhouzhi\gitlit_code\logistic_tracking_system\logistic_tracking_system\utils\print_co2.py changed, reloading.]
[2021-08-11 16:23:25,004][MainThread:21108][task_id:django.utils.autoreload][autoreload.py:637][INFO][Watching for file changes with StatReloader]
[2021-08-11 16:24:27,796][MainThread:21108][task_id:django.utils.autoreload][autoreload.py:251][INFO][D:\zhouzhi\gitlit_code\logistic_tracking_system\logistic_tracking_system\lts\views.py changed, reloading.]
[2021-08-11 16:24:28,803][MainThread:19920][task_id:django.utils.autoreload][autoreload.py:637][INFO][Watching for file changes with StatReloader]
[2021-08-11 16:25:20,429][MainThread:19920][task_id:django.utils.autoreload][autoreload.py:251][INFO][D:\zhouzhi\gitlit_code\logistic_tracking_system\logistic_tracking_system\lts\views.py changed, reloading.]
[2021-08-11 16:25:21,548][MainThread:2452][task_id:django.utils.autoreload][autoreload.py:637][INFO][Watching for file changes with StatReloader]
[2021-08-11 16:26:13,862][MainThread:2452][task_id:django.utils.autoreload][autoreload.py:251][INFO][D:\zhouzhi\gitlit_code\logistic_tracking_system\logistic_tracking_system\lts\views.py changed, reloading.]
[2021-08-11 16:26:14,912][MainThread:21636][task_id:django.utils.autoreload][autoreload.py:637][INFO][Watching for file changes with StatReloader]
[2021-08-11 16:26:18,786][MainThread:21636][task_id:django.utils.autoreload][autoreload.py:251][INFO][D:\zhouzhi\gitlit_code\logistic_tracking_system\logistic_tracking_system\utils\print_co2.py changed, reloading.]
[2021-08-11 16:26:19,805][MainThread:2632][task_id:django.utils.autoreload][autoreload.py:637][INFO][Watching for file changes with StatReloader]
[2021-08-11 16:27:11,981][MainThread:2632][task_id:django.utils.autoreload][autoreload.py:251][INFO][D:\zhouzhi\gitlit_code\logistic_tracking_system\logistic_tracking_system\lts\views.py changed, reloading.]
[2021-08-11 16:27:13,002][MainThread:9672][task_id:django.utils.autoreload][autoreload.py:637][INFO][Watching for file changes with StatReloader]
[2021-08-11 16:27:17,301][Thread-1:22584][task_id:django.request][log.py:230][ERROR][Internal Server Error: /logistic/Logistictest]
Traceback (most recent call last):
  File "D:\zhouzhi\gitlit_code\logistic_tracking_system\logistic_tracking_system\lts\views.py", line 6615, in get
    f.pen()
AttributeError: 'test11' object has no attribute 'pen'

During handling of the above exception, another exception occurred:

Traceback (most recent call last):
  File "C:\Users\zhi.zhou\Anaconda3\envs\lts\lib\site-packages\django\core\handlers\exception.py", line 47, in inner
    response = get_response(request)
  File "C:\Users\zhi.zhou\Anaconda3\envs\lts\lib\site-packages\django\core\handlers\base.py", line 181, in _get_response
    response = wrapped_callback(request, *callback_args, **callback_kwargs)
  File "C:\Users\zhi.zhou\Anaconda3\envs\lts\lib\site-packages\django\views\generic\base.py", line 70, in view
    return self.dispatch(request, *args, **kwargs)
  File "C:\Users\zhi.zhou\Anaconda3\envs\lts\lib\site-packages\django\views\generic\base.py", line 98, in dispatch
    return handler(request, *args, **kwargs)
  File "D:\zhouzhi\gitlit_code\logistic_tracking_system\logistic_tracking_system\lts\views.py", line 6627, in get
    result = json.dumps(result)
  File "C:\Users\zhi.zhou\Anaconda3\envs\lts\lib\json\__init__.py", line 231, in dumps
    return _default_encoder.encode(obj)
  File "C:\Users\zhi.zhou\Anaconda3\envs\lts\lib\json\encoder.py", line 199, in encode
    chunks = self.iterencode(o, _one_shot=True)
  File "C:\Users\zhi.zhou\Anaconda3\envs\lts\lib\json\encoder.py", line 257, in iterencode
    return _iterencode(o, 0)
  File "C:\Users\zhi.zhou\Anaconda3\envs\lts\lib\json\encoder.py", line 180, in default
    o.__class__.__name__)
TypeError: Object of type 'AttributeError' is not JSON serializable
[2021-08-11 16:27:17,955][MainThread:9672][task_id:django.utils.autoreload][autoreload.py:251][INFO][D:\zhouzhi\gitlit_code\logistic_tracking_system\logistic_tracking_system\utils\print_co2.py changed, reloading.]
[2021-08-11 16:27:18,960][MainThread:16244][task_id:django.utils.autoreload][autoreload.py:637][INFO][Watching for file changes with StatReloader]
[2021-08-11 16:27:27,142][Thread-1:19252][task_id:django.request][log.py:230][ERROR][Internal Server Error: /logistic/Logistictest]
Traceback (most recent call last):
  File "D:\zhouzhi\gitlit_code\logistic_tracking_system\logistic_tracking_system\lts\views.py", line 6615, in get
    f.pen()
AttributeError: 'test11' object has no attribute 'pen'

During handling of the above exception, another exception occurred:

Traceback (most recent call last):
  File "C:\Users\zhi.zhou\Anaconda3\envs\lts\lib\site-packages\django\core\handlers\exception.py", line 47, in inner
    response = get_response(request)
  File "C:\Users\zhi.zhou\Anaconda3\envs\lts\lib\site-packages\django\core\handlers\base.py", line 181, in _get_response
    response = wrapped_callback(request, *callback_args, **callback_kwargs)
  File "C:\Users\zhi.zhou\Anaconda3\envs\lts\lib\site-packages\django\views\generic\base.py", line 70, in view
    return self.dispatch(request, *args, **kwargs)
  File "C:\Users\zhi.zhou\Anaconda3\envs\lts\lib\site-packages\django\views\generic\base.py", line 98, in dispatch
    return handler(request, *args, **kwargs)
  File "D:\zhouzhi\gitlit_code\logistic_tracking_system\logistic_tracking_system\lts\views.py", line 6627, in get
    result = json.dumps(result)
  File "C:\Users\zhi.zhou\Anaconda3\envs\lts\lib\json\__init__.py", line 231, in dumps
    return _default_encoder.encode(obj)
  File "C:\Users\zhi.zhou\Anaconda3\envs\lts\lib\json\encoder.py", line 199, in encode
    chunks = self.iterencode(o, _one_shot=True)
  File "C:\Users\zhi.zhou\Anaconda3\envs\lts\lib\json\encoder.py", line 257, in iterencode
    return _iterencode(o, 0)
  File "C:\Users\zhi.zhou\Anaconda3\envs\lts\lib\json\encoder.py", line 180, in default
    o.__class__.__name__)
TypeError: Object of type 'AttributeError' is not JSON serializable
[2021-08-11 16:27:28,183][MainThread:16244][task_id:django.utils.autoreload][autoreload.py:251][INFO][D:\zhouzhi\gitlit_code\logistic_tracking_system\logistic_tracking_system\utils\print_co2.py changed, reloading.]
[2021-08-11 16:27:29,191][MainThread:21628][task_id:django.utils.autoreload][autoreload.py:637][INFO][Watching for file changes with StatReloader]
[2021-08-11 16:27:57,597][MainThread:21628][task_id:django.utils.autoreload][autoreload.py:251][INFO][D:\zhouzhi\gitlit_code\logistic_tracking_system\logistic_tracking_system\lts\views.py changed, reloading.]
[2021-08-11 16:27:58,622][MainThread:23428][task_id:django.utils.autoreload][autoreload.py:637][INFO][Watching for file changes with StatReloader]
[2021-08-11 16:28:00,567][Thread-1:21764][task_id:django.request][log.py:230][ERROR][Internal Server Error: /logistic/Logistictest]
Traceback (most recent call last):
  File "D:\zhouzhi\gitlit_code\logistic_tracking_system\logistic_tracking_system\lts\views.py", line 6615, in get
    f.pen()
AttributeError: 'test11' object has no attribute 'pen'

During handling of the above exception, another exception occurred:

Traceback (most recent call last):
  File "C:\Users\zhi.zhou\Anaconda3\envs\lts\lib\site-packages\django\core\handlers\exception.py", line 47, in inner
    response = get_response(request)
  File "C:\Users\zhi.zhou\Anaconda3\envs\lts\lib\site-packages\django\core\handlers\base.py", line 181, in _get_response
    response = wrapped_callback(request, *callback_args, **callback_kwargs)
  File "C:\Users\zhi.zhou\Anaconda3\envs\lts\lib\site-packages\django\views\generic\base.py", line 70, in view
    return self.dispatch(request, *args, **kwargs)
  File "C:\Users\zhi.zhou\Anaconda3\envs\lts\lib\site-packages\django\views\generic\base.py", line 98, in dispatch
    return handler(request, *args, **kwargs)
  File "D:\zhouzhi\gitlit_code\logistic_tracking_system\logistic_tracking_system\lts\views.py", line 6627, in get
    result = json.dumps(result)
  File "C:\Users\zhi.zhou\Anaconda3\envs\lts\lib\json\__init__.py", line 231, in dumps
    return _default_encoder.encode(obj)
  File "C:\Users\zhi.zhou\Anaconda3\envs\lts\lib\json\encoder.py", line 199, in encode
    chunks = self.iterencode(o, _one_shot=True)
  File "C:\Users\zhi.zhou\Anaconda3\envs\lts\lib\json\encoder.py", line 257, in iterencode
    return _iterencode(o, 0)
  File "C:\Users\zhi.zhou\Anaconda3\envs\lts\lib\json\encoder.py", line 180, in default
    o.__class__.__name__)
TypeError: Object of type 'AttributeError' is not JSON serializable
[2021-08-11 16:28:01,405][MainThread:23428][task_id:django.utils.autoreload][autoreload.py:251][INFO][D:\zhouzhi\gitlit_code\logistic_tracking_system\logistic_tracking_system\utils\print_co2.py changed, reloading.]
[2021-08-11 16:28:02,413][MainThread:22892][task_id:django.utils.autoreload][autoreload.py:637][INFO][Watching for file changes with StatReloader]
[2021-08-11 16:30:53,401][MainThread:22892][task_id:django.utils.autoreload][autoreload.py:251][INFO][D:\zhouzhi\gitlit_code\logistic_tracking_system\logistic_tracking_system\lts\views.py changed, reloading.]
[2021-08-11 16:30:54,949][MainThread:22080][task_id:django.utils.autoreload][autoreload.py:637][INFO][Watching for file changes with StatReloader]
[2021-08-11 16:30:58,754][Thread-1:7764][task_id:django.request][log.py:230][ERROR][Internal Server Error: /logistic/Logistictest]
Traceback (most recent call last):
  File "D:\zhouzhi\gitlit_code\logistic_tracking_system\logistic_tracking_system\lts\views.py", line 6620, in get
    opt.install_one()
TypeError: install_one() missing 1 required positional argument: 'self'

During handling of the above exception, another exception occurred:

Traceback (most recent call last):
  File "C:\Users\zhi.zhou\Anaconda3\envs\lts\lib\site-packages\django\core\handlers\exception.py", line 47, in inner
    response = get_response(request)
  File "C:\Users\zhi.zhou\Anaconda3\envs\lts\lib\site-packages\django\core\handlers\base.py", line 181, in _get_response
    response = wrapped_callback(request, *callback_args, **callback_kwargs)
  File "C:\Users\zhi.zhou\Anaconda3\envs\lts\lib\site-packages\django\views\generic\base.py", line 70, in view
    return self.dispatch(request, *args, **kwargs)
  File "C:\Users\zhi.zhou\Anaconda3\envs\lts\lib\site-packages\django\views\generic\base.py", line 98, in dispatch
    return handler(request, *args, **kwargs)
  File "D:\zhouzhi\gitlit_code\logistic_tracking_system\logistic_tracking_system\lts\views.py", line 6629, in get
    result = json.dumps(result)
  File "C:\Users\zhi.zhou\Anaconda3\envs\lts\lib\json\__init__.py", line 231, in dumps
    return _default_encoder.encode(obj)
  File "C:\Users\zhi.zhou\Anaconda3\envs\lts\lib\json\encoder.py", line 199, in encode
    chunks = self.iterencode(o, _one_shot=True)
  File "C:\Users\zhi.zhou\Anaconda3\envs\lts\lib\json\encoder.py", line 257, in iterencode
    return _iterencode(o, 0)
  File "C:\Users\zhi.zhou\Anaconda3\envs\lts\lib\json\encoder.py", line 180, in default
    o.__class__.__name__)
TypeError: Object of type 'TypeError' is not JSON serializable
[2021-08-11 16:31:15,280][MainThread:22080][task_id:django.utils.autoreload][autoreload.py:251][INFO][D:\zhouzhi\gitlit_code\logistic_tracking_system\logistic_tracking_system\lts\views.py changed, reloading.]
[2021-08-11 16:31:16,602][MainThread:5428][task_id:django.utils.autoreload][autoreload.py:637][INFO][Watching for file changes with StatReloader]
[2021-08-11 16:32:27,070][MainThread:5428][task_id:django.utils.autoreload][autoreload.py:251][INFO][D:\zhouzhi\gitlit_code\logistic_tracking_system\logistic_tracking_system\lts\views.py changed, reloading.]
[2021-08-11 16:32:28,086][MainThread:23108][task_id:django.utils.autoreload][autoreload.py:637][INFO][Watching for file changes with StatReloader]
[2021-08-11 16:32:32,878][MainThread:23108][task_id:django.utils.autoreload][autoreload.py:251][INFO][D:\zhouzhi\gitlit_code\logistic_tracking_system\logistic_tracking_system\lts\views.py changed, reloading.]
[2021-08-11 16:32:33,890][MainThread:19748][task_id:django.utils.autoreload][autoreload.py:637][INFO][Watching for file changes with StatReloader]
[2021-08-11 16:32:35,861][Thread-1:22876][task_id:django.request][log.py:230][ERROR][Internal Server Error: /logistic/Logistictest]
Traceback (most recent call last):
  File "D:\zhouzhi\gitlit_code\logistic_tracking_system\logistic_tracking_system\lts\views.py", line 6615, in get
    test11.pen(self)
AttributeError: type object 'test11' has no attribute 'pen'

During handling of the above exception, another exception occurred:

Traceback (most recent call last):
  File "C:\Users\zhi.zhou\Anaconda3\envs\lts\lib\site-packages\django\core\handlers\exception.py", line 47, in inner
    response = get_response(request)
  File "C:\Users\zhi.zhou\Anaconda3\envs\lts\lib\site-packages\django\core\handlers\base.py", line 181, in _get_response
    response = wrapped_callback(request, *callback_args, **callback_kwargs)
  File "C:\Users\zhi.zhou\Anaconda3\envs\lts\lib\site-packages\django\views\generic\base.py", line 70, in view
    return self.dispatch(request, *args, **kwargs)
  File "C:\Users\zhi.zhou\Anaconda3\envs\lts\lib\site-packages\django\views\generic\base.py", line 98, in dispatch
    return handler(request, *args, **kwargs)
  File "D:\zhouzhi\gitlit_code\logistic_tracking_system\logistic_tracking_system\lts\views.py", line 6628, in get
    result = json.dumps(result)
  File "C:\Users\zhi.zhou\Anaconda3\envs\lts\lib\json\__init__.py", line 231, in dumps
    return _default_encoder.encode(obj)
  File "C:\Users\zhi.zhou\Anaconda3\envs\lts\lib\json\encoder.py", line 199, in encode
    chunks = self.iterencode(o, _one_shot=True)
  File "C:\Users\zhi.zhou\Anaconda3\envs\lts\lib\json\encoder.py", line 257, in iterencode
    return _iterencode(o, 0)
  File "C:\Users\zhi.zhou\Anaconda3\envs\lts\lib\json\encoder.py", line 180, in default
    o.__class__.__name__)
TypeError: Object of type 'AttributeError' is not JSON serializable
[2021-08-11 16:32:36,709][MainThread:19748][task_id:django.utils.autoreload][autoreload.py:251][INFO][D:\zhouzhi\gitlit_code\logistic_tracking_system\logistic_tracking_system\utils\print_co2.py changed, reloading.]
[2021-08-11 16:32:37,706][MainThread:22432][task_id:django.utils.autoreload][autoreload.py:637][INFO][Watching for file changes with StatReloader]
[2021-08-11 16:34:47,246][MainThread:22432][task_id:django.utils.autoreload][autoreload.py:251][INFO][D:\zhouzhi\gitlit_code\logistic_tracking_system\logistic_tracking_system\utils\print_co2.py changed, reloading.]
[2021-08-11 16:34:48,261][MainThread:8468][task_id:django.utils.autoreload][autoreload.py:637][INFO][Watching for file changes with StatReloader]
[2021-08-11 16:34:55,358][Thread-1:17792][task_id:django.request][log.py:230][ERROR][Internal Server Error: /logistic/Logistictest2]
Traceback (most recent call last):
  File "C:\Users\zhi.zhou\Anaconda3\envs\lts\lib\site-packages\django\core\handlers\exception.py", line 47, in inner
    response = get_response(request)
  File "C:\Users\zhi.zhou\Anaconda3\envs\lts\lib\site-packages\django\core\handlers\base.py", line 181, in _get_response
    response = wrapped_callback(request, *callback_args, **callback_kwargs)
  File "C:\Users\zhi.zhou\Anaconda3\envs\lts\lib\site-packages\django\views\generic\base.py", line 70, in view
    return self.dispatch(request, *args, **kwargs)
  File "C:\Users\zhi.zhou\Anaconda3\envs\lts\lib\site-packages\django\views\generic\base.py", line 98, in dispatch
    return handler(request, *args, **kwargs)
  File "D:\zhouzhi\gitlit_code\logistic_tracking_system\logistic_tracking_system\lts\views.py", line 6630, in get
    test11.pen(self)
AttributeError: type object 'test11' has no attribute 'pen'
[2021-08-11 16:35:33,211][MainThread:8468][task_id:django.utils.autoreload][autoreload.py:251][INFO][D:\zhouzhi\gitlit_code\logistic_tracking_system\logistic_tracking_system\utils\print_co2.py changed, reloading.]
[2021-08-11 16:35:34,234][MainThread:19860][task_id:django.utils.autoreload][autoreload.py:637][INFO][Watching for file changes with StatReloader]
[2021-08-11 16:35:56,158][MainThread:19860][task_id:django.utils.autoreload][autoreload.py:251][INFO][D:\zhouzhi\gitlit_code\logistic_tracking_system\logistic_tracking_system\utils\print_co2.py changed, reloading.]
[2021-08-11 16:35:57,180][MainThread:21360][task_id:django.utils.autoreload][autoreload.py:637][INFO][Watching for file changes with StatReloader]
[2021-08-11 16:36:00,820][Thread-1:620][task_id:django.request][log.py:230][ERROR][Internal Server Error: /logistic/Logistictest2]
Traceback (most recent call last):
  File "C:\Users\zhi.zhou\Anaconda3\envs\lts\lib\site-packages\django\core\handlers\exception.py", line 47, in inner
    response = get_response(request)
  File "C:\Users\zhi.zhou\Anaconda3\envs\lts\lib\site-packages\django\core\handlers\base.py", line 181, in _get_response
    response = wrapped_callback(request, *callback_args, **callback_kwargs)
  File "C:\Users\zhi.zhou\Anaconda3\envs\lts\lib\site-packages\django\views\generic\base.py", line 70, in view
    return self.dispatch(request, *args, **kwargs)
  File "C:\Users\zhi.zhou\Anaconda3\envs\lts\lib\site-packages\django\views\generic\base.py", line 98, in dispatch
    return handler(request, *args, **kwargs)
  File "D:\zhouzhi\gitlit_code\logistic_tracking_system\logistic_tracking_system\lts\views.py", line 6630, in get
    test11.pen(self)
AttributeError: type object 'test11' has no attribute 'pen'
[2021-08-11 16:36:55,873][MainThread:21360][task_id:django.utils.autoreload][autoreload.py:251][INFO][D:\zhouzhi\gitlit_code\logistic_tracking_system\logistic_tracking_system\utils\print_co2.py changed, reloading.]
[2021-08-11 16:36:56,892][MainThread:5460][task_id:django.utils.autoreload][autoreload.py:637][INFO][Watching for file changes with StatReloader]
[2021-08-11 16:38:21,908][MainThread:5460][task_id:django.utils.autoreload][autoreload.py:251][INFO][D:\zhouzhi\gitlit_code\logistic_tracking_system\logistic_tracking_system\utils\print_co2.py changed, reloading.]
[2021-08-11 16:38:23,410][MainThread:17252][task_id:django.utils.autoreload][autoreload.py:637][INFO][Watching for file changes with StatReloader]
[2021-08-11 16:38:36,642][Thread-1:23496][task_id:django.request][log.py:230][ERROR][Internal Server Error: /logistic/Logistictest]
Traceback (most recent call last):
  File "D:\zhouzhi\gitlit_code\logistic_tracking_system\logistic_tracking_system\lts\views.py", line 6614, in get
    test11.pen(self)
AttributeError: type object 'test11' has no attribute 'pen'

During handling of the above exception, another exception occurred:

Traceback (most recent call last):
  File "C:\Users\zhi.zhou\Anaconda3\envs\lts\lib\site-packages\django\core\handlers\exception.py", line 47, in inner
    response = get_response(request)
  File "C:\Users\zhi.zhou\Anaconda3\envs\lts\lib\site-packages\django\core\handlers\base.py", line 181, in _get_response
    response = wrapped_callback(request, *callback_args, **callback_kwargs)
  File "C:\Users\zhi.zhou\Anaconda3\envs\lts\lib\site-packages\django\views\generic\base.py", line 70, in view
    return self.dispatch(request, *args, **kwargs)
  File "C:\Users\zhi.zhou\Anaconda3\envs\lts\lib\site-packages\django\views\generic\base.py", line 98, in dispatch
    return handler(request, *args, **kwargs)
  File "D:\zhouzhi\gitlit_code\logistic_tracking_system\logistic_tracking_system\lts\views.py", line 6628, in get
    result = json.dumps(result)
  File "C:\Users\zhi.zhou\Anaconda3\envs\lts\lib\json\__init__.py", line 231, in dumps
    return _default_encoder.encode(obj)
  File "C:\Users\zhi.zhou\Anaconda3\envs\lts\lib\json\encoder.py", line 199, in encode
    chunks = self.iterencode(o, _one_shot=True)
  File "C:\Users\zhi.zhou\Anaconda3\envs\lts\lib\json\encoder.py", line 257, in iterencode
    return _iterencode(o, 0)
  File "C:\Users\zhi.zhou\Anaconda3\envs\lts\lib\json\encoder.py", line 180, in default
    o.__class__.__name__)
TypeError: Object of type 'AttributeError' is not JSON serializable
[2021-08-11 16:38:37,029][MainThread:17252][task_id:django.utils.autoreload][autoreload.py:251][INFO][D:\zhouzhi\gitlit_code\logistic_tracking_system\logistic_tracking_system\utils\print_co2.py changed, reloading.]
[2021-08-11 16:38:38,028][MainThread:7320][task_id:django.utils.autoreload][autoreload.py:637][INFO][Watching for file changes with StatReloader]
[2021-08-11 16:39:04,603][MainThread:7320][task_id:django.utils.autoreload][autoreload.py:251][INFO][D:\zhouzhi\gitlit_code\logistic_tracking_system\logistic_tracking_system\utils\print_co2.py changed, reloading.]
[2021-08-11 16:39:05,631][MainThread:3984][task_id:django.utils.autoreload][autoreload.py:637][INFO][Watching for file changes with StatReloader]
[2021-08-11 16:39:19,894][Thread-1:8644][task_id:django.request][log.py:230][ERROR][Internal Server Error: /logistic/Logistictest]
Traceback (most recent call last):
  File "D:\zhouzhi\gitlit_code\logistic_tracking_system\logistic_tracking_system\lts\views.py", line 6614, in get
    test11.pen(self)
AttributeError: type object 'test11' has no attribute 'pen'

During handling of the above exception, another exception occurred:

Traceback (most recent call last):
  File "C:\Users\zhi.zhou\Anaconda3\envs\lts\lib\site-packages\django\core\handlers\exception.py", line 47, in inner
    response = get_response(request)
  File "C:\Users\zhi.zhou\Anaconda3\envs\lts\lib\site-packages\django\core\handlers\base.py", line 181, in _get_response
    response = wrapped_callback(request, *callback_args, **callback_kwargs)
  File "C:\Users\zhi.zhou\Anaconda3\envs\lts\lib\site-packages\django\views\generic\base.py", line 70, in view
    return self.dispatch(request, *args, **kwargs)
  File "C:\Users\zhi.zhou\Anaconda3\envs\lts\lib\site-packages\django\views\generic\base.py", line 98, in dispatch
    return handler(request, *args, **kwargs)
  File "D:\zhouzhi\gitlit_code\logistic_tracking_system\logistic_tracking_system\lts\views.py", line 6628, in get
    result = json.dumps(result)
  File "C:\Users\zhi.zhou\Anaconda3\envs\lts\lib\json\__init__.py", line 231, in dumps
    return _default_encoder.encode(obj)
  File "C:\Users\zhi.zhou\Anaconda3\envs\lts\lib\json\encoder.py", line 199, in encode
    chunks = self.iterencode(o, _one_shot=True)
  File "C:\Users\zhi.zhou\Anaconda3\envs\lts\lib\json\encoder.py", line 257, in iterencode
    return _iterencode(o, 0)
  File "C:\Users\zhi.zhou\Anaconda3\envs\lts\lib\json\encoder.py", line 180, in default
    o.__class__.__name__)
TypeError: Object of type 'AttributeError' is not JSON serializable
[2021-08-11 16:39:20,213][MainThread:3984][task_id:django.utils.autoreload][autoreload.py:251][INFO][D:\zhouzhi\gitlit_code\logistic_tracking_system\logistic_tracking_system\utils\print_co2.py changed, reloading.]
[2021-08-11 16:39:21,228][MainThread:4640][task_id:django.utils.autoreload][autoreload.py:637][INFO][Watching for file changes with StatReloader]
[2021-08-11 16:41:12,408][MainThread:4640][task_id:django.utils.autoreload][autoreload.py:251][INFO][D:\zhouzhi\gitlit_code\logistic_tracking_system\logistic_tracking_system\lts\views.py changed, reloading.]
[2021-08-11 16:41:13,429][MainThread:20416][task_id:django.utils.autoreload][autoreload.py:637][INFO][Watching for file changes with StatReloader]
[2021-08-11 16:53:03,305][MainThread:20416][task_id:django.utils.autoreload][autoreload.py:251][INFO][D:\zhouzhi\gitlit_code\logistic_tracking_system\logistic_tracking_system\lts\views.py changed, reloading.]
[2021-08-11 16:53:04,338][MainThread:15452][task_id:django.utils.autoreload][autoreload.py:637][INFO][Watching for file changes with StatReloader]
[2021-08-11 16:53:43,571][MainThread:15452][task_id:django.utils.autoreload][autoreload.py:251][INFO][D:\zhouzhi\gitlit_code\logistic_tracking_system\logistic_tracking_system\lts\views.py changed, reloading.]
[2021-08-11 16:53:44,686][MainThread:23244][task_id:django.utils.autoreload][autoreload.py:637][INFO][Watching for file changes with StatReloader]
[2021-08-11 17:09:05,401][MainThread:23244][task_id:django.utils.autoreload][autoreload.py:251][INFO][D:\zhouzhi\gitlit_code\logistic_tracking_system\logistic_tracking_system\lts\views.py changed, reloading.]
[2021-08-11 17:09:06,429][MainThread:7780][task_id:django.utils.autoreload][autoreload.py:637][INFO][Watching for file changes with StatReloader]
[2021-08-11 17:10:14,897][MainThread:7780][task_id:django.utils.autoreload][autoreload.py:251][INFO][D:\zhouzhi\gitlit_code\logistic_tracking_system\logistic_tracking_system\lts\views.py changed, reloading.]
[2021-08-11 17:10:15,940][MainThread:24040][task_id:django.utils.autoreload][autoreload.py:637][INFO][Watching for file changes with StatReloader]
[2021-08-11 17:11:15,135][MainThread:24040][task_id:django.utils.autoreload][autoreload.py:251][INFO][D:\zhouzhi\gitlit_code\logistic_tracking_system\logistic_tracking_system\lts\views.py changed, reloading.]
[2021-08-11 17:11:16,151][MainThread:21340][task_id:django.utils.autoreload][autoreload.py:637][INFO][Watching for file changes with StatReloader]
[2021-08-11 17:11:47,247][MainThread:21340][task_id:django.utils.autoreload][autoreload.py:251][INFO][D:\zhouzhi\gitlit_code\logistic_tracking_system\logistic_tracking_system\lts\views.py changed, reloading.]
[2021-08-11 17:11:48,536][MainThread:24020][task_id:django.utils.autoreload][autoreload.py:637][INFO][Watching for file changes with StatReloader]
[2021-08-11 17:20:08,123][MainThread:24020][task_id:django.utils.autoreload][autoreload.py:251][INFO][D:\zhouzhi\gitlit_code\logistic_tracking_system\logistic_tracking_system\lts\views.py changed, reloading.]
[2021-08-11 17:20:09,651][MainThread:2680][task_id:django.utils.autoreload][autoreload.py:637][INFO][Watching for file changes with StatReloader]
[2021-08-11 17:20:47,989][MainThread:2680][task_id:django.utils.autoreload][autoreload.py:251][INFO][D:\zhouzhi\gitlit_code\logistic_tracking_system\logistic_tracking_system\lts\views.py changed, reloading.]
[2021-08-11 17:20:49,132][MainThread:20300][task_id:django.utils.autoreload][autoreload.py:637][INFO][Watching for file changes with StatReloader]
[2021-08-11 17:21:00,208][MainThread:20300][task_id:django.utils.autoreload][autoreload.py:251][INFO][D:\zhouzhi\gitlit_code\logistic_tracking_system\logistic_tracking_system\lts\views.py changed, reloading.]
[2021-08-11 17:21:01,611][MainThread:19692][task_id:django.utils.autoreload][autoreload.py:637][INFO][Watching for file changes with StatReloader]
[2021-08-11 17:21:07,233][MainThread:19692][task_id:django.utils.autoreload][autoreload.py:251][INFO][D:\zhouzhi\gitlit_code\logistic_tracking_system\logistic_tracking_system\lts\views.py changed, reloading.]
[2021-08-11 17:21:08,491][MainThread:23064][task_id:django.utils.autoreload][autoreload.py:637][INFO][Watching for file changes with StatReloader]
[2021-08-11 17:21:10,962][MainThread:23064][task_id:django.utils.autoreload][autoreload.py:251][INFO][D:\zhouzhi\gitlit_code\logistic_tracking_system\logistic_tracking_system\lts\views.py changed, reloading.]
[2021-08-11 17:21:12,215][MainThread:15564][task_id:django.utils.autoreload][autoreload.py:637][INFO][Watching for file changes with StatReloader]
[2021-08-11 17:21:13,562][MainThread:15564][task_id:django.utils.autoreload][autoreload.py:251][INFO][D:\zhouzhi\gitlit_code\logistic_tracking_system\logistic_tracking_system\lts\views.py changed, reloading.]
[2021-08-11 17:21:15,009][MainThread:23852][task_id:django.utils.autoreload][autoreload.py:637][INFO][Watching for file changes with StatReloader]
[2021-08-11 17:21:17,442][MainThread:23852][task_id:django.utils.autoreload][autoreload.py:251][INFO][D:\zhouzhi\gitlit_code\logistic_tracking_system\logistic_tracking_system\lts\views.py changed, reloading.]
[2021-08-11 17:21:19,000][MainThread:10628][task_id:django.utils.autoreload][autoreload.py:637][INFO][Watching for file changes with StatReloader]
[2021-08-11 17:21:24,773][MainThread:10628][task_id:django.utils.autoreload][autoreload.py:251][INFO][D:\zhouzhi\gitlit_code\logistic_tracking_system\logistic_tracking_system\lts\views.py changed, reloading.]
[2021-08-11 17:21:25,869][MainThread:24272][task_id:django.utils.autoreload][autoreload.py:637][INFO][Watching for file changes with StatReloader]
[2021-08-11 17:21:28,328][MainThread:24272][task_id:django.utils.autoreload][autoreload.py:251][INFO][D:\zhouzhi\gitlit_code\logistic_tracking_system\logistic_tracking_system\lts\views.py changed, reloading.]
[2021-08-11 17:21:29,709][MainThread:20488][task_id:django.utils.autoreload][autoreload.py:637][INFO][Watching for file changes with StatReloader]
[2021-08-11 17:21:31,251][MainThread:20488][task_id:django.utils.autoreload][autoreload.py:251][INFO][D:\zhouzhi\gitlit_code\logistic_tracking_system\logistic_tracking_system\lts\views.py changed, reloading.]
[2021-08-11 17:21:33,480][MainThread:20256][task_id:django.utils.autoreload][autoreload.py:637][INFO][Watching for file changes with StatReloader]
[2021-08-11 17:21:46,957][MainThread:20256][task_id:django.utils.autoreload][autoreload.py:251][INFO][D:\zhouzhi\gitlit_code\logistic_tracking_system\logistic_tracking_system\lts\views.py changed, reloading.]
[2021-08-11 17:21:48,025][MainThread:23724][task_id:django.utils.autoreload][autoreload.py:637][INFO][Watching for file changes with StatReloader]
[2021-08-11 17:21:59,809][MainThread:23724][task_id:django.utils.autoreload][autoreload.py:251][INFO][D:\zhouzhi\gitlit_code\logistic_tracking_system\logistic_tracking_system\lts\views.py changed, reloading.]
[2021-08-11 17:22:01,282][MainThread:23216][task_id:django.utils.autoreload][autoreload.py:637][INFO][Watching for file changes with StatReloader]
[2021-08-11 17:23:43,228][MainThread:23216][task_id:django.utils.autoreload][autoreload.py:251][INFO][D:\zhouzhi\gitlit_code\logistic_tracking_system\logistic_tracking_system\lts\views.py changed, reloading.]
[2021-08-11 17:23:44,305][MainThread:24568][task_id:django.utils.autoreload][autoreload.py:637][INFO][Watching for file changes with StatReloader]
[2021-08-11 17:24:12,227][MainThread:24568][task_id:django.utils.autoreload][autoreload.py:251][INFO][D:\zhouzhi\gitlit_code\logistic_tracking_system\logistic_tracking_system\lts\views.py changed, reloading.]
[2021-08-11 17:24:13,263][MainThread:21944][task_id:django.utils.autoreload][autoreload.py:637][INFO][Watching for file changes with StatReloader]
[2021-08-11 17:24:26,515][MainThread:21944][task_id:django.utils.autoreload][autoreload.py:251][INFO][D:\zhouzhi\gitlit_code\logistic_tracking_system\logistic_tracking_system\lts\views.py changed, reloading.]
[2021-08-11 17:24:27,630][MainThread:10616][task_id:django.utils.autoreload][autoreload.py:637][INFO][Watching for file changes with StatReloader]
[2021-08-11 17:24:30,101][MainThread:10616][task_id:django.utils.autoreload][autoreload.py:251][INFO][D:\zhouzhi\gitlit_code\logistic_tracking_system\logistic_tracking_system\lts\views.py changed, reloading.]
[2021-08-11 17:24:31,859][MainThread:15616][task_id:django.utils.autoreload][autoreload.py:637][INFO][Watching for file changes with StatReloader]
[2021-08-11 17:24:42,953][MainThread:15616][task_id:django.utils.autoreload][autoreload.py:251][INFO][D:\zhouzhi\gitlit_code\logistic_tracking_system\logistic_tracking_system\lts\views.py changed, reloading.]
[2021-08-11 17:24:44,318][MainThread:23232][task_id:django.utils.autoreload][autoreload.py:637][INFO][Watching for file changes with StatReloader]
[2021-08-11 17:24:50,993][MainThread:23232][task_id:django.utils.autoreload][autoreload.py:251][INFO][D:\zhouzhi\gitlit_code\logistic_tracking_system\logistic_tracking_system\lts\views.py changed, reloading.]
[2021-08-11 17:24:52,494][MainThread:23216][task_id:django.utils.autoreload][autoreload.py:637][INFO][Watching for file changes with StatReloader]
[2021-08-11 17:25:05,585][MainThread:23216][task_id:django.utils.autoreload][autoreload.py:251][INFO][D:\zhouzhi\gitlit_code\logistic_tracking_system\logistic_tracking_system\lts\views.py changed, reloading.]
[2021-08-11 17:25:06,614][MainThread:13336][task_id:django.utils.autoreload][autoreload.py:637][INFO][Watching for file changes with StatReloader]
[2021-08-11 17:25:12,220][MainThread:13336][task_id:django.utils.autoreload][autoreload.py:251][INFO][D:\zhouzhi\gitlit_code\logistic_tracking_system\logistic_tracking_system\lts\views.py changed, reloading.]
[2021-08-11 17:25:13,609][MainThread:21844][task_id:django.utils.autoreload][autoreload.py:637][INFO][Watching for file changes with StatReloader]
[2021-08-11 17:25:20,693][MainThread:21844][task_id:django.utils.autoreload][autoreload.py:251][INFO][D:\zhouzhi\gitlit_code\logistic_tracking_system\logistic_tracking_system\lts\views.py changed, reloading.]
[2021-08-11 17:25:21,867][MainThread:21144][task_id:django.utils.autoreload][autoreload.py:637][INFO][Watching for file changes with StatReloader]
[2021-08-11 17:25:28,796][MainThread:21144][task_id:django.utils.autoreload][autoreload.py:251][INFO][D:\zhouzhi\gitlit_code\logistic_tracking_system\logistic_tracking_system\lts\views.py changed, reloading.]
[2021-08-11 17:25:30,141][MainThread:21572][task_id:django.utils.autoreload][autoreload.py:637][INFO][Watching for file changes with StatReloader]
[2021-08-11 17:25:33,584][MainThread:21572][task_id:django.utils.autoreload][autoreload.py:251][INFO][D:\zhouzhi\gitlit_code\logistic_tracking_system\logistic_tracking_system\lts\views.py changed, reloading.]
[2021-08-11 17:25:35,021][MainThread:13624][task_id:django.utils.autoreload][autoreload.py:637][INFO][Watching for file changes with StatReloader]
[2021-08-11 17:25:42,151][MainThread:13624][task_id:django.utils.autoreload][autoreload.py:251][INFO][D:\zhouzhi\gitlit_code\logistic_tracking_system\logistic_tracking_system\lts\views.py changed, reloading.]
[2021-08-11 17:25:43,174][MainThread:5588][task_id:django.utils.autoreload][autoreload.py:637][INFO][Watching for file changes with StatReloader]
[2021-08-11 17:25:53,081][MainThread:5588][task_id:django.utils.autoreload][autoreload.py:251][INFO][D:\zhouzhi\gitlit_code\logistic_tracking_system\logistic_tracking_system\lts\views.py changed, reloading.]
[2021-08-11 17:25:54,193][MainThread:6300][task_id:django.utils.autoreload][autoreload.py:637][INFO][Watching for file changes with StatReloader]
[2021-08-11 17:26:23,335][MainThread:6300][task_id:django.utils.autoreload][autoreload.py:251][INFO][D:\zhouzhi\gitlit_code\logistic_tracking_system\logistic_tracking_system\lts\views.py changed, reloading.]
[2021-08-11 17:26:24,862][MainThread:22652][task_id:django.utils.autoreload][autoreload.py:637][INFO][Watching for file changes with StatReloader]
[2021-08-11 17:28:09,054][MainThread:22652][task_id:django.utils.autoreload][autoreload.py:251][INFO][D:\zhouzhi\gitlit_code\logistic_tracking_system\logistic_tracking_system\lts\views.py changed, reloading.]
[2021-08-11 17:28:10,124][MainThread:22244][task_id:django.utils.autoreload][autoreload.py:637][INFO][Watching for file changes with StatReloader]
[2021-08-11 17:30:11,011][MainThread:22244][task_id:django.utils.autoreload][autoreload.py:251][INFO][D:\zhouzhi\gitlit_code\logistic_tracking_system\logistic_tracking_system\lts\views.py changed, reloading.]
[2021-08-11 17:30:12,732][MainThread:23248][task_id:django.utils.autoreload][autoreload.py:637][INFO][Watching for file changes with StatReloader]
[2021-08-11 17:30:50,691][Thread-1:22404][task_id:root][views.py:209][ERROR][用户没有进入此工站的权限]
[2021-08-11 17:31:03,324][Thread-1:22404][task_id:lts.views][views.py:206][INFO][登录成功]
[2021-08-11 17:31:19,464][Thread-1:22404][task_id:django.request][log.py:230][ERROR][Internal Server Error: /logistic/LogisticAddModel]
Traceback (most recent call last):
  File "D:\zhouzhi\gitlit_code\logistic_tracking_system\logistic_tracking_system\lts\views.py", line 6503, in post
    json_data = request.body()
TypeError: 'bytes' object is not callable

During handling of the above exception, another exception occurred:

Traceback (most recent call last):
  File "C:\Users\zhi.zhou\Anaconda3\envs\lts\lib\site-packages\django\core\handlers\exception.py", line 47, in inner
    response = get_response(request)
  File "C:\Users\zhi.zhou\Anaconda3\envs\lts\lib\site-packages\django\core\handlers\base.py", line 181, in _get_response
    response = wrapped_callback(request, *callback_args, **callback_kwargs)
  File "C:\Users\zhi.zhou\Anaconda3\envs\lts\lib\site-packages\django\views\generic\base.py", line 70, in view
    return self.dispatch(request, *args, **kwargs)
  File "C:\Users\zhi.zhou\Anaconda3\envs\lts\lib\site-packages\django\views\generic\base.py", line 98, in dispatch
    return handler(request, *args, **kwargs)
  File "D:\zhouzhi\gitlit_code\logistic_tracking_system\logistic_tracking_system\lts\views.py", line 6546, in post
    result = json.dumps(result)
  File "C:\Users\zhi.zhou\Anaconda3\envs\lts\lib\json\__init__.py", line 231, in dumps
    return _default_encoder.encode(obj)
  File "C:\Users\zhi.zhou\Anaconda3\envs\lts\lib\json\encoder.py", line 199, in encode
    chunks = self.iterencode(o, _one_shot=True)
  File "C:\Users\zhi.zhou\Anaconda3\envs\lts\lib\json\encoder.py", line 257, in iterencode
    return _iterencode(o, 0)
  File "C:\Users\zhi.zhou\Anaconda3\envs\lts\lib\json\encoder.py", line 180, in default
    o.__class__.__name__)
TypeError: Object of type 'TypeError' is not JSON serializable
[2021-08-11 17:31:40,724][MainThread:23248][task_id:django.utils.autoreload][autoreload.py:251][INFO][D:\zhouzhi\gitlit_code\logistic_tracking_system\logistic_tracking_system\lts\views.py changed, reloading.]
[2021-08-11 17:31:41,750][MainThread:22480][task_id:django.utils.autoreload][autoreload.py:637][INFO][Watching for file changes with StatReloader]
[2021-08-11 17:33:39,477][MainThread:22480][task_id:django.utils.autoreload][autoreload.py:251][INFO][D:\zhouzhi\gitlit_code\logistic_tracking_system\logistic_tracking_system\lts\views.py changed, reloading.]
[2021-08-11 17:33:41,102][MainThread:25056][task_id:django.utils.autoreload][autoreload.py:637][INFO][Watching for file changes with StatReloader]
[2021-08-11 17:33:45,444][Thread-1:25368][task_id:django.request][log.py:230][ERROR][Internal Server Error: /logistic/LogisticAddModel]
Traceback (most recent call last):
  File "D:\zhouzhi\gitlit_code\logistic_tracking_system\logistic_tracking_system\lts\views.py", line 6504, in post
    json_data = request.body()
TypeError: 'bytes' object is not callable

During handling of the above exception, another exception occurred:

Traceback (most recent call last):
  File "C:\Users\zhi.zhou\Anaconda3\envs\lts\lib\site-packages\django\core\handlers\exception.py", line 47, in inner
    response = get_response(request)
  File "C:\Users\zhi.zhou\Anaconda3\envs\lts\lib\site-packages\django\core\handlers\base.py", line 181, in _get_response
    response = wrapped_callback(request, *callback_args, **callback_kwargs)
  File "C:\Users\zhi.zhou\Anaconda3\envs\lts\lib\site-packages\django\views\generic\base.py", line 70, in view
    return self.dispatch(request, *args, **kwargs)
  File "C:\Users\zhi.zhou\Anaconda3\envs\lts\lib\site-packages\django\views\generic\base.py", line 98, in dispatch
    return handler(request, *args, **kwargs)
  File "D:\zhouzhi\gitlit_code\logistic_tracking_system\logistic_tracking_system\lts\views.py", line 6548, in post
    result = json.dumps(result)
  File "C:\Users\zhi.zhou\Anaconda3\envs\lts\lib\json\__init__.py", line 231, in dumps
    return _default_encoder.encode(obj)
  File "C:\Users\zhi.zhou\Anaconda3\envs\lts\lib\json\encoder.py", line 199, in encode
    chunks = self.iterencode(o, _one_shot=True)
  File "C:\Users\zhi.zhou\Anaconda3\envs\lts\lib\json\encoder.py", line 257, in iterencode
    return _iterencode(o, 0)
  File "C:\Users\zhi.zhou\Anaconda3\envs\lts\lib\json\encoder.py", line 180, in default
    o.__class__.__name__)
TypeError: Object of type 'TypeError' is not JSON serializable
