[2021-08-19 08:48:48,563][MainThread:2188][task_id:django.utils.autoreload][autoreload.py:637][INFO][Watching for file changes with StatReloader]
[2021-08-19 08:49:49,849][Thread-3:8688][task_id:django.request][log.py:230][ERROR][Internal Server Error: /logistic/LogisticWorkStation]
Traceback (most recent call last):
  File "D:\zhouzhi\gitlit_code\logistic_tracking_system\logistic_tracking_system\lts\views.py", line 2262, in get
    drs = db.execute_sql(conn, sql_main)
  File "D:\zhouzhi\gitlit_code\logistic_tracking_system\logistic_tracking_system\common\db.py", line 45, in execute_sql
    cursor.execute(sql)
  File "C:\Users\zhi.zhou\Anaconda3\envs\lts\lib\site-packages\pymysql\cursors.py", line 148, in execute
    result = self._query(query)
  File "C:\Users\zhi.zhou\Anaconda3\envs\lts\lib\site-packages\pymysql\cursors.py", line 310, in _query
    conn.query(q)
  File "C:\Users\zhi.zhou\Anaconda3\envs\lts\lib\site-packages\pymysql\connections.py", line 548, in query
    self._affected_rows = self._read_query_result(unbuffered=unbuffered)
  File "C:\Users\zhi.zhou\Anaconda3\envs\lts\lib\site-packages\pymysql\connections.py", line 775, in _read_query_result
    result.read()
  File "C:\Users\zhi.zhou\Anaconda3\envs\lts\lib\site-packages\pymysql\connections.py", line 1156, in read
    first_packet = self.connection._read_packet()
  File "C:\Users\zhi.zhou\Anaconda3\envs\lts\lib\site-packages\pymysql\connections.py", line 725, in _read_packet
    packet.raise_for_error()
  File "C:\Users\zhi.zhou\Anaconda3\envs\lts\lib\site-packages\pymysql\protocol.py", line 221, in raise_for_error
    err.raise_mysql_exception(self._data)
  File "C:\Users\zhi.zhou\Anaconda3\envs\lts\lib\site-packages\pymysql\err.py", line 143, in raise_mysql_exception
    raise errorclass(errno, errval)
pymysql.err.OperationalError: (1046, 'No database selected')

During handling of the above exception, another exception occurred:

Traceback (most recent call last):
  File "C:\Users\zhi.zhou\Anaconda3\envs\lts\lib\site-packages\django\core\handlers\exception.py", line 47, in inner
    response = get_response(request)
  File "C:\Users\zhi.zhou\Anaconda3\envs\lts\lib\site-packages\django\core\handlers\base.py", line 181, in _get_response
    response = wrapped_callback(request, *callback_args, **callback_kwargs)
  File "C:\Users\zhi.zhou\Anaconda3\envs\lts\lib\site-packages\django\views\generic\base.py", line 70, in view
    return self.dispatch(request, *args, **kwargs)
  File "C:\Users\zhi.zhou\Anaconda3\envs\lts\lib\site-packages\django\views\generic\base.py", line 98, in dispatch
    return handler(request, *args, **kwargs)
  File "D:\zhouzhi\gitlit_code\logistic_tracking_system\logistic_tracking_system\lts\views.py", line 2294, in get
    result = json.dumps(result)
  File "C:\Users\zhi.zhou\Anaconda3\envs\lts\lib\json\__init__.py", line 231, in dumps
    return _default_encoder.encode(obj)
  File "C:\Users\zhi.zhou\Anaconda3\envs\lts\lib\json\encoder.py", line 199, in encode
    chunks = self.iterencode(o, _one_shot=True)
  File "C:\Users\zhi.zhou\Anaconda3\envs\lts\lib\json\encoder.py", line 257, in iterencode
    return _iterencode(o, 0)
  File "C:\Users\zhi.zhou\Anaconda3\envs\lts\lib\json\encoder.py", line 180, in default
    o.__class__.__name__)
TypeError: Object of type 'OperationalError' is not JSON serializable
[2021-08-19 08:49:49,856][Thread-2:5444][task_id:django.request][log.py:230][ERROR][Internal Server Error: /logistic/LogisticWorkCodeName]
Traceback (most recent call last):
  File "D:\zhouzhi\gitlit_code\logistic_tracking_system\logistic_tracking_system\lts\views.py", line 3881, in get
    drs = db.execute_sql(conn, sql)
  File "D:\zhouzhi\gitlit_code\logistic_tracking_system\logistic_tracking_system\common\db.py", line 45, in execute_sql
    cursor.execute(sql)
  File "C:\Users\zhi.zhou\Anaconda3\envs\lts\lib\site-packages\pymysql\cursors.py", line 148, in execute
    result = self._query(query)
  File "C:\Users\zhi.zhou\Anaconda3\envs\lts\lib\site-packages\pymysql\cursors.py", line 310, in _query
    conn.query(q)
  File "C:\Users\zhi.zhou\Anaconda3\envs\lts\lib\site-packages\pymysql\connections.py", line 548, in query
    self._affected_rows = self._read_query_result(unbuffered=unbuffered)
  File "C:\Users\zhi.zhou\Anaconda3\envs\lts\lib\site-packages\pymysql\connections.py", line 775, in _read_query_result
    result.read()
  File "C:\Users\zhi.zhou\Anaconda3\envs\lts\lib\site-packages\pymysql\connections.py", line 1156, in read
    first_packet = self.connection._read_packet()
  File "C:\Users\zhi.zhou\Anaconda3\envs\lts\lib\site-packages\pymysql\connections.py", line 725, in _read_packet
    packet.raise_for_error()
  File "C:\Users\zhi.zhou\Anaconda3\envs\lts\lib\site-packages\pymysql\protocol.py", line 221, in raise_for_error
    err.raise_mysql_exception(self._data)
  File "C:\Users\zhi.zhou\Anaconda3\envs\lts\lib\site-packages\pymysql\err.py", line 143, in raise_mysql_exception
    raise errorclass(errno, errval)
pymysql.err.OperationalError: (1046, 'No database selected')

During handling of the above exception, another exception occurred:

Traceback (most recent call last):
  File "C:\Users\zhi.zhou\Anaconda3\envs\lts\lib\site-packages\django\core\handlers\exception.py", line 47, in inner
    response = get_response(request)
  File "C:\Users\zhi.zhou\Anaconda3\envs\lts\lib\site-packages\django\core\handlers\base.py", line 181, in _get_response
    response = wrapped_callback(request, *callback_args, **callback_kwargs)
  File "C:\Users\zhi.zhou\Anaconda3\envs\lts\lib\site-packages\django\views\generic\base.py", line 70, in view
    return self.dispatch(request, *args, **kwargs)
  File "C:\Users\zhi.zhou\Anaconda3\envs\lts\lib\site-packages\django\views\generic\base.py", line 98, in dispatch
    return handler(request, *args, **kwargs)
  File "D:\zhouzhi\gitlit_code\logistic_tracking_system\logistic_tracking_system\lts\views.py", line 3898, in get
    data = json.dumps(data)
  File "C:\Users\zhi.zhou\Anaconda3\envs\lts\lib\json\__init__.py", line 231, in dumps
    return _default_encoder.encode(obj)
  File "C:\Users\zhi.zhou\Anaconda3\envs\lts\lib\json\encoder.py", line 199, in encode
    chunks = self.iterencode(o, _one_shot=True)
  File "C:\Users\zhi.zhou\Anaconda3\envs\lts\lib\json\encoder.py", line 257, in iterencode
    return _iterencode(o, 0)
  File "C:\Users\zhi.zhou\Anaconda3\envs\lts\lib\json\encoder.py", line 180, in default
    o.__class__.__name__)
TypeError: Object of type 'OperationalError' is not JSON serializable
[2021-08-19 08:50:01,709][Thread-2:5444][task_id:lts.views][views.py:364][INFO][登录成功]
[2021-08-19 08:51:23,593][Thread-4:17800][task_id:lts.views][views.py:396][INFO][登录成功]
[2021-08-19 08:53:08,950][MainThread:2188][task_id:django.utils.autoreload][autoreload.py:251][INFO][D:\zhouzhi\gitlit_code\logistic_tracking_system\logistic_tracking_system\lts\views.py changed, reloading.]
[2021-08-19 08:53:10,043][MainThread:18972][task_id:django.utils.autoreload][autoreload.py:637][INFO][Watching for file changes with StatReloader]
[2021-08-19 08:54:08,535][Thread-1:1176][task_id:lts.views][views.py:396][INFO][登录成功]
[2021-08-19 08:58:44,145][MainThread:18972][task_id:django.utils.autoreload][autoreload.py:251][INFO][D:\zhouzhi\gitlit_code\logistic_tracking_system\logistic_tracking_system\lts\views.py changed, reloading.]
[2021-08-19 08:58:45,223][MainThread:17784][task_id:django.utils.autoreload][autoreload.py:637][INFO][Watching for file changes with StatReloader]
[2021-08-19 08:58:56,765][Thread-1:19112][task_id:lts.views][views.py:364][INFO][登录成功]
[2021-08-19 08:59:22,954][Thread-1:19112][task_id:lts.views][views.py:364][INFO][登录成功]
[2021-08-19 09:07:05,548][MainThread:17784][task_id:django.utils.autoreload][autoreload.py:251][INFO][D:\zhouzhi\gitlit_code\logistic_tracking_system\logistic_tracking_system\lts\views.py changed, reloading.]
[2021-08-19 09:07:06,829][MainThread:5996][task_id:django.utils.autoreload][autoreload.py:637][INFO][Watching for file changes with StatReloader]
[2021-08-19 09:08:44,817][MainThread:5996][task_id:django.utils.autoreload][autoreload.py:251][INFO][D:\zhouzhi\gitlit_code\logistic_tracking_system\logistic_tracking_system\lts\views.py changed, reloading.]
[2021-08-19 09:08:45,848][MainThread:10660][task_id:django.utils.autoreload][autoreload.py:637][INFO][Watching for file changes with StatReloader]
[2021-08-19 09:11:03,037][Thread-1:18548][task_id:lts.views][views.py:2047][INFO][修改产品列表或者物料表成功]
[2021-08-19 09:16:05,253][MainThread:10660][task_id:django.utils.autoreload][autoreload.py:251][INFO][D:\zhouzhi\gitlit_code\logistic_tracking_system\logistic_tracking_system\lts\views.py changed, reloading.]
[2021-08-19 09:16:06,316][MainThread:16724][task_id:django.utils.autoreload][autoreload.py:637][INFO][Watching for file changes with StatReloader]
[2021-08-19 09:16:33,294][MainThread:16724][task_id:django.utils.autoreload][autoreload.py:251][INFO][D:\zhouzhi\gitlit_code\logistic_tracking_system\logistic_tracking_system\lts\views.py changed, reloading.]
[2021-08-19 09:16:34,453][MainThread:2248][task_id:django.utils.autoreload][autoreload.py:637][INFO][Watching for file changes with StatReloader]
[2021-08-19 09:16:42,878][Thread-1:6868][task_id:lts.views][views.py:2057][ERROR][修改产品列表失败,(1049, "Unknown database 'product_id'")]
[2021-08-19 09:17:10,547][MainThread:2248][task_id:django.utils.autoreload][autoreload.py:251][INFO][D:\zhouzhi\gitlit_code\logistic_tracking_system\logistic_tracking_system\lts\views.py changed, reloading.]
[2021-08-19 09:17:11,625][MainThread:2200][task_id:django.utils.autoreload][autoreload.py:637][INFO][Watching for file changes with StatReloader]
[2021-08-19 09:17:19,309][Thread-1:16440][task_id:lts.views][views.py:2057][ERROR][修改产品列表失败,(1046, 'No database selected')]
[2021-08-19 09:17:50,142][MainThread:2200][task_id:django.utils.autoreload][autoreload.py:251][INFO][D:\zhouzhi\gitlit_code\logistic_tracking_system\logistic_tracking_system\lts\views.py changed, reloading.]
[2021-08-19 09:17:51,750][MainThread:8532][task_id:django.utils.autoreload][autoreload.py:637][INFO][Watching for file changes with StatReloader]
[2021-08-19 09:18:10,513][Thread-1:10572][task_id:lts.views][views.py:364][INFO][登录成功]
[2021-08-19 09:18:14,976][Thread-2:5172][task_id:lts.views][views.py:2058][ERROR][修改产品列表失败,(1046, 'No database selected')]
[2021-08-19 09:19:06,572][Thread-2:5172][task_id:lts.views][views.py:396][INFO][登录成功]
[2021-08-19 09:22:47,653][MainThread:8532][task_id:django.utils.autoreload][autoreload.py:251][INFO][D:\zhouzhi\gitlit_code\logistic_tracking_system\logistic_tracking_system\lts\views.py changed, reloading.]
[2021-08-19 09:22:48,730][MainThread:2248][task_id:django.utils.autoreload][autoreload.py:637][INFO][Watching for file changes with StatReloader]
[2021-08-19 09:23:00,171][Thread-1:2876][task_id:lts.views][views.py:2048][INFO][修改产品列表或者物料表成功]
[2021-08-19 09:23:44,781][Thread-1:2876][task_id:lts.views][views.py:2048][INFO][修改产品列表或者物料表成功]
[2021-08-19 09:24:03,337][Thread-1:2876][task_id:lts.views][views.py:364][INFO][登录成功]
[2021-08-19 09:24:11,257][Thread-4:17280][task_id:lts.views][views.py:2058][ERROR][修改产品列表失败,(1046, 'No database selected')]
[2021-08-19 09:25:05,271][MainThread:2248][task_id:django.utils.autoreload][autoreload.py:251][INFO][D:\zhouzhi\gitlit_code\logistic_tracking_system\logistic_tracking_system\lts\views.py changed, reloading.]
[2021-08-19 09:25:06,302][MainThread:18592][task_id:django.utils.autoreload][autoreload.py:637][INFO][Watching for file changes with StatReloader]
[2021-08-19 09:25:15,412][Thread-1:12096][task_id:lts.views][views.py:2048][INFO][修改产品列表或者物料表成功]
[2021-08-19 09:27:51,803][Thread-5:18644][task_id:django.request][log.py:230][ERROR][Internal Server Error: /logistic/LogisticWorkCodeName]
Traceback (most recent call last):
  File "D:\zhouzhi\gitlit_code\logistic_tracking_system\logistic_tracking_system\lts\views.py", line 3892, in get
    drs = db.execute_sql(conn, sql)
  File "D:\zhouzhi\gitlit_code\logistic_tracking_system\logistic_tracking_system\common\db.py", line 45, in execute_sql
    cursor.execute(sql)
  File "C:\Users\zhi.zhou\Anaconda3\envs\lts\lib\site-packages\pymysql\cursors.py", line 148, in execute
    result = self._query(query)
  File "C:\Users\zhi.zhou\Anaconda3\envs\lts\lib\site-packages\pymysql\cursors.py", line 310, in _query
    conn.query(q)
  File "C:\Users\zhi.zhou\Anaconda3\envs\lts\lib\site-packages\pymysql\connections.py", line 548, in query
    self._affected_rows = self._read_query_result(unbuffered=unbuffered)
  File "C:\Users\zhi.zhou\Anaconda3\envs\lts\lib\site-packages\pymysql\connections.py", line 775, in _read_query_result
    result.read()
  File "C:\Users\zhi.zhou\Anaconda3\envs\lts\lib\site-packages\pymysql\connections.py", line 1156, in read
    first_packet = self.connection._read_packet()
  File "C:\Users\zhi.zhou\Anaconda3\envs\lts\lib\site-packages\pymysql\connections.py", line 725, in _read_packet
    packet.raise_for_error()
  File "C:\Users\zhi.zhou\Anaconda3\envs\lts\lib\site-packages\pymysql\protocol.py", line 221, in raise_for_error
    err.raise_mysql_exception(self._data)
  File "C:\Users\zhi.zhou\Anaconda3\envs\lts\lib\site-packages\pymysql\err.py", line 143, in raise_mysql_exception
    raise errorclass(errno, errval)
pymysql.err.OperationalError: (1046, 'No database selected')

During handling of the above exception, another exception occurred:

Traceback (most recent call last):
  File "C:\Users\zhi.zhou\Anaconda3\envs\lts\lib\site-packages\django\core\handlers\exception.py", line 47, in inner
    response = get_response(request)
  File "C:\Users\zhi.zhou\Anaconda3\envs\lts\lib\site-packages\django\core\handlers\base.py", line 181, in _get_response
    response = wrapped_callback(request, *callback_args, **callback_kwargs)
  File "C:\Users\zhi.zhou\Anaconda3\envs\lts\lib\site-packages\django\views\generic\base.py", line 70, in view
    return self.dispatch(request, *args, **kwargs)
  File "C:\Users\zhi.zhou\Anaconda3\envs\lts\lib\site-packages\django\views\generic\base.py", line 98, in dispatch
    return handler(request, *args, **kwargs)
  File "D:\zhouzhi\gitlit_code\logistic_tracking_system\logistic_tracking_system\lts\views.py", line 3909, in get
    data = json.dumps(data)
  File "C:\Users\zhi.zhou\Anaconda3\envs\lts\lib\json\__init__.py", line 231, in dumps
    return _default_encoder.encode(obj)
  File "C:\Users\zhi.zhou\Anaconda3\envs\lts\lib\json\encoder.py", line 199, in encode
    chunks = self.iterencode(o, _one_shot=True)
  File "C:\Users\zhi.zhou\Anaconda3\envs\lts\lib\json\encoder.py", line 257, in iterencode
    return _iterencode(o, 0)
  File "C:\Users\zhi.zhou\Anaconda3\envs\lts\lib\json\encoder.py", line 180, in default
    o.__class__.__name__)
TypeError: Object of type 'OperationalError' is not JSON serializable
[2021-08-19 09:27:51,827][Thread-6:2096][task_id:django.request][log.py:230][ERROR][Internal Server Error: /logistic/LogisticWorkStation]
Traceback (most recent call last):
  File "D:\zhouzhi\gitlit_code\logistic_tracking_system\logistic_tracking_system\lts\views.py", line 2273, in get
    drs = db.execute_sql(conn, sql_main)
  File "D:\zhouzhi\gitlit_code\logistic_tracking_system\logistic_tracking_system\common\db.py", line 45, in execute_sql
    cursor.execute(sql)
  File "C:\Users\zhi.zhou\Anaconda3\envs\lts\lib\site-packages\pymysql\cursors.py", line 148, in execute
    result = self._query(query)
  File "C:\Users\zhi.zhou\Anaconda3\envs\lts\lib\site-packages\pymysql\cursors.py", line 310, in _query
    conn.query(q)
  File "C:\Users\zhi.zhou\Anaconda3\envs\lts\lib\site-packages\pymysql\connections.py", line 548, in query
    self._affected_rows = self._read_query_result(unbuffered=unbuffered)
  File "C:\Users\zhi.zhou\Anaconda3\envs\lts\lib\site-packages\pymysql\connections.py", line 775, in _read_query_result
    result.read()
  File "C:\Users\zhi.zhou\Anaconda3\envs\lts\lib\site-packages\pymysql\connections.py", line 1156, in read
    first_packet = self.connection._read_packet()
  File "C:\Users\zhi.zhou\Anaconda3\envs\lts\lib\site-packages\pymysql\connections.py", line 725, in _read_packet
    packet.raise_for_error()
  File "C:\Users\zhi.zhou\Anaconda3\envs\lts\lib\site-packages\pymysql\protocol.py", line 221, in raise_for_error
    err.raise_mysql_exception(self._data)
  File "C:\Users\zhi.zhou\Anaconda3\envs\lts\lib\site-packages\pymysql\err.py", line 143, in raise_mysql_exception
    raise errorclass(errno, errval)
pymysql.err.OperationalError: (1046, 'No database selected')

During handling of the above exception, another exception occurred:

Traceback (most recent call last):
  File "C:\Users\zhi.zhou\Anaconda3\envs\lts\lib\site-packages\django\core\handlers\exception.py", line 47, in inner
    response = get_response(request)
  File "C:\Users\zhi.zhou\Anaconda3\envs\lts\lib\site-packages\django\core\handlers\base.py", line 181, in _get_response
    response = wrapped_callback(request, *callback_args, **callback_kwargs)
  File "C:\Users\zhi.zhou\Anaconda3\envs\lts\lib\site-packages\django\views\generic\base.py", line 70, in view
    return self.dispatch(request, *args, **kwargs)
  File "C:\Users\zhi.zhou\Anaconda3\envs\lts\lib\site-packages\django\views\generic\base.py", line 98, in dispatch
    return handler(request, *args, **kwargs)
  File "D:\zhouzhi\gitlit_code\logistic_tracking_system\logistic_tracking_system\lts\views.py", line 2305, in get
    result = json.dumps(result)
  File "C:\Users\zhi.zhou\Anaconda3\envs\lts\lib\json\__init__.py", line 231, in dumps
    return _default_encoder.encode(obj)
  File "C:\Users\zhi.zhou\Anaconda3\envs\lts\lib\json\encoder.py", line 199, in encode
    chunks = self.iterencode(o, _one_shot=True)
  File "C:\Users\zhi.zhou\Anaconda3\envs\lts\lib\json\encoder.py", line 257, in iterencode
    return _iterencode(o, 0)
  File "C:\Users\zhi.zhou\Anaconda3\envs\lts\lib\json\encoder.py", line 180, in default
    o.__class__.__name__)
TypeError: Object of type 'OperationalError' is not JSON serializable
[2021-08-19 09:27:56,496][Thread-6:2096][task_id:django.request][log.py:230][ERROR][Internal Server Error: /logistic/LogisticWorkCodeName]
Traceback (most recent call last):
  File "D:\zhouzhi\gitlit_code\logistic_tracking_system\logistic_tracking_system\lts\views.py", line 3892, in get
    drs = db.execute_sql(conn, sql)
  File "D:\zhouzhi\gitlit_code\logistic_tracking_system\logistic_tracking_system\common\db.py", line 45, in execute_sql
    cursor.execute(sql)
  File "C:\Users\zhi.zhou\Anaconda3\envs\lts\lib\site-packages\pymysql\cursors.py", line 148, in execute
    result = self._query(query)
  File "C:\Users\zhi.zhou\Anaconda3\envs\lts\lib\site-packages\pymysql\cursors.py", line 310, in _query
    conn.query(q)
  File "C:\Users\zhi.zhou\Anaconda3\envs\lts\lib\site-packages\pymysql\connections.py", line 548, in query
    self._affected_rows = self._read_query_result(unbuffered=unbuffered)
  File "C:\Users\zhi.zhou\Anaconda3\envs\lts\lib\site-packages\pymysql\connections.py", line 775, in _read_query_result
    result.read()
  File "C:\Users\zhi.zhou\Anaconda3\envs\lts\lib\site-packages\pymysql\connections.py", line 1156, in read
    first_packet = self.connection._read_packet()
  File "C:\Users\zhi.zhou\Anaconda3\envs\lts\lib\site-packages\pymysql\connections.py", line 725, in _read_packet
    packet.raise_for_error()
  File "C:\Users\zhi.zhou\Anaconda3\envs\lts\lib\site-packages\pymysql\protocol.py", line 221, in raise_for_error
    err.raise_mysql_exception(self._data)
  File "C:\Users\zhi.zhou\Anaconda3\envs\lts\lib\site-packages\pymysql\err.py", line 143, in raise_mysql_exception
    raise errorclass(errno, errval)
pymysql.err.OperationalError: (1046, 'No database selected')

During handling of the above exception, another exception occurred:

Traceback (most recent call last):
  File "C:\Users\zhi.zhou\Anaconda3\envs\lts\lib\site-packages\django\core\handlers\exception.py", line 47, in inner
    response = get_response(request)
  File "C:\Users\zhi.zhou\Anaconda3\envs\lts\lib\site-packages\django\core\handlers\base.py", line 181, in _get_response
    response = wrapped_callback(request, *callback_args, **callback_kwargs)
  File "C:\Users\zhi.zhou\Anaconda3\envs\lts\lib\site-packages\django\views\generic\base.py", line 70, in view
    return self.dispatch(request, *args, **kwargs)
  File "C:\Users\zhi.zhou\Anaconda3\envs\lts\lib\site-packages\django\views\generic\base.py", line 98, in dispatch
    return handler(request, *args, **kwargs)
  File "D:\zhouzhi\gitlit_code\logistic_tracking_system\logistic_tracking_system\lts\views.py", line 3909, in get
    data = json.dumps(data)
  File "C:\Users\zhi.zhou\Anaconda3\envs\lts\lib\json\__init__.py", line 231, in dumps
    return _default_encoder.encode(obj)
  File "C:\Users\zhi.zhou\Anaconda3\envs\lts\lib\json\encoder.py", line 199, in encode
    chunks = self.iterencode(o, _one_shot=True)
  File "C:\Users\zhi.zhou\Anaconda3\envs\lts\lib\json\encoder.py", line 257, in iterencode
    return _iterencode(o, 0)
  File "C:\Users\zhi.zhou\Anaconda3\envs\lts\lib\json\encoder.py", line 180, in default
    o.__class__.__name__)
TypeError: Object of type 'OperationalError' is not JSON serializable
[2021-08-19 09:27:56,521][Thread-5:18644][task_id:django.request][log.py:230][ERROR][Internal Server Error: /logistic/LogisticWorkStation]
Traceback (most recent call last):
  File "D:\zhouzhi\gitlit_code\logistic_tracking_system\logistic_tracking_system\lts\views.py", line 2273, in get
    drs = db.execute_sql(conn, sql_main)
  File "D:\zhouzhi\gitlit_code\logistic_tracking_system\logistic_tracking_system\common\db.py", line 45, in execute_sql
    cursor.execute(sql)
  File "C:\Users\zhi.zhou\Anaconda3\envs\lts\lib\site-packages\pymysql\cursors.py", line 148, in execute
    result = self._query(query)
  File "C:\Users\zhi.zhou\Anaconda3\envs\lts\lib\site-packages\pymysql\cursors.py", line 310, in _query
    conn.query(q)
  File "C:\Users\zhi.zhou\Anaconda3\envs\lts\lib\site-packages\pymysql\connections.py", line 548, in query
    self._affected_rows = self._read_query_result(unbuffered=unbuffered)
  File "C:\Users\zhi.zhou\Anaconda3\envs\lts\lib\site-packages\pymysql\connections.py", line 775, in _read_query_result
    result.read()
  File "C:\Users\zhi.zhou\Anaconda3\envs\lts\lib\site-packages\pymysql\connections.py", line 1156, in read
    first_packet = self.connection._read_packet()
  File "C:\Users\zhi.zhou\Anaconda3\envs\lts\lib\site-packages\pymysql\connections.py", line 725, in _read_packet
    packet.raise_for_error()
  File "C:\Users\zhi.zhou\Anaconda3\envs\lts\lib\site-packages\pymysql\protocol.py", line 221, in raise_for_error
    err.raise_mysql_exception(self._data)
  File "C:\Users\zhi.zhou\Anaconda3\envs\lts\lib\site-packages\pymysql\err.py", line 143, in raise_mysql_exception
    raise errorclass(errno, errval)
pymysql.err.OperationalError: (1046, 'No database selected')

During handling of the above exception, another exception occurred:

Traceback (most recent call last):
  File "C:\Users\zhi.zhou\Anaconda3\envs\lts\lib\site-packages\django\core\handlers\exception.py", line 47, in inner
    response = get_response(request)
  File "C:\Users\zhi.zhou\Anaconda3\envs\lts\lib\site-packages\django\core\handlers\base.py", line 181, in _get_response
    response = wrapped_callback(request, *callback_args, **callback_kwargs)
  File "C:\Users\zhi.zhou\Anaconda3\envs\lts\lib\site-packages\django\views\generic\base.py", line 70, in view
    return self.dispatch(request, *args, **kwargs)
  File "C:\Users\zhi.zhou\Anaconda3\envs\lts\lib\site-packages\django\views\generic\base.py", line 98, in dispatch
    return handler(request, *args, **kwargs)
  File "D:\zhouzhi\gitlit_code\logistic_tracking_system\logistic_tracking_system\lts\views.py", line 2305, in get
    result = json.dumps(result)
  File "C:\Users\zhi.zhou\Anaconda3\envs\lts\lib\json\__init__.py", line 231, in dumps
    return _default_encoder.encode(obj)
  File "C:\Users\zhi.zhou\Anaconda3\envs\lts\lib\json\encoder.py", line 199, in encode
    chunks = self.iterencode(o, _one_shot=True)
  File "C:\Users\zhi.zhou\Anaconda3\envs\lts\lib\json\encoder.py", line 257, in iterencode
    return _iterencode(o, 0)
  File "C:\Users\zhi.zhou\Anaconda3\envs\lts\lib\json\encoder.py", line 180, in default
    o.__class__.__name__)
TypeError: Object of type 'OperationalError' is not JSON serializable
[2021-08-19 09:27:56,991][Thread-8:10076][task_id:django.request][log.py:230][ERROR][Internal Server Error: /logistic/LogisticWorkStation]
Traceback (most recent call last):
  File "D:\zhouzhi\gitlit_code\logistic_tracking_system\logistic_tracking_system\lts\views.py", line 2273, in get
    drs = db.execute_sql(conn, sql_main)
  File "D:\zhouzhi\gitlit_code\logistic_tracking_system\logistic_tracking_system\common\db.py", line 45, in execute_sql
    cursor.execute(sql)
  File "C:\Users\zhi.zhou\Anaconda3\envs\lts\lib\site-packages\pymysql\cursors.py", line 148, in execute
    result = self._query(query)
  File "C:\Users\zhi.zhou\Anaconda3\envs\lts\lib\site-packages\pymysql\cursors.py", line 310, in _query
    conn.query(q)
  File "C:\Users\zhi.zhou\Anaconda3\envs\lts\lib\site-packages\pymysql\connections.py", line 548, in query
    self._affected_rows = self._read_query_result(unbuffered=unbuffered)
  File "C:\Users\zhi.zhou\Anaconda3\envs\lts\lib\site-packages\pymysql\connections.py", line 775, in _read_query_result
    result.read()
  File "C:\Users\zhi.zhou\Anaconda3\envs\lts\lib\site-packages\pymysql\connections.py", line 1156, in read
    first_packet = self.connection._read_packet()
  File "C:\Users\zhi.zhou\Anaconda3\envs\lts\lib\site-packages\pymysql\connections.py", line 725, in _read_packet
    packet.raise_for_error()
  File "C:\Users\zhi.zhou\Anaconda3\envs\lts\lib\site-packages\pymysql\protocol.py", line 221, in raise_for_error
    err.raise_mysql_exception(self._data)
  File "C:\Users\zhi.zhou\Anaconda3\envs\lts\lib\site-packages\pymysql\err.py", line 143, in raise_mysql_exception
    raise errorclass(errno, errval)
pymysql.err.OperationalError: (1046, 'No database selected')

During handling of the above exception, another exception occurred:

Traceback (most recent call last):
  File "C:\Users\zhi.zhou\Anaconda3\envs\lts\lib\site-packages\django\core\handlers\exception.py", line 47, in inner
    response = get_response(request)
  File "C:\Users\zhi.zhou\Anaconda3\envs\lts\lib\site-packages\django\core\handlers\base.py", line 181, in _get_response
    response = wrapped_callback(request, *callback_args, **callback_kwargs)
  File "C:\Users\zhi.zhou\Anaconda3\envs\lts\lib\site-packages\django\views\generic\base.py", line 70, in view
    return self.dispatch(request, *args, **kwargs)
  File "C:\Users\zhi.zhou\Anaconda3\envs\lts\lib\site-packages\django\views\generic\base.py", line 98, in dispatch
    return handler(request, *args, **kwargs)
  File "D:\zhouzhi\gitlit_code\logistic_tracking_system\logistic_tracking_system\lts\views.py", line 2305, in get
    result = json.dumps(result)
  File "C:\Users\zhi.zhou\Anaconda3\envs\lts\lib\json\__init__.py", line 231, in dumps
    return _default_encoder.encode(obj)
  File "C:\Users\zhi.zhou\Anaconda3\envs\lts\lib\json\encoder.py", line 199, in encode
    chunks = self.iterencode(o, _one_shot=True)
  File "C:\Users\zhi.zhou\Anaconda3\envs\lts\lib\json\encoder.py", line 257, in iterencode
    return _iterencode(o, 0)
  File "C:\Users\zhi.zhou\Anaconda3\envs\lts\lib\json\encoder.py", line 180, in default
    o.__class__.__name__)
TypeError: Object of type 'OperationalError' is not JSON serializable
[2021-08-19 09:27:57,036][Thread-7:7008][task_id:django.request][log.py:230][ERROR][Internal Server Error: /logistic/LogisticWorkCodeName]
Traceback (most recent call last):
  File "D:\zhouzhi\gitlit_code\logistic_tracking_system\logistic_tracking_system\lts\views.py", line 3892, in get
    drs = db.execute_sql(conn, sql)
  File "D:\zhouzhi\gitlit_code\logistic_tracking_system\logistic_tracking_system\common\db.py", line 45, in execute_sql
    cursor.execute(sql)
  File "C:\Users\zhi.zhou\Anaconda3\envs\lts\lib\site-packages\pymysql\cursors.py", line 148, in execute
    result = self._query(query)
  File "C:\Users\zhi.zhou\Anaconda3\envs\lts\lib\site-packages\pymysql\cursors.py", line 310, in _query
    conn.query(q)
  File "C:\Users\zhi.zhou\Anaconda3\envs\lts\lib\site-packages\pymysql\connections.py", line 548, in query
    self._affected_rows = self._read_query_result(unbuffered=unbuffered)
  File "C:\Users\zhi.zhou\Anaconda3\envs\lts\lib\site-packages\pymysql\connections.py", line 775, in _read_query_result
    result.read()
  File "C:\Users\zhi.zhou\Anaconda3\envs\lts\lib\site-packages\pymysql\connections.py", line 1156, in read
    first_packet = self.connection._read_packet()
  File "C:\Users\zhi.zhou\Anaconda3\envs\lts\lib\site-packages\pymysql\connections.py", line 725, in _read_packet
    packet.raise_for_error()
  File "C:\Users\zhi.zhou\Anaconda3\envs\lts\lib\site-packages\pymysql\protocol.py", line 221, in raise_for_error
    err.raise_mysql_exception(self._data)
  File "C:\Users\zhi.zhou\Anaconda3\envs\lts\lib\site-packages\pymysql\err.py", line 143, in raise_mysql_exception
    raise errorclass(errno, errval)
pymysql.err.OperationalError: (1046, 'No database selected')

During handling of the above exception, another exception occurred:

Traceback (most recent call last):
  File "C:\Users\zhi.zhou\Anaconda3\envs\lts\lib\site-packages\django\core\handlers\exception.py", line 47, in inner
    response = get_response(request)
  File "C:\Users\zhi.zhou\Anaconda3\envs\lts\lib\site-packages\django\core\handlers\base.py", line 181, in _get_response
    response = wrapped_callback(request, *callback_args, **callback_kwargs)
  File "C:\Users\zhi.zhou\Anaconda3\envs\lts\lib\site-packages\django\views\generic\base.py", line 70, in view
    return self.dispatch(request, *args, **kwargs)
  File "C:\Users\zhi.zhou\Anaconda3\envs\lts\lib\site-packages\django\views\generic\base.py", line 98, in dispatch
    return handler(request, *args, **kwargs)
  File "D:\zhouzhi\gitlit_code\logistic_tracking_system\logistic_tracking_system\lts\views.py", line 3909, in get
    data = json.dumps(data)
  File "C:\Users\zhi.zhou\Anaconda3\envs\lts\lib\json\__init__.py", line 231, in dumps
    return _default_encoder.encode(obj)
  File "C:\Users\zhi.zhou\Anaconda3\envs\lts\lib\json\encoder.py", line 199, in encode
    chunks = self.iterencode(o, _one_shot=True)
  File "C:\Users\zhi.zhou\Anaconda3\envs\lts\lib\json\encoder.py", line 257, in iterencode
    return _iterencode(o, 0)
  File "C:\Users\zhi.zhou\Anaconda3\envs\lts\lib\json\encoder.py", line 180, in default
    o.__class__.__name__)
TypeError: Object of type 'OperationalError' is not JSON serializable
[2021-08-19 09:28:02,781][Thread-10:20028][task_id:django.request][log.py:230][WARNING][Not Found: /favicon.ico]
[2021-08-19 09:28:02,782][Thread-9:11572][task_id:django.request][log.py:230][WARNING][Not Found: /favicon.ico]
[2021-08-19 09:28:03,349][Thread-9:11572][task_id:django.request][log.py:230][WARNING][Not Found: /favicon.ico]
[2021-08-19 09:28:03,349][Thread-10:20028][task_id:django.request][log.py:230][WARNING][Not Found: /favicon.ico]
[2021-08-19 09:28:03,966][Thread-9:11572][task_id:django.request][log.py:230][WARNING][Not Found: /favicon.ico]
[2021-08-19 09:28:03,966][Thread-10:20028][task_id:django.request][log.py:230][WARNING][Not Found: /favicon.ico]
[2021-08-19 09:28:04,566][Thread-9:11572][task_id:django.request][log.py:230][WARNING][Not Found: /favicon.ico]
[2021-08-19 09:28:04,567][Thread-10:20028][task_id:django.request][log.py:230][WARNING][Not Found: /favicon.ico]
[2021-08-19 09:31:56,496][Thread-13:1492][task_id:django.request][log.py:230][ERROR][Internal Server Error: /logistic/LogisticWorkStation]
Traceback (most recent call last):
  File "D:\zhouzhi\gitlit_code\logistic_tracking_system\logistic_tracking_system\lts\views.py", line 2273, in get
    drs = db.execute_sql(conn, sql_main)
  File "D:\zhouzhi\gitlit_code\logistic_tracking_system\logistic_tracking_system\common\db.py", line 45, in execute_sql
    cursor.execute(sql)
  File "C:\Users\zhi.zhou\Anaconda3\envs\lts\lib\site-packages\pymysql\cursors.py", line 148, in execute
    result = self._query(query)
  File "C:\Users\zhi.zhou\Anaconda3\envs\lts\lib\site-packages\pymysql\cursors.py", line 310, in _query
    conn.query(q)
  File "C:\Users\zhi.zhou\Anaconda3\envs\lts\lib\site-packages\pymysql\connections.py", line 548, in query
    self._affected_rows = self._read_query_result(unbuffered=unbuffered)
  File "C:\Users\zhi.zhou\Anaconda3\envs\lts\lib\site-packages\pymysql\connections.py", line 775, in _read_query_result
    result.read()
  File "C:\Users\zhi.zhou\Anaconda3\envs\lts\lib\site-packages\pymysql\connections.py", line 1156, in read
    first_packet = self.connection._read_packet()
  File "C:\Users\zhi.zhou\Anaconda3\envs\lts\lib\site-packages\pymysql\connections.py", line 725, in _read_packet
    packet.raise_for_error()
  File "C:\Users\zhi.zhou\Anaconda3\envs\lts\lib\site-packages\pymysql\protocol.py", line 221, in raise_for_error
    err.raise_mysql_exception(self._data)
  File "C:\Users\zhi.zhou\Anaconda3\envs\lts\lib\site-packages\pymysql\err.py", line 143, in raise_mysql_exception
    raise errorclass(errno, errval)
pymysql.err.OperationalError: (1046, 'No database selected')

During handling of the above exception, another exception occurred:

Traceback (most recent call last):
  File "C:\Users\zhi.zhou\Anaconda3\envs\lts\lib\site-packages\django\core\handlers\exception.py", line 47, in inner
    response = get_response(request)
  File "C:\Users\zhi.zhou\Anaconda3\envs\lts\lib\site-packages\django\core\handlers\base.py", line 181, in _get_response
    response = wrapped_callback(request, *callback_args, **callback_kwargs)
  File "C:\Users\zhi.zhou\Anaconda3\envs\lts\lib\site-packages\django\views\generic\base.py", line 70, in view
    return self.dispatch(request, *args, **kwargs)
  File "C:\Users\zhi.zhou\Anaconda3\envs\lts\lib\site-packages\django\views\generic\base.py", line 98, in dispatch
    return handler(request, *args, **kwargs)
  File "D:\zhouzhi\gitlit_code\logistic_tracking_system\logistic_tracking_system\lts\views.py", line 2305, in get
    result = json.dumps(result)
  File "C:\Users\zhi.zhou\Anaconda3\envs\lts\lib\json\__init__.py", line 231, in dumps
    return _default_encoder.encode(obj)
  File "C:\Users\zhi.zhou\Anaconda3\envs\lts\lib\json\encoder.py", line 199, in encode
    chunks = self.iterencode(o, _one_shot=True)
  File "C:\Users\zhi.zhou\Anaconda3\envs\lts\lib\json\encoder.py", line 257, in iterencode
    return _iterencode(o, 0)
  File "C:\Users\zhi.zhou\Anaconda3\envs\lts\lib\json\encoder.py", line 180, in default
    o.__class__.__name__)
TypeError: Object of type 'OperationalError' is not JSON serializable
[2021-08-19 09:31:56,528][Thread-12:5228][task_id:django.request][log.py:230][ERROR][Internal Server Error: /logistic/LogisticWorkCodeName]
Traceback (most recent call last):
  File "D:\zhouzhi\gitlit_code\logistic_tracking_system\logistic_tracking_system\lts\views.py", line 3892, in get
    drs = db.execute_sql(conn, sql)
  File "D:\zhouzhi\gitlit_code\logistic_tracking_system\logistic_tracking_system\common\db.py", line 45, in execute_sql
    cursor.execute(sql)
  File "C:\Users\zhi.zhou\Anaconda3\envs\lts\lib\site-packages\pymysql\cursors.py", line 148, in execute
    result = self._query(query)
  File "C:\Users\zhi.zhou\Anaconda3\envs\lts\lib\site-packages\pymysql\cursors.py", line 310, in _query
    conn.query(q)
  File "C:\Users\zhi.zhou\Anaconda3\envs\lts\lib\site-packages\pymysql\connections.py", line 548, in query
    self._affected_rows = self._read_query_result(unbuffered=unbuffered)
  File "C:\Users\zhi.zhou\Anaconda3\envs\lts\lib\site-packages\pymysql\connections.py", line 775, in _read_query_result
    result.read()
  File "C:\Users\zhi.zhou\Anaconda3\envs\lts\lib\site-packages\pymysql\connections.py", line 1156, in read
    first_packet = self.connection._read_packet()
  File "C:\Users\zhi.zhou\Anaconda3\envs\lts\lib\site-packages\pymysql\connections.py", line 725, in _read_packet
    packet.raise_for_error()
  File "C:\Users\zhi.zhou\Anaconda3\envs\lts\lib\site-packages\pymysql\protocol.py", line 221, in raise_for_error
    err.raise_mysql_exception(self._data)
  File "C:\Users\zhi.zhou\Anaconda3\envs\lts\lib\site-packages\pymysql\err.py", line 143, in raise_mysql_exception
    raise errorclass(errno, errval)
pymysql.err.OperationalError: (1046, 'No database selected')

During handling of the above exception, another exception occurred:

Traceback (most recent call last):
  File "C:\Users\zhi.zhou\Anaconda3\envs\lts\lib\site-packages\django\core\handlers\exception.py", line 47, in inner
    response = get_response(request)
  File "C:\Users\zhi.zhou\Anaconda3\envs\lts\lib\site-packages\django\core\handlers\base.py", line 181, in _get_response
    response = wrapped_callback(request, *callback_args, **callback_kwargs)
  File "C:\Users\zhi.zhou\Anaconda3\envs\lts\lib\site-packages\django\views\generic\base.py", line 70, in view
    return self.dispatch(request, *args, **kwargs)
  File "C:\Users\zhi.zhou\Anaconda3\envs\lts\lib\site-packages\django\views\generic\base.py", line 98, in dispatch
    return handler(request, *args, **kwargs)
  File "D:\zhouzhi\gitlit_code\logistic_tracking_system\logistic_tracking_system\lts\views.py", line 3909, in get
    data = json.dumps(data)
  File "C:\Users\zhi.zhou\Anaconda3\envs\lts\lib\json\__init__.py", line 231, in dumps
    return _default_encoder.encode(obj)
  File "C:\Users\zhi.zhou\Anaconda3\envs\lts\lib\json\encoder.py", line 199, in encode
    chunks = self.iterencode(o, _one_shot=True)
  File "C:\Users\zhi.zhou\Anaconda3\envs\lts\lib\json\encoder.py", line 257, in iterencode
    return _iterencode(o, 0)
  File "C:\Users\zhi.zhou\Anaconda3\envs\lts\lib\json\encoder.py", line 180, in default
    o.__class__.__name__)
TypeError: Object of type 'OperationalError' is not JSON serializable
[2021-08-19 09:32:34,343][Thread-12:5228][task_id:django.request][log.py:230][ERROR][Internal Server Error: /logistic/LogisticWorkStation]
Traceback (most recent call last):
  File "D:\zhouzhi\gitlit_code\logistic_tracking_system\logistic_tracking_system\lts\views.py", line 2273, in get
    drs = db.execute_sql(conn, sql_main)
  File "D:\zhouzhi\gitlit_code\logistic_tracking_system\logistic_tracking_system\common\db.py", line 45, in execute_sql
    cursor.execute(sql)
  File "C:\Users\zhi.zhou\Anaconda3\envs\lts\lib\site-packages\pymysql\cursors.py", line 148, in execute
    result = self._query(query)
  File "C:\Users\zhi.zhou\Anaconda3\envs\lts\lib\site-packages\pymysql\cursors.py", line 310, in _query
    conn.query(q)
  File "C:\Users\zhi.zhou\Anaconda3\envs\lts\lib\site-packages\pymysql\connections.py", line 548, in query
    self._affected_rows = self._read_query_result(unbuffered=unbuffered)
  File "C:\Users\zhi.zhou\Anaconda3\envs\lts\lib\site-packages\pymysql\connections.py", line 775, in _read_query_result
    result.read()
  File "C:\Users\zhi.zhou\Anaconda3\envs\lts\lib\site-packages\pymysql\connections.py", line 1156, in read
    first_packet = self.connection._read_packet()
  File "C:\Users\zhi.zhou\Anaconda3\envs\lts\lib\site-packages\pymysql\connections.py", line 725, in _read_packet
    packet.raise_for_error()
  File "C:\Users\zhi.zhou\Anaconda3\envs\lts\lib\site-packages\pymysql\protocol.py", line 221, in raise_for_error
    err.raise_mysql_exception(self._data)
  File "C:\Users\zhi.zhou\Anaconda3\envs\lts\lib\site-packages\pymysql\err.py", line 143, in raise_mysql_exception
    raise errorclass(errno, errval)
pymysql.err.OperationalError: (1046, 'No database selected')

During handling of the above exception, another exception occurred:

Traceback (most recent call last):
  File "C:\Users\zhi.zhou\Anaconda3\envs\lts\lib\site-packages\django\core\handlers\exception.py", line 47, in inner
    response = get_response(request)
  File "C:\Users\zhi.zhou\Anaconda3\envs\lts\lib\site-packages\django\core\handlers\base.py", line 181, in _get_response
    response = wrapped_callback(request, *callback_args, **callback_kwargs)
  File "C:\Users\zhi.zhou\Anaconda3\envs\lts\lib\site-packages\django\views\generic\base.py", line 70, in view
    return self.dispatch(request, *args, **kwargs)
  File "C:\Users\zhi.zhou\Anaconda3\envs\lts\lib\site-packages\django\views\generic\base.py", line 98, in dispatch
    return handler(request, *args, **kwargs)
  File "D:\zhouzhi\gitlit_code\logistic_tracking_system\logistic_tracking_system\lts\views.py", line 2305, in get
    result = json.dumps(result)
  File "C:\Users\zhi.zhou\Anaconda3\envs\lts\lib\json\__init__.py", line 231, in dumps
    return _default_encoder.encode(obj)
  File "C:\Users\zhi.zhou\Anaconda3\envs\lts\lib\json\encoder.py", line 199, in encode
    chunks = self.iterencode(o, _one_shot=True)
  File "C:\Users\zhi.zhou\Anaconda3\envs\lts\lib\json\encoder.py", line 257, in iterencode
    return _iterencode(o, 0)
  File "C:\Users\zhi.zhou\Anaconda3\envs\lts\lib\json\encoder.py", line 180, in default
    o.__class__.__name__)
TypeError: Object of type 'OperationalError' is not JSON serializable
[2021-08-19 09:32:34,374][Thread-13:1492][task_id:django.request][log.py:230][ERROR][Internal Server Error: /logistic/LogisticWorkCodeName]
Traceback (most recent call last):
  File "D:\zhouzhi\gitlit_code\logistic_tracking_system\logistic_tracking_system\lts\views.py", line 3892, in get
    drs = db.execute_sql(conn, sql)
  File "D:\zhouzhi\gitlit_code\logistic_tracking_system\logistic_tracking_system\common\db.py", line 45, in execute_sql
    cursor.execute(sql)
  File "C:\Users\zhi.zhou\Anaconda3\envs\lts\lib\site-packages\pymysql\cursors.py", line 148, in execute
    result = self._query(query)
  File "C:\Users\zhi.zhou\Anaconda3\envs\lts\lib\site-packages\pymysql\cursors.py", line 310, in _query
    conn.query(q)
  File "C:\Users\zhi.zhou\Anaconda3\envs\lts\lib\site-packages\pymysql\connections.py", line 548, in query
    self._affected_rows = self._read_query_result(unbuffered=unbuffered)
  File "C:\Users\zhi.zhou\Anaconda3\envs\lts\lib\site-packages\pymysql\connections.py", line 775, in _read_query_result
    result.read()
  File "C:\Users\zhi.zhou\Anaconda3\envs\lts\lib\site-packages\pymysql\connections.py", line 1156, in read
    first_packet = self.connection._read_packet()
  File "C:\Users\zhi.zhou\Anaconda3\envs\lts\lib\site-packages\pymysql\connections.py", line 725, in _read_packet
    packet.raise_for_error()
  File "C:\Users\zhi.zhou\Anaconda3\envs\lts\lib\site-packages\pymysql\protocol.py", line 221, in raise_for_error
    err.raise_mysql_exception(self._data)
  File "C:\Users\zhi.zhou\Anaconda3\envs\lts\lib\site-packages\pymysql\err.py", line 143, in raise_mysql_exception
    raise errorclass(errno, errval)
pymysql.err.OperationalError: (1046, 'No database selected')

During handling of the above exception, another exception occurred:

Traceback (most recent call last):
  File "C:\Users\zhi.zhou\Anaconda3\envs\lts\lib\site-packages\django\core\handlers\exception.py", line 47, in inner
    response = get_response(request)
  File "C:\Users\zhi.zhou\Anaconda3\envs\lts\lib\site-packages\django\core\handlers\base.py", line 181, in _get_response
    response = wrapped_callback(request, *callback_args, **callback_kwargs)
  File "C:\Users\zhi.zhou\Anaconda3\envs\lts\lib\site-packages\django\views\generic\base.py", line 70, in view
    return self.dispatch(request, *args, **kwargs)
  File "C:\Users\zhi.zhou\Anaconda3\envs\lts\lib\site-packages\django\views\generic\base.py", line 98, in dispatch
    return handler(request, *args, **kwargs)
  File "D:\zhouzhi\gitlit_code\logistic_tracking_system\logistic_tracking_system\lts\views.py", line 3909, in get
    data = json.dumps(data)
  File "C:\Users\zhi.zhou\Anaconda3\envs\lts\lib\json\__init__.py", line 231, in dumps
    return _default_encoder.encode(obj)
  File "C:\Users\zhi.zhou\Anaconda3\envs\lts\lib\json\encoder.py", line 199, in encode
    chunks = self.iterencode(o, _one_shot=True)
  File "C:\Users\zhi.zhou\Anaconda3\envs\lts\lib\json\encoder.py", line 257, in iterencode
    return _iterencode(o, 0)
  File "C:\Users\zhi.zhou\Anaconda3\envs\lts\lib\json\encoder.py", line 180, in default
    o.__class__.__name__)
TypeError: Object of type 'OperationalError' is not JSON serializable
[2021-08-19 09:33:36,199][Thread-2:9980][task_id:lts.views][views.py:364][INFO][登录成功]
[2021-08-19 09:33:37,308][Thread-3:6416][task_id:lts.views][views.py:364][INFO][登录成功]
[2021-08-19 09:34:12,097][Thread-2:9980][task_id:lts.views][views.py:364][INFO][登录成功]
[2021-08-19 09:35:18,323][Thread-2:9980][task_id:lts.views][views.py:364][INFO][登录成功]
[2021-08-19 09:36:22,942][Thread-3:6416][task_id:lts.views][views.py:396][INFO][登录成功]
[2021-08-19 09:37:04,213][MainThread:18592][task_id:django.utils.autoreload][autoreload.py:251][INFO][D:\zhouzhi\gitlit_code\logistic_tracking_system\logistic_tracking_system\lts\views.py changed, reloading.]
[2021-08-19 09:37:05,291][MainThread:9256][task_id:django.utils.autoreload][autoreload.py:637][INFO][Watching for file changes with StatReloader]
[2021-08-19 09:42:09,716][Thread-3:15188][task_id:lts.views][views.py:369][ERROR][用户名或者密码不正确或者没有此项目的权限]
[2021-08-19 09:42:18,917][Thread-3:15188][task_id:lts.views][views.py:364][INFO][登录成功]
[2021-08-19 09:43:01,548][Thread-3:15188][task_id:lts.views][views.py:1302][INFO][创建物料详情表成功]
[2021-08-19 09:52:05,905][MainThread:9256][task_id:django.utils.autoreload][autoreload.py:251][INFO][D:\zhouzhi\gitlit_code\logistic_tracking_system\logistic_tracking_system\lts\views.py changed, reloading.]
[2021-08-19 09:52:07,045][MainThread:11976][task_id:django.utils.autoreload][autoreload.py:637][INFO][Watching for file changes with StatReloader]
[2021-08-19 09:53:20,215][MainThread:19956][task_id:django.utils.autoreload][autoreload.py:637][INFO][Watching for file changes with StatReloader]
[2021-08-19 09:54:31,339][MainThread:19956][task_id:django.utils.autoreload][autoreload.py:251][INFO][D:\zhouzhi\gitlit_code\logistic_tracking_system\logistic_tracking_system\lts\views.py changed, reloading.]
[2021-08-19 09:54:32,542][MainThread:1272][task_id:django.utils.autoreload][autoreload.py:637][INFO][Watching for file changes with StatReloader]
[2021-08-19 09:55:33,544][MainThread:5640][task_id:django.utils.autoreload][autoreload.py:637][INFO][Watching for file changes with StatReloader]
[2021-08-19 09:57:25,351][MainThread:12360][task_id:django.utils.autoreload][autoreload.py:637][INFO][Watching for file changes with StatReloader]
[2021-08-19 09:58:40,656][MainThread:19864][task_id:django.utils.autoreload][autoreload.py:637][INFO][Watching for file changes with StatReloader]
[2021-08-19 10:02:49,921][MainThread:19864][task_id:django.utils.autoreload][autoreload.py:251][INFO][D:\zhouzhi\gitlit_code\logistic_tracking_system\logistic_tracking_system\lts\views.py changed, reloading.]
[2021-08-19 10:02:51,062][MainThread:9812][task_id:django.utils.autoreload][autoreload.py:637][INFO][Watching for file changes with StatReloader]
[2021-08-19 10:05:35,516][MainThread:9812][task_id:django.utils.autoreload][autoreload.py:251][INFO][D:\zhouzhi\gitlit_code\logistic_tracking_system\logistic_tracking_system\lts\views.py changed, reloading.]
[2021-08-19 10:05:36,579][MainThread:6064][task_id:django.utils.autoreload][autoreload.py:637][INFO][Watching for file changes with StatReloader]
[2021-08-19 10:05:40,234][MainThread:6064][task_id:django.utils.autoreload][autoreload.py:251][INFO][D:\zhouzhi\gitlit_code\logistic_tracking_system\logistic_tracking_system\lts\views.py changed, reloading.]
[2021-08-19 10:05:42,031][MainThread:1452][task_id:django.utils.autoreload][autoreload.py:637][INFO][Watching for file changes with StatReloader]
[2021-08-19 10:05:45,670][MainThread:1452][task_id:django.utils.autoreload][autoreload.py:251][INFO][D:\zhouzhi\gitlit_code\logistic_tracking_system\logistic_tracking_system\lts\views.py changed, reloading.]
[2021-08-19 10:05:47,311][MainThread:20092][task_id:django.utils.autoreload][autoreload.py:637][INFO][Watching for file changes with StatReloader]
[2021-08-19 10:06:47,671][MainThread:20092][task_id:django.utils.autoreload][autoreload.py:251][INFO][D:\zhouzhi\gitlit_code\logistic_tracking_system\logistic_tracking_system\lts\views.py changed, reloading.]
[2021-08-19 10:06:48,921][MainThread:4592][task_id:django.utils.autoreload][autoreload.py:637][INFO][Watching for file changes with StatReloader]
[2021-08-19 10:07:36,535][MainThread:4592][task_id:django.utils.autoreload][autoreload.py:251][INFO][D:\zhouzhi\gitlit_code\logistic_tracking_system\logistic_tracking_system\lts\views.py changed, reloading.]
[2021-08-19 10:07:37,644][MainThread:14688][task_id:django.utils.autoreload][autoreload.py:637][INFO][Watching for file changes with StatReloader]
[2021-08-19 10:07:52,501][Thread-1:5916][task_id:django.request][log.py:230][ERROR][Internal Server Error: /logistic/LogisticWorkCodeName]
Traceback (most recent call last):
  File "D:\zhouzhi\gitlit_code\logistic_tracking_system\logistic_tracking_system\lts\views.py", line 3905, in get
    drs = db.execute_sql(conn, sql)
  File "D:\zhouzhi\gitlit_code\logistic_tracking_system\logistic_tracking_system\common\db.py", line 45, in execute_sql
    cursor.execute(sql)
  File "C:\Users\zhi.zhou\Anaconda3\envs\lts\lib\site-packages\pymysql\cursors.py", line 148, in execute
    result = self._query(query)
  File "C:\Users\zhi.zhou\Anaconda3\envs\lts\lib\site-packages\pymysql\cursors.py", line 310, in _query
    conn.query(q)
  File "C:\Users\zhi.zhou\Anaconda3\envs\lts\lib\site-packages\pymysql\connections.py", line 548, in query
    self._affected_rows = self._read_query_result(unbuffered=unbuffered)
  File "C:\Users\zhi.zhou\Anaconda3\envs\lts\lib\site-packages\pymysql\connections.py", line 775, in _read_query_result
    result.read()
  File "C:\Users\zhi.zhou\Anaconda3\envs\lts\lib\site-packages\pymysql\connections.py", line 1156, in read
    first_packet = self.connection._read_packet()
  File "C:\Users\zhi.zhou\Anaconda3\envs\lts\lib\site-packages\pymysql\connections.py", line 725, in _read_packet
    packet.raise_for_error()
  File "C:\Users\zhi.zhou\Anaconda3\envs\lts\lib\site-packages\pymysql\protocol.py", line 221, in raise_for_error
    err.raise_mysql_exception(self._data)
  File "C:\Users\zhi.zhou\Anaconda3\envs\lts\lib\site-packages\pymysql\err.py", line 143, in raise_mysql_exception
    raise errorclass(errno, errval)
pymysql.err.OperationalError: (1046, 'No database selected')

During handling of the above exception, another exception occurred:

Traceback (most recent call last):
  File "C:\Users\zhi.zhou\Anaconda3\envs\lts\lib\site-packages\django\core\handlers\exception.py", line 47, in inner
    response = get_response(request)
  File "C:\Users\zhi.zhou\Anaconda3\envs\lts\lib\site-packages\django\core\handlers\base.py", line 181, in _get_response
    response = wrapped_callback(request, *callback_args, **callback_kwargs)
  File "C:\Users\zhi.zhou\Anaconda3\envs\lts\lib\site-packages\django\views\generic\base.py", line 70, in view
    return self.dispatch(request, *args, **kwargs)
  File "C:\Users\zhi.zhou\Anaconda3\envs\lts\lib\site-packages\django\views\generic\base.py", line 98, in dispatch
    return handler(request, *args, **kwargs)
  File "D:\zhouzhi\gitlit_code\logistic_tracking_system\logistic_tracking_system\lts\views.py", line 3922, in get
    data = json.dumps(data)
  File "C:\Users\zhi.zhou\Anaconda3\envs\lts\lib\json\__init__.py", line 231, in dumps
    return _default_encoder.encode(obj)
  File "C:\Users\zhi.zhou\Anaconda3\envs\lts\lib\json\encoder.py", line 199, in encode
    chunks = self.iterencode(o, _one_shot=True)
  File "C:\Users\zhi.zhou\Anaconda3\envs\lts\lib\json\encoder.py", line 257, in iterencode
    return _iterencode(o, 0)
  File "C:\Users\zhi.zhou\Anaconda3\envs\lts\lib\json\encoder.py", line 180, in default
    o.__class__.__name__)
TypeError: Object of type 'OperationalError' is not JSON serializable
[2021-08-19 10:07:52,518][Thread-2:16736][task_id:django.request][log.py:230][ERROR][Internal Server Error: /logistic/LogisticWorkStation]
Traceback (most recent call last):
  File "D:\zhouzhi\gitlit_code\logistic_tracking_system\logistic_tracking_system\lts\views.py", line 2286, in get
    drs = db.execute_sql(conn, sql_main)
  File "D:\zhouzhi\gitlit_code\logistic_tracking_system\logistic_tracking_system\common\db.py", line 45, in execute_sql
    cursor.execute(sql)
  File "C:\Users\zhi.zhou\Anaconda3\envs\lts\lib\site-packages\pymysql\cursors.py", line 148, in execute
    result = self._query(query)
  File "C:\Users\zhi.zhou\Anaconda3\envs\lts\lib\site-packages\pymysql\cursors.py", line 310, in _query
    conn.query(q)
  File "C:\Users\zhi.zhou\Anaconda3\envs\lts\lib\site-packages\pymysql\connections.py", line 548, in query
    self._affected_rows = self._read_query_result(unbuffered=unbuffered)
  File "C:\Users\zhi.zhou\Anaconda3\envs\lts\lib\site-packages\pymysql\connections.py", line 775, in _read_query_result
    result.read()
  File "C:\Users\zhi.zhou\Anaconda3\envs\lts\lib\site-packages\pymysql\connections.py", line 1156, in read
    first_packet = self.connection._read_packet()
  File "C:\Users\zhi.zhou\Anaconda3\envs\lts\lib\site-packages\pymysql\connections.py", line 725, in _read_packet
    packet.raise_for_error()
  File "C:\Users\zhi.zhou\Anaconda3\envs\lts\lib\site-packages\pymysql\protocol.py", line 221, in raise_for_error
    err.raise_mysql_exception(self._data)
  File "C:\Users\zhi.zhou\Anaconda3\envs\lts\lib\site-packages\pymysql\err.py", line 143, in raise_mysql_exception
    raise errorclass(errno, errval)
pymysql.err.OperationalError: (1046, 'No database selected')

During handling of the above exception, another exception occurred:

Traceback (most recent call last):
  File "C:\Users\zhi.zhou\Anaconda3\envs\lts\lib\site-packages\django\core\handlers\exception.py", line 47, in inner
    response = get_response(request)
  File "C:\Users\zhi.zhou\Anaconda3\envs\lts\lib\site-packages\django\core\handlers\base.py", line 181, in _get_response
    response = wrapped_callback(request, *callback_args, **callback_kwargs)
  File "C:\Users\zhi.zhou\Anaconda3\envs\lts\lib\site-packages\django\views\generic\base.py", line 70, in view
    return self.dispatch(request, *args, **kwargs)
  File "C:\Users\zhi.zhou\Anaconda3\envs\lts\lib\site-packages\django\views\generic\base.py", line 98, in dispatch
    return handler(request, *args, **kwargs)
  File "D:\zhouzhi\gitlit_code\logistic_tracking_system\logistic_tracking_system\lts\views.py", line 2318, in get
    result = json.dumps(result)
  File "C:\Users\zhi.zhou\Anaconda3\envs\lts\lib\json\__init__.py", line 231, in dumps
    return _default_encoder.encode(obj)
  File "C:\Users\zhi.zhou\Anaconda3\envs\lts\lib\json\encoder.py", line 199, in encode
    chunks = self.iterencode(o, _one_shot=True)
  File "C:\Users\zhi.zhou\Anaconda3\envs\lts\lib\json\encoder.py", line 257, in iterencode
    return _iterencode(o, 0)
  File "C:\Users\zhi.zhou\Anaconda3\envs\lts\lib\json\encoder.py", line 180, in default
    o.__class__.__name__)
TypeError: Object of type 'OperationalError' is not JSON serializable
[2021-08-19 10:08:46,008][MainThread:14688][task_id:django.utils.autoreload][autoreload.py:251][INFO][D:\zhouzhi\gitlit_code\logistic_tracking_system\logistic_tracking_system\lts\views.py changed, reloading.]
[2021-08-19 10:08:47,191][MainThread:10180][task_id:django.utils.autoreload][autoreload.py:637][INFO][Watching for file changes with StatReloader]
[2021-08-19 10:08:48,195][Thread-1:2660][task_id:lts.views][views.py:408][INFO][登录成功]
[2021-08-19 10:09:01,856][MainThread:10180][task_id:django.utils.autoreload][autoreload.py:251][INFO][D:\zhouzhi\gitlit_code\logistic_tracking_system\logistic_tracking_system\lts\views.py changed, reloading.]
[2021-08-19 10:09:03,106][MainThread:5624][task_id:django.utils.autoreload][autoreload.py:637][INFO][Watching for file changes with StatReloader]
[2021-08-19 10:09:16,299][Thread-3:19912][task_id:lts.views][views.py:2061][INFO][修改产品列表或者物料表成功]
[2021-08-19 10:09:18,036][Thread-3:19912][task_id:lts.views][views.py:2061][INFO][修改产品列表或者物料表成功]
[2021-08-19 10:11:46,078][MainThread:5624][task_id:django.utils.autoreload][autoreload.py:251][INFO][D:\zhouzhi\gitlit_code\logistic_tracking_system\logistic_tracking_system\lts\views.py changed, reloading.]
[2021-08-19 10:11:47,140][MainThread:9896][task_id:django.utils.autoreload][autoreload.py:637][INFO][Watching for file changes with StatReloader]
[2021-08-19 10:12:53,710][Thread-1:17576][task_id:lts.views][views.py:408][INFO][登录成功]
[2021-08-19 10:14:05,962][Thread-2:2872][task_id:lts.views][views.py:419][ERROR][该用户不是超级管理员]
[2021-08-19 10:14:28,366][Thread-2:2872][task_id:lts.views][views.py:408][INFO][登录成功]
[2021-08-19 10:15:09,930][MainThread:9896][task_id:django.utils.autoreload][autoreload.py:251][INFO][D:\zhouzhi\gitlit_code\logistic_tracking_system\logistic_tracking_system\lts\views.py changed, reloading.]
[2021-08-19 10:15:11,133][MainThread:11728][task_id:django.utils.autoreload][autoreload.py:637][INFO][Watching for file changes with StatReloader]
[2021-08-19 10:17:13,965][MainThread:11728][task_id:django.utils.autoreload][autoreload.py:251][INFO][D:\zhouzhi\gitlit_code\logistic_tracking_system\logistic_tracking_system\lts\views.py changed, reloading.]
[2021-08-19 10:17:15,053][MainThread:9900][task_id:django.utils.autoreload][autoreload.py:637][INFO][Watching for file changes with StatReloader]
[2021-08-19 10:17:18,059][Thread-1:6800][task_id:lts.views][views.py:408][INFO][登录成功]
[2021-08-19 10:17:56,647][MainThread:9900][task_id:django.utils.autoreload][autoreload.py:251][INFO][D:\zhouzhi\gitlit_code\logistic_tracking_system\logistic_tracking_system\lts\views.py changed, reloading.]
[2021-08-19 10:17:57,709][MainThread:5596][task_id:django.utils.autoreload][autoreload.py:637][INFO][Watching for file changes with StatReloader]
[2021-08-19 10:20:13,139][Thread-1:7144][task_id:lts.views][views.py:408][INFO][登录成功]
[2021-08-19 10:20:36,060][Thread-1:7144][task_id:lts.views][views.py:376][INFO][登录成功]
[2021-08-19 10:37:22,362][MainThread:5596][task_id:django.utils.autoreload][autoreload.py:251][INFO][D:\zhouzhi\gitlit_code\logistic_tracking_system\logistic_tracking_system\lts\views.py changed, reloading.]
[2021-08-19 10:37:23,440][MainThread:18064][task_id:django.utils.autoreload][autoreload.py:637][INFO][Watching for file changes with StatReloader]
[2021-08-19 10:38:12,296][MainThread:18064][task_id:django.utils.autoreload][autoreload.py:251][INFO][D:\zhouzhi\gitlit_code\logistic_tracking_system\logistic_tracking_system\lts\views.py changed, reloading.]
[2021-08-19 10:38:13,358][MainThread:11692][task_id:django.utils.autoreload][autoreload.py:637][INFO][Watching for file changes with StatReloader]
[2021-08-19 10:39:16,372][MainThread:11692][task_id:django.utils.autoreload][autoreload.py:251][INFO][D:\zhouzhi\gitlit_code\logistic_tracking_system\logistic_tracking_system\lts\views.py changed, reloading.]
[2021-08-19 10:39:17,450][MainThread:12620][task_id:django.utils.autoreload][autoreload.py:637][INFO][Watching for file changes with StatReloader]
[2021-08-19 10:51:28,519][Thread-17:6960][task_id:lts.views][views.py:408][INFO][登录成功]
[2021-08-19 10:51:41,582][Thread-16:18380][task_id:lts.views][views.py:408][INFO][登录成功]
[2021-08-19 10:52:09,011][Thread-17:6960][task_id:lts.views][views.py:376][INFO][登录成功]
[2021-08-19 10:52:40,489][Thread-16:18380][task_id:lts.views][views.py:2060][INFO][修改产品列表或者物料表成功]
[2021-08-19 10:54:14,856][Thread-26:6852][task_id:lts.views][views.py:376][INFO][登录成功]
[2021-08-19 10:56:05,707][Thread-26:6852][task_id:lts.views][views.py:376][INFO][登录成功]
[2021-08-19 11:22:15,447][MainThread:12620][task_id:django.utils.autoreload][autoreload.py:251][INFO][D:\zhouzhi\gitlit_code\logistic_tracking_system\logistic_tracking_system\lts\views.py changed, reloading.]
[2021-08-19 11:22:16,544][MainThread:17696][task_id:django.utils.autoreload][autoreload.py:637][INFO][Watching for file changes with StatReloader]
[2021-08-19 11:27:27,197][Thread-6:9644][task_id:django.request][log.py:230][ERROR][Internal Server Error: /logistic/LogisticDeleteWorkStation]
Traceback (most recent call last):
  File "D:\zhouzhi\gitlit_code\logistic_tracking_system\logistic_tracking_system\lts\views.py", line 2471, in get
    dfs = db.execute_sql(conn, sql_product_tansit_main)
  File "D:\zhouzhi\gitlit_code\logistic_tracking_system\logistic_tracking_system\common\db.py", line 45, in execute_sql
    cursor.execute(sql)
  File "C:\Users\zhi.zhou\Anaconda3\envs\lts\lib\site-packages\pymysql\cursors.py", line 148, in execute
    result = self._query(query)
  File "C:\Users\zhi.zhou\Anaconda3\envs\lts\lib\site-packages\pymysql\cursors.py", line 310, in _query
    conn.query(q)
  File "C:\Users\zhi.zhou\Anaconda3\envs\lts\lib\site-packages\pymysql\connections.py", line 548, in query
    self._affected_rows = self._read_query_result(unbuffered=unbuffered)
  File "C:\Users\zhi.zhou\Anaconda3\envs\lts\lib\site-packages\pymysql\connections.py", line 775, in _read_query_result
    result.read()
  File "C:\Users\zhi.zhou\Anaconda3\envs\lts\lib\site-packages\pymysql\connections.py", line 1156, in read
    first_packet = self.connection._read_packet()
  File "C:\Users\zhi.zhou\Anaconda3\envs\lts\lib\site-packages\pymysql\connections.py", line 725, in _read_packet
    packet.raise_for_error()
  File "C:\Users\zhi.zhou\Anaconda3\envs\lts\lib\site-packages\pymysql\protocol.py", line 221, in raise_for_error
    err.raise_mysql_exception(self._data)
  File "C:\Users\zhi.zhou\Anaconda3\envs\lts\lib\site-packages\pymysql\err.py", line 143, in raise_mysql_exception
    raise errorclass(errno, errval)
pymysql.err.ProgrammingError: (1064, "You have an error in your SQL syntax; check the manual that corresponds to your MySQL server version for the right syntax to use near '-06' at line 1")

During handling of the above exception, another exception occurred:

Traceback (most recent call last):
  File "C:\Users\zhi.zhou\Anaconda3\envs\lts\lib\site-packages\django\core\handlers\exception.py", line 47, in inner
    response = get_response(request)
  File "C:\Users\zhi.zhou\Anaconda3\envs\lts\lib\site-packages\django\core\handlers\base.py", line 181, in _get_response
    response = wrapped_callback(request, *callback_args, **callback_kwargs)
  File "C:\Users\zhi.zhou\Anaconda3\envs\lts\lib\site-packages\django\views\generic\base.py", line 70, in view
    return self.dispatch(request, *args, **kwargs)
  File "C:\Users\zhi.zhou\Anaconda3\envs\lts\lib\site-packages\django\views\generic\base.py", line 98, in dispatch
    return handler(request, *args, **kwargs)
  File "D:\zhouzhi\gitlit_code\logistic_tracking_system\logistic_tracking_system\lts\views.py", line 2482, in get
    data = json.dumps(data)
  File "C:\Users\zhi.zhou\Anaconda3\envs\lts\lib\json\__init__.py", line 231, in dumps
    return _default_encoder.encode(obj)
  File "C:\Users\zhi.zhou\Anaconda3\envs\lts\lib\json\encoder.py", line 199, in encode
    chunks = self.iterencode(o, _one_shot=True)
  File "C:\Users\zhi.zhou\Anaconda3\envs\lts\lib\json\encoder.py", line 257, in iterencode
    return _iterencode(o, 0)
  File "C:\Users\zhi.zhou\Anaconda3\envs\lts\lib\json\encoder.py", line 180, in default
    o.__class__.__name__)
TypeError: Object of type 'ProgrammingError' is not JSON serializable
[2021-08-19 11:27:41,157][Thread-6:9644][task_id:django.request][log.py:230][ERROR][Internal Server Error: /logistic/LogisticDeleteWorkStation]
Traceback (most recent call last):
  File "D:\zhouzhi\gitlit_code\logistic_tracking_system\logistic_tracking_system\lts\views.py", line 2471, in get
    dfs = db.execute_sql(conn, sql_product_tansit_main)
  File "D:\zhouzhi\gitlit_code\logistic_tracking_system\logistic_tracking_system\common\db.py", line 45, in execute_sql
    cursor.execute(sql)
  File "C:\Users\zhi.zhou\Anaconda3\envs\lts\lib\site-packages\pymysql\cursors.py", line 148, in execute
    result = self._query(query)
  File "C:\Users\zhi.zhou\Anaconda3\envs\lts\lib\site-packages\pymysql\cursors.py", line 310, in _query
    conn.query(q)
  File "C:\Users\zhi.zhou\Anaconda3\envs\lts\lib\site-packages\pymysql\connections.py", line 548, in query
    self._affected_rows = self._read_query_result(unbuffered=unbuffered)
  File "C:\Users\zhi.zhou\Anaconda3\envs\lts\lib\site-packages\pymysql\connections.py", line 775, in _read_query_result
    result.read()
  File "C:\Users\zhi.zhou\Anaconda3\envs\lts\lib\site-packages\pymysql\connections.py", line 1156, in read
    first_packet = self.connection._read_packet()
  File "C:\Users\zhi.zhou\Anaconda3\envs\lts\lib\site-packages\pymysql\connections.py", line 725, in _read_packet
    packet.raise_for_error()
  File "C:\Users\zhi.zhou\Anaconda3\envs\lts\lib\site-packages\pymysql\protocol.py", line 221, in raise_for_error
    err.raise_mysql_exception(self._data)
  File "C:\Users\zhi.zhou\Anaconda3\envs\lts\lib\site-packages\pymysql\err.py", line 143, in raise_mysql_exception
    raise errorclass(errno, errval)
pymysql.err.ProgrammingError: (1064, "You have an error in your SQL syntax; check the manual that corresponds to your MySQL server version for the right syntax to use near '-06' at line 1")

During handling of the above exception, another exception occurred:

Traceback (most recent call last):
  File "C:\Users\zhi.zhou\Anaconda3\envs\lts\lib\site-packages\django\core\handlers\exception.py", line 47, in inner
    response = get_response(request)
  File "C:\Users\zhi.zhou\Anaconda3\envs\lts\lib\site-packages\django\core\handlers\base.py", line 181, in _get_response
    response = wrapped_callback(request, *callback_args, **callback_kwargs)
  File "C:\Users\zhi.zhou\Anaconda3\envs\lts\lib\site-packages\django\views\generic\base.py", line 70, in view
    return self.dispatch(request, *args, **kwargs)
  File "C:\Users\zhi.zhou\Anaconda3\envs\lts\lib\site-packages\django\views\generic\base.py", line 98, in dispatch
    return handler(request, *args, **kwargs)
  File "D:\zhouzhi\gitlit_code\logistic_tracking_system\logistic_tracking_system\lts\views.py", line 2482, in get
    data = json.dumps(data)
  File "C:\Users\zhi.zhou\Anaconda3\envs\lts\lib\json\__init__.py", line 231, in dumps
    return _default_encoder.encode(obj)
  File "C:\Users\zhi.zhou\Anaconda3\envs\lts\lib\json\encoder.py", line 199, in encode
    chunks = self.iterencode(o, _one_shot=True)
  File "C:\Users\zhi.zhou\Anaconda3\envs\lts\lib\json\encoder.py", line 257, in iterencode
    return _iterencode(o, 0)
  File "C:\Users\zhi.zhou\Anaconda3\envs\lts\lib\json\encoder.py", line 180, in default
    o.__class__.__name__)
TypeError: Object of type 'ProgrammingError' is not JSON serializable
[2021-08-19 11:30:53,511][MainThread:17696][task_id:django.utils.autoreload][autoreload.py:251][INFO][D:\zhouzhi\gitlit_code\logistic_tracking_system\logistic_tracking_system\lts\views.py changed, reloading.]
[2021-08-19 11:30:54,578][MainThread:9288][task_id:django.utils.autoreload][autoreload.py:637][INFO][Watching for file changes with StatReloader]
[2021-08-19 11:32:13,005][MainThread:9288][task_id:django.utils.autoreload][autoreload.py:251][INFO][D:\zhouzhi\gitlit_code\logistic_tracking_system\logistic_tracking_system\lts\views.py changed, reloading.]
[2021-08-19 11:32:14,259][MainThread:14700][task_id:django.utils.autoreload][autoreload.py:637][INFO][Watching for file changes with StatReloader]
[2021-08-19 11:32:19,345][MainThread:14700][task_id:django.utils.autoreload][autoreload.py:251][INFO][D:\zhouzhi\gitlit_code\logistic_tracking_system\logistic_tracking_system\lts\views.py changed, reloading.]
[2021-08-19 11:32:20,490][MainThread:15624][task_id:django.utils.autoreload][autoreload.py:637][INFO][Watching for file changes with StatReloader]
[2021-08-19 11:32:24,780][MainThread:15624][task_id:django.utils.autoreload][autoreload.py:251][INFO][D:\zhouzhi\gitlit_code\logistic_tracking_system\logistic_tracking_system\lts\views.py changed, reloading.]
[2021-08-19 11:32:25,919][MainThread:19784][task_id:django.utils.autoreload][autoreload.py:637][INFO][Watching for file changes with StatReloader]
[2021-08-19 11:35:19,028][MainThread:19784][task_id:django.utils.autoreload][autoreload.py:251][INFO][D:\zhouzhi\gitlit_code\logistic_tracking_system\logistic_tracking_system\lts\views.py changed, reloading.]
[2021-08-19 11:35:20,085][MainThread:11944][task_id:django.utils.autoreload][autoreload.py:637][INFO][Watching for file changes with StatReloader]
[2021-08-19 11:56:17,972][MainThread:11944][task_id:django.utils.autoreload][autoreload.py:251][INFO][D:\zhouzhi\gitlit_code\logistic_tracking_system\logistic_tracking_system\lts\views.py changed, reloading.]
[2021-08-19 11:56:19,479][MainThread:14128][task_id:django.utils.autoreload][autoreload.py:637][INFO][Watching for file changes with StatReloader]
[2021-08-19 13:03:27,440][MainThread:14128][task_id:django.utils.autoreload][autoreload.py:251][INFO][D:\zhouzhi\gitlit_code\logistic_tracking_system\logistic_tracking_system\lts\views.py changed, reloading.]
[2021-08-19 13:03:28,544][MainThread:15648][task_id:django.utils.autoreload][autoreload.py:637][INFO][Watching for file changes with StatReloader]
[2021-08-19 13:03:50,039][MainThread:15648][task_id:django.utils.autoreload][autoreload.py:251][INFO][D:\zhouzhi\gitlit_code\logistic_tracking_system\logistic_tracking_system\lts\views.py changed, reloading.]
[2021-08-19 13:03:51,228][MainThread:18480][task_id:django.utils.autoreload][autoreload.py:637][INFO][Watching for file changes with StatReloader]
[2021-08-19 13:05:35,131][MainThread:18480][task_id:django.utils.autoreload][autoreload.py:251][INFO][D:\zhouzhi\gitlit_code\logistic_tracking_system\logistic_tracking_system\lts\views.py changed, reloading.]
[2021-08-19 13:05:36,220][MainThread:18068][task_id:django.utils.autoreload][autoreload.py:637][INFO][Watching for file changes with StatReloader]
[2021-08-19 13:05:41,220][MainThread:18068][task_id:django.utils.autoreload][autoreload.py:251][INFO][D:\zhouzhi\gitlit_code\logistic_tracking_system\logistic_tracking_system\lts\views.py changed, reloading.]
[2021-08-19 13:05:42,825][MainThread:19176][task_id:django.utils.autoreload][autoreload.py:637][INFO][Watching for file changes with StatReloader]
[2021-08-19 13:13:46,907][MainThread:19176][task_id:django.utils.autoreload][autoreload.py:251][INFO][D:\zhouzhi\gitlit_code\logistic_tracking_system\logistic_tracking_system\lts\views.py changed, reloading.]
[2021-08-19 13:13:47,985][MainThread:18072][task_id:django.utils.autoreload][autoreload.py:637][INFO][Watching for file changes with StatReloader]
[2021-08-19 13:17:40,410][MainThread:18072][task_id:django.utils.autoreload][autoreload.py:251][INFO][D:\zhouzhi\gitlit_code\logistic_tracking_system\logistic_tracking_system\lts\views.py changed, reloading.]
[2021-08-19 13:17:41,549][MainThread:5464][task_id:django.utils.autoreload][autoreload.py:637][INFO][Watching for file changes with StatReloader]
[2021-08-19 13:20:02,520][MainThread:5464][task_id:django.utils.autoreload][autoreload.py:251][INFO][D:\zhouzhi\gitlit_code\logistic_tracking_system\logistic_tracking_system\lts\views.py changed, reloading.]
[2021-08-19 13:20:03,629][MainThread:16628][task_id:django.utils.autoreload][autoreload.py:637][INFO][Watching for file changes with StatReloader]
[2021-08-19 13:28:06,621][MainThread:16628][task_id:django.utils.autoreload][autoreload.py:251][INFO][D:\zhouzhi\gitlit_code\logistic_tracking_system\logistic_tracking_system\lts\views.py changed, reloading.]
[2021-08-19 13:28:08,698][MainThread:9556][task_id:django.utils.autoreload][autoreload.py:637][INFO][Watching for file changes with StatReloader]
[2021-08-19 13:28:26,569][MainThread:9556][task_id:django.utils.autoreload][autoreload.py:251][INFO][D:\zhouzhi\gitlit_code\logistic_tracking_system\logistic_tracking_system\lts\views.py changed, reloading.]
[2021-08-19 13:28:28,222][MainThread:19044][task_id:django.utils.autoreload][autoreload.py:637][INFO][Watching for file changes with StatReloader]
[2021-08-19 13:28:43,246][MainThread:19044][task_id:django.utils.autoreload][autoreload.py:251][INFO][D:\zhouzhi\gitlit_code\logistic_tracking_system\logistic_tracking_system\lts\views.py changed, reloading.]
[2021-08-19 13:28:44,667][MainThread:5380][task_id:django.utils.autoreload][autoreload.py:637][INFO][Watching for file changes with StatReloader]
[2021-08-19 13:28:51,847][MainThread:5380][task_id:django.utils.autoreload][autoreload.py:251][INFO][D:\zhouzhi\gitlit_code\logistic_tracking_system\logistic_tracking_system\lts\views.py changed, reloading.]
[2021-08-19 13:28:53,159][MainThread:8900][task_id:django.utils.autoreload][autoreload.py:637][INFO][Watching for file changes with StatReloader]
[2021-08-19 13:29:05,596][MainThread:8900][task_id:django.utils.autoreload][autoreload.py:251][INFO][D:\zhouzhi\gitlit_code\logistic_tracking_system\logistic_tracking_system\lts\views.py changed, reloading.]
[2021-08-19 13:29:06,909][MainThread:7344][task_id:django.utils.autoreload][autoreload.py:637][INFO][Watching for file changes with StatReloader]
[2021-08-19 13:29:20,600][MainThread:7344][task_id:django.utils.autoreload][autoreload.py:251][INFO][D:\zhouzhi\gitlit_code\logistic_tracking_system\logistic_tracking_system\lts\views.py changed, reloading.]
[2021-08-19 13:29:22,013][MainThread:9644][task_id:django.utils.autoreload][autoreload.py:637][INFO][Watching for file changes with StatReloader]
[2021-08-19 13:29:34,297][MainThread:9644][task_id:django.utils.autoreload][autoreload.py:251][INFO][D:\zhouzhi\gitlit_code\logistic_tracking_system\logistic_tracking_system\lts\views.py changed, reloading.]
[2021-08-19 13:29:35,376][MainThread:19068][task_id:django.utils.autoreload][autoreload.py:637][INFO][Watching for file changes with StatReloader]
[2021-08-19 13:29:45,522][MainThread:19068][task_id:django.utils.autoreload][autoreload.py:251][INFO][D:\zhouzhi\gitlit_code\logistic_tracking_system\logistic_tracking_system\lts\views.py changed, reloading.]
[2021-08-19 13:29:46,858][MainThread:20072][task_id:django.utils.autoreload][autoreload.py:637][INFO][Watching for file changes with StatReloader]
[2021-08-19 13:29:55,967][MainThread:20072][task_id:django.utils.autoreload][autoreload.py:251][INFO][D:\zhouzhi\gitlit_code\logistic_tracking_system\logistic_tracking_system\lts\views.py changed, reloading.]
[2021-08-19 13:29:57,337][MainThread:19840][task_id:django.utils.autoreload][autoreload.py:637][INFO][Watching for file changes with StatReloader]
[2021-08-19 13:30:05,498][MainThread:19840][task_id:django.utils.autoreload][autoreload.py:251][INFO][D:\zhouzhi\gitlit_code\logistic_tracking_system\logistic_tracking_system\lts\views.py changed, reloading.]
[2021-08-19 13:30:06,716][MainThread:17360][task_id:django.utils.autoreload][autoreload.py:637][INFO][Watching for file changes with StatReloader]
[2021-08-19 13:30:17,208][MainThread:17360][task_id:django.utils.autoreload][autoreload.py:251][INFO][D:\zhouzhi\gitlit_code\logistic_tracking_system\logistic_tracking_system\lts\views.py changed, reloading.]
[2021-08-19 13:30:18,325][MainThread:2788][task_id:django.utils.autoreload][autoreload.py:637][INFO][Watching for file changes with StatReloader]
[2021-08-19 13:31:21,918][MainThread:2788][task_id:django.utils.autoreload][autoreload.py:251][INFO][D:\zhouzhi\gitlit_code\logistic_tracking_system\logistic_tracking_system\lts\views.py changed, reloading.]
[2021-08-19 13:31:22,980][MainThread:17920][task_id:django.utils.autoreload][autoreload.py:637][INFO][Watching for file changes with StatReloader]
[2021-08-19 13:33:08,436][MainThread:17920][task_id:django.utils.autoreload][autoreload.py:251][INFO][D:\zhouzhi\gitlit_code\logistic_tracking_system\logistic_tracking_system\lts\views.py changed, reloading.]
[2021-08-19 13:33:09,514][MainThread:14976][task_id:django.utils.autoreload][autoreload.py:637][INFO][Watching for file changes with StatReloader]
[2021-08-19 13:36:38,868][MainThread:14976][task_id:django.utils.autoreload][autoreload.py:251][INFO][D:\zhouzhi\gitlit_code\logistic_tracking_system\logistic_tracking_system\lts\views.py changed, reloading.]
[2021-08-19 13:36:39,925][MainThread:15308][task_id:django.utils.autoreload][autoreload.py:637][INFO][Watching for file changes with StatReloader]
[2021-08-19 13:41:13,150][MainThread:15308][task_id:django.utils.autoreload][autoreload.py:251][INFO][D:\zhouzhi\gitlit_code\logistic_tracking_system\logistic_tracking_system\lts\views.py changed, reloading.]
[2021-08-19 13:41:14,229][MainThread:4528][task_id:django.utils.autoreload][autoreload.py:637][INFO][Watching for file changes with StatReloader]
[2021-08-19 13:43:36,380][MainThread:4528][task_id:django.utils.autoreload][autoreload.py:251][INFO][D:\zhouzhi\gitlit_code\logistic_tracking_system\logistic_tracking_system\lts\views.py changed, reloading.]
[2021-08-19 13:43:37,483][MainThread:14744][task_id:django.utils.autoreload][autoreload.py:637][INFO][Watching for file changes with StatReloader]
[2021-08-19 13:45:36,242][MainThread:14744][task_id:django.utils.autoreload][autoreload.py:251][INFO][D:\zhouzhi\gitlit_code\logistic_tracking_system\logistic_tracking_system\lts\views.py changed, reloading.]
[2021-08-19 13:45:37,329][MainThread:16672][task_id:django.utils.autoreload][autoreload.py:637][INFO][Watching for file changes with StatReloader]
[2021-08-19 14:00:52,193][MainThread:16672][task_id:django.utils.autoreload][autoreload.py:251][INFO][D:\zhouzhi\gitlit_code\logistic_tracking_system\logistic_tracking_system\lts\views.py changed, reloading.]
[2021-08-19 14:00:53,568][MainThread:19428][task_id:django.utils.autoreload][autoreload.py:637][INFO][Watching for file changes with StatReloader]
[2021-08-19 14:03:28,440][MainThread:19428][task_id:django.utils.autoreload][autoreload.py:251][INFO][D:\zhouzhi\gitlit_code\logistic_tracking_system\logistic_tracking_system\lts\views.py changed, reloading.]
[2021-08-19 14:03:29,506][MainThread:13268][task_id:django.utils.autoreload][autoreload.py:637][INFO][Watching for file changes with StatReloader]
[2021-08-19 14:10:21,035][MainThread:13268][task_id:django.utils.autoreload][autoreload.py:251][INFO][D:\zhouzhi\gitlit_code\logistic_tracking_system\logistic_tracking_system\lts\views.py changed, reloading.]
[2021-08-19 14:10:22,140][MainThread:15452][task_id:django.utils.autoreload][autoreload.py:637][INFO][Watching for file changes with StatReloader]
[2021-08-19 14:10:46,460][MainThread:15452][task_id:django.utils.autoreload][autoreload.py:251][INFO][D:\zhouzhi\gitlit_code\logistic_tracking_system\logistic_tracking_system\lts\views.py changed, reloading.]
[2021-08-19 14:10:47,557][MainThread:14972][task_id:django.utils.autoreload][autoreload.py:637][INFO][Watching for file changes with StatReloader]
[2021-08-19 14:10:56,173][MainThread:14972][task_id:django.utils.autoreload][autoreload.py:251][INFO][D:\zhouzhi\gitlit_code\logistic_tracking_system\logistic_tracking_system\lts\views.py changed, reloading.]
[2021-08-19 14:10:57,266][MainThread:20344][task_id:django.utils.autoreload][autoreload.py:637][INFO][Watching for file changes with StatReloader]
[2021-08-19 14:11:04,934][MainThread:20344][task_id:django.utils.autoreload][autoreload.py:251][INFO][D:\zhouzhi\gitlit_code\logistic_tracking_system\logistic_tracking_system\lts\views.py changed, reloading.]
[2021-08-19 14:11:06,277][MainThread:13064][task_id:django.utils.autoreload][autoreload.py:637][INFO][Watching for file changes with StatReloader]
[2021-08-19 14:11:10,284][MainThread:13064][task_id:django.utils.autoreload][autoreload.py:251][INFO][D:\zhouzhi\gitlit_code\logistic_tracking_system\logistic_tracking_system\lts\views.py changed, reloading.]
[2021-08-19 14:11:12,088][MainThread:2940][task_id:django.utils.autoreload][autoreload.py:637][INFO][Watching for file changes with StatReloader]
[2021-08-19 14:12:09,942][MainThread:2940][task_id:django.utils.autoreload][autoreload.py:251][INFO][D:\zhouzhi\gitlit_code\logistic_tracking_system\logistic_tracking_system\lts\views.py changed, reloading.]
[2021-08-19 14:12:11,694][MainThread:8372][task_id:django.utils.autoreload][autoreload.py:637][INFO][Watching for file changes with StatReloader]
[2021-08-19 14:15:44,713][MainThread:8372][task_id:django.utils.autoreload][autoreload.py:251][INFO][D:\zhouzhi\gitlit_code\logistic_tracking_system\logistic_tracking_system\lts\views.py changed, reloading.]
[2021-08-19 14:15:46,177][MainThread:16672][task_id:django.utils.autoreload][autoreload.py:637][INFO][Watching for file changes with StatReloader]
[2021-08-19 14:16:01,115][MainThread:16672][task_id:django.utils.autoreload][autoreload.py:251][INFO][D:\zhouzhi\gitlit_code\logistic_tracking_system\logistic_tracking_system\lts\views.py changed, reloading.]
[2021-08-19 14:16:02,281][MainThread:18972][task_id:django.utils.autoreload][autoreload.py:637][INFO][Watching for file changes with StatReloader]
[2021-08-19 14:16:08,896][MainThread:18972][task_id:django.utils.autoreload][autoreload.py:251][INFO][D:\zhouzhi\gitlit_code\logistic_tracking_system\logistic_tracking_system\lts\views.py changed, reloading.]
[2021-08-19 14:16:10,031][MainThread:1432][task_id:django.utils.autoreload][autoreload.py:637][INFO][Watching for file changes with StatReloader]
[2021-08-19 14:16:15,408][MainThread:1432][task_id:django.utils.autoreload][autoreload.py:251][INFO][D:\zhouzhi\gitlit_code\logistic_tracking_system\logistic_tracking_system\lts\views.py changed, reloading.]
[2021-08-19 14:16:16,753][MainThread:1992][task_id:django.utils.autoreload][autoreload.py:637][INFO][Watching for file changes with StatReloader]
[2021-08-19 14:16:24,336][MainThread:1992][task_id:django.utils.autoreload][autoreload.py:251][INFO][D:\zhouzhi\gitlit_code\logistic_tracking_system\logistic_tracking_system\lts\views.py changed, reloading.]
[2021-08-19 14:16:25,643][MainThread:15892][task_id:django.utils.autoreload][autoreload.py:637][INFO][Watching for file changes with StatReloader]
[2021-08-19 14:16:29,773][MainThread:15892][task_id:django.utils.autoreload][autoreload.py:251][INFO][D:\zhouzhi\gitlit_code\logistic_tracking_system\logistic_tracking_system\lts\views.py changed, reloading.]
[2021-08-19 14:16:30,913][MainThread:4320][task_id:django.utils.autoreload][autoreload.py:637][INFO][Watching for file changes with StatReloader]
[2021-08-19 14:16:35,017][MainThread:4320][task_id:django.utils.autoreload][autoreload.py:251][INFO][D:\zhouzhi\gitlit_code\logistic_tracking_system\logistic_tracking_system\lts\views.py changed, reloading.]
[2021-08-19 14:16:36,406][MainThread:15892][task_id:django.utils.autoreload][autoreload.py:637][INFO][Watching for file changes with StatReloader]
[2021-08-19 14:16:39,322][MainThread:15892][task_id:django.utils.autoreload][autoreload.py:251][INFO][D:\zhouzhi\gitlit_code\logistic_tracking_system\logistic_tracking_system\lts\views.py changed, reloading.]
[2021-08-19 14:16:40,552][MainThread:2996][task_id:django.utils.autoreload][autoreload.py:637][INFO][Watching for file changes with StatReloader]
[2021-08-19 14:16:49,439][MainThread:2996][task_id:django.utils.autoreload][autoreload.py:251][INFO][D:\zhouzhi\gitlit_code\logistic_tracking_system\logistic_tracking_system\lts\views.py changed, reloading.]
[2021-08-19 14:16:50,644][MainThread:16736][task_id:django.utils.autoreload][autoreload.py:637][INFO][Watching for file changes with StatReloader]
[2021-08-19 14:17:49,515][MainThread:16736][task_id:django.utils.autoreload][autoreload.py:251][INFO][D:\zhouzhi\gitlit_code\logistic_tracking_system\logistic_tracking_system\lts\views.py changed, reloading.]
[2021-08-19 14:17:50,789][MainThread:10588][task_id:django.utils.autoreload][autoreload.py:637][INFO][Watching for file changes with StatReloader]
[2021-08-19 14:21:29,551][MainThread:10588][task_id:django.utils.autoreload][autoreload.py:251][INFO][D:\zhouzhi\gitlit_code\logistic_tracking_system\logistic_tracking_system\lts\views.py changed, reloading.]
[2021-08-19 14:21:30,640][MainThread:20644][task_id:django.utils.autoreload][autoreload.py:637][INFO][Watching for file changes with StatReloader]
[2021-08-19 14:28:46,404][MainThread:20644][task_id:django.utils.autoreload][autoreload.py:251][INFO][D:\zhouzhi\gitlit_code\logistic_tracking_system\logistic_tracking_system\lts\views.py changed, reloading.]
[2021-08-19 14:28:47,542][MainThread:21048][task_id:django.utils.autoreload][autoreload.py:637][INFO][Watching for file changes with StatReloader]
[2021-08-19 14:31:55,418][MainThread:21048][task_id:django.utils.autoreload][autoreload.py:251][INFO][D:\zhouzhi\gitlit_code\logistic_tracking_system\logistic_tracking_system\lts\views.py changed, reloading.]
[2021-08-19 14:31:56,475][MainThread:21392][task_id:django.utils.autoreload][autoreload.py:637][INFO][Watching for file changes with StatReloader]
[2021-08-19 14:35:18,571][MainThread:21392][task_id:django.utils.autoreload][autoreload.py:251][INFO][D:\zhouzhi\gitlit_code\logistic_tracking_system\logistic_tracking_system\lts\views.py changed, reloading.]
[2021-08-19 14:35:19,625][MainThread:5164][task_id:django.utils.autoreload][autoreload.py:637][INFO][Watching for file changes with StatReloader]
[2021-08-19 14:37:56,787][MainThread:5164][task_id:django.utils.autoreload][autoreload.py:251][INFO][D:\zhouzhi\gitlit_code\logistic_tracking_system\logistic_tracking_system\lts\views.py changed, reloading.]
[2021-08-19 14:37:57,851][MainThread:13596][task_id:django.utils.autoreload][autoreload.py:637][INFO][Watching for file changes with StatReloader]
[2021-08-19 14:40:40,254][MainThread:13596][task_id:django.utils.autoreload][autoreload.py:251][INFO][D:\zhouzhi\gitlit_code\logistic_tracking_system\logistic_tracking_system\lts\views.py changed, reloading.]
[2021-08-19 14:40:41,285][MainThread:17876][task_id:django.utils.autoreload][autoreload.py:637][INFO][Watching for file changes with StatReloader]
[2021-08-19 14:42:51,676][MainThread:17876][task_id:django.utils.autoreload][autoreload.py:251][INFO][D:\zhouzhi\gitlit_code\logistic_tracking_system\logistic_tracking_system\lts\views.py changed, reloading.]
[2021-08-19 14:42:52,736][MainThread:3120][task_id:django.utils.autoreload][autoreload.py:637][INFO][Watching for file changes with StatReloader]
[2021-08-19 14:43:40,097][MainThread:3120][task_id:django.utils.autoreload][autoreload.py:251][INFO][D:\zhouzhi\gitlit_code\logistic_tracking_system\logistic_tracking_system\lts\views.py changed, reloading.]
[2021-08-19 14:43:41,141][MainThread:21044][task_id:django.utils.autoreload][autoreload.py:637][INFO][Watching for file changes with StatReloader]
[2021-08-19 14:44:58,527][MainThread:21044][task_id:django.utils.autoreload][autoreload.py:251][INFO][D:\zhouzhi\gitlit_code\logistic_tracking_system\logistic_tracking_system\lts\views.py changed, reloading.]
[2021-08-19 14:44:59,626][MainThread:1968][task_id:django.utils.autoreload][autoreload.py:637][INFO][Watching for file changes with StatReloader]
[2021-08-19 14:45:09,916][MainThread:1968][task_id:django.utils.autoreload][autoreload.py:251][INFO][D:\zhouzhi\gitlit_code\logistic_tracking_system\logistic_tracking_system\lts\urls.py changed, reloading.]
[2021-08-19 14:45:11,012][MainThread:18532][task_id:django.utils.autoreload][autoreload.py:637][INFO][Watching for file changes with StatReloader]
[2021-08-19 14:46:16,971][MainThread:18532][task_id:django.utils.autoreload][autoreload.py:251][INFO][D:\zhouzhi\gitlit_code\logistic_tracking_system\logistic_tracking_system\lts\urls.py changed, reloading.]
[2021-08-19 14:46:18,062][MainThread:18568][task_id:django.utils.autoreload][autoreload.py:637][INFO][Watching for file changes with StatReloader]
[2021-08-19 14:48:21,272][MainThread:18568][task_id:django.utils.autoreload][autoreload.py:251][INFO][D:\zhouzhi\gitlit_code\logistic_tracking_system\logistic_tracking_system\lts\views.py changed, reloading.]
[2021-08-19 14:48:22,375][MainThread:13064][task_id:django.utils.autoreload][autoreload.py:637][INFO][Watching for file changes with StatReloader]
[2021-08-19 14:48:51,104][MainThread:13064][task_id:django.utils.autoreload][autoreload.py:251][INFO][D:\zhouzhi\gitlit_code\logistic_tracking_system\logistic_tracking_system\lts\views.py changed, reloading.]
[2021-08-19 14:48:52,188][MainThread:15268][task_id:django.utils.autoreload][autoreload.py:637][INFO][Watching for file changes with StatReloader]
[2021-08-19 14:50:39,284][MainThread:15268][task_id:django.utils.autoreload][autoreload.py:251][INFO][D:\zhouzhi\gitlit_code\logistic_tracking_system\logistic_tracking_system\lts\urls.py changed, reloading.]
[2021-08-19 14:50:40,388][MainThread:21384][task_id:django.utils.autoreload][autoreload.py:637][INFO][Watching for file changes with StatReloader]
[2021-08-19 15:02:19,091][Thread-6:13496][task_id:lts.views][views.py:1906][ERROR][创建产品详情表失败]
[2021-08-19 15:02:33,615][Thread-6:13496][task_id:lts.views][views.py:1906][ERROR][创建产品详情表失败]
[2021-08-19 15:03:32,783][Thread-6:13496][task_id:lts.views][views.py:7680][ERROR][创建数据表成失败]
[2021-08-19 15:03:42,630][Thread-6:13496][task_id:lts.views][views.py:7680][ERROR][创建数据表成失败]
[2021-08-19 15:04:46,414][Thread-8:21208][task_id:lts.views][views.py:7680][ERROR][创建数据表成失败]
[2021-08-19 15:04:50,633][MainThread:21384][task_id:django.utils.autoreload][autoreload.py:251][INFO][D:\zhouzhi\gitlit_code\logistic_tracking_system\logistic_tracking_system\lts\views.py changed, reloading.]
[2021-08-19 15:04:52,386][MainThread:4420][task_id:django.utils.autoreload][autoreload.py:637][INFO][Watching for file changes with StatReloader]
[2021-08-19 15:05:06,199][Thread-1:21496][task_id:lts.views][views.py:7683][ERROR][创建数据表成失败]
[2021-08-19 15:08:17,096][Thread-4:20612][task_id:lts.views][views.py:7683][ERROR][创建数据表成失败]
[2021-08-19 15:09:37,899][MainThread:4420][task_id:django.utils.autoreload][autoreload.py:251][INFO][D:\zhouzhi\gitlit_code\logistic_tracking_system\logistic_tracking_system\lts\views.py changed, reloading.]
[2021-08-19 15:09:38,976][MainThread:21096][task_id:django.utils.autoreload][autoreload.py:637][INFO][Watching for file changes with StatReloader]
[2021-08-19 15:11:29,592][MainThread:21096][task_id:django.utils.autoreload][autoreload.py:251][INFO][D:\zhouzhi\gitlit_code\logistic_tracking_system\logistic_tracking_system\lts\views.py changed, reloading.]
[2021-08-19 15:11:30,743][MainThread:13152][task_id:django.utils.autoreload][autoreload.py:637][INFO][Watching for file changes with StatReloader]
[2021-08-19 15:11:55,742][MainThread:13152][task_id:django.utils.autoreload][autoreload.py:251][INFO][D:\zhouzhi\gitlit_code\logistic_tracking_system\logistic_tracking_system\lts\views.py changed, reloading.]
[2021-08-19 15:11:56,823][MainThread:20236][task_id:django.utils.autoreload][autoreload.py:637][INFO][Watching for file changes with StatReloader]
[2021-08-19 15:12:46,571][MainThread:20236][task_id:django.utils.autoreload][autoreload.py:251][INFO][D:\zhouzhi\gitlit_code\logistic_tracking_system\logistic_tracking_system\lts\views.py changed, reloading.]
[2021-08-19 15:12:48,323][MainThread:9144][task_id:django.utils.autoreload][autoreload.py:637][INFO][Watching for file changes with StatReloader]
[2021-08-19 15:13:01,059][Thread-1:9016][task_id:lts.views][views.py:7688][ERROR][创建数据表成失败]
[2021-08-19 15:16:04,949][MainThread:9144][task_id:django.utils.autoreload][autoreload.py:251][INFO][D:\zhouzhi\gitlit_code\logistic_tracking_system\logistic_tracking_system\lts\views.py changed, reloading.]
[2021-08-19 15:16:06,044][MainThread:16940][task_id:django.utils.autoreload][autoreload.py:637][INFO][Watching for file changes with StatReloader]
[2021-08-19 15:16:08,498][Thread-1:21336][task_id:lts.views][views.py:7688][ERROR][创建数据表成失败]
[2021-08-19 15:17:19,632][Thread-1:21336][task_id:lts.views][views.py:7688][ERROR][创建数据表成失败]
[2021-08-19 15:19:04,589][MainThread:16940][task_id:django.utils.autoreload][autoreload.py:251][INFO][D:\zhouzhi\gitlit_code\logistic_tracking_system\logistic_tracking_system\lts\views.py changed, reloading.]
[2021-08-19 15:19:05,683][MainThread:2888][task_id:django.utils.autoreload][autoreload.py:637][INFO][Watching for file changes with StatReloader]
[2021-08-19 15:19:35,076][Thread-1:16036][task_id:lts.views][views.py:7690][ERROR][创建数据表成失败]
[2021-08-19 15:23:44,848][MainThread:2888][task_id:django.utils.autoreload][autoreload.py:251][INFO][D:\zhouzhi\gitlit_code\logistic_tracking_system\logistic_tracking_system\lts\views.py changed, reloading.]
[2021-08-19 15:23:46,531][MainThread:19856][task_id:django.utils.autoreload][autoreload.py:637][INFO][Watching for file changes with StatReloader]
[2021-08-19 15:23:50,836][Thread-1:20640][task_id:lts.views][views.py:7700][ERROR][创建数据表成失败]
[2021-08-19 15:26:10,131][MainThread:19856][task_id:django.utils.autoreload][autoreload.py:251][INFO][D:\zhouzhi\gitlit_code\logistic_tracking_system\logistic_tracking_system\lts\views.py changed, reloading.]
[2021-08-19 15:26:11,222][MainThread:15512][task_id:django.utils.autoreload][autoreload.py:637][INFO][Watching for file changes with StatReloader]
[2021-08-19 15:28:12,894][MainThread:15512][task_id:django.utils.autoreload][autoreload.py:251][INFO][D:\zhouzhi\gitlit_code\logistic_tracking_system\logistic_tracking_system\lts\views.py changed, reloading.]
[2021-08-19 15:28:13,998][MainThread:11932][task_id:django.utils.autoreload][autoreload.py:637][INFO][Watching for file changes with StatReloader]
[2021-08-19 15:28:53,438][MainThread:11932][task_id:django.utils.autoreload][autoreload.py:251][INFO][D:\zhouzhi\gitlit_code\logistic_tracking_system\logistic_tracking_system\lts\views.py changed, reloading.]
[2021-08-19 15:28:54,571][MainThread:9776][task_id:django.utils.autoreload][autoreload.py:637][INFO][Watching for file changes with StatReloader]
[2021-08-19 15:29:17,110][MainThread:9776][task_id:django.utils.autoreload][autoreload.py:251][INFO][D:\zhouzhi\gitlit_code\logistic_tracking_system\logistic_tracking_system\lts\views.py changed, reloading.]
[2021-08-19 15:29:18,333][MainThread:572][task_id:django.utils.autoreload][autoreload.py:637][INFO][Watching for file changes with StatReloader]
[2021-08-19 15:31:07,179][MainThread:572][task_id:django.utils.autoreload][autoreload.py:251][INFO][D:\zhouzhi\gitlit_code\logistic_tracking_system\logistic_tracking_system\lts\views.py changed, reloading.]
[2021-08-19 15:31:08,239][MainThread:18144][task_id:django.utils.autoreload][autoreload.py:637][INFO][Watching for file changes with StatReloader]
[2021-08-19 15:32:43,363][Thread-1:18284][task_id:lts.views][views.py:7714][ERROR][创建数据表成失败]
[2021-08-19 15:34:58,402][MainThread:18144][task_id:django.utils.autoreload][autoreload.py:251][INFO][D:\zhouzhi\gitlit_code\logistic_tracking_system\logistic_tracking_system\lts\views.py changed, reloading.]
[2021-08-19 15:34:59,472][MainThread:14952][task_id:django.utils.autoreload][autoreload.py:637][INFO][Watching for file changes with StatReloader]
[2021-08-19 15:35:41,567][MainThread:14952][task_id:django.utils.autoreload][autoreload.py:251][INFO][D:\zhouzhi\gitlit_code\logistic_tracking_system\logistic_tracking_system\lts\views.py changed, reloading.]
[2021-08-19 15:35:42,891][MainThread:18772][task_id:django.utils.autoreload][autoreload.py:637][INFO][Watching for file changes with StatReloader]
[2021-08-19 15:36:57,534][MainThread:18772][task_id:django.utils.autoreload][autoreload.py:251][INFO][D:\zhouzhi\gitlit_code\logistic_tracking_system\logistic_tracking_system\lts\views.py changed, reloading.]
[2021-08-19 15:36:58,616][MainThread:9224][task_id:django.utils.autoreload][autoreload.py:637][INFO][Watching for file changes with StatReloader]
[2021-08-19 15:38:10,351][Thread-1:8900][task_id:lts.views][views.py:7706][INFO][创建数据表成功]
[2021-08-19 15:39:26,555][Thread-2:21360][task_id:lts.views][views.py:7706][INFO][创建数据表成功]
[2021-08-19 15:41:30,323][Thread-6:9288][task_id:django.request][log.py:230][ERROR][Internal Server Error: /logistic/LogisticWorkCodeName]
Traceback (most recent call last):
  File "D:\zhouzhi\gitlit_code\logistic_tracking_system\logistic_tracking_system\lts\views.py", line 3929, in get
    drs = db.execute_sql(conn, sql)
  File "D:\zhouzhi\gitlit_code\logistic_tracking_system\logistic_tracking_system\common\db.py", line 45, in execute_sql
    cursor.execute(sql)
  File "C:\Users\zhi.zhou\Anaconda3\envs\lts\lib\site-packages\pymysql\cursors.py", line 148, in execute
    result = self._query(query)
  File "C:\Users\zhi.zhou\Anaconda3\envs\lts\lib\site-packages\pymysql\cursors.py", line 310, in _query
    conn.query(q)
  File "C:\Users\zhi.zhou\Anaconda3\envs\lts\lib\site-packages\pymysql\connections.py", line 548, in query
    self._affected_rows = self._read_query_result(unbuffered=unbuffered)
  File "C:\Users\zhi.zhou\Anaconda3\envs\lts\lib\site-packages\pymysql\connections.py", line 775, in _read_query_result
    result.read()
  File "C:\Users\zhi.zhou\Anaconda3\envs\lts\lib\site-packages\pymysql\connections.py", line 1156, in read
    first_packet = self.connection._read_packet()
  File "C:\Users\zhi.zhou\Anaconda3\envs\lts\lib\site-packages\pymysql\connections.py", line 725, in _read_packet
    packet.raise_for_error()
  File "C:\Users\zhi.zhou\Anaconda3\envs\lts\lib\site-packages\pymysql\protocol.py", line 221, in raise_for_error
    err.raise_mysql_exception(self._data)
  File "C:\Users\zhi.zhou\Anaconda3\envs\lts\lib\site-packages\pymysql\err.py", line 143, in raise_mysql_exception
    raise errorclass(errno, errval)
pymysql.err.OperationalError: (1046, 'No database selected')

During handling of the above exception, another exception occurred:

Traceback (most recent call last):
  File "C:\Users\zhi.zhou\Anaconda3\envs\lts\lib\site-packages\django\core\handlers\exception.py", line 47, in inner
    response = get_response(request)
  File "C:\Users\zhi.zhou\Anaconda3\envs\lts\lib\site-packages\django\core\handlers\base.py", line 181, in _get_response
    response = wrapped_callback(request, *callback_args, **callback_kwargs)
  File "C:\Users\zhi.zhou\Anaconda3\envs\lts\lib\site-packages\django\views\generic\base.py", line 70, in view
    return self.dispatch(request, *args, **kwargs)
  File "C:\Users\zhi.zhou\Anaconda3\envs\lts\lib\site-packages\django\views\generic\base.py", line 98, in dispatch
    return handler(request, *args, **kwargs)
  File "D:\zhouzhi\gitlit_code\logistic_tracking_system\logistic_tracking_system\lts\views.py", line 3946, in get
    data = json.dumps(data)
  File "C:\Users\zhi.zhou\Anaconda3\envs\lts\lib\json\__init__.py", line 231, in dumps
    return _default_encoder.encode(obj)
  File "C:\Users\zhi.zhou\Anaconda3\envs\lts\lib\json\encoder.py", line 199, in encode
    chunks = self.iterencode(o, _one_shot=True)
  File "C:\Users\zhi.zhou\Anaconda3\envs\lts\lib\json\encoder.py", line 257, in iterencode
    return _iterencode(o, 0)
  File "C:\Users\zhi.zhou\Anaconda3\envs\lts\lib\json\encoder.py", line 180, in default
    o.__class__.__name__)
TypeError: Object of type 'OperationalError' is not JSON serializable
[2021-08-19 15:41:30,346][Thread-5:14196][task_id:django.request][log.py:230][ERROR][Internal Server Error: /logistic/LogisticWorkManage]
Traceback (most recent call last):
  File "D:\zhouzhi\gitlit_code\logistic_tracking_system\logistic_tracking_system\lts\views.py", line 7447, in get
    drs = db.execute_sql(conn, sql)
  File "D:\zhouzhi\gitlit_code\logistic_tracking_system\logistic_tracking_system\common\db.py", line 45, in execute_sql
    cursor.execute(sql)
  File "C:\Users\zhi.zhou\Anaconda3\envs\lts\lib\site-packages\pymysql\cursors.py", line 148, in execute
    result = self._query(query)
  File "C:\Users\zhi.zhou\Anaconda3\envs\lts\lib\site-packages\pymysql\cursors.py", line 310, in _query
    conn.query(q)
  File "C:\Users\zhi.zhou\Anaconda3\envs\lts\lib\site-packages\pymysql\connections.py", line 548, in query
    self._affected_rows = self._read_query_result(unbuffered=unbuffered)
  File "C:\Users\zhi.zhou\Anaconda3\envs\lts\lib\site-packages\pymysql\connections.py", line 775, in _read_query_result
    result.read()
  File "C:\Users\zhi.zhou\Anaconda3\envs\lts\lib\site-packages\pymysql\connections.py", line 1156, in read
    first_packet = self.connection._read_packet()
  File "C:\Users\zhi.zhou\Anaconda3\envs\lts\lib\site-packages\pymysql\connections.py", line 725, in _read_packet
    packet.raise_for_error()
  File "C:\Users\zhi.zhou\Anaconda3\envs\lts\lib\site-packages\pymysql\protocol.py", line 221, in raise_for_error
    err.raise_mysql_exception(self._data)
  File "C:\Users\zhi.zhou\Anaconda3\envs\lts\lib\site-packages\pymysql\err.py", line 143, in raise_mysql_exception
    raise errorclass(errno, errval)
pymysql.err.OperationalError: (1046, 'No database selected')

During handling of the above exception, another exception occurred:

Traceback (most recent call last):
  File "C:\Users\zhi.zhou\Anaconda3\envs\lts\lib\site-packages\django\core\handlers\exception.py", line 47, in inner
    response = get_response(request)
  File "C:\Users\zhi.zhou\Anaconda3\envs\lts\lib\site-packages\django\core\handlers\base.py", line 181, in _get_response
    response = wrapped_callback(request, *callback_args, **callback_kwargs)
  File "C:\Users\zhi.zhou\Anaconda3\envs\lts\lib\site-packages\django\views\generic\base.py", line 70, in view
    return self.dispatch(request, *args, **kwargs)
  File "C:\Users\zhi.zhou\Anaconda3\envs\lts\lib\site-packages\django\views\generic\base.py", line 98, in dispatch
    return handler(request, *args, **kwargs)
  File "D:\zhouzhi\gitlit_code\logistic_tracking_system\logistic_tracking_system\lts\views.py", line 7489, in get
    result = json.dumps(result)
  File "C:\Users\zhi.zhou\Anaconda3\envs\lts\lib\json\__init__.py", line 231, in dumps
    return _default_encoder.encode(obj)
  File "C:\Users\zhi.zhou\Anaconda3\envs\lts\lib\json\encoder.py", line 199, in encode
    chunks = self.iterencode(o, _one_shot=True)
  File "C:\Users\zhi.zhou\Anaconda3\envs\lts\lib\json\encoder.py", line 257, in iterencode
    return _iterencode(o, 0)
  File "C:\Users\zhi.zhou\Anaconda3\envs\lts\lib\json\encoder.py", line 180, in default
    o.__class__.__name__)
TypeError: Object of type 'OperationalError' is not JSON serializable
[2021-08-19 15:42:45,382][Thread-7:20868][task_id:lts.views][views.py:7706][INFO][创建数据表成功]
[2021-08-19 15:44:49,482][MainThread:9224][task_id:django.utils.autoreload][autoreload.py:251][INFO][D:\zhouzhi\gitlit_code\logistic_tracking_system\logistic_tracking_system\lts\views.py changed, reloading.]
[2021-08-19 15:44:50,553][MainThread:9488][task_id:django.utils.autoreload][autoreload.py:637][INFO][Watching for file changes with StatReloader]
[2021-08-19 15:46:07,846][Thread-1:21404][task_id:lts.views][views.py:7706][INFO][创建数据表成功]
[2021-08-19 15:47:07,792][MainThread:9488][task_id:django.utils.autoreload][autoreload.py:251][INFO][D:\zhouzhi\gitlit_code\logistic_tracking_system\logistic_tracking_system\lts\views.py changed, reloading.]
[2021-08-19 15:47:08,867][MainThread:2980][task_id:django.utils.autoreload][autoreload.py:637][INFO][Watching for file changes with StatReloader]
[2021-08-19 15:48:52,613][MainThread:2980][task_id:django.utils.autoreload][autoreload.py:251][INFO][D:\zhouzhi\gitlit_code\logistic_tracking_system\logistic_tracking_system\lts\views.py changed, reloading.]
[2021-08-19 15:48:53,697][MainThread:21304][task_id:django.utils.autoreload][autoreload.py:637][INFO][Watching for file changes with StatReloader]
[2021-08-19 15:49:11,135][MainThread:21304][task_id:django.utils.autoreload][autoreload.py:251][INFO][D:\zhouzhi\gitlit_code\logistic_tracking_system\logistic_tracking_system\lts\views.py changed, reloading.]
[2021-08-19 15:49:12,996][MainThread:20504][task_id:django.utils.autoreload][autoreload.py:637][INFO][Watching for file changes with StatReloader]
[2021-08-19 15:51:52,293][MainThread:20504][task_id:django.utils.autoreload][autoreload.py:251][INFO][D:\zhouzhi\gitlit_code\logistic_tracking_system\logistic_tracking_system\lts\views.py changed, reloading.]
[2021-08-19 15:51:53,406][MainThread:12520][task_id:django.utils.autoreload][autoreload.py:637][INFO][Watching for file changes with StatReloader]
[2021-08-19 15:54:28,400][MainThread:12520][task_id:django.utils.autoreload][autoreload.py:251][INFO][D:\zhouzhi\gitlit_code\logistic_tracking_system\logistic_tracking_system\lts\views.py changed, reloading.]
[2021-08-19 15:54:29,507][MainThread:17820][task_id:django.utils.autoreload][autoreload.py:637][INFO][Watching for file changes with StatReloader]
[2021-08-19 15:54:34,852][MainThread:17820][task_id:django.utils.autoreload][autoreload.py:251][INFO][D:\zhouzhi\gitlit_code\logistic_tracking_system\logistic_tracking_system\lts\views.py changed, reloading.]
[2021-08-19 15:54:36,034][MainThread:4328][task_id:django.utils.autoreload][autoreload.py:637][INFO][Watching for file changes with StatReloader]
[2021-08-19 15:54:39,392][MainThread:4328][task_id:django.utils.autoreload][autoreload.py:251][INFO][D:\zhouzhi\gitlit_code\logistic_tracking_system\logistic_tracking_system\lts\views.py changed, reloading.]
[2021-08-19 15:54:40,574][MainThread:21160][task_id:django.utils.autoreload][autoreload.py:637][INFO][Watching for file changes with StatReloader]
[2021-08-19 15:54:43,619][MainThread:21160][task_id:django.utils.autoreload][autoreload.py:251][INFO][D:\zhouzhi\gitlit_code\logistic_tracking_system\logistic_tracking_system\lts\views.py changed, reloading.]
[2021-08-19 15:54:44,828][MainThread:19140][task_id:django.utils.autoreload][autoreload.py:637][INFO][Watching for file changes with StatReloader]
[2021-08-19 15:54:55,565][MainThread:19140][task_id:django.utils.autoreload][autoreload.py:251][INFO][D:\zhouzhi\gitlit_code\logistic_tracking_system\logistic_tracking_system\lts\views.py changed, reloading.]
[2021-08-19 15:54:56,650][MainThread:832][task_id:django.utils.autoreload][autoreload.py:637][INFO][Watching for file changes with StatReloader]
[2021-08-19 15:56:18,045][MainThread:832][task_id:django.utils.autoreload][autoreload.py:251][INFO][D:\zhouzhi\gitlit_code\logistic_tracking_system\logistic_tracking_system\lts\views.py changed, reloading.]
[2021-08-19 15:56:19,144][MainThread:21304][task_id:django.utils.autoreload][autoreload.py:637][INFO][Watching for file changes with StatReloader]
[2021-08-19 15:59:48,951][MainThread:21304][task_id:django.utils.autoreload][autoreload.py:251][INFO][D:\zhouzhi\gitlit_code\logistic_tracking_system\logistic_tracking_system\lts\views.py changed, reloading.]
[2021-08-19 15:59:50,054][MainThread:18532][task_id:django.utils.autoreload][autoreload.py:637][INFO][Watching for file changes with StatReloader]
[2021-08-19 16:01:29,852][MainThread:18532][task_id:django.utils.autoreload][autoreload.py:251][INFO][D:\zhouzhi\gitlit_code\logistic_tracking_system\logistic_tracking_system\lts\views.py changed, reloading.]
[2021-08-19 16:01:30,923][MainThread:21104][task_id:django.utils.autoreload][autoreload.py:637][INFO][Watching for file changes with StatReloader]
[2021-08-19 16:02:06,390][MainThread:21104][task_id:django.utils.autoreload][autoreload.py:251][INFO][D:\zhouzhi\gitlit_code\logistic_tracking_system\logistic_tracking_system\lts\views.py changed, reloading.]
[2021-08-19 16:02:07,485][MainThread:21100][task_id:django.utils.autoreload][autoreload.py:637][INFO][Watching for file changes with StatReloader]
[2021-08-19 16:02:40,651][Thread-2:20860][task_id:lts.views][views.py:7524][ERROR][查询产品列表失败]
[2021-08-19 16:02:41,181][Thread-1:3016][task_id:django.request][log.py:230][ERROR][Internal Server Error: /logistic/LogisticWorkCodeName]
Traceback (most recent call last):
  File "D:\zhouzhi\gitlit_code\logistic_tracking_system\logistic_tracking_system\lts\views.py", line 3929, in get
    drs = db.execute_sql(conn, sql)
  File "D:\zhouzhi\gitlit_code\logistic_tracking_system\logistic_tracking_system\common\db.py", line 45, in execute_sql
    cursor.execute(sql)
  File "C:\Users\zhi.zhou\Anaconda3\envs\lts\lib\site-packages\pymysql\cursors.py", line 148, in execute
    result = self._query(query)
  File "C:\Users\zhi.zhou\Anaconda3\envs\lts\lib\site-packages\pymysql\cursors.py", line 310, in _query
    conn.query(q)
  File "C:\Users\zhi.zhou\Anaconda3\envs\lts\lib\site-packages\pymysql\connections.py", line 548, in query
    self._affected_rows = self._read_query_result(unbuffered=unbuffered)
  File "C:\Users\zhi.zhou\Anaconda3\envs\lts\lib\site-packages\pymysql\connections.py", line 775, in _read_query_result
    result.read()
  File "C:\Users\zhi.zhou\Anaconda3\envs\lts\lib\site-packages\pymysql\connections.py", line 1156, in read
    first_packet = self.connection._read_packet()
  File "C:\Users\zhi.zhou\Anaconda3\envs\lts\lib\site-packages\pymysql\connections.py", line 725, in _read_packet
    packet.raise_for_error()
  File "C:\Users\zhi.zhou\Anaconda3\envs\lts\lib\site-packages\pymysql\protocol.py", line 221, in raise_for_error
    err.raise_mysql_exception(self._data)
  File "C:\Users\zhi.zhou\Anaconda3\envs\lts\lib\site-packages\pymysql\err.py", line 143, in raise_mysql_exception
    raise errorclass(errno, errval)
pymysql.err.OperationalError: (1046, 'No database selected')

During handling of the above exception, another exception occurred:

Traceback (most recent call last):
  File "C:\Users\zhi.zhou\Anaconda3\envs\lts\lib\site-packages\django\core\handlers\exception.py", line 47, in inner
    response = get_response(request)
  File "C:\Users\zhi.zhou\Anaconda3\envs\lts\lib\site-packages\django\core\handlers\base.py", line 181, in _get_response
    response = wrapped_callback(request, *callback_args, **callback_kwargs)
  File "C:\Users\zhi.zhou\Anaconda3\envs\lts\lib\site-packages\django\views\generic\base.py", line 70, in view
    return self.dispatch(request, *args, **kwargs)
  File "C:\Users\zhi.zhou\Anaconda3\envs\lts\lib\site-packages\django\views\generic\base.py", line 98, in dispatch
    return handler(request, *args, **kwargs)
  File "D:\zhouzhi\gitlit_code\logistic_tracking_system\logistic_tracking_system\lts\views.py", line 3946, in get
    data = json.dumps(data)
  File "C:\Users\zhi.zhou\Anaconda3\envs\lts\lib\json\__init__.py", line 231, in dumps
    return _default_encoder.encode(obj)
  File "C:\Users\zhi.zhou\Anaconda3\envs\lts\lib\json\encoder.py", line 199, in encode
    chunks = self.iterencode(o, _one_shot=True)
  File "C:\Users\zhi.zhou\Anaconda3\envs\lts\lib\json\encoder.py", line 257, in iterencode
    return _iterencode(o, 0)
  File "C:\Users\zhi.zhou\Anaconda3\envs\lts\lib\json\encoder.py", line 180, in default
    o.__class__.__name__)
TypeError: Object of type 'OperationalError' is not JSON serializable
[2021-08-19 16:02:42,899][Thread-2:20860][task_id:lts.views][views.py:7524][ERROR][查询产品列表失败]
[2021-08-19 16:02:42,933][Thread-1:3016][task_id:django.request][log.py:230][ERROR][Internal Server Error: /logistic/LogisticWorkCodeName]
Traceback (most recent call last):
  File "D:\zhouzhi\gitlit_code\logistic_tracking_system\logistic_tracking_system\lts\views.py", line 3929, in get
    drs = db.execute_sql(conn, sql)
  File "D:\zhouzhi\gitlit_code\logistic_tracking_system\logistic_tracking_system\common\db.py", line 45, in execute_sql
    cursor.execute(sql)
  File "C:\Users\zhi.zhou\Anaconda3\envs\lts\lib\site-packages\pymysql\cursors.py", line 148, in execute
    result = self._query(query)
  File "C:\Users\zhi.zhou\Anaconda3\envs\lts\lib\site-packages\pymysql\cursors.py", line 310, in _query
    conn.query(q)
  File "C:\Users\zhi.zhou\Anaconda3\envs\lts\lib\site-packages\pymysql\connections.py", line 548, in query
    self._affected_rows = self._read_query_result(unbuffered=unbuffered)
  File "C:\Users\zhi.zhou\Anaconda3\envs\lts\lib\site-packages\pymysql\connections.py", line 775, in _read_query_result
    result.read()
  File "C:\Users\zhi.zhou\Anaconda3\envs\lts\lib\site-packages\pymysql\connections.py", line 1156, in read
    first_packet = self.connection._read_packet()
  File "C:\Users\zhi.zhou\Anaconda3\envs\lts\lib\site-packages\pymysql\connections.py", line 725, in _read_packet
    packet.raise_for_error()
  File "C:\Users\zhi.zhou\Anaconda3\envs\lts\lib\site-packages\pymysql\protocol.py", line 221, in raise_for_error
    err.raise_mysql_exception(self._data)
  File "C:\Users\zhi.zhou\Anaconda3\envs\lts\lib\site-packages\pymysql\err.py", line 143, in raise_mysql_exception
    raise errorclass(errno, errval)
pymysql.err.OperationalError: (1046, 'No database selected')

During handling of the above exception, another exception occurred:

Traceback (most recent call last):
  File "C:\Users\zhi.zhou\Anaconda3\envs\lts\lib\site-packages\django\core\handlers\exception.py", line 47, in inner
    response = get_response(request)
  File "C:\Users\zhi.zhou\Anaconda3\envs\lts\lib\site-packages\django\core\handlers\base.py", line 181, in _get_response
    response = wrapped_callback(request, *callback_args, **callback_kwargs)
  File "C:\Users\zhi.zhou\Anaconda3\envs\lts\lib\site-packages\django\views\generic\base.py", line 70, in view
    return self.dispatch(request, *args, **kwargs)
  File "C:\Users\zhi.zhou\Anaconda3\envs\lts\lib\site-packages\django\views\generic\base.py", line 98, in dispatch
    return handler(request, *args, **kwargs)
  File "D:\zhouzhi\gitlit_code\logistic_tracking_system\logistic_tracking_system\lts\views.py", line 3946, in get
    data = json.dumps(data)
  File "C:\Users\zhi.zhou\Anaconda3\envs\lts\lib\json\__init__.py", line 231, in dumps
    return _default_encoder.encode(obj)
  File "C:\Users\zhi.zhou\Anaconda3\envs\lts\lib\json\encoder.py", line 199, in encode
    chunks = self.iterencode(o, _one_shot=True)
  File "C:\Users\zhi.zhou\Anaconda3\envs\lts\lib\json\encoder.py", line 257, in iterencode
    return _iterencode(o, 0)
  File "C:\Users\zhi.zhou\Anaconda3\envs\lts\lib\json\encoder.py", line 180, in default
    o.__class__.__name__)
TypeError: Object of type 'OperationalError' is not JSON serializable
[2021-08-19 16:02:45,984][Thread-3:6800][task_id:lts.views][views.py:1614][ERROR][查询产品列表失败]
[2021-08-19 16:02:46,060][Thread-1:3016][task_id:django.request][log.py:230][ERROR][Internal Server Error: /logistic/LogisticProcessNameCode]
Traceback (most recent call last):
  File "D:\zhouzhi\gitlit_code\logistic_tracking_system\logistic_tracking_system\lts\views.py", line 4691, in get
    drs = db.execute_sql(conn, sql)
  File "D:\zhouzhi\gitlit_code\logistic_tracking_system\logistic_tracking_system\common\db.py", line 45, in execute_sql
    cursor.execute(sql)
  File "C:\Users\zhi.zhou\Anaconda3\envs\lts\lib\site-packages\pymysql\cursors.py", line 148, in execute
    result = self._query(query)
  File "C:\Users\zhi.zhou\Anaconda3\envs\lts\lib\site-packages\pymysql\cursors.py", line 310, in _query
    conn.query(q)
  File "C:\Users\zhi.zhou\Anaconda3\envs\lts\lib\site-packages\pymysql\connections.py", line 548, in query
    self._affected_rows = self._read_query_result(unbuffered=unbuffered)
  File "C:\Users\zhi.zhou\Anaconda3\envs\lts\lib\site-packages\pymysql\connections.py", line 775, in _read_query_result
    result.read()
  File "C:\Users\zhi.zhou\Anaconda3\envs\lts\lib\site-packages\pymysql\connections.py", line 1156, in read
    first_packet = self.connection._read_packet()
  File "C:\Users\zhi.zhou\Anaconda3\envs\lts\lib\site-packages\pymysql\connections.py", line 725, in _read_packet
    packet.raise_for_error()
  File "C:\Users\zhi.zhou\Anaconda3\envs\lts\lib\site-packages\pymysql\protocol.py", line 221, in raise_for_error
    err.raise_mysql_exception(self._data)
  File "C:\Users\zhi.zhou\Anaconda3\envs\lts\lib\site-packages\pymysql\err.py", line 143, in raise_mysql_exception
    raise errorclass(errno, errval)
pymysql.err.OperationalError: (1046, 'No database selected')

During handling of the above exception, another exception occurred:

Traceback (most recent call last):
  File "C:\Users\zhi.zhou\Anaconda3\envs\lts\lib\site-packages\django\core\handlers\exception.py", line 47, in inner
    response = get_response(request)
  File "C:\Users\zhi.zhou\Anaconda3\envs\lts\lib\site-packages\django\core\handlers\base.py", line 181, in _get_response
    response = wrapped_callback(request, *callback_args, **callback_kwargs)
  File "C:\Users\zhi.zhou\Anaconda3\envs\lts\lib\site-packages\django\views\generic\base.py", line 70, in view
    return self.dispatch(request, *args, **kwargs)
  File "C:\Users\zhi.zhou\Anaconda3\envs\lts\lib\site-packages\django\views\generic\base.py", line 98, in dispatch
    return handler(request, *args, **kwargs)
  File "D:\zhouzhi\gitlit_code\logistic_tracking_system\logistic_tracking_system\lts\views.py", line 4705, in get
    data = json.dumps(data)
  File "C:\Users\zhi.zhou\Anaconda3\envs\lts\lib\json\__init__.py", line 231, in dumps
    return _default_encoder.encode(obj)
  File "C:\Users\zhi.zhou\Anaconda3\envs\lts\lib\json\encoder.py", line 199, in encode
    chunks = self.iterencode(o, _one_shot=True)
  File "C:\Users\zhi.zhou\Anaconda3\envs\lts\lib\json\encoder.py", line 257, in iterencode
    return _iterencode(o, 0)
  File "C:\Users\zhi.zhou\Anaconda3\envs\lts\lib\json\encoder.py", line 180, in default
    o.__class__.__name__)
TypeError: Object of type 'OperationalError' is not JSON serializable
[2021-08-19 16:02:46,084][Thread-5:2520][task_id:django.request][log.py:230][ERROR][Internal Server Error: /logistic/LogisticProcessDeal]
Traceback (most recent call last):
  File "D:\zhouzhi\gitlit_code\logistic_tracking_system\logistic_tracking_system\lts\views.py", line 3544, in get
    current_person_id = request.session['session_currentId']
  File "C:\Users\zhi.zhou\Anaconda3\envs\lts\lib\site-packages\django\contrib\sessions\backends\base.py", line 65, in __getitem__
    return self._session[key]
KeyError: 'session_currentId'

During handling of the above exception, another exception occurred:

Traceback (most recent call last):
  File "C:\Users\zhi.zhou\Anaconda3\envs\lts\lib\site-packages\django\core\handlers\exception.py", line 47, in inner
    response = get_response(request)
  File "C:\Users\zhi.zhou\Anaconda3\envs\lts\lib\site-packages\django\core\handlers\base.py", line 181, in _get_response
    response = wrapped_callback(request, *callback_args, **callback_kwargs)
  File "C:\Users\zhi.zhou\Anaconda3\envs\lts\lib\site-packages\django\views\generic\base.py", line 70, in view
    return self.dispatch(request, *args, **kwargs)
  File "C:\Users\zhi.zhou\Anaconda3\envs\lts\lib\site-packages\django\views\generic\base.py", line 98, in dispatch
    return handler(request, *args, **kwargs)
  File "D:\zhouzhi\gitlit_code\logistic_tracking_system\logistic_tracking_system\lts\views.py", line 3628, in get
    data = json.dumps(data)
  File "C:\Users\zhi.zhou\Anaconda3\envs\lts\lib\json\__init__.py", line 231, in dumps
    return _default_encoder.encode(obj)
  File "C:\Users\zhi.zhou\Anaconda3\envs\lts\lib\json\encoder.py", line 199, in encode
    chunks = self.iterencode(o, _one_shot=True)
  File "C:\Users\zhi.zhou\Anaconda3\envs\lts\lib\json\encoder.py", line 257, in iterencode
    return _iterencode(o, 0)
  File "C:\Users\zhi.zhou\Anaconda3\envs\lts\lib\json\encoder.py", line 180, in default
    o.__class__.__name__)
TypeError: Object of type 'KeyError' is not JSON serializable
[2021-08-19 16:02:46,089][Thread-2:20860][task_id:django.request][log.py:230][ERROR][Internal Server Error: /logistic/LogisticWorkCodeName]
Traceback (most recent call last):
  File "D:\zhouzhi\gitlit_code\logistic_tracking_system\logistic_tracking_system\lts\views.py", line 3929, in get
    drs = db.execute_sql(conn, sql)
  File "D:\zhouzhi\gitlit_code\logistic_tracking_system\logistic_tracking_system\common\db.py", line 45, in execute_sql
    cursor.execute(sql)
  File "C:\Users\zhi.zhou\Anaconda3\envs\lts\lib\site-packages\pymysql\cursors.py", line 148, in execute
    result = self._query(query)
  File "C:\Users\zhi.zhou\Anaconda3\envs\lts\lib\site-packages\pymysql\cursors.py", line 310, in _query
    conn.query(q)
  File "C:\Users\zhi.zhou\Anaconda3\envs\lts\lib\site-packages\pymysql\connections.py", line 548, in query
    self._affected_rows = self._read_query_result(unbuffered=unbuffered)
  File "C:\Users\zhi.zhou\Anaconda3\envs\lts\lib\site-packages\pymysql\connections.py", line 775, in _read_query_result
    result.read()
  File "C:\Users\zhi.zhou\Anaconda3\envs\lts\lib\site-packages\pymysql\connections.py", line 1156, in read
    first_packet = self.connection._read_packet()
  File "C:\Users\zhi.zhou\Anaconda3\envs\lts\lib\site-packages\pymysql\connections.py", line 725, in _read_packet
    packet.raise_for_error()
  File "C:\Users\zhi.zhou\Anaconda3\envs\lts\lib\site-packages\pymysql\protocol.py", line 221, in raise_for_error
    err.raise_mysql_exception(self._data)
  File "C:\Users\zhi.zhou\Anaconda3\envs\lts\lib\site-packages\pymysql\err.py", line 143, in raise_mysql_exception
    raise errorclass(errno, errval)
pymysql.err.OperationalError: (1046, 'No database selected')

During handling of the above exception, another exception occurred:

Traceback (most recent call last):
  File "C:\Users\zhi.zhou\Anaconda3\envs\lts\lib\site-packages\django\core\handlers\exception.py", line 47, in inner
    response = get_response(request)
  File "C:\Users\zhi.zhou\Anaconda3\envs\lts\lib\site-packages\django\core\handlers\base.py", line 181, in _get_response
    response = wrapped_callback(request, *callback_args, **callback_kwargs)
  File "C:\Users\zhi.zhou\Anaconda3\envs\lts\lib\site-packages\django\views\generic\base.py", line 70, in view
    return self.dispatch(request, *args, **kwargs)
  File "C:\Users\zhi.zhou\Anaconda3\envs\lts\lib\site-packages\django\views\generic\base.py", line 98, in dispatch
    return handler(request, *args, **kwargs)
  File "D:\zhouzhi\gitlit_code\logistic_tracking_system\logistic_tracking_system\lts\views.py", line 3946, in get
    data = json.dumps(data)
  File "C:\Users\zhi.zhou\Anaconda3\envs\lts\lib\json\__init__.py", line 231, in dumps
    return _default_encoder.encode(obj)
  File "C:\Users\zhi.zhou\Anaconda3\envs\lts\lib\json\encoder.py", line 199, in encode
    chunks = self.iterencode(o, _one_shot=True)
  File "C:\Users\zhi.zhou\Anaconda3\envs\lts\lib\json\encoder.py", line 257, in iterencode
    return _iterencode(o, 0)
  File "C:\Users\zhi.zhou\Anaconda3\envs\lts\lib\json\encoder.py", line 180, in default
    o.__class__.__name__)
TypeError: Object of type 'OperationalError' is not JSON serializable
[2021-08-19 16:02:46,118][Thread-4:20524][task_id:django.request][log.py:230][ERROR][Internal Server Error: /logistic/LogisticNoPagePersonMatter]
Traceback (most recent call last):
  File "D:\zhouzhi\gitlit_code\logistic_tracking_system\logistic_tracking_system\lts\views.py", line 3478, in get
    drs = db.execute_sql(conn, sql)
  File "D:\zhouzhi\gitlit_code\logistic_tracking_system\logistic_tracking_system\common\db.py", line 45, in execute_sql
    cursor.execute(sql)
  File "C:\Users\zhi.zhou\Anaconda3\envs\lts\lib\site-packages\pymysql\cursors.py", line 148, in execute
    result = self._query(query)
  File "C:\Users\zhi.zhou\Anaconda3\envs\lts\lib\site-packages\pymysql\cursors.py", line 310, in _query
    conn.query(q)
  File "C:\Users\zhi.zhou\Anaconda3\envs\lts\lib\site-packages\pymysql\connections.py", line 548, in query
    self._affected_rows = self._read_query_result(unbuffered=unbuffered)
  File "C:\Users\zhi.zhou\Anaconda3\envs\lts\lib\site-packages\pymysql\connections.py", line 775, in _read_query_result
    result.read()
  File "C:\Users\zhi.zhou\Anaconda3\envs\lts\lib\site-packages\pymysql\connections.py", line 1156, in read
    first_packet = self.connection._read_packet()
  File "C:\Users\zhi.zhou\Anaconda3\envs\lts\lib\site-packages\pymysql\connections.py", line 725, in _read_packet
    packet.raise_for_error()
  File "C:\Users\zhi.zhou\Anaconda3\envs\lts\lib\site-packages\pymysql\protocol.py", line 221, in raise_for_error
    err.raise_mysql_exception(self._data)
  File "C:\Users\zhi.zhou\Anaconda3\envs\lts\lib\site-packages\pymysql\err.py", line 143, in raise_mysql_exception
    raise errorclass(errno, errval)
pymysql.err.OperationalError: (1046, 'No database selected')

During handling of the above exception, another exception occurred:

Traceback (most recent call last):
  File "C:\Users\zhi.zhou\Anaconda3\envs\lts\lib\site-packages\django\core\handlers\exception.py", line 47, in inner
    response = get_response(request)
  File "C:\Users\zhi.zhou\Anaconda3\envs\lts\lib\site-packages\django\core\handlers\base.py", line 181, in _get_response
    response = wrapped_callback(request, *callback_args, **callback_kwargs)
  File "C:\Users\zhi.zhou\Anaconda3\envs\lts\lib\site-packages\django\views\generic\base.py", line 70, in view
    return self.dispatch(request, *args, **kwargs)
  File "C:\Users\zhi.zhou\Anaconda3\envs\lts\lib\site-packages\django\views\generic\base.py", line 98, in dispatch
    return handler(request, *args, **kwargs)
  File "D:\zhouzhi\gitlit_code\logistic_tracking_system\logistic_tracking_system\lts\views.py", line 3510, in get
    result = json.dumps(result)
  File "C:\Users\zhi.zhou\Anaconda3\envs\lts\lib\json\__init__.py", line 231, in dumps
    return _default_encoder.encode(obj)
  File "C:\Users\zhi.zhou\Anaconda3\envs\lts\lib\json\encoder.py", line 199, in encode
    chunks = self.iterencode(o, _one_shot=True)
  File "C:\Users\zhi.zhou\Anaconda3\envs\lts\lib\json\encoder.py", line 257, in iterencode
    return _iterencode(o, 0)
  File "C:\Users\zhi.zhou\Anaconda3\envs\lts\lib\json\encoder.py", line 180, in default
    o.__class__.__name__)
TypeError: Object of type 'OperationalError' is not JSON serializable
[2021-08-19 16:02:57,932][Thread-7:12276][task_id:lts.views][views.py:7524][ERROR][查询产品列表失败]
[2021-08-19 16:02:58,152][MainThread:21100][task_id:django.utils.autoreload][autoreload.py:251][INFO][D:\zhouzhi\gitlit_code\logistic_tracking_system\logistic_tracking_system\lts\views.py changed, reloading.]
[2021-08-19 16:02:59,238][MainThread:12788][task_id:django.utils.autoreload][autoreload.py:637][INFO][Watching for file changes with StatReloader]
[2021-08-19 16:03:16,397][MainThread:12788][task_id:django.utils.autoreload][autoreload.py:251][INFO][D:\zhouzhi\gitlit_code\logistic_tracking_system\logistic_tracking_system\lts\views.py changed, reloading.]
[2021-08-19 16:03:17,476][MainThread:14932][task_id:django.utils.autoreload][autoreload.py:637][INFO][Watching for file changes with StatReloader]
[2021-08-19 16:03:20,481][Thread-1:17660][task_id:lts.views][views.py:376][INFO][登录成功]
[2021-08-19 16:03:20,994][MainThread:14932][task_id:django.utils.autoreload][autoreload.py:251][INFO][D:\zhouzhi\gitlit_code\logistic_tracking_system\logistic_tracking_system\lts\views.py changed, reloading.]
[2021-08-19 16:03:22,122][MainThread:9776][task_id:django.utils.autoreload][autoreload.py:637][INFO][Watching for file changes with StatReloader]
[2021-08-19 16:03:28,161][MainThread:9776][task_id:django.utils.autoreload][autoreload.py:251][INFO][D:\zhouzhi\gitlit_code\logistic_tracking_system\logistic_tracking_system\lts\views.py changed, reloading.]
[2021-08-19 16:03:29,217][MainThread:6168][task_id:django.utils.autoreload][autoreload.py:637][INFO][Watching for file changes with StatReloader]
[2021-08-19 16:03:31,822][Thread-2:12964][task_id:lts.views][views.py:7524][ERROR][查询产品列表失败]
[2021-08-19 16:03:32,596][MainThread:6168][task_id:django.utils.autoreload][autoreload.py:251][INFO][D:\zhouzhi\gitlit_code\logistic_tracking_system\logistic_tracking_system\lts\views.py changed, reloading.]
[2021-08-19 16:03:33,694][MainThread:16344][task_id:django.utils.autoreload][autoreload.py:637][INFO][Watching for file changes with StatReloader]
[2021-08-19 16:03:36,955][MainThread:16344][task_id:django.utils.autoreload][autoreload.py:251][INFO][D:\zhouzhi\gitlit_code\logistic_tracking_system\logistic_tracking_system\lts\views.py changed, reloading.]
[2021-08-19 16:03:38,032][MainThread:20176][task_id:django.utils.autoreload][autoreload.py:637][INFO][Watching for file changes with StatReloader]
[2021-08-19 16:03:43,494][Thread-2:19008][task_id:lts.views][views.py:7524][ERROR][查询产品列表失败]
[2021-08-19 16:03:50,784][MainThread:20176][task_id:django.utils.autoreload][autoreload.py:251][INFO][D:\zhouzhi\gitlit_code\logistic_tracking_system\logistic_tracking_system\lts\views.py changed, reloading.]
[2021-08-19 16:03:51,863][MainThread:18472][task_id:django.utils.autoreload][autoreload.py:637][INFO][Watching for file changes with StatReloader]
[2021-08-19 16:03:53,834][Thread-1:16332][task_id:lts.views][views.py:376][INFO][登录成功]
[2021-08-19 16:03:56,314][Thread-1:16332][task_id:lts.views][views.py:7525][ERROR][查询产品列表失败]
[2021-08-19 16:04:03,300][Thread-1:16332][task_id:lts.views][views.py:7525][ERROR][查询产品列表失败]
[2021-08-19 16:04:47,377][MainThread:18472][task_id:django.utils.autoreload][autoreload.py:251][INFO][D:\zhouzhi\gitlit_code\logistic_tracking_system\logistic_tracking_system\lts\views.py changed, reloading.]
[2021-08-19 16:04:48,485][MainThread:11836][task_id:django.utils.autoreload][autoreload.py:637][INFO][Watching for file changes with StatReloader]
[2021-08-19 16:06:22,462][MainThread:11836][task_id:django.utils.autoreload][autoreload.py:251][INFO][D:\zhouzhi\gitlit_code\logistic_tracking_system\logistic_tracking_system\lts\views.py changed, reloading.]
[2021-08-19 16:06:24,007][MainThread:21136][task_id:django.utils.autoreload][autoreload.py:637][INFO][Watching for file changes with StatReloader]
[2021-08-19 16:07:27,113][MainThread:21136][task_id:django.utils.autoreload][autoreload.py:251][INFO][D:\zhouzhi\gitlit_code\logistic_tracking_system\logistic_tracking_system\lts\views.py changed, reloading.]
[2021-08-19 16:07:28,285][MainThread:13876][task_id:django.utils.autoreload][autoreload.py:637][INFO][Watching for file changes with StatReloader]
[2021-08-19 16:07:56,528][MainThread:13876][task_id:django.utils.autoreload][autoreload.py:251][INFO][D:\zhouzhi\gitlit_code\logistic_tracking_system\logistic_tracking_system\lts\views.py changed, reloading.]
[2021-08-19 16:07:57,658][MainThread:19852][task_id:django.utils.autoreload][autoreload.py:637][INFO][Watching for file changes with StatReloader]
[2021-08-19 16:38:42,066][MainThread:19852][task_id:django.utils.autoreload][autoreload.py:251][INFO][D:\zhouzhi\gitlit_code\logistic_tracking_system\logistic_tracking_system\lts\views.py changed, reloading.]
[2021-08-19 16:38:43,720][MainThread:1480][task_id:django.utils.autoreload][autoreload.py:637][INFO][Watching for file changes with StatReloader]
[2021-08-19 16:40:56,190][MainThread:1480][task_id:django.utils.autoreload][autoreload.py:251][INFO][D:\zhouzhi\gitlit_code\logistic_tracking_system\logistic_tracking_system\lts\views.py changed, reloading.]
[2021-08-19 16:40:57,350][MainThread:21184][task_id:django.utils.autoreload][autoreload.py:637][INFO][Watching for file changes with StatReloader]
[2021-08-19 16:41:00,468][Thread-2:16564][task_id:lts.views][views.py:7522][ERROR][查询产品列表失败]
[2021-08-19 16:41:19,934][MainThread:21184][task_id:django.utils.autoreload][autoreload.py:251][INFO][D:\zhouzhi\gitlit_code\logistic_tracking_system\logistic_tracking_system\lts\views.py changed, reloading.]
[2021-08-19 16:41:21,062][MainThread:11952][task_id:django.utils.autoreload][autoreload.py:637][INFO][Watching for file changes with StatReloader]
[2021-08-19 16:41:59,789][MainThread:11952][task_id:django.utils.autoreload][autoreload.py:251][INFO][D:\zhouzhi\gitlit_code\logistic_tracking_system\logistic_tracking_system\lts\views.py changed, reloading.]
[2021-08-19 16:42:01,460][MainThread:19928][task_id:django.utils.autoreload][autoreload.py:637][INFO][Watching for file changes with StatReloader]
[2021-08-19 16:42:59,770][MainThread:19928][task_id:django.utils.autoreload][autoreload.py:251][INFO][D:\zhouzhi\gitlit_code\logistic_tracking_system\logistic_tracking_system\lts\views.py changed, reloading.]
[2021-08-19 16:43:00,932][MainThread:14760][task_id:django.utils.autoreload][autoreload.py:637][INFO][Watching for file changes with StatReloader]
[2021-08-19 16:45:17,422][MainThread:14760][task_id:django.utils.autoreload][autoreload.py:251][INFO][D:\zhouzhi\gitlit_code\logistic_tracking_system\logistic_tracking_system\lts\views.py changed, reloading.]
[2021-08-19 16:45:18,552][MainThread:12040][task_id:django.utils.autoreload][autoreload.py:637][INFO][Watching for file changes with StatReloader]
[2021-08-19 16:47:24,537][MainThread:12040][task_id:django.utils.autoreload][autoreload.py:251][INFO][D:\zhouzhi\gitlit_code\logistic_tracking_system\logistic_tracking_system\lts\views.py changed, reloading.]
[2021-08-19 16:47:26,175][MainThread:15928][task_id:django.utils.autoreload][autoreload.py:637][INFO][Watching for file changes with StatReloader]
[2021-08-19 16:47:31,188][MainThread:15928][task_id:django.utils.autoreload][autoreload.py:251][INFO][D:\zhouzhi\gitlit_code\logistic_tracking_system\logistic_tracking_system\lts\views.py changed, reloading.]
[2021-08-19 16:47:32,995][MainThread:7528][task_id:django.utils.autoreload][autoreload.py:637][INFO][Watching for file changes with StatReloader]
[2021-08-19 16:47:39,193][MainThread:7528][task_id:django.utils.autoreload][autoreload.py:251][INFO][D:\zhouzhi\gitlit_code\logistic_tracking_system\logistic_tracking_system\lts\views.py changed, reloading.]
[2021-08-19 16:47:40,643][MainThread:7016][task_id:django.utils.autoreload][autoreload.py:637][INFO][Watching for file changes with StatReloader]
[2021-08-19 16:47:59,856][MainThread:7016][task_id:django.utils.autoreload][autoreload.py:251][INFO][D:\zhouzhi\gitlit_code\logistic_tracking_system\logistic_tracking_system\lts\views.py changed, reloading.]
[2021-08-19 16:48:00,946][MainThread:14744][task_id:django.utils.autoreload][autoreload.py:637][INFO][Watching for file changes with StatReloader]
[2021-08-19 16:55:57,278][MainThread:14744][task_id:django.utils.autoreload][autoreload.py:251][INFO][D:\zhouzhi\gitlit_code\logistic_tracking_system\logistic_tracking_system\lts\views.py changed, reloading.]
[2021-08-19 16:55:58,375][MainThread:11864][task_id:django.utils.autoreload][autoreload.py:637][INFO][Watching for file changes with StatReloader]
[2021-08-19 16:56:31,502][MainThread:11864][task_id:django.utils.autoreload][autoreload.py:251][INFO][D:\zhouzhi\gitlit_code\logistic_tracking_system\logistic_tracking_system\lts\views.py changed, reloading.]
[2021-08-19 16:56:32,557][MainThread:9164][task_id:django.utils.autoreload][autoreload.py:637][INFO][Watching for file changes with StatReloader]
[2021-08-19 16:56:36,892][MainThread:9164][task_id:django.utils.autoreload][autoreload.py:251][INFO][D:\zhouzhi\gitlit_code\logistic_tracking_system\logistic_tracking_system\lts\views.py changed, reloading.]
[2021-08-19 16:56:38,188][MainThread:20552][task_id:django.utils.autoreload][autoreload.py:637][INFO][Watching for file changes with StatReloader]
[2021-08-19 16:56:44,189][MainThread:20552][task_id:django.utils.autoreload][autoreload.py:251][INFO][D:\zhouzhi\gitlit_code\logistic_tracking_system\logistic_tracking_system\lts\views.py changed, reloading.]
[2021-08-19 16:56:45,248][MainThread:21204][task_id:django.utils.autoreload][autoreload.py:637][INFO][Watching for file changes with StatReloader]
[2021-08-19 16:56:49,571][MainThread:21204][task_id:django.utils.autoreload][autoreload.py:251][INFO][D:\zhouzhi\gitlit_code\logistic_tracking_system\logistic_tracking_system\lts\views.py changed, reloading.]
[2021-08-19 16:56:50,626][MainThread:7636][task_id:django.utils.autoreload][autoreload.py:637][INFO][Watching for file changes with StatReloader]
[2021-08-19 16:56:53,754][MainThread:7636][task_id:django.utils.autoreload][autoreload.py:251][INFO][D:\zhouzhi\gitlit_code\logistic_tracking_system\logistic_tracking_system\lts\views.py changed, reloading.]
[2021-08-19 16:56:54,848][MainThread:17224][task_id:django.utils.autoreload][autoreload.py:637][INFO][Watching for file changes with StatReloader]
[2021-08-19 16:57:00,444][MainThread:17224][task_id:django.utils.autoreload][autoreload.py:251][INFO][D:\zhouzhi\gitlit_code\logistic_tracking_system\logistic_tracking_system\lts\views.py changed, reloading.]
[2021-08-19 16:57:01,520][MainThread:19908][task_id:django.utils.autoreload][autoreload.py:637][INFO][Watching for file changes with StatReloader]
[2021-08-19 16:58:51,507][MainThread:19908][task_id:django.utils.autoreload][autoreload.py:251][INFO][D:\zhouzhi\gitlit_code\logistic_tracking_system\logistic_tracking_system\lts\views.py changed, reloading.]
[2021-08-19 16:58:52,580][MainThread:1628][task_id:django.utils.autoreload][autoreload.py:637][INFO][Watching for file changes with StatReloader]
[2021-08-19 17:03:10,491][MainThread:1628][task_id:django.utils.autoreload][autoreload.py:251][INFO][D:\zhouzhi\gitlit_code\logistic_tracking_system\logistic_tracking_system\lts\views.py changed, reloading.]
[2021-08-19 17:03:11,575][MainThread:20696][task_id:django.utils.autoreload][autoreload.py:637][INFO][Watching for file changes with StatReloader]
[2021-08-19 17:03:37,449][MainThread:20696][task_id:django.utils.autoreload][autoreload.py:251][INFO][D:\zhouzhi\gitlit_code\logistic_tracking_system\logistic_tracking_system\lts\views.py changed, reloading.]
[2021-08-19 17:03:38,520][MainThread:15656][task_id:django.utils.autoreload][autoreload.py:637][INFO][Watching for file changes with StatReloader]
[2021-08-19 17:03:44,012][MainThread:15656][task_id:django.utils.autoreload][autoreload.py:251][INFO][D:\zhouzhi\gitlit_code\logistic_tracking_system\logistic_tracking_system\lts\views.py changed, reloading.]
[2021-08-19 17:03:45,210][MainThread:7064][task_id:django.utils.autoreload][autoreload.py:637][INFO][Watching for file changes with StatReloader]
[2021-08-19 17:03:53,407][MainThread:7064][task_id:django.utils.autoreload][autoreload.py:251][INFO][D:\zhouzhi\gitlit_code\logistic_tracking_system\logistic_tracking_system\lts\views.py changed, reloading.]
[2021-08-19 17:03:54,463][MainThread:19276][task_id:django.utils.autoreload][autoreload.py:637][INFO][Watching for file changes with StatReloader]
[2021-08-19 17:04:00,129][MainThread:19276][task_id:django.utils.autoreload][autoreload.py:251][INFO][D:\zhouzhi\gitlit_code\logistic_tracking_system\logistic_tracking_system\lts\views.py changed, reloading.]
[2021-08-19 17:04:01,217][MainThread:16672][task_id:django.utils.autoreload][autoreload.py:637][INFO][Watching for file changes with StatReloader]
[2021-08-19 17:04:05,645][MainThread:16672][task_id:django.utils.autoreload][autoreload.py:251][INFO][D:\zhouzhi\gitlit_code\logistic_tracking_system\logistic_tracking_system\lts\views.py changed, reloading.]
[2021-08-19 17:04:06,768][MainThread:13596][task_id:django.utils.autoreload][autoreload.py:637][INFO][Watching for file changes with StatReloader]
[2021-08-19 17:04:12,892][MainThread:13596][task_id:django.utils.autoreload][autoreload.py:251][INFO][D:\zhouzhi\gitlit_code\logistic_tracking_system\logistic_tracking_system\lts\views.py changed, reloading.]
[2021-08-19 17:04:13,941][MainThread:8356][task_id:django.utils.autoreload][autoreload.py:637][INFO][Watching for file changes with StatReloader]
[2021-08-19 17:04:19,498][MainThread:8356][task_id:django.utils.autoreload][autoreload.py:251][INFO][D:\zhouzhi\gitlit_code\logistic_tracking_system\logistic_tracking_system\lts\views.py changed, reloading.]
[2021-08-19 17:04:20,773][MainThread:19952][task_id:django.utils.autoreload][autoreload.py:637][INFO][Watching for file changes with StatReloader]
[2021-08-19 17:04:46,546][MainThread:19952][task_id:django.utils.autoreload][autoreload.py:251][INFO][D:\zhouzhi\gitlit_code\logistic_tracking_system\logistic_tracking_system\lts\views.py changed, reloading.]
[2021-08-19 17:04:47,622][MainThread:21420][task_id:django.utils.autoreload][autoreload.py:637][INFO][Watching for file changes with StatReloader]
[2021-08-19 17:05:01,430][MainThread:21420][task_id:django.utils.autoreload][autoreload.py:251][INFO][D:\zhouzhi\gitlit_code\logistic_tracking_system\logistic_tracking_system\lts\views.py changed, reloading.]
[2021-08-19 17:05:02,503][MainThread:3084][task_id:django.utils.autoreload][autoreload.py:637][INFO][Watching for file changes with StatReloader]
[2021-08-19 17:07:03,173][MainThread:3084][task_id:django.utils.autoreload][autoreload.py:251][INFO][D:\zhouzhi\gitlit_code\logistic_tracking_system\logistic_tracking_system\lts\views.py changed, reloading.]
[2021-08-19 17:07:04,270][MainThread:8356][task_id:django.utils.autoreload][autoreload.py:637][INFO][Watching for file changes with StatReloader]
[2021-08-19 17:09:01,420][MainThread:8356][task_id:django.utils.autoreload][autoreload.py:251][INFO][D:\zhouzhi\gitlit_code\logistic_tracking_system\logistic_tracking_system\lts\views.py changed, reloading.]
[2021-08-19 17:09:02,518][MainThread:5452][task_id:django.utils.autoreload][autoreload.py:637][INFO][Watching for file changes with StatReloader]
[2021-08-19 17:10:16,661][MainThread:5452][task_id:django.utils.autoreload][autoreload.py:251][INFO][D:\zhouzhi\gitlit_code\logistic_tracking_system\logistic_tracking_system\lts\views.py changed, reloading.]
[2021-08-19 17:10:17,807][MainThread:20240][task_id:django.utils.autoreload][autoreload.py:637][INFO][Watching for file changes with StatReloader]
[2021-08-19 17:11:10,190][MainThread:20240][task_id:django.utils.autoreload][autoreload.py:251][INFO][D:\zhouzhi\gitlit_code\logistic_tracking_system\logistic_tracking_system\lts\views.py changed, reloading.]
[2021-08-19 17:11:11,290][MainThread:16680][task_id:django.utils.autoreload][autoreload.py:637][INFO][Watching for file changes with StatReloader]
[2021-08-19 17:12:51,484][MainThread:16680][task_id:django.utils.autoreload][autoreload.py:251][INFO][D:\zhouzhi\gitlit_code\logistic_tracking_system\logistic_tracking_system\lts\views.py changed, reloading.]
[2021-08-19 17:12:53,007][MainThread:1872][task_id:django.utils.autoreload][autoreload.py:637][INFO][Watching for file changes with StatReloader]
[2021-08-19 17:13:11,357][MainThread:1872][task_id:django.utils.autoreload][autoreload.py:251][INFO][D:\zhouzhi\gitlit_code\logistic_tracking_system\logistic_tracking_system\lts\views.py changed, reloading.]
[2021-08-19 17:13:12,423][MainThread:20524][task_id:django.utils.autoreload][autoreload.py:637][INFO][Watching for file changes with StatReloader]
[2021-08-19 17:15:06,902][MainThread:20524][task_id:django.utils.autoreload][autoreload.py:251][INFO][D:\zhouzhi\gitlit_code\logistic_tracking_system\logistic_tracking_system\lts\views.py changed, reloading.]
[2021-08-19 17:15:08,020][MainThread:8836][task_id:django.utils.autoreload][autoreload.py:637][INFO][Watching for file changes with StatReloader]
[2021-08-19 17:15:13,133][MainThread:8836][task_id:django.utils.autoreload][autoreload.py:251][INFO][D:\zhouzhi\gitlit_code\logistic_tracking_system\logistic_tracking_system\lts\views.py changed, reloading.]
[2021-08-19 17:15:14,253][MainThread:20964][task_id:django.utils.autoreload][autoreload.py:637][INFO][Watching for file changes with StatReloader]
[2021-08-19 17:15:18,298][MainThread:20964][task_id:django.utils.autoreload][autoreload.py:251][INFO][D:\zhouzhi\gitlit_code\logistic_tracking_system\logistic_tracking_system\lts\views.py changed, reloading.]
[2021-08-19 17:15:19,521][MainThread:20500][task_id:django.utils.autoreload][autoreload.py:637][INFO][Watching for file changes with StatReloader]
[2021-08-19 17:15:23,329][MainThread:20500][task_id:django.utils.autoreload][autoreload.py:251][INFO][D:\zhouzhi\gitlit_code\logistic_tracking_system\logistic_tracking_system\lts\views.py changed, reloading.]
[2021-08-19 17:15:24,440][MainThread:12884][task_id:django.utils.autoreload][autoreload.py:637][INFO][Watching for file changes with StatReloader]
[2021-08-19 17:15:31,367][MainThread:12884][task_id:django.utils.autoreload][autoreload.py:251][INFO][D:\zhouzhi\gitlit_code\logistic_tracking_system\logistic_tracking_system\lts\views.py changed, reloading.]
[2021-08-19 17:15:32,461][MainThread:4580][task_id:django.utils.autoreload][autoreload.py:637][INFO][Watching for file changes with StatReloader]
[2021-08-19 17:15:38,517][MainThread:4580][task_id:django.utils.autoreload][autoreload.py:251][INFO][D:\zhouzhi\gitlit_code\logistic_tracking_system\logistic_tracking_system\lts\views.py changed, reloading.]
[2021-08-19 17:15:39,574][MainThread:16392][task_id:django.utils.autoreload][autoreload.py:637][INFO][Watching for file changes with StatReloader]
[2021-08-19 17:15:42,575][MainThread:16392][task_id:django.utils.autoreload][autoreload.py:251][INFO][D:\zhouzhi\gitlit_code\logistic_tracking_system\logistic_tracking_system\lts\views.py changed, reloading.]
[2021-08-19 17:15:43,669][MainThread:308][task_id:django.utils.autoreload][autoreload.py:637][INFO][Watching for file changes with StatReloader]
[2021-08-19 17:15:49,092][MainThread:308][task_id:django.utils.autoreload][autoreload.py:251][INFO][D:\zhouzhi\gitlit_code\logistic_tracking_system\logistic_tracking_system\lts\views.py changed, reloading.]
[2021-08-19 17:15:50,386][MainThread:4512][task_id:django.utils.autoreload][autoreload.py:637][INFO][Watching for file changes with StatReloader]
[2021-08-19 17:15:58,863][MainThread:4512][task_id:django.utils.autoreload][autoreload.py:251][INFO][D:\zhouzhi\gitlit_code\logistic_tracking_system\logistic_tracking_system\lts\views.py changed, reloading.]
[2021-08-19 17:15:59,946][MainThread:12316][task_id:django.utils.autoreload][autoreload.py:637][INFO][Watching for file changes with StatReloader]
[2021-08-19 17:17:01,561][MainThread:12316][task_id:django.utils.autoreload][autoreload.py:251][INFO][D:\zhouzhi\gitlit_code\logistic_tracking_system\logistic_tracking_system\lts\views.py changed, reloading.]
[2021-08-19 17:17:03,301][MainThread:7160][task_id:django.utils.autoreload][autoreload.py:637][INFO][Watching for file changes with StatReloader]
[2021-08-19 17:17:29,083][MainThread:7160][task_id:django.utils.autoreload][autoreload.py:251][INFO][D:\zhouzhi\gitlit_code\logistic_tracking_system\logistic_tracking_system\lts\views.py changed, reloading.]
[2021-08-19 17:17:30,737][MainThread:15536][task_id:django.utils.autoreload][autoreload.py:637][INFO][Watching for file changes with StatReloader]
[2021-08-19 17:31:39,841][MainThread:15536][task_id:django.utils.autoreload][autoreload.py:251][INFO][D:\zhouzhi\gitlit_code\logistic_tracking_system\logistic_tracking_system\lts\views.py changed, reloading.]
[2021-08-19 17:31:40,907][MainThread:5244][task_id:django.utils.autoreload][autoreload.py:637][INFO][Watching for file changes with StatReloader]
[2021-08-19 17:35:45,524][MainThread:5244][task_id:django.utils.autoreload][autoreload.py:251][INFO][D:\zhouzhi\gitlit_code\logistic_tracking_system\logistic_tracking_system\lts\views.py changed, reloading.]
[2021-08-19 17:35:47,022][MainThread:3016][task_id:django.utils.autoreload][autoreload.py:637][INFO][Watching for file changes with StatReloader]
[2021-08-19 17:36:48,003][MainThread:3016][task_id:django.utils.autoreload][autoreload.py:251][INFO][D:\zhouzhi\gitlit_code\logistic_tracking_system\logistic_tracking_system\lts\views.py changed, reloading.]
[2021-08-19 17:36:49,060][MainThread:8416][task_id:django.utils.autoreload][autoreload.py:637][INFO][Watching for file changes with StatReloader]
[2021-08-19 17:37:05,812][MainThread:8416][task_id:django.utils.autoreload][autoreload.py:251][INFO][D:\zhouzhi\gitlit_code\logistic_tracking_system\logistic_tracking_system\lts\views.py changed, reloading.]
[2021-08-19 17:37:07,070][MainThread:18036][task_id:django.utils.autoreload][autoreload.py:637][INFO][Watching for file changes with StatReloader]
[2021-08-19 17:38:38,258][MainThread:18036][task_id:django.utils.autoreload][autoreload.py:251][INFO][D:\zhouzhi\gitlit_code\logistic_tracking_system\logistic_tracking_system\lts\views.py changed, reloading.]
[2021-08-19 17:38:39,357][MainThread:2416][task_id:django.utils.autoreload][autoreload.py:637][INFO][Watching for file changes with StatReloader]
[2021-08-19 17:41:15,204][MainThread:2416][task_id:django.utils.autoreload][autoreload.py:251][INFO][D:\zhouzhi\gitlit_code\logistic_tracking_system\logistic_tracking_system\lts\views.py changed, reloading.]
[2021-08-19 17:41:16,278][MainThread:304][task_id:django.utils.autoreload][autoreload.py:637][INFO][Watching for file changes with StatReloader]
[2021-08-19 17:43:25,717][MainThread:304][task_id:django.utils.autoreload][autoreload.py:251][INFO][D:\zhouzhi\gitlit_code\logistic_tracking_system\logistic_tracking_system\lts\views.py changed, reloading.]
[2021-08-19 17:43:26,826][MainThread:16432][task_id:django.utils.autoreload][autoreload.py:637][INFO][Watching for file changes with StatReloader]
[2021-08-19 17:43:57,782][MainThread:16432][task_id:django.utils.autoreload][autoreload.py:251][INFO][D:\zhouzhi\gitlit_code\logistic_tracking_system\logistic_tracking_system\lts\views.py changed, reloading.]
[2021-08-19 17:43:58,912][MainThread:22068][task_id:django.utils.autoreload][autoreload.py:637][INFO][Watching for file changes with StatReloader]
[2021-08-19 17:44:53,269][MainThread:22068][task_id:django.utils.autoreload][autoreload.py:251][INFO][D:\zhouzhi\gitlit_code\logistic_tracking_system\logistic_tracking_system\lts\views.py changed, reloading.]
[2021-08-19 17:44:54,594][MainThread:2388][task_id:django.utils.autoreload][autoreload.py:637][INFO][Watching for file changes with StatReloader]
[2021-08-19 17:45:05,993][MainThread:2388][task_id:django.utils.autoreload][autoreload.py:251][INFO][D:\zhouzhi\gitlit_code\logistic_tracking_system\logistic_tracking_system\lts\views.py changed, reloading.]
[2021-08-19 17:45:07,054][MainThread:21856][task_id:django.utils.autoreload][autoreload.py:637][INFO][Watching for file changes with StatReloader]
[2021-08-19 17:56:27,312][MainThread:21856][task_id:django.utils.autoreload][autoreload.py:251][INFO][D:\zhouzhi\gitlit_code\logistic_tracking_system\logistic_tracking_system\lts\views.py changed, reloading.]
[2021-08-19 17:56:28,810][MainThread:20840][task_id:django.utils.autoreload][autoreload.py:637][INFO][Watching for file changes with StatReloader]
[2021-08-19 18:07:16,987][MainThread:20840][task_id:django.utils.autoreload][autoreload.py:251][INFO][D:\zhouzhi\gitlit_code\logistic_tracking_system\logistic_tracking_system\lts\views.py changed, reloading.]
[2021-08-19 18:07:18,068][MainThread:3016][task_id:django.utils.autoreload][autoreload.py:637][INFO][Watching for file changes with StatReloader]
[2021-08-19 18:08:15,323][MainThread:3016][task_id:django.utils.autoreload][autoreload.py:251][INFO][D:\zhouzhi\gitlit_code\logistic_tracking_system\logistic_tracking_system\lts\views.py changed, reloading.]
[2021-08-19 18:08:17,007][MainThread:21736][task_id:django.utils.autoreload][autoreload.py:637][INFO][Watching for file changes with StatReloader]
[2021-08-19 18:09:26,136][MainThread:21736][task_id:django.utils.autoreload][autoreload.py:251][INFO][D:\zhouzhi\gitlit_code\logistic_tracking_system\logistic_tracking_system\lts\views.py changed, reloading.]
[2021-08-19 18:09:27,228][MainThread:22308][task_id:django.utils.autoreload][autoreload.py:637][INFO][Watching for file changes with StatReloader]
[2021-08-19 18:11:13,958][MainThread:22308][task_id:django.utils.autoreload][autoreload.py:251][INFO][D:\zhouzhi\gitlit_code\logistic_tracking_system\logistic_tracking_system\lts\views.py changed, reloading.]
[2021-08-19 18:11:15,024][MainThread:22424][task_id:django.utils.autoreload][autoreload.py:637][INFO][Watching for file changes with StatReloader]
[2021-08-19 18:19:00,635][MainThread:22424][task_id:django.utils.autoreload][autoreload.py:251][INFO][D:\zhouzhi\gitlit_code\logistic_tracking_system\logistic_tracking_system\lts\views.py changed, reloading.]
[2021-08-19 18:19:01,790][MainThread:23508][task_id:django.utils.autoreload][autoreload.py:637][INFO][Watching for file changes with StatReloader]
[2021-08-19 18:22:18,128][MainThread:23508][task_id:django.utils.autoreload][autoreload.py:251][INFO][D:\zhouzhi\gitlit_code\logistic_tracking_system\logistic_tracking_system\lts\views.py changed, reloading.]
[2021-08-19 18:22:19,291][MainThread:22932][task_id:django.utils.autoreload][autoreload.py:637][INFO][Watching for file changes with StatReloader]
[2021-08-19 18:22:56,667][MainThread:22932][task_id:django.utils.autoreload][autoreload.py:251][INFO][D:\zhouzhi\gitlit_code\logistic_tracking_system\logistic_tracking_system\lts\views.py changed, reloading.]
[2021-08-19 18:22:57,757][MainThread:23464][task_id:django.utils.autoreload][autoreload.py:637][INFO][Watching for file changes with StatReloader]
[2021-08-19 18:25:31,003][MainThread:23464][task_id:django.utils.autoreload][autoreload.py:251][INFO][D:\zhouzhi\gitlit_code\logistic_tracking_system\logistic_tracking_system\lts\views.py changed, reloading.]
[2021-08-19 18:25:35,388][MainThread:13332][task_id:django.utils.autoreload][autoreload.py:637][INFO][Watching for file changes with StatReloader]
[2021-08-19 18:25:58,010][MainThread:13332][task_id:django.utils.autoreload][autoreload.py:251][INFO][D:\zhouzhi\gitlit_code\logistic_tracking_system\logistic_tracking_system\lts\views.py changed, reloading.]
[2021-08-19 18:25:59,400][MainThread:12328][task_id:django.utils.autoreload][autoreload.py:637][INFO][Watching for file changes with StatReloader]
[2021-08-19 18:27:04,041][MainThread:12328][task_id:django.utils.autoreload][autoreload.py:251][INFO][D:\zhouzhi\gitlit_code\logistic_tracking_system\logistic_tracking_system\lts\urls.py changed, reloading.]
[2021-08-19 18:27:05,121][MainThread:1020][task_id:django.utils.autoreload][autoreload.py:637][INFO][Watching for file changes with StatReloader]
[2021-08-19 18:28:20,716][MainThread:1020][task_id:django.utils.autoreload][autoreload.py:251][INFO][D:\zhouzhi\gitlit_code\logistic_tracking_system\logistic_tracking_system\lts\urls.py changed, reloading.]
[2021-08-19 18:28:21,784][MainThread:20812][task_id:django.utils.autoreload][autoreload.py:637][INFO][Watching for file changes with StatReloader]
[2021-08-19 18:29:01,722][MainThread:20812][task_id:django.utils.autoreload][autoreload.py:251][INFO][D:\zhouzhi\gitlit_code\logistic_tracking_system\logistic_tracking_system\lts\views.py changed, reloading.]
[2021-08-19 18:29:02,796][MainThread:16460][task_id:django.utils.autoreload][autoreload.py:637][INFO][Watching for file changes with StatReloader]
[2021-08-19 18:30:14,007][Thread-5:22036][task_id:lts.views][views.py:7807][ERROR][修改失败---->name 'true' is not defined]
[2021-08-19 18:31:37,846][Thread-6:22536][task_id:django.request][log.py:230][ERROR][Internal Server Error: /logistic/LogisticDeleteWorkManage]
Traceback (most recent call last):
  File "C:\Users\zhi.zhou\Anaconda3\envs\lts\lib\site-packages\django\core\handlers\exception.py", line 47, in inner
    response = get_response(request)
  File "C:\Users\zhi.zhou\Anaconda3\envs\lts\lib\site-packages\django\core\handlers\base.py", line 188, in _get_response
    self.check_response(response, callback)
  File "C:\Users\zhi.zhou\Anaconda3\envs\lts\lib\site-packages\django\core\handlers\base.py", line 311, in check_response
    "instead." % name
ValueError: The view lts.views.DeleteWorkManage didn't return an HttpResponse object. It returned None instead.
[2021-08-19 18:32:12,659][Thread-6:22536][task_id:lts.views][views.py:7807][ERROR][修改失败---->name 'true' is not defined]
[2021-08-19 18:33:04,518][Thread-9:6572][task_id:lts.views][views.py:7807][ERROR][修改失败---->name 'true' is not defined]
[2021-08-19 18:33:27,793][MainThread:16460][task_id:django.utils.autoreload][autoreload.py:251][INFO][D:\zhouzhi\gitlit_code\logistic_tracking_system\logistic_tracking_system\lts\views.py changed, reloading.]
[2021-08-19 18:33:28,895][MainThread:21228][task_id:django.utils.autoreload][autoreload.py:637][INFO][Watching for file changes with StatReloader]
[2021-08-19 18:33:42,098][Thread-1:22504][task_id:lts.views][views.py:7809][ERROR][修改失败---->name 'true' is not defined]
[2021-08-19 18:34:21,536][MainThread:21228][task_id:django.utils.autoreload][autoreload.py:251][INFO][D:\zhouzhi\gitlit_code\logistic_tracking_system\logistic_tracking_system\lts\views.py changed, reloading.]
[2021-08-19 18:34:22,603][MainThread:12080][task_id:django.utils.autoreload][autoreload.py:637][INFO][Watching for file changes with StatReloader]
[2021-08-19 18:34:39,127][Thread-2:23356][task_id:lts.views][views.py:7810][ERROR][修改失败---->name 'true' is not defined]
[2021-08-19 18:34:59,131][MainThread:12080][task_id:django.utils.autoreload][autoreload.py:251][INFO][D:\zhouzhi\gitlit_code\logistic_tracking_system\logistic_tracking_system\lts\views.py changed, reloading.]
[2021-08-19 18:35:00,282][MainThread:22708][task_id:django.utils.autoreload][autoreload.py:637][INFO][Watching for file changes with StatReloader]
[2021-08-19 18:35:12,905][Thread-1:21800][task_id:lts.views][views.py:7811][ERROR][修改失败---->name 'true' is not defined]
[2021-08-19 18:35:32,441][MainThread:22708][task_id:django.utils.autoreload][autoreload.py:251][INFO][D:\zhouzhi\gitlit_code\logistic_tracking_system\logistic_tracking_system\lts\views.py changed, reloading.]
[2021-08-19 18:35:33,530][MainThread:23548][task_id:django.utils.autoreload][autoreload.py:637][INFO][Watching for file changes with StatReloader]
[2021-08-19 18:35:50,504][Thread-1:22512][task_id:lts.views][views.py:7811][ERROR][修改失败---->'str' object has no attribute 'get']
[2021-08-19 18:36:33,804][MainThread:23548][task_id:django.utils.autoreload][autoreload.py:251][INFO][D:\zhouzhi\gitlit_code\logistic_tracking_system\logistic_tracking_system\lts\views.py changed, reloading.]
[2021-08-19 18:36:34,888][MainThread:22020][task_id:django.utils.autoreload][autoreload.py:637][INFO][Watching for file changes with StatReloader]
[2021-08-19 18:39:58,572][MainThread:17284][task_id:django.utils.autoreload][autoreload.py:637][INFO][Watching for file changes with StatReloader]
[2021-08-19 18:40:32,829][MainThread:17284][task_id:django.utils.autoreload][autoreload.py:251][INFO][D:\zhouzhi\gitlit_code\logistic_tracking_system\logistic_tracking_system\lts\views.py changed, reloading.]
[2021-08-19 18:40:34,313][MainThread:4736][task_id:django.utils.autoreload][autoreload.py:637][INFO][Watching for file changes with StatReloader]
[2021-08-19 18:40:47,465][Thread-2:18880][task_id:django.request][log.py:230][ERROR][Internal Server Error: /logistic/LogisticWorkStation]
Traceback (most recent call last):
  File "D:\zhouzhi\gitlit_code\logistic_tracking_system\logistic_tracking_system\lts\views.py", line 2306, in get
    drs = db.execute_sql(conn, sql_main)
  File "D:\zhouzhi\gitlit_code\logistic_tracking_system\logistic_tracking_system\common\db.py", line 45, in execute_sql
    cursor.execute(sql)
  File "C:\Users\zhi.zhou\Anaconda3\envs\lts\lib\site-packages\pymysql\cursors.py", line 148, in execute
    result = self._query(query)
  File "C:\Users\zhi.zhou\Anaconda3\envs\lts\lib\site-packages\pymysql\cursors.py", line 310, in _query
    conn.query(q)
  File "C:\Users\zhi.zhou\Anaconda3\envs\lts\lib\site-packages\pymysql\connections.py", line 548, in query
    self._affected_rows = self._read_query_result(unbuffered=unbuffered)
  File "C:\Users\zhi.zhou\Anaconda3\envs\lts\lib\site-packages\pymysql\connections.py", line 775, in _read_query_result
    result.read()
  File "C:\Users\zhi.zhou\Anaconda3\envs\lts\lib\site-packages\pymysql\connections.py", line 1156, in read
    first_packet = self.connection._read_packet()
  File "C:\Users\zhi.zhou\Anaconda3\envs\lts\lib\site-packages\pymysql\connections.py", line 725, in _read_packet
    packet.raise_for_error()
  File "C:\Users\zhi.zhou\Anaconda3\envs\lts\lib\site-packages\pymysql\protocol.py", line 221, in raise_for_error
    err.raise_mysql_exception(self._data)
  File "C:\Users\zhi.zhou\Anaconda3\envs\lts\lib\site-packages\pymysql\err.py", line 143, in raise_mysql_exception
    raise errorclass(errno, errval)
pymysql.err.OperationalError: (1046, 'No database selected')

During handling of the above exception, another exception occurred:

Traceback (most recent call last):
  File "C:\Users\zhi.zhou\Anaconda3\envs\lts\lib\site-packages\django\core\handlers\exception.py", line 47, in inner
    response = get_response(request)
  File "C:\Users\zhi.zhou\Anaconda3\envs\lts\lib\site-packages\django\core\handlers\base.py", line 181, in _get_response
    response = wrapped_callback(request, *callback_args, **callback_kwargs)
  File "C:\Users\zhi.zhou\Anaconda3\envs\lts\lib\site-packages\django\views\generic\base.py", line 70, in view
    return self.dispatch(request, *args, **kwargs)
  File "C:\Users\zhi.zhou\Anaconda3\envs\lts\lib\site-packages\django\views\generic\base.py", line 98, in dispatch
    return handler(request, *args, **kwargs)
  File "D:\zhouzhi\gitlit_code\logistic_tracking_system\logistic_tracking_system\lts\views.py", line 2341, in get
    result = json.dumps(result)
  File "C:\Users\zhi.zhou\Anaconda3\envs\lts\lib\json\__init__.py", line 231, in dumps
    return _default_encoder.encode(obj)
  File "C:\Users\zhi.zhou\Anaconda3\envs\lts\lib\json\encoder.py", line 199, in encode
    chunks = self.iterencode(o, _one_shot=True)
  File "C:\Users\zhi.zhou\Anaconda3\envs\lts\lib\json\encoder.py", line 257, in iterencode
    return _iterencode(o, 0)
  File "C:\Users\zhi.zhou\Anaconda3\envs\lts\lib\json\encoder.py", line 180, in default
    o.__class__.__name__)
TypeError: Object of type 'OperationalError' is not JSON serializable
[2021-08-19 18:40:47,472][Thread-1:18876][task_id:django.request][log.py:230][ERROR][Internal Server Error: /logistic/LogisticWorkCodeName]
Traceback (most recent call last):
  File "D:\zhouzhi\gitlit_code\logistic_tracking_system\logistic_tracking_system\lts\views.py", line 3929, in get
    drs = db.execute_sql(conn, sql)
  File "D:\zhouzhi\gitlit_code\logistic_tracking_system\logistic_tracking_system\common\db.py", line 45, in execute_sql
    cursor.execute(sql)
  File "C:\Users\zhi.zhou\Anaconda3\envs\lts\lib\site-packages\pymysql\cursors.py", line 148, in execute
    result = self._query(query)
  File "C:\Users\zhi.zhou\Anaconda3\envs\lts\lib\site-packages\pymysql\cursors.py", line 310, in _query
    conn.query(q)
  File "C:\Users\zhi.zhou\Anaconda3\envs\lts\lib\site-packages\pymysql\connections.py", line 548, in query
    self._affected_rows = self._read_query_result(unbuffered=unbuffered)
  File "C:\Users\zhi.zhou\Anaconda3\envs\lts\lib\site-packages\pymysql\connections.py", line 775, in _read_query_result
    result.read()
  File "C:\Users\zhi.zhou\Anaconda3\envs\lts\lib\site-packages\pymysql\connections.py", line 1156, in read
    first_packet = self.connection._read_packet()
  File "C:\Users\zhi.zhou\Anaconda3\envs\lts\lib\site-packages\pymysql\connections.py", line 725, in _read_packet
    packet.raise_for_error()
  File "C:\Users\zhi.zhou\Anaconda3\envs\lts\lib\site-packages\pymysql\protocol.py", line 221, in raise_for_error
    err.raise_mysql_exception(self._data)
  File "C:\Users\zhi.zhou\Anaconda3\envs\lts\lib\site-packages\pymysql\err.py", line 143, in raise_mysql_exception
    raise errorclass(errno, errval)
pymysql.err.OperationalError: (1046, 'No database selected')

During handling of the above exception, another exception occurred:

Traceback (most recent call last):
  File "C:\Users\zhi.zhou\Anaconda3\envs\lts\lib\site-packages\django\core\handlers\exception.py", line 47, in inner
    response = get_response(request)
  File "C:\Users\zhi.zhou\Anaconda3\envs\lts\lib\site-packages\django\core\handlers\base.py", line 181, in _get_response
    response = wrapped_callback(request, *callback_args, **callback_kwargs)
  File "C:\Users\zhi.zhou\Anaconda3\envs\lts\lib\site-packages\django\views\generic\base.py", line 70, in view
    return self.dispatch(request, *args, **kwargs)
  File "C:\Users\zhi.zhou\Anaconda3\envs\lts\lib\site-packages\django\views\generic\base.py", line 98, in dispatch
    return handler(request, *args, **kwargs)
  File "D:\zhouzhi\gitlit_code\logistic_tracking_system\logistic_tracking_system\lts\views.py", line 3946, in get
    data = json.dumps(data)
  File "C:\Users\zhi.zhou\Anaconda3\envs\lts\lib\json\__init__.py", line 231, in dumps
    return _default_encoder.encode(obj)
  File "C:\Users\zhi.zhou\Anaconda3\envs\lts\lib\json\encoder.py", line 199, in encode
    chunks = self.iterencode(o, _one_shot=True)
  File "C:\Users\zhi.zhou\Anaconda3\envs\lts\lib\json\encoder.py", line 257, in iterencode
    return _iterencode(o, 0)
  File "C:\Users\zhi.zhou\Anaconda3\envs\lts\lib\json\encoder.py", line 180, in default
    o.__class__.__name__)
TypeError: Object of type 'OperationalError' is not JSON serializable
[2021-08-19 18:41:06,347][Thread-1:18876][task_id:lts.views][views.py:376][INFO][登录成功]
[2021-08-19 18:41:24,046][Thread-1:18876][task_id:lts.views][views.py:7811][ERROR][修改失败---->name 'true' is not defined]
[2021-08-19 18:41:32,024][Thread-4:7080][task_id:lts.views][views.py:7811][ERROR][修改失败---->name 'true' is not defined]
[2021-08-19 18:41:40,240][MainThread:4736][task_id:django.utils.autoreload][autoreload.py:251][INFO][D:\zhouzhi\gitlit_code\logistic_tracking_system\logistic_tracking_system\lts\views.py changed, reloading.]
[2021-08-19 18:41:41,472][MainThread:19116][task_id:django.utils.autoreload][autoreload.py:637][INFO][Watching for file changes with StatReloader]
[2021-08-19 18:41:46,584][Thread-1:17820][task_id:lts.views][views.py:7811][ERROR][修改失败---->'str' object has no attribute 'get']
[2021-08-19 18:42:30,338][MainThread:19116][task_id:django.utils.autoreload][autoreload.py:251][INFO][D:\zhouzhi\gitlit_code\logistic_tracking_system\logistic_tracking_system\lts\views.py changed, reloading.]
[2021-08-19 18:42:31,682][MainThread:18688][task_id:django.utils.autoreload][autoreload.py:637][INFO][Watching for file changes with StatReloader]
[2021-08-19 18:42:41,382][Thread-1:7488][task_id:lts.views][views.py:7811][ERROR][修改失败---->name 'true' is not defined]
[2021-08-19 18:43:23,808][Thread-2:11424][task_id:lts.views][views.py:7811][ERROR][修改失败---->name 'true' is not defined]
[2021-08-19 18:43:32,696][MainThread:18688][task_id:django.utils.autoreload][autoreload.py:251][INFO][D:\zhouzhi\gitlit_code\logistic_tracking_system\logistic_tracking_system\lts\views.py changed, reloading.]
[2021-08-19 18:43:33,758][MainThread:11628][task_id:django.utils.autoreload][autoreload.py:637][INFO][Watching for file changes with StatReloader]
[2021-08-19 18:44:00,608][MainThread:11628][task_id:django.utils.autoreload][autoreload.py:251][INFO][D:\zhouzhi\gitlit_code\logistic_tracking_system\logistic_tracking_system\lts\views.py changed, reloading.]
[2021-08-19 18:44:02,108][MainThread:3496][task_id:django.utils.autoreload][autoreload.py:637][INFO][Watching for file changes with StatReloader]
[2021-08-19 18:44:24,329][MainThread:3496][task_id:django.utils.autoreload][autoreload.py:251][INFO][D:\zhouzhi\gitlit_code\logistic_tracking_system\logistic_tracking_system\lts\views.py changed, reloading.]
[2021-08-19 18:44:25,422][MainThread:18224][task_id:django.utils.autoreload][autoreload.py:637][INFO][Watching for file changes with StatReloader]
[2021-08-19 18:44:30,877][Thread-1:3400][task_id:lts.views][views.py:7814][ERROR][修改失败---->name 'true' is not defined]
[2021-08-19 18:45:03,770][MainThread:18224][task_id:django.utils.autoreload][autoreload.py:251][INFO][D:\zhouzhi\gitlit_code\logistic_tracking_system\logistic_tracking_system\lts\views.py changed, reloading.]
[2021-08-19 18:45:05,146][MainThread:15704][task_id:django.utils.autoreload][autoreload.py:637][INFO][Watching for file changes with StatReloader]
[2021-08-19 18:45:05,974][Thread-1:17028][task_id:lts.views][views.py:7815][ERROR][修改失败---->name 'true' is not defined]
[2021-08-19 18:45:27,534][Thread-2:13996][task_id:lts.views][views.py:7815][ERROR][修改失败---->name 'true' is not defined]
[2021-08-19 18:50:08,877][MainThread:15704][task_id:django.utils.autoreload][autoreload.py:251][INFO][D:\zhouzhi\gitlit_code\logistic_tracking_system\logistic_tracking_system\lts\views.py changed, reloading.]
[2021-08-19 18:50:10,205][MainThread:3400][task_id:django.utils.autoreload][autoreload.py:637][INFO][Watching for file changes with StatReloader]
[2021-08-19 18:50:18,074][Thread-1:12560][task_id:lts.views][views.py:7814][ERROR][修改失败---->name 'true' is not defined]
[2021-08-19 18:51:58,174][Thread-2:5488][task_id:lts.views][views.py:144][INFO][登录成功]
[2021-08-19 18:53:42,437][Thread-7:15456][task_id:lts.views][views.py:7814][ERROR][修改失败---->name 'true' is not defined]
[2021-08-19 18:56:11,560][MainThread:3400][task_id:django.utils.autoreload][autoreload.py:251][INFO][D:\zhouzhi\gitlit_code\logistic_tracking_system\logistic_tracking_system\lts\views.py changed, reloading.]
[2021-08-19 18:56:12,622][MainThread:7488][task_id:django.utils.autoreload][autoreload.py:637][INFO][Watching for file changes with StatReloader]
[2021-08-19 18:57:27,617][Thread-2:4624][task_id:lts.views][views.py:7815][ERROR][修改失败---->name 'true' is not defined]
[2021-08-19 18:58:39,223][MainThread:7488][task_id:django.utils.autoreload][autoreload.py:251][INFO][D:\zhouzhi\gitlit_code\logistic_tracking_system\logistic_tracking_system\lts\views.py changed, reloading.]
[2021-08-19 18:58:42,304][MainThread:11520][task_id:django.utils.autoreload][autoreload.py:637][INFO][Watching for file changes with StatReloader]
[2021-08-19 19:00:19,318][MainThread:11520][task_id:django.utils.autoreload][autoreload.py:251][INFO][D:\zhouzhi\gitlit_code\logistic_tracking_system\logistic_tracking_system\lts\views.py changed, reloading.]
[2021-08-19 19:00:20,620][MainThread:9900][task_id:django.utils.autoreload][autoreload.py:637][INFO][Watching for file changes with StatReloader]
[2021-08-19 19:00:20,964][Thread-1:19368][task_id:lts.views][views.py:7823][ERROR][修改失败---->name 'true' is not defined]
[2021-08-19 19:00:46,006][MainThread:9900][task_id:django.utils.autoreload][autoreload.py:251][INFO][D:\zhouzhi\gitlit_code\logistic_tracking_system\logistic_tracking_system\lts\views.py changed, reloading.]
[2021-08-19 19:00:47,053][MainThread:9940][task_id:django.utils.autoreload][autoreload.py:637][INFO][Watching for file changes with StatReloader]
[2021-08-19 19:00:49,172][Thread-1:18736][task_id:lts.views][views.py:7823][ERROR][修改失败---->'str' object has no attribute 'get']
[2021-08-19 19:01:31,038][MainThread:9940][task_id:django.utils.autoreload][autoreload.py:251][INFO][D:\zhouzhi\gitlit_code\logistic_tracking_system\logistic_tracking_system\lts\views.py changed, reloading.]
[2021-08-19 19:01:32,234][MainThread:1516][task_id:django.utils.autoreload][autoreload.py:637][INFO][Watching for file changes with StatReloader]
[2021-08-19 19:01:33,085][Thread-1:13412][task_id:lts.views][views.py:7824][ERROR][修改失败---->name 'true' is not defined]
[2021-08-19 19:01:37,364][Thread-1:13412][task_id:lts.views][views.py:7824][ERROR][修改失败---->name 'true' is not defined]
[2021-08-19 19:02:25,426][MainThread:1516][task_id:django.utils.autoreload][autoreload.py:251][INFO][D:\zhouzhi\gitlit_code\logistic_tracking_system\logistic_tracking_system\lts\views.py changed, reloading.]
[2021-08-19 19:02:26,505][MainThread:11436][task_id:django.utils.autoreload][autoreload.py:637][INFO][Watching for file changes with StatReloader]
[2021-08-19 19:02:28,286][Thread-1:12052][task_id:lts.views][views.py:7826][ERROR][修改失败---->name 'true' is not defined]
[2021-08-19 19:05:34,467][MainThread:11436][task_id:django.utils.autoreload][autoreload.py:251][INFO][D:\zhouzhi\gitlit_code\logistic_tracking_system\logistic_tracking_system\lts\views.py changed, reloading.]
[2021-08-19 19:05:35,845][MainThread:17804][task_id:django.utils.autoreload][autoreload.py:637][INFO][Watching for file changes with StatReloader]
[2021-08-19 19:08:01,341][MainThread:17804][task_id:django.utils.autoreload][autoreload.py:251][INFO][D:\zhouzhi\gitlit_code\logistic_tracking_system\logistic_tracking_system\lts\views.py changed, reloading.]
[2021-08-19 19:08:02,410][MainThread:17972][task_id:django.utils.autoreload][autoreload.py:637][INFO][Watching for file changes with StatReloader]
[2021-08-19 19:08:05,789][Thread-1:15780][task_id:lts.views][views.py:7829][ERROR][修改失败---->'str' object has no attribute 'get']
[2021-08-19 19:08:38,754][MainThread:17972][task_id:django.utils.autoreload][autoreload.py:251][INFO][D:\zhouzhi\gitlit_code\logistic_tracking_system\logistic_tracking_system\lts\views.py changed, reloading.]
[2021-08-19 19:08:39,883][MainThread:8908][task_id:django.utils.autoreload][autoreload.py:637][INFO][Watching for file changes with StatReloader]
[2021-08-19 19:08:40,353][Thread-1:11436][task_id:lts.views][views.py:7830][ERROR][修改失败---->'str' object has no attribute 'get']
[2021-08-19 19:10:05,448][MainThread:8908][task_id:django.utils.autoreload][autoreload.py:251][INFO][D:\zhouzhi\gitlit_code\logistic_tracking_system\logistic_tracking_system\lts\views.py changed, reloading.]
[2021-08-19 19:10:06,835][MainThread:16712][task_id:django.utils.autoreload][autoreload.py:637][INFO][Watching for file changes with StatReloader]
[2021-08-19 19:10:09,277][Thread-1:17952][task_id:lts.views][views.py:7830][ERROR][修改失败---->name 'true' is not defined]
[2021-08-19 19:10:30,359][MainThread:16712][task_id:django.utils.autoreload][autoreload.py:251][INFO][D:\zhouzhi\gitlit_code\logistic_tracking_system\logistic_tracking_system\lts\views.py changed, reloading.]
[2021-08-19 19:10:31,567][MainThread:14960][task_id:django.utils.autoreload][autoreload.py:637][INFO][Watching for file changes with StatReloader]
[2021-08-19 19:10:32,564][Thread-1:3956][task_id:lts.views][views.py:7830][ERROR][修改失败---->'str' object has no attribute 'get']
[2021-08-19 19:10:41,930][MainThread:14960][task_id:django.utils.autoreload][autoreload.py:251][INFO][D:\zhouzhi\gitlit_code\logistic_tracking_system\logistic_tracking_system\lts\views.py changed, reloading.]
[2021-08-19 19:10:43,224][MainThread:15572][task_id:django.utils.autoreload][autoreload.py:637][INFO][Watching for file changes with StatReloader]
[2021-08-19 19:10:44,996][Thread-1:5476][task_id:lts.views][views.py:7830][ERROR][修改失败---->name 'true' is not defined]
[2021-08-19 19:12:36,499][Thread-2:9092][task_id:lts.views][views.py:7830][ERROR][修改失败---->name 'true' is not defined]
[2021-08-19 19:12:42,317][MainThread:15572][task_id:django.utils.autoreload][autoreload.py:251][INFO][D:\zhouzhi\gitlit_code\logistic_tracking_system\logistic_tracking_system\lts\views.py changed, reloading.]
[2021-08-19 19:12:43,401][MainThread:15928][task_id:django.utils.autoreload][autoreload.py:637][INFO][Watching for file changes with StatReloader]
[2021-08-19 19:16:13,490][MainThread:15928][task_id:django.utils.autoreload][autoreload.py:251][INFO][D:\zhouzhi\gitlit_code\logistic_tracking_system\logistic_tracking_system\lts\views.py changed, reloading.]
[2021-08-19 19:16:14,943][MainThread:2592][task_id:django.utils.autoreload][autoreload.py:637][INFO][Watching for file changes with StatReloader]
[2021-08-19 19:16:22,142][MainThread:2592][task_id:django.utils.autoreload][autoreload.py:251][INFO][D:\zhouzhi\gitlit_code\logistic_tracking_system\logistic_tracking_system\lts\views.py changed, reloading.]
[2021-08-19 19:16:23,492][MainThread:11432][task_id:django.utils.autoreload][autoreload.py:637][INFO][Watching for file changes with StatReloader]
[2021-08-19 19:24:24,810][Thread-6:20460][task_id:lts.views][views.py:7830][ERROR][修改失败---->name 'true' is not defined]
[2021-08-19 19:25:20,848][Thread-5:20076][task_id:lts.views][views.py:7830][ERROR][修改失败---->name 'true' is not defined]
[2021-08-19 19:26:11,127][Thread-6:20460][task_id:lts.views][views.py:7830][ERROR][修改失败---->name 'true' is not defined]
[2021-08-19 19:27:59,781][Thread-8:18220][task_id:lts.views][views.py:7830][ERROR][修改失败---->name 'true' is not defined]
[2021-08-19 19:28:29,842][MainThread:11432][task_id:django.utils.autoreload][autoreload.py:251][INFO][D:\zhouzhi\gitlit_code\logistic_tracking_system\logistic_tracking_system\lts\views.py changed, reloading.]
[2021-08-19 19:28:30,915][MainThread:13492][task_id:django.utils.autoreload][autoreload.py:637][INFO][Watching for file changes with StatReloader]
[2021-08-19 19:29:09,229][Thread-4:2808][task_id:lts.views][views.py:7830][ERROR][修改失败---->name 'true' is not defined]
[2021-08-19 19:30:10,081][Thread-7:7624][task_id:lts.views][views.py:7830][ERROR][修改失败---->(1064, "You have an error in your SQL syntax; check the manual that corresponds to your MySQL server version for the right syntax to use near 'INT AUTO_INCREMENT  primary key  not null' at line 1")]
[2021-08-19 19:30:37,304][MainThread:13492][task_id:django.utils.autoreload][autoreload.py:251][INFO][D:\zhouzhi\gitlit_code\logistic_tracking_system\logistic_tracking_system\lts\views.py changed, reloading.]
[2021-08-19 19:30:38,341][MainThread:10456][task_id:django.utils.autoreload][autoreload.py:637][INFO][Watching for file changes with StatReloader]
[2021-08-19 19:31:12,331][Thread-4:8880][task_id:lts.views][views.py:7830][ERROR][修改失败---->(1064, "You have an error in your SQL syntax; check the manual that corresponds to your MySQL server version for the right syntax to use near 'INT AUTO_INCREMENT  primary key  not null' at line 1")]
[2021-08-19 19:33:59,320][MainThread:10456][task_id:django.utils.autoreload][autoreload.py:251][INFO][D:\zhouzhi\gitlit_code\logistic_tracking_system\logistic_tracking_system\lts\views.py changed, reloading.]
[2021-08-19 19:34:00,362][MainThread:11484][task_id:django.utils.autoreload][autoreload.py:637][INFO][Watching for file changes with StatReloader]
[2021-08-19 19:34:16,663][Thread-1:18732][task_id:lts.views][views.py:7835][ERROR][修改失败---->(1064, "You have an error in your SQL syntax; check the manual that corresponds to your MySQL server version for the right syntax to use near 'INT AUTO_INCREMENT  primary key  not null' at line 1")]
[2021-08-19 19:40:16,199][MainThread:11484][task_id:django.utils.autoreload][autoreload.py:251][INFO][D:\zhouzhi\gitlit_code\logistic_tracking_system\logistic_tracking_system\lts\views.py changed, reloading.]
[2021-08-19 19:40:17,242][MainThread:2932][task_id:django.utils.autoreload][autoreload.py:637][INFO][Watching for file changes with StatReloader]
[2021-08-19 19:41:36,333][MainThread:2932][task_id:django.utils.autoreload][autoreload.py:251][INFO][D:\zhouzhi\gitlit_code\logistic_tracking_system\logistic_tracking_system\lts\views.py changed, reloading.]
[2021-08-19 19:41:37,592][MainThread:1532][task_id:django.utils.autoreload][autoreload.py:637][INFO][Watching for file changes with StatReloader]
[2021-08-19 19:42:25,933][MainThread:1532][task_id:django.utils.autoreload][autoreload.py:251][INFO][D:\zhouzhi\gitlit_code\logistic_tracking_system\logistic_tracking_system\lts\views.py changed, reloading.]
[2021-08-19 19:42:27,021][MainThread:12332][task_id:django.utils.autoreload][autoreload.py:637][INFO][Watching for file changes with StatReloader]
[2021-08-19 19:43:39,838][MainThread:12332][task_id:django.utils.autoreload][autoreload.py:251][INFO][D:\zhouzhi\gitlit_code\logistic_tracking_system\logistic_tracking_system\lts\views.py changed, reloading.]
[2021-08-19 19:43:40,930][MainThread:2080][task_id:django.utils.autoreload][autoreload.py:637][INFO][Watching for file changes with StatReloader]
[2021-08-19 19:44:44,475][MainThread:2080][task_id:django.utils.autoreload][autoreload.py:251][INFO][D:\zhouzhi\gitlit_code\logistic_tracking_system\logistic_tracking_system\lts\views.py changed, reloading.]
[2021-08-19 19:44:45,869][MainThread:15696][task_id:django.utils.autoreload][autoreload.py:637][INFO][Watching for file changes with StatReloader]
[2021-08-19 19:45:22,525][MainThread:15696][task_id:django.utils.autoreload][autoreload.py:251][INFO][D:\zhouzhi\gitlit_code\logistic_tracking_system\logistic_tracking_system\lts\views.py changed, reloading.]
[2021-08-19 19:45:23,595][MainThread:20368][task_id:django.utils.autoreload][autoreload.py:637][INFO][Watching for file changes with StatReloader]
[2021-08-19 19:45:51,252][MainThread:20368][task_id:django.utils.autoreload][autoreload.py:251][INFO][D:\zhouzhi\gitlit_code\logistic_tracking_system\logistic_tracking_system\lts\views.py changed, reloading.]
[2021-08-19 19:45:52,305][MainThread:20144][task_id:django.utils.autoreload][autoreload.py:637][INFO][Watching for file changes with StatReloader]
[2021-08-19 19:45:55,665][Thread-1:3764][task_id:lts.views][views.py:7853][ERROR][修改失败---->(3940, "Constraint 'field_name' does not exist.")]
[2021-08-19 19:46:47,160][MainThread:20144][task_id:django.utils.autoreload][autoreload.py:251][INFO][D:\zhouzhi\gitlit_code\logistic_tracking_system\logistic_tracking_system\lts\views.py changed, reloading.]
[2021-08-19 19:46:48,322][MainThread:15112][task_id:django.utils.autoreload][autoreload.py:637][INFO][Watching for file changes with StatReloader]
[2021-08-19 19:46:49,822][Thread-1:9088][task_id:lts.views][views.py:7853][ERROR][修改失败---->(3940, "Constraint 'id' does not exist.")]
[2021-08-19 19:48:16,253][MainThread:15112][task_id:django.utils.autoreload][autoreload.py:251][INFO][D:\zhouzhi\gitlit_code\logistic_tracking_system\logistic_tracking_system\lts\views.py changed, reloading.]
[2021-08-19 19:48:17,483][MainThread:17656][task_id:django.utils.autoreload][autoreload.py:637][INFO][Watching for file changes with StatReloader]
[2021-08-19 19:48:19,248][Thread-1:2808][task_id:lts.views][views.py:7854][ERROR][修改失败---->(3940, "Constraint 'id' does not exist.")]
[2021-08-19 19:58:54,512][MainThread:17656][task_id:django.utils.autoreload][autoreload.py:251][INFO][D:\zhouzhi\gitlit_code\logistic_tracking_system\logistic_tracking_system\lts\views.py changed, reloading.]
[2021-08-19 19:58:55,590][MainThread:19368][task_id:django.utils.autoreload][autoreload.py:637][INFO][Watching for file changes with StatReloader]
[2021-08-19 19:58:59,781][Thread-1:19184][task_id:lts.views][views.py:7854][ERROR][修改失败---->(1064, "You have an error in your SQL syntax; check the manual that corresponds to your MySQL server version for the right syntax to use near 'PRIMARY' at line 1")]
[2021-08-19 19:59:43,973][MainThread:19368][task_id:django.utils.autoreload][autoreload.py:251][INFO][D:\zhouzhi\gitlit_code\logistic_tracking_system\logistic_tracking_system\lts\views.py changed, reloading.]
[2021-08-19 19:59:45,029][MainThread:7612][task_id:django.utils.autoreload][autoreload.py:637][INFO][Watching for file changes with StatReloader]
[2021-08-19 19:59:46,719][Thread-1:14848][task_id:lts.views][views.py:7854][ERROR][修改失败---->(1064, "You have an error in your SQL syntax; check the manual that corresponds to your MySQL server version for the right syntax to use near ''PRIMARY'' at line 1")]
[2021-08-19 20:06:35,581][MainThread:7612][task_id:django.utils.autoreload][autoreload.py:251][INFO][D:\zhouzhi\gitlit_code\logistic_tracking_system\logistic_tracking_system\lts\views.py changed, reloading.]
[2021-08-19 20:06:36,672][MainThread:12136][task_id:django.utils.autoreload][autoreload.py:637][INFO][Watching for file changes with StatReloader]
[2021-08-19 20:06:40,078][Thread-1:21412][task_id:lts.views][views.py:7854][ERROR][修改失败---->(1075, 'Incorrect table definition; there can be only one auto column and it must be defined as a key')]
[2021-08-19 20:09:15,130][Thread-3:13964][task_id:lts.views][views.py:7854][ERROR][修改失败---->(1075, 'Incorrect table definition; there can be only one auto column and it must be defined as a key')]
[2021-08-19 20:13:34,453][MainThread:12136][task_id:django.utils.autoreload][autoreload.py:251][INFO][D:\zhouzhi\gitlit_code\logistic_tracking_system\logistic_tracking_system\lts\views.py changed, reloading.]
[2021-08-19 20:13:35,569][MainThread:11188][task_id:django.utils.autoreload][autoreload.py:637][INFO][Watching for file changes with StatReloader]
[2021-08-19 20:13:37,269][Thread-1:13672][task_id:lts.views][views.py:7855][ERROR][修改失败---->(1064, "You have an error in your SQL syntax; check the manual that corresponds to your MySQL server version for the right syntax to use near '' at line 1")]
[2021-08-19 20:14:59,759][MainThread:11188][task_id:django.utils.autoreload][autoreload.py:251][INFO][D:\zhouzhi\gitlit_code\logistic_tracking_system\logistic_tracking_system\lts\views.py changed, reloading.]
[2021-08-19 20:15:00,912][MainThread:14816][task_id:django.utils.autoreload][autoreload.py:637][INFO][Watching for file changes with StatReloader]
[2021-08-19 20:15:01,267][Thread-1:20936][task_id:lts.views][views.py:7856][ERROR][修改失败---->(1064, "You have an error in your SQL syntax; check the manual that corresponds to your MySQL server version for the right syntax to use near '' at line 1")]
[2021-08-19 20:15:42,290][MainThread:14816][task_id:django.utils.autoreload][autoreload.py:251][INFO][D:\zhouzhi\gitlit_code\logistic_tracking_system\logistic_tracking_system\lts\views.py changed, reloading.]
[2021-08-19 20:15:43,362][MainThread:13672][task_id:django.utils.autoreload][autoreload.py:637][INFO][Watching for file changes with StatReloader]
[2021-08-19 20:15:44,663][Thread-1:17656][task_id:lts.views][views.py:7858][ERROR][修改失败---->(1064, "You have an error in your SQL syntax; check the manual that corresponds to your MySQL server version for the right syntax to use near '' at line 1")]
[2021-08-19 20:16:10,323][MainThread:13672][task_id:django.utils.autoreload][autoreload.py:251][INFO][D:\zhouzhi\gitlit_code\logistic_tracking_system\logistic_tracking_system\lts\views.py changed, reloading.]
[2021-08-19 20:16:12,043][MainThread:2472][task_id:django.utils.autoreload][autoreload.py:637][INFO][Watching for file changes with StatReloader]
[2021-08-19 20:16:12,493][Thread-1:3744][task_id:lts.views][views.py:7859][ERROR][修改失败---->(1064, "You have an error in your SQL syntax; check the manual that corresponds to your MySQL server version for the right syntax to use near '' at line 1")]
[2021-08-19 20:16:59,487][MainThread:2472][task_id:django.utils.autoreload][autoreload.py:251][INFO][D:\zhouzhi\gitlit_code\logistic_tracking_system\logistic_tracking_system\lts\views.py changed, reloading.]
[2021-08-19 20:17:00,561][MainThread:3084][task_id:django.utils.autoreload][autoreload.py:637][INFO][Watching for file changes with StatReloader]
[2021-08-19 20:17:01,997][Thread-1:21052][task_id:lts.views][views.py:7857][ERROR][修改失败---->(1075, 'Incorrect table definition; there can be only one auto column and it must be defined as a key')]
[2021-08-19 20:20:39,884][MainThread:3084][task_id:django.utils.autoreload][autoreload.py:251][INFO][D:\zhouzhi\gitlit_code\logistic_tracking_system\logistic_tracking_system\lts\views.py changed, reloading.]
[2021-08-19 20:20:40,967][MainThread:19936][task_id:django.utils.autoreload][autoreload.py:637][INFO][Watching for file changes with StatReloader]
[2021-08-19 20:20:43,282][Thread-1:20940][task_id:lts.views][views.py:7858][ERROR][修改失败---->(1075, 'Incorrect table definition; there can be only one auto column and it must be defined as a key')]
[2021-08-19 20:25:35,601][MainThread:19936][task_id:django.utils.autoreload][autoreload.py:251][INFO][D:\zhouzhi\gitlit_code\logistic_tracking_system\logistic_tracking_system\lts\views.py changed, reloading.]
[2021-08-19 20:25:36,709][MainThread:15972][task_id:django.utils.autoreload][autoreload.py:637][INFO][Watching for file changes with StatReloader]
[2021-08-19 20:29:05,180][MainThread:15972][task_id:django.utils.autoreload][autoreload.py:251][INFO][D:\zhouzhi\gitlit_code\logistic_tracking_system\logistic_tracking_system\lts\views.py changed, reloading.]
[2021-08-19 20:29:06,245][MainThread:12000][task_id:django.utils.autoreload][autoreload.py:637][INFO][Watching for file changes with StatReloader]
[2021-08-19 20:31:15,095][MainThread:12000][task_id:django.utils.autoreload][autoreload.py:251][INFO][D:\zhouzhi\gitlit_code\logistic_tracking_system\logistic_tracking_system\lts\views.py changed, reloading.]
[2021-08-19 20:31:16,174][MainThread:6436][task_id:django.utils.autoreload][autoreload.py:637][INFO][Watching for file changes with StatReloader]
[2021-08-19 20:31:33,173][MainThread:6436][task_id:django.utils.autoreload][autoreload.py:251][INFO][D:\zhouzhi\gitlit_code\logistic_tracking_system\logistic_tracking_system\lts\views.py changed, reloading.]
[2021-08-19 20:31:34,698][MainThread:4672][task_id:django.utils.autoreload][autoreload.py:637][INFO][Watching for file changes with StatReloader]
[2021-08-19 20:36:15,507][MainThread:19744][task_id:django.utils.autoreload][autoreload.py:637][INFO][Watching for file changes with StatReloader]
[2021-08-19 20:37:42,587][MainThread:19744][task_id:django.utils.autoreload][autoreload.py:251][INFO][D:\zhouzhi\gitlit_code\logistic_tracking_system\logistic_tracking_system\lts\views.py changed, reloading.]
[2021-08-19 20:37:44,324][MainThread:20080][task_id:django.utils.autoreload][autoreload.py:637][INFO][Watching for file changes with StatReloader]
[2021-08-19 20:42:28,022][MainThread:20080][task_id:django.utils.autoreload][autoreload.py:251][INFO][D:\zhouzhi\gitlit_code\logistic_tracking_system\logistic_tracking_system\lts\views.py changed, reloading.]
[2021-08-19 20:42:29,115][MainThread:18116][task_id:django.utils.autoreload][autoreload.py:637][INFO][Watching for file changes with StatReloader]
[2021-08-19 20:50:05,505][Thread-9:8668][task_id:lts.views][views.py:7860][ERROR][修改失败---->(1064, "You have an error in your SQL syntax; check the manual that corresponds to your MySQL server version for the right syntax to use near 'INT' at line 1")]
[2021-08-19 21:00:45,654][Thread-10:19920][task_id:lts.views][views.py:7860][ERROR][修改失败---->(1064, "You have an error in your SQL syntax; check the manual that corresponds to your MySQL server version for the right syntax to use near 'INT' at line 1")]
[2021-08-19 21:00:52,897][Thread-10:19920][task_id:lts.views][views.py:7860][ERROR][修改失败---->(1064, "You have an error in your SQL syntax; check the manual that corresponds to your MySQL server version for the right syntax to use near 'INT' at line 1")]
[2021-08-19 21:02:23,973][MainThread:18116][task_id:django.utils.autoreload][autoreload.py:251][INFO][D:\zhouzhi\gitlit_code\logistic_tracking_system\logistic_tracking_system\lts\views.py changed, reloading.]
[2021-08-19 21:02:25,259][MainThread:1100][task_id:django.utils.autoreload][autoreload.py:637][INFO][Watching for file changes with StatReloader]
[2021-08-19 21:02:39,587][MainThread:1100][task_id:django.utils.autoreload][autoreload.py:251][INFO][D:\zhouzhi\gitlit_code\logistic_tracking_system\logistic_tracking_system\lts\views.py changed, reloading.]
[2021-08-19 21:02:40,645][MainThread:22032][task_id:django.utils.autoreload][autoreload.py:637][INFO][Watching for file changes with StatReloader]
[2021-08-19 21:03:23,472][MainThread:22032][task_id:django.utils.autoreload][autoreload.py:251][INFO][D:\zhouzhi\gitlit_code\logistic_tracking_system\logistic_tracking_system\lts\views.py changed, reloading.]
[2021-08-19 21:03:24,532][MainThread:21696][task_id:django.utils.autoreload][autoreload.py:637][INFO][Watching for file changes with StatReloader]
[2021-08-19 21:03:47,790][MainThread:21696][task_id:django.utils.autoreload][autoreload.py:251][INFO][D:\zhouzhi\gitlit_code\logistic_tracking_system\logistic_tracking_system\lts\views.py changed, reloading.]
[2021-08-19 21:03:48,932][MainThread:21688][task_id:django.utils.autoreload][autoreload.py:637][INFO][Watching for file changes with StatReloader]
[2021-08-19 21:03:55,629][Thread-1:20184][task_id:lts.views][views.py:7863][ERROR][修改失败---->(1064, "You have an error in your SQL syntax; check the manual that corresponds to your MySQL server version for the right syntax to use near '(column age INT)' at line 1")]
[2021-08-19 21:07:02,695][MainThread:21688][task_id:django.utils.autoreload][autoreload.py:251][INFO][D:\zhouzhi\gitlit_code\logistic_tracking_system\logistic_tracking_system\lts\views.py changed, reloading.]
[2021-08-19 21:07:03,758][MainThread:5624][task_id:django.utils.autoreload][autoreload.py:637][INFO][Watching for file changes with StatReloader]
