[2021-07-27 09:03:31,816][MainThread:916][task_id:django.utils.autoreload][autoreload.py:637][INFO][Watching for file changes with StatReloader]
[2021-07-27 09:13:45,087][Thread-2:5128][task_id:lts.views][views.py:148][INFO][登录成功]
[2021-07-27 09:23:10,799][Thread-4:17376][task_id:lts.views][views.py:218][INFO][登录成功]
[2021-07-27 09:23:14,205][Thread-4:17376][task_id:django.request][log.py:230][ERROR][Internal Server Error: /logistic/LogisticProcessDeal]
Traceback (most recent call last):
  File "D:\zhouzhi\gitlit_code\logistic_tracking_system\logistic_tracking_system\lts\views.py", line 3773, in get
    if len(production_name) == 0 and len(prodect_code) == 0 and len(work_id) == 0:
TypeError: object of type 'NoneType' has no len()

During handling of the above exception, another exception occurred:

Traceback (most recent call last):
  File "C:\Users\zhi.zhou\Anaconda3\envs\lts\lib\site-packages\django\core\handlers\exception.py", line 47, in inner
    response = get_response(request)
  File "C:\Users\zhi.zhou\Anaconda3\envs\lts\lib\site-packages\django\core\handlers\base.py", line 181, in _get_response
    response = wrapped_callback(request, *callback_args, **callback_kwargs)
  File "C:\Users\zhi.zhou\Anaconda3\envs\lts\lib\site-packages\django\views\generic\base.py", line 70, in view
    return self.dispatch(request, *args, **kwargs)
  File "C:\Users\zhi.zhou\Anaconda3\envs\lts\lib\site-packages\django\views\generic\base.py", line 98, in dispatch
    return handler(request, *args, **kwargs)
  File "D:\zhouzhi\gitlit_code\logistic_tracking_system\logistic_tracking_system\lts\views.py", line 4033, in get
    data = json.dumps(data)
  File "C:\Users\zhi.zhou\Anaconda3\envs\lts\lib\json\__init__.py", line 231, in dumps
    return _default_encoder.encode(obj)
  File "C:\Users\zhi.zhou\Anaconda3\envs\lts\lib\json\encoder.py", line 199, in encode
    chunks = self.iterencode(o, _one_shot=True)
  File "C:\Users\zhi.zhou\Anaconda3\envs\lts\lib\json\encoder.py", line 257, in iterencode
    return _iterencode(o, 0)
  File "C:\Users\zhi.zhou\Anaconda3\envs\lts\lib\json\encoder.py", line 180, in default
    o.__class__.__name__)
TypeError: Object of type 'TypeError' is not JSON serializable
[2021-07-27 09:28:15,291][Thread-6:10400][task_id:django.request][log.py:230][ERROR][Internal Server Error: /logistic/LogisticWorkStation]
Traceback (most recent call last):
  File "D:\zhouzhi\gitlit_code\logistic_tracking_system\logistic_tracking_system\lts\views.py", line 2451, in get
    drs = db.execute_sql(conn, sql_main)
  File "D:\zhouzhi\gitlit_code\logistic_tracking_system\logistic_tracking_system\common\db.py", line 45, in execute_sql
    cursor.execute(sql)
  File "C:\Users\zhi.zhou\Anaconda3\envs\lts\lib\site-packages\pymysql\cursors.py", line 148, in execute
    result = self._query(query)
  File "C:\Users\zhi.zhou\Anaconda3\envs\lts\lib\site-packages\pymysql\cursors.py", line 310, in _query
    conn.query(q)
  File "C:\Users\zhi.zhou\Anaconda3\envs\lts\lib\site-packages\pymysql\connections.py", line 548, in query
    self._affected_rows = self._read_query_result(unbuffered=unbuffered)
  File "C:\Users\zhi.zhou\Anaconda3\envs\lts\lib\site-packages\pymysql\connections.py", line 775, in _read_query_result
    result.read()
  File "C:\Users\zhi.zhou\Anaconda3\envs\lts\lib\site-packages\pymysql\connections.py", line 1156, in read
    first_packet = self.connection._read_packet()
  File "C:\Users\zhi.zhou\Anaconda3\envs\lts\lib\site-packages\pymysql\connections.py", line 725, in _read_packet
    packet.raise_for_error()
  File "C:\Users\zhi.zhou\Anaconda3\envs\lts\lib\site-packages\pymysql\protocol.py", line 221, in raise_for_error
    err.raise_mysql_exception(self._data)
  File "C:\Users\zhi.zhou\Anaconda3\envs\lts\lib\site-packages\pymysql\err.py", line 143, in raise_mysql_exception
    raise errorclass(errno, errval)
pymysql.err.OperationalError: (1046, 'No database selected')

During handling of the above exception, another exception occurred:

Traceback (most recent call last):
  File "C:\Users\zhi.zhou\Anaconda3\envs\lts\lib\site-packages\django\core\handlers\exception.py", line 47, in inner
    response = get_response(request)
  File "C:\Users\zhi.zhou\Anaconda3\envs\lts\lib\site-packages\django\core\handlers\base.py", line 181, in _get_response
    response = wrapped_callback(request, *callback_args, **callback_kwargs)
  File "C:\Users\zhi.zhou\Anaconda3\envs\lts\lib\site-packages\django\views\generic\base.py", line 70, in view
    return self.dispatch(request, *args, **kwargs)
  File "C:\Users\zhi.zhou\Anaconda3\envs\lts\lib\site-packages\django\views\generic\base.py", line 98, in dispatch
    return handler(request, *args, **kwargs)
  File "D:\zhouzhi\gitlit_code\logistic_tracking_system\logistic_tracking_system\lts\views.py", line 2587, in get
    result = json.dumps(result)
  File "C:\Users\zhi.zhou\Anaconda3\envs\lts\lib\json\__init__.py", line 231, in dumps
    return _default_encoder.encode(obj)
  File "C:\Users\zhi.zhou\Anaconda3\envs\lts\lib\json\encoder.py", line 199, in encode
    chunks = self.iterencode(o, _one_shot=True)
  File "C:\Users\zhi.zhou\Anaconda3\envs\lts\lib\json\encoder.py", line 257, in iterencode
    return _iterencode(o, 0)
  File "C:\Users\zhi.zhou\Anaconda3\envs\lts\lib\json\encoder.py", line 180, in default
    o.__class__.__name__)
TypeError: Object of type 'OperationalError' is not JSON serializable
[2021-07-27 09:28:37,692][Thread-6:10400][task_id:lts.views][views.py:218][INFO][登录成功]
[2021-07-27 09:28:41,425][Thread-6:10400][task_id:django.request][log.py:230][ERROR][Internal Server Error: /logistic/LogisticProcessDeal]
Traceback (most recent call last):
  File "D:\zhouzhi\gitlit_code\logistic_tracking_system\logistic_tracking_system\lts\views.py", line 3773, in get
    if len(production_name) == 0 and len(prodect_code) == 0 and len(work_id) == 0:
TypeError: object of type 'NoneType' has no len()

During handling of the above exception, another exception occurred:

Traceback (most recent call last):
  File "C:\Users\zhi.zhou\Anaconda3\envs\lts\lib\site-packages\django\core\handlers\exception.py", line 47, in inner
    response = get_response(request)
  File "C:\Users\zhi.zhou\Anaconda3\envs\lts\lib\site-packages\django\core\handlers\base.py", line 181, in _get_response
    response = wrapped_callback(request, *callback_args, **callback_kwargs)
  File "C:\Users\zhi.zhou\Anaconda3\envs\lts\lib\site-packages\django\views\generic\base.py", line 70, in view
    return self.dispatch(request, *args, **kwargs)
  File "C:\Users\zhi.zhou\Anaconda3\envs\lts\lib\site-packages\django\views\generic\base.py", line 98, in dispatch
    return handler(request, *args, **kwargs)
  File "D:\zhouzhi\gitlit_code\logistic_tracking_system\logistic_tracking_system\lts\views.py", line 4033, in get
    data = json.dumps(data)
  File "C:\Users\zhi.zhou\Anaconda3\envs\lts\lib\json\__init__.py", line 231, in dumps
    return _default_encoder.encode(obj)
  File "C:\Users\zhi.zhou\Anaconda3\envs\lts\lib\json\encoder.py", line 199, in encode
    chunks = self.iterencode(o, _one_shot=True)
  File "C:\Users\zhi.zhou\Anaconda3\envs\lts\lib\json\encoder.py", line 257, in iterencode
    return _iterencode(o, 0)
  File "C:\Users\zhi.zhou\Anaconda3\envs\lts\lib\json\encoder.py", line 180, in default
    o.__class__.__name__)
TypeError: Object of type 'TypeError' is not JSON serializable
[2021-07-27 09:29:53,552][Thread-9:3132][task_id:django.request][log.py:230][ERROR][Internal Server Error: /logistic/LogisticProcessDeal]
Traceback (most recent call last):
  File "D:\zhouzhi\gitlit_code\logistic_tracking_system\logistic_tracking_system\lts\views.py", line 3773, in get
    if len(production_name) == 0 and len(prodect_code) == 0 and len(work_id) == 0:
TypeError: object of type 'NoneType' has no len()

During handling of the above exception, another exception occurred:

Traceback (most recent call last):
  File "C:\Users\zhi.zhou\Anaconda3\envs\lts\lib\site-packages\django\core\handlers\exception.py", line 47, in inner
    response = get_response(request)
  File "C:\Users\zhi.zhou\Anaconda3\envs\lts\lib\site-packages\django\core\handlers\base.py", line 181, in _get_response
    response = wrapped_callback(request, *callback_args, **callback_kwargs)
  File "C:\Users\zhi.zhou\Anaconda3\envs\lts\lib\site-packages\django\views\generic\base.py", line 70, in view
    return self.dispatch(request, *args, **kwargs)
  File "C:\Users\zhi.zhou\Anaconda3\envs\lts\lib\site-packages\django\views\generic\base.py", line 98, in dispatch
    return handler(request, *args, **kwargs)
  File "D:\zhouzhi\gitlit_code\logistic_tracking_system\logistic_tracking_system\lts\views.py", line 4033, in get
    data = json.dumps(data)
  File "C:\Users\zhi.zhou\Anaconda3\envs\lts\lib\json\__init__.py", line 231, in dumps
    return _default_encoder.encode(obj)
  File "C:\Users\zhi.zhou\Anaconda3\envs\lts\lib\json\encoder.py", line 199, in encode
    chunks = self.iterencode(o, _one_shot=True)
  File "C:\Users\zhi.zhou\Anaconda3\envs\lts\lib\json\encoder.py", line 257, in iterencode
    return _iterencode(o, 0)
  File "C:\Users\zhi.zhou\Anaconda3\envs\lts\lib\json\encoder.py", line 180, in default
    o.__class__.__name__)
TypeError: Object of type 'TypeError' is not JSON serializable
[2021-07-27 09:29:53,722][Thread-10:4316][task_id:django.request][log.py:230][ERROR][Internal Server Error: /logistic/LogisticProcessDeal]
Traceback (most recent call last):
  File "D:\zhouzhi\gitlit_code\logistic_tracking_system\logistic_tracking_system\lts\views.py", line 3773, in get
    if len(production_name) == 0 and len(prodect_code) == 0 and len(work_id) == 0:
TypeError: object of type 'NoneType' has no len()

During handling of the above exception, another exception occurred:

Traceback (most recent call last):
  File "C:\Users\zhi.zhou\Anaconda3\envs\lts\lib\site-packages\django\core\handlers\exception.py", line 47, in inner
    response = get_response(request)
  File "C:\Users\zhi.zhou\Anaconda3\envs\lts\lib\site-packages\django\core\handlers\base.py", line 181, in _get_response
    response = wrapped_callback(request, *callback_args, **callback_kwargs)
  File "C:\Users\zhi.zhou\Anaconda3\envs\lts\lib\site-packages\django\views\generic\base.py", line 70, in view
    return self.dispatch(request, *args, **kwargs)
  File "C:\Users\zhi.zhou\Anaconda3\envs\lts\lib\site-packages\django\views\generic\base.py", line 98, in dispatch
    return handler(request, *args, **kwargs)
  File "D:\zhouzhi\gitlit_code\logistic_tracking_system\logistic_tracking_system\lts\views.py", line 4033, in get
    data = json.dumps(data)
  File "C:\Users\zhi.zhou\Anaconda3\envs\lts\lib\json\__init__.py", line 231, in dumps
    return _default_encoder.encode(obj)
  File "C:\Users\zhi.zhou\Anaconda3\envs\lts\lib\json\encoder.py", line 199, in encode
    chunks = self.iterencode(o, _one_shot=True)
  File "C:\Users\zhi.zhou\Anaconda3\envs\lts\lib\json\encoder.py", line 257, in iterencode
    return _iterencode(o, 0)
  File "C:\Users\zhi.zhou\Anaconda3\envs\lts\lib\json\encoder.py", line 180, in default
    o.__class__.__name__)
TypeError: Object of type 'TypeError' is not JSON serializable
[2021-07-27 09:31:44,387][MainThread:916][task_id:django.utils.autoreload][autoreload.py:251][INFO][D:\zhouzhi\gitlit_code\logistic_tracking_system\logistic_tracking_system\lts\views.py changed, reloading.]
[2021-07-27 09:31:45,050][MainThread:7824][task_id:django.utils.autoreload][autoreload.py:637][INFO][Watching for file changes with StatReloader]
[2021-07-27 09:32:06,085][MainThread:7824][task_id:django.utils.autoreload][autoreload.py:251][INFO][D:\zhouzhi\gitlit_code\logistic_tracking_system\logistic_tracking_system\lts\views.py changed, reloading.]
[2021-07-27 09:32:06,858][MainThread:4620][task_id:django.utils.autoreload][autoreload.py:637][INFO][Watching for file changes with StatReloader]
[2021-07-27 09:34:02,610][MainThread:4620][task_id:django.utils.autoreload][autoreload.py:251][INFO][D:\zhouzhi\gitlit_code\logistic_tracking_system\logistic_tracking_system\lts\views.py changed, reloading.]
[2021-07-27 09:34:03,270][MainThread:876][task_id:django.utils.autoreload][autoreload.py:637][INFO][Watching for file changes with StatReloader]
[2021-07-27 09:34:14,986][MainThread:876][task_id:django.utils.autoreload][autoreload.py:251][INFO][D:\zhouzhi\gitlit_code\logistic_tracking_system\logistic_tracking_system\lts\views.py changed, reloading.]
[2021-07-27 09:34:15,618][MainThread:7708][task_id:django.utils.autoreload][autoreload.py:637][INFO][Watching for file changes with StatReloader]
[2021-07-27 09:36:20,211][MainThread:7708][task_id:django.utils.autoreload][autoreload.py:251][INFO][D:\zhouzhi\gitlit_code\logistic_tracking_system\logistic_tracking_system\lts\views.py changed, reloading.]
[2021-07-27 09:36:20,849][MainThread:3696][task_id:django.utils.autoreload][autoreload.py:637][INFO][Watching for file changes with StatReloader]
[2021-07-27 09:36:39,869][MainThread:3696][task_id:django.utils.autoreload][autoreload.py:251][INFO][D:\zhouzhi\gitlit_code\logistic_tracking_system\logistic_tracking_system\lts\views.py changed, reloading.]
[2021-07-27 09:36:40,512][MainThread:12064][task_id:django.utils.autoreload][autoreload.py:637][INFO][Watching for file changes with StatReloader]
[2021-07-27 09:41:20,872][Thread-2:10176][task_id:lts.views][views.py:218][INFO][登录成功]
[2021-07-27 09:41:37,876][Thread-2:10176][task_id:lts.views][views.py:272][INFO][登录成功]
[2021-07-27 09:46:09,546][Thread-5:7376][task_id:lts.views][views.py:218][INFO][登录成功]
[2021-07-27 09:47:18,651][Thread-7:12772][task_id:lts.views][views.py:2041][INFO][创建产品详情表成功]
[2021-07-27 09:48:05,943][Thread-7:12772][task_id:lts.views][views.py:218][INFO][登录成功]
[2021-07-27 09:48:12,701][Thread-8:9800][task_id:django.request][log.py:230][ERROR][Internal Server Error: /logistic/LogisticProcessDeal]
Traceback (most recent call last):
  File "D:\zhouzhi\gitlit_code\logistic_tracking_system\logistic_tracking_system\lts\views.py", line 3774, in get
    if len(production_name) == 0 and len(prodect_code) == 0 and len(work_id) == 0:
TypeError: object of type 'NoneType' has no len()

During handling of the above exception, another exception occurred:

Traceback (most recent call last):
  File "C:\Users\zhi.zhou\Anaconda3\envs\lts\lib\site-packages\django\core\handlers\exception.py", line 47, in inner
    response = get_response(request)
  File "C:\Users\zhi.zhou\Anaconda3\envs\lts\lib\site-packages\django\core\handlers\base.py", line 181, in _get_response
    response = wrapped_callback(request, *callback_args, **callback_kwargs)
  File "C:\Users\zhi.zhou\Anaconda3\envs\lts\lib\site-packages\django\views\generic\base.py", line 70, in view
    return self.dispatch(request, *args, **kwargs)
  File "C:\Users\zhi.zhou\Anaconda3\envs\lts\lib\site-packages\django\views\generic\base.py", line 98, in dispatch
    return handler(request, *args, **kwargs)
  File "D:\zhouzhi\gitlit_code\logistic_tracking_system\logistic_tracking_system\lts\views.py", line 4042, in get
    data = json.dumps(data)
  File "C:\Users\zhi.zhou\Anaconda3\envs\lts\lib\json\__init__.py", line 231, in dumps
    return _default_encoder.encode(obj)
  File "C:\Users\zhi.zhou\Anaconda3\envs\lts\lib\json\encoder.py", line 199, in encode
    chunks = self.iterencode(o, _one_shot=True)
  File "C:\Users\zhi.zhou\Anaconda3\envs\lts\lib\json\encoder.py", line 257, in iterencode
    return _iterencode(o, 0)
  File "C:\Users\zhi.zhou\Anaconda3\envs\lts\lib\json\encoder.py", line 180, in default
    o.__class__.__name__)
TypeError: Object of type 'TypeError' is not JSON serializable
[2021-07-27 09:49:21,343][Thread-8:9800][task_id:lts.views][views.py:272][INFO][登录成功]
[2021-07-27 09:53:15,864][Thread-10:17092][task_id:django.request][log.py:230][ERROR][Internal Server Error: /logistic/LogisticWorkStation]
Traceback (most recent call last):
  File "D:\zhouzhi\gitlit_code\logistic_tracking_system\logistic_tracking_system\lts\views.py", line 2452, in get
    drs = db.execute_sql(conn, sql_main)
  File "D:\zhouzhi\gitlit_code\logistic_tracking_system\logistic_tracking_system\common\db.py", line 45, in execute_sql
    cursor.execute(sql)
  File "C:\Users\zhi.zhou\Anaconda3\envs\lts\lib\site-packages\pymysql\cursors.py", line 148, in execute
    result = self._query(query)
  File "C:\Users\zhi.zhou\Anaconda3\envs\lts\lib\site-packages\pymysql\cursors.py", line 310, in _query
    conn.query(q)
  File "C:\Users\zhi.zhou\Anaconda3\envs\lts\lib\site-packages\pymysql\connections.py", line 548, in query
    self._affected_rows = self._read_query_result(unbuffered=unbuffered)
  File "C:\Users\zhi.zhou\Anaconda3\envs\lts\lib\site-packages\pymysql\connections.py", line 775, in _read_query_result
    result.read()
  File "C:\Users\zhi.zhou\Anaconda3\envs\lts\lib\site-packages\pymysql\connections.py", line 1156, in read
    first_packet = self.connection._read_packet()
  File "C:\Users\zhi.zhou\Anaconda3\envs\lts\lib\site-packages\pymysql\connections.py", line 725, in _read_packet
    packet.raise_for_error()
  File "C:\Users\zhi.zhou\Anaconda3\envs\lts\lib\site-packages\pymysql\protocol.py", line 221, in raise_for_error
    err.raise_mysql_exception(self._data)
  File "C:\Users\zhi.zhou\Anaconda3\envs\lts\lib\site-packages\pymysql\err.py", line 143, in raise_mysql_exception
    raise errorclass(errno, errval)
pymysql.err.OperationalError: (1046, 'No database selected')

During handling of the above exception, another exception occurred:

Traceback (most recent call last):
  File "C:\Users\zhi.zhou\Anaconda3\envs\lts\lib\site-packages\django\core\handlers\exception.py", line 47, in inner
    response = get_response(request)
  File "C:\Users\zhi.zhou\Anaconda3\envs\lts\lib\site-packages\django\core\handlers\base.py", line 181, in _get_response
    response = wrapped_callback(request, *callback_args, **callback_kwargs)
  File "C:\Users\zhi.zhou\Anaconda3\envs\lts\lib\site-packages\django\views\generic\base.py", line 70, in view
    return self.dispatch(request, *args, **kwargs)
  File "C:\Users\zhi.zhou\Anaconda3\envs\lts\lib\site-packages\django\views\generic\base.py", line 98, in dispatch
    return handler(request, *args, **kwargs)
  File "D:\zhouzhi\gitlit_code\logistic_tracking_system\logistic_tracking_system\lts\views.py", line 2588, in get
    result = json.dumps(result)
  File "C:\Users\zhi.zhou\Anaconda3\envs\lts\lib\json\__init__.py", line 231, in dumps
    return _default_encoder.encode(obj)
  File "C:\Users\zhi.zhou\Anaconda3\envs\lts\lib\json\encoder.py", line 199, in encode
    chunks = self.iterencode(o, _one_shot=True)
  File "C:\Users\zhi.zhou\Anaconda3\envs\lts\lib\json\encoder.py", line 257, in iterencode
    return _iterencode(o, 0)
  File "C:\Users\zhi.zhou\Anaconda3\envs\lts\lib\json\encoder.py", line 180, in default
    o.__class__.__name__)
TypeError: Object of type 'OperationalError' is not JSON serializable
[2021-07-27 09:54:15,434][Thread-10:17092][task_id:django.request][log.py:230][ERROR][Internal Server Error: /logistic/LogisticWorkCodeName]
Traceback (most recent call last):
  File "D:\zhouzhi\gitlit_code\logistic_tracking_system\logistic_tracking_system\lts\views.py", line 4245, in get
    drs = db.execute_sql(conn, sql)
  File "D:\zhouzhi\gitlit_code\logistic_tracking_system\logistic_tracking_system\common\db.py", line 45, in execute_sql
    cursor.execute(sql)
  File "C:\Users\zhi.zhou\Anaconda3\envs\lts\lib\site-packages\pymysql\cursors.py", line 148, in execute
    result = self._query(query)
  File "C:\Users\zhi.zhou\Anaconda3\envs\lts\lib\site-packages\pymysql\cursors.py", line 310, in _query
    conn.query(q)
  File "C:\Users\zhi.zhou\Anaconda3\envs\lts\lib\site-packages\pymysql\connections.py", line 548, in query
    self._affected_rows = self._read_query_result(unbuffered=unbuffered)
  File "C:\Users\zhi.zhou\Anaconda3\envs\lts\lib\site-packages\pymysql\connections.py", line 775, in _read_query_result
    result.read()
  File "C:\Users\zhi.zhou\Anaconda3\envs\lts\lib\site-packages\pymysql\connections.py", line 1156, in read
    first_packet = self.connection._read_packet()
  File "C:\Users\zhi.zhou\Anaconda3\envs\lts\lib\site-packages\pymysql\connections.py", line 725, in _read_packet
    packet.raise_for_error()
  File "C:\Users\zhi.zhou\Anaconda3\envs\lts\lib\site-packages\pymysql\protocol.py", line 221, in raise_for_error
    err.raise_mysql_exception(self._data)
  File "C:\Users\zhi.zhou\Anaconda3\envs\lts\lib\site-packages\pymysql\err.py", line 143, in raise_mysql_exception
    raise errorclass(errno, errval)
pymysql.err.OperationalError: (1046, 'No database selected')

During handling of the above exception, another exception occurred:

Traceback (most recent call last):
  File "C:\Users\zhi.zhou\Anaconda3\envs\lts\lib\site-packages\django\core\handlers\exception.py", line 47, in inner
    response = get_response(request)
  File "C:\Users\zhi.zhou\Anaconda3\envs\lts\lib\site-packages\django\core\handlers\base.py", line 181, in _get_response
    response = wrapped_callback(request, *callback_args, **callback_kwargs)
  File "C:\Users\zhi.zhou\Anaconda3\envs\lts\lib\site-packages\django\views\generic\base.py", line 70, in view
    return self.dispatch(request, *args, **kwargs)
  File "C:\Users\zhi.zhou\Anaconda3\envs\lts\lib\site-packages\django\views\generic\base.py", line 98, in dispatch
    return handler(request, *args, **kwargs)
  File "D:\zhouzhi\gitlit_code\logistic_tracking_system\logistic_tracking_system\lts\views.py", line 4259, in get
    data = json.dumps(data)
  File "C:\Users\zhi.zhou\Anaconda3\envs\lts\lib\json\__init__.py", line 231, in dumps
    return _default_encoder.encode(obj)
  File "C:\Users\zhi.zhou\Anaconda3\envs\lts\lib\json\encoder.py", line 199, in encode
    chunks = self.iterencode(o, _one_shot=True)
  File "C:\Users\zhi.zhou\Anaconda3\envs\lts\lib\json\encoder.py", line 257, in iterencode
    return _iterencode(o, 0)
  File "C:\Users\zhi.zhou\Anaconda3\envs\lts\lib\json\encoder.py", line 180, in default
    o.__class__.__name__)
TypeError: Object of type 'OperationalError' is not JSON serializable
[2021-07-27 09:54:26,795][Thread-10:17092][task_id:django.request][log.py:230][ERROR][Internal Server Error: /logistic/LogisticWorkStation]
Traceback (most recent call last):
  File "D:\zhouzhi\gitlit_code\logistic_tracking_system\logistic_tracking_system\lts\views.py", line 2452, in get
    drs = db.execute_sql(conn, sql_main)
  File "D:\zhouzhi\gitlit_code\logistic_tracking_system\logistic_tracking_system\common\db.py", line 45, in execute_sql
    cursor.execute(sql)
  File "C:\Users\zhi.zhou\Anaconda3\envs\lts\lib\site-packages\pymysql\cursors.py", line 148, in execute
    result = self._query(query)
  File "C:\Users\zhi.zhou\Anaconda3\envs\lts\lib\site-packages\pymysql\cursors.py", line 310, in _query
    conn.query(q)
  File "C:\Users\zhi.zhou\Anaconda3\envs\lts\lib\site-packages\pymysql\connections.py", line 548, in query
    self._affected_rows = self._read_query_result(unbuffered=unbuffered)
  File "C:\Users\zhi.zhou\Anaconda3\envs\lts\lib\site-packages\pymysql\connections.py", line 775, in _read_query_result
    result.read()
  File "C:\Users\zhi.zhou\Anaconda3\envs\lts\lib\site-packages\pymysql\connections.py", line 1156, in read
    first_packet = self.connection._read_packet()
  File "C:\Users\zhi.zhou\Anaconda3\envs\lts\lib\site-packages\pymysql\connections.py", line 725, in _read_packet
    packet.raise_for_error()
  File "C:\Users\zhi.zhou\Anaconda3\envs\lts\lib\site-packages\pymysql\protocol.py", line 221, in raise_for_error
    err.raise_mysql_exception(self._data)
  File "C:\Users\zhi.zhou\Anaconda3\envs\lts\lib\site-packages\pymysql\err.py", line 143, in raise_mysql_exception
    raise errorclass(errno, errval)
pymysql.err.OperationalError: (1046, 'No database selected')

During handling of the above exception, another exception occurred:

Traceback (most recent call last):
  File "C:\Users\zhi.zhou\Anaconda3\envs\lts\lib\site-packages\django\core\handlers\exception.py", line 47, in inner
    response = get_response(request)
  File "C:\Users\zhi.zhou\Anaconda3\envs\lts\lib\site-packages\django\core\handlers\base.py", line 181, in _get_response
    response = wrapped_callback(request, *callback_args, **callback_kwargs)
  File "C:\Users\zhi.zhou\Anaconda3\envs\lts\lib\site-packages\django\views\generic\base.py", line 70, in view
    return self.dispatch(request, *args, **kwargs)
  File "C:\Users\zhi.zhou\Anaconda3\envs\lts\lib\site-packages\django\views\generic\base.py", line 98, in dispatch
    return handler(request, *args, **kwargs)
  File "D:\zhouzhi\gitlit_code\logistic_tracking_system\logistic_tracking_system\lts\views.py", line 2588, in get
    result = json.dumps(result)
  File "C:\Users\zhi.zhou\Anaconda3\envs\lts\lib\json\__init__.py", line 231, in dumps
    return _default_encoder.encode(obj)
  File "C:\Users\zhi.zhou\Anaconda3\envs\lts\lib\json\encoder.py", line 199, in encode
    chunks = self.iterencode(o, _one_shot=True)
  File "C:\Users\zhi.zhou\Anaconda3\envs\lts\lib\json\encoder.py", line 257, in iterencode
    return _iterencode(o, 0)
  File "C:\Users\zhi.zhou\Anaconda3\envs\lts\lib\json\encoder.py", line 180, in default
    o.__class__.__name__)
TypeError: Object of type 'OperationalError' is not JSON serializable
[2021-07-27 09:54:28,608][Thread-10:17092][task_id:django.request][log.py:230][ERROR][Internal Server Error: /logistic/LogisticWorkCodeName]
Traceback (most recent call last):
  File "D:\zhouzhi\gitlit_code\logistic_tracking_system\logistic_tracking_system\lts\views.py", line 4245, in get
    drs = db.execute_sql(conn, sql)
  File "D:\zhouzhi\gitlit_code\logistic_tracking_system\logistic_tracking_system\common\db.py", line 45, in execute_sql
    cursor.execute(sql)
  File "C:\Users\zhi.zhou\Anaconda3\envs\lts\lib\site-packages\pymysql\cursors.py", line 148, in execute
    result = self._query(query)
  File "C:\Users\zhi.zhou\Anaconda3\envs\lts\lib\site-packages\pymysql\cursors.py", line 310, in _query
    conn.query(q)
  File "C:\Users\zhi.zhou\Anaconda3\envs\lts\lib\site-packages\pymysql\connections.py", line 548, in query
    self._affected_rows = self._read_query_result(unbuffered=unbuffered)
  File "C:\Users\zhi.zhou\Anaconda3\envs\lts\lib\site-packages\pymysql\connections.py", line 775, in _read_query_result
    result.read()
  File "C:\Users\zhi.zhou\Anaconda3\envs\lts\lib\site-packages\pymysql\connections.py", line 1156, in read
    first_packet = self.connection._read_packet()
  File "C:\Users\zhi.zhou\Anaconda3\envs\lts\lib\site-packages\pymysql\connections.py", line 725, in _read_packet
    packet.raise_for_error()
  File "C:\Users\zhi.zhou\Anaconda3\envs\lts\lib\site-packages\pymysql\protocol.py", line 221, in raise_for_error
    err.raise_mysql_exception(self._data)
  File "C:\Users\zhi.zhou\Anaconda3\envs\lts\lib\site-packages\pymysql\err.py", line 143, in raise_mysql_exception
    raise errorclass(errno, errval)
pymysql.err.OperationalError: (1046, 'No database selected')

During handling of the above exception, another exception occurred:

Traceback (most recent call last):
  File "C:\Users\zhi.zhou\Anaconda3\envs\lts\lib\site-packages\django\core\handlers\exception.py", line 47, in inner
    response = get_response(request)
  File "C:\Users\zhi.zhou\Anaconda3\envs\lts\lib\site-packages\django\core\handlers\base.py", line 181, in _get_response
    response = wrapped_callback(request, *callback_args, **callback_kwargs)
  File "C:\Users\zhi.zhou\Anaconda3\envs\lts\lib\site-packages\django\views\generic\base.py", line 70, in view
    return self.dispatch(request, *args, **kwargs)
  File "C:\Users\zhi.zhou\Anaconda3\envs\lts\lib\site-packages\django\views\generic\base.py", line 98, in dispatch
    return handler(request, *args, **kwargs)
  File "D:\zhouzhi\gitlit_code\logistic_tracking_system\logistic_tracking_system\lts\views.py", line 4259, in get
    data = json.dumps(data)
  File "C:\Users\zhi.zhou\Anaconda3\envs\lts\lib\json\__init__.py", line 231, in dumps
    return _default_encoder.encode(obj)
  File "C:\Users\zhi.zhou\Anaconda3\envs\lts\lib\json\encoder.py", line 199, in encode
    chunks = self.iterencode(o, _one_shot=True)
  File "C:\Users\zhi.zhou\Anaconda3\envs\lts\lib\json\encoder.py", line 257, in iterencode
    return _iterencode(o, 0)
  File "C:\Users\zhi.zhou\Anaconda3\envs\lts\lib\json\encoder.py", line 180, in default
    o.__class__.__name__)
TypeError: Object of type 'OperationalError' is not JSON serializable
[2021-07-27 09:56:29,992][Thread-13:9804][task_id:django.request][log.py:230][ERROR][Internal Server Error: /logistic/LogisticWorkCodeName]
Traceback (most recent call last):
  File "D:\zhouzhi\gitlit_code\logistic_tracking_system\logistic_tracking_system\lts\views.py", line 4245, in get
    drs = db.execute_sql(conn, sql)
  File "D:\zhouzhi\gitlit_code\logistic_tracking_system\logistic_tracking_system\common\db.py", line 45, in execute_sql
    cursor.execute(sql)
  File "C:\Users\zhi.zhou\Anaconda3\envs\lts\lib\site-packages\pymysql\cursors.py", line 148, in execute
    result = self._query(query)
  File "C:\Users\zhi.zhou\Anaconda3\envs\lts\lib\site-packages\pymysql\cursors.py", line 310, in _query
    conn.query(q)
  File "C:\Users\zhi.zhou\Anaconda3\envs\lts\lib\site-packages\pymysql\connections.py", line 548, in query
    self._affected_rows = self._read_query_result(unbuffered=unbuffered)
  File "C:\Users\zhi.zhou\Anaconda3\envs\lts\lib\site-packages\pymysql\connections.py", line 775, in _read_query_result
    result.read()
  File "C:\Users\zhi.zhou\Anaconda3\envs\lts\lib\site-packages\pymysql\connections.py", line 1156, in read
    first_packet = self.connection._read_packet()
  File "C:\Users\zhi.zhou\Anaconda3\envs\lts\lib\site-packages\pymysql\connections.py", line 725, in _read_packet
    packet.raise_for_error()
  File "C:\Users\zhi.zhou\Anaconda3\envs\lts\lib\site-packages\pymysql\protocol.py", line 221, in raise_for_error
    err.raise_mysql_exception(self._data)
  File "C:\Users\zhi.zhou\Anaconda3\envs\lts\lib\site-packages\pymysql\err.py", line 143, in raise_mysql_exception
    raise errorclass(errno, errval)
pymysql.err.OperationalError: (1046, 'No database selected')

During handling of the above exception, another exception occurred:

Traceback (most recent call last):
  File "C:\Users\zhi.zhou\Anaconda3\envs\lts\lib\site-packages\django\core\handlers\exception.py", line 47, in inner
    response = get_response(request)
  File "C:\Users\zhi.zhou\Anaconda3\envs\lts\lib\site-packages\django\core\handlers\base.py", line 181, in _get_response
    response = wrapped_callback(request, *callback_args, **callback_kwargs)
  File "C:\Users\zhi.zhou\Anaconda3\envs\lts\lib\site-packages\django\views\generic\base.py", line 70, in view
    return self.dispatch(request, *args, **kwargs)
  File "C:\Users\zhi.zhou\Anaconda3\envs\lts\lib\site-packages\django\views\generic\base.py", line 98, in dispatch
    return handler(request, *args, **kwargs)
  File "D:\zhouzhi\gitlit_code\logistic_tracking_system\logistic_tracking_system\lts\views.py", line 4259, in get
    data = json.dumps(data)
  File "C:\Users\zhi.zhou\Anaconda3\envs\lts\lib\json\__init__.py", line 231, in dumps
    return _default_encoder.encode(obj)
  File "C:\Users\zhi.zhou\Anaconda3\envs\lts\lib\json\encoder.py", line 199, in encode
    chunks = self.iterencode(o, _one_shot=True)
  File "C:\Users\zhi.zhou\Anaconda3\envs\lts\lib\json\encoder.py", line 257, in iterencode
    return _iterencode(o, 0)
  File "C:\Users\zhi.zhou\Anaconda3\envs\lts\lib\json\encoder.py", line 180, in default
    o.__class__.__name__)
TypeError: Object of type 'OperationalError' is not JSON serializable
[2021-07-27 09:56:45,240][Thread-13:9804][task_id:django.request][log.py:230][ERROR][Internal Server Error: /logistic/LogisticWorkCodeName]
Traceback (most recent call last):
  File "D:\zhouzhi\gitlit_code\logistic_tracking_system\logistic_tracking_system\lts\views.py", line 4245, in get
    drs = db.execute_sql(conn, sql)
  File "D:\zhouzhi\gitlit_code\logistic_tracking_system\logistic_tracking_system\common\db.py", line 45, in execute_sql
    cursor.execute(sql)
  File "C:\Users\zhi.zhou\Anaconda3\envs\lts\lib\site-packages\pymysql\cursors.py", line 148, in execute
    result = self._query(query)
  File "C:\Users\zhi.zhou\Anaconda3\envs\lts\lib\site-packages\pymysql\cursors.py", line 310, in _query
    conn.query(q)
  File "C:\Users\zhi.zhou\Anaconda3\envs\lts\lib\site-packages\pymysql\connections.py", line 548, in query
    self._affected_rows = self._read_query_result(unbuffered=unbuffered)
  File "C:\Users\zhi.zhou\Anaconda3\envs\lts\lib\site-packages\pymysql\connections.py", line 775, in _read_query_result
    result.read()
  File "C:\Users\zhi.zhou\Anaconda3\envs\lts\lib\site-packages\pymysql\connections.py", line 1156, in read
    first_packet = self.connection._read_packet()
  File "C:\Users\zhi.zhou\Anaconda3\envs\lts\lib\site-packages\pymysql\connections.py", line 725, in _read_packet
    packet.raise_for_error()
  File "C:\Users\zhi.zhou\Anaconda3\envs\lts\lib\site-packages\pymysql\protocol.py", line 221, in raise_for_error
    err.raise_mysql_exception(self._data)
  File "C:\Users\zhi.zhou\Anaconda3\envs\lts\lib\site-packages\pymysql\err.py", line 143, in raise_mysql_exception
    raise errorclass(errno, errval)
pymysql.err.OperationalError: (1046, 'No database selected')

During handling of the above exception, another exception occurred:

Traceback (most recent call last):
  File "C:\Users\zhi.zhou\Anaconda3\envs\lts\lib\site-packages\django\core\handlers\exception.py", line 47, in inner
    response = get_response(request)
  File "C:\Users\zhi.zhou\Anaconda3\envs\lts\lib\site-packages\django\core\handlers\base.py", line 181, in _get_response
    response = wrapped_callback(request, *callback_args, **callback_kwargs)
  File "C:\Users\zhi.zhou\Anaconda3\envs\lts\lib\site-packages\django\views\generic\base.py", line 70, in view
    return self.dispatch(request, *args, **kwargs)
  File "C:\Users\zhi.zhou\Anaconda3\envs\lts\lib\site-packages\django\views\generic\base.py", line 98, in dispatch
    return handler(request, *args, **kwargs)
  File "D:\zhouzhi\gitlit_code\logistic_tracking_system\logistic_tracking_system\lts\views.py", line 4259, in get
    data = json.dumps(data)
  File "C:\Users\zhi.zhou\Anaconda3\envs\lts\lib\json\__init__.py", line 231, in dumps
    return _default_encoder.encode(obj)
  File "C:\Users\zhi.zhou\Anaconda3\envs\lts\lib\json\encoder.py", line 199, in encode
    chunks = self.iterencode(o, _one_shot=True)
  File "C:\Users\zhi.zhou\Anaconda3\envs\lts\lib\json\encoder.py", line 257, in iterencode
    return _iterencode(o, 0)
  File "C:\Users\zhi.zhou\Anaconda3\envs\lts\lib\json\encoder.py", line 180, in default
    o.__class__.__name__)
TypeError: Object of type 'OperationalError' is not JSON serializable
[2021-07-27 09:56:50,376][Thread-13:9804][task_id:django.request][log.py:230][ERROR][Internal Server Error: /logistic/LogisticWorkStation]
Traceback (most recent call last):
  File "D:\zhouzhi\gitlit_code\logistic_tracking_system\logistic_tracking_system\lts\views.py", line 2452, in get
    drs = db.execute_sql(conn, sql_main)
  File "D:\zhouzhi\gitlit_code\logistic_tracking_system\logistic_tracking_system\common\db.py", line 45, in execute_sql
    cursor.execute(sql)
  File "C:\Users\zhi.zhou\Anaconda3\envs\lts\lib\site-packages\pymysql\cursors.py", line 148, in execute
    result = self._query(query)
  File "C:\Users\zhi.zhou\Anaconda3\envs\lts\lib\site-packages\pymysql\cursors.py", line 310, in _query
    conn.query(q)
  File "C:\Users\zhi.zhou\Anaconda3\envs\lts\lib\site-packages\pymysql\connections.py", line 548, in query
    self._affected_rows = self._read_query_result(unbuffered=unbuffered)
  File "C:\Users\zhi.zhou\Anaconda3\envs\lts\lib\site-packages\pymysql\connections.py", line 775, in _read_query_result
    result.read()
  File "C:\Users\zhi.zhou\Anaconda3\envs\lts\lib\site-packages\pymysql\connections.py", line 1156, in read
    first_packet = self.connection._read_packet()
  File "C:\Users\zhi.zhou\Anaconda3\envs\lts\lib\site-packages\pymysql\connections.py", line 725, in _read_packet
    packet.raise_for_error()
  File "C:\Users\zhi.zhou\Anaconda3\envs\lts\lib\site-packages\pymysql\protocol.py", line 221, in raise_for_error
    err.raise_mysql_exception(self._data)
  File "C:\Users\zhi.zhou\Anaconda3\envs\lts\lib\site-packages\pymysql\err.py", line 143, in raise_mysql_exception
    raise errorclass(errno, errval)
pymysql.err.OperationalError: (1046, 'No database selected')

During handling of the above exception, another exception occurred:

Traceback (most recent call last):
  File "C:\Users\zhi.zhou\Anaconda3\envs\lts\lib\site-packages\django\core\handlers\exception.py", line 47, in inner
    response = get_response(request)
  File "C:\Users\zhi.zhou\Anaconda3\envs\lts\lib\site-packages\django\core\handlers\base.py", line 181, in _get_response
    response = wrapped_callback(request, *callback_args, **callback_kwargs)
  File "C:\Users\zhi.zhou\Anaconda3\envs\lts\lib\site-packages\django\views\generic\base.py", line 70, in view
    return self.dispatch(request, *args, **kwargs)
  File "C:\Users\zhi.zhou\Anaconda3\envs\lts\lib\site-packages\django\views\generic\base.py", line 98, in dispatch
    return handler(request, *args, **kwargs)
  File "D:\zhouzhi\gitlit_code\logistic_tracking_system\logistic_tracking_system\lts\views.py", line 2588, in get
    result = json.dumps(result)
  File "C:\Users\zhi.zhou\Anaconda3\envs\lts\lib\json\__init__.py", line 231, in dumps
    return _default_encoder.encode(obj)
  File "C:\Users\zhi.zhou\Anaconda3\envs\lts\lib\json\encoder.py", line 199, in encode
    chunks = self.iterencode(o, _one_shot=True)
  File "C:\Users\zhi.zhou\Anaconda3\envs\lts\lib\json\encoder.py", line 257, in iterencode
    return _iterencode(o, 0)
  File "C:\Users\zhi.zhou\Anaconda3\envs\lts\lib\json\encoder.py", line 180, in default
    o.__class__.__name__)
TypeError: Object of type 'OperationalError' is not JSON serializable
[2021-07-27 09:56:51,300][Thread-13:9804][task_id:django.request][log.py:230][ERROR][Internal Server Error: /logistic/LogisticWorkCodeName]
Traceback (most recent call last):
  File "D:\zhouzhi\gitlit_code\logistic_tracking_system\logistic_tracking_system\lts\views.py", line 4245, in get
    drs = db.execute_sql(conn, sql)
  File "D:\zhouzhi\gitlit_code\logistic_tracking_system\logistic_tracking_system\common\db.py", line 45, in execute_sql
    cursor.execute(sql)
  File "C:\Users\zhi.zhou\Anaconda3\envs\lts\lib\site-packages\pymysql\cursors.py", line 148, in execute
    result = self._query(query)
  File "C:\Users\zhi.zhou\Anaconda3\envs\lts\lib\site-packages\pymysql\cursors.py", line 310, in _query
    conn.query(q)
  File "C:\Users\zhi.zhou\Anaconda3\envs\lts\lib\site-packages\pymysql\connections.py", line 548, in query
    self._affected_rows = self._read_query_result(unbuffered=unbuffered)
  File "C:\Users\zhi.zhou\Anaconda3\envs\lts\lib\site-packages\pymysql\connections.py", line 775, in _read_query_result
    result.read()
  File "C:\Users\zhi.zhou\Anaconda3\envs\lts\lib\site-packages\pymysql\connections.py", line 1156, in read
    first_packet = self.connection._read_packet()
  File "C:\Users\zhi.zhou\Anaconda3\envs\lts\lib\site-packages\pymysql\connections.py", line 725, in _read_packet
    packet.raise_for_error()
  File "C:\Users\zhi.zhou\Anaconda3\envs\lts\lib\site-packages\pymysql\protocol.py", line 221, in raise_for_error
    err.raise_mysql_exception(self._data)
  File "C:\Users\zhi.zhou\Anaconda3\envs\lts\lib\site-packages\pymysql\err.py", line 143, in raise_mysql_exception
    raise errorclass(errno, errval)
pymysql.err.OperationalError: (1046, 'No database selected')

During handling of the above exception, another exception occurred:

Traceback (most recent call last):
  File "C:\Users\zhi.zhou\Anaconda3\envs\lts\lib\site-packages\django\core\handlers\exception.py", line 47, in inner
    response = get_response(request)
  File "C:\Users\zhi.zhou\Anaconda3\envs\lts\lib\site-packages\django\core\handlers\base.py", line 181, in _get_response
    response = wrapped_callback(request, *callback_args, **callback_kwargs)
  File "C:\Users\zhi.zhou\Anaconda3\envs\lts\lib\site-packages\django\views\generic\base.py", line 70, in view
    return self.dispatch(request, *args, **kwargs)
  File "C:\Users\zhi.zhou\Anaconda3\envs\lts\lib\site-packages\django\views\generic\base.py", line 98, in dispatch
    return handler(request, *args, **kwargs)
  File "D:\zhouzhi\gitlit_code\logistic_tracking_system\logistic_tracking_system\lts\views.py", line 4259, in get
    data = json.dumps(data)
  File "C:\Users\zhi.zhou\Anaconda3\envs\lts\lib\json\__init__.py", line 231, in dumps
    return _default_encoder.encode(obj)
  File "C:\Users\zhi.zhou\Anaconda3\envs\lts\lib\json\encoder.py", line 199, in encode
    chunks = self.iterencode(o, _one_shot=True)
  File "C:\Users\zhi.zhou\Anaconda3\envs\lts\lib\json\encoder.py", line 257, in iterencode
    return _iterencode(o, 0)
  File "C:\Users\zhi.zhou\Anaconda3\envs\lts\lib\json\encoder.py", line 180, in default
    o.__class__.__name__)
TypeError: Object of type 'OperationalError' is not JSON serializable
[2021-07-27 09:56:53,827][Thread-13:9804][task_id:django.request][log.py:230][ERROR][Internal Server Error: /logistic/LogisticWorkCodeName]
Traceback (most recent call last):
  File "D:\zhouzhi\gitlit_code\logistic_tracking_system\logistic_tracking_system\lts\views.py", line 4245, in get
    drs = db.execute_sql(conn, sql)
  File "D:\zhouzhi\gitlit_code\logistic_tracking_system\logistic_tracking_system\common\db.py", line 45, in execute_sql
    cursor.execute(sql)
  File "C:\Users\zhi.zhou\Anaconda3\envs\lts\lib\site-packages\pymysql\cursors.py", line 148, in execute
    result = self._query(query)
  File "C:\Users\zhi.zhou\Anaconda3\envs\lts\lib\site-packages\pymysql\cursors.py", line 310, in _query
    conn.query(q)
  File "C:\Users\zhi.zhou\Anaconda3\envs\lts\lib\site-packages\pymysql\connections.py", line 548, in query
    self._affected_rows = self._read_query_result(unbuffered=unbuffered)
  File "C:\Users\zhi.zhou\Anaconda3\envs\lts\lib\site-packages\pymysql\connections.py", line 775, in _read_query_result
    result.read()
  File "C:\Users\zhi.zhou\Anaconda3\envs\lts\lib\site-packages\pymysql\connections.py", line 1156, in read
    first_packet = self.connection._read_packet()
  File "C:\Users\zhi.zhou\Anaconda3\envs\lts\lib\site-packages\pymysql\connections.py", line 725, in _read_packet
    packet.raise_for_error()
  File "C:\Users\zhi.zhou\Anaconda3\envs\lts\lib\site-packages\pymysql\protocol.py", line 221, in raise_for_error
    err.raise_mysql_exception(self._data)
  File "C:\Users\zhi.zhou\Anaconda3\envs\lts\lib\site-packages\pymysql\err.py", line 143, in raise_mysql_exception
    raise errorclass(errno, errval)
pymysql.err.OperationalError: (1046, 'No database selected')

During handling of the above exception, another exception occurred:

Traceback (most recent call last):
  File "C:\Users\zhi.zhou\Anaconda3\envs\lts\lib\site-packages\django\core\handlers\exception.py", line 47, in inner
    response = get_response(request)
  File "C:\Users\zhi.zhou\Anaconda3\envs\lts\lib\site-packages\django\core\handlers\base.py", line 181, in _get_response
    response = wrapped_callback(request, *callback_args, **callback_kwargs)
  File "C:\Users\zhi.zhou\Anaconda3\envs\lts\lib\site-packages\django\views\generic\base.py", line 70, in view
    return self.dispatch(request, *args, **kwargs)
  File "C:\Users\zhi.zhou\Anaconda3\envs\lts\lib\site-packages\django\views\generic\base.py", line 98, in dispatch
    return handler(request, *args, **kwargs)
  File "D:\zhouzhi\gitlit_code\logistic_tracking_system\logistic_tracking_system\lts\views.py", line 4259, in get
    data = json.dumps(data)
  File "C:\Users\zhi.zhou\Anaconda3\envs\lts\lib\json\__init__.py", line 231, in dumps
    return _default_encoder.encode(obj)
  File "C:\Users\zhi.zhou\Anaconda3\envs\lts\lib\json\encoder.py", line 199, in encode
    chunks = self.iterencode(o, _one_shot=True)
  File "C:\Users\zhi.zhou\Anaconda3\envs\lts\lib\json\encoder.py", line 257, in iterencode
    return _iterencode(o, 0)
  File "C:\Users\zhi.zhou\Anaconda3\envs\lts\lib\json\encoder.py", line 180, in default
    o.__class__.__name__)
TypeError: Object of type 'OperationalError' is not JSON serializable
[2021-07-27 10:00:44,527][Thread-14:18160][task_id:django.request][log.py:230][ERROR][Internal Server Error: /logistic/LogisticWorkCodeName]
Traceback (most recent call last):
  File "D:\zhouzhi\gitlit_code\logistic_tracking_system\logistic_tracking_system\lts\views.py", line 4245, in get
    drs = db.execute_sql(conn, sql)
  File "D:\zhouzhi\gitlit_code\logistic_tracking_system\logistic_tracking_system\common\db.py", line 45, in execute_sql
    cursor.execute(sql)
  File "C:\Users\zhi.zhou\Anaconda3\envs\lts\lib\site-packages\pymysql\cursors.py", line 148, in execute
    result = self._query(query)
  File "C:\Users\zhi.zhou\Anaconda3\envs\lts\lib\site-packages\pymysql\cursors.py", line 310, in _query
    conn.query(q)
  File "C:\Users\zhi.zhou\Anaconda3\envs\lts\lib\site-packages\pymysql\connections.py", line 548, in query
    self._affected_rows = self._read_query_result(unbuffered=unbuffered)
  File "C:\Users\zhi.zhou\Anaconda3\envs\lts\lib\site-packages\pymysql\connections.py", line 775, in _read_query_result
    result.read()
  File "C:\Users\zhi.zhou\Anaconda3\envs\lts\lib\site-packages\pymysql\connections.py", line 1156, in read
    first_packet = self.connection._read_packet()
  File "C:\Users\zhi.zhou\Anaconda3\envs\lts\lib\site-packages\pymysql\connections.py", line 725, in _read_packet
    packet.raise_for_error()
  File "C:\Users\zhi.zhou\Anaconda3\envs\lts\lib\site-packages\pymysql\protocol.py", line 221, in raise_for_error
    err.raise_mysql_exception(self._data)
  File "C:\Users\zhi.zhou\Anaconda3\envs\lts\lib\site-packages\pymysql\err.py", line 143, in raise_mysql_exception
    raise errorclass(errno, errval)
pymysql.err.OperationalError: (1046, 'No database selected')

During handling of the above exception, another exception occurred:

Traceback (most recent call last):
  File "C:\Users\zhi.zhou\Anaconda3\envs\lts\lib\site-packages\django\core\handlers\exception.py", line 47, in inner
    response = get_response(request)
  File "C:\Users\zhi.zhou\Anaconda3\envs\lts\lib\site-packages\django\core\handlers\base.py", line 181, in _get_response
    response = wrapped_callback(request, *callback_args, **callback_kwargs)
  File "C:\Users\zhi.zhou\Anaconda3\envs\lts\lib\site-packages\django\views\generic\base.py", line 70, in view
    return self.dispatch(request, *args, **kwargs)
  File "C:\Users\zhi.zhou\Anaconda3\envs\lts\lib\site-packages\django\views\generic\base.py", line 98, in dispatch
    return handler(request, *args, **kwargs)
  File "D:\zhouzhi\gitlit_code\logistic_tracking_system\logistic_tracking_system\lts\views.py", line 4259, in get
    data = json.dumps(data)
  File "C:\Users\zhi.zhou\Anaconda3\envs\lts\lib\json\__init__.py", line 231, in dumps
    return _default_encoder.encode(obj)
  File "C:\Users\zhi.zhou\Anaconda3\envs\lts\lib\json\encoder.py", line 199, in encode
    chunks = self.iterencode(o, _one_shot=True)
  File "C:\Users\zhi.zhou\Anaconda3\envs\lts\lib\json\encoder.py", line 257, in iterencode
    return _iterencode(o, 0)
  File "C:\Users\zhi.zhou\Anaconda3\envs\lts\lib\json\encoder.py", line 180, in default
    o.__class__.__name__)
TypeError: Object of type 'OperationalError' is not JSON serializable
[2021-07-27 10:16:09,200][Thread-15:19468][task_id:django.request][log.py:230][ERROR][Internal Server Error: /logistic/LogisticProcessDeal]
Traceback (most recent call last):
  File "D:\zhouzhi\gitlit_code\logistic_tracking_system\logistic_tracking_system\lts\views.py", line 3774, in get
    if len(production_name) == 0 and len(prodect_code) == 0 and len(work_id) == 0:
TypeError: object of type 'NoneType' has no len()

During handling of the above exception, another exception occurred:

Traceback (most recent call last):
  File "C:\Users\zhi.zhou\Anaconda3\envs\lts\lib\site-packages\django\core\handlers\exception.py", line 47, in inner
    response = get_response(request)
  File "C:\Users\zhi.zhou\Anaconda3\envs\lts\lib\site-packages\django\core\handlers\base.py", line 181, in _get_response
    response = wrapped_callback(request, *callback_args, **callback_kwargs)
  File "C:\Users\zhi.zhou\Anaconda3\envs\lts\lib\site-packages\django\views\generic\base.py", line 70, in view
    return self.dispatch(request, *args, **kwargs)
  File "C:\Users\zhi.zhou\Anaconda3\envs\lts\lib\site-packages\django\views\generic\base.py", line 98, in dispatch
    return handler(request, *args, **kwargs)
  File "D:\zhouzhi\gitlit_code\logistic_tracking_system\logistic_tracking_system\lts\views.py", line 4042, in get
    data = json.dumps(data)
  File "C:\Users\zhi.zhou\Anaconda3\envs\lts\lib\json\__init__.py", line 231, in dumps
    return _default_encoder.encode(obj)
  File "C:\Users\zhi.zhou\Anaconda3\envs\lts\lib\json\encoder.py", line 199, in encode
    chunks = self.iterencode(o, _one_shot=True)
  File "C:\Users\zhi.zhou\Anaconda3\envs\lts\lib\json\encoder.py", line 257, in iterencode
    return _iterencode(o, 0)
  File "C:\Users\zhi.zhou\Anaconda3\envs\lts\lib\json\encoder.py", line 180, in default
    o.__class__.__name__)
TypeError: Object of type 'TypeError' is not JSON serializable
[2021-07-27 10:16:15,935][Thread-15:19468][task_id:django.request][log.py:230][ERROR][Internal Server Error: /logistic/LogisticProcessDeal]
Traceback (most recent call last):
  File "D:\zhouzhi\gitlit_code\logistic_tracking_system\logistic_tracking_system\lts\views.py", line 3774, in get
    if len(production_name) == 0 and len(prodect_code) == 0 and len(work_id) == 0:
TypeError: object of type 'NoneType' has no len()

During handling of the above exception, another exception occurred:

Traceback (most recent call last):
  File "C:\Users\zhi.zhou\Anaconda3\envs\lts\lib\site-packages\django\core\handlers\exception.py", line 47, in inner
    response = get_response(request)
  File "C:\Users\zhi.zhou\Anaconda3\envs\lts\lib\site-packages\django\core\handlers\base.py", line 181, in _get_response
    response = wrapped_callback(request, *callback_args, **callback_kwargs)
  File "C:\Users\zhi.zhou\Anaconda3\envs\lts\lib\site-packages\django\views\generic\base.py", line 70, in view
    return self.dispatch(request, *args, **kwargs)
  File "C:\Users\zhi.zhou\Anaconda3\envs\lts\lib\site-packages\django\views\generic\base.py", line 98, in dispatch
    return handler(request, *args, **kwargs)
  File "D:\zhouzhi\gitlit_code\logistic_tracking_system\logistic_tracking_system\lts\views.py", line 4042, in get
    data = json.dumps(data)
  File "C:\Users\zhi.zhou\Anaconda3\envs\lts\lib\json\__init__.py", line 231, in dumps
    return _default_encoder.encode(obj)
  File "C:\Users\zhi.zhou\Anaconda3\envs\lts\lib\json\encoder.py", line 199, in encode
    chunks = self.iterencode(o, _one_shot=True)
  File "C:\Users\zhi.zhou\Anaconda3\envs\lts\lib\json\encoder.py", line 257, in iterencode
    return _iterencode(o, 0)
  File "C:\Users\zhi.zhou\Anaconda3\envs\lts\lib\json\encoder.py", line 180, in default
    o.__class__.__name__)
TypeError: Object of type 'TypeError' is not JSON serializable
[2021-07-27 10:17:02,544][Thread-15:19468][task_id:django.request][log.py:230][ERROR][Internal Server Error: /logistic/LogisticProcessDeal]
Traceback (most recent call last):
  File "D:\zhouzhi\gitlit_code\logistic_tracking_system\logistic_tracking_system\lts\views.py", line 3774, in get
    if len(production_name) == 0 and len(prodect_code) == 0 and len(work_id) == 0:
TypeError: object of type 'NoneType' has no len()

During handling of the above exception, another exception occurred:

Traceback (most recent call last):
  File "C:\Users\zhi.zhou\Anaconda3\envs\lts\lib\site-packages\django\core\handlers\exception.py", line 47, in inner
    response = get_response(request)
  File "C:\Users\zhi.zhou\Anaconda3\envs\lts\lib\site-packages\django\core\handlers\base.py", line 181, in _get_response
    response = wrapped_callback(request, *callback_args, **callback_kwargs)
  File "C:\Users\zhi.zhou\Anaconda3\envs\lts\lib\site-packages\django\views\generic\base.py", line 70, in view
    return self.dispatch(request, *args, **kwargs)
  File "C:\Users\zhi.zhou\Anaconda3\envs\lts\lib\site-packages\django\views\generic\base.py", line 98, in dispatch
    return handler(request, *args, **kwargs)
  File "D:\zhouzhi\gitlit_code\logistic_tracking_system\logistic_tracking_system\lts\views.py", line 4042, in get
    data = json.dumps(data)
  File "C:\Users\zhi.zhou\Anaconda3\envs\lts\lib\json\__init__.py", line 231, in dumps
    return _default_encoder.encode(obj)
  File "C:\Users\zhi.zhou\Anaconda3\envs\lts\lib\json\encoder.py", line 199, in encode
    chunks = self.iterencode(o, _one_shot=True)
  File "C:\Users\zhi.zhou\Anaconda3\envs\lts\lib\json\encoder.py", line 257, in iterencode
    return _iterencode(o, 0)
  File "C:\Users\zhi.zhou\Anaconda3\envs\lts\lib\json\encoder.py", line 180, in default
    o.__class__.__name__)
TypeError: Object of type 'TypeError' is not JSON serializable
[2021-07-27 10:17:11,612][Thread-16:18520][task_id:django.request][log.py:230][ERROR][Internal Server Error: /logistic/LogisticWorkCodeName]
Traceback (most recent call last):
  File "D:\zhouzhi\gitlit_code\logistic_tracking_system\logistic_tracking_system\lts\views.py", line 4245, in get
    drs = db.execute_sql(conn, sql)
  File "D:\zhouzhi\gitlit_code\logistic_tracking_system\logistic_tracking_system\common\db.py", line 45, in execute_sql
    cursor.execute(sql)
  File "C:\Users\zhi.zhou\Anaconda3\envs\lts\lib\site-packages\pymysql\cursors.py", line 148, in execute
    result = self._query(query)
  File "C:\Users\zhi.zhou\Anaconda3\envs\lts\lib\site-packages\pymysql\cursors.py", line 310, in _query
    conn.query(q)
  File "C:\Users\zhi.zhou\Anaconda3\envs\lts\lib\site-packages\pymysql\connections.py", line 548, in query
    self._affected_rows = self._read_query_result(unbuffered=unbuffered)
  File "C:\Users\zhi.zhou\Anaconda3\envs\lts\lib\site-packages\pymysql\connections.py", line 775, in _read_query_result
    result.read()
  File "C:\Users\zhi.zhou\Anaconda3\envs\lts\lib\site-packages\pymysql\connections.py", line 1156, in read
    first_packet = self.connection._read_packet()
  File "C:\Users\zhi.zhou\Anaconda3\envs\lts\lib\site-packages\pymysql\connections.py", line 725, in _read_packet
    packet.raise_for_error()
  File "C:\Users\zhi.zhou\Anaconda3\envs\lts\lib\site-packages\pymysql\protocol.py", line 221, in raise_for_error
    err.raise_mysql_exception(self._data)
  File "C:\Users\zhi.zhou\Anaconda3\envs\lts\lib\site-packages\pymysql\err.py", line 143, in raise_mysql_exception
    raise errorclass(errno, errval)
pymysql.err.OperationalError: (1046, 'No database selected')

During handling of the above exception, another exception occurred:

Traceback (most recent call last):
  File "C:\Users\zhi.zhou\Anaconda3\envs\lts\lib\site-packages\django\core\handlers\exception.py", line 47, in inner
    response = get_response(request)
  File "C:\Users\zhi.zhou\Anaconda3\envs\lts\lib\site-packages\django\core\handlers\base.py", line 181, in _get_response
    response = wrapped_callback(request, *callback_args, **callback_kwargs)
  File "C:\Users\zhi.zhou\Anaconda3\envs\lts\lib\site-packages\django\views\generic\base.py", line 70, in view
    return self.dispatch(request, *args, **kwargs)
  File "C:\Users\zhi.zhou\Anaconda3\envs\lts\lib\site-packages\django\views\generic\base.py", line 98, in dispatch
    return handler(request, *args, **kwargs)
  File "D:\zhouzhi\gitlit_code\logistic_tracking_system\logistic_tracking_system\lts\views.py", line 4259, in get
    data = json.dumps(data)
  File "C:\Users\zhi.zhou\Anaconda3\envs\lts\lib\json\__init__.py", line 231, in dumps
    return _default_encoder.encode(obj)
  File "C:\Users\zhi.zhou\Anaconda3\envs\lts\lib\json\encoder.py", line 199, in encode
    chunks = self.iterencode(o, _one_shot=True)
  File "C:\Users\zhi.zhou\Anaconda3\envs\lts\lib\json\encoder.py", line 257, in iterencode
    return _iterencode(o, 0)
  File "C:\Users\zhi.zhou\Anaconda3\envs\lts\lib\json\encoder.py", line 180, in default
    o.__class__.__name__)
TypeError: Object of type 'OperationalError' is not JSON serializable
[2021-07-27 10:17:19,127][Thread-15:19468][task_id:django.request][log.py:230][ERROR][Internal Server Error: /logistic/LogisticProcessDeal]
Traceback (most recent call last):
  File "D:\zhouzhi\gitlit_code\logistic_tracking_system\logistic_tracking_system\lts\views.py", line 3774, in get
    if len(production_name) == 0 and len(prodect_code) == 0 and len(work_id) == 0:
TypeError: object of type 'NoneType' has no len()

During handling of the above exception, another exception occurred:

Traceback (most recent call last):
  File "C:\Users\zhi.zhou\Anaconda3\envs\lts\lib\site-packages\django\core\handlers\exception.py", line 47, in inner
    response = get_response(request)
  File "C:\Users\zhi.zhou\Anaconda3\envs\lts\lib\site-packages\django\core\handlers\base.py", line 181, in _get_response
    response = wrapped_callback(request, *callback_args, **callback_kwargs)
  File "C:\Users\zhi.zhou\Anaconda3\envs\lts\lib\site-packages\django\views\generic\base.py", line 70, in view
    return self.dispatch(request, *args, **kwargs)
  File "C:\Users\zhi.zhou\Anaconda3\envs\lts\lib\site-packages\django\views\generic\base.py", line 98, in dispatch
    return handler(request, *args, **kwargs)
  File "D:\zhouzhi\gitlit_code\logistic_tracking_system\logistic_tracking_system\lts\views.py", line 4042, in get
    data = json.dumps(data)
  File "C:\Users\zhi.zhou\Anaconda3\envs\lts\lib\json\__init__.py", line 231, in dumps
    return _default_encoder.encode(obj)
  File "C:\Users\zhi.zhou\Anaconda3\envs\lts\lib\json\encoder.py", line 199, in encode
    chunks = self.iterencode(o, _one_shot=True)
  File "C:\Users\zhi.zhou\Anaconda3\envs\lts\lib\json\encoder.py", line 257, in iterencode
    return _iterencode(o, 0)
  File "C:\Users\zhi.zhou\Anaconda3\envs\lts\lib\json\encoder.py", line 180, in default
    o.__class__.__name__)
TypeError: Object of type 'TypeError' is not JSON serializable
[2021-07-27 10:17:43,527][Thread-16:18520][task_id:lts.views][views.py:272][INFO][登录成功]
[2021-07-27 10:17:46,627][Thread-16:18520][task_id:django.request][log.py:230][ERROR][Internal Server Error: /logistic/LogisticProcessDeal]
Traceback (most recent call last):
  File "D:\zhouzhi\gitlit_code\logistic_tracking_system\logistic_tracking_system\lts\views.py", line 3774, in get
    if len(production_name) == 0 and len(prodect_code) == 0 and len(work_id) == 0:
TypeError: object of type 'NoneType' has no len()

During handling of the above exception, another exception occurred:

Traceback (most recent call last):
  File "C:\Users\zhi.zhou\Anaconda3\envs\lts\lib\site-packages\django\core\handlers\exception.py", line 47, in inner
    response = get_response(request)
  File "C:\Users\zhi.zhou\Anaconda3\envs\lts\lib\site-packages\django\core\handlers\base.py", line 181, in _get_response
    response = wrapped_callback(request, *callback_args, **callback_kwargs)
  File "C:\Users\zhi.zhou\Anaconda3\envs\lts\lib\site-packages\django\views\generic\base.py", line 70, in view
    return self.dispatch(request, *args, **kwargs)
  File "C:\Users\zhi.zhou\Anaconda3\envs\lts\lib\site-packages\django\views\generic\base.py", line 98, in dispatch
    return handler(request, *args, **kwargs)
  File "D:\zhouzhi\gitlit_code\logistic_tracking_system\logistic_tracking_system\lts\views.py", line 4042, in get
    data = json.dumps(data)
  File "C:\Users\zhi.zhou\Anaconda3\envs\lts\lib\json\__init__.py", line 231, in dumps
    return _default_encoder.encode(obj)
  File "C:\Users\zhi.zhou\Anaconda3\envs\lts\lib\json\encoder.py", line 199, in encode
    chunks = self.iterencode(o, _one_shot=True)
  File "C:\Users\zhi.zhou\Anaconda3\envs\lts\lib\json\encoder.py", line 257, in iterencode
    return _iterencode(o, 0)
  File "C:\Users\zhi.zhou\Anaconda3\envs\lts\lib\json\encoder.py", line 180, in default
    o.__class__.__name__)
TypeError: Object of type 'TypeError' is not JSON serializable
[2021-07-27 10:20:16,358][MainThread:12064][task_id:django.utils.autoreload][autoreload.py:251][INFO][D:\zhouzhi\gitlit_code\logistic_tracking_system\logistic_tracking_system\lts\views.py changed, reloading.]
[2021-07-27 10:20:17,031][MainThread:14220][task_id:django.utils.autoreload][autoreload.py:637][INFO][Watching for file changes with StatReloader]
[2021-07-27 10:20:34,545][Thread-1:9956][task_id:django.request][log.py:230][ERROR][Internal Server Error: /logistic/LogisticProcessDeal]
Traceback (most recent call last):
  File "D:\zhouzhi\gitlit_code\logistic_tracking_system\logistic_tracking_system\lts\views.py", line 3774, in get
    if len(production_name) == 0 and len(prodect_code) == 0 and len(work_id) == 0:
TypeError: object of type 'NoneType' has no len()

During handling of the above exception, another exception occurred:

Traceback (most recent call last):
  File "C:\Users\zhi.zhou\Anaconda3\envs\lts\lib\site-packages\django\core\handlers\exception.py", line 47, in inner
    response = get_response(request)
  File "C:\Users\zhi.zhou\Anaconda3\envs\lts\lib\site-packages\django\core\handlers\base.py", line 181, in _get_response
    response = wrapped_callback(request, *callback_args, **callback_kwargs)
  File "C:\Users\zhi.zhou\Anaconda3\envs\lts\lib\site-packages\django\views\generic\base.py", line 70, in view
    return self.dispatch(request, *args, **kwargs)
  File "C:\Users\zhi.zhou\Anaconda3\envs\lts\lib\site-packages\django\views\generic\base.py", line 98, in dispatch
    return handler(request, *args, **kwargs)
  File "D:\zhouzhi\gitlit_code\logistic_tracking_system\logistic_tracking_system\lts\views.py", line 4042, in get
    data = json.dumps(data)
  File "C:\Users\zhi.zhou\Anaconda3\envs\lts\lib\json\__init__.py", line 231, in dumps
    return _default_encoder.encode(obj)
  File "C:\Users\zhi.zhou\Anaconda3\envs\lts\lib\json\encoder.py", line 199, in encode
    chunks = self.iterencode(o, _one_shot=True)
  File "C:\Users\zhi.zhou\Anaconda3\envs\lts\lib\json\encoder.py", line 257, in iterencode
    return _iterencode(o, 0)
  File "C:\Users\zhi.zhou\Anaconda3\envs\lts\lib\json\encoder.py", line 180, in default
    o.__class__.__name__)
TypeError: Object of type 'TypeError' is not JSON serializable
[2021-07-27 10:20:39,150][MainThread:14220][task_id:django.utils.autoreload][autoreload.py:251][INFO][D:\zhouzhi\gitlit_code\logistic_tracking_system\logistic_tracking_system\lts\views.py changed, reloading.]
[2021-07-27 10:20:39,840][MainThread:19936][task_id:django.utils.autoreload][autoreload.py:637][INFO][Watching for file changes with StatReloader]
[2021-07-27 10:20:49,480][Thread-1:12752][task_id:django.request][log.py:230][ERROR][Internal Server Error: /logistic/LogisticProcessDeal]
Traceback (most recent call last):
  File "D:\zhouzhi\gitlit_code\logistic_tracking_system\logistic_tracking_system\lts\views.py", line 3774, in get
    if len(production_name) == 0 and len(prodect_code) == 0 and len(work_id) == 0:
TypeError: object of type 'NoneType' has no len()

During handling of the above exception, another exception occurred:

Traceback (most recent call last):
  File "C:\Users\zhi.zhou\Anaconda3\envs\lts\lib\site-packages\django\core\handlers\exception.py", line 47, in inner
    response = get_response(request)
  File "C:\Users\zhi.zhou\Anaconda3\envs\lts\lib\site-packages\django\core\handlers\base.py", line 181, in _get_response
    response = wrapped_callback(request, *callback_args, **callback_kwargs)
  File "C:\Users\zhi.zhou\Anaconda3\envs\lts\lib\site-packages\django\views\generic\base.py", line 70, in view
    return self.dispatch(request, *args, **kwargs)
  File "C:\Users\zhi.zhou\Anaconda3\envs\lts\lib\site-packages\django\views\generic\base.py", line 98, in dispatch
    return handler(request, *args, **kwargs)
  File "D:\zhouzhi\gitlit_code\logistic_tracking_system\logistic_tracking_system\lts\views.py", line 4042, in get
    data = json.dumps(data)
  File "C:\Users\zhi.zhou\Anaconda3\envs\lts\lib\json\__init__.py", line 231, in dumps
    return _default_encoder.encode(obj)
  File "C:\Users\zhi.zhou\Anaconda3\envs\lts\lib\json\encoder.py", line 199, in encode
    chunks = self.iterencode(o, _one_shot=True)
  File "C:\Users\zhi.zhou\Anaconda3\envs\lts\lib\json\encoder.py", line 257, in iterencode
    return _iterencode(o, 0)
  File "C:\Users\zhi.zhou\Anaconda3\envs\lts\lib\json\encoder.py", line 180, in default
    o.__class__.__name__)
TypeError: Object of type 'TypeError' is not JSON serializable
[2021-07-27 10:20:49,499][Thread-2:11388][task_id:django.request][log.py:230][ERROR][Internal Server Error: /logistic/LogisticProcessDeal]
Traceback (most recent call last):
  File "D:\zhouzhi\gitlit_code\logistic_tracking_system\logistic_tracking_system\lts\views.py", line 3774, in get
    if len(production_name) == 0 and len(prodect_code) == 0 and len(work_id) == 0:
TypeError: object of type 'NoneType' has no len()

During handling of the above exception, another exception occurred:

Traceback (most recent call last):
  File "C:\Users\zhi.zhou\Anaconda3\envs\lts\lib\site-packages\django\core\handlers\exception.py", line 47, in inner
    response = get_response(request)
  File "C:\Users\zhi.zhou\Anaconda3\envs\lts\lib\site-packages\django\core\handlers\base.py", line 181, in _get_response
    response = wrapped_callback(request, *callback_args, **callback_kwargs)
  File "C:\Users\zhi.zhou\Anaconda3\envs\lts\lib\site-packages\django\views\generic\base.py", line 70, in view
    return self.dispatch(request, *args, **kwargs)
  File "C:\Users\zhi.zhou\Anaconda3\envs\lts\lib\site-packages\django\views\generic\base.py", line 98, in dispatch
    return handler(request, *args, **kwargs)
  File "D:\zhouzhi\gitlit_code\logistic_tracking_system\logistic_tracking_system\lts\views.py", line 4042, in get
    data = json.dumps(data)
  File "C:\Users\zhi.zhou\Anaconda3\envs\lts\lib\json\__init__.py", line 231, in dumps
    return _default_encoder.encode(obj)
  File "C:\Users\zhi.zhou\Anaconda3\envs\lts\lib\json\encoder.py", line 199, in encode
    chunks = self.iterencode(o, _one_shot=True)
  File "C:\Users\zhi.zhou\Anaconda3\envs\lts\lib\json\encoder.py", line 257, in iterencode
    return _iterencode(o, 0)
  File "C:\Users\zhi.zhou\Anaconda3\envs\lts\lib\json\encoder.py", line 180, in default
    o.__class__.__name__)
TypeError: Object of type 'TypeError' is not JSON serializable
[2021-07-27 10:23:58,222][MainThread:19936][task_id:django.utils.autoreload][autoreload.py:251][INFO][D:\zhouzhi\gitlit_code\logistic_tracking_system\logistic_tracking_system\lts\views.py changed, reloading.]
[2021-07-27 10:23:58,866][MainThread:5992][task_id:django.utils.autoreload][autoreload.py:637][INFO][Watching for file changes with StatReloader]
[2021-07-27 10:24:22,932][MainThread:5992][task_id:django.utils.autoreload][autoreload.py:251][INFO][D:\zhouzhi\gitlit_code\logistic_tracking_system\logistic_tracking_system\lts\views.py changed, reloading.]
[2021-07-27 10:24:23,606][MainThread:16744][task_id:django.utils.autoreload][autoreload.py:637][INFO][Watching for file changes with StatReloader]
[2021-07-27 10:25:20,030][MainThread:16744][task_id:django.utils.autoreload][autoreload.py:251][INFO][D:\zhouzhi\gitlit_code\logistic_tracking_system\logistic_tracking_system\lts\views.py changed, reloading.]
[2021-07-27 10:25:20,661][MainThread:17648][task_id:django.utils.autoreload][autoreload.py:637][INFO][Watching for file changes with StatReloader]
[2021-07-27 10:26:28,215][MainThread:17648][task_id:django.utils.autoreload][autoreload.py:251][INFO][D:\zhouzhi\gitlit_code\logistic_tracking_system\logistic_tracking_system\lts\views.py changed, reloading.]
[2021-07-27 10:26:28,903][MainThread:5324][task_id:django.utils.autoreload][autoreload.py:637][INFO][Watching for file changes with StatReloader]
[2021-07-27 10:28:53,459][MainThread:5324][task_id:django.utils.autoreload][autoreload.py:251][INFO][D:\zhouzhi\gitlit_code\logistic_tracking_system\logistic_tracking_system\lts\views.py changed, reloading.]
[2021-07-27 10:28:54,123][MainThread:12144][task_id:django.utils.autoreload][autoreload.py:637][INFO][Watching for file changes with StatReloader]
[2021-07-27 10:34:51,791][MainThread:12144][task_id:django.utils.autoreload][autoreload.py:251][INFO][D:\zhouzhi\gitlit_code\logistic_tracking_system\logistic_tracking_system\lts\views.py changed, reloading.]
[2021-07-27 10:34:52,484][MainThread:17512][task_id:django.utils.autoreload][autoreload.py:637][INFO][Watching for file changes with StatReloader]
[2021-07-27 10:39:33,432][Thread-4:19348][task_id:lts.views][views.py:272][INFO][登录成功]
[2021-07-27 10:45:46,668][MainThread:17512][task_id:django.utils.autoreload][autoreload.py:251][INFO][D:\zhouzhi\gitlit_code\logistic_tracking_system\logistic_tracking_system\lts\views.py changed, reloading.]
[2021-07-27 10:45:47,405][MainThread:2828][task_id:django.utils.autoreload][autoreload.py:637][INFO][Watching for file changes with StatReloader]
[2021-07-27 10:46:11,520][MainThread:2828][task_id:django.utils.autoreload][autoreload.py:251][INFO][D:\zhouzhi\gitlit_code\logistic_tracking_system\logistic_tracking_system\lts\views.py changed, reloading.]
[2021-07-27 10:46:12,261][MainThread:19112][task_id:django.utils.autoreload][autoreload.py:637][INFO][Watching for file changes with StatReloader]
[2021-07-27 10:48:27,501][MainThread:19112][task_id:django.utils.autoreload][autoreload.py:251][INFO][D:\zhouzhi\gitlit_code\logistic_tracking_system\logistic_tracking_system\lts\views.py changed, reloading.]
[2021-07-27 10:48:28,159][MainThread:12752][task_id:django.utils.autoreload][autoreload.py:637][INFO][Watching for file changes with StatReloader]
[2021-07-27 10:48:41,570][Thread-1:6260][task_id:lts.views][views.py:272][INFO][登录成功]
[2021-07-27 10:48:47,226][Thread-2:13216][task_id:django.request][log.py:230][ERROR][Internal Server Error: /logistic/LogisticProcessDeal]
Traceback (most recent call last):
  File "D:\zhouzhi\gitlit_code\logistic_tracking_system\logistic_tracking_system\lts\views.py", line 3757, in get
    work_id = request.session['session_workId']
  File "C:\Users\zhi.zhou\Anaconda3\envs\lts\lib\site-packages\django\contrib\sessions\backends\base.py", line 65, in __getitem__
    return self._session[key]
KeyError: 'session_workId'

During handling of the above exception, another exception occurred:

Traceback (most recent call last):
  File "C:\Users\zhi.zhou\Anaconda3\envs\lts\lib\site-packages\django\core\handlers\exception.py", line 47, in inner
    response = get_response(request)
  File "C:\Users\zhi.zhou\Anaconda3\envs\lts\lib\site-packages\django\core\handlers\base.py", line 181, in _get_response
    response = wrapped_callback(request, *callback_args, **callback_kwargs)
  File "C:\Users\zhi.zhou\Anaconda3\envs\lts\lib\site-packages\django\views\generic\base.py", line 70, in view
    return self.dispatch(request, *args, **kwargs)
  File "C:\Users\zhi.zhou\Anaconda3\envs\lts\lib\site-packages\django\views\generic\base.py", line 98, in dispatch
    return handler(request, *args, **kwargs)
  File "D:\zhouzhi\gitlit_code\logistic_tracking_system\logistic_tracking_system\lts\views.py", line 4093, in get
    data = json.dumps(data)
  File "C:\Users\zhi.zhou\Anaconda3\envs\lts\lib\json\__init__.py", line 231, in dumps
    return _default_encoder.encode(obj)
  File "C:\Users\zhi.zhou\Anaconda3\envs\lts\lib\json\encoder.py", line 199, in encode
    chunks = self.iterencode(o, _one_shot=True)
  File "C:\Users\zhi.zhou\Anaconda3\envs\lts\lib\json\encoder.py", line 257, in iterencode
    return _iterencode(o, 0)
  File "C:\Users\zhi.zhou\Anaconda3\envs\lts\lib\json\encoder.py", line 180, in default
    o.__class__.__name__)
TypeError: Object of type 'KeyError' is not JSON serializable
[2021-07-27 10:48:51,240][Thread-2:13216][task_id:django.request][log.py:230][ERROR][Internal Server Error: /logistic/LogisticProcessDeal]
Traceback (most recent call last):
  File "D:\zhouzhi\gitlit_code\logistic_tracking_system\logistic_tracking_system\lts\views.py", line 3757, in get
    work_id = request.session['session_workId']
  File "C:\Users\zhi.zhou\Anaconda3\envs\lts\lib\site-packages\django\contrib\sessions\backends\base.py", line 65, in __getitem__
    return self._session[key]
KeyError: 'session_workId'

During handling of the above exception, another exception occurred:

Traceback (most recent call last):
  File "C:\Users\zhi.zhou\Anaconda3\envs\lts\lib\site-packages\django\core\handlers\exception.py", line 47, in inner
    response = get_response(request)
  File "C:\Users\zhi.zhou\Anaconda3\envs\lts\lib\site-packages\django\core\handlers\base.py", line 181, in _get_response
    response = wrapped_callback(request, *callback_args, **callback_kwargs)
  File "C:\Users\zhi.zhou\Anaconda3\envs\lts\lib\site-packages\django\views\generic\base.py", line 70, in view
    return self.dispatch(request, *args, **kwargs)
  File "C:\Users\zhi.zhou\Anaconda3\envs\lts\lib\site-packages\django\views\generic\base.py", line 98, in dispatch
    return handler(request, *args, **kwargs)
  File "D:\zhouzhi\gitlit_code\logistic_tracking_system\logistic_tracking_system\lts\views.py", line 4093, in get
    data = json.dumps(data)
  File "C:\Users\zhi.zhou\Anaconda3\envs\lts\lib\json\__init__.py", line 231, in dumps
    return _default_encoder.encode(obj)
  File "C:\Users\zhi.zhou\Anaconda3\envs\lts\lib\json\encoder.py", line 199, in encode
    chunks = self.iterencode(o, _one_shot=True)
  File "C:\Users\zhi.zhou\Anaconda3\envs\lts\lib\json\encoder.py", line 257, in iterencode
    return _iterencode(o, 0)
  File "C:\Users\zhi.zhou\Anaconda3\envs\lts\lib\json\encoder.py", line 180, in default
    o.__class__.__name__)
TypeError: Object of type 'KeyError' is not JSON serializable
[2021-07-27 10:51:44,510][MainThread:12752][task_id:django.utils.autoreload][autoreload.py:251][INFO][D:\zhouzhi\gitlit_code\logistic_tracking_system\logistic_tracking_system\lts\views.py changed, reloading.]
[2021-07-27 10:51:45,182][MainThread:7696][task_id:django.utils.autoreload][autoreload.py:637][INFO][Watching for file changes with StatReloader]
[2021-07-27 11:06:19,523][Thread-2:4188][task_id:lts.views][views.py:272][INFO][登录成功]
[2021-07-27 11:07:26,636][Thread-4:20392][task_id:django.request][log.py:230][ERROR][Internal Server Error: /logistic/LogisticProductTransitInfo]
Traceback (most recent call last):
  File "D:\zhouzhi\gitlit_code\logistic_tracking_system\logistic_tracking_system\lts\views.py", line 4752, in get
    work_code = drss[0][0]
IndexError: tuple index out of range

During handling of the above exception, another exception occurred:

Traceback (most recent call last):
  File "C:\Users\zhi.zhou\Anaconda3\envs\lts\lib\site-packages\django\core\handlers\exception.py", line 47, in inner
    response = get_response(request)
  File "C:\Users\zhi.zhou\Anaconda3\envs\lts\lib\site-packages\django\core\handlers\base.py", line 181, in _get_response
    response = wrapped_callback(request, *callback_args, **callback_kwargs)
  File "C:\Users\zhi.zhou\Anaconda3\envs\lts\lib\site-packages\django\views\generic\base.py", line 70, in view
    return self.dispatch(request, *args, **kwargs)
  File "C:\Users\zhi.zhou\Anaconda3\envs\lts\lib\site-packages\django\views\generic\base.py", line 98, in dispatch
    return handler(request, *args, **kwargs)
  File "D:\zhouzhi\gitlit_code\logistic_tracking_system\logistic_tracking_system\lts\views.py", line 4886, in get
    data = json.dumps(data)
  File "C:\Users\zhi.zhou\Anaconda3\envs\lts\lib\json\__init__.py", line 231, in dumps
    return _default_encoder.encode(obj)
  File "C:\Users\zhi.zhou\Anaconda3\envs\lts\lib\json\encoder.py", line 199, in encode
    chunks = self.iterencode(o, _one_shot=True)
  File "C:\Users\zhi.zhou\Anaconda3\envs\lts\lib\json\encoder.py", line 257, in iterencode
    return _iterencode(o, 0)
  File "C:\Users\zhi.zhou\Anaconda3\envs\lts\lib\json\encoder.py", line 180, in default
    o.__class__.__name__)
TypeError: Object of type 'IndexError' is not JSON serializable
[2021-07-27 11:07:52,230][MainThread:7696][task_id:django.utils.autoreload][autoreload.py:251][INFO][D:\zhouzhi\gitlit_code\logistic_tracking_system\logistic_tracking_system\lts\views.py changed, reloading.]
[2021-07-27 11:07:52,881][MainThread:19552][task_id:django.utils.autoreload][autoreload.py:637][INFO][Watching for file changes with StatReloader]
[2021-07-27 11:18:20,733][MainThread:19552][task_id:django.utils.autoreload][autoreload.py:251][INFO][D:\zhouzhi\gitlit_code\logistic_tracking_system\logistic_tracking_system\lts\views.py changed, reloading.]
[2021-07-27 11:18:21,392][MainThread:16184][task_id:django.utils.autoreload][autoreload.py:637][INFO][Watching for file changes with StatReloader]
[2021-07-27 11:18:44,684][MainThread:16184][task_id:django.utils.autoreload][autoreload.py:251][INFO][D:\zhouzhi\gitlit_code\logistic_tracking_system\logistic_tracking_system\lts\views.py changed, reloading.]
[2021-07-27 11:19:34,472][MainThread:14740][task_id:django.utils.autoreload][autoreload.py:637][INFO][Watching for file changes with StatReloader]
[2021-07-27 11:21:11,396][Thread-2:5800][task_id:lts.views][views.py:272][INFO][登录成功]
[2021-07-27 11:22:18,609][Thread-4:19004][task_id:lts.views][views.py:148][INFO][登录成功]
[2021-07-27 11:23:21,993][Thread-5:9484][task_id:lts.views][views.py:272][INFO][登录成功]
[2021-07-27 11:23:36,453][Thread-6:20356][task_id:lts.views][views.py:148][INFO][登录成功]
[2021-07-27 11:27:06,865][Thread-7:13368][task_id:lts.views][views.py:148][INFO][登录成功]
[2021-07-27 11:30:29,278][Thread-11:6020][task_id:lts.views][views.py:1497][INFO][创建物料详情表成功]
[2021-07-27 11:30:38,845][Thread-11:6020][task_id:lts.views][views.py:1497][INFO][创建物料详情表成功]
[2021-07-27 12:38:43,520][Thread-21:19772][task_id:django.request][log.py:230][ERROR][Internal Server Error: /logistic/LogisticProductPlanCodeName]
Traceback (most recent call last):
  File "D:\zhouzhi\gitlit_code\logistic_tracking_system\logistic_tracking_system\lts\views.py", line 4250, in get
    drs = db.execute_sql(conn, sql)
  File "D:\zhouzhi\gitlit_code\logistic_tracking_system\logistic_tracking_system\common\db.py", line 45, in execute_sql
    cursor.execute(sql)
  File "C:\Users\zhi.zhou\Anaconda3\envs\lts\lib\site-packages\pymysql\cursors.py", line 148, in execute
    result = self._query(query)
  File "C:\Users\zhi.zhou\Anaconda3\envs\lts\lib\site-packages\pymysql\cursors.py", line 310, in _query
    conn.query(q)
  File "C:\Users\zhi.zhou\Anaconda3\envs\lts\lib\site-packages\pymysql\connections.py", line 548, in query
    self._affected_rows = self._read_query_result(unbuffered=unbuffered)
  File "C:\Users\zhi.zhou\Anaconda3\envs\lts\lib\site-packages\pymysql\connections.py", line 775, in _read_query_result
    result.read()
  File "C:\Users\zhi.zhou\Anaconda3\envs\lts\lib\site-packages\pymysql\connections.py", line 1156, in read
    first_packet = self.connection._read_packet()
  File "C:\Users\zhi.zhou\Anaconda3\envs\lts\lib\site-packages\pymysql\connections.py", line 725, in _read_packet
    packet.raise_for_error()
  File "C:\Users\zhi.zhou\Anaconda3\envs\lts\lib\site-packages\pymysql\protocol.py", line 221, in raise_for_error
    err.raise_mysql_exception(self._data)
  File "C:\Users\zhi.zhou\Anaconda3\envs\lts\lib\site-packages\pymysql\err.py", line 143, in raise_mysql_exception
    raise errorclass(errno, errval)
pymysql.err.OperationalError: (1046, 'No database selected')

During handling of the above exception, another exception occurred:

Traceback (most recent call last):
  File "C:\Users\zhi.zhou\Anaconda3\envs\lts\lib\site-packages\django\core\handlers\exception.py", line 47, in inner
    response = get_response(request)
  File "C:\Users\zhi.zhou\Anaconda3\envs\lts\lib\site-packages\django\core\handlers\base.py", line 181, in _get_response
    response = wrapped_callback(request, *callback_args, **callback_kwargs)
  File "C:\Users\zhi.zhou\Anaconda3\envs\lts\lib\site-packages\django\views\generic\base.py", line 70, in view
    return self.dispatch(request, *args, **kwargs)
  File "C:\Users\zhi.zhou\Anaconda3\envs\lts\lib\site-packages\django\views\generic\base.py", line 98, in dispatch
    return handler(request, *args, **kwargs)
  File "D:\zhouzhi\gitlit_code\logistic_tracking_system\logistic_tracking_system\lts\views.py", line 4263, in get
    data = json.dumps(data)
  File "C:\Users\zhi.zhou\Anaconda3\envs\lts\lib\json\__init__.py", line 231, in dumps
    return _default_encoder.encode(obj)
  File "C:\Users\zhi.zhou\Anaconda3\envs\lts\lib\json\encoder.py", line 199, in encode
    chunks = self.iterencode(o, _one_shot=True)
  File "C:\Users\zhi.zhou\Anaconda3\envs\lts\lib\json\encoder.py", line 257, in iterencode
    return _iterencode(o, 0)
  File "C:\Users\zhi.zhou\Anaconda3\envs\lts\lib\json\encoder.py", line 180, in default
    o.__class__.__name__)
TypeError: Object of type 'OperationalError' is not JSON serializable
[2021-07-27 12:39:19,425][Thread-21:19772][task_id:lts.views][views.py:148][INFO][登录成功]
[2021-07-27 12:53:15,346][Thread-25:18584][task_id:django.request][log.py:230][ERROR][Internal Server Error: /logistic/LogisticProductPlanCodeName]
Traceback (most recent call last):
  File "D:\zhouzhi\gitlit_code\logistic_tracking_system\logistic_tracking_system\lts\views.py", line 4250, in get
    drs = db.execute_sql(conn, sql)
  File "D:\zhouzhi\gitlit_code\logistic_tracking_system\logistic_tracking_system\common\db.py", line 45, in execute_sql
    cursor.execute(sql)
  File "C:\Users\zhi.zhou\Anaconda3\envs\lts\lib\site-packages\pymysql\cursors.py", line 148, in execute
    result = self._query(query)
  File "C:\Users\zhi.zhou\Anaconda3\envs\lts\lib\site-packages\pymysql\cursors.py", line 310, in _query
    conn.query(q)
  File "C:\Users\zhi.zhou\Anaconda3\envs\lts\lib\site-packages\pymysql\connections.py", line 548, in query
    self._affected_rows = self._read_query_result(unbuffered=unbuffered)
  File "C:\Users\zhi.zhou\Anaconda3\envs\lts\lib\site-packages\pymysql\connections.py", line 775, in _read_query_result
    result.read()
  File "C:\Users\zhi.zhou\Anaconda3\envs\lts\lib\site-packages\pymysql\connections.py", line 1156, in read
    first_packet = self.connection._read_packet()
  File "C:\Users\zhi.zhou\Anaconda3\envs\lts\lib\site-packages\pymysql\connections.py", line 725, in _read_packet
    packet.raise_for_error()
  File "C:\Users\zhi.zhou\Anaconda3\envs\lts\lib\site-packages\pymysql\protocol.py", line 221, in raise_for_error
    err.raise_mysql_exception(self._data)
  File "C:\Users\zhi.zhou\Anaconda3\envs\lts\lib\site-packages\pymysql\err.py", line 143, in raise_mysql_exception
    raise errorclass(errno, errval)
pymysql.err.OperationalError: (1046, 'No database selected')

During handling of the above exception, another exception occurred:

Traceback (most recent call last):
  File "C:\Users\zhi.zhou\Anaconda3\envs\lts\lib\site-packages\django\core\handlers\exception.py", line 47, in inner
    response = get_response(request)
  File "C:\Users\zhi.zhou\Anaconda3\envs\lts\lib\site-packages\django\core\handlers\base.py", line 181, in _get_response
    response = wrapped_callback(request, *callback_args, **callback_kwargs)
  File "C:\Users\zhi.zhou\Anaconda3\envs\lts\lib\site-packages\django\views\generic\base.py", line 70, in view
    return self.dispatch(request, *args, **kwargs)
  File "C:\Users\zhi.zhou\Anaconda3\envs\lts\lib\site-packages\django\views\generic\base.py", line 98, in dispatch
    return handler(request, *args, **kwargs)
  File "D:\zhouzhi\gitlit_code\logistic_tracking_system\logistic_tracking_system\lts\views.py", line 4263, in get
    data = json.dumps(data)
  File "C:\Users\zhi.zhou\Anaconda3\envs\lts\lib\json\__init__.py", line 231, in dumps
    return _default_encoder.encode(obj)
  File "C:\Users\zhi.zhou\Anaconda3\envs\lts\lib\json\encoder.py", line 199, in encode
    chunks = self.iterencode(o, _one_shot=True)
  File "C:\Users\zhi.zhou\Anaconda3\envs\lts\lib\json\encoder.py", line 257, in iterencode
    return _iterencode(o, 0)
  File "C:\Users\zhi.zhou\Anaconda3\envs\lts\lib\json\encoder.py", line 180, in default
    o.__class__.__name__)
TypeError: Object of type 'OperationalError' is not JSON serializable
[2021-07-27 13:00:27,608][Thread-27:7340][task_id:lts.views][views.py:3519][INFO][创建产品详情表成功]
[2021-07-27 13:16:33,541][Thread-30:4184][task_id:lts.views][views.py:218][INFO][登录成功]
[2021-07-27 13:17:18,329][Thread-32:3296][task_id:django.request][log.py:230][ERROR][Internal Server Error: /logistic/LogisticProductPlanCodeName]
Traceback (most recent call last):
  File "D:\zhouzhi\gitlit_code\logistic_tracking_system\logistic_tracking_system\lts\views.py", line 4250, in get
    drs = db.execute_sql(conn, sql)
  File "D:\zhouzhi\gitlit_code\logistic_tracking_system\logistic_tracking_system\common\db.py", line 45, in execute_sql
    cursor.execute(sql)
  File "C:\Users\zhi.zhou\Anaconda3\envs\lts\lib\site-packages\pymysql\cursors.py", line 148, in execute
    result = self._query(query)
  File "C:\Users\zhi.zhou\Anaconda3\envs\lts\lib\site-packages\pymysql\cursors.py", line 310, in _query
    conn.query(q)
  File "C:\Users\zhi.zhou\Anaconda3\envs\lts\lib\site-packages\pymysql\connections.py", line 548, in query
    self._affected_rows = self._read_query_result(unbuffered=unbuffered)
  File "C:\Users\zhi.zhou\Anaconda3\envs\lts\lib\site-packages\pymysql\connections.py", line 775, in _read_query_result
    result.read()
  File "C:\Users\zhi.zhou\Anaconda3\envs\lts\lib\site-packages\pymysql\connections.py", line 1156, in read
    first_packet = self.connection._read_packet()
  File "C:\Users\zhi.zhou\Anaconda3\envs\lts\lib\site-packages\pymysql\connections.py", line 725, in _read_packet
    packet.raise_for_error()
  File "C:\Users\zhi.zhou\Anaconda3\envs\lts\lib\site-packages\pymysql\protocol.py", line 221, in raise_for_error
    err.raise_mysql_exception(self._data)
  File "C:\Users\zhi.zhou\Anaconda3\envs\lts\lib\site-packages\pymysql\err.py", line 143, in raise_mysql_exception
    raise errorclass(errno, errval)
pymysql.err.OperationalError: (1046, 'No database selected')

During handling of the above exception, another exception occurred:

Traceback (most recent call last):
  File "C:\Users\zhi.zhou\Anaconda3\envs\lts\lib\site-packages\django\core\handlers\exception.py", line 47, in inner
    response = get_response(request)
  File "C:\Users\zhi.zhou\Anaconda3\envs\lts\lib\site-packages\django\core\handlers\base.py", line 181, in _get_response
    response = wrapped_callback(request, *callback_args, **callback_kwargs)
  File "C:\Users\zhi.zhou\Anaconda3\envs\lts\lib\site-packages\django\views\generic\base.py", line 70, in view
    return self.dispatch(request, *args, **kwargs)
  File "C:\Users\zhi.zhou\Anaconda3\envs\lts\lib\site-packages\django\views\generic\base.py", line 98, in dispatch
    return handler(request, *args, **kwargs)
  File "D:\zhouzhi\gitlit_code\logistic_tracking_system\logistic_tracking_system\lts\views.py", line 4263, in get
    data = json.dumps(data)
  File "C:\Users\zhi.zhou\Anaconda3\envs\lts\lib\json\__init__.py", line 231, in dumps
    return _default_encoder.encode(obj)
  File "C:\Users\zhi.zhou\Anaconda3\envs\lts\lib\json\encoder.py", line 199, in encode
    chunks = self.iterencode(o, _one_shot=True)
  File "C:\Users\zhi.zhou\Anaconda3\envs\lts\lib\json\encoder.py", line 257, in iterencode
    return _iterencode(o, 0)
  File "C:\Users\zhi.zhou\Anaconda3\envs\lts\lib\json\encoder.py", line 180, in default
    o.__class__.__name__)
TypeError: Object of type 'OperationalError' is not JSON serializable
[2021-07-27 13:17:18,990][Thread-32:3296][task_id:django.request][log.py:230][ERROR][Internal Server Error: /logistic/LogisticProductPlanCodeName]
Traceback (most recent call last):
  File "D:\zhouzhi\gitlit_code\logistic_tracking_system\logistic_tracking_system\lts\views.py", line 4250, in get
    drs = db.execute_sql(conn, sql)
  File "D:\zhouzhi\gitlit_code\logistic_tracking_system\logistic_tracking_system\common\db.py", line 45, in execute_sql
    cursor.execute(sql)
  File "C:\Users\zhi.zhou\Anaconda3\envs\lts\lib\site-packages\pymysql\cursors.py", line 148, in execute
    result = self._query(query)
  File "C:\Users\zhi.zhou\Anaconda3\envs\lts\lib\site-packages\pymysql\cursors.py", line 310, in _query
    conn.query(q)
  File "C:\Users\zhi.zhou\Anaconda3\envs\lts\lib\site-packages\pymysql\connections.py", line 548, in query
    self._affected_rows = self._read_query_result(unbuffered=unbuffered)
  File "C:\Users\zhi.zhou\Anaconda3\envs\lts\lib\site-packages\pymysql\connections.py", line 775, in _read_query_result
    result.read()
  File "C:\Users\zhi.zhou\Anaconda3\envs\lts\lib\site-packages\pymysql\connections.py", line 1156, in read
    first_packet = self.connection._read_packet()
  File "C:\Users\zhi.zhou\Anaconda3\envs\lts\lib\site-packages\pymysql\connections.py", line 725, in _read_packet
    packet.raise_for_error()
  File "C:\Users\zhi.zhou\Anaconda3\envs\lts\lib\site-packages\pymysql\protocol.py", line 221, in raise_for_error
    err.raise_mysql_exception(self._data)
  File "C:\Users\zhi.zhou\Anaconda3\envs\lts\lib\site-packages\pymysql\err.py", line 143, in raise_mysql_exception
    raise errorclass(errno, errval)
pymysql.err.OperationalError: (1046, 'No database selected')

During handling of the above exception, another exception occurred:

Traceback (most recent call last):
  File "C:\Users\zhi.zhou\Anaconda3\envs\lts\lib\site-packages\django\core\handlers\exception.py", line 47, in inner
    response = get_response(request)
  File "C:\Users\zhi.zhou\Anaconda3\envs\lts\lib\site-packages\django\core\handlers\base.py", line 181, in _get_response
    response = wrapped_callback(request, *callback_args, **callback_kwargs)
  File "C:\Users\zhi.zhou\Anaconda3\envs\lts\lib\site-packages\django\views\generic\base.py", line 70, in view
    return self.dispatch(request, *args, **kwargs)
  File "C:\Users\zhi.zhou\Anaconda3\envs\lts\lib\site-packages\django\views\generic\base.py", line 98, in dispatch
    return handler(request, *args, **kwargs)
  File "D:\zhouzhi\gitlit_code\logistic_tracking_system\logistic_tracking_system\lts\views.py", line 4263, in get
    data = json.dumps(data)
  File "C:\Users\zhi.zhou\Anaconda3\envs\lts\lib\json\__init__.py", line 231, in dumps
    return _default_encoder.encode(obj)
  File "C:\Users\zhi.zhou\Anaconda3\envs\lts\lib\json\encoder.py", line 199, in encode
    chunks = self.iterencode(o, _one_shot=True)
  File "C:\Users\zhi.zhou\Anaconda3\envs\lts\lib\json\encoder.py", line 257, in iterencode
    return _iterencode(o, 0)
  File "C:\Users\zhi.zhou\Anaconda3\envs\lts\lib\json\encoder.py", line 180, in default
    o.__class__.__name__)
TypeError: Object of type 'OperationalError' is not JSON serializable
[2021-07-27 13:19:05,877][Thread-34:744][task_id:lts.views][views.py:148][INFO][登录成功]
[2021-07-27 13:21:39,828][Thread-38:7356][task_id:lts.views][views.py:1856][ERROR][查询产品列表失败]
[2021-07-27 13:21:50,619][Thread-38:7356][task_id:lts.views][views.py:218][INFO][登录成功]
[2021-07-27 13:28:19,243][Thread-43:2816][task_id:lts.views][views.py:218][INFO][登录成功]
[2021-07-27 13:28:39,899][Thread-44:20064][task_id:lts.views][views.py:272][INFO][登录成功]
[2021-07-27 13:46:51,081][Thread-50:18272][task_id:lts.views][views.py:218][INFO][登录成功]
[2021-07-27 13:47:18,947][Thread-50:18272][task_id:lts.views][views.py:272][INFO][登录成功]
[2021-07-27 13:52:19,313][Thread-55:7340][task_id:lts.views][views.py:148][INFO][登录成功]
[2021-07-27 14:00:26,515][MainThread:14740][task_id:django.utils.autoreload][autoreload.py:251][INFO][D:\zhouzhi\gitlit_code\logistic_tracking_system\logistic_tracking_system\lts\views.py changed, reloading.]
[2021-07-27 14:00:27,187][MainThread:11156][task_id:django.utils.autoreload][autoreload.py:637][INFO][Watching for file changes with StatReloader]
[2021-07-27 14:01:15,092][MainThread:11156][task_id:django.utils.autoreload][autoreload.py:251][INFO][D:\zhouzhi\gitlit_code\logistic_tracking_system\logistic_tracking_system\lts\views.py changed, reloading.]
[2021-07-27 14:01:15,739][MainThread:3580][task_id:django.utils.autoreload][autoreload.py:637][INFO][Watching for file changes with StatReloader]
[2021-07-27 14:03:14,395][MainThread:3580][task_id:django.utils.autoreload][autoreload.py:251][INFO][D:\zhouzhi\gitlit_code\logistic_tracking_system\logistic_tracking_system\lts\views.py changed, reloading.]
[2021-07-27 14:03:15,061][MainThread:5164][task_id:django.utils.autoreload][autoreload.py:637][INFO][Watching for file changes with StatReloader]
[2021-07-27 14:03:32,815][Thread-2:19224][task_id:django.request][log.py:230][ERROR][Internal Server Error: /logistic/LogisticQualifiedMatterCode]
Traceback (most recent call last):
  File "D:\zhouzhi\gitlit_code\logistic_tracking_system\logistic_tracking_system\lts\views.py", line 5407, in get
    drs = db.execute_sql(conn, sql_work_id)
  File "D:\zhouzhi\gitlit_code\logistic_tracking_system\logistic_tracking_system\common\db.py", line 45, in execute_sql
    cursor.execute(sql)
  File "C:\Users\zhi.zhou\Anaconda3\envs\lts\lib\site-packages\pymysql\cursors.py", line 148, in execute
    result = self._query(query)
  File "C:\Users\zhi.zhou\Anaconda3\envs\lts\lib\site-packages\pymysql\cursors.py", line 310, in _query
    conn.query(q)
  File "C:\Users\zhi.zhou\Anaconda3\envs\lts\lib\site-packages\pymysql\connections.py", line 548, in query
    self._affected_rows = self._read_query_result(unbuffered=unbuffered)
  File "C:\Users\zhi.zhou\Anaconda3\envs\lts\lib\site-packages\pymysql\connections.py", line 775, in _read_query_result
    result.read()
  File "C:\Users\zhi.zhou\Anaconda3\envs\lts\lib\site-packages\pymysql\connections.py", line 1156, in read
    first_packet = self.connection._read_packet()
  File "C:\Users\zhi.zhou\Anaconda3\envs\lts\lib\site-packages\pymysql\connections.py", line 725, in _read_packet
    packet.raise_for_error()
  File "C:\Users\zhi.zhou\Anaconda3\envs\lts\lib\site-packages\pymysql\protocol.py", line 221, in raise_for_error
    err.raise_mysql_exception(self._data)
  File "C:\Users\zhi.zhou\Anaconda3\envs\lts\lib\site-packages\pymysql\err.py", line 143, in raise_mysql_exception
    raise errorclass(errno, errval)
pymysql.err.OperationalError: (1046, 'No database selected')

During handling of the above exception, another exception occurred:

Traceback (most recent call last):
  File "C:\Users\zhi.zhou\Anaconda3\envs\lts\lib\site-packages\django\core\handlers\exception.py", line 47, in inner
    response = get_response(request)
  File "C:\Users\zhi.zhou\Anaconda3\envs\lts\lib\site-packages\django\core\handlers\base.py", line 181, in _get_response
    response = wrapped_callback(request, *callback_args, **callback_kwargs)
  File "C:\Users\zhi.zhou\Anaconda3\envs\lts\lib\site-packages\django\views\generic\base.py", line 70, in view
    return self.dispatch(request, *args, **kwargs)
  File "C:\Users\zhi.zhou\Anaconda3\envs\lts\lib\site-packages\django\views\generic\base.py", line 98, in dispatch
    return handler(request, *args, **kwargs)
  File "D:\zhouzhi\gitlit_code\logistic_tracking_system\logistic_tracking_system\lts\views.py", line 5437, in get
    data = json.dumps(data)
  File "C:\Users\zhi.zhou\Anaconda3\envs\lts\lib\json\__init__.py", line 231, in dumps
    return _default_encoder.encode(obj)
  File "C:\Users\zhi.zhou\Anaconda3\envs\lts\lib\json\encoder.py", line 199, in encode
    chunks = self.iterencode(o, _one_shot=True)
  File "C:\Users\zhi.zhou\Anaconda3\envs\lts\lib\json\encoder.py", line 257, in iterencode
    return _iterencode(o, 0)
  File "C:\Users\zhi.zhou\Anaconda3\envs\lts\lib\json\encoder.py", line 180, in default
    o.__class__.__name__)
TypeError: Object of type 'OperationalError' is not JSON serializable
[2021-07-27 14:03:32,833][Thread-1:19020][task_id:django.request][log.py:230][ERROR][Internal Server Error: /logistic/LogisticUnqualifiedProduct]
Traceback (most recent call last):
  File "D:\zhouzhi\gitlit_code\logistic_tracking_system\logistic_tracking_system\lts\views.py", line 5236, in get
    page = int(request.GET.get("page"))
TypeError: int() argument must be a string, a bytes-like object or a number, not 'NoneType'

During handling of the above exception, another exception occurred:

Traceback (most recent call last):
  File "C:\Users\zhi.zhou\Anaconda3\envs\lts\lib\site-packages\django\core\handlers\exception.py", line 47, in inner
    response = get_response(request)
  File "C:\Users\zhi.zhou\Anaconda3\envs\lts\lib\site-packages\django\core\handlers\base.py", line 181, in _get_response
    response = wrapped_callback(request, *callback_args, **callback_kwargs)
  File "C:\Users\zhi.zhou\Anaconda3\envs\lts\lib\site-packages\django\views\generic\base.py", line 70, in view
    return self.dispatch(request, *args, **kwargs)
  File "C:\Users\zhi.zhou\Anaconda3\envs\lts\lib\site-packages\django\views\generic\base.py", line 98, in dispatch
    return handler(request, *args, **kwargs)
  File "D:\zhouzhi\gitlit_code\logistic_tracking_system\logistic_tracking_system\lts\views.py", line 5315, in get
    data = json.dumps(data)
  File "C:\Users\zhi.zhou\Anaconda3\envs\lts\lib\json\__init__.py", line 231, in dumps
    return _default_encoder.encode(obj)
  File "C:\Users\zhi.zhou\Anaconda3\envs\lts\lib\json\encoder.py", line 199, in encode
    chunks = self.iterencode(o, _one_shot=True)
  File "C:\Users\zhi.zhou\Anaconda3\envs\lts\lib\json\encoder.py", line 257, in iterencode
    return _iterencode(o, 0)
  File "C:\Users\zhi.zhou\Anaconda3\envs\lts\lib\json\encoder.py", line 180, in default
    o.__class__.__name__)
TypeError: Object of type 'TypeError' is not JSON serializable
[2021-07-27 14:03:32,892][Thread-2:19224][task_id:django.request][log.py:230][ERROR][Internal Server Error: /logistic/LogisticProductTransitInfo]
Traceback (most recent call last):
  File "D:\zhouzhi\gitlit_code\logistic_tracking_system\logistic_tracking_system\lts\views.py", line 4755, in get
    drss = db.execute_sql(conn, sql_work_code_main)
  File "D:\zhouzhi\gitlit_code\logistic_tracking_system\logistic_tracking_system\common\db.py", line 45, in execute_sql
    cursor.execute(sql)
  File "C:\Users\zhi.zhou\Anaconda3\envs\lts\lib\site-packages\pymysql\cursors.py", line 148, in execute
    result = self._query(query)
  File "C:\Users\zhi.zhou\Anaconda3\envs\lts\lib\site-packages\pymysql\cursors.py", line 310, in _query
    conn.query(q)
  File "C:\Users\zhi.zhou\Anaconda3\envs\lts\lib\site-packages\pymysql\connections.py", line 548, in query
    self._affected_rows = self._read_query_result(unbuffered=unbuffered)
  File "C:\Users\zhi.zhou\Anaconda3\envs\lts\lib\site-packages\pymysql\connections.py", line 775, in _read_query_result
    result.read()
  File "C:\Users\zhi.zhou\Anaconda3\envs\lts\lib\site-packages\pymysql\connections.py", line 1156, in read
    first_packet = self.connection._read_packet()
  File "C:\Users\zhi.zhou\Anaconda3\envs\lts\lib\site-packages\pymysql\connections.py", line 725, in _read_packet
    packet.raise_for_error()
  File "C:\Users\zhi.zhou\Anaconda3\envs\lts\lib\site-packages\pymysql\protocol.py", line 221, in raise_for_error
    err.raise_mysql_exception(self._data)
  File "C:\Users\zhi.zhou\Anaconda3\envs\lts\lib\site-packages\pymysql\err.py", line 143, in raise_mysql_exception
    raise errorclass(errno, errval)
pymysql.err.OperationalError: (1046, 'No database selected')

During handling of the above exception, another exception occurred:

Traceback (most recent call last):
  File "C:\Users\zhi.zhou\Anaconda3\envs\lts\lib\site-packages\django\core\handlers\exception.py", line 47, in inner
    response = get_response(request)
  File "C:\Users\zhi.zhou\Anaconda3\envs\lts\lib\site-packages\django\core\handlers\base.py", line 181, in _get_response
    response = wrapped_callback(request, *callback_args, **callback_kwargs)
  File "C:\Users\zhi.zhou\Anaconda3\envs\lts\lib\site-packages\django\views\generic\base.py", line 70, in view
    return self.dispatch(request, *args, **kwargs)
  File "C:\Users\zhi.zhou\Anaconda3\envs\lts\lib\site-packages\django\views\generic\base.py", line 98, in dispatch
    return handler(request, *args, **kwargs)
  File "D:\zhouzhi\gitlit_code\logistic_tracking_system\logistic_tracking_system\lts\views.py", line 4890, in get
    data = json.dumps(data)
  File "C:\Users\zhi.zhou\Anaconda3\envs\lts\lib\json\__init__.py", line 231, in dumps
    return _default_encoder.encode(obj)
  File "C:\Users\zhi.zhou\Anaconda3\envs\lts\lib\json\encoder.py", line 199, in encode
    chunks = self.iterencode(o, _one_shot=True)
  File "C:\Users\zhi.zhou\Anaconda3\envs\lts\lib\json\encoder.py", line 257, in iterencode
    return _iterencode(o, 0)
  File "C:\Users\zhi.zhou\Anaconda3\envs\lts\lib\json\encoder.py", line 180, in default
    o.__class__.__name__)
TypeError: Object of type 'OperationalError' is not JSON serializable
[2021-07-27 14:05:43,273][MainThread:5164][task_id:django.utils.autoreload][autoreload.py:251][INFO][D:\zhouzhi\gitlit_code\logistic_tracking_system\logistic_tracking_system\lts\views.py changed, reloading.]
[2021-07-27 14:05:43,980][MainThread:15020][task_id:django.utils.autoreload][autoreload.py:637][INFO][Watching for file changes with StatReloader]
[2021-07-27 14:06:32,592][Thread-2:10968][task_id:lts.views][views.py:1852][ERROR][查询产品列表失败]
[2021-07-27 14:07:46,629][MainThread:15020][task_id:django.utils.autoreload][autoreload.py:251][INFO][D:\zhouzhi\gitlit_code\logistic_tracking_system\logistic_tracking_system\lts\views.py changed, reloading.]
[2021-07-27 14:07:47,305][MainThread:8992][task_id:django.utils.autoreload][autoreload.py:637][INFO][Watching for file changes with StatReloader]
[2021-07-27 14:08:47,841][MainThread:8992][task_id:django.utils.autoreload][autoreload.py:251][INFO][D:\zhouzhi\gitlit_code\logistic_tracking_system\logistic_tracking_system\lts\views.py changed, reloading.]
[2021-07-27 14:08:48,497][MainThread:15220][task_id:django.utils.autoreload][autoreload.py:637][INFO][Watching for file changes with StatReloader]
[2021-07-27 14:09:06,803][MainThread:15220][task_id:django.utils.autoreload][autoreload.py:251][INFO][D:\zhouzhi\gitlit_code\logistic_tracking_system\logistic_tracking_system\lts\views.py changed, reloading.]
[2021-07-27 14:09:07,464][MainThread:6336][task_id:django.utils.autoreload][autoreload.py:637][INFO][Watching for file changes with StatReloader]
[2021-07-27 14:09:26,453][MainThread:6336][task_id:django.utils.autoreload][autoreload.py:251][INFO][D:\zhouzhi\gitlit_code\logistic_tracking_system\logistic_tracking_system\lts\views.py changed, reloading.]
[2021-07-27 14:09:27,120][MainThread:4176][task_id:django.utils.autoreload][autoreload.py:637][INFO][Watching for file changes with StatReloader]
[2021-07-27 14:10:04,624][MainThread:4176][task_id:django.utils.autoreload][autoreload.py:251][INFO][D:\zhouzhi\gitlit_code\logistic_tracking_system\logistic_tracking_system\lts\views.py changed, reloading.]
[2021-07-27 14:10:05,295][MainThread:19728][task_id:django.utils.autoreload][autoreload.py:637][INFO][Watching for file changes with StatReloader]
[2021-07-27 14:10:22,086][MainThread:19728][task_id:django.utils.autoreload][autoreload.py:251][INFO][D:\zhouzhi\gitlit_code\logistic_tracking_system\logistic_tracking_system\lts\views.py changed, reloading.]
[2021-07-27 14:10:22,734][MainThread:20048][task_id:django.utils.autoreload][autoreload.py:637][INFO][Watching for file changes with StatReloader]
[2021-07-27 14:10:33,593][MainThread:20048][task_id:django.utils.autoreload][autoreload.py:251][INFO][D:\zhouzhi\gitlit_code\logistic_tracking_system\logistic_tracking_system\lts\views.py changed, reloading.]
[2021-07-27 14:10:34,240][MainThread:16392][task_id:django.utils.autoreload][autoreload.py:637][INFO][Watching for file changes with StatReloader]
[2021-07-27 14:10:44,985][MainThread:16392][task_id:django.utils.autoreload][autoreload.py:251][INFO][D:\zhouzhi\gitlit_code\logistic_tracking_system\logistic_tracking_system\lts\views.py changed, reloading.]
[2021-07-27 14:10:45,660][MainThread:1336][task_id:django.utils.autoreload][autoreload.py:637][INFO][Watching for file changes with StatReloader]
[2021-07-27 14:10:57,387][MainThread:1336][task_id:django.utils.autoreload][autoreload.py:251][INFO][D:\zhouzhi\gitlit_code\logistic_tracking_system\logistic_tracking_system\lts\views.py changed, reloading.]
[2021-07-27 14:10:58,047][MainThread:13172][task_id:django.utils.autoreload][autoreload.py:637][INFO][Watching for file changes with StatReloader]
[2021-07-27 14:11:21,425][MainThread:13172][task_id:django.utils.autoreload][autoreload.py:251][INFO][D:\zhouzhi\gitlit_code\logistic_tracking_system\logistic_tracking_system\lts\views.py changed, reloading.]
[2021-07-27 14:11:22,088][MainThread:20140][task_id:django.utils.autoreload][autoreload.py:637][INFO][Watching for file changes with StatReloader]
[2021-07-27 14:11:34,767][MainThread:20140][task_id:django.utils.autoreload][autoreload.py:251][INFO][D:\zhouzhi\gitlit_code\logistic_tracking_system\logistic_tracking_system\lts\views.py changed, reloading.]
[2021-07-27 14:11:35,429][MainThread:10000][task_id:django.utils.autoreload][autoreload.py:637][INFO][Watching for file changes with StatReloader]
[2021-07-27 14:11:49,273][MainThread:10000][task_id:django.utils.autoreload][autoreload.py:251][INFO][D:\zhouzhi\gitlit_code\logistic_tracking_system\logistic_tracking_system\lts\views.py changed, reloading.]
[2021-07-27 14:11:49,914][MainThread:19400][task_id:django.utils.autoreload][autoreload.py:637][INFO][Watching for file changes with StatReloader]
[2021-07-27 14:12:02,703][MainThread:19400][task_id:django.utils.autoreload][autoreload.py:251][INFO][D:\zhouzhi\gitlit_code\logistic_tracking_system\logistic_tracking_system\lts\views.py changed, reloading.]
[2021-07-27 14:12:03,335][MainThread:14952][task_id:django.utils.autoreload][autoreload.py:637][INFO][Watching for file changes with StatReloader]
[2021-07-27 14:13:47,392][MainThread:14952][task_id:django.utils.autoreload][autoreload.py:251][INFO][D:\zhouzhi\gitlit_code\logistic_tracking_system\logistic_tracking_system\lts\views.py changed, reloading.]
[2021-07-27 14:13:48,044][MainThread:7092][task_id:django.utils.autoreload][autoreload.py:637][INFO][Watching for file changes with StatReloader]
[2021-07-27 14:16:15,344][MainThread:7092][task_id:django.utils.autoreload][autoreload.py:251][INFO][D:\zhouzhi\gitlit_code\logistic_tracking_system\logistic_tracking_system\lts\views.py changed, reloading.]
[2021-07-27 14:16:15,999][MainThread:15048][task_id:django.utils.autoreload][autoreload.py:637][INFO][Watching for file changes with StatReloader]
[2021-07-27 14:16:33,994][Thread-1:19876][task_id:lts.views][views.py:218][INFO][登录成功]
[2021-07-27 14:18:13,812][MainThread:15048][task_id:django.utils.autoreload][autoreload.py:251][INFO][D:\zhouzhi\gitlit_code\logistic_tracking_system\logistic_tracking_system\lts\views.py changed, reloading.]
[2021-07-27 14:18:14,842][MainThread:20260][task_id:django.utils.autoreload][autoreload.py:637][INFO][Watching for file changes with StatReloader]
[2021-07-27 14:19:04,453][MainThread:20260][task_id:django.utils.autoreload][autoreload.py:251][INFO][D:\zhouzhi\gitlit_code\logistic_tracking_system\logistic_tracking_system\lts\views.py changed, reloading.]
[2021-07-27 14:19:05,086][MainThread:20324][task_id:django.utils.autoreload][autoreload.py:637][INFO][Watching for file changes with StatReloader]
[2021-07-27 14:20:27,456][MainThread:20324][task_id:django.utils.autoreload][autoreload.py:251][INFO][D:\zhouzhi\gitlit_code\logistic_tracking_system\logistic_tracking_system\lts\views.py changed, reloading.]
[2021-07-27 14:20:28,124][MainThread:19728][task_id:django.utils.autoreload][autoreload.py:637][INFO][Watching for file changes with StatReloader]
[2021-07-27 14:20:36,734][MainThread:19728][task_id:django.utils.autoreload][autoreload.py:251][INFO][D:\zhouzhi\gitlit_code\logistic_tracking_system\logistic_tracking_system\lts\views.py changed, reloading.]
[2021-07-27 14:20:37,377][MainThread:20396][task_id:django.utils.autoreload][autoreload.py:637][INFO][Watching for file changes with StatReloader]
[2021-07-27 14:21:56,877][MainThread:20396][task_id:django.utils.autoreload][autoreload.py:251][INFO][D:\zhouzhi\gitlit_code\logistic_tracking_system\logistic_tracking_system\lts\views.py changed, reloading.]
[2021-07-27 14:21:57,519][MainThread:8996][task_id:django.utils.autoreload][autoreload.py:637][INFO][Watching for file changes with StatReloader]
[2021-07-27 14:22:05,159][MainThread:8996][task_id:django.utils.autoreload][autoreload.py:251][INFO][D:\zhouzhi\gitlit_code\logistic_tracking_system\logistic_tracking_system\lts\views.py changed, reloading.]
[2021-07-27 14:22:05,792][MainThread:13696][task_id:django.utils.autoreload][autoreload.py:637][INFO][Watching for file changes with StatReloader]
[2021-07-27 14:23:51,131][MainThread:13696][task_id:django.utils.autoreload][autoreload.py:251][INFO][D:\zhouzhi\gitlit_code\logistic_tracking_system\logistic_tracking_system\lts\views.py changed, reloading.]
[2021-07-27 14:23:51,788][MainThread:10184][task_id:django.utils.autoreload][autoreload.py:637][INFO][Watching for file changes with StatReloader]
[2021-07-27 14:26:15,088][MainThread:10184][task_id:django.utils.autoreload][autoreload.py:251][INFO][D:\zhouzhi\gitlit_code\logistic_tracking_system\logistic_tracking_system\lts\views.py changed, reloading.]
[2021-07-27 14:26:15,757][MainThread:19608][task_id:django.utils.autoreload][autoreload.py:637][INFO][Watching for file changes with StatReloader]
[2021-07-27 14:26:34,661][MainThread:19608][task_id:django.utils.autoreload][autoreload.py:251][INFO][D:\zhouzhi\gitlit_code\logistic_tracking_system\logistic_tracking_system\lts\views.py changed, reloading.]
[2021-07-27 14:26:35,446][MainThread:4952][task_id:django.utils.autoreload][autoreload.py:637][INFO][Watching for file changes with StatReloader]
[2021-07-27 14:28:02,681][MainThread:4952][task_id:django.utils.autoreload][autoreload.py:251][INFO][D:\zhouzhi\gitlit_code\logistic_tracking_system\logistic_tracking_system\lts\urls.py changed, reloading.]
[2021-07-27 14:28:03,366][MainThread:15496][task_id:django.utils.autoreload][autoreload.py:637][INFO][Watching for file changes with StatReloader]
[2021-07-27 14:33:44,807][Thread-1:9884][task_id:django.request][log.py:230][ERROR][Internal Server Error: /logistic/LogisticProductPlanCodeName]
Traceback (most recent call last):
  File "D:\zhouzhi\gitlit_code\logistic_tracking_system\logistic_tracking_system\lts\views.py", line 4245, in get
    drs = db.execute_sql(conn, sql)
  File "D:\zhouzhi\gitlit_code\logistic_tracking_system\logistic_tracking_system\common\db.py", line 45, in execute_sql
    cursor.execute(sql)
  File "C:\Users\zhi.zhou\Anaconda3\envs\lts\lib\site-packages\pymysql\cursors.py", line 148, in execute
    result = self._query(query)
  File "C:\Users\zhi.zhou\Anaconda3\envs\lts\lib\site-packages\pymysql\cursors.py", line 310, in _query
    conn.query(q)
  File "C:\Users\zhi.zhou\Anaconda3\envs\lts\lib\site-packages\pymysql\connections.py", line 548, in query
    self._affected_rows = self._read_query_result(unbuffered=unbuffered)
  File "C:\Users\zhi.zhou\Anaconda3\envs\lts\lib\site-packages\pymysql\connections.py", line 775, in _read_query_result
    result.read()
  File "C:\Users\zhi.zhou\Anaconda3\envs\lts\lib\site-packages\pymysql\connections.py", line 1156, in read
    first_packet = self.connection._read_packet()
  File "C:\Users\zhi.zhou\Anaconda3\envs\lts\lib\site-packages\pymysql\connections.py", line 725, in _read_packet
    packet.raise_for_error()
  File "C:\Users\zhi.zhou\Anaconda3\envs\lts\lib\site-packages\pymysql\protocol.py", line 221, in raise_for_error
    err.raise_mysql_exception(self._data)
  File "C:\Users\zhi.zhou\Anaconda3\envs\lts\lib\site-packages\pymysql\err.py", line 143, in raise_mysql_exception
    raise errorclass(errno, errval)
pymysql.err.OperationalError: (1046, 'No database selected')

During handling of the above exception, another exception occurred:

Traceback (most recent call last):
  File "C:\Users\zhi.zhou\Anaconda3\envs\lts\lib\site-packages\django\core\handlers\exception.py", line 47, in inner
    response = get_response(request)
  File "C:\Users\zhi.zhou\Anaconda3\envs\lts\lib\site-packages\django\core\handlers\base.py", line 181, in _get_response
    response = wrapped_callback(request, *callback_args, **callback_kwargs)
  File "C:\Users\zhi.zhou\Anaconda3\envs\lts\lib\site-packages\django\views\generic\base.py", line 70, in view
    return self.dispatch(request, *args, **kwargs)
  File "C:\Users\zhi.zhou\Anaconda3\envs\lts\lib\site-packages\django\views\generic\base.py", line 98, in dispatch
    return handler(request, *args, **kwargs)
  File "D:\zhouzhi\gitlit_code\logistic_tracking_system\logistic_tracking_system\lts\views.py", line 4258, in get
    data = json.dumps(data)
  File "C:\Users\zhi.zhou\Anaconda3\envs\lts\lib\json\__init__.py", line 231, in dumps
    return _default_encoder.encode(obj)
  File "C:\Users\zhi.zhou\Anaconda3\envs\lts\lib\json\encoder.py", line 199, in encode
    chunks = self.iterencode(o, _one_shot=True)
  File "C:\Users\zhi.zhou\Anaconda3\envs\lts\lib\json\encoder.py", line 257, in iterencode
    return _iterencode(o, 0)
  File "C:\Users\zhi.zhou\Anaconda3\envs\lts\lib\json\encoder.py", line 180, in default
    o.__class__.__name__)
TypeError: Object of type 'OperationalError' is not JSON serializable
[2021-07-27 14:34:15,914][Thread-3:14304][task_id:django.request][log.py:230][ERROR][Internal Server Error: /logistic/LogisticWorkCodeName]
Traceback (most recent call last):
  File "D:\zhouzhi\gitlit_code\logistic_tracking_system\logistic_tracking_system\lts\views.py", line 4304, in get
    drs = db.execute_sql(conn, sql)
  File "D:\zhouzhi\gitlit_code\logistic_tracking_system\logistic_tracking_system\common\db.py", line 45, in execute_sql
    cursor.execute(sql)
  File "C:\Users\zhi.zhou\Anaconda3\envs\lts\lib\site-packages\pymysql\cursors.py", line 148, in execute
    result = self._query(query)
  File "C:\Users\zhi.zhou\Anaconda3\envs\lts\lib\site-packages\pymysql\cursors.py", line 310, in _query
    conn.query(q)
  File "C:\Users\zhi.zhou\Anaconda3\envs\lts\lib\site-packages\pymysql\connections.py", line 548, in query
    self._affected_rows = self._read_query_result(unbuffered=unbuffered)
  File "C:\Users\zhi.zhou\Anaconda3\envs\lts\lib\site-packages\pymysql\connections.py", line 775, in _read_query_result
    result.read()
  File "C:\Users\zhi.zhou\Anaconda3\envs\lts\lib\site-packages\pymysql\connections.py", line 1156, in read
    first_packet = self.connection._read_packet()
  File "C:\Users\zhi.zhou\Anaconda3\envs\lts\lib\site-packages\pymysql\connections.py", line 725, in _read_packet
    packet.raise_for_error()
  File "C:\Users\zhi.zhou\Anaconda3\envs\lts\lib\site-packages\pymysql\protocol.py", line 221, in raise_for_error
    err.raise_mysql_exception(self._data)
  File "C:\Users\zhi.zhou\Anaconda3\envs\lts\lib\site-packages\pymysql\err.py", line 143, in raise_mysql_exception
    raise errorclass(errno, errval)
pymysql.err.OperationalError: (1046, 'No database selected')

During handling of the above exception, another exception occurred:

Traceback (most recent call last):
  File "C:\Users\zhi.zhou\Anaconda3\envs\lts\lib\site-packages\django\core\handlers\exception.py", line 47, in inner
    response = get_response(request)
  File "C:\Users\zhi.zhou\Anaconda3\envs\lts\lib\site-packages\django\core\handlers\base.py", line 181, in _get_response
    response = wrapped_callback(request, *callback_args, **callback_kwargs)
  File "C:\Users\zhi.zhou\Anaconda3\envs\lts\lib\site-packages\django\views\generic\base.py", line 70, in view
    return self.dispatch(request, *args, **kwargs)
  File "C:\Users\zhi.zhou\Anaconda3\envs\lts\lib\site-packages\django\views\generic\base.py", line 98, in dispatch
    return handler(request, *args, **kwargs)
  File "D:\zhouzhi\gitlit_code\logistic_tracking_system\logistic_tracking_system\lts\views.py", line 4319, in get
    data = json.dumps(data)
  File "C:\Users\zhi.zhou\Anaconda3\envs\lts\lib\json\__init__.py", line 231, in dumps
    return _default_encoder.encode(obj)
  File "C:\Users\zhi.zhou\Anaconda3\envs\lts\lib\json\encoder.py", line 199, in encode
    chunks = self.iterencode(o, _one_shot=True)
  File "C:\Users\zhi.zhou\Anaconda3\envs\lts\lib\json\encoder.py", line 257, in iterencode
    return _iterencode(o, 0)
  File "C:\Users\zhi.zhou\Anaconda3\envs\lts\lib\json\encoder.py", line 180, in default
    o.__class__.__name__)
TypeError: Object of type 'OperationalError' is not JSON serializable
[2021-07-27 14:36:08,713][Thread-4:12188][task_id:lts.views][views.py:1853][ERROR][查询产品列表失败]
[2021-07-27 14:36:19,366][Thread-4:12188][task_id:lts.views][views.py:218][INFO][登录成功]
[2021-07-27 14:36:47,257][Thread-4:12188][task_id:lts.views][views.py:218][INFO][登录成功]
[2021-07-27 14:38:08,730][Thread-6:7688][task_id:lts.views][views.py:2036][INFO][创建产品详情表成功]
[2021-07-27 14:38:18,538][Thread-6:7688][task_id:lts.views][views.py:218][INFO][登录成功]
[2021-07-27 14:41:17,660][Thread-6:7688][task_id:lts.views][views.py:1495][INFO][创建物料详情表成功]
[2021-07-27 14:42:20,679][MainThread:15496][task_id:django.utils.autoreload][autoreload.py:251][INFO][D:\zhouzhi\gitlit_code\logistic_tracking_system\logistic_tracking_system\lts\views.py changed, reloading.]
[2021-07-27 14:42:21,341][MainThread:5852][task_id:django.utils.autoreload][autoreload.py:637][INFO][Watching for file changes with StatReloader]
[2021-07-27 14:43:42,441][MainThread:5852][task_id:django.utils.autoreload][autoreload.py:251][INFO][D:\zhouzhi\gitlit_code\logistic_tracking_system\logistic_tracking_system\lts\views.py changed, reloading.]
[2021-07-27 14:43:43,084][MainThread:11324][task_id:django.utils.autoreload][autoreload.py:637][INFO][Watching for file changes with StatReloader]
[2021-07-27 14:52:57,900][Thread-6:1828][task_id:lts.views][views.py:1493][INFO][创建物料详情表成功]
[2021-07-27 14:56:49,549][MainThread:11324][task_id:django.utils.autoreload][autoreload.py:251][INFO][D:\zhouzhi\gitlit_code\logistic_tracking_system\logistic_tracking_system\lts\views.py changed, reloading.]
[2021-07-27 14:56:50,209][MainThread:19608][task_id:django.utils.autoreload][autoreload.py:637][INFO][Watching for file changes with StatReloader]
[2021-07-27 14:57:23,594][MainThread:19608][task_id:django.utils.autoreload][autoreload.py:251][INFO][D:\zhouzhi\gitlit_code\logistic_tracking_system\logistic_tracking_system\lts\views.py changed, reloading.]
[2021-07-27 14:57:24,229][MainThread:12084][task_id:django.utils.autoreload][autoreload.py:637][INFO][Watching for file changes with StatReloader]
[2021-07-27 15:00:51,977][MainThread:12084][task_id:django.utils.autoreload][autoreload.py:251][INFO][D:\zhouzhi\gitlit_code\logistic_tracking_system\logistic_tracking_system\lts\views.py changed, reloading.]
[2021-07-27 15:00:52,634][MainThread:1720][task_id:django.utils.autoreload][autoreload.py:637][INFO][Watching for file changes with StatReloader]
[2021-07-27 15:05:34,696][MainThread:1720][task_id:django.utils.autoreload][autoreload.py:251][INFO][D:\zhouzhi\gitlit_code\logistic_tracking_system\logistic_tracking_system\lts\views.py changed, reloading.]
[2021-07-27 15:05:35,343][MainThread:18728][task_id:django.utils.autoreload][autoreload.py:637][INFO][Watching for file changes with StatReloader]
[2021-07-27 15:05:48,063][MainThread:18728][task_id:django.utils.autoreload][autoreload.py:251][INFO][D:\zhouzhi\gitlit_code\logistic_tracking_system\logistic_tracking_system\lts\views.py changed, reloading.]
[2021-07-27 15:05:48,716][MainThread:20100][task_id:django.utils.autoreload][autoreload.py:637][INFO][Watching for file changes with StatReloader]
[2021-07-27 15:08:28,445][MainThread:20100][task_id:django.utils.autoreload][autoreload.py:251][INFO][D:\zhouzhi\gitlit_code\logistic_tracking_system\logistic_tracking_system\lts\views.py changed, reloading.]
[2021-07-27 15:08:29,096][MainThread:17792][task_id:django.utils.autoreload][autoreload.py:637][INFO][Watching for file changes with StatReloader]
[2021-07-27 15:09:16,040][MainThread:17792][task_id:django.utils.autoreload][autoreload.py:251][INFO][D:\zhouzhi\gitlit_code\logistic_tracking_system\logistic_tracking_system\lts\views.py changed, reloading.]
[2021-07-27 15:09:16,694][MainThread:19832][task_id:django.utils.autoreload][autoreload.py:637][INFO][Watching for file changes with StatReloader]
[2021-07-27 15:09:23,158][MainThread:19832][task_id:django.utils.autoreload][autoreload.py:251][INFO][D:\zhouzhi\gitlit_code\logistic_tracking_system\logistic_tracking_system\lts\views.py changed, reloading.]
[2021-07-27 15:09:23,803][MainThread:7644][task_id:django.utils.autoreload][autoreload.py:637][INFO][Watching for file changes with StatReloader]
[2021-07-27 15:09:29,448][MainThread:7644][task_id:django.utils.autoreload][autoreload.py:251][INFO][D:\zhouzhi\gitlit_code\logistic_tracking_system\logistic_tracking_system\lts\views.py changed, reloading.]
[2021-07-27 15:09:30,089][MainThread:5060][task_id:django.utils.autoreload][autoreload.py:637][INFO][Watching for file changes with StatReloader]
[2021-07-27 15:09:40,701][MainThread:5060][task_id:django.utils.autoreload][autoreload.py:251][INFO][D:\zhouzhi\gitlit_code\logistic_tracking_system\logistic_tracking_system\lts\views.py changed, reloading.]
[2021-07-27 15:09:41,352][MainThread:16260][task_id:django.utils.autoreload][autoreload.py:637][INFO][Watching for file changes with StatReloader]
[2021-07-27 15:09:56,043][Thread-2:8376][task_id:lts.views][views.py:1606][ERROR][修改失败---->(1064, "You have an error in your SQL syntax; check the manual that corresponds to your MySQL server version for the right syntax to use near 'where matter_code = 'Im_BOM_Matter_1'' at line 3")]
[2021-07-27 15:10:06,690][Thread-2:8376][task_id:lts.views][views.py:1606][ERROR][修改失败---->(1064, "You have an error in your SQL syntax; check the manual that corresponds to your MySQL server version for the right syntax to use near 'where matter_code = 'Im_BOM_Matter_1'' at line 3")]
[2021-07-27 15:10:54,443][MainThread:16260][task_id:django.utils.autoreload][autoreload.py:251][INFO][D:\zhouzhi\gitlit_code\logistic_tracking_system\logistic_tracking_system\lts\views.py changed, reloading.]
[2021-07-27 15:10:55,124][MainThread:12608][task_id:django.utils.autoreload][autoreload.py:637][INFO][Watching for file changes with StatReloader]
[2021-07-27 15:11:41,266][Thread-1:17504][task_id:lts.views][views.py:1608][ERROR][修改失败---->(1064, "You have an error in your SQL syntax; check the manual that corresponds to your MySQL server version for the right syntax to use near 'where matter_code = 'Im_BOM_Matter_1'' at line 3")]
[2021-07-27 15:12:45,193][MainThread:12608][task_id:django.utils.autoreload][autoreload.py:251][INFO][D:\zhouzhi\gitlit_code\logistic_tracking_system\logistic_tracking_system\lts\views.py changed, reloading.]
[2021-07-27 15:12:45,849][MainThread:19920][task_id:django.utils.autoreload][autoreload.py:637][INFO][Watching for file changes with StatReloader]
[2021-07-27 15:19:32,433][Thread-4:12804][task_id:lts.views][views.py:218][INFO][登录成功]
[2021-07-27 15:27:06,808][Thread-13:1608][task_id:lts.views][views.py:3528][ERROR][创建产品详情表失败]
[2021-07-27 15:27:20,474][Thread-13:1608][task_id:lts.views][views.py:272][INFO][登录成功]
[2021-07-27 15:28:13,612][Thread-13:1608][task_id:lts.views][views.py:218][INFO][登录成功]
[2021-07-27 15:41:14,285][Thread-22:3132][task_id:lts.views][views.py:2043][INFO][创建产品详情表成功]
[2021-07-27 15:53:41,081][MainThread:19920][task_id:django.utils.autoreload][autoreload.py:251][INFO][D:\zhouzhi\gitlit_code\logistic_tracking_system\logistic_tracking_system\lts\views.py changed, reloading.]
[2021-07-27 15:53:41,735][MainThread:9124][task_id:django.utils.autoreload][autoreload.py:637][INFO][Watching for file changes with StatReloader]
[2021-07-27 15:59:03,508][Thread-3:19960][task_id:lts.views][views.py:272][INFO][登录成功]
[2021-07-27 16:01:42,693][Thread-4:19048][task_id:lts.views][views.py:3517][INFO][创建产品详情表成功]
[2021-07-27 16:02:05,266][MainThread:9124][task_id:django.utils.autoreload][autoreload.py:251][INFO][D:\zhouzhi\gitlit_code\logistic_tracking_system\logistic_tracking_system\lts\views.py changed, reloading.]
[2021-07-27 16:02:05,905][MainThread:4592][task_id:django.utils.autoreload][autoreload.py:637][INFO][Watching for file changes with StatReloader]
[2021-07-27 16:03:39,434][MainThread:4592][task_id:django.utils.autoreload][autoreload.py:251][INFO][D:\zhouzhi\gitlit_code\logistic_tracking_system\logistic_tracking_system\lts\views.py changed, reloading.]
[2021-07-27 16:03:40,103][MainThread:10004][task_id:django.utils.autoreload][autoreload.py:637][INFO][Watching for file changes with StatReloader]
[2021-07-27 16:06:13,760][Thread-2:11272][task_id:lts.views][views.py:218][INFO][登录成功]
[2021-07-27 16:07:11,505][Thread-3:9800][task_id:lts.views][views.py:272][INFO][登录成功]
[2021-07-27 16:08:28,425][MainThread:10004][task_id:django.utils.autoreload][autoreload.py:251][INFO][D:\zhouzhi\gitlit_code\logistic_tracking_system\logistic_tracking_system\lts\views.py changed, reloading.]
[2021-07-27 16:08:29,079][MainThread:20000][task_id:django.utils.autoreload][autoreload.py:637][INFO][Watching for file changes with StatReloader]
[2021-07-27 16:08:49,297][Thread-1:5256][task_id:lts.views][views.py:272][INFO][登录成功]
[2021-07-27 16:11:09,153][MainThread:20000][task_id:django.utils.autoreload][autoreload.py:251][INFO][D:\zhouzhi\gitlit_code\logistic_tracking_system\logistic_tracking_system\lts\views.py changed, reloading.]
[2021-07-27 16:11:09,789][MainThread:12340][task_id:django.utils.autoreload][autoreload.py:637][INFO][Watching for file changes with StatReloader]
[2021-07-27 16:11:38,388][Thread-1:14140][task_id:lts.views][views.py:272][INFO][登录成功]
[2021-07-27 16:11:43,272][Thread-2:7096][task_id:lts.views][views.py:1864][ERROR][查询产品列表失败]
[2021-07-27 16:17:20,057][MainThread:12340][task_id:django.utils.autoreload][autoreload.py:251][INFO][D:\zhouzhi\gitlit_code\logistic_tracking_system\logistic_tracking_system\lts\views.py changed, reloading.]
[2021-07-27 16:17:20,710][MainThread:6664][task_id:django.utils.autoreload][autoreload.py:637][INFO][Watching for file changes with StatReloader]
[2021-07-27 16:18:33,696][Thread-1:8556][task_id:lts.views][views.py:272][INFO][登录成功]
[2021-07-27 16:19:17,823][Thread-2:2440][task_id:lts.views][views.py:272][INFO][登录成功]
[2021-07-27 16:21:34,104][MainThread:6664][task_id:django.utils.autoreload][autoreload.py:251][INFO][D:\zhouzhi\gitlit_code\logistic_tracking_system\logistic_tracking_system\lts\views.py changed, reloading.]
[2021-07-27 16:21:34,737][MainThread:3892][task_id:django.utils.autoreload][autoreload.py:637][INFO][Watching for file changes with StatReloader]
[2021-07-27 16:21:45,783][Thread-1:1280][task_id:lts.views][views.py:272][INFO][登录成功]
[2021-07-27 16:27:28,131][MainThread:3892][task_id:django.utils.autoreload][autoreload.py:251][INFO][D:\zhouzhi\gitlit_code\logistic_tracking_system\logistic_tracking_system\lts\views.py changed, reloading.]
[2021-07-27 16:27:28,786][MainThread:12144][task_id:django.utils.autoreload][autoreload.py:637][INFO][Watching for file changes with StatReloader]
[2021-07-27 16:28:02,851][Thread-1:3468][task_id:django.request][log.py:230][ERROR][Internal Server Error: /logistic/LogisticNoPagePersonMatter]
Traceback (most recent call last):
  File "D:\zhouzhi\gitlit_code\logistic_tracking_system\logistic_tracking_system\lts\views.py", line 3702, in get
    dict_data["rule"] = dr[4]
IndexError: tuple index out of range

During handling of the above exception, another exception occurred:

Traceback (most recent call last):
  File "C:\Users\zhi.zhou\Anaconda3\envs\lts\lib\site-packages\django\core\handlers\exception.py", line 47, in inner
    response = get_response(request)
  File "C:\Users\zhi.zhou\Anaconda3\envs\lts\lib\site-packages\django\core\handlers\base.py", line 181, in _get_response
    response = wrapped_callback(request, *callback_args, **callback_kwargs)
  File "C:\Users\zhi.zhou\Anaconda3\envs\lts\lib\site-packages\django\views\generic\base.py", line 70, in view
    return self.dispatch(request, *args, **kwargs)
  File "C:\Users\zhi.zhou\Anaconda3\envs\lts\lib\site-packages\django\views\generic\base.py", line 98, in dispatch
    return handler(request, *args, **kwargs)
  File "D:\zhouzhi\gitlit_code\logistic_tracking_system\logistic_tracking_system\lts\views.py", line 3726, in get
    result = json.dumps(result)
  File "C:\Users\zhi.zhou\Anaconda3\envs\lts\lib\json\__init__.py", line 231, in dumps
    return _default_encoder.encode(obj)
  File "C:\Users\zhi.zhou\Anaconda3\envs\lts\lib\json\encoder.py", line 199, in encode
    chunks = self.iterencode(o, _one_shot=True)
  File "C:\Users\zhi.zhou\Anaconda3\envs\lts\lib\json\encoder.py", line 257, in iterencode
    return _iterencode(o, 0)
  File "C:\Users\zhi.zhou\Anaconda3\envs\lts\lib\json\encoder.py", line 180, in default
    o.__class__.__name__)
TypeError: Object of type 'IndexError' is not JSON serializable
[2021-07-27 16:28:16,270][Thread-1:3468][task_id:django.request][log.py:230][ERROR][Internal Server Error: /logistic/LogisticNoPagePersonMatter]
Traceback (most recent call last):
  File "D:\zhouzhi\gitlit_code\logistic_tracking_system\logistic_tracking_system\lts\views.py", line 3702, in get
    dict_data["rule"] = dr[4]
IndexError: tuple index out of range

During handling of the above exception, another exception occurred:

Traceback (most recent call last):
  File "C:\Users\zhi.zhou\Anaconda3\envs\lts\lib\site-packages\django\core\handlers\exception.py", line 47, in inner
    response = get_response(request)
  File "C:\Users\zhi.zhou\Anaconda3\envs\lts\lib\site-packages\django\core\handlers\base.py", line 181, in _get_response
    response = wrapped_callback(request, *callback_args, **callback_kwargs)
  File "C:\Users\zhi.zhou\Anaconda3\envs\lts\lib\site-packages\django\views\generic\base.py", line 70, in view
    return self.dispatch(request, *args, **kwargs)
  File "C:\Users\zhi.zhou\Anaconda3\envs\lts\lib\site-packages\django\views\generic\base.py", line 98, in dispatch
    return handler(request, *args, **kwargs)
  File "D:\zhouzhi\gitlit_code\logistic_tracking_system\logistic_tracking_system\lts\views.py", line 3726, in get
    result = json.dumps(result)
  File "C:\Users\zhi.zhou\Anaconda3\envs\lts\lib\json\__init__.py", line 231, in dumps
    return _default_encoder.encode(obj)
  File "C:\Users\zhi.zhou\Anaconda3\envs\lts\lib\json\encoder.py", line 199, in encode
    chunks = self.iterencode(o, _one_shot=True)
  File "C:\Users\zhi.zhou\Anaconda3\envs\lts\lib\json\encoder.py", line 257, in iterencode
    return _iterencode(o, 0)
  File "C:\Users\zhi.zhou\Anaconda3\envs\lts\lib\json\encoder.py", line 180, in default
    o.__class__.__name__)
TypeError: Object of type 'IndexError' is not JSON serializable
[2021-07-27 16:32:11,456][Thread-4:11096][task_id:lts.views][views.py:218][INFO][登录成功]
[2021-07-27 16:33:23,583][Thread-3:16984][task_id:django.request][log.py:230][ERROR][Internal Server Error: /logistic/LogisticNoPagePersonMatter]
Traceback (most recent call last):
  File "D:\zhouzhi\gitlit_code\logistic_tracking_system\logistic_tracking_system\lts\views.py", line 3702, in get
    dict_data["rule"] = dr[4]
IndexError: tuple index out of range

During handling of the above exception, another exception occurred:

Traceback (most recent call last):
  File "C:\Users\zhi.zhou\Anaconda3\envs\lts\lib\site-packages\django\core\handlers\exception.py", line 47, in inner
    response = get_response(request)
  File "C:\Users\zhi.zhou\Anaconda3\envs\lts\lib\site-packages\django\core\handlers\base.py", line 181, in _get_response
    response = wrapped_callback(request, *callback_args, **callback_kwargs)
  File "C:\Users\zhi.zhou\Anaconda3\envs\lts\lib\site-packages\django\views\generic\base.py", line 70, in view
    return self.dispatch(request, *args, **kwargs)
  File "C:\Users\zhi.zhou\Anaconda3\envs\lts\lib\site-packages\django\views\generic\base.py", line 98, in dispatch
    return handler(request, *args, **kwargs)
  File "D:\zhouzhi\gitlit_code\logistic_tracking_system\logistic_tracking_system\lts\views.py", line 3726, in get
    result = json.dumps(result)
  File "C:\Users\zhi.zhou\Anaconda3\envs\lts\lib\json\__init__.py", line 231, in dumps
    return _default_encoder.encode(obj)
  File "C:\Users\zhi.zhou\Anaconda3\envs\lts\lib\json\encoder.py", line 199, in encode
    chunks = self.iterencode(o, _one_shot=True)
  File "C:\Users\zhi.zhou\Anaconda3\envs\lts\lib\json\encoder.py", line 257, in iterencode
    return _iterencode(o, 0)
  File "C:\Users\zhi.zhou\Anaconda3\envs\lts\lib\json\encoder.py", line 180, in default
    o.__class__.__name__)
TypeError: Object of type 'IndexError' is not JSON serializable
[2021-07-27 16:33:28,164][Thread-6:6724][task_id:django.request][log.py:230][ERROR][Internal Server Error: /logistic/LogisticNoPagePersonMatter]
Traceback (most recent call last):
  File "D:\zhouzhi\gitlit_code\logistic_tracking_system\logistic_tracking_system\lts\views.py", line 3702, in get
    dict_data["rule"] = dr[4]
IndexError: tuple index out of range

During handling of the above exception, another exception occurred:

Traceback (most recent call last):
  File "C:\Users\zhi.zhou\Anaconda3\envs\lts\lib\site-packages\django\core\handlers\exception.py", line 47, in inner
    response = get_response(request)
  File "C:\Users\zhi.zhou\Anaconda3\envs\lts\lib\site-packages\django\core\handlers\base.py", line 181, in _get_response
    response = wrapped_callback(request, *callback_args, **callback_kwargs)
  File "C:\Users\zhi.zhou\Anaconda3\envs\lts\lib\site-packages\django\views\generic\base.py", line 70, in view
    return self.dispatch(request, *args, **kwargs)
  File "C:\Users\zhi.zhou\Anaconda3\envs\lts\lib\site-packages\django\views\generic\base.py", line 98, in dispatch
    return handler(request, *args, **kwargs)
  File "D:\zhouzhi\gitlit_code\logistic_tracking_system\logistic_tracking_system\lts\views.py", line 3726, in get
    result = json.dumps(result)
  File "C:\Users\zhi.zhou\Anaconda3\envs\lts\lib\json\__init__.py", line 231, in dumps
    return _default_encoder.encode(obj)
  File "C:\Users\zhi.zhou\Anaconda3\envs\lts\lib\json\encoder.py", line 199, in encode
    chunks = self.iterencode(o, _one_shot=True)
  File "C:\Users\zhi.zhou\Anaconda3\envs\lts\lib\json\encoder.py", line 257, in iterencode
    return _iterencode(o, 0)
  File "C:\Users\zhi.zhou\Anaconda3\envs\lts\lib\json\encoder.py", line 180, in default
    o.__class__.__name__)
TypeError: Object of type 'IndexError' is not JSON serializable
[2021-07-27 16:35:16,862][Thread-7:12936][task_id:django.request][log.py:230][ERROR][Internal Server Error: /logistic/LogisticNoPagePersonMatter]
Traceback (most recent call last):
  File "D:\zhouzhi\gitlit_code\logistic_tracking_system\logistic_tracking_system\lts\views.py", line 3702, in get
    dict_data["rule"] = dr[4]
IndexError: tuple index out of range

During handling of the above exception, another exception occurred:

Traceback (most recent call last):
  File "C:\Users\zhi.zhou\Anaconda3\envs\lts\lib\site-packages\django\core\handlers\exception.py", line 47, in inner
    response = get_response(request)
  File "C:\Users\zhi.zhou\Anaconda3\envs\lts\lib\site-packages\django\core\handlers\base.py", line 181, in _get_response
    response = wrapped_callback(request, *callback_args, **callback_kwargs)
  File "C:\Users\zhi.zhou\Anaconda3\envs\lts\lib\site-packages\django\views\generic\base.py", line 70, in view
    return self.dispatch(request, *args, **kwargs)
  File "C:\Users\zhi.zhou\Anaconda3\envs\lts\lib\site-packages\django\views\generic\base.py", line 98, in dispatch
    return handler(request, *args, **kwargs)
  File "D:\zhouzhi\gitlit_code\logistic_tracking_system\logistic_tracking_system\lts\views.py", line 3726, in get
    result = json.dumps(result)
  File "C:\Users\zhi.zhou\Anaconda3\envs\lts\lib\json\__init__.py", line 231, in dumps
    return _default_encoder.encode(obj)
  File "C:\Users\zhi.zhou\Anaconda3\envs\lts\lib\json\encoder.py", line 199, in encode
    chunks = self.iterencode(o, _one_shot=True)
  File "C:\Users\zhi.zhou\Anaconda3\envs\lts\lib\json\encoder.py", line 257, in iterencode
    return _iterencode(o, 0)
  File "C:\Users\zhi.zhou\Anaconda3\envs\lts\lib\json\encoder.py", line 180, in default
    o.__class__.__name__)
TypeError: Object of type 'IndexError' is not JSON serializable
[2021-07-27 16:39:59,684][MainThread:12144][task_id:django.utils.autoreload][autoreload.py:251][INFO][D:\zhouzhi\gitlit_code\logistic_tracking_system\logistic_tracking_system\lts\views.py changed, reloading.]
[2021-07-27 16:40:00,357][MainThread:20280][task_id:django.utils.autoreload][autoreload.py:637][INFO][Watching for file changes with StatReloader]
[2021-07-27 16:40:44,122][MainThread:20280][task_id:django.utils.autoreload][autoreload.py:251][INFO][D:\zhouzhi\gitlit_code\logistic_tracking_system\logistic_tracking_system\lts\views.py changed, reloading.]
[2021-07-27 16:40:44,788][MainThread:20016][task_id:django.utils.autoreload][autoreload.py:637][INFO][Watching for file changes with StatReloader]
[2021-07-27 16:43:25,046][MainThread:20016][task_id:django.utils.autoreload][autoreload.py:251][INFO][D:\zhouzhi\gitlit_code\logistic_tracking_system\logistic_tracking_system\lts\views.py changed, reloading.]
[2021-07-27 16:43:25,711][MainThread:20012][task_id:django.utils.autoreload][autoreload.py:637][INFO][Watching for file changes with StatReloader]
[2021-07-27 16:46:09,737][MainThread:20012][task_id:django.utils.autoreload][autoreload.py:251][INFO][D:\zhouzhi\gitlit_code\logistic_tracking_system\logistic_tracking_system\lts\views.py changed, reloading.]
[2021-07-27 16:46:10,432][MainThread:19416][task_id:django.utils.autoreload][autoreload.py:637][INFO][Watching for file changes with StatReloader]
[2021-07-27 16:46:44,857][Thread-1:10868][task_id:django.request][log.py:230][WARNING][Not Found: /favicon.ico]
[2021-07-27 16:47:10,841][MainThread:19416][task_id:django.utils.autoreload][autoreload.py:251][INFO][D:\zhouzhi\gitlit_code\logistic_tracking_system\logistic_tracking_system\lts\views.py changed, reloading.]
[2021-07-27 16:47:11,616][MainThread:19140][task_id:django.utils.autoreload][autoreload.py:637][INFO][Watching for file changes with StatReloader]
[2021-07-27 16:49:28,016][Thread-1:21404][task_id:lts.views][views.py:272][INFO][登录成功]
[2021-07-27 16:55:29,401][Thread-4:21920][task_id:lts.views][views.py:272][INFO][登录成功]
[2021-07-27 16:56:46,033][Thread-7:21844][task_id:lts.views][views.py:218][INFO][登录成功]
[2021-07-27 16:57:32,952][Thread-10:7500][task_id:lts.views][views.py:272][INFO][登录成功]
[2021-07-27 17:02:30,078][Thread-16:15672][task_id:lts.views][views.py:3620][ERROR][修改失败---->(1054, "Unknown column 'status' in 'field list'")]
[2021-07-27 17:03:28,805][Thread-20:2944][task_id:lts.views][views.py:3620][ERROR][修改失败---->(1054, "Unknown column 'status' in 'field list'")]
[2021-07-27 17:04:40,024][Thread-16:15672][task_id:lts.views][views.py:3620][ERROR][修改失败---->(1054, "Unknown column 'status' in 'field list'")]
[2021-07-27 17:05:16,548][Thread-16:15672][task_id:lts.views][views.py:3620][ERROR][修改失败---->(1054, "Unknown column 'status' in 'field list'")]
[2021-07-27 17:06:49,195][Thread-23:13368][task_id:django.request][log.py:230][ERROR][Internal Server Error: /logistic/LogisticMatterNameCode]
Traceback (most recent call last):
  File "D:\zhouzhi\gitlit_code\logistic_tracking_system\logistic_tracking_system\lts\views.py", line 5096, in get
    drs = db.execute_sql(conn, sql)
  File "D:\zhouzhi\gitlit_code\logistic_tracking_system\logistic_tracking_system\common\db.py", line 45, in execute_sql
    cursor.execute(sql)
  File "C:\Users\zhi.zhou\Anaconda3\envs\lts\lib\site-packages\pymysql\cursors.py", line 148, in execute
    result = self._query(query)
  File "C:\Users\zhi.zhou\Anaconda3\envs\lts\lib\site-packages\pymysql\cursors.py", line 310, in _query
    conn.query(q)
  File "C:\Users\zhi.zhou\Anaconda3\envs\lts\lib\site-packages\pymysql\connections.py", line 548, in query
    self._affected_rows = self._read_query_result(unbuffered=unbuffered)
  File "C:\Users\zhi.zhou\Anaconda3\envs\lts\lib\site-packages\pymysql\connections.py", line 775, in _read_query_result
    result.read()
  File "C:\Users\zhi.zhou\Anaconda3\envs\lts\lib\site-packages\pymysql\connections.py", line 1156, in read
    first_packet = self.connection._read_packet()
  File "C:\Users\zhi.zhou\Anaconda3\envs\lts\lib\site-packages\pymysql\connections.py", line 725, in _read_packet
    packet.raise_for_error()
  File "C:\Users\zhi.zhou\Anaconda3\envs\lts\lib\site-packages\pymysql\protocol.py", line 221, in raise_for_error
    err.raise_mysql_exception(self._data)
  File "C:\Users\zhi.zhou\Anaconda3\envs\lts\lib\site-packages\pymysql\err.py", line 143, in raise_mysql_exception
    raise errorclass(errno, errval)
pymysql.err.OperationalError: (1054, "Unknown column 'matter_name' in 'field list'")

During handling of the above exception, another exception occurred:

Traceback (most recent call last):
  File "C:\Users\zhi.zhou\Anaconda3\envs\lts\lib\site-packages\django\core\handlers\exception.py", line 47, in inner
    response = get_response(request)
  File "C:\Users\zhi.zhou\Anaconda3\envs\lts\lib\site-packages\django\core\handlers\base.py", line 181, in _get_response
    response = wrapped_callback(request, *callback_args, **callback_kwargs)
  File "C:\Users\zhi.zhou\Anaconda3\envs\lts\lib\site-packages\django\views\generic\base.py", line 70, in view
    return self.dispatch(request, *args, **kwargs)
  File "C:\Users\zhi.zhou\Anaconda3\envs\lts\lib\site-packages\django\views\generic\base.py", line 98, in dispatch
    return handler(request, *args, **kwargs)
  File "D:\zhouzhi\gitlit_code\logistic_tracking_system\logistic_tracking_system\lts\views.py", line 5110, in get
    data = json.dumps(data)
  File "C:\Users\zhi.zhou\Anaconda3\envs\lts\lib\json\__init__.py", line 231, in dumps
    return _default_encoder.encode(obj)
  File "C:\Users\zhi.zhou\Anaconda3\envs\lts\lib\json\encoder.py", line 199, in encode
    chunks = self.iterencode(o, _one_shot=True)
  File "C:\Users\zhi.zhou\Anaconda3\envs\lts\lib\json\encoder.py", line 257, in iterencode
    return _iterencode(o, 0)
  File "C:\Users\zhi.zhou\Anaconda3\envs\lts\lib\json\encoder.py", line 180, in default
    o.__class__.__name__)
TypeError: Object of type 'OperationalError' is not JSON serializable
[2021-07-27 17:06:50,060][Thread-23:13368][task_id:django.request][log.py:230][ERROR][Internal Server Error: /logistic/LogisticMatterNameCode]
Traceback (most recent call last):
  File "D:\zhouzhi\gitlit_code\logistic_tracking_system\logistic_tracking_system\lts\views.py", line 5096, in get
    drs = db.execute_sql(conn, sql)
  File "D:\zhouzhi\gitlit_code\logistic_tracking_system\logistic_tracking_system\common\db.py", line 45, in execute_sql
    cursor.execute(sql)
  File "C:\Users\zhi.zhou\Anaconda3\envs\lts\lib\site-packages\pymysql\cursors.py", line 148, in execute
    result = self._query(query)
  File "C:\Users\zhi.zhou\Anaconda3\envs\lts\lib\site-packages\pymysql\cursors.py", line 310, in _query
    conn.query(q)
  File "C:\Users\zhi.zhou\Anaconda3\envs\lts\lib\site-packages\pymysql\connections.py", line 548, in query
    self._affected_rows = self._read_query_result(unbuffered=unbuffered)
  File "C:\Users\zhi.zhou\Anaconda3\envs\lts\lib\site-packages\pymysql\connections.py", line 775, in _read_query_result
    result.read()
  File "C:\Users\zhi.zhou\Anaconda3\envs\lts\lib\site-packages\pymysql\connections.py", line 1156, in read
    first_packet = self.connection._read_packet()
  File "C:\Users\zhi.zhou\Anaconda3\envs\lts\lib\site-packages\pymysql\connections.py", line 725, in _read_packet
    packet.raise_for_error()
  File "C:\Users\zhi.zhou\Anaconda3\envs\lts\lib\site-packages\pymysql\protocol.py", line 221, in raise_for_error
    err.raise_mysql_exception(self._data)
  File "C:\Users\zhi.zhou\Anaconda3\envs\lts\lib\site-packages\pymysql\err.py", line 143, in raise_mysql_exception
    raise errorclass(errno, errval)
pymysql.err.OperationalError: (1054, "Unknown column 'matter_name' in 'field list'")

During handling of the above exception, another exception occurred:

Traceback (most recent call last):
  File "C:\Users\zhi.zhou\Anaconda3\envs\lts\lib\site-packages\django\core\handlers\exception.py", line 47, in inner
    response = get_response(request)
  File "C:\Users\zhi.zhou\Anaconda3\envs\lts\lib\site-packages\django\core\handlers\base.py", line 181, in _get_response
    response = wrapped_callback(request, *callback_args, **callback_kwargs)
  File "C:\Users\zhi.zhou\Anaconda3\envs\lts\lib\site-packages\django\views\generic\base.py", line 70, in view
    return self.dispatch(request, *args, **kwargs)
  File "C:\Users\zhi.zhou\Anaconda3\envs\lts\lib\site-packages\django\views\generic\base.py", line 98, in dispatch
    return handler(request, *args, **kwargs)
  File "D:\zhouzhi\gitlit_code\logistic_tracking_system\logistic_tracking_system\lts\views.py", line 5110, in get
    data = json.dumps(data)
  File "C:\Users\zhi.zhou\Anaconda3\envs\lts\lib\json\__init__.py", line 231, in dumps
    return _default_encoder.encode(obj)
  File "C:\Users\zhi.zhou\Anaconda3\envs\lts\lib\json\encoder.py", line 199, in encode
    chunks = self.iterencode(o, _one_shot=True)
  File "C:\Users\zhi.zhou\Anaconda3\envs\lts\lib\json\encoder.py", line 257, in iterencode
    return _iterencode(o, 0)
  File "C:\Users\zhi.zhou\Anaconda3\envs\lts\lib\json\encoder.py", line 180, in default
    o.__class__.__name__)
TypeError: Object of type 'OperationalError' is not JSON serializable
[2021-07-27 17:07:26,900][Thread-25:21496][task_id:lts.views][views.py:272][INFO][登录成功]
[2021-07-27 17:08:31,648][Thread-27:22360][task_id:lts.views][views.py:3620][ERROR][修改失败---->(1054, "Unknown column 'status' in 'field list'")]
[2021-07-27 17:09:17,910][Thread-28:21696][task_id:lts.views][views.py:3620][ERROR][修改失败---->(1054, "Unknown column 'status' in 'field list'")]
